Workbook

Sheet 模板 - 职责分离分析表
B2: 客户名称：
B3: 项目名称： | E3: 编制人： | G3: 编制日期： | H3: 索引号：XX
B4: 日期： | E4: 复核人： | G4: 复核日期：
B6: 职责分离分析测试
B8: 人员 (角色) | C8: 授权或批准 | D8: 记录或报告 | E8: 资产保管 | F8: 存在职责分离问题? | G8: 识别出缺陷 ? | H8: 描述职责分离问题或已作出的重要判断(如有)
B10: 业务流程 XYZ
B11: 人员 1 | F11: =IF(COUNTIF(C11:E11,Data!$A$3)>1,Data!$B$2,Data!$B$3) -> 否
B12: 人员 2 | F12: =IF(COUNTIF(C12:E12,Data!$A$3)>1,Data!$B$2,Data!$B$3) -> 否
B13: 人员 3 | F13: =IF(COUNTIF(C13:E13,Data!$A$3)>1,Data!$B$2,Data!$B$3) -> 否
B14: 人员 4 | F14: =IF(COUNTIF(C14:E14,Data!$A$3)>1,Data!$B$2,Data!$B$3) -> 否
B15: 人员 5 | F15: =IF(COUNTIF(C15:E15,Data!$A$3)>1,Data!$B$2,Data!$B$3) -> 否
B17: 业务流程 XYZ
B18: 人员 1 | C18: =IF(COUNTIF(C19:C21,Data!$A$3)>0,"X","-") -> - | D18: =IF(COUNTIF(D19:D21,Data!$A$3)>0,"X","-") -> - | E18: =IF(COUNTIF(E19:E21,Data!$A$3)>0,"X","-") -> - | F18: =IF(COUNTIF(C18:E18,Data!$A$3)>1,Data!$B$2,Data!$B$3) -> 否
B19: 步骤 a
B20: 步骤 b
B21: 步骤 c
B23: 人员 2 | C23: =IF(COUNTIF(C24:C26,Data!$A$3)>0,"X","-") -> - | D23: =IF(COUNTIF(D24:D26,Data!$A$3)>0,"X","-") -> - | E23: =IF(COUNTIF(E24:E26,Data!$A$3)>0,"X","-") -> - | F23: =IF(COUNTIF(C23:E23,Data!$A$3)>1,Data!$B$2,Data!$B$3) -> 否
B24: 步骤 a
B25: 步骤 b
B26: 步骤 c
B28: 人员 3 | C28: =IF(COUNTIF(C29:C31,Data!$A$3)>0,"X","-") -> - | D28: =IF(COUNTIF(D29:D31,Data!$A$3)>0,"X","-") -> - | E28: =IF(COUNTIF(E29:E31,Data!$A$3)>0,"X","-") -> - | F28: =IF(COUNTIF(C28:E28,Data!$A$3)>1,Data!$B$2,Data!$B$3) -> 否
B29: 步骤 a
B30: 步骤 b
B31: 步骤 c
B33: 人员 4 | C33: =IF(COUNTIF(C34:C36,Data!$A$3)>0,"X","-") -> - | D33: =IF(COUNTIF(D34:D36,Data!$A$3)>0,"X","-") -> - | E33: =IF(COUNTIF(E34:E36,Data!$A$3)>0,"X","-") -> - | F33: =IF(COUNTIF(C33:E33,Data!$A$3)>1,Data!$B$2,Data!$B$3) -> 否
B34: 步骤 a
B35: 步骤 b
B36: 步骤 c
B38: 人员 5 | C38: =IF(COUNTIF(C39:C41,Data!$A$3)>0,"X","-") -> - | D38: =IF(COUNTIF(D39:D41,Data!$A$3)>0,"X","-") -> - | E38: =IF(COUNTIF(E39:E41,Data!$A$3)>0,"X","-") -> - | F38: =IF(COUNTIF(C38:E38,Data!$A$3)>1,Data!$B$2,Data!$B$3) -> 否
B39: 步骤 a
B40: 步骤 b
B41: 步骤 c

Sheet 模板 - 职责分离控制测试
B2: 客户名称：
B3: 项目名称： | J3: 编制人： | K3: 编制人： | M3: 索引号：XX
B4: 日期： | J4: 复核人： | K4: 复核人：
B6: 职责分离控制测试
B8: 控制 | C8: 控制编号 | D8: 控制描述 | E8: 信息系统控制目标 | F8: 财务报表认定 | G8: 自动/人工 | H8: 预防性/检查性 | I8: 频率 | J8: 测试步骤 | K8: 测试结果 | L8: 是否发现例外 | M8: 支持性文件

Sheet 指引及示例 - 职责分离分析
A1: 指引及示例
B3: 指引
B4: 此模板用于分析业务流程中的职责分离，特别是那些在财务报表中的重要交易。根据项目的具体情况修订模板，适当的添加或删减内容。 职责分离通常需要将授权和批准、记录和报告以及资产保管的职责作出分离。例如，负责对客户授予信用额度的经理不应当具有维护应收账款记录或处理现金收据的职责。当职责分离不能实施时，管理层通常选择和建立替代性的控制（例如，检查性控制）。存在职责分离问题应该被确定为缺陷，并评价其严重程度。 记录每个角色所执行的职责（特别是当一名人员执行多个职责时）。在执行职责的角色中填入“X”。如果某个角色（或人员）在一个或多个重要交易过程中履行多项职责，那么通常出现职务分离问题。下面的示例中显示了两种文档记录供参考。
B14: 授权或批准 | C14: 确保交易是有效的（即，存在真实的经济实质并符合被审计单位的政策）。授权通常采取高层管理人员批准的形式以验证交易是否有效。
B17: 记录或报告 | C17: 记录： 在会计系统记录交易信息 报告： 从总账获取交易信息，并反映在被审计单位的财务报表
B20: 资产保管 | C20: 资产保管一般是指妥善保管被审计单位的资产（比如，持有证券和接收或存入现金、票据）
B23: 示例
B26: 人员 (角色) | C26: 授权或批准 | D26: 记录或报告 | E26: 资产保管 | F26: 存在职责分离问题? | G26: 识别出缺陷 ? | H26: 描述职责分离问题或已作出的重要判断(如有)
B28: 业务流程 XYZ
B29: 销售人员 | C29: - | D29: X | E29: - | F29: =IF(COUNTIF(C29:E29,Data!$A$3)>1,Data!$B$2,Data!$B$3) -> 否
B30: 仓储主管 | C30: X | D30: - | E30: - | F30: =IF(COUNTIF(C30:E30,Data!$A$3)>1,Data!$B$2,Data!$B$3) -> 否
B31: 仓储人员 | C31: - | D31: X | E31: X | F31: =IF(COUNTIF(C31:E31,Data!$A$3)>1,Data!$B$2,Data!$B$3) -> 是 | G31: 是 | H31: 详述描述职责分离问题和是否识别出缺陷。
B33: 业务流程 XYZ
B35: 销售人员 | C35: =IF(COUNTIF(C36:C36,Data!$A$3)>0,"X","-") -> - | D35: =IF(COUNTIF(D36:D36,Data!$A$3)>0,"X","-") -> X | E35: =IF(COUNTIF(E36:E36,Data!$A$3)>0,"X","-") -> - | F35: =IF(COUNTIF(C35:E35,Data!$A$3)>1,Data!$B$2,Data!$B$3) -> 否
B36: 输入采购订单 | C36: - | D36: X | E36: -
B38: 仓储主管 | C38: =IF(COUNTIF(C39:C39,Data!$A$3)>0,"X","-") -> X | D38: =IF(COUNTIF(D39:D39,Data!$A$3)>0,"X","-") -> - | E38: =IF(COUNTIF(E39:E39,Data!$A$3)>0,"X","-") -> - | F38: =IF(COUNTIF(C38:E38,Data!$A$3)>1,Data!$B$2,Data!$B$3) -> 否
B39: 打印和分配采购订单给仓储人员 | C39: X | D39: - | E39: -
B41: 仓储人员 | C41: =IF(COUNTIF(C42:C44,Data!$A$3)>0,"X","-") -> - | D41: =IF(COUNTIF(D42:D44,Data!$A$3)>0,"X","-") -> X | E41: =IF(COUNTIF(E42:E44,Data!$A$3)>0,"X","-") -> X | F41: =IF(COUNTIF(C41:E41,Data!$A$3)>1,Data!$B$2,Data!$B$3) -> 是 | G41: 是 | H41: 详述描述职责分离问题和是否识别出缺陷。
B42: 按发货清单挑选物品并发送 | C42: - | D42: - | E42: X
B43: 按物品数量输入IT系统 | C43: - | D43: X | E43: -
B44: 打印发票并放入箱内等待发出 | C44: - | D44: X | E44: -

Sheet 示例 - 职责分离控制测试
B2: 客户名称：
B3: 项目名称： | J3: 编制人： | K3: 编制人： | M3: 索引号：XX
B4: 日期： | J4: 复核人： | K4: 复核人：
B6: 职责分离控制测试
B8: 控制 | C8: 控制编号 | D8: 控制描述 | E8: 信息系统控制目标 | F8: 财务报表认定 | G8: 自动/人工 | H8: 预防性/检查性 | I8: 频率 | J8: 测试步骤 | K8: 测试结果 | L8: 是否发现例外 | M8: 支持性文件
B9: 用户权限审核 | C9: REV-AC-03 | D9: 业务系统负责人定期对本部门员工的实际权限与标准核对，对不一致的权限设置进行跟进并作出相对应的处理。 | E9: 访问限制 | F9: 不使用 | G9: 手工依赖系统 | H9: 检查性 | I9: 每季 | J9: 1．询问相关负责人，了解定期审核程序； | K9: 询问：略 | L9: 未发现例外 | M9: ××公司系统安全管理制度财务系统职责分离权限矩阵问题发现清单再产权限变更申请
J10: 2．抽取两个季度的审核结果，与相关负责人讨论审核发现，获取并检查后续跟进和相关处理工作。 | K10: 检查：我们检查了6月及9月的审核文档，以及相关的27项与标准不符的后续跟进工作，并与业务系统负责人及相关人员所属的部门主管进行讨论。具体检查过程及发现：略
B11: …
B12: …

Sheet 指引 - 职责分离矩阵
B2: 说明：
B3: 针对注册会计师在实施信息系统应用控制——职责分离相关控制测试时可以考虑的要素和方面（即可能存在冲突的角色）进行说明。由于每家企业所实施的系统及其功能都有所区别，因此，以下举例不能列示所有注册会计师应当考虑的控制，而以下所列示的控制也不一定适用于每一项审计的具体情况。注册会计师在实务工作中需要根据企业的具体情况识别控制，并根据对风险的评估选取适当的样本规模进行测试。
B4: 其中，“X”表示不相容的职责
B8: ERP系统职责分离矩阵 | E8: 收入与应收 | N8: 采购与应付 | T8: 库存管理 | AC8: 财务会计 | AI8: 成本会计 | AK8: 项目管理 | AM8: 生产制造管理 | AO8: 设备维护
E9: 1 | F9: 2 | G9: 3 | H9: 4 | I9: 5 | J9: 6 | K9: 7 | L9: 8 | M9: 9 | N9: 10 | O9: 11 | P9: 12 | Q9: 13 | R9: 14 | S9: 15 | T9: 16 | U9: 17 | V9: 18 | W9: 19 | X9: 20 | Y9: 21 | Z9: 22 | AA9: 23 | AB9: 24 | AC9: 25 | AD9: 26 | AE9: 27 | AF9: 28 | AG9: 29 | AH9: 30 | AI9: 31 | AJ9: 32 | AK9: 33 | AL9: 34 | AM9: 35 | AN9: 36 | AO9: 37 | AP9: 38
B10: 模块 | C10: 序号 | D10: 业务活动 | E10: 维护客户主数据 | F10: 信用管理 | G10: 价格维护 | H10: 维护销售订单 | I10: 维护借/贷项申请单 | J10: 审批销售订单 | K10: 审批借/贷项申请单 | L10: 外向交货单 | M10: 销售发票 | N10: 维护供应商主数据 | O10: 维护采购订单 | P10: 审核采购订单 | Q10: 维护转储单/调拨单 | R10: 审批转储单/调拨单 | S10: 采购发票校验 | T10: 销售出库 | U10: 其他出库 | V10: 存货入库 | W10: 服务确认 | X10: 维护物料主数据 | Y10: 维护服务主数据 | Z10: 开关物料期间 | AA10: 录入存货差异结果 | AB10: 存货差异过账 | AC10: 会计科目主数据维护 | AD10: 财务专用供应商主数据维护 | AE10: 财务专用客户主数据维护 | AF10: 会计核算 | AG10: 稽核过账 | AH10: 总账管理 | AI10: 成本主数据维护 | AJ10: 成本核算 | AK10: 项目维护 | AL10: 项目审批 | AM10: 生产计划主数据维护 | AN10: 作业量确认 | AO10: 工单维护 | AP10: 工单审批
B11: 收入与应收 | C11: 1 | D11: 维护客户主数据 | E11: N | F11: X | H11: X | J11: X | K11: X | L11: X | M11: X | AF11: X | AG11: X | AH11: X | AJ11: X
C12: 2 | D12: 信用管理 | E12: X | F12: N | H12: X | I12: X | J12: X | K12: X | L12: X | M12: X | AF12: X | AG12: X | AH12: X | AJ12: X
C13: 3 | D13: 价格维护 | G13: N | H13: X | I13: X | J13: X | K13: X | L13: X | M13: X | AF13: X | AG13: X | AH13: X | AJ13: X
C14: 4 | D14: 维护销售订单 | E14: X | F14: X | G14: X | H14: N | J14: X | M14: X | T14: X | X14: X | AF14: X | AG14: X | AH14: X | AJ14: X
C15: 5 | D15: 维护借/贷项申请单 | F15: X | G15: X | I15: N | K15: X | M15: X | X15: X | AF15: X | AG15: X | AH15: X | AJ15: X
C16: 6 | D16: 审批销售订单 | E16: X | F16: X | G16: X | H16: X | J16: N | M16: X | T16: X | AF16: X | AG16: X | AH16: X | AJ16: X
C17: 7 | D17: 审批借/贷项申请单 | E17: X | F17: X | G17: X | I17: X | K17: N | M17: X | AF17: X | AG17: X | AH17: X | AJ17: X
C18: 8 | D18: 外向交货单 | E18: X | F18: X | G18: X | L18: N | M18: X | T18: X | AF18: X | AG18: X | AH18: X | AJ18: X
B19: 采购与应付 | C19: 9 | D19: 销售发票 | E19: X | F19: X | G19: X | H19: X | I19: X | J19: X | K19: X | L19: X | M19: N | T19: X | AH19: X
C20: 10 | D20: 维护供应商主数据 | N20: N | O20: X | P20: X | S20: X | AF20: X | AG20: X | AH20: X | AJ20: X
C21: 11 | D21: 维护采购订单 | N21: X | O21: N | P21: X | S21: X | T21: X | V21: X | W21: X | X21: X | Y21: X | AF21: X | AG21: X | AH21: X | AJ21: X
C22: 12 | D22: 审核采购订单 | N22: X | O22: X | P22: N | S22: X | T22: X | V22: X | W22: X | AF22: X | AG22: X | AH22: X | AJ22: X
C23: 13 | D23: 维护转储单/调拨单 | Q23: N | R23: X | U23: X | V23: X | X23: X | AF23: X | AG23: X | AH23: X | AJ23: X
C24: 14 | D24: 审批转储单/调拨单 | Q24: X | R24: N | U24: X | V24: X | AF24: X | AG24: X | AH24: X | AJ24: X
C25: 15 | D25: 采购发票校验 | N25: X | O25: X | P25: X | S25: N | T25: X | V25: X | W25: X | AH25: X
B26: 库存管理 | C26: 16 | D26: 销售出库 | H26: X | J26: X | L26: X | M26: X | O26: X | P26: X | S26: X | T26: N | X26: X | Z26: X | AB26: X | AF26: X | AG26: X | AH26: X | AJ26: X
C27: 17 | D27: 其他出库 | Q27: X | R27: X | U27: N | X27: X | Z27: X | AB27: X | AF27: X | AG27: X | AH27: X | AI27: X | AJ27: X | AK27: X | AL27: X | AM27: X | AO27: X | AP27: X
C28: 18 | D28: 存货入库 | O28: X | P28: X | Q28: X | R28: X | S28: X | V28: N | X28: X | Z28: X | AB28: X | AF28: X | AG28: X | AH28: X | AJ28: X
C29: 19 | D29: 服务确认 | O29: X | P29: X | S29: X | W29: N | Y29: X | Z29: X | AF29: X | AG29: X | AH29: X | AJ29: X | AO29: X | AP29: X
C30: 20 | D30: 维护物料主数据 | H30: X | I30: X | O30: X | Q30: X | T30: X | U30: X | V30: X | X30: N | AB30: X | AF30: X | AG30: X | AJ30: X
C31: 21 | D31: 维护服务主数据 | O31: X | W31: X | Y31: N | AF31: X | AG31: X | AJ31: X
C32: 22 | D32: 开关物料期间 | T32: X | U32: X | V32: X | W32: X | Z32: N | AB32: X | AF32: X | AG32: X | AJ32: X
C33: 23 | D33: 录入存货差异结果 | AA33: N | AB33: X | AF33: X | AG33: X | AH33: X | AJ33: X
C34: 24 | D34: 存货差异过账 | T34: X | U34: X | V34: X | X34: X | Z34: X | AA34: X | AB34: N | AF34: X | AG34: X | AH34: X | AJ34: X
B35: 财务会计 | C35: 25 | D35: 会计科目主数据维护 | AC35: N | AF35: X | AG35: X | AJ35: X
C36: 26 | D36: 财务专用供应商主数据维护 | AD36: N | AF36: X | AG36: X | AJ36: X
C37: 27 | D37: 财务专用客户主数据维护 | AE37: N | AF37: X | AG37: X | AJ37: X
C38: 28 | D38: 会计核算 | E38: X | F38: X | G38: X | H38: X | I38: X | J38: X | K38: X | L38: X | N38: X | O38: X | P38: X | Q38: X | R38: X | T38: X | U38: X | V38: X | W38: X | X38: X | Y38: X | Z38: X | AA38: X | AB38: X | AC38: X | AD38: X | AE38: X | AF38: N | AG38: X | AH38: X | AI38: X | AK38: X | AL38: X | AM38: X | AN38: X | AO38: X | AP38: X
C39: 29 | D39: 稽核过账 | E39: X | F39: X | G39: X | H39: X | I39: X | J39: X | K39: X | L39: X | N39: X | O39: X | P39: X | Q39: X | R39: X | T39: X | U39: X | V39: X | W39: X | X39: X | Y39: X | Z39: X | AA39: X | AB39: X | AC39: X | AD39: X | AE39: X | AF39: X | AG39: N | AH39: X | AI39: X | AJ39: X | AK39: X | AL39: X | AM39: X | AN39: X | AO39: X | AP39: X
C40: 30 | D40: 总账管理 | E40: X | F40: X | G40: X | H40: X | I40: X | J40: X | K40: X | L40: X | M40: X | N40: X | O40: X | P40: X | Q40: X | R40: X | S40: X | T40: X | U40: X | V40: X | W40: X | AA40: X | AB40: X | AF40: X | AG40: X | AH40: N | AJ40: X
B41: 成本会计 | C41: 31 | D41: 成本主数据维护 | U41: X | AF41: X | AG41: X | AI41: N | AJ41: X
C42: 32 | D42: 成本核算 | E42: X | F42: X | G42: X | H42: X | I42: X | J42: X | K42: X | L42: X | N42: X | O42: X | P42: X | Q42: X | R42: X | T42: X | U42: X | V42: X | W42: X | X42: X | Y42: X | Z42: X | AA42: X | AB42: X | AC42: X | AD42: X | AE42: X | AG42: X | AH42: X | AI42: X | AJ42: N | AK42: X | AL42: X | AM42: X | AN42: X | AO42: X | AP42: X
B43: 项目管理 | C43: 33 | D43: 项目维护 | T43: X | AF43: X | AG43: X | AJ43: X | AK43: N | AL43: X
C44: 34 | D44: 项目审批 | T44: X | AF44: X | AG44: X | AJ44: X | AK44: X | AL44: N
...

Sheet Data
A1: Procedure | B1: Yes No
A2: - | B2: 是
A3: X | B3: 否
