Workbook

Sheet 底稿目录
A1: 底稿开列时，可先在以下单元格填写有关内容，以便其他底稿引用有关数据：
A2: 被审计单位： | D2: 序号 | E2: 内容 | F2: 索引号 | G2: 备注
A3: 截止日：202X年12月31日 | D3: 1 | E3: 企业信用报告信息查询记录 | F3: E1-18
A4: 编制人： | D4: 2 | E4: 企业信用报告信息与账面核对记录 | F4: E1-19
A5: 编制日期： | D5: 3 | E5: 银行存款及其他货币资金应计利息测算 | F5: E1-20
A6: 复核人： | D6: 4 | E6: 银行存款截止测试表 | F6: E1-21
A7: 复核日期： | D7: 5 | E7: 其他货币资金截止测试表 | F7: E1-22
D8: 6 | E8: 货币资金收支检查表 | F8: E1-23
D9: 7 | E9: 自定义底稿 | F9: E1-24
D10: 8 | E10: 自定义底稿 | F10: E1-25

Sheet 企业信用报告信息查询记录E1-18
A1: 致同会计师事务所
A2: 企业信用报告查询记录
A3: =底稿目录!A2 -> 被审计单位： | B3: =底稿目录!A4 -> 编制人： | D3: =底稿目录!A5 -> 编制日期： | F3: 索引号： | G3: =底稿目录!F3 -> E1-18
A4: =底稿目录!A3 -> 截止日：202X年12月31日 | B4: =底稿目录!A6 -> 复核人： | D4: =底稿目录!A7 -> 复核日期： | F4: 页次：
A5: 我们于 年 月 日到银行（或由被审计单位XX下载并打印征信报告，观察并记录被审计单位具有操作权限人员的查询、打印过程）对企业的信用情况进行查询，查询情况如下：
A6: 一、参加人员：
A7: 客户人员： | C7: 审计人员： | E7: 银行协助查询人员（如有）：
A8: 二、报告时间： | B8: 年 月 日
A9: 三、借款人名称： | B9: 征信人代码： | E9: 贷款卡编码：
A10: 四、查询情况：在银行计算机上输入贷款卡卡号和密码（或由企业具有操作权限的人员登录网银）后，进入银行信贷咨询系统，查询了以下主要内容：
A11: 1、征信人概况查询： | C11: （打印件附后）
A12: 2、征信人财务信息： | C12: （打印件附后）
A13: 3、信贷信息查询： | C13: （打印件附后）
A14: 未结清的信贷信息中：保函、承兑汇票及票据贴现（未到期的票据贴现）已与企业账面核对一致。
A15: 六、查询结果：
A16: 从贷款卡上信息表明企业的信贷信息正常。
A17: 征信报告信息附后，索引号：
A19: 被审计单位参加人员签字：
A20: 审计人员签字：

Sheet 企业信用报告信息与账面核对记录E1-19
A1: 致同会计师事务所
A2: 企业信用报告信息与账面核对记录
A3: =底稿目录!A2 -> 被审计单位： | D3: =底稿目录!A4 -> 编制人： | F3: =底稿目录!A5 -> 编制日期： | H3: 索引号： | I3: =底稿目录!F4 -> E1-19
A4: =底稿目录!A3 -> 截止日：202X年12月31日 | D4: =底稿目录!A6 -> 复核人： | F4: =底稿目录!A7 -> 复核日期： | H4: 页次：
A5: 一、审计目标：
A6: 核对征信报告信息与账面记录是否一致；借款、银行承兑汇票、信用证等完整性。
A7: 二、审计过程：
A8: （一）注册资本及主要出资人信息
A9: 征信报告信息 | C9: 企业账面 | E9: 核对 | F9: 不一致原因 | G9: 备注
A10: 出资方 | B10: 出资比例 | C10: 出资比例 | D10: 出资比例
A16: （二）征信报告信息与账面核对记录
A17: 类别 | B17: 中长期借款 | C17: 短期借款 | D17: 银行承兑汇票 | E17: 信用证 | F17: 银行保函 | G17: 贴现 | H17: … | I17: 备注
A18: 征信报告信息
A19: 账面记录
A20: 差异 | B20: =B18-B19 -> 0 | C20: =C18-C19 -> 0 | D20: =D18-D19 -> 0 | E20: =E18-E19 -> 0 | F20: =F18-F19 -> 0 | G20: =G18-G19 -> 0 | H20: =H18-H19 -> 0
A22: （三）不一致事项账面差异调节
A23: 类别 | B23: 信用报告打印日未结清业务总额 ① | C23: 加上：资产负债表日至信用报告日已经还清贷款类金额 ② | D23: 减去：资产负债表日至信用报告日新增贷款类业务 ③ | E23: 资产负债表日信用报告贷款类业务金额【④=①+②-③】 | F23: 总账科目名称 | G23: 总账科目金额⑤ | H23: 差异 ⑥=④-⑤ | I23: 差异原因
A24: 短期借款 | E24: =B24+C24-D24 -> 0 | H24: =E24-G24 -> 0
A25: 中长期借款 | E25: =B25+C25-D25 -> 0 | H25: =E25-G25 -> 0
A26: 循环透支 | E26: =B26+C26-D26 -> 0 | H26: =E26-G26 -> 0
A27: 银行承兑汇票 | E27: =B27+C27-D27 -> 0 | H27: =E27-G27 -> 0
A28: 信用证 | E28: =B28+C28-D28 -> 0 | H28: =E28-G28 -> 0
A29: 银行保函 | E29: =B29+C29-D29 -> 0 | H29: =E29-G29 -> 0
A30: 贴现 | E30: =B30+C30-D30 -> 0 | H30: =E30-G30 -> 0
A31: … | E31: =B31+C31-D31 -> 0 | H31: =E31-G31 -> 0
A32: 审计说明：
A33: 1.短期借款与企业信用报告详细核对见短期借款底稿<L1-4>；
A34: 2.中长期借款与企业信用报告详细核对见长期借款底稿<L3-4>；
A36: （四）担保事项
A37: 征信报告截图
A44: 担保事项应与报告披露核对一致
A46: （五）关联关系企业
A47: 征信报告关联方名称 | B47: 征信报告中关联关系 | C47: 是否纳入被审计单位关联方清单 | D47: 披露的关联关系
A50: ……
A52: 三、审计说明：
A54: 四、审计结论：
A56: 提示：
A57: 1.如存在未披露的担保情况，需进一步询问上市公司管理层、其他责任人员和相关人员、查阅相关会议纪要和法律信函、复核相关费用账户记录、与外部法律顾问进行直接沟通、检查公章管理及使用情况等，必要时还应通过相关查询渠道（如中国裁判文书网等），查询相关法院公告信息。
A58: 2.保持职业怀疑，关注企业信用报告的真实性和完整性，充分考虑其局限性，如存在银行未及时、完整、准确填列有关信用信息，上市公司利用离岸账户等特殊方式。

Sheet 银行存款及其他货币资金应计利息测算E1-20
A1: 致同会计师事务所
A2: 银行存款及其他货币资金应计利息测算表
A3: =底稿目录!A2 -> 被审计单位： | D3: =底稿目录!A4 -> 编制人： | H3: =底稿目录!A5 -> 编制日期： | L3: 索引号： | M3: =底稿目录!F5 -> E1-20
A4: =底稿目录!A3 -> 截止日：202X年12月31日 | D4: =底稿目录!A6 -> 复核人： | H4: =底稿目录!A7 -> 复核日期： | L4: 页 次：
A5: 一、审计目标:
A6: 1.资产负债表中记录的货币资金是存在的，且已记录于恰当的账户；2.所有应当记录的货币资金均已记录，所有应当包括在财务报表中的相关披露均已包括；
A7: 3.货币资金以恰当的金额包括在财务报表中，与之相关的计价或分摊调整已恰当记录，相关披露已得到恰当计量和描述。
A8: 二、审计过程：
A9: 开户银行 | B9: 银行账号 | C9: 账户性质/主要用途 | D9: 原币币种 | E9: 原币金额 | F9: 结息日 | G9: 截止日 | H9: 应计利息天数 | I9: 日利率 | J9: 应计利息（原币金额） | K9: 折算汇率 | L9: 应计利息（人民币金额） | M9: 备注
J10: =E10*H10*I10 -> 0 | L10: =J10*K10 -> 0
J11: =E11*H11*I11 -> 0 | L11: =J11*K11 -> 0
J12: =E12*H12*I12 -> 0 | L12: =J12*K12 -> 0
J13: =E13*H13*I13 -> 0 | L13: =J13*K13 -> 0
J14: =E14*H14*I14 -> 0 | L14: =J14*K14 -> 0
J15: =E15*H15*I15 -> 0 | L15: =J15*K15 -> 0
J16: =E16*H16*I16 -> 0 | L16: =J16*K16 -> 0
J17: =E17*H17*I17 -> 0 | L17: =J17*K17 -> 0
J18: =E18*H18*I18 -> 0 | L18: =J18*K18 -> 0
J19: =E19*H19*I19 -> 0 | L19: =J19*K19 -> 0
J20: =E20*H20*I20 -> 0 | L20: =J20*K20 -> 0
J21: =E21*H21*I21 -> 0 | L21: =J21*K21 -> 0
... J24: =E24*H24*I24 -> 0 | L24: =J24*K24 -> 0
A25: 合 计 | L25: =SUM(L10:L24) -> 0
A27: 三、审计说明：
A29: 四、审计结论：
A31: 提示：
A32: 本表为应计提尚未结算利息，结息日至资产负债表日按存款计算应计提利息

Sheet 银行存款截止测试表E1-21
A1: 致同会计师事务所
A2: 银行存款截止测试表
A3: =底稿目录!A2 -> 被审计单位： | C3: =底稿目录!A4 -> 编制人： | D3: =底稿目录!A5 -> 编制日期： | G3: 索引号： | H3: =底稿目录!F6 -> E1-21
A4: =底稿目录!A3 -> 截止日：202X年12月31日 | C4: =底稿目录!A6 -> 复核人： | D4: =底稿目录!A7 -> 复核日期： | G4: 页 次：
A5: 一、审计目标
A6: 1.资产负债表中记录的货币资金是存在的，且已记录于恰当的账户；
A7: 2.所有应当记录的货币资金均已记录，所有应当包括在财务报表中的相关披露均已包括。
A8: 二、审计过程
A9: 从银行日记账中抽取资产负债表日前（ ）天、后（ ）天，且金额大于 元的记账凭证，与收付款凭单以及其他原始凭单核对
A10: 提示：如果存在跨期舞弊风险或者所检查样本中发现有跨期的，应扩大测试期间和样本，甚至可以考虑将截止测试期间延长至审计报告日。同时考虑是否存在内控缺陷。
A11: 测试凭证内容 | F11: 收付款凭单日期 | G11: 其他原始凭单日期 | H11: 是否跨期
A12: 日期 | B12: 凭证编号 | C12: 业务内容 | D12: 借方金额 | E12: 贷方金额
A30: ——————截止日期：202X年12月31日——————
A49: 三、审计说明：
A51: 四、审计结论：

Sheet 其他货币资金截止测试表E1-22
A1: 致同会计师事务所
A2: 其他货币资金截止测试表
A3: =底稿目录!A2 -> 被审计单位： | C3: =底稿目录!A4 -> 编制人： | D3: =底稿目录!A5 -> 编制日期： | G3: 索引号： | H3: =底稿目录!F7 -> E1-22
A4: =底稿目录!A3 -> 截止日：202X年12月31日 | C4: =底稿目录!A6 -> 复核人： | D4: =底稿目录!A7 -> 复核日期： | G4: 页 次：
A5: 一、审计目标
A6: 1.资产负债表中记录的货币资金是存在的，且已记录于恰当的账户；
A7: 2.所有应当记录的货币资金均已记录，所有应当包括在财务报表中的相关披露均已包括。
A8: 二、审计过程
A9: 从其他货币资金明细账中抽取资产负债表日前（ ）天、后（ ）天，且金额大于 元的记账凭证，与收付款凭单以及其他原始凭单核对
A10: 提示：如果存在跨期舞弊风险或者所检查样本中发现有跨期的，应扩大测试期间和样本，甚至可以考虑将截止测试期间延长至审计报告日。同时考虑是否存在内控缺陷。
A11: 测试凭证内容 | F11: 收付款凭单日期 | G11: 其他原始凭单日期 | H11: 是否跨期
A12: 日期 | B12: 凭证编号 | C12: 业务内容 | D12: 借方金额 | E12: 贷方金额
A28: ——————截止日期：202X年12月31日——————
A48: 三、审计说明：
A50: 四、审计结论：

Sheet 货币资金收支检查情况表E1-23
A1: 致同会计师事务所
A2: 货币资金收支检查情况表
A3: =底稿目录!A2 -> 被审计单位： | E3: =底稿目录!A4 -> 编制人： | J3: =底稿目录!A5 -> 编制日期： | O3: 索引号： | P3: =底稿目录!F8 -> E1-23
A4: =底稿目录!A3 -> 截止日：202X年12月31日 | E4: =底稿目录!A6 -> 复核人： | J4: =底稿目录!A7 -> 复核日期： | O4: 页 次：
A5: 一、测试目标：
A6: 1.资产负债表中记录的货币资金是存在的，且已经记录在恰当的账户中；2.记录的货币资金由被审计单位拥有或控制；
A7: 3.货币资金以恰当的金额包括在财务报表中，与之相关的计价或分摊调整已恰当记录，相关披露已得到恰当计量和描述
A8: 二、样本选取标准与规模：
A9: 测试总体： | B9: 如货币资金借方发生额所有凭证共XX笔金额XX、贷方发生额所有凭证共XX笔金额XX | H9: 特定样本： | I9: XX金额以上（大额）、关联方/关联交易形成的款项、XX异常款项全部测试，共XX笔；
A10: 抽样总体： | B10: 测试总体扣除特定样本以外的样本，共XX笔、金额XX | H10: 确定的抽样样本量： | J10: 抽取XX笔 | K10: （如果使用了样本计算器计算样本量，样本量计算过程见<XX>底稿）
A11: 抽样方法： | B11: 随机选样/系统选样/货币单元抽样/随意选样（非统计抽样适用） | H11: 抽样过程： | I11: 使用IDEA（XX抽样工具）选择XX数量、金额XX的样本进行测试，抽样工具中的样本选择过程和结果见<XX>底稿
A12: 三、测试：
A13: 收入测试内容说明：1.原始凭证是否齐全；2.收款凭证记录信息与银行回单中金额、付款方是否相符；3.账务处理是否正确；4.是否记录于恰当的会计期间；5.关注是否与生产经营无关；6.关注收款时间是否异常（节假日收款）；7.……
A14: 支出测试内容说明：1.原始凭证是否齐全；2.付款凭证记录信息与银行回单金额、收款方是否相符；3.付款的授权审批手续是否齐全、签章完整；4.原始凭证具有合法的发票或依据；5.原始凭证的内容与付款凭证业务内容是否一致；6.账务处理是否正确；7.是否记录于恰当的会计期间；8.关注是否与生产经营无关；9.……
A15: 1.本期借方金额检查
A16: 所属科目 | B16: 日期 | C16: 凭证编号 | D16: 业务内容 | E16: 对方科目 | F16: 对方明细科目 | G16: 借方金额 | H16: 银行回单 | K16: 其他支持性文件名称 | N16: 索引号 | O16: 是否异常
H17: 日期 | I17: 付款方 | J17: 金额
A18: 现金
A19: 现金
A20: ……
A21: 银行存款
A22: 银行存款
A23: 银行存款
A24: 银行存款
A25: 银行存款
A26: 银行存款
A27: 银行存款
A28: 银行存款
A29: 银行存款
... A39: ……
A40: 合计 | G40: =SUM(G18:G39) -> 0 | J40: =SUM(J18:J39) -> 0
A41: 2.本期贷方金额检查
A42: 所属科目 | B42: 日期 | C42: 凭证编号 | D42: 业务内容 | E42: 对方科目 | F42: 对方明细科目 | G42: 贷方金额 | H42: 银行回单 | K42: 付款审批单 | M42: 其他支持性文件名称 | O42: 索引号 | P42: 是否异常
H43: 日期 | I43: 收款方 | J43: 金额 | K43: 日期/编号 | L43: 是否经过恰当审批
A44: 现金
A45: 现金
A46: ……
A47: 银行存款
A48: 银行存款
A49: 银行存款
...
