Workbook

Sheet 底稿目录
A1: 底稿开列时，可先在以下单元格填写有关内容，以便其他底稿引用有关数据：
A2: 被审计单位： | D2: 序号 | E2: 内容 | F2: 索引号
A3: 截止日：202X年12月31日 | D3: 1 | E3: 货币资金实质性程序表 | F3: E1A
A4: 编制人： | D4: 2 | E4: 货币资金审定表 | F4: E1-1
A5: 编制日期： | D5: 3 | E5: 附注披露信息(上市公司) | G5: 无需打印
A6: 复核人： | D6: 4 | E6: 附注披露信息(国企) | G6: 无需打印
A7: 复核日期： | D7: 5 | E7: 现金明细表 | F7: E1-2
D8: 6 | E8: 银行存款及其他货币资金明细表（仅人民币） | F8: E1-3
A9: 关于工作底稿与审计程序索引号对应的说明 | D9: 7 | E9: 银行存款及其他货币资金明细表（人民币及外币） | F9: E1-3
A10: 1.编制的审计工作底稿应与审计程序对应。审计项目组应根据被审计单位实际情况和风险评估情况在实质性程序表中裁剪、修改或增加审计程序，根据实际执行的审计程序完成相应审计工作底稿，编制的工作底稿中应按自然顺序依次编制索引号，并通过唯一的索引号将与实质性程序表中的程序对应关联（即将工作底稿的索引号填入实质性程序表中的底稿索引号列）。 | D10: 8 | E10: 数字货币明细表 | F10: E1-4
D11: 9 | E11: 调整分录汇总表 | F11: E1-5
D12: 10 | E12: 银行存款余额调节表 | F12: E1-6
D13: 11 | E13: 库存现金（人民币）盘点表 | F13: E1-7
A14: 2.获取的支持性证据应与审计底稿或程序对应。审计项目组在完成底稿时获取的支持性证据应根据底稿索引号编制下一级按自然顺序排序的索引号（如D1-2-1、D1-2-2、……），并在底稿中说明引用的支持性证据、关联索引号。 | D14: 12 | E14: 库存现金（外币）盘点表 | F14: E1-8
D15: 13 | E15: 银行存单盘点表 | F15: E1-9
D16: 14 | E16: 已开立银行结算账户清单核对表 | F16: E1-10
A17: 3.工作底稿索引号的编码规则：实质性程序索引号按循环从“D”到“N”,循环内账户以顺序号排列，模板中底稿索引号按账户顺序+自然数顺序（即模板中索引号按二级自然顺序排列，如D1-1、D1-2、D1-3、……D1-N）。 | D17: 15 | E17: 银行账户情况承诺 | F17: E1-11
D18: 16 | E18: 自定义底稿 | F18: E1-12
D19: 17 | E19: 自定义底稿 | F19: E1-13

Sheet 货币资金实质性程序表E1A
A1: 致同会计师事务所
A2: 货币资金实质性程序表
A3: =底稿目录!A2 -> 被审计单位： | D3: =底稿目录!A4 -> 编制人： | G3: =底稿目录!A5 -> 编制日期： | I3: 索引号： | J3: =底稿目录!F3 -> E1A
A4: =底稿目录!A3 -> 截止日：202X年12月31日 | D4: =底稿目录!A6 -> 复核人： | G4: =底稿目录!A7 -> 复核日期： | I4: 页 次：
A5: 一、本账户涉及的科目
A6: 货币资金
A7: 二、审计目标与认定对应关系
A8: 审计目标 | H8: 财务报表的认定
A9: A.资产负债表中记录的货币资金是存在的，且已记录于恰当的账户 | H9: 存在
A10: B.所有应当记录的货币资金均已记录，所有应当包括在财务报表中的相关披露均已包括 | H10: 完整性
A11: C.记录的货币资金由被审计单位拥有或控制 | H11: 权利和义务
A12: D.货币资金以恰当的金额包括在财务报表中，与之相关的计价或分摊调整已恰当记录，相关披露已得到恰当计量和描述 | H12: 准确性、计价和分摊
A13: E.货币资金已被恰当地汇总或分解且表述清楚，相关披露在按照企业会计准则的编制基础下是相关的、可理解的 | H13: 列报
A14: 三、计划实施的实质性程序
A15: 序号 | B15: 对应LEAP程序 | C15: 审计程序 | D15: 程序分类 | E15: 财务报表的认定 | J15: 底稿索引号
E16: 存在 | F16: 完整性 | G16: 权利和义务 | H16: 准确性、计价和分摊 | I16: 列报 | K16: 根据被审计单位实际情况和风险评估情况裁剪、修改或增加审计程序
A17: （一） | B17: 常规程序 | C17: 获取或编制现金、银行存款、其他货币资金、数字货币的明细表,完成以下工作，并编制审定表 (1)复核加计是否正确，与总账、明细账合计数核对是否相符，期初余额与上期审定期末余额是否相符； (2)检查外币现金、银行存款、其他货币资金折合记账本位币所采用的折算汇率是否正确，折算差额是否已按规定进行会计处理。 | D17: 常规★ | E17: √ | F17: √ | H17: √ | J17: E1-1 /E1-2 /E1-3 //E1-4
A18: （二） | B18: IPE程序 | C18: 在使用手工编制、自定义信息报告、系统生成的非固定格式报告等由被审计单位生成的信息时，测试有关信息准确性和完整性，并考虑针对编制和维护由被审计单位生成的信息的相关控制实施控制测试，以评价该信息是否能够为实现审计目的提供基础。 | D18: 常规★ | F18: √ | H18: √ | J18: T1 /E0-2 / | K18: 可参见《审计手册》4.2.6，由被审计单位生成的信息可能是由系统生成的、或手工编制的、或二者兼而有之的方式生成的。例如，由被审计单位生成的信息可能包括： • 不涉及自定义的、由系统生成的报告（如，固定格式报告）； • 可能通过人工自定义的、由系统生成的报告，例如，（计算机）查询信息或特别定制的报告； • 手工编制的信息，例如，汇总信息的电子表格或用以支持分配、计算以及调节的电子表格； • 其他系统生成或手工编制的信息，例如，由被审计单位编制的客户发票； • 通过影印、拍摄、扫描或其他方式转换成电子形式的文件记录。
A19: （三） | B19: 期初余额 | C19: 对期初余额的审计，取得现金、银行存款、其他货币资金、数字货币期初余额明细表复核加计是否正确，与总账、明细账合计数是否相符，外币折算是否正确，获取上期末银行对账单和调节表与账面金额核对、查明大额及不正常未达账项，函证期初银行存款/其他货币资金/数字货币以及其他必要追加的审计程序。（适用于首次承接） | D19: 备选 | E19: √ | F19: √ | G19: √ | H19: √ | K19: 由被审计单位生成的信息不包括： • 总分类账或明细分类账、试算平衡表、或经审计的财务报表； • 第三方（除了服务机构）的报表或报告，例如，原始银行对账单，或函证的回函； • 外部数据（例如，第三方发布的数据，如，定价来源）。
A20: （四） | B20: 应对措施-实质性/非实质性分析程序 | C20: 分析货币资金构成及重要指标： (1)分析货币资金、其他货币资金构成，结构比以及变动情况，了解被审计单位融资政策等，分析其变动原因； (2)分析银行存款在总资产比重、定期存款占货币资金比重等重要指标的本期与前期变化情况； (3)分析货币资金余额、定期存款余额占贷款余额的比例，关注是否存在存贷双高异常情况； | D20: 常规★ | E20: √ | H20: √ | J20: E1-14
A21: （五） | C21: 库存现金
A22: 1 | B22: 常规程序 | C22: 监盘库存现金： (l)选择恰当的日期突击监盘现金，对被审计单位库存现金存放在两处或两处以上的，应同时实施监盘，留存所有盘点人员签字的现金盘点表原件； (2)将盘点金额与现金日记账余额进行核对，如有差异，应要求被审计单位查明原因并作适当调整； (3)在非资产负债表日进行盘点时，应调整至资产负债表日的金额。 (4)若有充抵库存现金的借条、未提现支票、未作报销的原始凭证，在盘点表中注明，如有必要应作调整。 | D22: 常规★ | E22: √ | F22: √ | G22: √ | H22: √ | J22: E1-7 /E1-8
A23: 2 | B23: 应对措施-检查 | C23: 如存在大额现金交易或余额，考虑分析现金交易的成因，判断其合理性，增加大额现金检查、截止测试、舞弊应对等其他审计程序 | D23: IPO/上市/新三板/重组/舞弊应对 | J23: E1-26A
A24: （六） | C24: 银行存款、其他货币资金
A25: 1 | B25: 应对措施-检查 | C25: 获取银行存款/其他货币资金对账单、银行存款/其他货币资金余额调节表与账面金额进行核对，查明大额及不正常未达账项，结合期后回款（付款）情况验证银行存款余额调节表项目，判断其是否为调整事项；对于长期未达账项，检查是否存在记账差错、挪用资金等事项； | D25: 常规★ | E25: √ | F25: √ | H25: √ | J25: E1-3 /E1-6
A26: 2 | B26: 应对措施-检查 | C26: 如存在财务公司存款，取得财务公司与企业签订的金融服务协议，考虑财务公司信用风险。对于首次将资金存放于财务公司的，必要时取得企业对财务公司出具的风险评估报告；必要时后续期间取得业对财务公司出具的风险持续评估报告。 | D26: 备选 | E26: √ | H26: √
A27: 3 | B27: 常规程序 | C27: 监盘并检查开户证实书或定期存单，编制银行存单盘点表，检查是否与账面记录金额一致（包括核对存款人、账号、期间、截止日、计息等），是否被质押或担保等限制使用，是否为被审计单位所有： （1）对未质押的定期存款，应检查开户证实书原件或定期存单原件； （2）对已质押的定期存款，应检查质押回单等，并与相应的质押合同核对，同时关注定期存单对应的质押借款有无入账、质押事项逾期的关注相关质权是否已被行使； （3）对审计外勤工作结束日前已提取的定期存款，应核对相应的兑付凭证、银行对账单等。 | D27: 常规★ | E27: √ | G27: √ | J27: E1-9
A28: 4 | B28: 常规程序 | C28: 询问办理货币资金业务的相关人员（如出纳），了解银行账户的开立、使用、注销等情况。获取本期所有（如包括本期沿用、注销、余额为零的）银行账户的清单，必要时亲自到人民银行或基本存款账户开户行查询并打印《已开立银行结算账户清单》，与企业账面账户情况进行核对，检查被审计单位银行账户的完整性，分析企业开户目的、账户是否合理。必要时获取被审计单位已将全部银行存款账户信息提供给注册会计师的书面声明。 | D28: 常规★ | E28: √ | F28: √ | G28: √ | J28: E1-10 /E1-11 | K28: IPO/上市/新三板/重组/对银行账账户存在疑虑时，应直接完成底稿<E1-29>
A29: 5 | B29: 应对措施-函证 | C29: 对银行存款（包括零余额账户和在本期内注销的账户）、其他货币资金、数字货币、借款及与金融机构往来/交易等其他重要信息实施函证程序： （1）以积极方式对银行存款、其他货币资金、借款等进行函证，设计询证函、发函前核实被函证单位信息； （2）注册会计师独立收发询证函； （3）编制函证结果汇总表，检查发函、回函物流信息和轨迹、比对回函印章和签字等以核实回函的真实性，检查回函是否相符，对不符事项查明原因确定是否存在错报或舞弊； （4）如果未收到回函，应当考虑与被询证者联系，要求对方作出回应或再次寄发询证函； （5）如果管理层不允许寄发询证函的，询问管理层不允许寄发的原因，是否为审计准则规定的可以不执行银行函证程序的范围； （6）如果管理层不允许寄发询证函的原因不合理、再次发函未收到回函、或者认为回函不可靠等，评价对评估的重大错报风险（包括舞弊风险）的影响，考虑与治理层进行沟通，并确定其对审计工作和审计意见的影响。 | D29: 常规★ | E29: √ | F29: √ | G29: √ | H29: √ | J29: E0
A30: 6 | B30: 应对措施-实质性/非实质性分析程序 | C30: 计算银行存款、其他货币资金累计余额应收利息收入，结合财务费用和投资收益审计，分析利息收入的合理性，关注银行存款是否真实存在、是否存在高息资金拆借、是否存在体外资金循环等情形。 | D30: 常规★ | E30: √ | F30: √ | H30: √ | J30: E1-15
A31: 7 | B31: 应对措施-检查 | C31: 获取企业信用报告（中国人民银行征信中心或开户行），打印全部信息(详细版)，核对企业基本信息是否一致，借款、质押、抵押及其他担保等信息是否与账面记录和披露一致。如果不一致查明原因，必要时查阅相关会议纪要和法律信函、复核相关费用账户记录、与外部法律顾问进行直接沟通、检查公章管理及使用情况等检查是否存在未披露的担保。 | D31: 常规★ | E31: √ | G31: √ | J31: E1-14 /E1-15
A32: 8 | B32: 应对措施-检查 | C32: 测算银行存款及其他货币资金应计利息是否正确 | D32: 备选 | E32: √ | F32: √ | H32: √ | J32: E1-18
A33: 9 | B33: 应对措施-检查 | C33: 实施银行存款、其他货币资金截止测试，抽查资产负债表日前后若干天一定金额以上银行存款收支凭证进行检查，如果跨期收支事项，考虑是否应进行调整。 | D33: 常规★ | E33: √ | F33: √ | J33: E1-20 /E1-21
A34: 10 | B34: 应对措施-检查 | C34: 选取样本检查银行存款、其他货币资金收支的银行回单等原始凭证，检查原始凭证是否齐全，记账凭证与原始凭证是否相符，账务处理是否正确，是否记录于恰当的会计期间等项内容；必要时核查大额货币资金流出和流入的业务背景，如有与被审计单位生产经营无关的收支事项，应查明原因并作相应的记录。 | D34: 常规★ | E34: √ | G34: √ | H34: √ | J34: E1-23
A35: 11 | B35: 常规程序 | C35: 保证金存款、存出投资款、第三方支付平台、信用卡的其他货币资金： （1）对于保证金存款，检查开立银行承兑汇票的协议或银行授信协议等，将保证金金额与相应的交易进行核对，检查保证金与相关债务的比例和合同约定是否一致； （2）对于存出投资款，检查资金流向，获取董事会决议等批准文件、开户资料、投资协议等； （3）因互联网支付留存于第三方支付平台的资金。获取第三方支付平台发生额及余额明细，并与账面记录进行核对，检查大额交易；向第三方平台支付账户函证； （4）对于信用卡存款，若信用卡持有人是被审计单位职员，应取得该职员提供的确认书，并应考虑进行调整 | D35: 备选 | E35: √ | F35: √ | H35: √
A36: 12 | B36: 应对措施-函证 | C36: 资金池业务： （1）了解被审计单位与银行账户有关的内部控制和操作规程，询问被审计单位资金管理人员，检查与关联方往来、银行函证等，了解是否存在资金池业务； （2）获取资金池协议、股东大会或根据其有效公司规章规定的有权机关同意加入协议的决议等文件，关注相关协议签订的授权审批情况； （3）了解资金集中方式、相关账户的余额显示模式，关注账户支付控制及其变更的设定等重要内容； （4）函证拨入、拨出单位和拨入/拨出余额，在可行的情况下，可以同时函证可用余额；必要时，关注函证基准日后资金池账户之间的资金划拨，防止被审计单位为应付注册会计师的函证程序而突击划转资金； （5）关注被审计单位是否将资金池资金按照企业会计准则的要求在会计报表中予以恰当列报。 | D36: 备选 | E36: √ | F36: √ | G36: √ | I36: √
A37: 13 | B37: 常规程序 | C37: 关注是否存在质押、冻结等对变现有限制或存在境外的款项。是否已作必要的调整和披露 | D37: 常规★ | G37: √ | I37: √ | J37: E1-3 /E0
A38: 14 | B38: 常规程序 | C38: 对不能随时用于支付等不符合现金及现金等价物条件的银行存款、其他货币资金在审计工作底稿中予以列明，考虑对现金流量表的影响 | D38: 常规★ | I38: √ | J38: A1-1/A1-15 /A1-16
A39: 15 | B39: 应对措施-会计估计 | C39: 关注在金融机构存放的超过保险储蓄额的存款，核实持有此类存款的金融机构财务状况的稳定性，以保证其能够履行义务，确定货币资金是否减值（如兑付风险）。 | D39: 备选 | G39: √
A40: （七） | C40: 其他
...

Sheet 附注披露信息(上市公司)
A1: 致同会计师事务所
A2: 货币资金附注披露信息（上市公司）
A3: =底稿目录!A2 -> 被审计单位： | C3: =底稿目录!A4 -> 编制人： | E3: =底稿目录!A5 -> 编制日期： | G3: 索引号：
A4: =底稿目录!A3 -> 截止日：202X年12月31日 | C4: =底稿目录!A6 -> 复核人： | E4: =底稿目录!A7 -> 复核日期： | G4: 页次：
A6: 货币资金
A7: 项 目 | B7: 期末数 | C7: 期初数
A8: 库存现金 | B8: ='货币资金审定表E1-1'!G7 -> 0 | C8: ='货币资金审定表E1-1'!D7 -> 0
A9: 银行存款 | B9: ='货币资金审定表E1-1'!G10 -> 0 | C9: ='货币资金审定表E1-1'!D10 -> 0
A10: 存放财务公司款项 | B10: ='货币资金审定表E1-1'!G9 -> 0 | C10: ='货币资金审定表E1-1'!D9 -> 0
A11: 其他货币资金 | B11: ='货币资金审定表E1-1'!G11 -> 0 | C11: ='货币资金审定表E1-1'!D11 -> 0
A12: 存款应计利息 | B12: ='货币资金审定表E1-1'!G14+'货币资金审定表E1-1'!G15+'货币资金审定表E1-1'!G16 -> 0 | C12: ='货币资金审定表E1-1'!D14+'货币资金审定表E1-1'!D15+'货币资金审定表E1-1'!D16 -> 0
A13: 数字货币
A14: 合计 | B14: =SUM(B8:B13) -> 0 | C14: =SUM(C8:C13) -> 0
A15: 其中：存放在境外的款项总额
B16: =B14-D62 -> 0 | C16: =C14-G62 -> 0
A17: （提示： （1）截止2023年12月31日，人民币汇率中间价：美元7.0827（6.9646）、港币0.90622（0.89327）、英镑9.0411（8.3941）、100日元5.0213（5.2358）、欧元7.8592（7.4229）。 （2）根据《企业会计准则解释第15号》（财会〔2021〕35号），关于资金集中管理相关列报，成员单位未归集至集团母公司账户而直接存入财务公司的资金，成员单位应当在资产负债表“货币资金”项目中列示，根据重要性原则并结合本企业的实际情况，成员单位可以在“货币资金”项目之下增设“其中：存放财务公司款项”项目单独列示。 （3）企业持有由中国人民银行发行的数字人民币的，可以增设“数字货币”二级科目进行核算，在资产负债表中将其列报在“货币资金”项目。）
A18: 期末，本集团不存在抵押、质押或冻结、或存放在境外且资金汇回受到限制的款项。
A19: （披露因抵押、质押或冻结等对使用有限制的款项，以及存放在境外的款项总额。公司应单独披露存放在境外且资金汇回受到限制的款项。）
A23: 【提示-关于存款利息的披露： （1）银行存款包括应计利息：指基于实际利率法计提的应计但未到付息期的银行存款利息；不包括已到期可收取但于资产负债表日尚未收到的利息（即逾期未收利息，列示于报表项目“应收利息”）； （2）可以在表格下方增加说明：银行存款中含应计利息XXX元；也可以增加二级明细“存款应计利息”。 （3）这部分利息不属于“现金及现金等价物”。】
A25: 外币性货币项目
A26: 项 目 | B26: 期末数 | E26: 期初数
B27: 外币余额 | C27: 折算率 | D27: 人民币金额 | E27: 外币余额 | F27: 折算率 | G27: 人民币金额
A28: 货币资金：
A29: 其中：美元 | B29: =B40+B46+B52+B58 -> 0 | C29: =C46 -> #N/A | D29: =D40+D46+D52+D58 -> 0 | E29: =E40+E46+E52+E58 -> 0 | F29: =F40 -> 0 | G29: =G40+G46+G52+G58 -> 0
A30: 日元 | B30: =B41+B47+B53+B59 -> 0 | C30: =C47 -> #N/A | D30: =D41+D47+D53+D59 -> 0 | E30: =E41+E47+E53+E59 -> 0 | F30: =F41 -> 0 | G30: =G41+G47+G53+G59 -> 0
A31: 澳元 | B31: =B42+B48+B54+B60 -> 0 | C31: =C48 -> #N/A | D31: =D42+D48+D54+D60 -> 0 | E31: =E42+E48+E54+E60 -> 0 | F31: =F42 -> 0 | G31: =G42+G48+G54+G60 -> 0
A32: 欧元 | B32: =B43+B49+B55+B61 -> 0 | C32: =C49 -> #N/A | D32: =D43+D49+D55+D61 -> 0 | E32: =E43+E49+E55+E61 -> 0 | F32: =F43 -> 0 | G32: =G43+G49+G55+G61 -> 0
A35: 货币资金
A36: 项 目 | B36: 期末数 | E36: 期初数
B37: 原币金额 | C37: 折算率 | D37: 人民币金额 | E37: 原币金额 | F37: 折算率 | G37: 人民币金额
A38: 库存现金： | D38: =SUM(D39:D43) -> 0 | G38: =SUM(G39:G43) -> 0
A39: 人民币 | B39: =SUMIF('现金明细表E1-2'!$A:$A,'附注披露信息(上市公司)'!$A39,'现金明细表E1-2'!$E:$E)+SUMIF('现金明细表E1-2'!$A:$A,'附注披露信息(上市公司)'!$A39,'现金明细表E1-2'!$H:$H) -> 0 | C39: 1 | D39: =B39*C39 -> 0 | E39: =SUMIF('现金明细表E1-2'!$A:$A,'附注披露信息(上市公司)'!$A39,'现金明细表E1-2'!$B:$B) -> 0 | F39: 1 | G39: =E39*F39 -> 0
A40: 美元 | B40: =SUMIF('现金明细表E1-2'!$A:$A,'附注披露信息(上市公司)'!$A40,'现金明细表E1-2'!$E:$E)+SUMIF('现金明细表E1-2'!$A:$A,'附注披露信息(上市公司)'!$A40,'现金明细表E1-2'!$H:$H) -> 0 | C40: =VLOOKUP(A40,'现金明细表E1-2'!$A:$F,6,FALSE) -> 0 | D40: =SUMIF('现金明细表E1-2'!$A$15:$A$19,A40,'现金明细表E1-2'!$G$15:$G$19) -> 0 | E40: =SUMIF('现金明细表E1-2'!$A:$A,'附注披露信息(上市公司)'!$A40,'现金明细表E1-2'!$B:$B) -> 0 | G40: =SUMIF('现金明细表E1-2'!$A$15:$A$19,A40,'现金明细表E1-2'!$B$15:$B$19) -> 0
A41: 日元 | B41: =SUMIF('现金明细表E1-2'!$A:$A,'附注披露信息(上市公司)'!$A41,'现金明细表E1-2'!$E:$E)+SUMIF('现金明细表E1-2'!$A:$A,'附注披露信息(上市公司)'!$A41,'现金明细表E1-2'!$H:$H) -> 0 | C41: =VLOOKUP(A41,'现金明细表E1-2'!$A:$F,6,FALSE) -> 0 | D41: =SUMIF('现金明细表E1-2'!$A$15:$A$19,A41,'现金明细表E1-2'!$G$15:$G$19) -> 0 | E41: =SUMIF('现金明细表E1-2'!$A:$A,'附注披露信息(上市公司)'!$A41,'现金明细表E1-2'!$B:$B) -> 0 | G41: =SUMIF('现金明细表E1-2'!$A$15:$A$19,A41,'现金明细表E1-2'!$B$15:$B$19) -> 0
A42: 澳元 | B42: =SUMIF('现金明细表E1-2'!$A:$A,'附注披露信息(上市公司)'!$A42,'现金明细表E1-2'!$E:$E)+SUMIF('现金明细表E1-2'!$A:$A,'附注披露信息(上市公司)'!$A42,'现金明细表E1-2'!$H:$H) -> 0 | C42: =VLOOKUP(A42,'现金明细表E1-2'!$A:$F,6,FALSE) -> 0 | D42: =B42*C42 -> 0 | E42: =SUMIF('现金明细表E1-2'!$A:$A,'附注披露信息(上市公司)'!$A42,'现金明细表E1-2'!$B:$B) -> 0 | G42: =SUMIF('现金明细表E1-2'!$A$15:$A$19,A42,'现金明细表E1-2'!$B$15:$B$19) -> 0
A43: 欧元 | B43: =SUMIF('现金明细表E1-2'!$A:$A,'附注披露信息(上市公司)'!$A43,'现金明细表E1-2'!$E:$E)+SUMIF('现金明细表E1-2'!$A:$A,'附注披露信息(上市公司)'!$A43,'现金明细表E1-2'!$H:$H) -> 0 | C43: =VLOOKUP(A43,'现金明细表E1-2'!$A:$F,6,FALSE) -> 0 | D43: =B43*C43 -> 0 | E43: =SUMIF('现金明细表E1-2'!$A:$A,'附注披露信息(上市公司)'!$A43,'现金明细表E1-2'!$B:$B) -> 0 | G43: =SUMIF('现金明细表E1-2'!$A$15:$A$19,A43,'现金明细表E1-2'!$B$15:$B$19) -> 0
A44: 银行存款： | D44: =SUM(D45:D49) -> 0 | G44: =SUM(G45:G49) -> 0
A45: 人民币 | B45: =SUMIF('银行存款及其他货币资金明细表(人民币及外币)E1-3'!$E$13:$E$17,$A45,'银行存款及其他货币资金明细表(人民币及外币)E1-3'!$AB$13:$AB$17)+SUMIF('银行存款及其他货币资金明细表(人民币及外币)E1-3'!$E$32:$E$33,$A45,'银行存款及其他货币资金明细表(人民币及外币)E1-3'!$AB$33:$AB$34) -> 0 | C45: 1 | D45: =B45*C45 -> 0 | E45: =SUMIF('银行存款及其他货币资金明细表(人民币及外币)E1-3'!$E$13:$E$17,$A45,'银行存款及其他货币资金明细表(人民币及外币)E1-3'!$Z$13:$Z$17)+SUMIF('银行存款及其他货币资金明细表(人民币及外币)E1-3'!$E$32:$E$33,$A45,'银行存款及其他货币资金明细表(人民币及外币)E1-3'!$Z$33:$Z$34) -> 0 | F45: 1 | G45: =E45*F45 -> 0
A46: 美元 | B46: =SUMIF('银行存款及其他货币资金明细表(人民币及外币)E1-3'!$E$13:$E$17,$A46,'银行存款及其他货币资金明细表(人民币及外币)E1-3'!$AB$13:$AB$17)+SUMIF('银行存款及其他货币资金明细表(人民币及外币)E1-3'!$E$32:$E$33,$A46,'银行存款及其他货币资金明细表(人民币及外币)E1-3'!$AB$33:$AB$34) -> 0 | C46: =VLOOKUP(A46,'银行存款及其他货币资金明细表(人民币及外币)E1-3'!$E:$F,2,FALSE) -> #N/A | D46: =SUMIF('银行存款及其他货币资金明细表(人民币及外币)E1-3'!$E$13:$E$17,A46,'银行存款及其他货币资金明细表(人民币及外币)E1-3'!$AB$13:$AB$17)+SUMIF('银行存款及其他货币资金明细表(人民币及外币)E1-3'!$E$32:$E$33,A46,'银行存款及其他货币资金明细表(人民币及外币)E1-3'!$AB$32:$AB$33) -> 0 | E46: =SUMIF('银行存款及其他货币资金明细表(人民币及外币)E1-3'!$E$13:$E$17,$A46,'银行存款及其他货币资金明细表(人民币及外币)E1-3'!$Z$13:$Z$17)+SUMIF('银行存款及其他货币资金明细表(人民币及外币)E1-3'!$E$32:$E$33,$A46,'银行存款及其他货币资金明细表(人民币及外币)E1-3'!$Z$33:$Z$34) -> 0 | G46: =SUMIF('银行存款及其他货币资金明细表(人民币及外币)E1-3'!$E$13:$E$17,A46,'银行存款及其他货币资金明细表(人民币及外币)E1-3'!$G$13:$G$17)+SUMIF('银行存款及其他货币资金明细表(人民币及外币)E1-3'!$E$32:$E$33,A46,'银行存款及其他货币资金明细表(人民币及外币)E1-3'!$G$32:$G$33) -> 0
A47: 日元 | B47: =SUMIF('银行存款及其他货币资金明细表(人民币及外币)E1-3'!$E$13:$E$17,$A47,'银行存款及其他货币资金明细表(人民币及外币)E1-3'!$AB$13:$AB$17)+SUMIF('银行存款及其他货币资金明细表(人民币及外币)E1-3'!$E$32:$E$33,$A47,'银行存款及其他货币资金明细表(人民币及外币)E1-3'!$AB$33:$AB$34) -> 0 | C47: =VLOOKUP(A47,'银行存款及其他货币资金明细表(人民币及外币)E1-3'!$E:$F,2,FALSE) -> #N/A | D47: =SUMIF('银行存款及其他货币资金明细表(人民币及外币)E1-3'!$E$13:$E$17,A47,'银行存款及其他货币资金明细表(人民币及外币)E1-3'!$AB$13:$AB$17)+SUMIF('银行存款及其他货币资金明细表(人民币及外币)E1-3'!$E$32:$E$33,A47,'银行存款及其他货币资金明细表(人民币及外币)E1-3'!$AB$32:$AB$33) -> 0 | E47: =SUMIF('银行存款及其他货币资金明细表(人民币及外币)E1-3'!$E$13:$E$17,$A47,'银行存款及其他货币资金明细表(人民币及外币)E1-3'!$Z$13:$Z$17)+SUMIF('银行存款及其他货币资金明细表(人民币及外币)E1-3'!$E$32:$E$33,$A47,'银行存款及其他货币资金明细表(人民币及外币)E1-3'!$Z$33:$Z$34) -> 0 | G47: =SUMIF('银行存款及其他货币资金明细表(人民币及外币)E1-3'!$E$13:$E$17,A47,'银行存款及其他货币资金明细表(人民币及外币)E1-3'!$G$13:$G$17)+SUMIF('银行存款及其他货币资金明细表(人民币及外币)E1-3'!$E$32:$E$33,A47,'银行存款及其他货币资金明细表(人民币及外币)E1-3'!$G$32:$G$33) -> 0
...

Sheet 附注披露信息(国企)
A1: 致同会计师事务所
A2: 货币资金附注披露信息（国企）
A3: =底稿目录!A2 -> 被审计单位： | C3: =底稿目录!A4 -> 编制人： | E3: =底稿目录!A5 -> 编制日期： | G3: 索引号：
A4: =底稿目录!A3 -> 截止日：202X年12月31日 | C4: =底稿目录!A6 -> 复核人： | E4: =底稿目录!A7 -> 复核日期： | G4: 页次：
A5: 货币资金附注披露信息：
A6: 货币资金
A7: 项 目 | B7: 期末余额 | C7: 年初余额
A8: 现金 | B8: ='现金明细表E1-2'!G22 -> 0 | C8: ='现金明细表E1-2'!B22 -> 0 | E8: =B8-'附注披露信息(上市公司)'!B8 -> 0
A9: 银行存款 | B9: ='银行存款及其他货币资金明细表(人民币及外币)E1-3'!AB42+'银行存款及其他货币资金明细表(人民币及外币)E1-3'!AB43 -> 0 | C9: ='银行存款及其他货币资金明细表(人民币及外币)E1-3'!G43+'银行存款及其他货币资金明细表(人民币及外币)E1-3'!G42 -> 0
A10: 其他货币资金 | B10: ='银行存款及其他货币资金明细表(人民币及外币)E1-3'!AB44 -> 0 | C10: ='银行存款及其他货币资金明细表(人民币及外币)E1-3'!G44 -> 0
A11: 数字货币
A12: 合 计 | B12: =SUM(B8:B11) -> 0 | C12: =SUM(C8:C11) -> 0 | E12: =B12-'附注披露信息(上市公司)'!D62 -> 0
A13: （如有因抵押、质押或冻结等对使用有限制、存放在境外、有潜在回收风险的款项应单独说明。）
A14: （提示：企业持有由中国人民银行发行的数字人民币，可单独增加“数字货币”二级明细项目）
A15: 受限制的货币资金明细
A16: 项 目 | B16: 期末余额 | C16: 年初余额
A17: 银行承兑汇票保证金 | B17: =SUMIF('银行存款及其他货币资金明细表(人民币及外币)E1-3'!$D$23:$D$28,A17,'银行存款及其他货币资金明细表(人民币及外币)E1-3'!$AB$23:$AB$28)+SUMIF('银行存款及其他货币资金明细表(人民币及外币)E1-3'!$D$38:$D$40,A17,'银行存款及其他货币资金明细表(人民币及外币)E1-3'!$AB$38:$AB$40) -> 0 | C17: =SUMIF('银行存款及其他货币资金明细表(人民币及外币)E1-3'!$D$23:$D$28,A17,'银行存款及其他货币资金明细表(人民币及外币)E1-3'!$AB$23:$AB$28)+SUMIF('银行存款及其他货币资金明细表(人民币及外币)E1-3'!$D$38:$D$40,A17,'银行存款及其他货币资金明细表(人民币及外币)E1-3'!$AB$38:$AB$40) -> 0
A18: 信用证保证金 | B18: =SUMIF('银行存款及其他货币资金明细表(人民币及外币)E1-3'!$D$23:$D$28,A18,'银行存款及其他货币资金明细表(人民币及外币)E1-3'!$AB$23:$AB$28)+SUMIF('银行存款及其他货币资金明细表(人民币及外币)E1-3'!$D$38:$D$40,A18,'银行存款及其他货币资金明细表(人民币及外币)E1-3'!$AB$38:$AB$40) -> 0 | C18: =SUMIF('银行存款及其他货币资金明细表(人民币及外币)E1-3'!$D$23:$D$28,A18,'银行存款及其他货币资金明细表(人民币及外币)E1-3'!$AB$23:$AB$28)+SUMIF('银行存款及其他货币资金明细表(人民币及外币)E1-3'!$D$38:$D$40,A18,'银行存款及其他货币资金明细表(人民币及外币)E1-3'!$AB$38:$AB$40) -> 0
A19: 履约保证金 | B19: =SUMIF('银行存款及其他货币资金明细表(人民币及外币)E1-3'!$D$23:$D$28,A19,'银行存款及其他货币资金明细表(人民币及外币)E1-3'!$AB$23:$AB$28)+SUMIF('银行存款及其他货币资金明细表(人民币及外币)E1-3'!$D$38:$D$40,A19,'银行存款及其他货币资金明细表(人民币及外币)E1-3'!$AB$38:$AB$40) -> 0 | C19: =SUMIF('银行存款及其他货币资金明细表(人民币及外币)E1-3'!$D$23:$D$28,A19,'银行存款及其他货币资金明细表(人民币及外币)E1-3'!$AB$23:$AB$28)+SUMIF('银行存款及其他货币资金明细表(人民币及外币)E1-3'!$D$38:$D$40,A19,'银行存款及其他货币资金明细表(人民币及外币)E1-3'!$AB$38:$AB$40) -> 0
A20: 用于担保的定期存款或通知存款 | B20: =SUMIF('银行存款及其他货币资金明细表(人民币及外币)E1-3'!$D$23:$D$28,A20,'银行存款及其他货币资金明细表(人民币及外币)E1-3'!$AB$23:$AB$28)+SUMIF('银行存款及其他货币资金明细表(人民币及外币)E1-3'!$D$38:$D$40,A20,'银行存款及其他货币资金明细表(人民币及外币)E1-3'!$AB$38:$AB$40) -> 0 | C20: =SUMIF('银行存款及其他货币资金明细表(人民币及外币)E1-3'!$D$23:$D$28,A20,'银行存款及其他货币资金明细表(人民币及外币)E1-3'!$AB$23:$AB$28)+SUMIF('银行存款及其他货币资金明细表(人民币及外币)E1-3'!$D$38:$D$40,A20,'银行存款及其他货币资金明细表(人民币及外币)E1-3'!$AB$38:$AB$40) -> 0
A21: 放在境外且资金汇回受到限制的款项 | B21: =SUMIF('银行存款及其他货币资金明细表(人民币及外币)E1-3'!$D$23:$D$28,A21,'银行存款及其他货币资金明细表(人民币及外币)E1-3'!$AB$23:$AB$28)+SUMIF('银行存款及其他货币资金明细表(人民币及外币)E1-3'!$D$38:$D$40,A21,'银行存款及其他货币资金明细表(人民币及外币)E1-3'!$AB$38:$AB$40) -> 0 | C21: =SUMIF('银行存款及其他货币资金明细表(人民币及外币)E1-3'!$D$23:$D$28,A21,'银行存款及其他货币资金明细表(人民币及外币)E1-3'!$AB$23:$AB$28)+SUMIF('银行存款及其他货币资金明细表(人民币及外币)E1-3'!$D$38:$D$40,A21,'银行存款及其他货币资金明细表(人民币及外币)E1-3'!$AB$38:$AB$40) -> 0
A22: …
A23: 合 计
A25: 外币性货币项目
A26: 项 目 | B26: 期末数 | E26: 期初数
B27: 外币余额 | C27: 折算率 | D27: 人民币金额 | E27: 外币余额 | F27: 折算率 | G27: 人民币金额
A28: 货币资金：
A29: 其中：美元 | B29: =B40+B46+B52+B58 -> 0 | C29: =C46 -> #N/A | D29: =D40+D46+D52+D58 -> 0 | E29: =E40+E46+E52+E58 -> 0 | F29: =F40 -> 0 | G29: =G40+G46+G52+G58 -> 0
A30: 日元 | B30: =B41+B47+B53+B59 -> 0 | C30: =C47 -> #N/A | D30: =D41+D47+D53+D59 -> 0 | E30: =E41+E47+E53+E59 -> 0 | F30: =F41 -> 0 | G30: =G41+G47+G53+G59 -> 0
A31: 澳元 | B31: =B42+B48+B54+B60 -> 0 | C31: =C48 -> #N/A | D31: =D42+D48+D54+D60 -> 0 | E31: =E42+E48+E54+E60 -> 0 | F31: =F42 -> 0 | G31: =G42+G48+G54+G60 -> 0
A32: 欧元 | B32: =B43+B49+B55+B61 -> 0 | C32: =C49 -> #N/A | D32: =D43+D49+D55+D61 -> 0 | E32: =E43+E49+E55+E61 -> 0 | F32: =F43 -> 0 | G32: =G43+G49+G55+G61 -> 0
A35: 货币资金
A36: 项 目 | B36: 期末数 | E36: 期初数
B37: 原币金额 | C37: 折算率 | D37: 人民币金额 | E37: 原币金额 | F37: 折算率 | G37: 人民币金额
A38: 库存现金： | D38: =SUM(D39:D43) -> 0 | G38: =SUM(G39:G43) -> 0
A39: 人民币 | B39: =SUMIF('现金明细表E1-2'!$A:$A,'附注披露信息(上市公司)'!$A39,'现金明细表E1-2'!$E:$E)+SUMIF('现金明细表E1-2'!$A:$A,'附注披露信息(上市公司)'!$A39,'现金明细表E1-2'!$H:$H) -> 0 | C39: 1 | D39: =B39*C39 -> 0 | E39: =SUMIF('现金明细表E1-2'!$A:$A,'附注披露信息(上市公司)'!$A39,'现金明细表E1-2'!$B:$B) -> 0 | F39: 1 | G39: =E39*F39 -> 0
A40: 美元 | B40: =SUMIF('现金明细表E1-2'!$A:$A,'附注披露信息(上市公司)'!$A40,'现金明细表E1-2'!$E:$E)+SUMIF('现金明细表E1-2'!$A:$A,'附注披露信息(上市公司)'!$A40,'现金明细表E1-2'!$H:$H) -> 0 | C40: =VLOOKUP(A40,'现金明细表E1-2'!$A:$F,6,FALSE) -> 0 | D40: =SUMIF('现金明细表E1-2'!$A$15:$A$19,A40,'现金明细表E1-2'!$G$15:$G$19) -> 0 | E40: =SUMIF('现金明细表E1-2'!$A:$A,'附注披露信息(上市公司)'!$A40,'现金明细表E1-2'!$B:$B) -> 0 | G40: =SUMIF('现金明细表E1-2'!$A$15:$A$19,A40,'现金明细表E1-2'!$B$15:$B$19) -> 0
A41: 日元 | B41: =SUMIF('现金明细表E1-2'!$A:$A,'附注披露信息(上市公司)'!$A41,'现金明细表E1-2'!$E:$E)+SUMIF('现金明细表E1-2'!$A:$A,'附注披露信息(上市公司)'!$A41,'现金明细表E1-2'!$H:$H) -> 0 | C41: =VLOOKUP(A41,'现金明细表E1-2'!$A:$F,6,FALSE) -> 0 | D41: =SUMIF('现金明细表E1-2'!$A$15:$A$19,A41,'现金明细表E1-2'!$G$15:$G$19) -> 0 | E41: =SUMIF('现金明细表E1-2'!$A:$A,'附注披露信息(上市公司)'!$A41,'现金明细表E1-2'!$B:$B) -> 0 | G41: =SUMIF('现金明细表E1-2'!$A$15:$A$19,A41,'现金明细表E1-2'!$B$15:$B$19) -> 0
A42: 澳元 | B42: =SUMIF('现金明细表E1-2'!$A:$A,'附注披露信息(上市公司)'!$A42,'现金明细表E1-2'!$E:$E)+SUMIF('现金明细表E1-2'!$A:$A,'附注披露信息(上市公司)'!$A42,'现金明细表E1-2'!$H:$H) -> 0 | C42: =VLOOKUP(A42,'现金明细表E1-2'!$A:$F,6,FALSE) -> 0 | D42: =B42*C42 -> 0 | E42: =SUMIF('现金明细表E1-2'!$A:$A,'附注披露信息(上市公司)'!$A42,'现金明细表E1-2'!$B:$B) -> 0 | G42: =SUMIF('现金明细表E1-2'!$A$15:$A$19,A42,'现金明细表E1-2'!$B$15:$B$19) -> 0
A43: 欧元 | B43: =SUMIF('现金明细表E1-2'!$A:$A,'附注披露信息(上市公司)'!$A43,'现金明细表E1-2'!$E:$E)+SUMIF('现金明细表E1-2'!$A:$A,'附注披露信息(上市公司)'!$A43,'现金明细表E1-2'!$H:$H) -> 0 | C43: =VLOOKUP(A43,'现金明细表E1-2'!$A:$F,6,FALSE) -> 0 | D43: =B43*C43 -> 0 | E43: =SUMIF('现金明细表E1-2'!$A:$A,'附注披露信息(上市公司)'!$A43,'现金明细表E1-2'!$B:$B) -> 0 | G43: =SUMIF('现金明细表E1-2'!$A$15:$A$19,A43,'现金明细表E1-2'!$B$15:$B$19) -> 0
...

Sheet 货币资金审定表E1-1
A1: 致同会计师事务所
A2: 货币资金审定表
A3: =底稿目录!A2 -> 被审计单位： | D3: =底稿目录!A4 -> 编制人： | G3: =底稿目录!A5 -> 编制日期： | I3: 索引号： | J3: E1-1
A4: =底稿目录!A3 -> 截止日：202X年12月31日 | D4: =底稿目录!A6 -> 复核人： | G4: =底稿目录!A7 -> 复核日期： | I4: 页 次：
A5: 项目名称（外币及人民币） | B5: 期初数 | E5: 期末数 | H5: 本期与上期比较 | J5: 原因分析
B6: 未审数 | C6: 账项调整 | D6: 审定数 | E6: 未审数 | F6: 账项调整 | G6: 审定数 | H6: 变动额 | I6: 变动率
A7: 库存现金 | B7: ='现金明细表E1-2'!B22 -> 0 | D7: =B7+C7 -> 0 | E7: ='现金明细表E1-2'!G22 -> 0 | F7: =G7-E7 -> 0 | G7: ='现金明细表E1-2'!I22 -> 0 | H7: =G7-D7 -> 0 | I7: =IF(AND(D7=0,G7=0),0,IF(AND(D7=0,G7>0),1,H7/D7)) -> 0
A8: 银行存款（本金） | B8: =B9+B10 -> 0 | C8: =C9+C10 -> 0 | D8: =B8+C8 -> 0 | E8: =E9+E10 -> 0 | F8: =F9+F10 -> 0 | G8: =E8+F8 -> 0 | H8: =G8-D8 -> 0 | I8: =IF(AND(D8=0,G8=0),0,IF(AND(D8=0,G8>0),1,H8/D8)) -> 0
A9: 其中：存放财务公司款项 | B9: ='银行存款及其他货币资金明细表(人民币及外币)E1-3'!H18 -> 0 | C9: ='银行存款及其他货币资金明细表(人民币及外币)E1-3'!V18 -> 0 | D9: =B9+C9 -> 0 | E9: ='银行存款及其他货币资金明细表(人民币及外币)E1-3'!R18 -> 0 | F9: ='银行存款及其他货币资金明细表(人民币及外币)E1-3'!X18 -> 0 | G9: =E9+F9 -> 0 | H9: =G9-D9 -> 0 | I9: =IF(AND(D9=0,G9=0),0,IF(AND(D9=0,G9>0),1,H9/D9)) -> 0
A10: 银行机构存款 | B10: ='银行存款及其他货币资金明细表(人民币及外币)E1-3'!H12 -> 0 | C10: ='银行存款及其他货币资金明细表(人民币及外币)E1-3'!V12 -> 0 | D10: =B10+C10 -> 0 | E10: ='银行存款及其他货币资金明细表(人民币及外币)E1-3'!R12 -> 0 | F10: ='银行存款及其他货币资金明细表(人民币及外币)E1-3'!X12 -> 0 | G10: =E10+F10 -> 0 | H10: =G10-D10 -> 0 | I10: =IF(AND(D10=0,G10=0),0,IF(AND(D10=0,G10>0),1,H10/D10)) -> 0
A11: 其他货币资金（本金） | B11: ='银行存款及其他货币资金明细表(人民币及外币)E1-3'!H22 -> 0 | C11: ='银行存款及其他货币资金明细表(人民币及外币)E1-3'!V22 -> 0 | D11: =B11+C11 -> 0 | E11: ='银行存款及其他货币资金明细表(人民币及外币)E1-3'!R22 -> 0 | F11: ='银行存款及其他货币资金明细表(人民币及外币)E1-3'!X22 -> 0 | G11: =E11+F11 -> 0 | H11: =G11-D11 -> 0 | I11: =IF(AND(D11=0,G11=0),0,IF(AND(D11=0,G11>0),1,H11/D11)) -> 0
A12: 数字货币（本金） | D12: =B12+C12 -> 0 | G12: =E12+F12 -> 0 | H12: =G12-D12 -> 0 | I12: =IF(AND(D12=0,G12=0),0,IF(AND(D12=0,G12>0),1,H12/D12)) -> 0
A13: 应计利息 | B13: =SUM(B14:B17) -> 0 | C13: =SUM(C14:C17) -> 0 | D13: =SUM(D14:D17) -> 0 | E13: =SUM(E14:E17) -> 0 | F13: =SUM(F14:F17) -> 0 | G13: =SUM(G14:G17) -> 0 | H13: =G13-D13 -> 0 | I13: =IF(AND(D13=0,G13=0),0,IF(AND(D13=0,G13>0),1,H13/D13)) -> 0
A14: 其中：财务公司存款 | B14: ='银行存款及其他货币资金明细表(人民币及外币)E1-3'!H34 -> 0 | C14: ='银行存款及其他货币资金明细表(人民币及外币)E1-3'!V34 -> 0 | D14: =B14+C14 -> 0 | E14: ='银行存款及其他货币资金明细表(人民币及外币)E1-3'!R34 -> 0 | F14: ='银行存款及其他货币资金明细表(人民币及外币)E1-3'!X34 -> 0 | G14: =E14+F14 -> 0 | H14: =G14-D14 -> 0 | I14: =IF(AND(D14=0,G14=0),0,IF(AND(D14=0,G14>0),1,H14/D14)) -> 0
A15: 银行机构存款 | B15: ='银行存款及其他货币资金明细表(人民币及外币)E1-3'!H31 -> 0 | C15: ='银行存款及其他货币资金明细表(人民币及外币)E1-3'!V31 -> 0 | D15: =B15+C15 -> 0 | E15: ='银行存款及其他货币资金明细表(人民币及外币)E1-3'!R31 -> 0 | F15: ='银行存款及其他货币资金明细表(人民币及外币)E1-3'!X31 -> 0 | G15: =E15+F15 -> 0 | H15: =G15-D15 -> 0 | I15: =IF(AND(D15=0,G15=0),0,IF(AND(D15=0,G15>0),1,H15/D15)) -> 0
A16: 其他货币资金 | B16: ='银行存款及其他货币资金明细表(人民币及外币)E1-3'!H37 -> 0 | C16: ='银行存款及其他货币资金明细表(人民币及外币)E1-3'!V37 -> 0 | D16: =B16+C16 -> 0 | E16: ='银行存款及其他货币资金明细表(人民币及外币)E1-3'!R37 -> 0 | F16: ='银行存款及其他货币资金明细表(人民币及外币)E1-3'!X37 -> 0 | G16: =E16+F16 -> 0 | H16: =G16-D16 -> 0 | I16: =IF(AND(D16=0,G16=0),0,IF(AND(D16=0,G16>0),1,H16/D16)) -> 0
A17: 数字货币 | D17: =B17+C17 -> 0 | G17: =E17+F17 -> 0 | H17: =G17-D17 -> 0 | I17: =IF(AND(D17=0,G17=0),0,IF(AND(D17=0,G17>0),1,H17/D17)) -> 0
A18: 合 计 | B18: =B7+B8+B11+B12+B13 -> 0 | C18: =C7+C8+C11+C12+C13 -> 0 | D18: =B18+C18 -> 0 | E18: =E7+E8+E11+E12+E13 -> 0 | F18: =F7+F8+F11+F12+F13 -> 0 | G18: =G7+G8+G11+G12+G13 -> 0 | H18: =H7+H8+H11+H12+H13 -> 0 | I18: =IF(AND(D18=0,G18=0),0,IF(AND(D18=0,G18>0),1,H18/D18)) -> 0
A19: 其中：存放在境外的款项总额 | B19: ='现金明细表E1-2'!B23+'银行存款及其他货币资金明细表(人民币及外币)E1-3'!H46 -> 0 | D19: =B19+C19 -> 0 | E19: ='现金明细表E1-2'!E23+'银行存款及其他货币资金明细表(人民币及外币)E1-3'!R46 -> 0 | F19: ='现金明细表E1-2'!F23+'银行存款及其他货币资金明细表(人民币及外币)E1-3'!X46 -> 0 | G19: =E19+F19 -> 0 | H19: =G19-D19 -> 0 | I19: =IF(AND(D19=0,G19=0),0,IF(AND(D19=0,G19>0),1,H19/D19)) -> 0
A20: 试算平衡表数
A21: 差异数 | D21: =D18-D20 -> 0 | G21: =G18-G20 -> 0
A23: 项目名称（仅人民币） | B23: 期初数 | E23: 期末数 | H23: 本期与上期比较 | J23: 原因分析
B24: 未审数 | C24: 账项调整 | D24: 审定数 | E24: 未审数 | F24: 账项调整 | G24: 审定数 | H24: 变动额 | I24: 变动率
A25: 库存现金 | B25: ='现金明细表E1-2'!B22 -> 0 | D25: =B25+C25 -> 0 | E25: ='现金明细表E1-2'!G22 -> 0 | F25: =G25-E25 -> 0 | G25: ='现金明细表E1-2'!I22 -> 0 | H25: =G25-D25 -> 0 | I25: =IF(AND(D25=0,G25=0),0,IF(AND(D25=0,G25>0),1,H25/D25)) -> 0
A26: 银行存款（本金） | B26: =B27+B28 -> 0 | C26: =C27+C28 -> 0 | D26: =B26+C26 -> 0 | E26: =E27+E28 -> 0 | F26: =F27+F28 -> 0 | G26: =E26+F26 -> 0 | H26: =G26-D26 -> 0 | I26: =IF(AND(D26=0,G26=0),0,IF(AND(D26=0,G26>0),1,H26/D26)) -> 0
A27: 其中：存放财务公司款项 | B27: ='银行存款及其他货币资金明细表(仅人民币)E1-3'!E22 -> 0 | D27: =B27+C27 -> 0 | E27: ='银行存款及其他货币资金明细表(仅人民币)E1-3'!H22 -> 0 | F27: ='银行存款及其他货币资金明细表(仅人民币)E1-3'!I22 -> 0 | G27: =E27+F27 -> 0 | H27: =G27-D27 -> 0 | I27: =IF(AND(D27=0,G27=0),0,IF(AND(D27=0,G27>0),1,H27/D27)) -> 0
A28: 银行机构存款 | B28: ='银行存款及其他货币资金明细表(仅人民币)E1-3'!E12 -> 0 | D28: =B28+C28 -> 0 | E28: ='银行存款及其他货币资金明细表(仅人民币)E1-3'!H12 -> 0 | F28: ='银行存款及其他货币资金明细表(仅人民币)E1-3'!I12 -> 0 | G28: =E28+F28 -> 0 | H28: =G28-D28 -> 0 | I28: =IF(AND(D28=0,G28=0),0,IF(AND(D28=0,G28>0),1,H28/D28)) -> 0
A29: 其他货币资金（本金） | B29: ='银行存款及其他货币资金明细表(仅人民币)E1-3'!E26 -> 0 | D29: =B29+C29 -> 0 | E29: ='银行存款及其他货币资金明细表(仅人民币)E1-3'!H26 -> 0 | F29: ='银行存款及其他货币资金明细表(仅人民币)E1-3'!I26 -> 0 | G29: =E29+F29 -> 0 | H29: =G29-D29 -> 0 | I29: =IF(AND(D29=0,G29=0),0,IF(AND(D29=0,G29>0),1,H29/D29)) -> 0
A30: 数字货币（本金） | D30: =B30+C30 -> 0 | G30: =E30+F30 -> 0 | H30: =G30-D30 -> 0 | I30: =IF(AND(D30=0,G30=0),0,IF(AND(D30=0,G30>0),1,H30/D30)) -> 0
A31: 应计利息 | B31: =SUM(B32:B35) -> 0 | C31: =SUM(C32:C35) -> 0 | D31: =SUM(D32:D35) -> 0 | E31: =SUM(E32:E35) -> 0 | F31: =SUM(F32:F35) -> 0 | G31: =G32+G33+G34 -> 0 | H31: =G31-D31 -> 0 | I31: =IF(AND(D31=0,G31=0),0,IF(AND(D31=0,G31>0),1,H31/D31)) -> 0
A32: 其中：财务公司存款 | B32: ='银行存款及其他货币资金明细表(仅人民币)E1-3'!E39 -> 0 | D32: =B32+C32 -> 0 | E32: ='银行存款及其他货币资金明细表(仅人民币)E1-3'!H39 -> 0 | F32: ='银行存款及其他货币资金明细表(仅人民币)E1-3'!I39 -> 0 | G32: =E32+F32 -> 0 | H32: =G32-D32 -> 0 | I32: =IF(AND(D32=0,G32=0),0,IF(AND(D32=0,G32>0),1,H32/D32)) -> 0
A33: 银行机构存款 | B33: ='银行存款及其他货币资金明细表(仅人民币)E1-3'!E36 -> 0 | D33: =B33+C33 -> 0 | E33: ='银行存款及其他货币资金明细表(仅人民币)E1-3'!H36 -> 0 | F33: ='银行存款及其他货币资金明细表(仅人民币)E1-3'!I36 -> 0 | G33: =E33+F33 -> 0 | H33: =G33-D33 -> 0 | I33: =IF(AND(D33=0,G33=0),0,IF(AND(D33=0,G33>0),1,H33/D33)) -> 0
A34: 其他货币资金 | B34: ='银行存款及其他货币资金明细表(仅人民币)E1-3'!E42 -> 0 | D34: =B34+C34 -> 0 | E34: ='银行存款及其他货币资金明细表(仅人民币)E1-3'!H42 -> 0 | F34: ='银行存款及其他货币资金明细表(仅人民币)E1-3'!I42 -> 0 | G34: =E34+F34 -> 0 | H34: =G34-D34 -> 0 | I34: =IF(AND(D34=0,G34=0),0,IF(AND(D34=0,G34>0),1,H34/D34)) -> 0
A35: 数字货币 | D35: =B35+C35 -> 0 | G35: =E35+F35 -> 0 | H35: =G35-D35 -> 0 | I35: =IF(AND(D35=0,G35=0),0,IF(AND(D35=0,G35>0),1,H35/D35)) -> 0
A36: 合 计 | B36: =B25+B26+B29+B30+B31 -> 0 | C36: =C25+C26+C29+C30+C31 -> 0 | D36: =B36+C36 -> 0 | E36: =E25+E26+E29+E30+E31 -> 0 | F36: =F25+F26+F29+F30+F31 -> 0 | G36: =G25+G26+G29+G30+G31 -> 0 | H36: =H25+H26+H29+H30+H31 -> 0 | I36: =IF(AND(D36=0,G36=0),0,IF(AND(D36=0,G36>0),1,H36/D36)) -> 0
A37: 其中：存放在境外的款项总额 | B37: ='现金明细表E1-2'!B23+'银行存款及其他货币资金明细表(仅人民币)E1-3'!E51 -> 0 | D37: =B37+C37 -> 0 | E37: ='现金明细表E1-2'!E23+'银行存款及其他货币资金明细表(仅人民币)E1-3'!H51 -> 0 | F37: ='现金明细表E1-2'!F23+'银行存款及其他货币资金明细表(仅人民币)E1-3'!I51 -> 0 | G37: =E37+F37 -> 0 | H37: =G37-D37 -> 0 | I37: =IF(AND(D37=0,G37=0),0,IF(AND(D37=0,G37>0),1,H37/D37)) -> 0
A38: 试算平衡表数
A39: 差异数 | D39: =D36-D38 -> 0 | G39: =G36-G38 -> 0
A40: 1、审计说明
A41: （1）公司货币资金期末余额较期初余额增加（负数为减少）： | D41: =I18 -> 0 | G41: （2）其他货币资金主要是：
...

Sheet 现金明细表E1-2
A1: 致同会计师事务所
A2: 库存现金明细表
A3: =底稿目录!A2 -> 被审计单位： | E3: =底稿目录!A4 -> 编制人： | G3: =底稿目录!A5 -> 编制日期： | I3: 索引号： | J3: =底稿目录!F7 -> E1-2
A4: =底稿目录!A3 -> 截止日：202X年12月31日 | E4: =底稿目录!A6 -> 复核人： | G4: =底稿目录!A7 -> 复核日期： | I4: 页 次：
A5: 一、审计目标:
A6: 1.资产负债表中记录的库存现金是存在的，且已经记录在恰当的账户中；
A7: 2.所有应记录的库存现金均已记录，所有应当包括在财务报表中的相关披露均已包括；
A8: 3.库存现金以恰当的金额包括在财务报表中，与之相关的计价或分摊调整已恰当记录，相关披露已得到恰当计量和描述
A9: 二、审计过程：
A10: 1.取得库存现金明细账，检查与总账、明细账合计数、报表金额等是否核对相符。
A11: 2.对于以外币计价的的库存现金余额，确定是否采用了适当的汇率进行了折算。
A12: 3.结合现金监盘结果，列示现金长、短款原因。
A13: 币种 | B13: 未审数（人民币金额） | H13: 审计调整-原币（调减为负数） | I13: 期末审定数（人民币金额） | J13: 备注
B14: 期初余额 | C14: 本期增加 | D14: 本期减少 | E14: 期末余额（原币） | F14: 期末折算汇率 | G14: 期末折算人民币金额
A15: 人民币 | E15: =B15+C15-D15 -> 0 | G15: =E15*F15 -> 0 | I15: =G15+H15*F15 -> 0 | J15: NOTE1
A16: 美元 | E16: =B16+C16-D16 -> 0 | G16: =E16*F16 -> 0 | I16: =G16+H16*F16 -> 0
A17: 日元 | E17: =B17+C17-D17 -> 0 | G17: =E17*F17 -> 0 | I17: =G17+H17*F17 -> 0
A18: 澳元 | E18: =B18+C18-D18 -> 0 | G18: =E18*F18 -> 0 | I18: =G18+H18*F18 -> 0
A19: 欧元 | E19: =B19+C19-D19 -> 0 | G19: =E19*F19 -> 0 | I19: =G19+H19*F19 -> 0
E20: =B20+C20-D20 -> 0 | G20: =E20*F20 -> 0 | I20: =G20+H20*F20 -> 0
E21: =B21+C21-D21 -> 0 | G21: =E21*F21 -> 0 | I21: =G21+H21*F21 -> 0
A22: 合计 | B22: =SUM(B15:B21) -> 0 | C22: =SUM(C15:C21) -> 0 | D22: =SUM(D15:D21) -> 0 | E22: =SUM(E15:E21) -> 0 | F22: =SUM(F15:F21) -> 0 | G22: =SUM(G15:G21) -> 0 | H22: =SUM(H15:H21) -> 0 | I22: =SUM(I15:I21) -> 0
A23: 其中：存放在境外的款项总额 | E23: =B23+C23-D23 -> 0 | G23: =E23+F23 -> 0
A24: 三、审计说明：
A26: 四、审计结论：
A28: 提示：
A29: 1.本科目核算企业的库存现金。企业有内部周转使用备用金的，可以单独设置“备用金”科目。
A30: 2.若公司仅有一种币种的现金，可不填列本表（用盘点表代替）。
A31: 3.期初余额应与上年末审定数一致。
A32: 4.审计说明可以概述：（1）程序的测试情况、结果；（2）拟调整事项及其调整分录、未调整事项及其影响，审计范围受到限制情况及其影响。
A33: 5.审计结论可参考：A、未见异常。 B、除上述重大不符事项应当作为调整事项予以调整外，其余未见异常。 C、由于存在以下重大未调整事项（或审计范围受到限制无法获取充分、适当证据），不可确认。

Sheet 银行存款及其他货币资金明细表(仅人民币)E1-3
A1: 致同会计师事务所
A2: 银行存款及其他货币资金明细表
A3: =底稿目录!A2 -> 被审计单位： | E3: =底稿目录!A4 -> 编制人： | J3: =底稿目录!A5 -> 编制日期： | R3: 索引号： | S3: =底稿目录!F8 -> E1-3
A4: =底稿目录!A3 -> 截止日：202X年12月31日 | E4: =底稿目录!A6 -> 复核人： | J4: =底稿目录!A7 -> 复核日期： | R4: 页 次：
A5: 一、审计目标:
A6: 1、资产负债表中记录的银行存款是存在的，且已经记录在恰当的账户中；2、所有应记录的银行存款均已记录，所有应当包括在财务报表中的相关披露均已包括；
A7: 3、银行存款以恰当的金额包括在财务报表中，与之相关的计价或分摊调整已恰当记录，相关披露已得到恰当计量和描述
A8: 二、审计过程：
A9: 开户银行 | B9: 总账银行名称 | C9: 银行账号 | D9: 账户性质/主要用途 | E9: 未审数（人民币金额） | I9: 账项调整（调减为负数） | J9: 期末审定数（人民币金额） | K9: 期末对账单余额 | L9: 期末账面余额与银行对账单余额差异 | M9: 回函确认金额 | N9: 银行对账单索引号 | O9: 银行存款余额调节表索引号 | P9: 银行询证函索引号 | Q9: 受限金额 | R9: 受限原因 | S9: 备注（财务公司、境外、资金池等）
E10: 期初余额 | F10: 本期增加 | G10: 本期减少 | H10: 期末余额
A11: （一）存款本金
A12: 银行： | E12: =SUM(E13:E21) -> 0 | F12: =SUM(F13:F21) -> 0 | G12: =SUM(G13:G21) -> 0 | H12: =SUM(H13:H21) -> 0 | I12: =SUM(I13:I21) -> 0 | J12: =SUM(J13:J21) -> 0 | K12: =SUM(K13:K21) -> 0 | L12: =SUM(L13:L21) -> 0 | M12: =SUM(M13:M21) -> 0
A13: XX银行 | H13: =E13+F13-G13 -> 0 | J13: =H13+I13 -> 0 | L13: =J13-K13 -> 0
A14: XX银行 | H14: =E14+F14-G14 -> 0 | J14: =H14+I14 -> 0 | L14: =J14-K14 -> 0
A15: XX银行 | H15: =E15+F15-G15 -> 0 | J15: =H15+I15 -> 0 | L15: =J15-K15 -> 0
A16: XX银行 | H16: =E16+F16-G16 -> 0 | J16: =H16+I16 -> 0 | L16: =J16-K16 -> 0
A17: XX银行 | H17: =E17+F17-G17 -> 0 | J17: =H17+I17 -> 0 | L17: =J17-K17 -> 0
A18: XX银行 | H18: =E18+F18-G18 -> 0 | J18: =H18+I18 -> 0 | L18: =J18-K18 -> 0
A19: XX银行 | H19: =E19+F19-G19 -> 0 | J19: =H19+I19 -> 0 | L19: =J19-K19 -> 0
A20: XX银行 | H20: =E20+F20-G20 -> 0 | J20: =H20+I20 -> 0 | L20: =J20-K20 -> 0
A21: XX银行 | H21: =E21+F21-G21 -> 0 | J21: =H21+I21 -> 0 | L21: =J21-K21 -> 0
A22: 其他金融机构（存放财务公司款项）： | E22: =SUM(E23:E25) -> 0 | F22: =SUM(F23:F25) -> 0 | G22: =SUM(G23:G25) -> 0 | H22: =SUM(H23:H25) -> 0 | I22: =SUM(I23:I25) -> 0 | J22: =SUM(J23:J25) -> 0 | K22: =SUM(K23:K25) -> 0 | L22: =SUM(L23:L25) -> 0 | M22: =SUM(M23:M25) -> 0
A23: XX财务公司 | H23: =E23+F23-G23 -> 0 | J23: =H23+I23 -> 0 | L23: =J23-K23 -> 0
A24: XX财务公司 | H24: =E24+F24-G24 -> 0 | J24: =H24+I24 -> 0 | L24: =J24-K24 -> 0
A25: XX财务公司 | H25: =E25+F25-G25 -> 0 | J25: =H25+I25 -> 0 | L25: =J25-K25 -> 0
A26: 其他货币资金： | E26: =SUM(E27:E33) -> 0 | F26: =SUM(F27:F33) -> 0 | G26: =SUM(G27:G33) -> 0 | H26: =SUM(H27:H33) -> 0 | I26: =SUM(I27:I33) -> 0 | J26: =SUM(J27:J33) -> 0 | K26: =SUM(K27:K33) -> 0 | L26: =SUM(L27:L33) -> 0
A27: XX银行 | D27: 银行承兑汇票保证金 | H27: =E27+F27-G27 -> 0 | J27: =H27+I27 -> 0 | L27: =J27-K27 -> 0
A28: XX银行 | D28: 信用证保证金 | H28: =E28+F28-G28 -> 0 | J28: =H28+I28 -> 0 | L28: =J28-K28 -> 0
A29: XX银行 | D29: 履约保证金 | H29: =E29+F29-G29 -> 0 | J29: =H29+I29 -> 0 | L29: =J29-K29 -> 0
A30: XX银行 | H30: =E30+F30-G30 -> 0 | J30: =H30+I30 -> 0 | L30: =J30-K30 -> 0
A31: XX银行 | H31: =E31+F31-G31 -> 0 | J31: =H31+I31 -> 0 | L31: =J31-K31 -> 0
A32: XX银行 | H32: =E32+F32-G32 -> 0 | J32: =H32+I32 -> 0 | L32: =J32-K32 -> 0
A33: XX银行 | H33: =E33+F33-G33 -> 0 | J33: =H33+I33 -> 0 | L33: =J33-K33 -> 0
A34: 存款本金小计 | E34: =E22+E12+E26 -> 0 | F34: =F22+F12+F26 -> 0 | G34: =G22+G12+G26 -> 0 | H34: =H22+H12+H26 -> 0 | I34: =I22+I12+I26 -> 0 | J34: =J12+J22+J26 -> 0 | K34: =K12+K22+K26 -> 0 | L34: =L12+L22+L26 -> 0
A35: （二）应计利息(基于实际利率法计提的金融工具的利息应包含在相应金融工具的账面余额中)
A36: 银行： | E36: =SUM(E37:E38) -> 0 | F36: =SUM(F37:F38) -> 0 | G36: =SUM(G37:G38) -> 0 | H36: =SUM(H37:H38) -> 0 | I36: =SUM(I37:I38) -> 0 | J36: =SUM(J37:J38) -> 0 | K36: =SUM(K37:K38) -> 0 | L36: =SUM(L37:L38) -> 0 | N36: -- | O36: -- | P36: --
A37: XX银行 | H37: =E37+F37-G37 -> 0 | J37: =H37+I37 -> 0 | L37: =J37-K37 -> 0
A38: XX银行 | H38: =E38+F38-G38 -> 0 | J38: =H38+I38 -> 0 | L38: =J38-K38 -> 0
A39: 其他金融机构： | E39: =SUM(E40:E41) -> 0 | F39: =SUM(F40:F41) -> 0 | G39: =SUM(G40:G41) -> 0 | H39: =SUM(H40:H41) -> 0 | I39: =SUM(I40:I41) -> 0 | J39: =SUM(J40:J41) -> 0 | K39: =SUM(K40:K41) -> 0 | L39: =SUM(L40:L41) -> 0
A40: XX财务公司 | H40: =E40+F40-G40 -> 0 | J40: =H40+I40 -> 0 | L40: =J40-K40 -> 0
...

Sheet 银行存款及其他货币资金明细表(人民币及外币)E1-3
A1: 致同会计师事务所 | U1: 致同会计师事务所
A2: 银行存款及其他货币资金明细表 | U2: 银行存款及其他货币资金明细表
A3: =底稿目录!A2 -> 被审计单位： | G3: =底稿目录!A4 -> 编制人： | L3: =底稿目录!A5 -> 编制日期： | Q3: 索引号： | R3: =底稿目录!F9 -> E1-3 | Y3: =底稿目录!A4 -> 编制人： | AE3: =底稿目录!A5 -> 编制日期： | AL3: 索引号： | AM3: =R3 -> E1-3
A4: =底稿目录!A3 -> 截止日：202X年12月31日 | G4: =底稿目录!A6 -> 复核人： | L4: =底稿目录!A7 -> 复核日期： | Q4: 页 次： | Y4: =底稿目录!A6 -> 复核人： | AE4: =底稿目录!A7 -> 复核日期： | AL4: 页 次：
A5: 一、审计目标:
B6: 1、资产负债表中记录的银行存款是存在的，且已经记录在恰当的账户中； 2、所有应记录的银行存款均已记录，所有应当包括在财务报表中的相关披露均已包括； 3、银行存款以恰当的金额包括在财务报表中，与之相关的计价或分摊调整已恰当记录，相关披露已得到恰当计量和描述 | U6: 1、资产负债表中记录的银行存款是存在的，且已经记录在恰当的账户中；2、所有应记录的银行存款均已记录，所有应当包括在财务报表中的相关披露均已包括； 3、银行存款以恰当的金额包括在财务报表中，与之相关的计价或分摊调整已恰当记录，相关披露已得到恰当计量和描述
A7: 二、审计过程：
A8: 开户银行 | B8: 总账银行名称 | C8: 银行账号 | D8: 账户性质/主要用途 | E8: 原币币种 | F8: 期末汇率 | G8: 未审数（人民币金额） | U8: 审计调整 | Y8: 审定数 | AC8: 审定本币测算差异 | AD8: 期末对账单余额 | AE8: 期末账面余额与银行对账单余额差异 | AF8: 回函确认金额 | AG8: 银行对账单索引号 | AH8: 银行存款余额调节表索引号 | AI8: 银行询证函索引号 | AJ8: 受限金额 | AK8: 受限原因 | AL8: 利率 | AM8: 备注（财务公司、境外、资金池等）
G9: 期初余额 | I9: 本期增加 | K9: 本期减少 | M9: 期末余额 | O9: 企业报表调整 | Q9: 企业报表数 | S9: 测算本币 | T9: 原报本币测算差异 | U9: 期初调整 | W9: 期末调整 | Y9: 期初审定 | AA9: 期末审定
G10: 原币 | H10: 人民币 | I10: 原币 | J10: 人民币 | K10: 原币 | L10: 人民币 | M10: 原币 | N10: 人民币 | O10: 原币 | P10: 人民币 | Q10: 原币 | R10: 人民币 | U10: 原币 | V10: 人民币 | W10: 原币 | X10: 人民币 | Y10: 原币 | Z10: 人民币 | AA10: 原币 | AB10: 人民币
A11: （一）存款本金
A12: 银行： | G12: =SUM(G13:G17) -> 0 | H12: =SUM(H13:H17) -> 0 | I12: =SUM(I13:I17) -> 0 | J12: =SUM(J13:J17) -> 0 | K12: =SUM(K13:K17) -> 0 | L12: =SUM(L13:L17) -> 0 | M12: =SUM(M13:M17) -> 0 | N12: =SUM(N13:N17) -> 0 | ... AF12: =SUM(AF13:AF17) -> 0
A13: XX银行 | M13: =G13+I13-K13 -> 0 | N13: =H13+J13-L13 -> 0 | Q13: =M13+O13 -> 0 | R13: =N13+P13 -> 0 | S13: =Q13*F13 -> 0 | T13: =S13-R13 -> 0 | Y13: =U13+G13 -> 0 | Z13: =V13+H13 -> 0 | AA13: =Q13+W13 -> 0 | AB13: =R13+X13 -> 0 | AC13: =AA13*F13-AB13 -> 0 | AE13: =AA13-AD13 -> 0
A14: XX银行 | M14: =G14+I14-K14 -> 0 | N14: =H14+J14-L14 -> 0 | Q14: =M14+O14 -> 0 | R14: =N14+P14 -> 0 | S14: =Q14*F14 -> 0 | T14: =S14-R14 -> 0 | Y14: =U14+G14 -> 0 | Z14: =V14+H14 -> 0 | AA14: =Q14+W14 -> 0 | AB14: =R14+X14 -> 0 | AC14: =AA14*F14-AB14 -> 0 | AE14: =AA14-AD14 -> 0
A15: XX银行 | M15: =G15+I15-K15 -> 0 | N15: =H15+J15-L15 -> 0 | Q15: =M15+O15 -> 0 | R15: =N15+P15 -> 0 | S15: =Q15*F15 -> 0 | T15: =S15-R15 -> 0 | Y15: =U15+G15 -> 0 | Z15: =V15+H15 -> 0 | AA15: =Q15+W15 -> 0 | AB15: =R15+X15 -> 0 | AC15: =AA15*F15-AB15 -> 0 | AE15: =AA15-AD15 -> 0
A16: XX银行 | M16: =G16+I16-K16 -> 0 | N16: =H16+J16-L16 -> 0 | Q16: =M16+O16 -> 0 | R16: =N16+P16 -> 0 | S16: =Q16*F16 -> 0 | T16: =S16-R16 -> 0 | Y16: =U16+G16 -> 0 | Z16: =V16+H16 -> 0 | AA16: =Q16+W16 -> 0 | AB16: =R16+X16 -> 0 | AC16: =AA16*F16-AB16 -> 0 | AE16: =AA16-AD16 -> 0
A17: XX银行 | M17: =G17+I17-K17 -> 0 | N17: =H17+J17-L17 -> 0 | Q17: =M17+O17 -> 0 | R17: =N17+P17 -> 0 | S17: =Q17*F17 -> 0 | T17: =S17-R17 -> 0 | Y17: =U17+G17 -> 0 | Z17: =V17+H17 -> 0 | AA17: =Q17+W17 -> 0 | AB17: =R17+X17 -> 0 | AC17: =AA17*F17-AB17 -> 0 | AE17: =AA17-AD17 -> 0
A18: 其他金融机构（存放财务公司款项）： | G18: =SUM(G19:G21) -> 0 | H18: =SUM(H19:H21) -> 0 | I18: =SUM(I19:I21) -> 0 | J18: =SUM(J19:J21) -> 0 | K18: =SUM(K19:K21) -> 0 | L18: =SUM(L19:L21) -> 0 | M18: =SUM(M19:M21) -> 0 | N18: =SUM(N19:N21) -> 0 | ... AD18: =SUM(AD19:AD21) -> 0 | AE18: =AA18-AD18 -> 0 | AF18: =AB18-AE18 -> 0
A19: XX财务公司 | M19: =G19+I19-K19 -> 0 | N19: =H19+J19-L19 -> 0 | Q19: =M19+O19 -> 0 | R19: =N19+P19 -> 0 | S19: =Q19*F19 -> 0 | T19: =S19-R19 -> 0 | Y19: =U19+G19 -> 0 | Z19: =V19+H19 -> 0 | AA19: =Q19+W19 -> 0 | AB19: =R19+X19 -> 0 | AC19: =AA19*F19-AB19 -> 0 | AE19: =AA19-AD19 -> 0
A20: XX财务公司 | M20: =G20+I20-K20 -> 0 | N20: =H20+J20-L20 -> 0 | Q20: =M20+O20 -> 0 | R20: =N20+P20 -> 0 | S20: =Q20*F20 -> 0 | T20: =S20-R20 -> 0 | Y20: =U20+G20 -> 0 | Z20: =V20+H20 -> 0 | AA20: =Q20+W20 -> 0 | AB20: =R20+X20 -> 0 | AC20: =AA20*F20-AB20 -> 0 | AE20: =AA20-AD20 -> 0
A21: XX财务公司 | M21: =G21+I21-K21 -> 0 | N21: =H21+J21-L21 -> 0 | Q21: =M21+O21 -> 0 | R21: =N21+P21 -> 0 | S21: =Q21*F21 -> 0 | T21: =S21-R21 -> 0 | Y21: =U21+G21 -> 0 | Z21: =V21+H21 -> 0 | AA21: =Q21+W21 -> 0 | AB21: =R21+X21 -> 0 | AC21: =AA21*F21-AB21 -> 0 | AE21: =AA21-AD21 -> 0
A22: 其他货币资金： | G22: =SUM(G23:G28) -> 0 | H22: =SUM(H23:H28) -> 0 | I22: =SUM(I23:I28) -> 0 | J22: =SUM(J23:J28) -> 0 | K22: =SUM(K23:K28) -> 0 | L22: =SUM(L23:L28) -> 0 | M22: =SUM(M23:M28) -> 0 | N22: =SUM(N23:N28) -> 0 | ... AF22: =SUM(AF23:AF28) -> 0
A23: XX银行 | D23: 银行承兑汇票保证金 | M23: =G23+I23-K23 -> 0 | N23: =H23+J23-L23 -> 0 | Q23: =M23+O23 -> 0 | R23: =N23+P23 -> 0 | S23: =Q23*F23 -> 0 | T23: =S23-R23 -> 0 | Y23: =U23+G23 -> 0 | Z23: =V23+H23 -> 0 | AA23: =Q23+W23 -> 0 | AB23: =R23+X23 -> 0 | AC23: =AA23*F23-AB23 -> 0 | AE23: =AA23-AD23 -> 0
A24: XX银行 | D24: 信用证保证金 | M24: =G24+I24-K24 -> 0 | N24: =H24+J24-L24 -> 0 | Q24: =M24+O24 -> 0 | R24: =N24+P24 -> 0 | S24: =Q24*F24 -> 0 | T24: =S24-R24 -> 0 | Y24: =U24+G24 -> 0 | Z24: =V24+H24 -> 0 | AA24: =Q24+W24 -> 0 | AB24: =R24+X24 -> 0 | AC24: =AA24*F24-AB24 -> 0 | AE24: =AA24-AD24 -> 0
A25: XX银行 | D25: 履约保证金 | M25: =G25+I25-K25 -> 0 | N25: =H25+J25-L25 -> 0 | Q25: =M25+O25 -> 0 | R25: =N25+P25 -> 0 | S25: =Q25*F25 -> 0 | T25: =S25-R25 -> 0 | Y25: =U25+G25 -> 0 | Z25: =V25+H25 -> 0 | AA25: =Q25+W25 -> 0 | AB25: =R25+X25 -> 0 | AC25: =AA25*F25-AB25 -> 0 | AE25: =AA25-AD25 -> 0
A26: XX银行 | M26: =G26+I26-K26 -> 0 | N26: =H26+J26-L26 -> 0 | Q26: =M26+O26 -> 0 | R26: =N26+P26 -> 0 | S26: =Q26*F26 -> 0 | T26: =S26-R26 -> 0 | Y26: =U26+G26 -> 0 | Z26: =V26+H26 -> 0 | AA26: =Q26+W26 -> 0 | AB26: =R26+X26 -> 0 | AC26: =AA26*F26-AB26 -> 0 | AE26: =AA26-AD26 -> 0
A27: XX银行 | M27: =G27+I27-K27 -> 0 | N27: =H27+J27-L27 -> 0 | Q27: =M27+O27 -> 0 | R27: =N27+P27 -> 0 | S27: =Q27*F27 -> 0 | T27: =S27-R27 -> 0 | Y27: =U27+G27 -> 0 | Z27: =V27+H27 -> 0 | AA27: =Q27+W27 -> 0 | AB27: =R27+X27 -> 0 | AC27: =AA27*F27-AB27 -> 0 | AE27: =AA27-AD27 -> 0
A28: XX银行 | M28: =G28+I28-K28 -> 0 | N28: =H28+J28-L28 -> 0 | Q28: =M28+O28 -> 0 | R28: =N28+P28 -> 0 | S28: =Q28*F28 -> 0 | T28: =S28-R28 -> 0 | Y28: =U28+G28 -> 0 | Z28: =V28+H28 -> 0 | AA28: =Q28+W28 -> 0 | AB28: =R28+X28 -> 0 | AC28: =AA28*F28-AB28 -> 0 | AE28: =AA28-AD28 -> 0
A29: 存款本金小计 | G29: =G18+G12+G22 -> 0 | H29: =H18+H12+H22 -> 0 | I29: =I18+I12+I22 -> 0 | J29: =J18+J12+J22 -> 0 | K29: =K18+K12+K22 -> 0 | L29: =L18+L12+L22 -> 0 | M29: =M18+M12+M22 -> 0 | N29: =N18+N12+N22 -> 0 | ... AE29: =AE18+AE12+AE22 -> 0
A30: （二）应计利息(基于实际利率法计提的金融工具的利息应包含在相应金融工具的账面余额中)
A31: 银行： | G31: =SUM(G32:G33) -> 0 | H31: =SUM(H32:H33) -> 0 | I31: =SUM(I32:I33) -> 0 | J31: =SUM(J32:J33) -> 0 | K31: =SUM(K32:K33) -> 0 | L31: =SUM(L32:L33) -> 0 | M31: =SUM(M32:M33) -> 0 | N31: =SUM(N32:N33) -> 0 | ... AC31: =SUM(AC32:AC33) -> 0 | AE31: =SUM(AE32:AE33) -> 0 | AG31: -- | AH31: -- | AI31: --
A32: XX银行 | M32: =G32+I32-K32 -> 0 | N32: =H32+J32-L32 -> 0 | Q32: =M32+O32 -> 0 | R32: =N32+P32 -> 0 | S32: =Q32*F32 -> 0 | T32: =S32-R32 -> 0 | Y32: =U32+G32 -> 0 | Z32: =V32+H32 -> 0 | AA32: =Q32+W32 -> 0 | AB32: =R32+X32 -> 0 | AC32: =AA32*F32-AB32 -> 0 | AE32: =AA32-AD32 -> 0
A33: XX银行 | M33: =G33+I33-K33 -> 0 | N33: =H33+J33-L33 -> 0 | Q33: =M33+O33 -> 0 | R33: =N33+P33 -> 0 | S33: =Q33*F33 -> 0 | T33: =S33-R33 -> 0 | Y33: =U33+G33 -> 0 | Z33: =V33+H33 -> 0 | AA33: =Q33+W33 -> 0 | AB33: =R33+X33 -> 0 | AC33: =AA33*F33-AB33 -> 0 | AE33: =AA33-AD33 -> 0
A34: 其他金融机构： | G34: =SUM(G35:G36) -> 0 | H34: =SUM(H35:H36) -> 0 | I34: =SUM(I35:I36) -> 0 | J34: =SUM(J35:J36) -> 0 | K34: =SUM(K35:K36) -> 0 | L34: =SUM(L35:L36) -> 0 | M34: =SUM(M35:M36) -> 0 | N34: =SUM(N35:N36) -> 0 | ... AC34: =SUM(AC35:AC36) -> 0 | AE34: =SUM(AE35:AE36) -> 0
A35: XX财务公司 | M35: =G35+I35-K35 -> 0 | N35: =H35+J35-L35 -> 0 | Q35: =M35+O35 -> 0 | R35: =N35+P35 -> 0 | S35: =Q35*F35 -> 0 | T35: =S35-R35 -> 0 | Y35: =U35+G35 -> 0 | Z35: =V35+H35 -> 0 | AA35: =Q35+W35 -> 0 | AB35: =R35+X35 -> 0 | AC35: =AA35*F35-AB35 -> 0 | AE35: =AA35-AD35 -> 0
A36: XX财务公司 | M36: =G36+I36-K36 -> 0 | N36: =H36+J36-L36 -> 0 | Q36: =M36+O36 -> 0 | R36: =N36+P36 -> 0 | S36: =Q36*F36 -> 0 | T36: =S36-R36 -> 0 | Y36: =U36+G36 -> 0 | Z36: =V36+H36 -> 0 | AA36: =Q36+W36 -> 0 | AB36: =R36+X36 -> 0 | AC36: =AA36*F36-AB36 -> 0 | AE36: =AA36-AD36 -> 0
A37: 其他货币资金： | G37: =SUM(G38:G40) -> 0 | H37: =SUM(H38:H40) -> 0 | I37: =SUM(I38:I40) -> 0 | J37: =SUM(J38:J40) -> 0 | K37: =SUM(K38:K40) -> 0 | L37: =SUM(L38:L40) -> 0 | M37: =SUM(M38:M40) -> 0 | N37: =SUM(N38:N40) -> 0 | ... AE37: =SUM(AE38:AE40) -> 0
A38: XX银行 | D38: 银行承兑汇票保证金 | M38: =G38+I38-K38 -> 0 | N38: =H38+J38-L38 -> 0 | Q38: =M38+O38 -> 0 | R38: =N38+P38 -> 0 | S38: =Q38*F38 -> 0 | T38: =S38-R38 -> 0 | Y38: =U38+G38 -> 0 | Z38: =V38+H38 -> 0 | AA38: =Q38+W38 -> 0 | AB38: =R38+X38 -> 0 | AC38: =AA38*F38-AB38 -> 0 | AE38: =AA38-AD38 -> 0
A39: XX银行 | D39: 信用证保证金 | M39: =G39+I39-K39 -> 0 | N39: =H39+J39-L39 -> 0 | Q39: =M39+O39 -> 0 | R39: =N39+P39 -> 0 | S39: =Q39*F39 -> 0 | T39: =S39-R39 -> 0 | Y39: =U39+G39 -> 0 | Z39: =V39+H39 -> 0 | AA39: =Q39+W39 -> 0 | AB39: =R39+X39 -> 0 | AC39: =AA39*F39-AB39 -> 0 | AE39: =AA39-AD39 -> 0
A40: XX银行 | D40: 履约保证金 | M40: =G40+I40-K40 -> 0 | N40: =H40+J40-L40 -> 0 | Q40: =M40+O40 -> 0 | R40: =N40+P40 -> 0 | S40: =Q40*F40 -> 0 | T40: =S40-R40 -> 0 | Y40: =U40+G40 -> 0 | Z40: =V40+H40 -> 0 | AA40: =Q40+W40 -> 0 | AB40: =R40+X40 -> 0 | AC40: =AA40*F40-AB40 -> 0 | AE40: =AA40-AD40 -> 0
...

Sheet 数字货币明细表E1-4
A1: 致同会计师事务所
A2: 数字货币明细表
A3: =底稿目录!A2 -> 被审计单位： | E3: =底稿目录!A4 -> 编制人： | K3: =底稿目录!A5 -> 编制日期： | P3: 索引号： | Q3: =底稿目录!F10 -> E1-4
A4: =底稿目录!A3 -> 截止日：202X年12月31日 | E4: =底稿目录!A6 -> 复核人： | K4: =底稿目录!A7 -> 复核日期： | P4: 页 次：
A5: 一、审计目标:
A6: 1.资产负债表中记录的数字货币是存在的，且已经记录在恰当的账户中；2.所有应记录的数字货币均已记录，所有应当包括在财务报表中的相关披露均已包括；
A7: 3.数字货币以恰当的金额包括在财务报表中，与之相关的计价或分摊调整已恰当记录，相关披露已得到恰当计量和描述 。
A8: 二、审计过程：
A9: 序号 | B9: 开户银行 | C9: 币种 | D9: 汇率 | E9: 期初余额(原币) | F9: 本期增加(原币) | G9: 本期减少(原币) | H9: 期末余额(原币) | I9: 期末余额(本位币) | J9: 账项调整（原币） | K9: 期末审定数（原币） | L9: 期末审定数（人民币） | M9: 期末银行查询余额 | N9: 期末账面余额与银行查询余额的差异 | O9: 银行余额索引号 | P9: 银行询证函索引号 | Q9: 备注
A10: 1 | B10: 北京 | H10: =E10+F10-G10 -> 0 | I10: =H10*D10 -> 0 | K10: =H10+J10 -> 0 | L10: =K10*D10 -> 0 | N10: =M10-K10 -> 0
A11: 2 | B11: 北京 | H11: =E11+F11-G11 -> 0 | I11: =H11*D11 -> 0 | K11: =H11+J11 -> 0 | L11: =K11*D11 -> 0 | N11: =M11-K11 -> 0
A12: 3 | B12: 北京 | H12: =E12+F12-G12 -> 0 | I12: =H12*D12 -> 0 | K12: =H12+J12 -> 0 | L12: =K12*D12 -> 0 | N12: =M12-K12 -> 0
A13: 4 | B13: 北京 | H13: =E13+F13-G13 -> 0 | I13: =H13*D13 -> 0 | K13: =H13+J13 -> 0 | L13: =K13*D13 -> 0 | N13: =M13-K13 -> 0
A14: 5 | B14: 北京 | H14: =E14+F14-G14 -> 0 | I14: =H14*D14 -> 0 | K14: =H14+J14 -> 0 | L14: =K14*D14 -> 0 | N14: =M14-K14 -> 0
A15: 6 | B15: 北京 | H15: =E15+F15-G15 -> 0 | I15: =H15*D15 -> 0 | K15: =H15+J15 -> 0 | L15: =K15*D15 -> 0 | N15: =M15-K15 -> 0
A16: 7 | B16: 北京 | H16: =E16+F16-G16 -> 0 | I16: =H16*D16 -> 0 | K16: =H16+J16 -> 0 | L16: =K16*D16 -> 0 | N16: =M16-K16 -> 0
A17: 合计 | E17: =SUM(E10:E16) -> 0 | F17: =SUM(F10:F16) -> 0 | G17: =SUM(G10:G16) -> 0 | H17: =SUM(H10:H16) -> 0 | I17: =SUM(I10:I16) -> 0 | J17: =SUM(J10:J16) -> 0 | K17: =SUM(K10:K16) -> 0 | L17: =SUM(L10:L16) -> 0 | ... N17: =SUM(N10:N16) -> 0 | O17: —— | P17: —— | Q17: ——
A20: 三、审计说明：
A22: 四、审计结论：

Sheet 调整分录汇总E1-5
A1: 致同会计师事务所
A2: 货币资金调整分录汇总表
A3: =底稿目录!A2 -> 被审计单位： | C3: =底稿目录!A4 -> 编制人： | G3: =底稿目录!A5 -> 编制日期： | I3: 索引： | J3: =底稿目录!F11 -> E1-5
A4: =底稿目录!A3 -> 截止日：202X年12月31日 | C4: =底稿目录!A6 -> 复核人： | G4: =底稿目录!A7 -> 复核日期： | I4: 页次：
A5: 调整事项说明 | B5: 类别（报表调整/账项调整/其他） | C5: 报表项目 | D5: 科目名称 | E5: 附注项目 | F5: …… | G5: 借方调整金额 | H5: 贷方调整金额 | I5: 索引 | J5: 备注
A21: 【注：本底稿适用于调整分录较多、较复杂的项目，且仅列示与本报表项目相关的审计调整。项目组可根据项目实际情况选择是否使用该底稿。】

Sheet 银行存款余额调节表E1-6
A1: 致同会计师事务所
A2: 银行存款余额调节表
A3: =底稿目录!A2 -> 被审计单位： | E3: =底稿目录!A4 -> 编制人： | H3: =底稿目录!A5 -> 编制日期： | J3: 索引号： | K3: =底稿目录!F12 -> E1-6
A4: =底稿目录!A3 -> 截止日：202X年12月31日 | E4: =底稿目录!A6 -> 复核人： | H4: =底稿目录!A7 -> 复核日期： | J4: 页次：
A5: 一、审计目标:
A6: 1.资产负债表中记录的数字货币是存在的，且已经记录在恰当的账户中；2.所有应记录的数字货币均已记录，所有应当包括在财务报表中的相关披露均已包括；
A7: 3.数字货币以恰当的金额包括在财务报表中，与之相关的计价或分摊调整已恰当记录，相关披露已得到恰当计量和描述 。
A8: 二、审计过程：
A9: 1.获取（本期）货币资金银行余额调节表确定计算的准确性，将账面余额与总账核对并与银行对账单核对。
A10: 2.对于长期未达账项，检查是否存在记账差错、挪用资金等事项。
A11: 3.对于大额或异常的未兑现支票，在途存款及其他调节项目：了解项目性质、检查支持性文件；追查至期后银行对账单记录，确认这些项目在期后是否已结
A12: 清，调查在合理期间内没有被结清的项目。
A13: 开户银行： | E13: 银行账号： | K13: 币种
A14: 被审计单位提供 | D14: 审计人员检查
A15: 序号 | B15: 项目 | C15: 审计前金额 | D15: 原始凭证检查 | K15: 审计调整
A16: 企业银行存款日记账余额
A17: 加：银行已收企业未收款项 | C17: =SUM(C20:C24) -> 0 | D17: 银行对账单记录 | F17: 报表日后是否入账 | G17: 收款凭证检查 | K17: 是否调整
D18: 银行收款日期 | E18: 收款金额 | G18: 记账日期 | H18: 记账凭证编号 | I18: 经济内容 | J18: 对应科目
A19: 其中：
A20: 1
A21: 2
A22: 3
A23: 4
A24: 5
A25: 减：银行已付、企业未付款项 | C25: =SUM(C28:C32) -> 0 | D25: 银行对账单记录 | F25: 报表日后是否入账 | G25: 付款凭证检查 | K25: 是否调整
D26: 银行付款日期 | E26: 付款金额 | G26: 记账日期 | H26: 记账凭证编号 | I26: 经济内容 | J26: 对应科目
A27: 其中：
A28: 1
A29: 2
A30: 3
A31: 4
A32: 5
A33: 调节后余额 | C33: =C16+C17-C25 -> 0
A34: 银行对账单余额 | C34: 0
A35: 加：企业已收银行未收款项 | C35: =SUM(C38:C42) -> 0 | D35: 账面记录 | I35: 检查记录 | K35: 是否调整
D36: 被审计单位收款日期 | E36: 收款凭证编号 | F36: 金额 | G36: 经济内容 | H36: 对应科目 | I36: 银行对账单显示的收款时间 | J36: 财务处理是否正确
A37: 其中：
A38: 1
A39: 2
A40: 3
...

Sheet 库存现金（人民币）盘点表E1-7
A1: 致同会计师事务所
A2: 库存现金（人民币）盘点核对表
A3: =底稿目录!A2 -> 被审计单位： | C3: =底稿目录!A4 -> 编制人： | D3: =底稿目录!A5 -> 编制日期： | F3: 索引号： | G3: =底稿目录!F13 -> E1-7
A4: =底稿目录!A3 -> 截止日：202X年12月31日 | C4: =底稿目录!A6 -> 复核人： | D4: =底稿目录!A7 -> 复核日期： | F4: 页次：
A5: 一、审计目标:
A6: 1.资产负债表中记录的货币资金是存在的，且已记录于恰当的账户；
A7: 2.所有应当记录的货币资金均已记录，所有应当包括在财务报表中的相关披露均已包括；
A8: 3.记录的货币资金由被审计单位拥有或控制；
A9: 4.货币资金以恰当的金额包括在财务报表中，与之相关的计价或分摊调整已恰当记录，相关披露已得到恰当计量和描述。
A10: 二、审计过程：
A11: 1.选取要盘点的资金地点（如：包括存放地点、较大余额、经营过程当中组成部分等）在出纳在场的情况下监盘所选定的现金，对现金盘点的全过程执行控制，直到盘点结束。
A12: 2.列出冲抵库存现金的借条的日期、付款人和金额的清单；列出未做报销的费用凭证的日期、领款人和金额的清单。
A13: 3.调查重大或者异常的调节项目；取得由现金出纳、会计主管签字确认的现金盘点表原件。
A14: 清点实有现金 | D14: 核对及追溯纪录
A15: 货币面值 | B15: 张数 | C15: 人民币余额 | D15: 项目 | G15: 金额
A16: 100 | C16: =A16*B16 -> 0 | D16: 1、报表日现金账面余额
A17: 50 | C17: =A17*B17 -> 0 | D17: 加：报表日至盘点日的上一日累计收入数
A18: 20 | C18: =A18*B18 -> 0 | D18: 减：报表日至盘点日的上一日累计支出数
A19: 10 | C19: =A19*B19 -> 0 | D19: 2、盘点日的上一日现金账面余额 | G19: =G16+G17-G18 -> 0
A20: 5 | C20: =A20*B20 -> 0 | D20: 加：收入凭证未记账数
A21: 2 | C21: =A21*B21 -> 0 | D21: 减：支出凭证未记账数
A22: 1 | C22: =A22*B22 -> 0 | D22: 加：未做记账凭证的收入数
A23: 0.5 | C23: =A23*B23 -> 0 | D23: 减：未做记账凭证的支出数
A24: 0.2 | C24: =A24*B24 -> 0 | D24: 3、盘点日现金应有数额 | G24: =G19+G20-G21+G22-G23 -> 0
A25: 0.1 | C25: =A25*B25 -> 0 | D25: 4、盘点日现金实有数额 | G25: =C29 -> 0
A26: 0.05 | C26: =A26*B26 -> 0 | D26: 5、差额： | G26: =G25-G24 -> 0
A27: 0.02 | C27: =A27*B27 -> 0 | D27: 长款 | G27: =IF(G26>0,G26,) -> 0
A28: 0.01 | C28: =A28*B28 -> 0 | D28: 短款 | G28: =IF(G26<0,G26,) -> 0
A29: 合计 | C29: =SUM(C16:C28) -> 0
A30: 会计主管人员： | D30: 日期： | F30: 出纳： | G30: 日期：
A31: 监盘人： | D31: 日期：
A32: 三、审计说明：
A33: 长（短）款原因系：
A35: 四、审计结论：

Sheet 库存现金（外币）盘点表E1-8
A1: 致同会计师事务所
A2: 库存现金（外币）盘点核对表
A3: =底稿目录!A2 -> 被审计单位： | D3: =底稿目录!A4 -> 编制人： | E3: =底稿目录!A5 -> 编制日期： | G3: 索引号： | H3: =底稿目录!F14 -> E1-8
A4: =底稿目录!A3 -> 截止日：202X年12月31日 | D4: =底稿目录!A6 -> 复核人： | E4: =底稿目录!A7 -> 复核日期： | G4: 页次：
A5: 一、审计目标:
A6: 1.资产负债表中记录的货币资金是存在的，且已记录于恰当的账户；
A7: 2.所有应当记录的货币资金均已记录，所有应当包括在财务报表中的相关披露均已包括；
A8: 3.记录的货币资金由被审计单位拥有或控制；
A9: 4.货币资金以恰当的金额包括在财务报表中，与之相关的计价或分摊调整已恰当记录，相关披露已得到恰当计量和描述。
A10: 二、审计过程：
A11: 1.选取要盘点的资金地点（如：包括存放地点、较大余额、经营过程当中组成部分等）在出纳在场的情况下监盘所选定的现金，对现金盘点的全过程执行控制，直到盘点结束。
A12: 2.列出冲抵库存现金的借条的日期、付款人和金额的清单；列出未做报销的费用凭证的日期、领款人和金额的清单。
A13: 3.调查重大或者异常的调节项目；取得由现金出纳、会计主管签字确认的现金盘点表原件。
A14: 清点实有现金 | E14: 核对及追溯纪录
A15: 货币面值 | B15: 张数 | C15: 原币金额 | D15: 本位币金额 | E15: 项目 | H15: 金额
C16: =A16*B16 -> 0 | D16: =C16*$H$36 -> 0 | E16: 1、报表日现金账面余额
C17: =A17*B17 -> 0 | D17: =C17*$H$36 -> 0 | E17: 加：报表日至盘点日的上一日累计收入数
A18: 100 | C18: =A18*B18 -> 0 | D18: =C18*$H$36 -> 0 | E18: 减：报表日至盘点日的上一日累计支出数
A19: 50 | C19: =A19*B19 -> 0 | D19: =C19*$H$36 -> 0 | E19: 2、盘点日的上一日现金账面余额 | H19: =H16+H17-H18 -> 0
A20: 20 | C20: =A20*B20 -> 0 | D20: =C20*$H$36 -> 0 | E20: 加：收入凭证未记账数
A21: 10 | C21: =A21*B21 -> 0 | D21: =C21*$H$36 -> 0 | E21: 减：支出凭证未记账数
A22: 5 | C22: =A22*B22 -> 0 | D22: =C22*$H$36 -> 0 | E22: 加：未做记账凭证的收入数
A23: 2 | C23: =A23*B23 -> 0 | D23: =C23*$H$36 -> 0 | E23: 减：未做记账凭证的支出数
A24: 1 | C24: =A24*B24 -> 0 | D24: =C24*$H$36 -> 0 | E24: 3、盘点日现金应有数额 | H24: =H19+H20-H21+H22-H23 -> 0
A25: 0.5 | C25: =A25*B25 -> 0 | D25: =C25*$H$36 -> 0 | E25: 4、盘点日现金实有数额 | H25: =C31 -> 0
A26: 0.2 | C26: =A26*B26 -> 0 | D26: =C26*$H$36 -> 0 | E26: 5、差额： | H26: =H25-H24 -> 0
A27: 0.1 | C27: =A27*B27 -> 0 | D27: =C27*$H$36 -> 0 | E27: 长款 | H27: =IF(H26>0,H26,) -> 0
A28: 0.05 | C28: =A28*B28 -> 0 | D28: =C28*$H$36 -> 0 | E28: 短款 | H28: =IF(H26<0,H26,) -> 0
A29: 0.02 | C29: =A29*B29 -> 0 | D29: =C29*$H$36 -> 0
A30: 0.01 | C30: =A30*B30 -> 0 | D30: =C30*$H$36 -> 0
A31: 合计 | C31: =SUM(C16:C30) -> 0 | D31: =SUM(D16:D30) -> 0
A32: 会计主管人员： | D32: 日期： | F32: 出纳： | H32: 日期：
A33: 监盘人： | D33: 日期：
A34: 三、审计说明：
A35: 1、 | B35: 长（短）款原因系： | G35: 2、汇率折算测试：
G36: 期末美元汇率为 | H36: 8.8888
G37: 报表日美元账面余额 | H37: =H16 -> 0
G38: 报表日美元应有余额 | H38: =H16*H36 -> 0
G39: 差异（汇兑损益） | H39: =H38-H37 -> 0
A40: 四、审计结论：
...

Sheet 银行存单盘点表E1-9
A1: 致同会计师事务所
A2: 银行存单盘点表
A3: =底稿目录!A2 -> 被审计单位： | F3: =底稿目录!A4 -> 编制人： | J3: =底稿目录!A5 -> 编制日期： | N3: 索引号： | O3: =底稿目录!F15 -> E1-9
A4: =底稿目录!A3 -> 截止日：202X年12月31日 | F4: =底稿目录!A6 -> 复核人： | J4: =底稿目录!A7 -> 复核日期： | N4: 页 次：
A5: 一、审计目标:
A6: 1.资产负债表中记录的货币资金是存在的，且已记录于恰当的账户； 2.所有应当记录的货币资金均已记录，所有应当包括在财务报表中的相关披露均已包括；
A7: 3.记录的货币资金由被审计单位拥有或控制； 4.货币资金以恰当的金额包括在财务报表中，与之相关的计价或分摊调整已恰当记录，相关披露已得到恰当计量和描述。
A8: 二、审计过程：
A9: 1.监盘开户证实书或定期存单（若无法获取，则应获取其他相关支持文件，比如质押回单等），编制银行存单盘点表，检查是否与账面记录金额一致；核对存款人、账号、期间、截止日、计息等是否与客户记录相符；是否抵押或限制使用。
A10: 2.对未质押的定期存款，检查开户证明原件，核对存款人、金额、期限等信息；对已质押的定期存款，检查定期存单复印件，并与对应的质押合同核对；对质押事项逾期的，重点关注相关质权是否已被行使。
A11: 3.如果监盘的电子存单，应记录现场电子存单的获取过程，包括企业有权限人员登录网银平台查询、下载等操作过程等。
A12: 银行存单原件记载（或开户证明、银行代保管证明等） | I12: 是否与账面记录核对一致 | J12: 不一致的情况描述 | K12: 是否抵押、质押受限 | L12: 银行存单原件索引号 | M12: 开户证明索引号 | N12: 银行代保管证明索引号 | O12: 备注
A13: 开户银行（或机构） | B13: 账号 | C13: 币种 | D13: 户名 | E13: 存入日期 | F13: 到期日 | G13: 金额 | H13: …
A20: 出纳： | B20: 日期： | D20: 会计主管人员： | G20: 日期： | K20: 监盘人： | N20: 日期：
A21: 三、审计说明：
A22: 1.经检查核对，以上所列存单报告日余额与被审计单位报告日账面余额一致；
A23: 2.以上所列存单存在的抵押或限制使用情况已在财务报告附注予以恰当披露；
A24: 3.对于以上所列存单存户名与被审计单位不一致的情况应查明原因，实施进一步审计程序，并考虑是否存在舞弊风险。
A26: 四、审计结论：
A28: 提示：
A29: 1.对已质押的定期存款，检查定期存单复印件、质押回单，并与相应的质押合同核对，核对存款人、金额、期限等相关信息。对于质押借款的定期存单，关注定期存单对应的质押借款有无入账，
A30: 对于超过借款期限但仍处于质押状态的定期存款，还应关注相关借款的偿还情况，了解相关质权是否已被行使；对于为他人担保的定期存单，关注担保是否逾期及相关质权是否已被行使；
A31: 2.对未质押的定期存款，应检查开户证实书原件而非复印件，以防止被审计单位提供的复印件是未质押或未提现前原件的复印件，特别关注被审计单位在定期存单到期之前，是否存在先质押贷款
A32: 或提前套现，再用质押贷款所得货币资金或套取的货币资金虚增收入、或挪作他用或从事其他违规业务。在检查时需认真核对相关信息，包括存款人、金额、期限等，如有异常，需实施进一步审计程序；
A33: 3.根据《中国注册会计师审计准则问题解答第18号——识别和应对第三方配合实施财务舞弊》：货币资金舞弊通常与收入舞弊、关联方资金占用及违规担保相联系，关注被审计单位以定期存款质押的方式为关联方提供担保，关联方取得借款后用于货款回笼。

Sheet 已开立银行账户清单核对表E1-10
A1: 致同会计师事务所
A2: 已开立银行账款清单核对表
A3: =底稿目录!A2 -> 被审计单位： | C3: =底稿目录!A4 -> 编制人： | F3: =底稿目录!A5 -> 编制日期： | J3: 索引号： | K3: =底稿目录!F16 -> E1-10 | L3: IPO/上市/新三板/重组/对银行账账户存在疑虑时，应直接完成底稿<E1-29>
A4: =底稿目录!A3 -> 截止日：202X年12月31日 | C4: =底稿目录!A6 -> 复核人： | F4: =底稿目录!A7 -> 复核日期： | J4: 页次：
A5: 一、审计目标:
A6: 1.资产负债表中记录的货币资金是存在的，且已记录于恰当的账户；2.所有应当记录的货币资金均已记录，所有应当包括在财务报表中的相关披露均已包括；
A7: 3.记录的货币资金由被审计单位拥有或控制
A8: 二、审计程：
A9: 在企业人员陪同下到人民银行或基本存款账户开户行查询并打印《已开立银行结算账户清单》，观察银行办事人员的查询、打印过程，并检查被审计单位账面记录的银行人民币结算账户是否完整
A10: （一）已开立银行结算账户清单与账面核对：
A11: 序号 | B11: 已开立银行结算账户清单 | H11: 开户原因 | I11: 销户原因 | J11: 与企业信息核对一致 | K11: 不一致原因
B12: 开户银行名称 | C12: 账号 | D12: 账户性质 | E12: 账户状态 | F12: 开户日期 | G12: 销户日期
A13: 1
A14: 2
A15: ……
A24: 三、审计说明：
A27: 四、审计结论：
A29: 提示：
A30: 1.应询问办理货币资金业务的相关人员（如出纳），了解银行账户的开立、使用、注销等情况。
A31: 2.如果对被审计单位银行账户的完整性存有疑虑，应亲自到人民银行或基本存款账户开户行查询并打印《已开立银行结算账户清单》，以确认被审计单位账面记录的银行账户是否完整。
A32: 3.结合企业信用报告，核对开户信息。
A33: 4.结合其他相关细节测试，关注交易相关单据中被审计单位的收（付）款银行账户是否均包含在注册会计师已获取的开立银行账户清单内。
A34: 5.如果对被审计单位外币银行账户的完整性存有疑虑，可以查阅被审计单位的公章使用登记，检查其中是否有使用公章申请开户的情况，如有，检查该账户是否已列入被审计单位提供的银行账户清单中。或者向负责保管网银密钥（UKey）的人员获取被审计单位开通网银的账户清单，实地观察该人员登录被审计单位网银系统，打印相关银行开立的所有银行账户清单，并与被审计单位管理层提供的信息进行比较，以检查其完整性如可行，注册会计师可以考虑与被审计单位人员一同前往被审计单位所在地人民银行外汇管理局，现场查询被审计单位的外币银行账户情况。
A35: 6.对于使用个人账户代替被审计单位账户发生经济业务的，应考虑获取该账户户主与被审计单位的书面声明，并考虑资产负载表日是否需要调整。
A36: 7.根据《中国注册会计师审计准则问题解答第18号——识别和应对第三方配合实施财务舞弊》：关注被审计单位及其控股股东是否与银行签订现金管理账户协议，将被审计单位
A37: 的银行账户作为子账户向控股股东集团账户自动归集（参见《中国注册会计师审计准则问题解答第12号——货币资金审计》），实现控股股东对被审计单位的资金占用。

Sheet 银行账户情况承诺E1-11
A1: 致同会计师事务所
A2: 银行账户清单完整性承诺
A3: =底稿目录!A2 -> 被审计单位： | C3: =底稿目录!A4 -> 编制人： | D3: =底稿目录!A5 -> 编制日期： | F3: 索引号： | G3: =底稿目录!F17 -> E1-11
A4: =底稿目录!A3 -> 截止日：202X年12月31日 | C4: =底稿目录!A6 -> 复核人： | D4: =底稿目录!A7 -> 复核日期： | F4: 页次：
A5: 关于银行账户清单完整性的管理层承诺函
A6: 致：致同会计师事务所（特殊普通合伙）
A7: 本公司（XXX公司）截止20XX年X月X日只在一家银行开立基本账户，所有银行账户记录均已反映在提供给贵公司的账簿中，本公司无账外账户存在，也不存在借用其他公司账户使用及将本公司银行账户借与他人使用的情况。
A9: 截至 20XX年X月X日止，本公司所有银行账户如下：
A10: 开户银行名称 | B10: 银行账号 | C10: 账户性质 | D10: 开户日期 | E10: 销户日期 | F10: 目前状态 | G10: 冻结、抵押、质押情况
D20: （公司盖章）
E22: 声明日期： 年 月 日
A25: 提示：
A26: 项目组根据项目风险进行判断，针对首次承接、IPO/上市公司/新三板/再融资/存在舞弊风险的项目，如果有外币账户或境外开户，需取得银行账户情况承诺；其他项目可以由项目合伙人判断确定执行的方式，例如在管理层声明书中增加条款或账户清单作为附件等。
