Workbook
Name OLE_LINK1: 货币资金实质性程序表E26A!#REF!
Name OLE_LINK2: 货币资金实质性程序表E26A!#REF!

Sheet 底稿目录
A1: 底稿开列时，可先在以下单元格填写有关内容，以便其他底稿引用有关数据：
A2: 被审计单位： | D2: 序号 | E2: 内容 | F2: 索引号 | G2: 备注
A3: 截止日：202X年12月31日 | D3: 1 | E3: 货币资金实质性程序表 | F3: E1-26A
A4: 编制人： | D4: 2 | E4: 现金交易分析 | F4: E1-26
A5: 编制日期： | D5: 3 | E5: 现金截止测试 | F5: E1-27
A6: 复核人： | D6: 3 | E6: 现金收支检查表 | F6: E1-28
A7: 复核日期： | D7: 3 | E7: 银行账户分析 | F7: E1-29
D8: 4 | E8: 存款规模与利息收入匹配性分析 | F8: E1-30
D9: 5 | E9: 银行流水双向核对表 | F9: E1-31
D10: 5 | E10: 董监高及关键岗位流水核查 | F10: E1-32
D11: 6 | E11: 自定义底稿 | F11: E1-33
D12: 7 | E12: 自定义底稿 | F12: E1-34

Sheet 货币资金实质性程序表E26A
A1: 致同会计师事务所
A2: 货币资金实质性程序表
A3: =底稿目录!A2 -> 被审计单位： | D3: =底稿目录!A4 -> 编制人： | F3: =底稿目录!A5 -> 编制日期： | I3: 索引号： | J3: =底稿目录!F3 -> E1-26A
A4: =底稿目录!A3 -> 截止日：202X年12月31日 | D4: =底稿目录!A6 -> 复核人： | F4: =底稿目录!A7 -> 复核日期： | I4: 页次
A5: 一、本账户涉及的科目
A6: 货币资金
A7: 二、审计目标与认定对应关系
A8: 审计目标 | H8: 财务报表的认定
A9: A.资产负债表中记录的货币资金是存在的，且已记录于恰当的账户 | H9: 存在
A10: B.所有应当记录的货币资金均已记录，所有应当包括在财务报表中的相关披露均已包括 | H10: 完整性
A11: C.记录的货币资金由被审计单位拥有或控制 | H11: 权利和义务
A12: D.货币资金以恰当的金额包括在财务报表中，与之相关的计价或分摊调整已恰当记录，相关披露已得到恰当计量和描述 | H12: 准确性、计价和分摊
A13: E.货币资金已被恰当地汇总或分解且表述清楚，相关披露在按照企业会计准则的编制基础下是相关的、可理解的 | H13: 列报
A14: 三、计划实施的实质性程序
A15: 序号 | B15: 对应LEAP程序 | C15: 审计程序 | D15: 程序分类 | E15: 财务报表的认定 | J15: 底稿索引号
E16: 存在 | F16: 完整性 | G16: 权利和义务 | H16: 准确性、计价和分摊 | I16: 列报 | K16: 根据被审计单位实际情况和风险评估情况裁剪、修改或增加审计程序
A17: （一） | C17: 大额现金交易
A18: 1 | B18: 应对措施-实质性/非实质性分析程序 | C18: 分析现金交易的成因，与其所在行业常用的结算方式是否明显不同，判断其合理性，统计分析现金交易的总体情况： （1）逐月统计报告期内现金销售收（付）款金额，核查现金收（付）款异常波动的原因,根据被审计单位情况分层统计分析； （2）分析现金销售收款、采购付款的金额分布情况及两期对比；分析现金销售收入、采购付款涉及客户、供应商情况； （3）关注库存现金规模明显超过业务周转所需资金。 | D18: IPO/上市/新三板/重组/舞弊应对 | E18: √ | H18: √ | J18: E1-26
A19: 2 | B19: 应对措施-函证 | C19: 了解现金交易对方的情况，是否为关联方，结合销售或采购交易询证函，向主要的现金交易对方函证被审计期间内发生的交易金额。 | D19: IPO/上市/新三板/重组/舞弊应对 | E19: √ | F19: √ | H19: √ | J19: E0
A20: 3 | B20: 应对措施-检查 | C20: 实施现金截止测试，抽查资产负债表日前后若干天一定金额以上现金收支凭证进行检查，如果跨期收支事项，考虑是否应进行调整。 | D20: IPO/上市/新三板/重组/舞弊应对 | E20: √ | F20: √ | J20: E1-27
A21: 4 | B21: 应对措施-检查 | C21: 抽取样本检查大额现金收支交易，关注大额现金使用范围是否符合《现金管理暂行条例》的规定；检查现金销售和采购的原始凭证是否齐全，记账凭证与原始凭证是否记录一致，签字的付款方和收款方是否与合同/订单、验收单等一致，注重与其他外部证据核对是否一致；关注是否存在现金退回交易。 | D21: IPO/上市/新三板/重组/舞弊应对 | E21: √ | G21: √ | H21: √ | J21: E1-28
A22: 5 | B22: 应对措施-检查（选择“执行延申检查”） | C22: 结合客户或供应商走访程序，选取现金结算量较大的交易对方进行实地观察或询问，关注交易对方经营业务的性质、规模与收付款项的性质、规模是否一致。 | D22: IPO/上市/新三板/重组/舞弊应对 | E22: √ | F22: √ | H22: √
A23: （二） | C23: 银行存款
A24: 1 | B24: 常规程序 | C24: 询问相关人员，亲自到银行获取并打印《已开立银行结算账户清单》，检查被审计单位银行账户的完整性： （1）询问办理货币资金业务的相关人员（如出纳），了解银行账户的开立、使用、注销等情况。 （2）注册会计师亲自到人民银行或基本存款账户开户行查询并打印《已开立银行结算账户清单》，以确认被审计单位账面记录的银行账户是否完整。 （3）中国人民银行征信中心或开户行查询企业信用报告。 （4）检查公章使用登记簿和重要会议纪要。 （5）获取被审计单位已将全部银行存款账户信息提供给注册会计师的书面声明。 | D24: IPO/上市/新三板/重组/舞弊应对 | F24: √
A25: 2 | B25: 常规程序 | C25: 检查被审计单位银行账户是否存在异常： 了解报告期内被审计单位开立账户的数量及分布，与被审计单位实际经营的需要进行比较，核查是否在没有经营业务的地区开立银行账户，或将高额资金存放其经营和注册地之外的异地，是否存在频繁开户、销户等，银行账户开立数量与企业实际的业务规模不匹配等，关注是否存在越权开立账户等异常情形。 | D25: IPO/上市/新三板/重组/舞弊应对 | E25: √ | F25: √ | G25: √ | J25: E1-29
A26: 3 | B26: 应对措施-检查 | C26: 关注企业资金是否存放于管理层或员工个人账户，货币资金收支金额是否与现金流量表不匹配。 | D26: IPO/上市/新三板/重组/舞弊应对 | E26: √ | F26: √ | G26: √
A27: 4 | B27: 应对措施-实质性/非实质性分析程序 | C27: 测算银行存款当期累计日利息与利息收入是否匹配： 取得活期银行存款每日余额，按活期银行存款日利率测算每日利息；取得定期存款明细，按定期存款利率、存款期限测算每日利息；将测算的当期利息收入与账面利息收入核对是否一致。 | D27: IPO/上市/新三板/重组/舞弊应对 | E27: √ | F27: √ | H27: √ | J27: E1-30
A28: 5 | B28: 应对措施-检查 | C28: 亲自从被审计单位的主要/可疑的开户银行获得带有交易对手名称的详式银行对账单（银行流水电子版或打印版），并执行双向核对测试，检查交易对手、金额、业务内容、印章等是否一致： （1）从银行日记账借贷方发生额中选取大额/异常记录，追查至银行对账单（流水）及相关支持性文件； （2）从银行对账单（流水）中选取大额/异常流入、流出记录，追查至账面记录及支持性文件； | D28: IPO/上市/新三板/重组/舞弊应对 | E28: √ | F28: √ | H28: √ | J28: E1-31
A29: 6 | B29: 应对措施-检查 | C29: 控股股东、实际控制人、发行人主要关联方、董事、监事、高管、关键岗位人员及其他关联方资金流水核查： （1）获取资金流水核查范围的全部银行账户流水，并取得银行账户信息完整性承诺函； （2）核查资金流水中的交易对手存在与被审计单位、被审计单位的客户和供应商、与被审计单位相同的其他交易对手、频繁或大额存现/取现等异常交易。 | D29: IPO/上市/新三板/重组/舞弊应对 | F29: √ | I29: √ | J29: E1-32

Sheet 现金交易分析E1-26
A1: 致同会计师事务所
A2: 现金交易分析表
A3: =底稿目录!A2 -> 被审计单位： | E3: =底稿目录!A4 -> 编制人： | I3: =底稿目录!A5 -> 编制日期： | L3: 索引号： | M3: =底稿目录!F4 -> E1-26
A4: =底稿目录!A3 -> 截止日：202X年12月31日 | E4: =底稿目录!A6 -> 复核人： | I4: =底稿目录!A7 -> 复核日期： | L4: 页次：
A5: 一、审计目标：
A6: 1.资产负债表中记录的货币资金是存在的，且已记录于恰当的账户；
A7: 2.货币资金以恰当的金额包括在财务报表中，与之相关的计价或分摊调整已恰当记录，相关披露已得到恰当计量和描述
A8: 二、审计过程：
A9: （一）现金销售收款、采购付款的总体情况
A10: 现金销售收款的总体情况 | G10: 现金采购付款的总体情况 | M10: 备注
A11: 月份 | B11: 本期金额 | C11: 上期金额 | E11: 本期变动 | F11: 上期变动 | G11: 月份 | H11: 本期金额 | I11: 上期金额 | K11: 本期变动 | L11: 上期变动
A12: 1 | E12: =IF(AND(B12=0,C12=0),0,IF(AND(B12>0,C12=0),1,(B12-C12)/C12)) -> 0 | F12: =IF(AND(C12=0,D12=0),0,IF(AND(C12>0,D12=0),1,(C12-D12)/D12)) -> 0 | G12: 1 | K12: =IF(AND(H12=0,I12=0),0,IF(AND(H12>0,I12=0),1,(H12-I12)/I12)) -> 0 | L12: =IF(AND(I12=0,J12=0),0,IF(AND(I12>0,J12=0),1,(I12-J12)/J12)) -> 0
A13: 2 | E13: =IF(AND(B13=0,C13=0),0,IF(AND(B13>0,C13=0),1,(B13-C13)/C13)) -> 0 | F13: =IF(AND(C13=0,D13=0),0,IF(AND(C13>0,D13=0),1,(C13-D13)/D13)) -> 0 | G13: 2 | K13: =IF(AND(H13=0,I13=0),0,IF(AND(H13>0,I13=0),1,(H13-I13)/I13)) -> 0 | L13: =IF(AND(I13=0,J13=0),0,IF(AND(I13>0,J13=0),1,(I13-J13)/J13)) -> 0
A14: 3 | E14: =IF(AND(B14=0,C14=0),0,IF(AND(B14>0,C14=0),1,(B14-C14)/C14)) -> 0 | F14: =IF(AND(C14=0,D14=0),0,IF(AND(C14>0,D14=0),1,(C14-D14)/D14)) -> 0 | G14: 3 | K14: =IF(AND(H14=0,I14=0),0,IF(AND(H14>0,I14=0),1,(H14-I14)/I14)) -> 0 | L14: =IF(AND(I14=0,J14=0),0,IF(AND(I14>0,J14=0),1,(I14-J14)/J14)) -> 0
A15: 4 | E15: =IF(AND(B15=0,C15=0),0,IF(AND(B15>0,C15=0),1,(B15-C15)/C15)) -> 0 | F15: =IF(AND(C15=0,D15=0),0,IF(AND(C15>0,D15=0),1,(C15-D15)/D15)) -> 0 | G15: 4 | K15: =IF(AND(H15=0,I15=0),0,IF(AND(H15>0,I15=0),1,(H15-I15)/I15)) -> 0 | L15: =IF(AND(I15=0,J15=0),0,IF(AND(I15>0,J15=0),1,(I15-J15)/J15)) -> 0
A16: 5 | E16: =IF(AND(B16=0,C16=0),0,IF(AND(B16>0,C16=0),1,(B16-C16)/C16)) -> 0 | F16: =IF(AND(C16=0,D16=0),0,IF(AND(C16>0,D16=0),1,(C16-D16)/D16)) -> 0 | G16: 5 | K16: =IF(AND(H16=0,I16=0),0,IF(AND(H16>0,I16=0),1,(H16-I16)/I16)) -> 0 | L16: =IF(AND(I16=0,J16=0),0,IF(AND(I16>0,J16=0),1,(I16-J16)/J16)) -> 0
A17: 6 | E17: =IF(AND(B17=0,C17=0),0,IF(AND(B17>0,C17=0),1,(B17-C17)/C17)) -> 0 | F17: =IF(AND(C17=0,D17=0),0,IF(AND(C17>0,D17=0),1,(C17-D17)/D17)) -> 0 | G17: 6 | K17: =IF(AND(H17=0,I17=0),0,IF(AND(H17>0,I17=0),1,(H17-I17)/I17)) -> 0 | L17: =IF(AND(I17=0,J17=0),0,IF(AND(I17>0,J17=0),1,(I17-J17)/J17)) -> 0
A18: 7 | E18: =IF(AND(B18=0,C18=0),0,IF(AND(B18>0,C18=0),1,(B18-C18)/C18)) -> 0 | F18: =IF(AND(C18=0,D18=0),0,IF(AND(C18>0,D18=0),1,(C18-D18)/D18)) -> 0 | G18: 7 | K18: =IF(AND(H18=0,I18=0),0,IF(AND(H18>0,I18=0),1,(H18-I18)/I18)) -> 0 | L18: =IF(AND(I18=0,J18=0),0,IF(AND(I18>0,J18=0),1,(I18-J18)/J18)) -> 0
A19: 8 | E19: =IF(AND(B19=0,C19=0),0,IF(AND(B19>0,C19=0),1,(B19-C19)/C19)) -> 0 | F19: =IF(AND(C19=0,D19=0),0,IF(AND(C19>0,D19=0),1,(C19-D19)/D19)) -> 0 | G19: 8 | K19: =IF(AND(H19=0,I19=0),0,IF(AND(H19>0,I19=0),1,(H19-I19)/I19)) -> 0 | L19: =IF(AND(I19=0,J19=0),0,IF(AND(I19>0,J19=0),1,(I19-J19)/J19)) -> 0
A20: 9 | E20: =IF(AND(B20=0,C20=0),0,IF(AND(B20>0,C20=0),1,(B20-C20)/C20)) -> 0 | F20: =IF(AND(C20=0,D20=0),0,IF(AND(C20>0,D20=0),1,(C20-D20)/D20)) -> 0 | G20: 9 | K20: =IF(AND(H20=0,I20=0),0,IF(AND(H20>0,I20=0),1,(H20-I20)/I20)) -> 0 | L20: =IF(AND(I20=0,J20=0),0,IF(AND(I20>0,J20=0),1,(I20-J20)/J20)) -> 0
A21: 10 | E21: =IF(AND(B21=0,C21=0),0,IF(AND(B21>0,C21=0),1,(B21-C21)/C21)) -> 0 | F21: =IF(AND(C21=0,D21=0),0,IF(AND(C21>0,D21=0),1,(C21-D21)/D21)) -> 0 | G21: 10 | K21: =IF(AND(H21=0,I21=0),0,IF(AND(H21>0,I21=0),1,(H21-I21)/I21)) -> 0 | L21: =IF(AND(I21=0,J21=0),0,IF(AND(I21>0,J21=0),1,(I21-J21)/J21)) -> 0
A22: 11 | E22: =IF(AND(B22=0,C22=0),0,IF(AND(B22>0,C22=0),1,(B22-C22)/C22)) -> 0 | F22: =IF(AND(C22=0,D22=0),0,IF(AND(C22>0,D22=0),1,(C22-D22)/D22)) -> 0 | G22: 11 | K22: =IF(AND(H22=0,I22=0),0,IF(AND(H22>0,I22=0),1,(H22-I22)/I22)) -> 0 | L22: =IF(AND(I22=0,J22=0),0,IF(AND(I22>0,J22=0),1,(I22-J22)/J22)) -> 0
A23: 12 | E23: =IF(AND(B23=0,C23=0),0,IF(AND(B23>0,C23=0),1,(B23-C23)/C23)) -> 0 | F23: =IF(AND(C23=0,D23=0),0,IF(AND(C23>0,D23=0),1,(C23-D23)/D23)) -> 0 | G23: 12 | K23: =IF(AND(H23=0,I23=0),0,IF(AND(H23>0,I23=0),1,(H23-I23)/I23)) -> 0 | L23: =IF(AND(I23=0,J23=0),0,IF(AND(I23>0,J23=0),1,(I23-J23)/J23)) -> 0
A24: 合 计 | B24: =SUM(B12:B23) -> 0 | C24: =SUM(C12:C23) -> 0 | E24: =IF(AND(B24=0,C24=0),0,IF(AND(B24>0,C24=0),1,(B24-C24)/C24)) -> 0 | F24: =IF(AND(C24=0,D24=0),0,IF(AND(C24>0,D24=0),1,(C24-D24)/D24)) -> 0 | G24: 合 计 | H24: =SUM(H12:H23) -> 0 | I24: =SUM(I12:I23) -> 0 | K24: =IF(AND(H24=0,I24=0),0,IF(AND(H24>0,I24=0),1,(H24-I24)/I24)) -> 0 | L24: =IF(AND(I24=0,J24=0),0,IF(AND(I24>0,J24=0),1,(I24-J24)/J24)) -> 0
A25: 当期含税收入 | G25: 当期含税支出
A26: 月均金额 | G26: 月均金额
A27: 占当期比重 | G27: 占当期比重
A28: （二）现金销售、采购合理性分析
A29: 现金交易的原因、所在行业常用的结算方式、现金交易比例较高的合理性、是否与其业务性质相匹配？
A32: （三）现金销售收款、采购付款的金额分布情况
A33: 现金销售收款 | G33: 现金采购付款 | M33: 备注
A34: 项目 | B34: 本期金额 | C34: 上期金额 | E34: 本期变动 | F34: 上期变动 | G34: 项目 | H34: 本期金额 | I34: 上期金额 | K34: 本期变动 | L34: 上期变动
A35: 现金销售总额 | E35: =IF(AND(B35=0,C35=0),0,IF(AND(B35>0,C35=0),1,(B35-C35)/C35)) -> 0 | F35: =IF(AND(C35=0,D35=0),0,IF(AND(C35>0,D35=0),1,(C35-D35)/D35)) -> 0 | G35: 现金采购总额 | K35: =IF(AND(H35=0,I35=0),0,IF(AND(H35>0,I35=0),1,(H35-I35)/I35)) -> 0 | L35: =IF(AND(I35=0,J35=0),0,IF(AND(I35>0,J35=0),1,(I35-J35)/J35)) -> 0
A36: 现金销售笔数 | E36: =IF(AND(B36=0,C36=0),0,IF(AND(B36>0,C36=0),1,(B36-C36)/C36)) -> 0 | F36: =IF(AND(C36=0,D36=0),0,IF(AND(C36>0,D36=0),1,(C36-D36)/D36)) -> 0 | G36: 现金采购笔数 | K36: =IF(AND(H36=0,I36=0),0,IF(AND(H36>0,I36=0),1,(H36-I36)/I36)) -> 0 | L36: =IF(AND(I36=0,J36=0),0,IF(AND(I36>0,J36=0),1,(I36-J36)/J36)) -> 0
A37: 平均每笔金额 | E37: =IF(AND(B37=0,C37=0),0,IF(AND(B37>0,C37=0),1,(B37-C37)/C37)) -> 0 | F37: =IF(AND(C37=0,D37=0),0,IF(AND(C37>0,D37=0),1,(C37-D37)/D37)) -> 0 | G37: 平均每笔金额 | K37: =IF(AND(H37=0,I37=0),0,IF(AND(H37>0,I37=0),1,(H37-I37)/I37)) -> 0 | L37: =IF(AND(I37=0,J37=0),0,IF(AND(I37>0,J37=0),1,(I37-J37)/J37)) -> 0
A38: 其中： | E38: =IF(AND(B38=0,C38=0),0,IF(AND(B38>0,C38=0),1,(B38-C38)/C38)) -> 0 | F38: =IF(AND(C38=0,D38=0),0,IF(AND(C38>0,D38=0),1,(C38-D38)/D38)) -> 0 | G38: 其中： | K38: =IF(AND(H38=0,I38=0),0,IF(AND(H38>0,I38=0),1,(H38-I38)/I38)) -> 0 | L38: =IF(AND(I38=0,J38=0),0,IF(AND(I38>0,J38=0),1,(I38-J38)/J38)) -> 0
A39: 0~~A万元 | E39: =IF(AND(B39=0,C39=0),0,IF(AND(B39>0,C39=0),1,(B39-C39)/C39)) -> 0 | F39: =IF(AND(C39=0,D39=0),0,IF(AND(C39>0,D39=0),1,(C39-D39)/D39)) -> 0 | G39: 0~~A万元 | K39: =IF(AND(H39=0,I39=0),0,IF(AND(H39>0,I39=0),1,(H39-I39)/I39)) -> 0 | L39: =IF(AND(I39=0,J39=0),0,IF(AND(I39>0,J39=0),1,(I39-J39)/J39)) -> 0
A40: A~B万元 | E40: =IF(AND(B40=0,C40=0),0,IF(AND(B40>0,C40=0),1,(B40-C40)/C40)) -> 0 | F40: =IF(AND(C40=0,D40=0),0,IF(AND(C40>0,D40=0),1,(C40-D40)/D40)) -> 0 | G40: A~B万元 | K40: =IF(AND(H40=0,I40=0),0,IF(AND(H40>0,I40=0),1,(H40-I40)/I40)) -> 0 | L40: =IF(AND(I40=0,J40=0),0,IF(AND(I40>0,J40=0),1,(I40-J40)/J40)) -> 0
A41: …… | E41: =IF(AND(B41=0,C41=0),0,IF(AND(B41>0,C41=0),1,(B41-C41)/C41)) -> 0 | F41: =IF(AND(C41=0,D41=0),0,IF(AND(C41>0,D41=0),1,(C41-D41)/D41)) -> 0 | G41: …… | K41: =IF(AND(H41=0,I41=0),0,IF(AND(H41>0,I41=0),1,(H41-I41)/I41)) -> 0 | L41: =IF(AND(I41=0,J41=0),0,IF(AND(I41>0,J41=0),1,(I41-J41)/J41)) -> 0
E42: =IF(AND(B42=0,C42=0),0,IF(AND(B42>0,C42=0),1,(B42-C42)/C42)) -> 0 | F42: =IF(AND(C42=0,D42=0),0,IF(AND(C42>0,D42=0),1,(C42-D42)/D42)) -> 0 | K42: =IF(AND(H42=0,I42=0),0,IF(AND(H42>0,I42=0),1,(H42-I42)/I42)) -> 0 | L42: =IF(AND(I42=0,J42=0),0,IF(AND(I42>0,J42=0),1,(I42-J42)/J42)) -> 0
...

Sheet 现金截止测试E1-27
A1: 致同会计师事务所
A2: 库存现金截止测试
A3: =底稿目录!A2 -> 被审计单位： | C3: =底稿目录!A4 -> 编制人： | D3: =底稿目录!A5 -> 编制日期： | G3: 索引号： | H3: =底稿目录!F5 -> E1-27
A4: =底稿目录!A3 -> 截止日：202X年12月31日 | C4: =底稿目录!A6 -> 复核人： | D4: =底稿目录!A7 -> 复核日期： | G4: 页 次：
A5: 一、审计目标
A6: 1.资产负债表中记录的货币资金是存在的，且已记录于恰当的账户；
A7: 2.所有应当记录的货币资金均已记录，所有应当包括在财务报表中的相关披露均已包括。
A8: 二、审计过程
A9: 从现金日记账中抽取资产负债表日前（ ）天、后（ ）天，且金额大于 元的记账凭证，与收付款凭单以及其他原始凭单核对
A10: 提示：如果存在跨期舞弊风险或者所检查样本中发现有跨期的，应扩大测试期间和样本，甚至可以考虑将截止测试期间延长至审计报告日。同时考虑是否存在内控缺陷。
A11: 测试凭证内容 | F11: 收付款凭单日期 | G11: 其他原始凭单日期 | H11: 是否跨期
A12: 日期 | B12: 凭证编号 | C12: 业务内容 | D12: 借方金额 | E12: 贷方金额
A27: ——————截止日期：202X年12月31日——————
A45: 三、审计说明：
A47: 四、审计结论：

Sheet 现金收支检查表E1-28
A1: 致同会计师事务所
A2: 库存现金收支检查表
A3: =[1]底稿目录!A2 -> 被审计单位：ABC公司 | E3: =[1]底稿目录!A4 -> 编制人：张XX | J3: =[1]底稿目录!A5 -> 编制日期：2025-4-1 | S3: 索引号： | T3: =底稿目录!F6 -> E1-28
A4: =[1]底稿目录!A3 -> 截止日：202X年12月31日 | E4: =[1]底稿目录!A6 -> 复核人：李XX | J4: =[1]底稿目录!A7 -> 复核日期：2025-5-1 | S4: 页 次：
A5: 一、测试目标：
A6: 1.资产负债表中记录的货币资金是存在的，且已经记录在恰当的账户中；2.记录的货币资金由被审计单位拥有或控制；
A7: 3.货币资金以恰当的金额包括在财务报表中，与之相关的计价或分摊调整已恰当记录，相关披露已得到恰当计量和描述
A8: 二、样本选取标准与规模：
A9: 测试总体： | B9: 如现金借方发生额所有凭证共XX笔金额XX、贷方发生额所有凭证共XX笔金额XX | H9: 特定样本： | I9: XX金额以上（大额）、关联方/关联交易形成的款项、XX异常款项全部测试，共XX笔；
A10: 抽样总体： | B10: 测试总体扣除特定样本以外的样本，共XX笔、金额XX | H10: 确定的抽样样本量： | J10: 抽取XX笔 | K10: （如果使用了样本计算器计算样本量，样本量计算过程见<XX>底稿）
A11: 抽样方法： | B11: 随机选样/系统选样/货币单元抽样/随意选样（非统计抽样适用） | H11: 抽样过程： | I11: 使用IDEA（XX抽样工具）选择XX数量、金额XX的样本进行测试，抽样工具中的样本选择过程和结果见<XX>底稿
A12: 三、测试：
A13: 收入测试内容说明：1.原始凭证是否齐全；2.收款凭证记录信息与付款人、交款金额是否相符；3.账务处理是否正确；4.是否记录于恰当的会计期间；5.付款人是否与合同/订单等核对一致；6.……
A14: 支出测试内容说明：1.原始凭证是否齐全；2.付款凭证记录信息与收款人、支付方式是否相符；3.付款的授权审批手续是否齐全、签章完整；4.原始凭证具有合法的发票或依据；5.原始凭证的内容与付款凭证业务内容是否一致；6.账务处理是否正确；7.是否记录于恰当的会计期间；8.……
A15: 1.本期借方金额检查
A16: 所属科目 | B16: 日期 | C16: 凭证编号 | D16: 业务内容 | E16: 对方科目 | F16: 对方明细科目 | G16: 借方金额 | H16: 收据/收款单 | K16: 销售合同/协议/订单 | O16: 签收/验收单 | Q16: …… | R16: …… | S16: 索引号 | T16: 是否异常
H17: 日期 | I17: 付款人（需签字） | J17: 金额 | K17: 日期 | L17: 客户名称 | M17: 合同金额 | N17: 结算方式 | O17: 日期/编号 | P17: 签/验收人（需签字）
A40: 合计 | G40: =SUM(G18:G39) -> 0
A41: 2.本期贷方金额检查
A42: 所属科目 | B42: 日期 | C42: 凭证编号 | D42: 业务内容 | E42: 对方科目 | F42: 对方明细科目 | G42: 贷方金额 | H42: 付款审批单 | L42: 销售合同/协议/订单 | P42: 入库单/验收单 | R42: …… | S42: 索引号 | T42: 是否异常
H43: 日期/编号 | I43: 收款人 | J43: 支付方式 | K43: 是否经过恰当审批 | L43: 日期 | M43: 供应商名称 | N43: 合同金额 | O43: 结算方式 | P43: 日期/编号 | Q43: ……
A65: 合计 | G65: =SUM(G44:G64) -> 0
A66: 四、审计说明：
A67: 1.本期发生额、期末余额检查比例： | E67: 方向 | F67: 账面金额 | G67: 检查金额 | H67: 检查比例 | I67: 如果检查比例较低请扩大检查样本量或说明原因
E68: 本期借方 | F68: ='[2]现金明细表E1-2'!$C$22 -> 0 | G68: =G40 -> 0 | H68: =ROUND(G68/F68,4) -> #DIV/0!
E69: 本期贷方 | F69: ='[2]现金明细表E1-2'!$D$22 -> 0 | G69: =G65 -> 0 | H69: =ROUND(G69/F69,2) -> #DIV/0!
A70: 2.……
A71: 五、审计结论：
A72: 提示：
A73: 1.如涉及现金销售，检查销售合同、发货凭证、收款单证等原始凭证是否完整、一致，核对付款方和付款金额与合同、订单、出库单是否一致，以确定款项确实由客户支付；
A74: 2.如涉及现金采购，检查采购合同、入库单、采购发票、付款单证等原始凭证是否完整、一致，核对收款方和收款金额与合同、订单、入库单是否一致，以确定款项确实向供应商支付；
A75: 3.现金交易应根据行业特点注重外部证据的检查，例如：对于农业行业，针对农产品管理特点，可以获取质检报告、检验检疫合格证、采伐资质、由税务局代开发票的资料副本等外部信息，验证其交易真实性
A76: 4.检查被审计单位现金退回记录，了解退回原因，分析其合理性；与退货记录、发票、运输等相关原始单据进行核对，确定相关会计处理是否恰当。

Sheet 银行账户分析E1-29
A1: 致同会计师事务所
A2: 银行账户分析表
A3: =底稿目录!A2 -> 被审计单位： | E3: =底稿目录!A4 -> 编制人： | J3: =底稿目录!A5 -> 编制日期： | N3: 索引号： | O3: =底稿目录!F7 -> E1-29
A4: =底稿目录!A3 -> 截止日：202X年12月31日 | E4: =底稿目录!A6 -> 复核人： | J4: =底稿目录!A7 -> 复核日期： | N4: 页 次：
A5: 一、审计目标:
A6: 1.资产负债表中记录的货币资金是存在的，且已记录于恰当的账户；2.所有应当记录的货币资金均已记录，所有应当包括在财务报表中的相关披露均已包括；
A7: 3.记录的货币资金由被审计单位拥有或控制
A8: 二、审计过程：
A9: （一）已开立银行结算账户清单与账面核对：
A10: 在企业人员陪同下到人民银行或基本存款账户开户行查询并打印《已开立银行结算账户清单》，观察银行办事人员的查询、打印过程，并检查被审计单位账面记录的银行人民币结算账户是否完整
B11: 已开立银行结算账户清单 | H11: 开户原因 | I11: 销户原因 | J11: 与企业信息核对一致 | K11: 不一致原因 | L11: 账户开户地 | M11: 账户开户地是否有经济业务 | N11: 异地开户原因 | O11: 备注
A12: 序号 | B12: 开户银行名称 | C12: 账号 | D12: 账户性质 | E12: 账户状态 | F12: 开户日期 | G12: 销户日期
A13: 1
A14: 2
A15: 3
A16: 4
A17: 5
A18: 6
A19: 7
A20: 8
A21: 9
A22: 10
A23: ……
A25: （二）公司账户情况分析
B26: 项目 | C26: 2025年 | D26: 2024年 | E26: 2023年 | F26: 无经济业务地开户数量 | G26: 是否与业务规模匹配 | H26: 是否频繁开户 | I26: 是否频繁销户 | J26: 异常说明 | K26: 其他备注
A27: 1 | B27: 公司账户数量
A28: 2 | B28: 本期开户数量
A29: 3 | B29: 本期销户数量
A30: 4 | B30: 零余额账户数量
A31: 5 | B31: ……
A33: 三、审计说明：
A35: 四、审计结论：
A37: 提示：
A38: 1.应询问办理货币资金业务的相关人员（如出纳），了解银行账户的开立、使用、注销等情况。
A39: 2.结合企业信用报告，核对开户信息。
A40: 3.如果对被审计单位外币银行账户的完整性存有疑虑，可以查阅被审计单位的公章使用登记，检查其中是否有使用公章申请开户的情况，如有，检查该账户是否已列入被审计单位提供的银行账户清单中。或者向负责保管网银密钥（UKey）的人员获取被审计单位开通网银的账户清单，实地观察该人员登录被审计单位网银系统，打印相关银行开立的所有银行账户清单，并与被审计单位管理层提供的信息进行比较，以检查其完整性如可行，注册会计师可以考虑与被审计单位人员一同前往被审计单位所在地人民银行外汇管理局，现场查询被审计单位的外币银行账户情况。
A41: 4.对银行账户开立数量与企业实际的业务规模不匹配、在没有经营业务的地区开立银行账户、企业资金存放于管理层或员工个人账户等异常情形应重点关注是否存在舞弊
A42: 5.关注银行账户以下异常情形：
A43: （1）被审计单位以各种理由不配合注册会计师实施银行函证、不配合注册会计师至人民银行或基本户开户行打印《已开立银行结算账户清单》；
A44: （2）银行账户开立数量与企业实际的业务规模不匹配，或存在多个零余额账户且长期不注销；
...

Sheet 存款规模与利息收入匹配性分析E1-30
A1: 致同会计师事务所
A2: 存款规模与利息收入匹配性分析
A3: =底稿目录!A2 -> 被审计单位： | E3: =底稿目录!A4 -> 编制人： | I3: =底稿目录!A5 -> 编制日期： | R3: 索引号： | S3: =底稿目录!F8 -> E1-30
A4: =底稿目录!A3 -> 截止日：202X年12月31日 | E4: =底稿目录!A6 -> 复核人： | I4: =底稿目录!A7 -> 复核日期： | R4: 页 次
A5: 一、审计目标：
A6: 1.资产负债表中记录的货币资金是存在的，且已记录于恰当的账户；
A7: 2.所有应当记录的货币资金均已记录，所有应当包括在财务报表中的相关披露均已包括；
A8: 3.货币资金以恰当的金额包括在财务报表中，与之相关的计价或分摊调整已恰当记录，相关披露已得到恰当计量和描述
A9: 二、审计过程：
A10: 获取全部账号每日存款余额，根据利率计算全年利息收入，与账面实际利息收入核对
A11: 日期 | B11: 活期存款 | I11: 七天通知存款 | M11: 大额存单
B12: XX银行 | E12: XX银行 | H12: … | I12: XX银行 | L12: 利息收入 | M12: XX银行 | O12: XX银行 | Q12: 利息收入 | R12: … | S12: 利息收入合计
B13: 年利率 | E13: 年利率 | I13: 银行账号1 | J13: 年化利率 | K13: … | M13: 银行账号1 | N13: 年化利率 | O13: 银行账号1 | P13: 年化利率
B14: 银行账号1 | C14: 银行账号2 | D14: 利息收入 | E14: 银行账号1 | F14: 银行账号2 | G14: 利息收入
A15: 45658 | D15: =SUM(B15:C15)*$D$13/360 -> 0 | G15: =SUM(E15:F15)*$G$13/360 -> 0 | L15: =I15*J15/360 -> 0 | Q15: =(M15*N15+O15*P15)/360 -> 0 | S15: =D15+G15+L15+Q15 -> 0
A16: 45659 | D16: =SUM(B16:C16)*$D$13/360 -> 0 | G16: =SUM(E16:F16)*$G$13/360 -> 0 | L16: =I16*J16/360 -> 0 | Q16: =(M16*N16+O16*P16)/360 -> 0 | S16: =D16+G16+L16+Q16 -> 0
A17: 45660 | D17: =SUM(B17:C17)*$D$13/360 -> 0 | G17: =SUM(E17:F17)*$G$13/360 -> 0 | L17: =I17*J17/360 -> 0 | Q17: =(M17*N17+O17*P17)/360 -> 0 | S17: =D17+G17+L17+Q17 -> 0
A18: 45661 | D18: =SUM(B18:C18)*$D$13/360 -> 0 | G18: =SUM(E18:F18)*$G$13/360 -> 0 | L18: =I18*J18/360 -> 0 | Q18: =(M18*N18+O18*P18)/360 -> 0 | S18: =D18+G18+L18+Q18 -> 0
A19: 45662 | D19: =SUM(B19:C19)*$D$13/360 -> 0 | G19: =SUM(E19:F19)*$G$13/360 -> 0 | L19: =I19*J19/360 -> 0 | Q19: =(M19*N19+O19*P19)/360 -> 0 | S19: =D19+G19+L19+Q19 -> 0
A20: 45663 | D20: =SUM(B20:C20)*$D$13/360 -> 0 | G20: =SUM(E20:F20)*$G$13/360 -> 0 | L20: =I20*J20/360 -> 0 | Q20: =(M20*N20+O20*P20)/360 -> 0 | S20: =D20+G20+L20+Q20 -> 0
A21: 45664 | D21: =SUM(B21:C21)*$D$13/360 -> 0 | G21: =SUM(E21:F21)*$G$13/360 -> 0 | L21: =I21*J21/360 -> 0 | Q21: =(M21*N21+O21*P21)/360 -> 0 | S21: =D21+G21+L21+Q21 -> 0
A22: 45665 | D22: =SUM(B22:C22)*$D$13/360 -> 0 | G22: =SUM(E22:F22)*$G$13/360 -> 0 | L22: =I22*J22/360 -> 0 | Q22: =(M22*N22+O22*P22)/360 -> 0 | S22: =D22+G22+L22+Q22 -> 0
A23: 45666 | D23: =SUM(B23:C23)*$D$13/360 -> 0 | G23: =SUM(E23:F23)*$G$13/360 -> 0 | L23: =I23*J23/360 -> 0 | Q23: =(M23*N23+O23*P23)/360 -> 0 | S23: =D23+G23+L23+Q23 -> 0
A24: 45667 | D24: =SUM(B24:C24)*$D$13/360 -> 0 | G24: =SUM(E24:F24)*$G$13/360 -> 0 | L24: =I24*J24/360 -> 0 | Q24: =(M24*N24+O24*P24)/360 -> 0 | S24: =D24+G24+L24+Q24 -> 0
A25: 45668 | D25: =SUM(B25:C25)*$D$13/360 -> 0 | G25: =SUM(E25:F25)*$G$13/360 -> 0 | L25: =I25*J25/360 -> 0 | Q25: =(M25*N25+O25*P25)/360 -> 0 | S25: =D25+G25+L25+Q25 -> 0
A26: 45669 | D26: =SUM(B26:C26)*$D$13/360 -> 0 | G26: =SUM(E26:F26)*$G$13/360 -> 0 | L26: =I26*J26/360 -> 0 | Q26: =(M26*N26+O26*P26)/360 -> 0 | S26: =D26+G26+L26+Q26 -> 0
... A379: 46022 | D379: =SUM(B379:C379)*$D$13/360 -> 0 | G379: =SUM(E379:F379)*$G$13/360 -> 0 | L379: =I379*J379/360 -> 0 | Q379: =(M379*N379+O379*P379)/360 -> 0 | S379: =D379+G379+L379+Q379 -> 0
A380: 合计 | B380: —— | C380: —— | D380: =SUM(D15:D379) -> 0 | E380: —— | F380: —— | G380: =SUM(G15:G379) -> 0 | H380: —— | I380: —— | J380: —— | K380: —— | L380: =SUM(L15:L379) -> 0 | M380: —— | N380: —— | O380: —— | P380: —— | Q380: =SUM(Q15:Q379) -> 0 | R380: —— | S380: =SUM(S15:S379) -> 0
A382: 三、审计说明：
B383: 金额
A384: 测算利息收入 | B384: =S380 -> 0
A385: 账面利息收入
A386: 差异 | B386: =B384-B385 -> 0
A389: 四、审计结论：

Sheet 银行流水双向核对表E1-31
A1: 致同会计师事务所
A2: 银行流水双向核对表
A3: =[1]底稿目录!A2 -> 被审计单位：ABC公司 | E3: =[1]底稿目录!A4 -> 编制人：张XX | J3: =[1]底稿目录!A5 -> 编制日期：2025-4-1 | P3: 索引号： | Q3: =底稿目录!F9 -> E1-31
A4: =[1]底稿目录!A3 -> 截止日：202X年12月31日 | E4: =[1]底稿目录!A6 -> 复核人：李XX | J4: =[1]底稿目录!A7 -> 复核日期：2025-5-1 | P4: 页 次：
A5: 一、审计目标：
A6: 1.资产负债表中记录的货币资金是存在的，且已记录于恰当的账户； 2.所有应当记录的货币资金均已记录，所有应当包括在财务报表中的相关披露均已包括；
A7: 3.货币资金以恰当的金额包括在财务报表中，与之相关的计价或分摊调整已恰当记录，相关披露已得到恰当计量和描述
A8: 二、审计过程：
A9: 可运用事务所开发的银行流水核对系统进行全部样本进行核对，系统所在位置：致同内网-应用系统-致同审计效率工具-银行流水核查工具（识别+核对），可将系统的核对结果导出作为底稿，并进一步检查支持性文件
A10: 对获取银行对账单的过程的说明：
A11: 1、如果亲自到银行打印银行流水，应对纸质银行流水保持全过程控制，并记录：202X年XX月XX日，审计人员XX在被审计单位XX的陪同下前往XX银行，打印银行对账单后直接交给审计人员XX。
A12: 2、如果从获取的从网银中下载的电子版银行流水，应观察下载银行流水的全过程，防止被修改，并记录：202X年XX月XX日 XX点XX分，审计人员XX亲自现场观察被审计单位出纳XX登录XX银行XX账户并操作网银系统下载信息的过程，已观察网银中显示和下载的信息与提供给注册会计师对账单中信息一致，出纳XX下载银行对账单后现场直接以邮件方式发送给审计人员XX。
A13: 开户银行： | E13: 账号：
A14: （一）检查的银行对账单/流水发生额、余额与银行日记账核对
A15: 月 | B15: 银行对账单/流水 | E15: 银行日记账 | H15: 借方发生额 | J15: 贷方发生额 | L15: 余额
B16: 收入 | C16: 支出 | D16: 余额 | E16: 借方发生额 | F16: 贷方发生额 | G16: 余额 | H16: 差额 | I16: 差异率 | J16: 差额 | K16: 差异率 | L16: 差额 | M16: 差异率
A17: 1月 | H17: =B17-E17 -> 0 | I17: =H17/B17 -> #DIV/0! | J17: =C17-F17 -> 0 | K17: =J17/C17 -> #DIV/0! | L17: =D17-G17 -> 0 | M17: =L17/D17 -> #DIV/0!
A18: 2月 | H18: =B18-E18 -> 0 | I18: =H18/B18 -> #DIV/0! | J18: =C18-F18 -> 0 | K18: =J18/C18 -> #DIV/0! | L18: =D18-G18 -> 0 | M18: =L18/D18 -> #DIV/0!
A19: 3月 | H19: =B19-E19 -> 0 | I19: =H19/B19 -> #DIV/0! | J19: =C19-F19 -> 0 | K19: =J19/C19 -> #DIV/0! | L19: =D19-G19 -> 0 | M19: =L19/D19 -> #DIV/0!
A20: 4月 | H20: =B20-E20 -> 0 | I20: =H20/B20 -> #DIV/0! | J20: =C20-F20 -> 0 | K20: =J20/C20 -> #DIV/0! | L20: =D20-G20 -> 0 | M20: =L20/D20 -> #DIV/0!
A21: 5月 | H21: =B21-E21 -> 0 | I21: =H21/B21 -> #DIV/0! | J21: =C21-F21 -> 0 | K21: =J21/C21 -> #DIV/0! | L21: =D21-G21 -> 0 | M21: =L21/D21 -> #DIV/0!
A22: 6月 | H22: =B22-E22 -> 0 | I22: =H22/B22 -> #DIV/0! | J22: =C22-F22 -> 0 | K22: =J22/C22 -> #DIV/0! | L22: =D22-G22 -> 0 | M22: =L22/D22 -> #DIV/0!
A23: 7月 | H23: =B23-E23 -> 0 | I23: =H23/B23 -> #DIV/0! | J23: =C23-F23 -> 0 | K23: =J23/C23 -> #DIV/0! | L23: =D23-G23 -> 0 | M23: =L23/D23 -> #DIV/0!
A24: 8月 | H24: =B24-E24 -> 0 | I24: =H24/B24 -> #DIV/0! | J24: =C24-F24 -> 0 | K24: =J24/C24 -> #DIV/0! | L24: =D24-G24 -> 0 | M24: =L24/D24 -> #DIV/0!
A25: 9月 | H25: =B25-E25 -> 0 | I25: =H25/B25 -> #DIV/0! | J25: =C25-F25 -> 0 | K25: =J25/C25 -> #DIV/0! | L25: =D25-G25 -> 0 | M25: =L25/D25 -> #DIV/0!
A26: 10月 | H26: =B26-E26 -> 0 | I26: =H26/B26 -> #DIV/0! | J26: =C26-F26 -> 0 | K26: =J26/C26 -> #DIV/0! | L26: =D26-G26 -> 0 | M26: =L26/D26 -> #DIV/0!
A27: 11月 | H27: =B27-E27 -> 0 | I27: =H27/B27 -> #DIV/0! | J27: =C27-F27 -> 0 | K27: =J27/C27 -> #DIV/0! | L27: =D27-G27 -> 0 | M27: =L27/D27 -> #DIV/0!
A28: 12月 | H28: =B28-E28 -> 0 | I28: =H28/B28 -> #DIV/0! | J28: =C28-F28 -> 0 | K28: =J28/C28 -> #DIV/0! | L28: =D28-G28 -> 0 | M28: =L28/D28 -> #DIV/0!
A29: 合计 | B29: =SUM(B17:B28) -> 0 | C29: =SUM(C17:C28) -> 0 | E29: =SUM(E17:E28) -> 0 | F29: =SUM(F17:F28) -> 0 | H29: =B29-E29 -> 0 | I29: =H29/B29 -> #DIV/0! | J29: =C29-F29 -> 0 | K29: =J29/C29 -> #DIV/0!
A31: （二）从银行日记账记录检查至银行流水/对账单 | F31: 大额的检查标准：大于______元
A32: 检查原因 | B32: 记账凭证 | I32: 银行对账单 | M32: 信息是否核对一致 | N32: 是否存在第三方回款/付款 | O32: 不一致原因 | P32: 支持性文件（描述具体支持性文件名称） | Q32: 核查结论
B33: 日期 | C33: 凭证号 | D33: 业务内容 | E33: 对方科目 | F33: 往来单位 | G33: 借方金额 | H33: 贷方金额 | I33: 收款/付款日期 | J33: 摘要/附言 | K33: 收款方/付款方 | L33: 收入/支付金额
A34: 大额
A35: 关联交易
A36: 双向交易
A55: ……
A57: 合计 | G57: =SUM(G34:G56) -> 0 | H57: =SUM(H34:H56) -> 0 | L57: =SUM(L34:L56) -> 0
A59: （三）从银行流水/对账单检查至银行存款日记账 | F59: 大额的检查标准：大于______元
A60: 检查原因 | B60: 银行对账单 | F60: 记账凭证 | M60: 信息是否核对一致 | N60: 是否存在第三方回款/付款 | O60: 不一致原因 | P60: 支持性文件（描述具体支持性文件名称） | Q60: 核查结论
B61: 收款/付款日期 | C61: 摘要/附言 | D61: 收款方/付款方 | E61: 收入/支付金额 | F61: 日期 | G61: 凭证号 | H61: 业务内容 | I61: 对方科目 | J61: 往来单位 | K61: 借方金额 | L61: 贷方金额
...

Sheet 董监高及关键岗位流水核查E1-32
A1: 致同会计师事务所
A2: 董监高关键岗位人员及其他关联方资金流水核查
A3: =底稿目录!A2 -> 被审计单位： | H3: =底稿目录!A4 -> 编制人： | K3: =底稿目录!A5 -> 编制日期： | Q3: 索引号： | R3: =底稿目录!F10 -> E1-32
A4: =底稿目录!A3 -> 截止日：202X年12月31日 | H4: =底稿目录!A6 -> 复核人： | K4: =底稿目录!A7 -> 复核日期： | Q4: 页 次
A5: 一、审计目标：
A6: 所有应当记录的货币资金均已记录，所有应当包括在财务报表中的相关披露均已包括
A7: 二、审计过程：
A8: 可运用事务所开发的银行流水核对系统进行全部样本进行核对，系统所在位置：致同内网-应用系统-致同审计效率工具-银行流水核查工具（识别+核对），可将系统的核对结果导出作为底稿，并进一步检查支持性文件
A9: 姓名： | D9: 职位：
A10: 序号 | B10: 账号 | C10: 开户行 | D10: 账号/卡号 | E10: 卡片类型 | F10: 交易日期 | G10: 币种 | H10: 摘要 | I10: 收入金额 | J10: 支出金额 | K10: 对方户名 | L10: 对方账号 | M10: 交易背景 | N10: 交易对手是否为被审计单位 | O10: 交易对手是否为被审计单位客户或供应商 | P10: 是否为被审计单位共同的其他交易对手 | Q10: 其他异常 | R10: 备注
A11: 1
A12: 2
A13: 3
A14: 4
A15: 5
A16: 6
A17: 7
A18: 8
A19: 9
A20: 10
A21: 11
A22: 12
... A30: 20
A31: ……
A33: 合计 | I33: =SUM(I11:I32) -> 0 | J33: =SUM(J11:J32) -> 0
A34: 三、审计说明：
A36: 四、审计结论：
