Workbook
Name DefsNoted: 'NS-1'!$B$27
Name DefsNoted: 'PE-3a'!$B$26
Name DefsNoted: 'PM-3'!$B$27
Name DefsNoted: 'PM-4b'!$B$36
Name DefsNoted: 'PM-4c'!$B$20
Name DefsNoted: 'PM-4e'!$B$26
Name DefsNoted: 'PM-5'!$B$34
Name DefsNoted: 'PM-6'!$B$38
Name DefsNoted: 'SA-10'!$B$25
Name DefsNoted: 'SA-11'!$B$25
Name DefsNoted: 'SA-12'!$B$41
Name DefsNoted: 'SA-13'!$B$24
Name DefsNoted: 'SA-14'!$B$25
Name DefsNoted: 'SA-3'!$B$26
Name DefsNoted: 'SA-4c'!$B$20
Name DefsNoted: 'SA-5'!$B$30
Name DefsNoted: 'SA-7'!$B$35
Name DefsNoted: 'SA-9'!$B$39
Name Description: 'NS-1'!$B$2
Name Description: 'NS-3'!$B$2
Name Description: 'NS-4'!$B$2
Name Description: 'NS-5.2'!$B$2
Name Description: 'NS-5.3'!$B$2
Name Description: 'NS-5.4'!$B$2
Name Description: 'NS-6.1'!$B$2
Name Description: 'NS-6.2'!$B$2
Name Description: 'PE-3a'!$B$2
Name Description: 'PM-3'!$B$2
Name Description: 'PM-4b'!$B$2
Name Description: 'PM-4c'!$B$2
Name Description: 'PM-4e'!$B$2
Name Description: 'PM-5'!$B$2
Name Description: 'PM-6'!$B$2
Name Description: 'SA-10'!$B$2
Name Description: 'SA-11'!$B$2
Name Description: 'SA-12'!$B$2
Name Description: 'SA-13'!$B$2
Name Description: 'SA-14'!$B$2
Name Description: 'SA-3'!$B$2
Name Description: 'SA-4c'!$B$2
Name Description: 'SA-5'!$B$2
Name Description: 'SA-7'!$B$2
Name Description: 'SA-9'!$B$2
Name DesignConclusion: 'NS-1'!$C$7
Name DesignConclusion: 'NS-3'!$C$7
Name DesignConclusion: 'NS-4'!$C$7
Name DesignConclusion: 'NS-5.1'!$C$7
Name DesignConclusion: 'NS-5.2'!$C$7
Name DesignConclusion: 'NS-5.3'!$C$7
Name DesignConclusion: 'NS-5.4'!$C$7
Name DesignConclusion: 'NS-6.1'!$C$7
Name DesignConclusion: 'NS-6.2'!$C$7
Name DesignConclusion: 'PE-3a'!$C$7
Name DesignConclusion: 'PM-3'!$C$7
Name DesignConclusion: 'PM-4b'!$C$7
Name DesignConclusion: 'PM-4c'!$C$7
Name DesignConclusion: 'PM-4e'!$C$7
Name DesignConclusion: 'PM-5'!$C$7
Name DesignConclusion: 'PM-6'!$C$7
Name DesignConclusion: 'SA-10'!$C$7

Sheet C22 IT一般控制测试
A1: 致同会计师事务所
A2: IT一般控制测试
A3: 被审计单位：XX公司 | C3: 编制人：XXX | E3: 编制日期：XXX | I3: 索引号： | J3: C22
A4: 截止日：XXX | C4: 复核人：XXX | E4: 复核日期：XXX | I4: 页 次： | J4: 1
A5: 步骤：
A6: 1.根据了解的IT内控情况，选择每个应用程序、基础设施、信息技术流程等一般控制安全管理、程序维护、程序执行、新系统上线方面的关键控制
A7: 2.测试每个应用程序、基础设施、信息技术流程等的一般控制，并记录测试结果
A8: 3.根据上述信息完成以下表格：
A9: IT控制类别 | B9: 风险描述 | C9: 控制编号 | D9: 控制描述 | E9: 相关应用系统 | F9: 索引号（索引至<B22A-4-3 了解IT环境>） | G9: 设计有效性 测试结论 | H9: 执行有效性 测试结论 | I9: 是否发现异常 | J9: 缺陷编号
A10: 信息安全 | B10: ITR001 缺乏信息科技相关制度或因制度未及时更新而无法满足公司当前现状，无法确保流程规范化并得到自上而下的贯彻实施，从而无法确保相关操作都是按照相同的控制流程执行的。 | C10: SA-3 | D10: 安全管理的相关制度和流程被恰当记录、审批和下发。 | E10: A系统 B系统
A11: 信息安全 | B11: ITR002 用户具有超出履行其被分配职责所必需的访问特权，这可能导致不适当的职责分工。 | C11: SA-4c | D11: 特权级别的访问权限已获授权及受到适当限制，并进行恰当的职责分离。 | E11: A系统 B系统
A12: 信息安全 | B12: ITR002 用户具有超出履行其被分配职责所必需的访问特权，这可能导致不适当的职责分工。 | C12: SA-5 | D12: 新的及经修改的用户访问权限得到恰当审批和记录。 | E12: A系统 B系统
A13: 信息安全 | B13: ITR002 用户具有超出履行其被分配职责所必需的访问特权，这可能导致不适当的职责分工。 | C13: SA-7 | D13: 已离职和/或调职的用户的访问权限被及时取消或修改。 | E13: A系统 B系统
A14: 信息安全 | B14: ITR002 用户具有超出履行其被分配职责所必需的访问特权，这可能导致不适当的职责分工。 | C14: SA-9 | D14: 定期对用户访问权限进行复核。 | E14: A系统 B系统
A15: 信息安全 | B15: ITR003 系统未予以充分配置或更新以限定只有经恰当授权及适当的用户才具有系统的访问权限。 | C15: SA-10 | D15: 访问权限通过唯一的用户ID和密码或其他方法验证，以作为核实用户经授权获得系统访问权限的机制。密码参数符合公司和/或专业政策和准则（如，密码最短长度和复杂性、到期和账户锁定）。 | E15: A系统 B系统
A16: 信息安全 | B16: ITR004 通过应用程序事务以外的其他方式直接对业务和财务数据作出不适当的变更。 | C16: SA-11 | D16: 企业安装了统一的防病毒软件，服务器的病毒库被设定成及时、自动更新；客户端的配置被统一设定，且不能私自更改，以保证防病毒软件的有效运行及病毒库的及时更新。 | E16: A系统 B系统
A17: 信息安全 | B17: ITR004 通过应用程序事务以外的其他方式直接对业务和财务数据作出不适当的变更。 | C17: SA-12 | D17: 在系统中启用日志，并且定期对特权级别用户操作日志进行监控或审计以侦测未经授权或不适当的活动。 | E17: A系统 B系统
A18: 信息安全 | B18: ITR004 通过应用程序事务以外的其他方式直接对业务和财务数据作出不适当的变更。 | C18: SA-13 | D18: 关键电子表格以及共享文档的访问权限受到恰当限制。 | E18: A系统 B系统
A19: 信息安全 | B19: ITR002 用户具有超出履行其被分配职责所必需的访问特权，这可能导致不适当的职责分工。 | C19: SA-14 | D19: 公司高管在系统中的权限设置合理，仅有查询权限。 | E19: A系统 B系统
A20: 运行维护 | B20: ITR001 缺乏信息科技相关制度或因制度未及时更新而无法满足公司当前现状，无法确保流程规范化并得到自上而下的贯彻实施，从而无法确保相关操作都是按照相同的控制流程执行的。 | C20: PE-3a | D20: 信息系统运行维护的相关制度和流程被恰当记录、审批和下发。 | E20: A系统 B系统
A21: 运行维护 | B21: ITR005 生产系统、程序、和/或作业导致不准确、不完整、或未经授权的数据处理。 | C21: PE-3d | D21: 只有经授权的用户才有权更新作业调度软件中的批次作业，且进行恰当职责分离。 | E21: A系统 B系统
D22: 批处理作业任务或计划的修改被恰当记录和审批。 | E22: A系统 B系统
A23: 运行维护 | B23: ITR005 生产系统、程序、和/或作业导致不准确、不完整、或未经授权的数据处理。 | C23: PE-5 | D23: 监控关键系统、程序和/或作业及更正处理错误以确保成功完成。 | E23: A系统 B系统
A24: 运行维护 | B24: ITR006 在发生数据丢失时无法及时恢复或访问业务和财务数据。 | C24: PE-6 | D24: 业务数据、财务数据依照既定安排和频率定期进行备份（包括异地备份）； | E24: A系统 B系统
D25: 备份介质存放于具备适当安全措施的地点； | E25: A系统 B系统
D26: 定期对备份数据进行恢复性测试，并保留相关记录； | E26: A系统 B系统
D27: 制定灾难恢复计划与业务连续性计划，并对灾难恢复计划进行定期测试。 | E27: A系统 B系统
A28: 运行维护 | B28: ITR005 生产系统、程序、和/或作业导致不准确、不完整、或未经授权的数据处理。 | C28: PE-7 | D28: 企业建立了问题上报的制度以及处理流程，并且企业对受理的问题做出明确的问题处理纪录。 | E28: A系统 B系统
A29: 运行维护 | B29: ITR007 机房未经授权的访问，或非法访问不能被及时发现，可能为系统运行带来安全隐患；机房环境未被合理设定，可能使关键信息资源及设备被破坏，导致业务中断。 | C29: PE-8 | D29: 数据中心和计算机机房的物理访问权限适当限制在须获得相关访问权限以执行其被分配职责的人员。且数据中心的物理访问权限由管理层定期复核以核实访问权限仅授予经授权和适当的人员。 | E29: A系统 B系统
D30: 机房内配备必要的环境设施，如不间断电源、温控、湿控、烟感、非液体自动灭火装置、防静电地板、监控或闭路电视等；机房环境设施进行定期巡检，确保物理安全。 | E30: A系统 B系统
A31: 变更管理 | B31: ITR001 缺乏信息科技相关制度或因制度未及时更新而无法满足公司当前现状，无法确保流程规范化并得到自上而下的贯彻实施，从而无法确保相关操作都是按照相同的控制流程执行的。 | C31: PM-3 | D31: 变更管理的相关制度和流程被恰当记录、审批和下发。 | E31: A系统 B系统
A32: 变更管理 | B32: ITR008 对应用系统或包含相关自动化控制（即，配置设置、自动化运算法则、自动化计算、及自动化数据提取）和/或报告逻辑的程序作出不适当的变更。 | C32: PM-4c | D32: 对生产环境实施变更的权限受到适当限制，且进行恰当职责分离。 | E32: A系统 B系统
A33: 变更管理 | B33: ITR008 对应用系统或包含相关自动化控制（即，配置设置、自动化运算法则、自动化计算、及自动化数据提取）和/或报告逻辑的程序作出不适当的变更。 | C33: PM-4b | D33: 管理层定期复核具有修改生产环境权限的用户操作。 | E33: A系统 B系统
A34: 变更管理 | B34: ITR008 对应用系统或包含相关自动化控制（即，配置设置、自动化运算法则、自动化计算、及自动化数据提取）和/或报告逻辑的程序作出不适当的变更。 | C34: PM-4e | D34: 生产环境、测试环境、开发环境恰当分离。 | E34: A系统 B系统
A35: 变更管理 | B35: ITR008 对应用系统或包含相关自动化控制（即，配置设置、自动化运算法则、自动化计算、及自动化数据提取）和/或报告逻辑的程序作出不适当的变更。 | C35: PM-5 | D35: 所有的系统变更均被有效记录，系统变更管理工具的访问权限受到适当限制。 | E35: A系统 B系统
A36: 变更管理 | B36: ITR008 对应用系统或包含相关自动化控制（即，配置设置、自动化运算法则、自动化计算、及自动化数据提取）和/或报告逻辑的程序作出不适当的变更。 | C36: PM-6 | D36: 变更在移至生产环境前已获适当批准及已被测试。 | E36: A系统 B系统
A37: 系统开发 | B37: ITR001 缺乏信息科技相关制度或因制度未及时更新而无法满足公司当前现状，无法确保流程规范化并得到自上而下的贯彻实施，从而无法确保相关操作都是按照相同的控制流程执行的。 | C37: NS-1 | D37: 系统开发、采购、实施的相关制度和流程被恰当记录、审批和下发。 | E37: A系统 B系统
A38: 系统开发 | B38: ITR009 缺乏完善的系统开发控制流程，可能导致设计、编程不合理，无法按进度要求完成验收和上线过程，系统无法满足业务部门的业务需求。 | C38: NS-3 | D38: 生产环境、测试环境、开发环境恰当分离。 | E38: A系统 B系统
A39: 系统开发 | B39: ITR009 缺乏完善的系统开发控制流程，可能导致设计、编程不合理，无法按进度要求完成验收和上线过程，系统无法满足业务部门的业务需求。 | C39: NS-4 | D39: 企业成立项目开发管理小组，组织开发单位与内部各单位的日常沟通和协调，督促开发单位按照建设方案、计划进度和质量要求完成编程工作，对配备的硬件设备和系统软件进行检查验收，组织系统上线运行等。 | E39: A系统 B系统
A40: 系统开发 | B40: ITR009 缺乏完善的系统开发控制流程，可能导致设计、编程不合理，无法按进度要求完成验收和上线过程，系统无法满足业务部门的业务需求。 | C40: NS-5 | D40: 信息系统在投入使用前都进行了必要的测试，如整体测试、单元测试、用户接受测试、并行测试及压力测试等（其中前三项是必须进行的测试）。 | E40: A系统 B系统
...

Sheet SA-3
A1: 控制编号 | B1: ='C22 IT一般控制测试'!C10 -> SA-3
A2: 控制活动 | B2: ='C22 IT一般控制测试'!D10 -> 安全管理的相关制度和流程被恰当记录、审批和下发。
A4: 设计有效性标准审计程序 | C4: 设计有效性执行的审计程序
A5: 1、询问IT管理层，并了解以下内容： •公司是否制定了正式的信息系统安全管理制度/流程； •制度制定或修订的流程，以及相关审批和下发渠道 2、获取并检查相关信息系统安全管理制度，确认公司是否制定了信息系统安全管理制度，制度是否足够和完善。 | C5: 1.通过访谈公司（信息技术部总监），我们了解到： 1)公司制定了《信息安全管理办法》、《信息系统账号管理细则》、《计算机病毒防治管理细则》等安全管理制度； 2)公司信息管理制度由（信息技术部）制定，经公司（信息化工作委员会）审批后通过(OA系统)下发执行； 3）（信息技术部）每年定期对信息管理制定进行复核，并根据实际情况进行更新。 2.我们获取并检查了上述《信息安全管理办法》、《信息系统账号管理细则》、《计算机病毒防治管理细则》等制度规范，确认公司已建立较为完善的安全管理制度。
A6: 审计证据 | C6: 《信息安全管理办法》<C22.SA-3-1> 《信息系统账号管理细则》<C22.SA-3-2> 《计算机病毒防治管理细则》<C22.SA-3-3>
A7: 设计有效性测试结论 | C7: 有效
A10: 执行有效性测试（描述一个样本）
A11: 测试期间&样本总量 | B11: 控制类型：手工 发生频率：在需要时执行 样本总量：12 审计期间：202X.1.1-202X.12.31
A12: 抽样数量 | B12: 抽样数量：2
A13: 测试步骤 | B13: 执行有效性标准审计程序 | C13: 执行有效性执行的审计程序
A14: 1 | B14: 获取审计期间内新增、修订的安全管理制度清单并选取样本。对每一个所选取的样本，测试下述属性： | C14: 1.我们获取了公司信息系统管理制度清单，审计期间内共发生制度新增、修订12次，我们从中抽取样本并执行以下测试：
A15: 2 | B15: •制度的新增、修订由适当的管理层批准和/或提交 | C15: 2.通过获取并检查《信息安全管理办法审批记录》<C22.SA-3-4>,我们了解到，《信息安全管理办法》的修订由信息技术部执行，更新时间为2017年3月10日，并经由公司信息化工作委员会审批，审批时间为2017年3月11日。
A16: 3 | B16: • 经审批的制度由恰当的途径下发 | C16: 3.通过获取并查看公司《OA系统制度下发通知》<C22.SA-3-5>,我们了解到，《信息安全管理办法》经审批后，通过公司OA系统下发通知，并正式执行。
A17: 4 | B17: • 制度内容是更新或适用的 | C17: 4.通过获取并查看公司更新后的《信息安全管理办法》<C22.SA-3-1>，我们了解到，该管理制度针对安全访问管理进行了更新，符合公司管理现状。
A18: 执行有效性测试结论 | C18: 有效
A20: 样本记录（如果抽样数量>1，则在下表记录其余样本）
A21: 序号 | B21: 信息系统安全管理制度/流程 | C21: 更新时间 | D21: 审批时间 | E21: 审批人 | F21: 是否得到恰当下发 | G21: 制度/流程是最更新或适用的
A22: 1 | B22: 《信息系统账号管理细则》 | C22: 202X/10/30 | D22: 202X/10/31 | E22: 信息化工作委员会 | F22: 是，通过OA系统下发 | G22: 是
A23: ... | B23: ... | C23: ... | D23: ... | E23: ... | F23: ... | G23: ...
A25: 缺陷评估
A26: 是否发现异常 | B26: No
A27: 缺陷描述 | B27: N/A
A28: 索引至<C21-1> IT审计发现汇总表 | B28: N/A

Sheet SA-4c
A1: 控制编号 | B1: ='C22 IT一般控制测试'!C11 -> SA-4c
A2: 控制活动 | B2: ='C22 IT一般控制测试'!D11 -> 特权级别的访问权限已获授权及受到适当限制，并进行恰当的职责分离。
A4: 设计有效性标准审计程序 | C4: 设计有效性执行的审计程序
A5: 1、询问IT管理层公司针对特权级别访问权限（管理员账号、超级账号、特殊权限等）的管理情况，并了解以下内容： • 公司是否制定了正式的特权级别访问权限管理制度/流程； • 公司安全管理组织架构及特权级别访问权限的用户配置文件描述； • 有权限使用特权账号访问的个人； • 持有特权级别访问权限人员职责分离是否恰当。 2、获取并检查相关证据，确认公司特权级别访问权限管理是否恰当。 | C5: 1.通过访谈公司（信息部总监），我们了解到： 公司已制定《帐户安全管理规范》，其中规范系统管理员要求如下： 第六条 系统超级用户或具有超级权限的用户一般应保持唯一性，每年由信息技术部进行授权。应用系统管理员不得兼任数据库层面、操作系统层面管理员。当管理员离职或调职时，由管理员进行账号交接，需建立或变更应在OA系统中填写《系统账号变更》，经信息管理部总经理审批，并在合规与风控部备案。 2.我们获取并检查公司《账户安全管理规范》<C22.SA-4c-1>,确认公司针对超级账号管理恰当。
A6: 审计证据 | C6: 《账户安全管理规范》<C22.SA-4c-1>
A7: 设计有效性测试结论 | C7: 有效
A10: 执行有效性测试（描述一个样本）
A11: 测试期间&样本总量 | B11: 控制类型：手工 发生频率：在需要时执行 样本总量：1 审计期间：202X.1.1-202X.12.31
A12: 抽样数量 | B12: 抽样数量：1
A13: 测试步骤 | B13: 执行有效性标准审计程序 | C13: 执行有效性执行的审计程序
A14: 1 | B14: 获取准确及完整的应用程序及基础设施层面（包括操作系统、数据库）等特权级别访问权限用户清单，测试下述属性： （备注：当被审计单位使用堡垒机对审计范围内操作系统、数据库等层面用户进行访问控制管理时，需结合实际，考虑对堡垒机相关特权用户管理情况进行测试。） | C14: 1.在Oracle系统应用系统管理员XXX的协助下，我们获取了Oracle系统用户清单。通过查看《Oracle系统用户清单》<C22.SA-4c-2>，同时现场检查系统内各账号的实际权限配置，我们了解到：Oracle系统应用层面特权用户为系统管理员。 用户名：administator，实际使用人：郭强
A15: 2 | B15: •基于对管理层的询问，访问特权已获授权且对于用户被分配的职责而言是恰当的（列明验证访问权限的人员） | C15: 2.通过与信息管理部运行维护中心运行控制Oracle项目部经理徐楠的访谈，我们了解到： 上述员工拥有Oracle系统应用层面特权权限经过管理层授权，且对于用户被分配的职责而言是恰当的。
A16: 3 | B16: • 基于对相关工作职能的检查，访问特权已获授权且对于用户被分配的职责而言是恰当的（包括佐证性信息来源的索引，例如组织架构图） | C16: 3.通过查看《管理员授权书》<C22.SA-4c-3>的访谈，我们了解到： 上述员工拥有Oracle系统应用层面特权权限经过信息管理部运行维护中心运行控制Oracle项目部经理徐楠授权，且对于用户被分配的职责而言是恰当的，符合公司的组织架构图。
A17: 执行有效性测试结论 | C17: 有效
A19: 缺陷评估
A20: 是否发现异常 | B20: No
A21: 缺陷描述 | B21: N/A
A22: 索引至<C21-1> IT审计发现汇总表 | B22: N/A

Sheet SA-5
A1: 控制编号 | B1: ='C22 IT一般控制测试'!C12 -> SA-5
A2: 控制活动 | B2: ='C22 IT一般控制测试'!D12 -> 新的及经修改的用户访问权限得到恰当审批和记录。
A4: 设计有效性标准审计程序 | C4: 设计有效性执行的审计程序
A5: 1、询问IT管理层针对新的访问权限及访问权限的修改进行申请和批准的流程，并了解以下内容： • 公司是否制定了正式的用户访问权限制度或流程； • 负责批准访问权限的人员或团队； • 负责管理访问权限的人员或团队； • 用户访问权限申请如何进行提交、批准及记录； • 审批人和执行人是否进行恰当职责分离； 2、 获取政策、程序指引或其他证据以佐证控制的设计。 | C5: 1.通过访谈公司（信息技术部总监），我们了解到： 公司已制定《帐户安全管理规范》<C22.SA-4c-1>，其中规范用户权限审批要求如下： 第七条所有帐户的申请应由使用者填写《系统帐户申请表》，经申请者所在部门经理和帐户对应主管部门批准后，各系统/设备管理员方可开通相应帐户，申请中应标明该帐户所处权限级别。 第八条所有帐户的权限变更应由使用者填写《系统帐户权限变更表》，经申请者所在部门经理和帐户对应主管部门批准后，各系统/设备管理员方可修改帐户权限。 2.我们获取并检查公司《账户安全管理规范》<C22.SA-4c-1>,确认公司针对新的访问权限及访问权限的修改控制恰当。
A6: 审计证据 | C6: 《帐户安全管理规范》<C22.SA-4c-1>
A7: 设计有效性测试结论 | C7: 有效
A10: 执行有效性测试（描述一个样本）
A11: 测试期间&样本总量 | B11: 控制类型：手工 发生频率：在需要时执行 样本总量： 新增：A系统（应用系统97，操作系统8，数据库10）；B系统（应用系统97，操作系统8，数据库10） 修改：A系统（应用系统97，操作系统8，数据库10）；B系统（应用系统97，操作系统8，数据库10） 审计期间：202X.1.1-202X.12.31
A12: 抽样数量 | B12: 抽样数量： 新增：A系统（应用系统20，操作系统2，数据库2）；B系统（应用系统20，操作系统2，数据库2） 修改：A系统（应用系统20，操作系统2，数据库2）；B系统（应用系统20，操作系统2，数据库2）
A13: 测试步骤 | B13: 执行有效性标准审计程序 | C13: 执行有效性执行的审计程序
A14: 1 | B14: 获取拟依赖控制期间内应用程序及基础设施层面（包括操作系统、数据库）新增用户权限及用户权限更新的清单。基于其频率和与控制相关的风险，选取获得访问权限的用户样本。对每一个所选取的用户样本，测试下述属性： （备注：当被审计单位使用堡垒机对审计范围内操作系统、数据库等层面用户进行访问控制管理时，需结合实际，考虑对堡垒机相关特权用户管理情况进行测试。） | C14: 1.我们获取了《Oracle系统用户清单》<C22.SA-5-1>，通过检查账号清单，其中OPERATE_TIME字段为用户权限最后修改日期。 审计期间共发生用户新增及修改97次，我们从中抽取账号杨朔进行如下测试：
A15: 2 | B15: • 用户的访问权限申请由适当的管理层（即，授权的申请人）批准和/或提交 | C15: 2.我们获取并检查了该用户的《用户账号申请》<C22.SA-5-2>，我们了解到： 审批时间：2017-5-17 所在部门：收益部 使用者：杨朔 审批者：王雁飞（部门领导） 用户的访问权限申请由适当的管理层批准。
A16: 3 | B16: • 所申请的访问权限与系统授予的访问权限相符 | C16: 3.我们获取并查看了用户在系统内实际开通的权限<C22.SA-5-3>，我们了解到： 用户申请的权限为“通用查询(中等)、市场运力统计”，用户在系统中实际开通的权限为“通用查询(中等)、市场运力统计”。 用户在系统内实际开通的权限与申请的权限相同。
A17: 4 | B17: • 被授予的访问权限与用户职责相符，并实施适当的职责分工 | C17: 4.通过与系统管理员郭强访谈，我们了解到： 用户杨朔被授予的访问权限与其所在部门的职责相符，不存在冲突权限。
A18: 5 | B18: • 申请人、审批人和授予访问权限的人士之间保持适当的职责分工 | C18: 5.通过检查《用户账号申请》<C22.SA-5-2>，我们了解到： 申请者：杨朔（XX部门） 审批者：王雁飞（XX部门） 授予访问权限者：米兰（XX部门） 申请人、审批人和授予访问权限的人士之间保持适当的职责分工。
A19: 执行有效性测试结论 | C19: 有效
A21: 样本记录（如果抽样数量>1，则在下表记录其余样本）
A22: A系统
A23: 序号 | B23: 用户名 | C23: 账号开通/访问权限新增时间 | D23: 申请人及岗位 | E23: 申请时间 | F23: 审批人及岗位 | G23: 审批时间 | H23: 执行人及岗位 | I23: 用户申请权限 | J23: 实际开通权限 | K23: 测试结论 | L23: 备注
A24: 1 | B24: 焦鹥 | C24: 42894 | D24: 焦鹥，地面服务部/XX岗 | E24: 42894 | F24: 张建元，地面服务部/XX岗 | G24: 42894 | H24: 谢力，信息技术部/系统管理员 | I24: 通用查询(中等 | J24: 通用查询(中等 | K24: 有效 | L24: N/A
A25: 2 | B25: 焦鹥 | C25: 42894 | D25: 焦鹥，地面服务部/XX岗 | E25: 42894 | F25: 张建元，地面服务部/XX岗 | G25: 42894 | H25: 谢力，信息技术部/系统管理员 | I25: 通用查询(中等 | J25: 通用查询(中等 | K25: 无效 | L25: N/A
A26: 3 | B26: 焦鹥 | C26: 42894 | D26: 焦鹥，地面服务部/XX岗 | E26: 42894 | F26: 张建元，地面服务部/XX岗 | G26: 42894 | H26: 谢力，信息技术部/系统管理员 | I26: 通用查询(中等 | J26: 通用查询(中等 | K26: 有效 | L26: N/A
A27: ... | B27: ... | C27: ... | D27: ... | E27: ... | F27: ... | G27: ... | H27: ... | I27: ... | J27: ... | K27: ... | L27: ...
A29: 缺陷评估
A30: 是否发现异常 | B30: No
A31: 缺陷描述 | B31: N/A
A32: 索引至<C21-1> IT审计发现汇总表 | B32: N/A

Sheet SA-7
A1: 控制编号 | B1: ='C22 IT一般控制测试'!C13 -> SA-7
A2: 控制活动 | B2: ='C22 IT一般控制测试'!D13 -> 已离职和/或调职的用户的访问权限被及时取消或修改。
A4: 设计有效性标准审计程序 | C4: 设计有效性执行的审计程序
A5: 1、询问管理层以了解与取消已离职或调职用户的应用程序及基础设施层面访问权限相关的控制。尤其应了解以下各项： • 公司是否建立了正式的用户身份管理的政策/流程； • 如何就已离职和/或调职的用户通知信息技术管理层； • 在雇员离职和/或调职时如何取消或调整访问权限； • 取消应用程序访问权限的方法（例如，禁用或删除，自动或手工）； • 在发生离职或调职时负责安全管理和更改用户访问权限的人员； • 对及时取消用户访问权限的预期（即，从离职或调职日至访问权限修改生效日之间的时间间隔）。 2、获取政策、程序指引或其他证据以佐证控制的设计。 | C5: 1.通过访谈公司（信息技术部总监），我们了解到： 公司已制定《帐户安全管理规范》<C22.SA-4c-1>，其中规范用户权限审批要求如下： 第十条如员工调职/离职，应在交接手续中确保其所有帐户及密码已移交给部门主管领导指定的交接人处，并由交接人和部门主管领导在调职/离职交接清单中签名确认后，人事部门方可办理调职/离职手续，交接人应在移交后立刻修改帐户密码，部门主管领导应视情况决定是否向运维部门申请禁用或删除相关帐户。 第十一条如需删除帐户，申请人应提出书面申请，经帐户对应主管部门和运维部门确认后方可由系统/设备管理员执行删除操作。 2.我们获取并检查公司《账户安全管理规范》<C22.SA-4c-1>,确认公司针对已离职或调职用户的访问权限控制恰当。
A6: 审计证据 | C6: 《帐户安全管理规范》<C22.SA-4c-1>
A7: 设计有效性测试结论 | C7: 有效
A10: 执行有效性测试（描述一个样本）
A11: 测试期间&样本总量 | B11: 控制类型：手工 发生频率：在需要时执行 样本总量： 离职：A系统（应用系统XX，操作系统XX，数据库XX）；B系统（应用系统XX，操作系统XX，数据库XX） 调整：A系统（应用系统XX，操作系统XX，数据库XX）；B系统（应用系统XX，操作系统XX，数据库XX） 审计期间：202X.1.1-202X.12.31
A12: 抽样数量 | B12: 抽样数量： 离职：A系统（应用系统XX，操作系统XX，数据库XX）；B系统（应用系统XX，操作系统XX，数据库XX） 调整：A系统（应用系统XX，操作系统XX，数据库XX）；B系统（应用系统XX，操作系统XX，数据库XX）
A13: 测试步骤 | B13: 执行有效性标准审计程序 | C13: 执行有效性执行的审计程序
A14: 1 | B14: 获取拟依赖控制期间内已离职和调职的雇员／承包商的清单。基于其频率和与控制相关的风险，选取已离职/调职的用户样本，对于每一个所选取的用户，测试下述属性： | C14: 1.我们从HR部门获取了审计期间内公司全部《离职及调职人员名单》<C22.SA-7-1>，确认审计期间内共计140人离职。 我们随机从离职、调职清单中选择一名用户，以执行下列测试：
A15: 2 | B15: • 用户的访问特权在系统中不会再被激活（检查范围包括应用程序、操作系统及数据库/堡垒机等）。访问权限自职务终止生效日起被及时取消、删除或禁用 | C15: 2.我们从HR部门获取的离职清单中随机抽取了本年度一名离职人员，并核对至系统用户清单，发现该用户的系统访问权限尚未注销： 员工：孙静，部门：运行控制中心 机组运行室 员工系统账号：sunjing，账号状态：正常启用 同时，我们核对了全部已离职员工是否在系统内存在访问权限，确认已离职员工的访问权限已不存在。我们将就此提出管理建议。
A16: 3 | B16: • 调职后，原岗位访问权限及时被注销 （检查范围包括应用程序、操作系统及数据库/堡垒机等） | C16: 3.我们从HR部门获取的调职清单中随机抽取了本年度一名调职人员，并核对至系统用户清单，发现该用户的系统访问权限未被及时禁用： 员工：崔小平，调职前部门：运行控制中心 机组运行室 员工系统账号：sunjing，账号状态：正常启用 同时，我们核对了全部已离职员工是否在系统内存在访问权限，确认共70名已离职员工的访问权限尚未注销。我们将就此提出管理建议。
A17: 执行有效性测试结论 | C17: 无效
A19: 样本记录（如果抽样数量>1，则在下表记录其余样本）
A20: 终止访问权限测试：
A21: A系统
A22: 序号 | B22: 用户名 | C22: 部门/岗位 | D22: 离职日期 | E22: 账号禁用/删除日期 | F22: 执行人及岗位 | G22: 离职后异常操作 | H22: 测试结论 | I22: 备注
A23: 1 | B23: XXX | C23: XXX | D23: 43039 | E23: 43039 | F23: XXX，系统管理员 | G23: 无 | H23: 有效 | I23: N/A
A24: 2 | B24: ... | C24: ... | D24: ... | E24: ... | F24: ... | G24: ... | H24: 无效 | I24: N/A
A25: 3 | B25: ... | C25: ... | D25: ... | E25: ... | F25: ... | G25: ... | H25: 有效 | I25: N/A
A27: 访问权限变动测试：
A28: A系统
A29: 序号 | B29: 用户名 | C29: 调整前部门及岗位 | D29: 调整后部门及岗位 | E29: 调岗日期 | F29: 账号或访问权限禁用/删除日期 | G29: 执行人及岗位 | H29: 调岗后异常操作 | I29: 测试结论 | J29: 备注
A30: 1 | B30: XXX | C30: XXX | D30: XXX | E30: 43039 | F30: 43039 | G30: XXX，系统管理员 | H30: 无 | I30: 有效 | J30: N/A
A31: 2 | B31: ... | C31: ... | D31: ... | E31: ... | F31: ... | G31: ... | H31: ... | I31: 无效 | J31: N/A
A32: 3 | B32: ... | C32: ... | D32: ... | E32: ... | F32: ... | G32: ... | H32: ... | I32: 有效 | J32: N/A
A34: 缺陷评估
A35: 是否发现异常 | B35: Yes
A36: 缺陷描述 | B36: 公司未及时注销已离职或调职员工的访问权限
A37: 索引至<C21-1> IT审计发现汇总表 | B37: ITGC#1

Sheet SA-9
A1: 控制编号 | B1: ='C22 IT一般控制测试'!C14 -> SA-9
A2: 控制活动 | B2: ='C22 IT一般控制测试'!D14 -> 定期对用户访问权限进行复核。
A4: 设计有效性标准审计程序 | C4: 设计有效性执行的审计程序
A5: 1、询问IT管理层针对复核应用程序的用户访问权限的流程，并了解以下内容： • 公司是否建立了正式的用户访问权限复核制度/流程； • 复核应用程序访问权限的程序及负责人； • 对访问权限进行复核的频率； • 复核的范围（例如，雇员、供应商、承包商、访客和通用/系统账户）和被视作例外的情况； • 复核执行的具体级别（例如，群组、菜单、交易）； • 如何对复核进行记录及如何保存反映例外情况得到及时处理的证据 2、获取政策、程序指引或其他证据以佐证控制的设计。 | C5: 1.通过访谈公司（信息技术部总监），我们了解到： 公司已制定《帐户安全管理规范》<C22.SA-4c-1>，其中规范用户访问权限定期复核要求如下： 公司每半年对系统用户进行访问权限的审阅，由业务部门确认账号权限的合理性，并填写《用户账号权限检查表》，冗余账号及权限由系统管理员根据检查结果进行清理。 2.我们获取并检查公司《账户安全管理规范》<C22.SA-4c-1>,确认公司针对用户访问权限定期复核控制恰当。
A6: 审计证据 | C6: 《帐户安全管理规范》<C22.SA-4c-1>
A7: 设计有效性测试结论 | C7: 有效
A10: 执行有效性测试（描述一个样本）
A11: 测试期间&样本总量 | B11: 控制类型：手工 发生频率：每半年一次 样本总量：2 审计期间：202X.1.1-202X.12.31
A12: 抽样数量 | B12: 抽样数量：1
A13: 测试步骤 | B13: 执行有效性标准审计程序 | C13: 执行有效性执行的审计程序
A14: 1 | B14: 基于与控制相关的风险和复核发生的频率，选取访问权限复核样本，测试下述属性： | C14: 1.在Oracle应用系统管理员XXX的协助下，我们获取了2017年审计期间内Oracle应用系统用户审阅的记录。 我们选取2017年7月的《Oracle用户账号权限检查表》作为样本，执行如下测试：
A15: 2 | B15: • 用户访问权限复核包括完整和准确的用户样本 | C15: 2.我们现场查看系统管理员重新导出用户权限清单的过程，发现系统管理员通过标准查询语句从系统内导出用于审阅的用户清单，清单的导出过程与我们用于审计的用户清单的导出过程一致。之后，系统管理员会使用导出的用户清单生成应用系统用户审阅的记录。 通过审阅《Oracle用户账号权限检查表》<C22.SA-9-1>，其中详细记录了用户名及对应的权限。对比《Oracle用户账号权限检查表》中的详细用户及对应权限和我们获得的《Oracle系统用户清单》<C22.SA-5-1>，我们确认： 用户访问权限复核包括完整和准确的用户样本。
A16: 3 | B16: •复核所覆盖的明细度及范围适当并得到适当的记录，以保证访问权限复核能核实每一位用户的访问权限与当前工作职责是否相符 | C16: 3.通过访谈Oracle应用系统管理员XXX，我们了解到，在导出系统清单后会提交给系统使用部门：财务部的负责人进行审阅。通过检查《Oracle用户账号权限检查表》<C22.SA-9-1>，我们了解到：审阅人许欣（财务部高级经理）会根据信息管理部提供的用户清单，核对每个用户的权限与岗位是否相符，是否存在已离职用户尚未删除账号的情况。我们现场观察许欣审阅的过程，审阅记录中的用户人数在40人左右，许欣会逐个核对清单上的人员及权限，确认无误后会在审阅记录上签字确认。如在审阅过程中有异常发现，会在审阅记录上进行记录，并返回给信息管理部进行进一步的跟进处理。
A17: 4 | B17: • 复核由适当的管理层人员执行且已实施适当的职责分工 | C17: 4.通过检查《Oracle用户账号权限检查表》<C22.SA-9-1>，我们了解到： 审阅人：许欣（财务部高级经理） 复核由适当的管理层人员执行且已实施适当的职责分工。
A18: 5 | B18: • 对访问权限复核所识别的例外情况，系统访问权限已被及时修改 | C18: 5.通过检查《Oracle用户账号权限检查表》<C22.SA-9-1>，我们了解到： 审阅人在审阅过程中没有识别出异常发现或例外情况。
A19: 执行有效性测试结论 | C19: 有效
A21: 样本记录（如果抽样数量>1，则在下表记录其余样本）
A22: 序号 | B22: 样本名称 | C22: 审核人姓名及岗位 | D22: 审核日期 | E22: 审核人适当*1 | F22: 审核工作是否发现异常 | G22: 审核导致的变动（如有）已适当记录*2 | H22: 审核导致的变动（如有）已被恰当的审批*3 | I22: 审核导致的变动（如有）已被恰当的处理 *4 | J22: 及时进行审核（符合定期要求）*5 | K22: 以适当的精确度进行审核，以得出具体的访问权限是适当的结论*6 | L22: 测试结论 | M22: 备注
A23: 1 | B23: 《XX复核记录》 | C23: 张三，XX部门XX岗位 | D23: 45809 | E23: √ | F23: 是 | G23: √ | H23: √ | I23: √ | J23: √ | K23: √ | L23: 有效 | M23: N/A
A24: 2
A25: 3
A27: 标记注释
A28: *1 | B28: 如果访问审核者认为恰当，则审核者： • 了解用户的工作职责，以及根据这些职责需要授予哪些安全组/角色/权限。 • 了解系统中存在的各种安全组/角色实际授予的权限（即，审核者了解他们正在审核的报告的内容）。 • 未审核他们自己的访问权限。 • 未审核他们自己的工作（即，既不是安全管理员也不是访问审核者）
A29: *2 | B29: 在以下情况下，访问审核生成的文档被认为是恰当的： • 记录访问审核是按照既定的用户访问审核过程进行的。 • 证据明确表明: 1) 谁执行了审核以及何时执行, 2) 审核结果需要哪些变化，并且 3) 需要调查/后续行动的情况被标记/突出显示。
A30: *3 | B30: 如果按照既定的用户访问审核流程，处理/应用由于审核而认为必要的逻辑访问变动（即 - 删除不适当的访问并根据审核者的指示增加新的访问），则认为是适当的。
A31: *4 | B31: 如果在处理/应用审核期间识别出的逻辑访问的必要更改（通过检查当前用户访问列表确定）是按照既定的用户访问审核流程进行的，则认为是适当的。
A32: *5 | B32: 如果访问审核节奏/时间表/频率是按照既定的用户访问审核流程执行，且至少每年进行一次，则认为是及时的。
A33: *6 | B33: 如果审核符合以下条件，则访问审核被认为适当精确的： • 将用户在单个系统内的访问所引发的职责分离冲突，与用户在多个系统之间的访问所引发的职责分离冲突，一并考虑在内。 • 考虑离职人员的账户。 • 考虑系统、服务和预置/内置账户。 • 考虑与第三方（如供应商）关联的帐户。 • 评估在功能级别分配给用户账号权限的适当性，而不仅仅是角色级别（不仅仅是角色名称，而是分配给该角色的特定权限）
A34: √ | B34: 经测试无偏差。
A35: × | B35: 不，不符合属性，已发现偏差。
A36: N/A | B36: 不适用
A38: 缺陷评估
A39: 是否发现异常 | B39: No
A40: 缺陷描述 | B40: N/A
A41: 索引至<C21-1> IT审计发现汇总表 | B41: N/A

Sheet SA-10
A1: 控制编号 | B1: ='C22 IT一般控制测试'!C15 -> SA-10
A2: 控制活动 | B2: ='C22 IT一般控制测试'!D15 -> 访问权限通过唯一的用户ID和密码或其他方法验证，以作为核实用户经授权获得系统访问权限的机制。密码参数符合公司和/或专业政策和准则（如，密码最短长度和复杂性、到期和账户锁定）。
A4: 设计有效性标准审计程序 | C4: 设计有效性执行的审计程序
A5: 1、询问IT管理层针对与应用程序相关的身份验证控制（例如，密码最短长度、复杂性、到期和账户锁定）并了解以下内容： • 公司是否建立了正式的身份验证和密码要求的制度/流程； • 针对在系统定义的全部账户类型（例如，终端用户、系统账户、管理员）的应用程序身份验证控制的设计 • 所定义的身份验证控制参数实施的时间或最近一次变更的时间 2、获取政策、程序指引或其他证据以佐证控制的设计。 | C5: 1.通过访谈公司（信息技术部总监），我们了解到： 公司已制定《帐户安全管理规范》<C22.SA-4c-1>，其中规范系统密码策略要求如下： 第五条 系统/设备自带的默认帐户，各系统/设备管理员应在系统/设备部署时修改其默认密码。 第六条 未经部门主管领导批准，不允许共享系统帐户。 第十四条 国航股份员工在设置密码时均应符合以下标准， 1) 长度不低于为8位的字母、数字、特殊符号中至少两种组成的混合字符串； 2) 混合包含了大写和小写字母； 3) 不要使用常见单词； 4）不基于个人信息(如姓名、生日、电话号码、家庭成员名称，职务名称等)； 5)不得与非国航股份系统的个人帐户密码(如个人邮箱帐户密码、个人网站注册帐户密码)相同。 系统/设备应设置帐户登录锁定阈值(单位时间内允许的失败登录次数)和锁定时间，以避免暴力猜测。 各类系统/设备的系统管理员帐户与管理帐户密码应至少每三个月修改一次，普通帐户密码应至少每六个月修改一次，修改密码时禁止重复使用最近三次使用过的旧密码。 2.我们获取并检查公司《账户安全管理规范》<C22.SA-4c-1>,确认公司针对用户身份验证和密码管理控制恰当。
A6: 审计证据 | C6: 《帐户安全管理规范》<C22.SA-4c-1>
A7: 设计有效性测试结论 | C7: 有效
A10: 执行有效性测试（描述一个样本）
A11: 测试期间&样本总量 | B11: 控制类型：自动 发生频率：在需要时执行 样本总量：1 审计期间：202X.1.1-202X.12.31
A12: 抽样数量 | B12: 抽样数量：1
A13: 测试步骤 | B13: 执行有效性标准审计程序 | C13: 执行有效性执行的审计程序
A14: 1 | B14: 获取关于身份验证和安全配置的证据（需考虑应用程序、操作系统及数据库/堡垒机（如有），以评价其实施是否与控制的设计相一致。在执行测试时考虑下述属性： • 密码长度； • 密码的复杂性（即，包含字母、数字、或特殊字符的组合）； • 密码更改的间隔（例如，每30-90天）； • 启用密码历史记录以防止密码的重复使用； • 登录失败锁定。 针对上述项目，测试下述属性： 密码参数的配置和公司制度一致。 | C14: 1.在Oracle应用系统管理员协助下，我们获取了应用系统用户清单和密码策略： 1）通过检查《Oracle系统用户清单》<C22.SA-5-1>，我们了解到：用户名ID是以字母数字形式存在，每位用户用户名各不相同。 2）通过检查《Oracle应用系统密码策略》<C22.SA-10-1>，我们了解到：Oracle系统密码策略已启用，策略如下: a)密码长度：至少8位 b)密码强度等级：必须有数字、字母、特殊符号中的两种 c)密码有效期：90天 d)密码历史：不能使用最近3次密码
A15: 2 | B15: 对于默认账户，测试账户的默认密码已被修改 | C15: 2.通过检查《Oracle系统用户清单》<C22.SA-5-1>，我们发现系统默认账户为“systest”，我们查看系统内《默认账号密码修改记录》<C22.SA-10-2>,确认该默认账号密码已被修改，修改日期为2015年10月16日。
A16: 3 | B16: 对于不能遵循密码策略自动配置的特权级别共享、通用、服务和/或供应商账户，测试手工控制以验证密码策略配置（如密码库，密码定期更换等） | C16: 3.通过检查《Oracle系统用户清单》<C22.SA-5-1>，我们了解到系统内不存在不能遵循密码策略自动配置的特权级别共享、通用、服务和/或供应商账户。
A17: 执行有效性测试结论 | C17: 有效
A19: 样本记录（如果抽样数量>1，则在下表记录其余样本）
A20: 序号 | B20: 系统名称 | C20: 是否需要独立的用户ID | D20: 最小密码长度 | E20: 密码复杂度 | F20: 密码有效期 | G20: 密码历史 | H20: 账户锁定阈值 -登录失败锁定 | I20: 登陆时密码得到适当屏蔽 | J20: 密码不以明文形式存储 | K20: 默认账号密码是否经过修改 | L20: 测试结论 | M20: 备注
A21: 1 | B21: 用友NC应用系统 | C21: 是 | D21: 8 | E21: 字母+数字+特殊字符 | F21: 180天 | G21: 不能使用最近3次密码 | H21: 5次 | I21: √ | J21: √ | K21: √ | L21: 有效 | M21: N/A
A22: ... | B22: ... | C22: ... | D22: ... | E22: ... | F22: ... | G22: ... | H22: ... | I22: ... | J22: ... | K22: ... | L22: 无效 | M22: N/A
A24: 缺陷评估
A25: 是否发现异常 | B25: No
A26: 缺陷描述 | B26: N/A
A27: 索引至<C21-1> IT审计发现汇总表 | B27: N/A

Sheet SA-12
A1: 控制编号 | B1: ='C22 IT一般控制测试'!C17 -> SA-12
A2: 控制活动 | B2: ='C22 IT一般控制测试'!D17 -> 在系统中启用日志，并且定期对特权级别用户操作日志进行监控或审计以侦测未经授权或不适当的活动。
A4: 设计有效性标准审计程序 | C4: 设计有效性执行的审计程序
A5: 1、询问IT管理层，并了解以下内容： •公司是否制定了正式的信息系统日志管理制度、程序、流程、标准及指引； •公司对信息系统日志记录采用何种方式记录、保存； •信息系统日志记录的级别、范围； •公司是否定期对特权用户、管理员用户操作记录进行复核/审计； 2、检查证据以证实控制设计。 | C5: 1.通过访谈公司（信息技术部总监），我们了解到： 1)公司制定了《信息安全管理办法》、《信息系统账号管理细则》、《计算机病毒防治管理细则》等安全管理制度； 2)公司《xxx》制度中明确规定了信息系统（如SAP，浪潮等ERP系统）需要开启系统日志，记录所有用户在系统中的操作。 3）公司信息系统SAP ECC系统启用了GRC模块及系统审计日志，可以记录所有用户单据级别的操作，记录周期为15自然日，系统日志滚动更新。（这里要分系统分别写） 4）信息系统同时日志记录除系统管理员外不能进行删除。 5）公司IT部门内审岗XXX定期（3个月？）执行对特权用户、超级用户的系统日志分析，识别是否存在违规操作。
A6: 审计证据 | C6: 《信息安全管理办法》<C22.SA-12-1> 《信息系统账号管理细则》<C22.SA-12-2> 《计算机病毒防治管理细则》<C22.SA-12-3>
A7: 设计有效性测试结论 | C7: 有效
A10: 执行有效性测试（描述一个样本）
A11: 测试期间&样本总量 | B11: 控制类型：手工/自动 发生频率：在需要时执行 样本总量：12 审计期间：202X.1.1-202X.12.31
A12: 抽样数量 | B12: 抽样数量：2
A13: 测试步骤 | B13: 执行有效性标准审计程序 | C13: 执行有效性执行的审计程序
A14: Test 1
A15: 1 | B15: 获取准确及完整的执行特权级别用户日志复核的人员清单，测试下述属性： | C15: 1.我们获取了执行系统特权级别用户定日志的人员清单<C22.SA-12-4>，共有xx人，分别是：张三、李四，我们从中抽取样本并执行以下测试：
A16: 2 | B16: •基于对管理层的询问，系统复核权限对于复核人的职责而言是恰当的（列明具有复核权限的人员） | C16: 2.通过与信息技术部负责人（xxx）的访谈，我们了解到，清单中人员（张某某、李四）等职员的岗位、职责分别是： 姓名 岗位 职责 系统ID 张某某 xxx xxx xxx 李四 xxx xxx xxx 对公司管理层而言上述人员的岗位与其具有（sap）系统的复核权限是相匹配的。 同时，通过对比《岗位职责不相容矩阵》，我们认为职员张某某、李四等人的岗位职责不存在冲突，公司对上述人员的授权是恰当的。 控制未见异常。
A17: 3 | B17: • 基于对相关工作职能的检查，信息系统中具有权限查询等职能权限对于复核人而言是恰当的（包括佐证性信息来源的索引，例如组织架构图） | C17: 3.通过获取并检查《岗位授权书》<C22.SA-12-5>，我们了解到清单中人员（张某某）在（sap）系统内的《权限申请审批单》<C22.SA-12-6>，审批信息具体如下： 人员 岗位 系统名称 系统id 申请日期 审批日期 申请权限 审批人 审批权限 xxx xxx xxx xxx xxx xxx xxx xxx xxx 我们现场在（sap）系统中进行了检查，职员张某某的系统权限与申请审批单一致，对比其担任的IT部门内审职责，我们认为职员张某某的访问特权对于被分配的职责而言是恰当的。 控制未见异常。 其余人员测试请参考OE测试底稿。
A18: 4 | B18: • 获取准确及完整的信息系统特权级别用户日志复核清单（检查范围包括应用程序、操作系统及数据库/堡垒机等日志），测试下述属性： | C18: 4.我们获取了（SAP）系统特权级别用户定日志复核清单<C22.SA-12-6>，审计期间内共有xx次复核记录，我们从中抽取样本并执行以下测试：
A19: 5 | B19: • 基于对相关工作的检查： (a) 确认日志复核工作是否足够精确、复核内容是否适当，以保证相关异常操作能够被发现并追查原因； (b) 复核是否发现异常，以及异常是否得到跟进/解决。 | C19: 批处理作业任务或计划的修改被恰当记录和审批。 5.通过获取并检查（sap）系统批处理作业变更清单，我们抽取其中xxx日期的变更记录工单，了解到： 变更系统 变更时间 变更内容 申请时间 审批时间 xxx xxx xxx xxx xxx 我们现场在（sap）系统中验证上述系统变更情况，我们认为关于该系统批处理作业的修改被恰当的记录和审批。 控制未见异常。 其余变更测试请参考OE测试底稿。
A20: Test 2
A21: 1 | B21: 如果公司使用具备审计功能的信息系统，或部署具备自动监测、检查功能的专业系统，能够识别信息系统中特权级别用户操作是否违规，则进行如下测试： | C21: 1.通过与xxx部门xxx访谈，我们了解到公司使用的SAP ECC系统具有GRC模块，可以对用户的操作进行记录并识别风险操作。
A22: 2 | B22: • 获取准确及完整的信息系统特权级别用户日志识别记录，测试下述属性： | C22: 2.通过获取信息系统特权级别用户日志识别记录，我们了解到XXX。
A23: 3 | B23: • 基于对相关工作的检查，确认信息系统特权级别用户日志是否出现违规操作。 | C23: 3.基于对相关工作的检查，我们发现XXX。
A24: 4 | B24: • 对于出现的异常记录，是否妥善处理。 | C24: 4.对于出现的异常记录，我们了解到XXX。
A25: 执行有效性测试结论 | C25: 有效
A27: 样本记录（如果抽样数量>1，则在下表记录其余样本）
A28: 序号 | B28: 系统名称 | C28: 样本名称 | D28: 复核日期 | E28: 复核涵盖的时间范围 | F28: 复核人及岗位 | G28: 复核人适当 *1 | H28: 复核是否发现异常 | I28: 跟进/解决措施是否恰当 *2 | J28: 及时进行审核（符合定期要求） *3 | K28: 以适当的精确度进行审核 *4 | L28: 被监督的人不能修改配置和日志 | M28: 测试结论 | N28: 备注
A29: 1 | M29: 有效 | N29: N/A
M30: 有效 | N30: N/A
A31: 标记注释
A32: *1 | B32: 在以下情况下，该审核被认为是由适当的个人进行的： • 不是审核自己的工作， • 审核人具备执行此审核所必须的技术知识，并且 • 审核人在组织中拥有必要的权力，可以处罚不遵守安全管理政策的个人。
A33: *2 | B33: 在以下情况下，为响应该审核中识别出的不适当的安全管理活动而采取的措施被认为是适当的： • 识别并修复了在审核期间发现的未经授权活动的根本原因。 • 不适当的交易/分录/账户/权限被撤回。 • 造成不适当活动的安全管理员因违反安全要求而受到处罚。
A34: *3 | B34: 如果访问审核节奏/时间表/频率是按照既定的用户访问审核流程执行，且至少每年进行一次，则认为是及时的。
A35: *4 | B35: 如果审核考虑了以下情况，则安全管理监督审核/过程的活动认为是精确恰当的： • 应用程序代码/逻辑的变动（例如，安装供应商发布的补丁，实现自定义开发的增强功能） • 对存于数据库对象中的代码/逻辑的变动（例如，对存储过程、打包和触发器的变动）（如适用） 此外，在安全管理也具有完全/不受限制的系统访问权限（即“安全管理员”和“系统管理员”访问权限相同）的情况下，管理层的安全管理监督审核/过程的活动被认为精确恰当的，如审核还考虑了： • 由系统管理员创建、修改和删除财务关键交易记录，如会计分录、销售、采购订单、现金收据。 • 由系统管理员执行修改关键的财务主文档，如供应商、客户和库存主文件。
A36: √ | B36: 经测试无偏差。
A37: × | B37: 不，不符合属性，已发现偏差。
A38: N/A | B38: 不适用
A40: 缺陷评估
A41: 是否发现异常 | B41: No
A42: 缺陷描述 | B42: N/A
A43: 索引至<C21-1> IT审计发现汇总表 | B43: N/A

Sheet SA-11
A1: 控制编号 | B1: ='C22 IT一般控制测试'!C16 -> SA-11
A2: 控制活动 | B2: ='C22 IT一般控制测试'!D16 -> 企业安装了统一的防病毒软件，服务器的病毒库被设定成及时、自动更新；客户端的配置被统一设定，且不能私自更改，以保证防病毒软件的有效运行及病毒库的及时更新。
A4: 设计有效性标准审计程序 | C4: 设计有效性执行的审计程序
A5: 针对防病毒管理 1、询问IT管理层，并了解以下内容： •公司是否制定了正式的防病毒管理制度/流程； •公司的防病毒管理策略、手段及工具 2、获取政策、程序指引或其他证据以佐证控制的设计。 | C5: 1.通过访谈公司（信息技术部总监），我们了解到： 1)公司制定了《计算机病毒防治管理细则》和《网络管理细则》的防病毒管理制度； 2)《计算机病毒防治管理细则》第十四条规定：公司所有服务器必须按规定安装防病毒软件，启用病毒库自动更新、实时杀毒并每周定期自动全盘扫描。联网用户必须安装制定的计算机防病毒产品，并接受服务器端的集中管理，并按照预定策略启动实时扫描和病毒特征码的自动更新。不联网的用户需要安装指定的单机版病毒防治产品，定时扫描和更新病毒码； 3）《网络管理细则》第十八条规定：公司网络连接应在技术条件许可的条件下启用防火墙，并根据需要进行双向的网络访问控制。除防火墙管理员之外，任何人在未得到信息管理部总经理授权前，不得对防火墙进行任何操作；防火墙管理员应每月检查和分析防火墙日志，查看是否遭受攻击行为，并对攻击行为进行追查，有关情况应及时上报信息管理部总经理。 2.我们获取并检查了上述《计算机病毒防治管理细则》和《网络管理细则》制度规范，确认公司已建立较为完善的防病毒管理制度。
A6: 审计证据 | C6: 《计算机病毒防治管理细则》<C22.SA-11-1> 《网络管理细则》<C22.SA-11-2>
A7: 设计有效性测试结论 | C7: 有效
A10: 执行有效性测试（描述一个样本）
A11: 测试期间&样本总量 | B11: 控制类型：手工 发生频率：在需要时执行 样本总量：12 审计期间：202X.1.1-202X.12.31
A12: 抽样数量 | B12: 抽样数量：2
A13: 测试步骤 | B13: 执行有效性标准审计程序 | C13: 执行有效性执行的审计程序
A14: 1 | B14: 获取关于防病毒服务器配置的证据，以评价其实施是否与控制的设计相一致。在执行测试时考虑下述属性： • 已开启防病毒服务器、防火墙设置，并于与公司管理制度一致 | C14: 1.在网络系统管理员的协助下，我们获取了公司防病毒和防火墙设置截图： 1）通过检查《防病毒服务器设置截图》<C22.SA-11-3>，我们了解到：公司目前安装了Symantec企业版杀毒软件（版本为XXX），设置了病毒代码自动更新升级，杀毒软件无法由员工随意删除。 2）通过检查《防火墙设置截图》<C22.SA-11-4>，我们了解到：公司目前安装了深信服下一代防火墙（版本为XXX），防火墙安全配置均已开启，且配置不得随意修改。
A15: 2 | B15: • 上述设置是否可以被任意修改 | C15: 2.通过检查《防病毒设置截图》<C22.SA-11-3>和《防火墙设置截图》<C22.SA-11-4>，我们确认，只有网络系统管理员具备设置修改权限，且设置的修改需经管理层审批后执行。
A16: 3 | B16: • 及时按照制度对防病毒结果进行检查和解决 | C16: 3.通过检查《每周全盘扫描报告》<C22.SA-11-5>和《防火墙日志检查表》<C22.SA-11-6>，我们了解到，网络管理员定期对防病毒结果进行检查，针对异常现象，及时进行处理和解决，未发现异常事项。
A17: 执行有效性测试结论 | C17: 有效
A19: 样本记录（如果抽样数量>1，则在下表记录其余样本）
A20: 序号 | B20: 样本名称 | C20: 处理时间 | D20: 处理人 | E20: 是否解决
A21: 1 | B21: 每周全盘扫描报告-XXX异常 | C21: 43106 | D21: XXX | E21: 是
A22: 2 | B22: 防火墙日志检查表-XXX异常 | C22: 43291 | D22: XXX | E22: 是
A24: 缺陷评估
A25: 是否发现异常 | B25: No
A26: 缺陷描述 | B26: N/A
A27: 索引至<C21-1> IT审计发现汇总表 | B27: N/A

Sheet SA-13
A1: 控制编号 | B1: ='C22 IT一般控制测试'!C18 -> SA-13
A2: 控制活动 | B2: ='C22 IT一般控制测试'!D18 -> 关键电子表格以及共享文档的访问权限受到恰当限制。
A4: 设计有效性标准审计程序 | C4: 设计有效性执行的审计程序
A5: 1、询问IT管理层，并了解以下内容： •公司对信息系统业务数据到财务系统财报数据自动传输流程之外的访问控制情况 2、获取并检查数据访问控制相关管理规范。 | C5: 1.通过访谈公司（信息技术部总监），我们了解到： 公司信息系统业务数据到财务系统财报数据为人工控制传输，业务数据从XX系统导出到XX位置Excel文件，通过人工触发控制导入到财务系统。XX文件所在文件夹为网络共享目录，需XX岗审批后通过OA系统提交至XX岗授权。 2.我们获取并检查了公司系统文件访问权限用户清单，确认业务文件访问权限受到恰当限制。
A6: 审计证据 | C6: 《系统文件访问权限清单》<C22-SA-13-1>
A7: 设计有效性测试结论 | C7: 有效
A10: 执行有效性测试（描述一个样本）
A11: 测试期间&样本总量 | B11: 控制类型：手工 发生频率：每季度一次 样本总量：3 审计期间：202X.1.1-202X.12.31
A12: 抽样数量 | B12: 抽样数量：2
A13: 测试步骤 | B13: 执行有效性标准审计程序 | C13: 执行有效性执行的审计程序
A14: 1 | B14: 获取公司系统文件访问权限用户清单。对每一个所选取的样本，测试以下属性： | C14: 1.我们获取了公司《系统文件访问权限清单》，共有三个用户，我们从中抽取样本并执行以下测试：
A15: 2 | B15: 获取所选样本的用户授权记录，检查样本用户权限是否经过授权，授予权限是否恰当。 | C15: 2.我们获取样本的《授权记录》<C22-SA-13-2>，确认样本用户均经过合理授权。
A16: 执行有效性测试结论 | C16: 有效
A18: 样本记录（如果抽样数量>1，则在下表记录其余样本）
A19: 序号 | B19: 用户名 | C19: 所属部门 | D19: 访问目的 | E19: 权限设置是否合理
A20: 1 | B20: XXX | C20: 财务部 | D20: 将数据汇总转换用于导入财务系统 | E20: 是
A21: 2 | B21: XXX | C21: 业务部 | D21: 业务数据核对，用户财务系统导入基础数据。 | E21: 是
A23: 缺陷评估
A24: 是否发现异常 | B24: No
A25: 缺陷描述 | B25: N/A
A26: 索引至<C21-1> IT审计发现汇总表 | B26: N/A

Sheet SA-14
A1: 控制编号 | B1: ='C22 IT一般控制测试'!C19 -> SA-14
A2: 控制活动 | B2: ='C22 IT一般控制测试'!D19 -> 公司高管在系统中的权限设置合理，仅有查询权限。
A4: 设计有效性标准审计程序 | C4: 设计有效性执行的审计程序
A5: 1、询问IT管理层，并了解以下内容： •公司对于高级管理人员（如董事长、董秘、CEO、CFO等）系统用户账号权限的分配及管理情况 2、获取并检查相关管理规范如系统权限控制矩阵、岗位职责说明等，确认公司高级管理人员权限分配是否恰当。 | C5: 1.通过访谈公司（信息技术部总监），我们了解到： 公司高级管理人员系统账号及权限一般为查询或审批权限，不会涉及具体的业务操作权限。 2.我们获取并检查了公司系统权限控制矩阵，确认控制矩阵中高级管理人员无具体业务操作权限。
A6: 审计证据 | C6: 《系统权限控制矩阵》<C22-SA-14-1>
A7: 设计有效性测试结论 | C7: 有效
A10: 执行有效性测试（描述一个样本）
A11: 测试期间&样本总量 | B11: 控制类型：手工 发生频率：在需要时执行 样本总量：5 审计期间：202X.1.1-202X.12.31
A12: 抽样数量 | B12: 抽样数量：2
A13: 测试步骤 | B13: 执行有效性标准审计程序 | C13: 执行有效性执行的审计程序
A14: 1 | B14: 获取公司高级管理人员名单，对于选定的高管人员，测试以下属性： | C14: 1.我们获取了公司《高级管理人员名单》<C22.SA-14-2>，审计期间内共有高管5名，我们执行以下测试：
A15: 2 | B15: •获取高管人员在系统中的权限设置，检查公司高管人员在系统中的权限是否合理。 | C15: 2.我们获取CFOXXX在Oracle财务系统中的《权限设置截图》<C22.SA-14-3>，确认CFO在系统中仅账套查询权限以及凭证审批权限，无其他增删改操作权限，权限设置合理。
A16: 执行有效性测试结论 | C16: 有效
A18: 样本记录（如果抽样数量>1，则在下表记录其余样本）
A19: 序号 | B19: 高管姓名及职位 | C19: 系统权限 | D19: 权限设置是否合理
A20: 1 | B20: XXX,董秘 | C20: Oracle系统查询权限 | D20: 是
A24: 缺陷评估
A25: 是否发现异常 | B25: No
A26: 缺陷描述 | B26: N/A
A27: 索引至<C21-1> IT审计发现汇总表 | B27: N/A

Sheet PE-3a
A1: 控制编号 | B1: ='C22 IT一般控制测试'!C20 -> PE-3a
A2: 控制活动 | B2: ='C22 IT一般控制测试'!D20 -> 信息系统运行维护的相关制度和流程被恰当记录、审批和下发。
A4: 设计有效性标准审计程序 | C4: 设计有效性执行的审计程序
A5: 1、询问IT管理层，并了解以下内容： •公司是否制定了正式的信息系统运行维护管理制度/流程； •制度制定或修订的流程，以及相关审批和下发渠道 2、获取并检查相关信息系统运行维护管理制度，确认公司是否制定了信息系统运维管理制度，制度是否足够和完善。 | C5: 1.通过访谈公司（信息技术部总监），我们了解到： 1)公司制定了《信息系统运维细则》、《计算机机房管理细则》、《信息系统备份管理细则》等运维管理制度； 2)公司信息管理制度由（信息技术部）制定，经公司（信息化工作委员会）审批后通过(OA系统)下发执行； 3）（信息技术部）每年定期对信息管理制定进行复核，并根据实际情况进行更新。 2.我们获取并检查了上述《信息系统运维细则》、《计算机机房管理细则》、《信息系统备份管理细则》等制度规范，确认公司已建立较为完善的安全管理制度。
A6: 审计证据 | C6: 《信息系统运维细则》<C22.PE-3a-1> 《计算机机房管理细则》<C22.PE-3a-2> 《信息系统备份管理细则》<C22.PE-3a-3>
A7: 设计有效性测试结论 | C7: 有效
A10: 执行有效性测试（描述一个样本）
A11: 测试期间&样本总量 | B11: 控制类型：手工 发生频率：在需要时执行 样本总量：12 审计期间：202X.1.1-202X.12.31
A12: 抽样数量 | B12: 抽样数量：2
A13: 测试步骤 | B13: 执行有效性标准审计程序 | C13: 执行有效性执行的审计程序
A14: 1 | B14: 获取审计期间内新增、修订的信息系统运行维护管理制度清单并选取样本。对每一个所选取的样本，测试下述属性： | C14: 1.我们获取了公司信息系统管理制度清单，审计期间内共发生制度新增、修订12次，我们从中抽取样本并执行以下测试：
A15: 2 | B15: •制度的新增、修订由适当的管理层批准和/或提交 | C15: 2.通过获取并检查《计算机机房管理办法审批记录》<C22.PE-3a-4>,我们了解到，《计算机机房管理办法》的修订由信息技术部执行，更新时间为2017年3月10日，并经由公司信息化工作委员会审批，审批时间为2017年3月11日。
A16: 3 | B16: • 经审批的制度由恰当的途径下发 | C16: 3.通过获取并查看公司《OA系统制度下发通知》<C22.PE-3a-5>,我们了解到，《计算机机房管理办法》经审批后，通过公司OA系统下发通知，并正式执行。
A17: 4 | B17: • 制度内容是更新或适用的 | C17: 4.通过获取并查看公司更新后的《计算机机房管理办法》<C22.PE-3a-2>，我们了解到，该管理制度针对安全访问管理进行了更新，符合公司管理现状。
A18: 执行有效性测试结论 | C18: 有效
A20: 样本记录（如果抽样数量>1，则在下表记录其余样本）
A21: 序号 | B21: 信息系统安全管理制度/流程 | C21: 更新时间 | D21: 审批时间 | E21: 审批人 | F21: 是否得到恰当下发 | G21: 制度/流程是最更新或适用的
A22: 1 | B22: 《信息系统备份管理细则》 | C22: 43038 | D22: 43039 | E22: 信息化工作委员会 | F22: 是，通过OA系统下发 | G22: 是
A23: 2 | B23: 《XX管理细则》 | C23: ... | D23: ... | E23: ... | F23: ... | G23: ...
A25: 缺陷评估
A26: 是否发现异常 | B26: No
A27: 缺陷描述 | B27: N/A
A28: 索引至<C21-1> IT审计发现汇总表 | B28: N/A

Sheet PE-3d
A1: 控制编号 | B1: ='C22 IT一般控制测试'!C21 -> PE-3d
A2: 控制活动 | B2: ='C22 IT一般控制测试'!D21 -> 只有经授权的用户才有权更新作业调度软件中的批次作业，且进行恰当职责分离。
B3: ='C22 IT一般控制测试'!D22 -> 批处理作业任务或计划的修改被恰当记录和审批。
A5: 设计有效性标准审计程序 | C5: 设计有效性执行的审计程序
A6: 1、询问IT管理层，并了解以下内容： •使用作业调度程序相关的管理制度、程序、流程、标准及指引； •使用作业调度程序的范围； •更新主要作业计划的流程； •有权力访问作业调度程序的人员，以及人员在程序中的权限与岗位职责是否匹配。 2、获取并检查相关制度、流程、标准，确认公司在作业调度程序方面的制度是否足够和完善。 | C6: 1.通过访谈公司（例如：信息技术部总监），我们了解到： 1)公司制定了《信息系统运维细则》等运维管理制度，及信息技术部门《岗位职责说明书》、《岗位职责不相容矩阵》等规范性文件； 2)公司在（SAP）系统中应用了作业调度程序，配置了批处理作业，主要处理成本结转、报表计算及DB2数据库的备份。 3）（信息技术部）根据（运维管理平台）中提出的需求进行评估，由（信息技术部）负责人进行审批后，由系统管理员对作业计划进行更新。 4）（SAP）系统中的作业调度程序的调用、变更由具有系统管理员角色的人员负责。其中（张某某、李四）是（SAP）系统管理员，分别是（信息技术部）应用运维管理岗职员、应用运维主管岗，根据《岗位职责说明书》、《岗位职责不相容矩阵》文档描述，具备岗位职责分离的要求。 2.我们获取并检查了上述《信息系统运维细则》等运维管理制度，及信息技术部门《岗位职责说明书》、《岗位职责不相容矩阵》等规范性文件，确认公司已建立较为完善的安全管理制度。
A7: 审计证据 | C7: 《信息系统运维细则》<C22.PE-3a-1> 《计算机机房管理细则》<C22.PE-3a-2> 《信息系统备份管理细则》<C22.PE-3a-3>
A8: 设计有效性测试结论 | C8: 有效
A11: 执行有效性测试（描述一个样本）
A12: 测试期间&样本总量 | B12: 控制类型：手工 发生频率：在需要时执行 样本总量：x 审计期间：202X.1.1-202X.12.31
A13: 抽样数量 | B13: 抽样数量：x
A14: 测试步骤 | B14: 执行有效性标准审计程序 | C14: 执行有效性执行的审计程序
A15: 1 | B15: 获取准确及完整的拥有处理关键财务数据的系統作业权限之用户清单，测试下述属性： | C15: 1.我们获取了（SAP）系统拥有批处理管理权限的用户清单<C22.PE-5-4>，共xx人，我们从中抽取样本并执行以下测试：
A16: 2 | B16: •基于对管理层的询问，访问特权已获授权且对于用户被分配的职责而言是恰当的（列明验证访问权限的人员） | C16: 2.通过与信息技术部负责人（xxx）的访谈，我们了解到，清单中人员（张某某、李四）等职员的岗位、职责分别是： 姓名 岗位 职责 系统ID 张某某 xxx xxx xxx 李四 xxx xxx xxx 对公司管理层而言上述人员的岗位与其具有（sap）系统的权限是相匹配的。 同时，通过对比《岗位职责不相容矩阵》，我们认为职员张某某、李四等人的岗位职责不存在冲突，公司对上述人员的授权是恰当的。 控制未见异常。
A17: 3 | B17: • 基于对相关工作职能的检查，访问特权已获授权且对于用户被分配的职责而言是恰当的（包括佐证性信息来源的索引，例如组织架构图） | C17: 3.通过获取并检查《岗位授权书》<C22.PE-5-5>，我们了解到清单中人员（张某某）在（sap）系统内的《权限申请审批单》<C22.PE-5-6>，审批信息具体如下： 人员 岗位 系统名称 系统id 申请日期 审批日期 申请权限 审批人 审批权限 xxx xxx xxx xxx xxx xxx xxx xxx xxx 我们现场在（sap）系统中进行了检查，职员张某某的系统权限与申请审批单一致，对比其担任的应用系统基础运维岗职责，我们认为职员张某某的访问特权对于被分配的职责而言是恰当的。 控制未见异常。 其余人员测试请参考OE测试底稿。
A18: 4 | B18: • 获取准确及完整的系统批处理作业变更清单（包括应用程序层面、操作系统及数据库层面），测试下述属性： | C18: 4.我们获取了（运维管理平台）中关于（sap）系统批处理作业变更清单<C22.PE-5-7>，我们从中抽取样本并执行以下测试：
A19: 5 | B19: • 基于对相关工作的检查，确认批处理作业任务或计划的修改被恰当的记录和审批。 | C19: 批处理作业任务或计划的修改被恰当记录和审批。 5.通过获取并检查（sap）系统批处理作业变更清单，我们抽取其中xxx日期的变更记录工单，了解到： 变更系统 变更时间 变更内容 申请时间 审批时间 xxx xxx xxx xxx xxx 我们现场在（sap）系统中验证上述系统变更情况，我们认为关于该系统批处理作业的修改被恰当的记录和审批。 控制未见异常。 其余变更测试请参考OE测试底稿。
A20: 执行有效性测试结论 | C20: 有效
A22: 样本记录（如果抽样数量>1，则在下表记录其余样本）
A23: 批处理作业变更权限记录：
A24: A系统
A25: 序号 | B25: 人员 | C25: 岗位 | D25: 系统名称 | E25: 申请日期 | F25: 审批日期 | G25: 申请权限 | H25: 审批人 | I25: 审批权限 | J25: 备注 | K25: 结论
A26: 1 | B26: 张某某 | C26: 应用系统基础运维岗 | D26: sap ecc6 | E26: 43170 | F26: 43171 | G26: 超级管理员账号 | H26: 蔡蔡 | I26: 超级管理员账号 | J26: N/A | K26: 有效
A27: 2
A29: 批处理作业变更审批记录：
A30: A系统
A31: 序号 | B31: 工作订单编号（如有） | C31: 变更内容 | D31: 执行人 | E31: 审批时间 | F31: 审批人 | G31: 完成日期 | H31: 备注 | I31: 结论
A32: 1 | C32: xxx | E32: 43170 | F32: 信息技术部总监，张三 | G32: 信息技术部总监，张三 | H32: N/A | I32: 有效
A33: 2
A35: 缺陷评估
A36: 是否发现异常 | B36: No
A37: 缺陷描述 | B37: N/A
A38: 索引至<C21-1> IT审计发现汇总表 | B38: N/A

Sheet PE-5
A1: 控制编号 | B1: ='C22 IT一般控制测试'!C23 -> PE-5
A2: 控制活动 | B2: ='C22 IT一般控制测试'!D23 -> 监控关键系统、程序和/或作业及更正处理错误以确保成功完成。
A4: 设计有效性标准审计程序 | C4: 设计有效性执行的审计程序
A5: 向管理层询问，了解如何监控关键系统，程序和/或作业，并纠正处理错误以确保成功完成。了解以下属性： •工作安排和监测的政策，标准和指南; •重新启动并解决程序失败作业; •保留具体证据，证明失败工作的解决方案; •使用的作业调度和监视工具; 检查证据以证实控制设计。 | C5: 1.通过访谈公司（例如：信息技术部总监），我们了解到： 1)公司制定了《信息系统运维细则》等运维管理制度，用以规范监控关键系统，程序和/或作业。 2)公司在（SAP）系统中应用了监控程序，配置了批处理作业，主要处理成本结转、报表计算及DB2数据库的备份。 3）（信息技术部）根据（运维管理平台）中提出的需求进行评估，由（信息技术部）负责人进行审批后，由系统管理员对作业计划进行更新。 4）（SAP）系统中的作业调度程序的调用、变更由具有系统管理员角色的人员负责。其中（张某某、李四）是（SAP）系统管理员，分别是（信息技术部）应用运维管理岗职员、应用运维主管岗，根据《岗位职责说明书》、《岗位职责不相容矩阵》文档描述，具备岗位职责分离的要求。 2.我们获取并检查了上述《信息系统运维细则》等运维管理制度，及信息技术部门《岗位职责说明书》、《岗位职责不相容矩阵》等规范性文件，确认公司已建立较为完善的安全管理制度。
A6: 审计证据 | C6: 《信息系统运维细则》<C22.PE-3a-1>
A7: 设计有效性测试结论 | C7: 有效
A10: 执行有效性测试（描述一个样本）
A11: 测试期间&样本总量 | B11: 控制类型：手工 发生频率：在需要时执行 样本总量：x 审计期间：202X.1.1-202X.12.31
A12: 抽样数量 | B12: 抽样数量：x
A13: 测试步骤 | B13: 执行有效性标准审计程序 | C13: 执行有效性执行的审计程序
A14: 1 | B14: 获取审计期内准确及完整的应用程序及基础设施层面（包括操作系统、数据库）作业状态的清单/ 日志。基于失败作业的发生频率，确定适当的测试样本量并选取样本。对于每一项所选取的作业失败样本，测试下述属性： | C14: 1.通过获取并检查（sap）系统的关键任务监控记录<C22.PE-5-x>，并抽取样本进行如下测试：
A15: 2 | B15: 从日期总体中抽取样本并测试这些日期运行的作业状态 | C15: 2.按照抽样频率抽取某个日期数据备份监控记录，并进行如下记录：
A16: 3 | B16: (a) 作业成功运行 | C16: 3.通过检查x年x月x日的关键任务记录，我们了解到（sap）系统的关键任务（如半成品加工成本报表）被成功执行。具体信息如下： xxxx 其余样本测试请参考OE测试底稿。
A17: 4 | B17: (b)若出现错误，会生成告警并通知适当人员，存在后续跟进处理以解决错误 | C17: 4.对于x年x月x日关键任务出现的异常情况，通过记录我们了解到由（信息科技部）xxx进行问题排查，并对出现错误的系统进行重新执行。
A18: 执行有效性测试结论 | C18: 有效
A20: 样本记录（如果抽样数量>1，则在下表记录其余样本）
A21: A系统
A22: 序号 | B22: 日期 | C22: 关键任务名称 | D22: 是否出现错误 | E22: 被审计单位对异常作业的跟进/解决措施 | F22: 跟进/解决措施是否有效 | G22: 结论 | H22: 备注
A23: 1 | B23: xxx | C23: xxx | D23: xxx | E23: xxx | F23: xxx | G23: 有效
A24: 2
A26: 缺陷评估
A27: 是否发现异常 | B27: No
A28: 缺陷描述 | B28: N/A
A29: 索引至<C21-1> IT审计发现汇总表 | B29: N/A

Sheet PE-5.1
A1: 接口测试：
A2: 对接口和数据在接口交互的完整性和准确性的客户关键控制执行了哪些测试？ | B2: 描述所执行的程序。该程序不仅应作为接口的独立验证穿行（直接的正向验证测试，确保数据流正常运作），而且还应侧重于测试客户的关键控制： 1) 如果客户针对完整性和准确性（C&A）有关键控制，并且执行人工对帐，则记录管理层的流程和附件，其中可以找到针对对帐控制的测试（假设测试不会在此处记录 - 如果是，则需要添加其他测试矩阵）。 2) 如果客户依赖其变更管理控制，包括其作为变更流程的一部分而进行的测试，作为其对C&A的关键控制，请记录并索引变更管理控制（同时确保ITGC程序维护测试涵盖接口）。 3) 如果客户端具有自动化的C&A控制来验证诸如数据总计，重复传输，不完整/错误的传输之类的内容，请描述这些控制的测试程序，不仅包括控制的自动属性（例如配置，通知等），还包括控制的手动解析属性。
A3: 控制接口的变动管理怎么样？针对这些变动管理控制执行哪些程序？ | B3: 具体定义如何控制与接口相关的变更管理。 如果接口变更管理控制与 ITGC 中已涵盖的相同，请参考 ITGC 测试中已完成的测试。 如果以前在 ITGC 测试中未涵盖接口变更管理控制，请更新 ITGC 程序维护工作簿以反映这些变更控制。
A4: 如果数据流是通过自动化作业启动的，那么在接口上的作业处理控制上执行了哪些测试过程？ | B4: 具体定义如何控制与接口相关的自动化作业。 如果接口程序执行控制与 ITGC 中已有的控制相同，请参考ITGC 测试中已完成的测试。 如果以前在 ITGC 测试中未涵盖接口程序执行控制，请更新 ITGC 程序执行工作簿以反映这些变更控制。
A5: 项目组还执行了哪些测试过程？

Sheet PE-6
A1: 控制编号 | B1: ='C22 IT一般控制测试'!C24 -> PE-6
A2: 控制活动 | B2: ='C22 IT一般控制测试'!D24 -> 业务数据、财务数据依照既定安排和频率定期进行备份（包括异地备份）；
B3: ='C22 IT一般控制测试'!D25 -> 备份介质存放于具备适当安全措施的地点；
B4: ='C22 IT一般控制测试'!D26 -> 定期对备份数据进行恢复性测试，并保留相关记录；
B5: ='C22 IT一般控制测试'!D27 -> 制定灾难恢复计划与业务连续性计划，并对灾难恢复计划进行定期测试。
A7: 设计有效性标准审计程序 | C7: 设计有效性执行的审计程序
A8: 咨询管理层，了解用于定期备份财务数据的机制。具体而言，请考虑酌情了解以下属性： •负责安排备份和定义备份要求的一个或多个团队; •备份哪些财务数据和/或信息; •执行备份的计划和频率; •用于执行备份的工具; •存储备份媒体的位置及其安全方式; •是否制定了灾难恢复计划于业务连续性计划，并对灾难恢复计划定期进行演练测试； 检查证据以证实控制的设计。 | C8: 1.通过访谈公司（例如：信息技术部总监），我们了解到： 1)公司制定了《信息系统运维细则》等运维管理制度，明确了数据备份的负责人、负责团队、备份频率、恢复测试等事项； 2)（信息技术部）指派专岗xxx负责（xxx）系统的备份工作，备份策略是（时间、频率、涉及系统、备份数据的性质、备份工具等）。 3）（信息技术部）（每月）对备份文件进行恢复性测试，保证备份文件的可用性。 4）备份介质分为磁带机、磁盘服务器等，其中生产机房数据在（频率）备份到磁盘服务器后，以（频率）存储在磁带机，磁带放于xxx保险箱内，由xxx保管。 5）公司制定了灾难恢复计划与业务连续性计划，并（频率）进行灾难恢复计划进行演练。 2.我们获取并检查了上述《信息系统运维细则》等运维管理制度，及信息技术部门《岗位职责说明书》、《岗位职责不相容矩阵》等规范性文件，确认公司已建立较为完善的安全管理制度。
A9: 审计证据 | C9: 《信息系统运维细则》<C22.PE-3a-1> 《灾难恢复计划》<C22.PE-6-1> 《业务连续性计划》<C22.PE-6-2>
A10: 设计有效性测试结论 | C10: 有效
A13: 执行有效性测试（描述一个样本）
A14: 测试期间&样本总量 | B14: 控制类型：自动 发生频率：每日/每日多次 样本总量：x 审计期间：202X.1.1-202X.12.31 （每一类OE要分别描述）
A15: 抽样数量 | B15: 抽样数量：x （每一类OE要分别描述）
A16: 测试步骤 | B16: 执行有效性标准审计程序 | C16: 执行有效性执行的审计程序
A17: Test 1
A18: 1 | B18: 获取关于系统/应用程序备份作业频率的证据。 确保备份频率符合公司和/或专业政策及准则。 | C18: 1.我们检查并获取xxx系统备份策略<C22.PE-6-x>，各系统备份策略如下： a系统： b系统： 通过与公司《信息系统运维制度》中备份规定的对比，上述系统备份策略符合公司规定要求。
A19: Test 2
A20: 1 | B20: 基于备份监控的发生频率和与控制相关的风险，选取管理层执行备份监控复核的样本，并获取有关证据，测试下述属性： | C20: 1.通过获取并检查xxx系统的数据备份监控记录<C22.PE-6-x>，并抽取样本进行如下测试：
A21: 2 | B21: 从日期总体中抽取样本并测试这些日期运行的作业状态 | C21: 2.按照抽样频率抽取某个日期数据备份监控记录，并进行如下记录：
A22: 3 | B22: (a)备份成功运行 | C22: 3.通过检查x年x月x日的备份监控记录，我们了解到xxx系统的数据备份被成功执行。具体信息如下： xxxx 其余样本测试请参考OE测试底稿。
A23: 4 | B23: (b)若出现错误，会生成告警并通知适当人员，存在后续跟进处理以解决错误 | C23: 4.对于x年x月x日备份出现的异常情况，通过检查备份记录我们了解到由（信息科技部）xxx进行问题排查，并对出现错误的系统进行重新备份。
A24: Test 3
A25: 1 | B25: 确保公司灾难恢复计划定期演练测试符合公司/或专业政策要求。 | C25: 1.通过获取并检查公司灾难恢复计划演练记录<C22.PE-6-x>，我们了解到公司（每年）进行一次针对xxx系统的灾难恢复演练，参加人员为xxx部门。 我们抽取x年x月x日灾难恢复演练记录，记录中主要演练环节为： - xxx - xxx 因此我们确认公司灾难恢复演练是符合公司要求的。 其余样本测试请参考OE测试底稿。
A26: 执行有效性测试结论 | C26: 有效
A28: 样本记录（如果抽样数量>1，则在下表记录其余样本）
A29: 数据备份记录
A30: 序号 | B30: 备份日期 | C30: 备份涉及系统 | D30: 备份是否成功 | E30: 是否出现错误 | F30: 错误处理情况 | G30: 备注 | H30: 结论
A31: 1 | B31: xxx | C31: xxx | D31: xxx | E31: xxx | F31: xxx | G31: N/A | H31: 有效
A32: 2
A33: 灾难恢复演练记录
A34: 序号 | B34: 演练时间 | C34: 演练地点 | D34: 演练涉及系统 | E34: 演练涉及部门 | F34: 演练主要内容 | G34: 备注 | H34: 结论
A35: 1 | B35: xxx | C35: xxx | D35: xxx | E35: xxx | F35: xxx | G35: xxx | H35: 有效
A36: 2
A38: 缺陷评估
A39: 是否发现异常 | B39: No
A40: 缺陷描述 | B40: N/A
A41: 索引至<C21-1> IT审计发现汇总表 | B41: N/A

Sheet PE-7
A1: 控制编号 | B1: ='C22 IT一般控制测试'!C28 -> PE-7
A2: 控制活动 | B2: ='C22 IT一般控制测试'!D28 -> 企业建立了问题上报的制度以及处理流程，并且企业对受理的问题做出明确的问题处理纪录。
A4: 设计有效性标准审计程序 | C4: 设计有效性执行的审计程序
A5: 询问IT管理层，针对企业对于信息系统建设、使用、维护等方面的问题，了解一下内容： •公司对于信息系统问题事件的处理流程、审批环节是否制定了相应的制度、政策; •如何提交、处理、记录用户的上报问题; •是否使用了工具、软件用以处理问题上报、跟踪； 审查证据以证实控制设计。 | C5: 1.通过访谈公司（例如：信息技术部总监），我们了解到： 1)公司制定了《信息系统运维细则》等运维管理制度，明确规定了使用xxx管理工具作为信息系统问题上报、处理、反馈平台； 2)公司xxx系统面向应用层面使用用户，由用户提交系统使用问题、需求，由（信息技术部）职员进行处理、反馈。 2.我们获取并检查了上述《信息系统运维细则》等运维管理制度，确认公司已建立信息系统问题处理制度、流程。
A6: 审计证据 | C6: 《信息系统运维细则》<C22.PE-3a-1>
A7: 设计有效性测试结论 | C7: 有效
A10: 执行有效性测试（描述一个样本）
A11: 测试期间&样本总量 | B11: 控制类型：手工 发生频率：在需要时执行 样本总量：x 审计期间：202X.1.1-202X.12.31
A12: 抽样数量 | B12: 抽样数量：x
A13: 测试步骤 | B13: 执行有效性标准审计程序 | C13: 执行有效性执行的审计程序
A14: 1 | B14: 获取准确及完整的问题清单，测试下述属性： | C14: 1.我们获取了xxx系统问题清单<C22.PE-7-x>，共xx个，我们从中抽取样本并执行以下测试：
A15: 2 | B15: • 基于对相关工作的检查，确认信息系统问题、需求被恰当及时的处理和记录。 | C15: 2.通过获取并检查xxx系统问题清单，我们抽取其中xxx日期序号xxx的工单，了解到： 序号 问题编号 提报人 提报部门 提报时间 问题类型 问题描述 问题处理人 问题处理时间 问题处理结果 xxx xxx xxx xxx xxx 我们现场在问题记录涉及的xxx系统中验证上述问题处理情况，因此我们认为关于公司对信息系统问题、需求的处理和记录是及时有效的。 控制未见异常。 其余问题记录测试请参考OE测试底稿。
A16: 执行有效性测试结论 | C16: 有效
A18: 样本记录（如果抽样数量>1，则在下表记录其余样本）
A19: 序号 | B19: 问题编号 | C19: 提报人 | D19: 提报部门 | E19: 提报时间 | F19: 问题类型 | G19: 问题描述 | H19: 问题处理人 | I19: 问题处理时间 | J19: 问题处理结果 | K19: 备注 | L19: 结论
A20: 1 | B20: 976 | C20: 张某某 | D20: xxx | E20: 43170 | H20: 超级管理员账号 | I20: 43171 | J20: 已处理 | K20: N/A | L20: 有效
A21: 2
A23: 缺陷评估
A24: 是否发现异常 | B24: No
A25: 缺陷描述 | B25: N/A
A26: 索引至<C21-1> IT审计发现汇总表 | B26: N/A

Sheet PE-8
A1: 控制编号 | B1: ='C22 IT一般控制测试'!C29 -> PE-8
A2: 控制活动 | B2: ='C22 IT一般控制测试'!D29 -> 数据中心和计算机机房的物理访问权限适当限制在须获得相关访问权限以执行其被分配职责的人员。且数据中心的物理访问权限由管理层定期复核以核实访问权限仅授予经授权和适当的人员。
B3: ='C22 IT一般控制测试'!D30 -> 机房内配备必要的环境设施，如不间断电源、温控、湿控、烟感、非液体自动灭火装置、防静电地板、监控或闭路电视等；机房环境设施进行定期巡检，确保物理安全。
A5: 设计有效性标准审计程序 | C5: 设计有效性执行的审计程序
A6: 询问IT管理层，针对数据中心和计算机机房的物理访问及基础设施运维，了解一下内容： •数据中心和计算机机房的物理访问及基础设施运维管理的流程、制度； •管理层是否定期核实具有物理访问人员的权限； •基础设施的设置是否完善，具有必要的可以支撑生产需要的设备，如UPS、动力、环境监控设备等； •机房环境巡检是如何安排布置的； 审查证据以证实控制设计。 | C6: 1.通过访谈公司（例如：信息技术部总监），我们了解到： 1)公司制定了《信息系统运维细则》等运维管理制度等规范性文件，明确了数据中心和计算机机房物理访问的申请流程，及管理层定期对访问权限的复核制度； 2)数据中心和计算机机房的基础环境及设施：（详列列明机房地点、环境、建设标准、以及所有设备类别）。 3）（信息技术部）设置专岗xxx负责对机房进行运维，并执行定期巡检。
A7: 审计证据 | C7: 《信息系统运维细则》<C22.PE-3a-1>
A8: 设计有效性测试结论 | C8: 有效
A11: 执行有效性测试（描述一个样本）
A12: 测试期间&样本总量 | B12: 控制类型：手工 发生频率：每日/每日多次 样本总量：x 审计期间：202X.1.1-202X.12.31
A13: 抽样数量 | B13: 抽样数量：x
A14: 测试步骤 | B14: 执行有效性标准审计程序 | C14: 执行有效性执行的审计程序
A15: 1 | B15: 获取准确及完整的，覆盖本地机房与云平台的高特权物理及逻辑访问人员清单，测试下述属性： | C15: 1.我们获取了拥有数据中心和计算机机房物理访问人员清单<C22.PE-8-x>，共xx人，我们从中抽取样本并执行以下测试：
A16: 2 | B16: •基于对管理层的询问，访问特权已获授权且对于用户被分配的职责而言是恰当的（列明验证访问权限的人员） | C16: 2.通过与信息技术部负责人（xxx）的访谈，我们了解到，清单中人员（张某某、李四）等职员的岗位、职责分别是： 姓名 岗位 职责 张某某 xxx xxx 李四 xxx xxx 对公司管理层而言上述人员的岗位与其具有机房物理访问的权限是相匹配的。 控制未见异常。
A17: 3 | B17: • 基于对相关工作职能的检查，访问特权已获授权且对于用户被分配的职责而言是恰当的（包括佐证性信息来源的索引，例如组织架构图） | C17: 3.通过获取并检查《岗位授权书》<C22.PE-8-x>，我们了解到清单中人员（张某某）在《权限申请审批单》<C22.PE-8-x>，审批信息具体如下： 人员 岗位 系统名称 系统id 申请日期 审批日期 申请权限 审批人 审批权限 xxx xxx xxx xxx xxx xxx xxx xxx xxx 通过了解其担任的(基础环境运维岗)职责，我们认为职员张某某的访问权限对于被分配的职责而言是恰当的。 控制未见异常。 其余人员测试请参考OE测试底稿。
A18: 4 | B18: 获取准确及完整的管理层定期复核数据中心和计算机机房具有物理访问权限人员的记录，测试下述属性： | C18: 4.我们获取了管理层定期复核数据中心和计算机机房具有物理访问权限人员的记录<C22.PE-8-x>，我们从中抽取样本并执行以下测试：
A19: 5 | B19: • 基于对相关工作的检查，确认数据中心和计算机机房具有物理访问权限人员持有的权限是恰当的。 | C19: 5.数据中心和计算机机房具有物理访问权限人员经过管理层定期复核，复核频率为xxx。 通过获取并检查复核记录，了解到： 复核日期 复核人 复核内容 xxx xxx xxx 我们认为关于该复核记录可以确认数据中心和计算机机房具有物理访问权限人员持有的权限是恰当的。 控制未见异常。 其余复核测试请参考OE测试底稿。
A20: 6 | B20: 通过现场对数据中心和计算机机房的检查，检查基础环境设备的配备情况是否是恰当的： | C20: 6.通过对xxx机房的现场检查，我们了解到公司的计算机机房的位于xxx，（该控制点可以单独列一张表）请参考页签<PE-8.1>
A21: 7 | B21: 获取准确及完整的数据中心和计算机机房巡检记录，测试下述属性： | C21: 7.我们获取了数据中心和计算机机房巡检<C22.PE-8-x>，我们从中抽取样本并执行以下测试：
A22: 8 | B22: • 基于对相关工作的检查，确认数据中心和计算机机房具有巡检机制，且巡检内容是完善、恰当的。 | C22: 8.数据中心和计算机机房具有巡检机制，巡检频率为xxx，巡检人员为xxx。 通过获取并检查复核记录，了解到： 巡检日期 巡检内容 测试项目 xxx xxx xxx 我们认为该巡检记录是恰当的。 控制未见异常。 其余复核测试请参考OE测试底稿。
A23: 执行有效性测试结论 | C23: 有效
A25: 样本记录（如果抽样数量>1，则在下表记录其余样本）
A26: 授权记录OE testing
A27: 序号 | B27: 人员 | C27: 岗位 | D27: 权限 | E27: 系统id | F27: 申请日期 | G27: 审批日期 | H27: 申请权限 | I27: 审批人 | J27: 审批权限 | K27: 备注 | L27: 结论
A28: 1 | B28: 张某某 | C28: xxx | D28: xxx | E28: xxx | F28: 43170 | G28: 43171 | H28: xxx | I28: 蔡蔡 | J28: xxx | K28: N/A | L28: 有效
A29: 2
A30: 复核记录OE testing
A31: 序号 | B31: 复核日期 | C31: 复核人 | D31: 复核内容 | E31: 备注 | F31: 结论
A32: 1 | B32: 45658 | C32: xxx | D32: xxx | E32: N/A | F32: 有效
A33: 2
A35: 巡检记录OE testing
A36: 序号 | B36: 巡检日期 | C36: 巡检内容 | D36: 巡检项目（精密空调） | E36: 巡检项目（UPS） | F36: 巡检项目（依次向右列示） | G36: 备注 | H36: 结论
A37: 1 | B37: 45658 | C37: xxx | D37: √ | E37: √ | F37: √ | G37: N/A | H37: 有效
A38: 2
A40: 缺陷评估
A41: 是否发现异常 | B41: No
A42: 缺陷描述 | B42: N/A
A43: 索引至<C21-1> IT审计发现汇总表 | B43: N/A

Sheet PE-8.1
A1: 分类 | B1: 生产机房 | C1: 同城灾备机房 | D1: 异地灾备机房
A2: 机房地址 | B2: 河南省郑州市金水区郑州银行大楼17层 | C2: N/A（若不涉及） | D2: N/A（若不涉及）
A3: 机房筹建、选址评估 | B3: 1.生产机房为郑东新区CBD外环路22号，为郑州银行固定资产，于2006年报批、筹建，在大楼设计时已经考虑到17层计算机机房建设需要； 2.经过郑州银行考察，发现同城灾备机房周边没有明显水灾隐患，不存在易燃、易爆隐患；没有强震源、强噪声源；没有强电磁场；不属于地震、资质灾害高发区。 3.机房设计使用面积 1000 m2，开发办公区需 2000 m2。机房净高（地板到梁底）3.7 米，地面承重按 700kg/m2 设计，建筑材料的耐火等级符合国家规定的一级耐火等级。 4.计算机系统接地采用专用接地线，专用接地线的引线和大楼的钢筋及各种金属管道绝缘， 计算机系统的几种接地要求及诸地之间的相互关系应符合设计规范的规定。 | C3: N/A（若不涉及） | D3: N/A（若不涉及）
A4: 投产时间 | B4: 40360 | C4: N/A（若不涉及） | D4: N/A（若不涉及）
A5: 建筑物基本情况 | B5: 机房位于大楼17层，层高4.4米，梁下4.2米。 机房区域地板高度0.6米，机房净高2.75米。 | C5: N/A（若不涉及） | D5: N/A（若不涉及）
A6: 功能分区 | B6: 机房分为A、B、C、D、M区域，A、D区域为机房，C、D区域为电源室，M区域为网络室。 | C6: N/A（若不涉及） | D6: N/A（若不涉及）
A7: 消防 | B7: 防火区域为A、B、C、D、E五个区域，每个区域均配备气体灭火设施，气体钢瓶置于大楼16层避难层。 大楼17层非机房设备的办公区采用大楼物业统一喷淋灭火。 大楼17层走廊配备手持灭火器。 大楼17层D、M区域设置有排烟设置。 | C7: N/A（若不涉及） | D7: N/A（若不涉及）
A8: 电气（UPS） | B8: 整体采用2N冗余设计，UPS具备双路输入、双母线、每路容量为300KVA，目前负载率在30%左右，主负载配备STS。 UPS主要为主机、服务器、网络设备、监控设备、照明、及其他弱点设备提供电源。 UPS配电系统采用UPS输入、输出总柜和UPS分配列头柜等，UPS分配列头柜总进线开关均有监控功能。 配备柴油发电机放于大楼负一层，由行政部门进行管理。外部市电接入CBD会展中心110KV变电站两路母线。 | C8: N/A（若不涉及） | D8: N/A（若不涉及）
A9: 电气（布线） | B9: 自UPS电源柜采用放射式配电方式配至各用电设备，采用专用屏蔽电力电缆铺设在地板下方线槽内，具有防电磁辐射干扰、防鼠、防虫害的作用。 电源机柜均设置零线地线汇流排设备。 | C9: N/A（若不涉及） | D9: N/A（若不涉及）
A10: 电气（动力） | B10: 动力配电系统主要为专用空调、照明、辅助插座及新风系统提供电源。 | C10: N/A（若不涉及） | D10: N/A（若不涉及）
A11: 电气（照明） | B11: 机房区域配备格栅灯（应急灯），并且机柜区域上方格栅灯与机柜放置方向一致,断电时将由UPS对其供电。 | C11: N/A（若不涉及） | D11: N/A（若不涉及）
A12: 电气（接地） | B12: 大楼17层除走廊通道外，均铺设抗静电地板，同时机柜接入地板下方铜带，统一接地。 | C12: N/A（若不涉及） | D12: N/A（若不涉及）
A13: 电气（防雷） | B13: 大楼总体在低压总配电室安装一级电源避雷器，17层机房在UPS输入总柜安装（B+C）级电源避雷器，在UPS输出柜、分配总柜等装C级电源避雷器，在机房列头柜装D级电源避雷器，组成三级防护体系。 | C13: N/A（若不涉及） | D13: N/A（若不涉及）
A14: 空调通风 | B14: 大楼17层机房区域A、B、C、D、E五个区域，每个区域均配备专用空调，并且铺设相关冷凝水、空调给水排水工程，同时在空调部署周围铺设50cm高拦水坝。 采用气体灭火的区域部署消防排气系统。 | C14: N/A（若不涉及） | D14: N/A（若不涉及）
A15: 安防系统 | B15: 机房去重要区域配置掌型识别/密码+感应卡式读卡器，采用刷卡方式控制出入口。 | C15: N/A（若不涉及） | D15: N/A（若不涉及）
A16: 集中监控系统 | B16: 对专用精密空调、UPS主机、所有低压配电柜、高密机柜和小型机的用电支路、环境温湿度控制、地面漏水监测、新风系统。具有监测报警功能，系统管理员为生产机房负责人。 | C16: N/A（若不涉及） | D16: N/A（若不涉及）
A17: 人员值守 | B17: 配备2人7*24小时进行巡检，每2小时进行巡回检查。 | C17: N/A（若不涉及） | D17: N/A（若不涉及）

Sheet PM-3
A1: 控制编号 | B1: ='C22 IT一般控制测试'!C31 -> PM-3
A2: 控制活动 | B2: ='C22 IT一般控制测试'!D31 -> 变更管理的相关制度和流程被恰当记录、审批和下发。
A4: 设计有效性标准审计程序 | C4: 设计有效性执行的审计程序
A5: 1、询问IT管理层，并了解以下内容： •公司是否制定了正式的信息系统变更管理制度/流程； •制度制定或修订的流程，以及相关审批和下发渠道 2、获取并检查相关信息系统变更管理制度，确认公司是否制定了信息系统变更管理制度，制度是否足够和完善。 | C5: 1.通过访谈公司（信息技术部总监），我们了解到： 1)公司制定了《系统变更管理规定》和《系统配置管理办法》的系统变更管理制度； 2)公司信息管理制度由（信息技术部）制定，经公司（信息化工作委员会）审批后通过(OA系统)下发执行； 3）（信息技术部）每年定期对信息管理制定进行复核，并根据实际情况进行更新。 2.我们获取并检查了上述《系统变更管理规定》和《系统配置管理办法》，确认公司已建立较为完善的系统变更管理制度。
A6: 审计证据 | C6: 《系统变更管理规定》<C22.PM-3-1> 《系统配置管理办法》<C22.PM-3-2>
A7: 设计有效性测试结论 | C7: 有效
A10: 执行有效性测试（描述一个样本）
A11: 测试期间&样本总量 | B11: 控制类型：手工 发生频率：在需要时执行 样本总量：2 审计期间：202X.1.1-202X.12.31
A12: 抽样数量 | B12: 抽样数量：1
A13: 测试步骤 | B13: 执行有效性标准审计程序 | C13: 执行有效性执行的审计程序
A14: 1 | B14: 获取审计期间内新增、修订的信息系统变更管理制度清单并选取样本。对每一个所选取的样本，测试下述属性： | C14: 1.我们获取了公司信息系统管理制度清单，审计期间内共发生制度新增、修订2次，我们从中抽取样本并执行以下测试：
A15: 2 | B15: •制度的新增、修订由适当的管理层批准和/或提交 | C15: 2.通过获取并检查《系统变更管理规定审批记录》<C22.PM-3-3>,我们了解到，《系统变更管理规定》的修订由信息技术部执行，更新时间为2017年3月10日，并经由公司信息化工作委员会审批，审批时间为2017年3月11日。
A16: 3 | B16: • 经审批的制度由恰当的途径下发 | C16: 3.通过获取并查看公司《OA系统制度下发通知》<C22.PM-3-4>,我们了解到，《系统变更管理规定》经审批后，通过公司OA系统下发通知，并正式执行。
A17: 4 | B17: • 制度内容是更新或适用的 | C17: 4.通过获取并查看公司更新后的《系统变更管理规定》<C22.PM-3-1>，我们了解到，该管理制度针对系统变更上线管理进行了更新，符合公司管理现状。
A18: 执行有效性测试结论 | C18: 有效
A20: 样本记录（如果抽样数量>1，则在下表记录其余样本）
A21: 序号 | B21: 信息系统安全管理制度/流程 | C21: 更新时间 | D21: 审批时间 | E21: 审批人 | F21: 是否得到恰当下发 | G21: 制度/流程是最更新或适用的
A26: 缺陷评估
A27: 是否发现异常 | B27: No
A28: 缺陷描述 | B28: N/A
A29: 索引至<C21-1> IT审计发现汇总表 | B29: N/A

Sheet PM-4c
A1: 控制编号 | B1: ='C22 IT一般控制测试'!#REF! -> #REF!
A2: 控制活动 | B2: ='C22 IT一般控制测试'!#REF! -> #REF!
A4: 设计有效性标准审计程序 | C4: 设计有效性执行的审计程序
A5: 1、询问IT管理层以了解对生产环境实施变更的权限限制的相关控制，并了解以下内容： • 公司是否建立了对生产环境实施变更的权限限制的制度/流程； • 哪些角色有权限对生产环境实施变更（含系统版本变更与参数变更）； • 在生产环境实施变更（含系统版本变更与参数变更）过程中如何进行职责分离。 2、获取政策、程序指引或其他证据以佐证控制的设计。 | C5: 1.通过访谈公司（信息技术部总监），我们了解到： 1)公司制定了《系统变更管理规定》<C22.PM-3-1>，其中规范对生产环境实施变更的权限限制要求如下： 对生产环境实施变更应由系统管理员实施，变更实施的过程中，必须一人操作、一人复核。 开发人员不得被授予对生产环境实施变更的权限。 以上审批过程必须留下可供审计的审批记录。 2)我们获取并检查公司《系统变更管理规定》<C22.PM-3-1>，确认公司对生产环境实施变更的权限限制的相关控制恰当、进行了恰当的职责分离。
A6: 审计证据 | C6: 《系统变更管理规定》<C22.PM-3-1>
A7: 设计有效性测试结论 | C7: 有效
A10: 执行有效性测试（描述一个样本）
A11: 测试期间&样本总量 | B11: 控制类型：手工 发生频率：在需要时执行 样本总量：1 审计期间：202X.1.1-202X.12.31
A12: 抽样数量 | B12: 抽样数量：1
A13: 测试步骤 | B13: 执行有效性标准审计程序 | C13: 执行有效性执行的审计程序
A14: 1 | B14: 获取准确及完整的具有对生产环境实施变更权限的用户清单，测试下述属性： | C14: 1.我们了解到，具有对生产环境实施变更权限的用户为操作系统管理员。在操作系统管理员XXX的协助下，我们获取了操作系统用户清单。通过查看《操作系统用户清单》<C22.PM-4c-1>，同时现场检查系统内各账号的实际权限配置，我们了解到：拥有对生产环境实施变更权限的用户如下： 用户名：root，实际使用人：N/A 用户名：zhangsan，实际使用人：张三 用户名：lisi，实际使用人：李四 张三与李四均担任操作系统管理员，互为备岗。
A15: 2 | B15: •基于对管理层的询问，对生产环境实施变更权限已获授权且对于用户被分配的职责而言是恰当的（列明验证有生产环境变更权限的人员） | C15: 2.通过与IT部XX的访谈，我们了解到： 上述员工拥有对生产环境实施变更的权限经过管理层授权，且对于用户被分配的职责而言是恰当的。
A16: 3 | B16: •基于对相关工作职能的检查，对生产环境实施变更权限已获授权且对于用户被分配的职责而言是恰当的（包括佐证性信息来源的索引，例如变更管理流程、岗位职责说明书） | C16: 3.通过查看《操作系统管理员岗位职责说明书》<C22.PM-4c-2>，我们了解到： 上述员工拥有对生产环境实施变更的权限经过IT部经理XX授权，且对于用户被分配的职责而言是恰当的，符合变更管理流程与岗位职责说明书。 该员工不具有业务职能，不属于开发人员，符合职责分离原则。
A17: 执行有效性测试结论 | C17: 有效
A19: 缺陷评估
A20: 是否发现异常 | B20: No
A21: 缺陷描述 | B21: N/A
A22: 索引至<C21-1> IT审计发现汇总表 | B22: N/A

Sheet PM-4b
A1: 控制编号 | B1: ='C22 IT一般控制测试'!C33 -> PM-4b
A2: 控制活动 | B2: ='C22 IT一般控制测试'!D33 -> 管理层定期复核具有修改生产环境权限的用户操作。
A4: 设计有效性标准审计程序 | C4: 设计有效性执行的审计程序
A5: 1. 询问IT管理层针对具有修改生产环境权限的用户操作的复核流程，并了解以下内容： • 公司是否建立了正式的针对具有修改生产环境权限的用户操作的复核制度/流程； • 复核用户操作的程序及负责人； • 对用户操作进行复核的频率； • 复核的范围（例如，超级账户、操作系统管理员账户、高权限账户）和被视作例外的情况； • 复核执行的具体方式（例如，通过版本控制工具检查版本变化情况、检查所复核账户的系统操作日志、检查修改生产环境操作是否经过审批）； • 如何对复核进行记录及如何保存反映例外情况得到及时处理的证据。 2. 获取政策、程序指引或其他证据以佐证控制的设计。 | C5: 1.通过访谈公司（信息技术部总监），我们了解到： 1)公司制定了《系统变更管理规定》<C22.PM-3-1>，其中规范对具有修改生产环境权限的用户操作定期复核要求如下： 公司每月对具有修改生产环境权限的用户操作进行复核，由IT部门XX确认是否存在不适当的修改生产环境操作，并填写《具有修改生产环境权限的用户操作检查表》<C22.PM-4b-1>，对于不适当的修改生产环境操作及时追查原因。 2)我们获取并检查公司《系统变更管理规定》<C22.PM-3-1>，确认公司针对用户访问权限定期复核控制恰当。
A6: 审计证据 | C6: 《系统变更管理规定》<C22.PM-3-1>
A7: 设计有效性测试结论 | C7: 有效
A10: 执行有效性测试（描述一个样本）
A11: 测试期间&样本总量 | B11: 控制类型：手工 发生频率：每月一次 样本总量：12 审计期间：202X.1.1-202X.12.31
A12: 抽样数量 | B12: 抽样数量：2
A13: 测试步骤 | B13: 执行有效性标准审计程序 | C13: 执行有效性执行的审计程序
A14: 1 | B14: 基于与控制相关的风险和复核发生的频率，选取访问权限复核样本，测试下述属性： | C14: 1.我们获取了2017年审计期间内针对具有修改生产环境权限的用户操作复核的记录。 我们选取2017年7月、12月的《具有修改生产环境权限的用户操作检查表》作为样本，执行如下测试：
A15: 2 | B15: •对具有修改生产环境权限的用户操作复核包括全部的关键账号 | C15: 2.我们现场查看系统管理员重新导出关键账号操作日志的过程，发现导出日志涵盖了超级用户root账号、系统管理员账号，每月末导出上月操作日志，由IT部XX进行抽样检查。 对具有修改生产环境权限的用户操作复核包括全部的关键账号。
A16: 3 | B16: • 复核所覆盖的明细度及范围适当并得到适当的记录，以保证针对具有修改生产环境权限的用户操作复核能合理保证对生产环境修改的异常操作能够被发现并追查原因。 | C16: 3.通过访谈IT部XX，我们了解到，对关键账号操作日志复核主要涵盖如下方面内容： 通过检查《具有修改生产环境权限的用户操作检查表》<C22.PM-4b-1>，我们发现其中详细记录了检查的范围、异常情况描述及追查结果，我们确认： 复核所覆盖的明细度及范围适当并得到适当的记录，以保证针对具有修改生产环境权限的用户操作复核能合理保证对生产环境修改的异常操作能够被发现并追查原因。
A17: 4 | B17: • 复核由适当的管理层人员执行且已实施适当的职责分工 | C17: 4.通过检查《具有修改生产环境权限的用户操作检查表》<C22.PM-4b-1>，我们了解到： 审阅人：XX（IT部经理） 复核由适当的管理层人员执行且已实施适当的职责分工。
A18: 执行有效性测试结论 | C18: 有效
A20: 样本记录（如果抽样数量>1，则在下表记录其余样本）
A21: 序号 | B21: 系统名称 | C21: 样本名称 | D21: 复核日期 | E21: 复核人 | F21: 复核人适当*1 | G21: 针对复核中识别出的不当变更所采取的行动是适当的*2 | H21: 复核频率是否符合制度要求 *3 | I21: 以适当的精度水平执行复核 *4 | J21: 结论 | K21: 备注
A22: 1
A23: 2
A24: 3
A26: 标记注释
A27: *1 | B27: 以下情况，控制变更的监控过程被视为由适当的个人执行： • 负责实施变更的人不执行复核， • 负责制定变更的人不执行复核， • 复核人具有执行复核所需的技术知识，且 • 复核人在组织中拥有必要的权限，可以处罚不遵守变更管理政策的人员。 •（或者）管理层采用了自动化的变更控制监控工具组（即，复核由自动化工具执行）。
A28: *2 | B28: 以下情况，针对复核中识别的不当变更而采取的行动被认为是适当的： •识别并修复了在复核中发现的未经授权变更的根本原因。 •不适当的更改被撤回。 • 对不适当变更承担责任的人员因违反变更管理要求而受到处罚。
A29: *3 | B29: 如果按照定义的变更管理监控流程（如上文“控制细节”部分所述）遵循复核的节奏/时间表/频率，并且至少每年进行一次，则认为是及时的。
A30: *4 | B30: 如果变更管理监控复核考虑了以下情况，则该复核被认为适当精确的： • 应用程序代码/逻辑的变更（例如，安装供应商发布的补丁，实现自定义开发的增强功能） • 对储存在数据库中的代码/逻辑的变更（例如，对存储过程、包和触发器的变更）（如果适用）
A31: √ | B31: 经测试无偏差。
A32: × | B32: 不，不符合属性，已发现偏差。
A33: N/A | B33: 不适用
A35: 缺陷评估
A36: 是否发现异常 | B36: No
A37: 缺陷描述 | B37: N/A
A38: 索引至<C21-1> IT审计发现汇总表 | B38: N/A

Sheet PM-4e
A1: 控制编号 | B1: ='C22 IT一般控制测试'!C34 -> PM-4e
A2: 控制活动 | B2: ='C22 IT一般控制测试'!D34 -> 生产环境、测试环境、开发环境恰当分离。
A4: 设计有效性标准审计程序 | C4: 设计有效性执行的审计程序
A5: 1、询问IT管理层以了解对生产环境、测试环境、开发环境恰当分离的相关控制，并了解以下内容： • 公司是否建立了对生产环境、测试环境、开发环境隔离的制度/流程； • 对生产环境、测试环境、开发环境隔离采用的技术手段； • 公司采用何种手段对生产环境、测试环境、开发环境进行隔离（物理隔离/逻辑隔离（VLAN隔离/端口隔离））。 2、获取政策、程序指引或其他证据以佐证控制的设计。 | C5: 1.通过访谈公司（信息技术部总监），我们了解到： 1)公司制定了《系统配置管理办法》<C22.PM-3-2>，其中规定必须对生产环境、测试环境与开发环境进行物理或逻辑隔离。 2)我们获取并检查公司《系统配置管理办法》<C22.PM-3-2>，确认公司针对生产环境、测试环境、开发环境恰当分离的控制恰当。
A6: 审计证据 | C6: 《系统配置管理办法》<C22.PM-3-2>
A7: 设计有效性测试结论 | C7: 有效
A10: 执行有效性测试（描述一个样本）
A11: 测试期间&样本总量 | B11: 控制类型：手工 发生频率：在需要时执行 样本总量：1 审计期间：202X.1.1-202X.12.31
A12: 抽样数量 | B12: 抽样数量：1
A13: 测试步骤 | B13: 执行有效性标准审计程序 | C13: 执行有效性执行的审计程序
A14: 1 | B14: 获取关于生产环境、测试环境、开发环境分离的证据，以评价其实施是否与控制的设计相一致。在执行测试时考虑下述属性： | C14: 1.我们获取了XX系统生产环境、测试环境及开发系统的IP地址。通过查看《生产环境、测试环境及开发系统IP地址截图》<C22.PM-4e-1>，我们了解到：各环境IP地址如下： 生产环境：XX.XX.XX.XX 测试环境：XX.XX.XX.XX 开发环境：XX.XX.XX.XX
A15: 2 | B15: •如对各环境采取物理隔离方式，则各环境所属网络物理结构在任何情况下不能互相通信 | C15: 2.通过与IT部XX的访谈，我们了解到公司采取物理隔离方式进行生产环境、测试环境、开发环境分离。 通过检查《网络拓扑图》<C22.PM-4e-2>，发现生产环境、测试环境、开发环境之间通过网闸进行物理隔离。
A16: 3 | B16: • 如对各环境采取逻辑隔离方式（VLAN隔离/端口隔离），则该隔离的配置有效，且各环境在生效的配置下无法直接通信 | C16: 3.通过与IT部XX的访谈，我们了解到公司采取逻辑隔离方式进行生产环境、测试环境、开发环境分离。 通过检查VLAN隔离/端口隔离配置，发现已将生产环境、测试环境、开发环境所属子网通过VLAN划分/同一VLAN内通过配置不同端口进行隔离。 实际验证后发现生产环境、测试环境、开发环境之间无法ping通，实现了逻辑隔离。
A17: 执行有效性测试结论 | C17: 有效
A19: 样本记录（如果抽样数量>1，则在下表记录其余样本）
A20: 序号 | B20: 审计范围内的操作系统，数据库和应用系统 | C20: 开发环境 | D20: 测试环境 | E20: 中间环境（质量控制，试机） | F20: 生产环境 | G20: 描述系统环境分离的方法 | H20: 分离方法有效
A25: 缺陷评估
A26: 是否发现异常 | B26: No
A27: 缺陷描述 | B27: N/A
A28: 索引至<C21-1> IT审计发现汇总表 | B28: N/A

Sheet PM-5
A1: 控制编号 | B1: ='C22 IT一般控制测试'!C35 -> PM-5
A2: 控制活动 | B2: ='C22 IT一般控制测试'!D35 -> 所有的系统变更均被有效记录，系统变更管理工具的访问权限受到适当限制。
A4: 设计有效性标准审计程序 | C4: 设计有效性执行的审计程序
A5: 1、询问IT管理层以了解对所有系统变更记录的相关控制，并了解以下内容： • 公司是否建立了对所有系统变更记录的制度/流程； • 采用何种方式记录变更（自动/手工），采用何种变更管理工具； • 复核变更记录的程序及负责人（仅在有系统自动记录时检查）； •采用何种控制方式对变更管理工具的访问权限进行控制。 2、获取政策、程序指引或其他证据以佐证控制的设计。 | C5: 1.通过访谈公司（信息技术部总监），我们了解到： 1)公司制定了《系统变更管理规定》<C22.PM-3-1>，其中规范对系统变更记录的要求如下： 使用excel手工台账记录所有的系统变更，由操作系统管理员作为变更实施人进行维护； 使用SVN记录所有的变更版本，通常于上线前后进行程序版本的备份，所有历史变更版本均保留。 仅操作系统管理员有权访问SVN。 2)我们获取并检查公司《系统变更管理规定》<C22.PM-3-1>，确认公司针对系统变更记录及系统变更管理工具访问权限的控制恰当。
A6: 审计证据 | C6: 《系统变更管理规定》<C22.PM-3-1>
A7: 设计有效性测试结论 | C7: 有效
A10: 执行有效性测试（描述一个样本）
A11: 测试期间&样本总量 | B11: 控制类型：手工 发生频率：在需要时执行 样本总量：12 审计期间：202X.1.1-202X.12.31
A12: 抽样数量 | B12: 抽样数量：2
A13: 测试步骤 | B13: 执行有效性标准审计程序 | C13: 执行有效性执行的审计程序
A14: 1 | B14: 获取审计期间内的全部变更清单并选取样本，测试以下属性： | C14: 1.在操作系统管理员XXX的协助下，我们获取了审计期间内SVN中记录的全部变更程序版本。通过查看《SVN变更程序清单》<C22.PM-5-1>，发现审计期间呢共发生变12次，我们从中抽取样本并执行以下测试：
A15: 2 | B15: •所有的系统变更均被有效记录 | C15: 2.通过检查《系统变更记录手工台账》<C22.PM-5-2>，我们发现： 抽样的系统变更样本均被有效记录。
A16: 3 | B16: •系统自动记录变更时，变更的记录均被有效检查 | C16: 3.通过与IT部XX的访谈，我们了解到： 操作系统管理员会对系统自动记录变更工具的变更结果进行检查，并形成检查记录《系统变更检查记录》<C22.PM-5-3>。
A17: 4 | B17: •变更管理工具的访问权限受到适当限制 | C17: 4.通过查看《操作系统管理员岗位职责说明书》<C22.PM-4c-2>，我们了解到： 仅操作系统管理员有权访问变更管理工具SVN，访问权限的开通需有IT部XX审批。
A18: 执行有效性测试结论 | C18: 有效
A20: 描述系统变更日志的记录和处理方法 | D20: 系统日志是否适当
A23: 描述系统变更管理工具的使用情况（适用时） | D23: 变更管理工具的使用是否适当
A26: 样本记录（如果抽样数量>1，则在下表记录其余样本）
A27: A系统
A28: 序号 | B28: 变更序列号 | C28: 变更内容 | D28: 上线时间 | E28: 变更有日志 （系统记录/系统外记录） | F28: 系统是否具有记录自己被修改的功能 | G28: 变更的序列号 | H28: 是否进行变更复核工作（仅在有系统自动记录时检查） | I28: 结论 | J28: 备注
A33: 缺陷评估
A34: 是否发现异常 | B34: No
A35: 缺陷描述 | B35: N/A
A36: 索引至<C21-1> IT审计发现汇总表 | B36: N/A

Sheet PM-6
A1: 控制编号 | B1: ='C22 IT一般控制测试'!C36 -> PM-6
A2: 控制活动 | B2: ='C22 IT一般控制测试'!D36 -> 变更在移至生产环境前已获适当批准及已被测试。
A4: 设计有效性标准审计程序 | C4: 设计有效性执行的审计程序
A5: 1、询问IT管理层以了解对变更移至生产环境前测试及批准的相关控制，并了解以下内容： • 公司是否建立了对变更移至生产环境前测试及批准的制度/流程； • 对变更移至生产环境前测试的主体及形成的测试记录； • 负责审批变更移至生产环境的人员或团队； • 变更申请如何进行提交、批准及记录； • 审批人和执行人是否进行恰当职责分离； 2、获取政策、程序指引或其他证据以佐证控制的设计。 | C5: 1.通过访谈公司（信息技术部总监），我们了解到： 1)公司制定了《系统变更管理规定》<C22.PM-3-1>，其中规范对变更移至生产环境前测试及批准的要求如下： 变更移至生产环境前必须经过测试，包括开发人员测试及用户测试，并分别形成测试报告； 变更移至生产环境根据变更的级别不同，采用不同审批流程，例如……； 审批人和执行人已进行恰当职责分离； 2)我们获取并检查公司《系统变更管理规定》<C22.PM-3-1>，确认公司针对变更移至生产环境前测试及批准的控制恰当。
A6: 审计证据 | C6: 《系统变更管理规定》<C22.PM-3-1>
A7: 设计有效性测试结论 | C7: 有效
A10: 执行有效性测试（描述一个样本）
A11: 测试期间&样本总量 | B11: 控制类型：手工 发生频率：在需要时执行 样本总量：12 审计期间：202X.1.1-202X.12.31
A12: 抽样数量 | B12: 抽样数量：2
A13: 测试步骤 | B13: 执行有效性标准审计程序 | C13: 执行有效性执行的审计程序
A14: 1 | B14: 获取关于变更移至生产环境前测试及批准的证据，以评价其实施是否与控制的设计相一致。在执行测试时考虑下述属性： | C14: 1.在操作系统管理员XXX的协助下，我们获取了审计期间内SVN中记录的全部变更程序版本。通过查看《SVN变更程序清单》<C22.PM-5-1>，发现审计期间呢共发生变12次，我们从中抽取样本并执行以下测试：
A15: 2 | B15: •变更移至生产环境前已被恰当测试，并保留完整测试记录 | C15: 2.获取并检查《系统变更集成测试报告》<C22.PM-6-1>与《系统变更用户测试报告》<C22.PM-6-2>，我们发现： 抽样的系统变更样本均经过恰当测试，并保留完整测试记录。
A16: 3 | B16: • 变更移至生产环境前已获适当批准，并保留完整审批记录 | C16: 3.获取并检查《系统变更审批记录》<C22.PM-6-2>，我们发现： 抽样的系统变更样本均经过适当批准，并保留完整审批记录。
A17: 4 | B17: • 审批人和执行人是否进行恰当职责分离 | C17: 4.通过与IT部XX的访谈，我们了解到： 操作系统管理员负责将系统变更移至生产环境，审批人为IT部XX，符合职责分离原则。
A18: 执行有效性测试结论 | C18: 有效
A20: 样本记录（如果抽样数量>1，则在下表记录其余样本）
A21: A系统
A22: 序号 | B22: 变更序列号 | C22: 变更内容 | D22: 上线时间 | E22: 上线审批日期 | F22: 适当的IT和用户批准 *1 | G22: 适当的测试范围 *2 | H22: 在适当的环境中测试 *3 | I22: 参与测试的用户 *4 | J22: 恰当的文件记录 *5 | K22: 由适当的人员转移到生产系统 *6 | L22: 结论 | M22: 备注
A26: 标记注释
A27: *1 | B27: 使用与变更的性质和重要性相适应的标准（包括文档）进行质量保证复核。 由适当客观性和知识丰富的、没有编程责任的IT人员进行质量保证复核。 在生产环境中已发布的变更，在实施之前获得批准（对于非紧急变更）。 由负责变更管理流程的 IT 人员批准，并在适用时（即 - 需要最终用户参与的变更）由相关最终用户组代表批准。
A28: *2 | B28: 根据变更的性质和重要性（包括质量保证）进行测试和记录。大型更新需要最终用户组进行更多的测试和参与，而修补程序更新可能只需要在实施之前由系统管理员进行测试。
A29: *3 | B29: 测试以不损害生产环境的方式执行（例如，在逻辑上或虚拟上与生产代码隔离开）。
A30: *4 | B30: 用户参与包括与变更的性质和重要性一致的内容。 大型更新需要最终用户组进行更多的测试和参与，而修补程序更新可能只需要在实施之前由系统管理员进行测试。
A31: *5 | B31: 文档包括以下项目：对所涉及的应用程序的描述、已解决或要解决的问题以及将来进行或将要进行的增强、记录、跟踪变更，并记录其最终的处置情况。
A32: *6 | B32: 由授权用户移至生产系统。
A33: √ | B33: 经测试无偏差。
A34: × | B34: 不，不符合属性，已发现偏差。
A35: N/A | B35: 不适用。
A37: 缺陷评估
A38: 是否发现异常 | B38: No
A39: 缺陷描述 | B39: N/A
A40: 索引至<C21-1> IT审计发现汇总表 | B40: N/A

Sheet NS-1
A1: 控制编号 | B1: ='C22 IT一般控制测试'!C37 -> NS-1
A2: 控制活动 | B2: ='C22 IT一般控制测试'!D37 -> 系统开发、采购、实施的相关制度和流程被恰当记录、审批和下发。
A4: 设计有效性标准审计程序 | C4: 设计有效性执行的审计程序
A5: 1、询问IT管理层，并了解以下内容： •公司是否制定了正式的信息系统开发管理制度/流程； •制度制定或修订的流程，以及相关审批和下发渠道 2、获取并检查相关信息系统开发管理制度，确认公司是否制定了信息系统变更管理制度，制度是否足够和完善。 | C5: 1.通过访谈公司（信息技术部总监），我们了解到： 1)公司制定了《信息系统项目管理办法》； 2)公司信息管理制度由（信息技术部）制定，经公司（信息化工作委员会）审批后通过(OA系统)下发执行； 3）（信息技术部）每年定期对信息管理制定进行复核，并根据实际情况进行更新。 2.我们获取并检查了上述《信息系统项目管理办法》，确认公司已建立较为完善的系统开发管理制度。
A6: 审计证据 | C6: 《信息系统项目管理办法》<C22.NS-1-1>
A7: 设计有效性测试结论 | C7: 有效
A10: 执行有效性测试（描述一个样本）
A11: 测试期间&样本总量 | B11: 控制类型：手工 发生频率：在需要时执行 样本总量：0 审计期间：202X.1.1-202X.12.31
A12: 抽样数量 | B12: 抽样数量：0
A13: 测试步骤 | B13: 执行有效性标准审计程序 | C13: 执行有效性执行的审计程序
A14: 1 | B14: 获取审计期间内新增、修订的信息系统开发管理制度清单并选取样本。对每一个所选取的样本，测试下述属性： | C14: 1.我们获取了公司信息系统管理制度清单，审计期间内公司信息系统开发制度未发生更新或修订情况。我们获取公司现有《信息系统项目管理办法》，并检查以下内容：
A15: 2 | B15: •制度的新增、修订由适当的管理层批准和/或提交 | C15: 2.《信息系统项目管理办法》的更新时间为2015年3月10日，并经由公司信息化工作委员会审批后正式执行。
A16: 3 | B16: • 经审批的制度由恰当的途径下发 | C16: 3.通过获取并查看公司《OA系统制度下发通知》<C22.PM-3-4>,我们了解到，《信息系统项目管理办法》经审批后，通过公司OA系统下发通知，时间为2015年3月11日。
A17: 4 | B17: • 制度内容是更新或适用的 | C17: 4.通过查看《信息系统项目管理办法》，我们了解到管理办法目前与公司实际管控情况一致，满足公司管理需要。
A18: 执行有效性测试结论 | C18: 未测试
A20: 样本记录（如果抽样数量>1，则在下表记录其余样本）
A21: 序号 | B21: 信息系统安全管理制度/流程 | C21: 更新时间 | D21: 审批时间 | E21: 审批人 | F21: 是否得到恰当下发 | G21: 制度/流程是最更新或适用的
A26: 缺陷评估
A27: 是否发现异常 | B27: No
A28: 缺陷描述 | B28: N/A
A29: 索引至<C21-1> IT审计发现汇总表 | B29: N/A

Sheet NS-3
A1: 控制编号 | B1: ='C22 IT一般控制测试'!C38 -> NS-3
A2: 控制活动 | B2: ='C22 IT一般控制测试'!D38 -> 生产环境、测试环境、开发环境恰当分离。
A4: 设计有效性标准审计程序 | C4: 设计有效性执行的审计程序
A5: 1、询问IT部门领导或系统开发工作的负责人，了解公司是否对审计范围内系统的生产环境、与开发环境，生产环境与测试环境在物理或逻辑方面进行了隔离； 2、获取并检查公司关于信息系统开发管理的相关制度，确认制度中是否明确规定对生产环境与开发环境、生产环境与测试环境进行物理或逻辑隔离。 | C5: • 通过询问ABC公司信息技术部开发经理XYZ，ITA 了解到：ABC公司在《ABC公司系统开发管理制度》<C22.NS-3-1>中规定了公司信息系统的生产环境与开发环境、生产环境与测试环境必须进行物理隔离，并依据该规定严格执行； • ITA获取并检查了《ABC公司系统开发管理制度》，其中第X章第X款中对生产环境与开发环境、生产环境与测试环境需进行物理隔离做出了明确规定。 • 经询问，公司A/B/C系统均使用不同的主机及IP地址来进行开发环境、生产环境与测试环境的隔离。
A6: 审计证据 | C6: 《ABC公司系统开发管理制度》<C22.NS-3-1>
A7: 设计有效性测试结论 | C7: 有效
A10: 执行有效性测试（描述一个样本）
A11: 测试期间&样本总量 | B11: 控制类型：手工 发生频率：在需要时执行 样本总量：3 审计期间：202X.1.1-202X.12.31
A12: 抽样数量 | B12: 抽样数量：3
A13: 测试步骤 | B13: 执行有效性标准审计程序 | C13: 执行有效性执行的审计程序
A14: 1 | B14: 针对审计范围内的系统，获取其开发环境、生产环境和测试环境的ip地址截图 | C14: 1.ITA获取A/B/C系统的开发环境IP地址、测试环境IP地址和生产环境IP地址截图，见《XX系统IP地址截图》<C22.NS-3-1>，并执行了以下测试：
A15: 2 | B15: 在cmd下(命令行状态下）运行ipconfig命令，在某一个环境的机器上进行网络通信测试（进入cmd，运行ping命令，ping其他环境的ip地址，这个操作应由ITA人员实地查看客户IT人员完成），获取并查看通信测试的截图（截图要包含本机ip地址，以及ping命令执行的结果），确认公司对相关系统的开发环境、生产环境和测试环境进行了物理或逻辑隔离。 | C15: 2.在测试环境中进行网络通信测试，ping开发环境及生产环境的ip地址，并获取，确认了ABC公司对XX系统生产环境与开发环境、生产环境与测试环境进行了物理隔离。
A16: 执行有效性测试结论 | C16: 有效
A18: 样本记录（如果抽样数量>1，则在下表记录其余样本）
