Workbook

Sheet 底稿目录
A1: 底稿开列时，可先在以下单元格填写有关内容，以便其他底稿引用有关数据：
A2: 被审计单位名称： | D2: 序号 | E2: 内容 | F2: 索引号
A3: 截止日：202X年12月31日 | D3: 1 | E3: 递延所得税资产审计程序表 | F3: N1A
A4: 编制人： | D4: 2 | E4: 递延所得税资产审定表 | F4: N1-1
A5: 编制日期： | D5: 3 | E5: 附注披露信息（上市公司） | G5: 无需打印
A6: 复核人： | D6: 4 | E6: 附注披露信息（国企） | G6: 无需打印
A7: 复核日期： | D7: 5 | E7: 递延所得税资产明细表 | F7: N1-2
D8: 6 | E8: 调整分录汇总 | F8: N1-3
A9: 关于工作底稿与审计程序索引号对应的说明 | D9: 7 | E9: 递延所得税资产（负债）测算表 | F9: N1-4
A10: 1.编制的审计工作底稿应与审计程序对应。审计项目组应根据被审计单位实际情况和风险评估情况在实质性程序表中裁剪、修改或增加审计程序，根据实际执行的审计程序完成相应审计工作底稿，编制的工作底稿中应按自然顺序依次编制索引号，并通过唯一的索引号将与实质性程序表中的程序对应关联（即将工作底稿的索引号填入实质性程序表中的底稿索引号列）。 | D10: 8 | E10: 可用以后年度税前利润弥补的亏损检查表 | F10: N1-5
A14: 2.获取的支持性证据应与审计底稿或程序对应。审计项目组在完成底稿时获取的支持性证据应根据底稿索引号编制下一级按自然顺序排序的索引号（如D1-2-1、D1-2-2、……），并在底稿中说明引用的支持性证据、关联索引号。
A17: 3.工作底稿索引号的编码规则：实质性程序索引号按循环从“D”到“N”,循环内账户以顺序号排列，模板中底稿索引号按账户顺序+自然数顺序（即模板中索引号按二级自然顺序排列，如D1-1、D1-2、D1-3、……D1-N）。

Sheet 递延所得税资产审计程序表的N1A
A1: 致同会计师事务所
A2: 递延所得税资产实质性程序表
A3: =底稿目录!A2 -> 被审计单位名称： | D3: =底稿目录!A4 -> 编制人： | G3: =底稿目录!A5 -> 编制日期： | I3: 索引号： | J3: N1A
A4: =底稿目录!A3 -> 截止日：202X年12月31日 | D4: =底稿目录!A6 -> 复核人： | G4: =底稿目录!A7 -> 复核日期： | I4: 页次：
A5: 一、本账户涉及的科目
A6: 递延所得税资产
A7: 二、审计目标与财务报表认定的关系
A8: 审计目标 | H8: 财务报表的认定
A9: A.资产负债表中记录的递延所得税资产是存在的，且已经记录在恰当的账户中 | H9: 存在
A10: B.所有应记录的递延所得税资产均已记录，所有应当包括在财务报表中的相关披露均已包括 | H10: 完整性
A11: C.记录的递延所得税资产由被审计单位拥有或控制。 | H11: 权利和义务
A12: D.递延所得税资产以恰当的金额包括在财务报表中，与之相关的计价或分摊调整已恰当记录，相关披露已得到恰当计量和描述 | H12: 准确性、计价和分摊
A13: E.递延所得税资产已被恰当地汇总或分解且表述清楚，相关披露在按照企业会计准则的编制基础下是相关的、可理解的 | H13: 列报
A14: 三、计划实施的实质性程序
A15: 序号 | B15: 对应LEAP程序 | C15: 审计程序 | D15: 程序分类 | E15: 财务报表的认定 | J15: 底稿索引号
E16: 存在 | F16: 完整性 | G16: 权利和 义务 | H16: 准确性、计价和分摊 | I16: 列报 | K16: 根据被审计单位实际情况和风险评估情况裁剪、修改或增加审计程序
A17: 1 | B17: 常规程序 | C17: 获取递延所得税资产明细表，完成以下工作并编制审定表： (1)复核加计正确，与总账、明细账合计数核对是否相符，期初余额与上期审定期末余额是否相符； (2)识别被审计单位期初递延所得税资产项目及金额，以及对当期经营损失以及未来期间的影响。 | D17: 常规★ | E17: √ | F17: √ | H17: √ | J17: N1-1 /N1-2
A18: 2 | B18: IPE程序 | C18: 在使用手工编制、自定义信息报告、系统生成的非固定格式报告等由被审计单位生成的信息时，测试有关信息准确性和完整性，并考虑针对编制和维护由被审计单位生成的信息的相关控制实施控制测试，以评价该信息是否能够为实现审计目的提供基础。 | F18: √ | H18: √ | J18: T1
A19: 3 | B19: 期初余额 | C19: 对期初余额的审计，获得并查阅账户余额明细表，确定采用的会计政策和程序是适当的，确定暂时性差异的合理性，必要时，向税务专家咨询。 (适用于首次承接） | D19: 备选 | E19: √ | G19: √ | H19: √
A20: 4 | B20: 应对措施-检查 | C20: 检查被审计单位采用的会计政策是否为资产负债表债务法。检查被审计单位用于确认递延所得税资产的税率是否根据税法的规定，按照预期收回该资产期间的适用税率计量。 | D20: 常规★ | E20: √ | F20: √ | H20: √ | J20: N1-1 /N1-2
A21: 5 | B21: 应对措施-检查 | C21: 重新计算各项可抵扣暂时性差异，检查其会计处理是否正确 | D21: 常规★ | H21: √ | J21: N1-4
A22: 6 | B22: 应对措施-检查 | C22: 检查是否以未来期间很可能取得用来抵扣可抵扣暂时性差异的应纳税所得额为限，确认由可抵扣暂时性差异产生的递延所得税资产，并检查提供证据是否充分，如果预计未来期间很可能无法获得足够的应纳税所得额用以抵扣递延所得税资产，检查是否减记递延所得税资产的账面价值。 | D22: 常规★ | E22: √ | G22: √ | H22: √ | J22: N1-5
A23: 7 | B23: 应对措施-检查 | C23: 检查递延所得税资产增减变动记录，及可抵扣暂时性差额的形成原因，确定是否符合有关规定，计算是否正确，预计转销期是否适当，并特别关注下列事项： (1)检查是否存在同时具有下列特征的交易因资产或负债的初始确认而产生的递延所得税资产不应予以确认，而被审计单位予以确认的情况 ①该项交易不是企业合并 ②交易发生时既不影响会计利润也不影响应纳税所得额或可抵扣亏损 (2)检查被审计单位对子公司、联营企业及合营企业投资相关的可抵扣暂时性差异，在同时满足下列条件时，是否确认相应的递延所得税资产 ①暂时性差异在可预见的未来很可能转回 ②未来很可能获得用来抵扣可抵扣暂时性差异的应纳税所得额 | D23: 常规★ | E23: √ | F23: √ | H23: √ | J23: N1-4 /N1-5
A24: 8 | C24: 根据评估的舞弊风险等因素增加的审计程序。 | D24: IPO/上市/新三板/重组/舞弊应对
A25: 9 | B25: 常规程序 | C25: 检查递延所得税资产是否已按企业会计准则或其他适用的规定在财务报表中做出恰当列报和披露。 | D25: 常规★ | J25: A1-1/A1-15 /A1-16

Sheet 递延所得税资产审定表N1-1
A1: 致同会计师事务所
A2: 递延所得税资产审定表
A3: =底稿目录!A2 -> 被审计单位名称： | C3: =底稿目录!A4 -> 编制人： | H3: =底稿目录!A5 -> 编制日期： | M3: 索引号： | N3: N1-1
A4: =底稿目录!A3 -> 截止日：202X年12月31日 | C4: =底稿目录!A6 -> 复核人： | H4: =底稿目录!A7 -> 复核日期： | M4: 页次：
A5: 项目 | B5: 期初数 | F5: 期末数 | J5: 本期未审数与上期 未审数的比较 | L5: 本期审定数与上期 审定数的比较 | N5: 原因分析 | O5: 提示：根据被审计单位税收项目具体情况增减项目明细
B6: 未审数 | C6: 账项调整 | D6: 重分类调整 | E6: 审定数 | F6: 未审数 | G6: 账项调整 | H6: 重分类调整 | I6: 审定数 | J6: 变动额 | K6: 变动率 | L6: 变动额 | M6: 变动率
A7: 资产减值准备 | B7: =SUMIF('递延所得税资产明细表N1-2'!$B$11:$B$40,'递延所得税资产审定表N1-1'!$A7,'递延所得税资产明细表N1-2'!E$11:E$40) -> 0 | C7: =SUMIF('递延所得税资产明细表N1-2'!$B$11:$B$40,'递延所得税资产审定表N1-1'!$A7,'递延所得税资产明细表N1-2'!F$11:F$40) -> 0 | D7: =SUMIF('递延所得税资产明细表N1-2'!$B$11:$B$40,'递延所得税资产审定表N1-1'!$A7,'递延所得税资产明细表N1-2'!G$11:G$40) -> 0 | E7: =B7+C7+D7 -> 0 | F7: =SUMIF('递延所得税资产明细表N1-2'!$B$11:$B$40,'递延所得税资产审定表N1-1'!$A7,'递延所得税资产明细表N1-2'!K$11:K$40) -> 0 | G7: =SUMIF('递延所得税资产明细表N1-2'!$B$11:$B$40,'递延所得税资产审定表N1-1'!$A7,'递延所得税资产明细表N1-2'!L$11:L$40) -> 0 | H7: =SUMIF('递延所得税资产明细表N1-2'!$B$11:$B$40,'递延所得税资产审定表N1-1'!$A7,'递延所得税资产明细表N1-2'!M$11:M$40) -> 0 | I7: =F7+G7+H7 -> 0 | J7: =F7-B7 -> 0 | K7: =IF(AND(B7=0,J7=0),0,IF(AND(B7=0,J7>0),1,J7/B7)) -> 0 | L7: =I7-E7 -> 0 | M7: =IF(AND(E7=0,L7=0),0,IF(AND(E7=0,L7>0),1,L7/E7)) -> 0
A8: 可抵扣亏损 | B8: =SUMIF('递延所得税资产明细表N1-2'!$B$11:$B$40,'递延所得税资产审定表N1-1'!$A8,'递延所得税资产明细表N1-2'!E$11:E$40) -> 0 | C8: =SUMIF('递延所得税资产明细表N1-2'!$B$11:$B$40,'递延所得税资产审定表N1-1'!$A8,'递延所得税资产明细表N1-2'!F$11:F$40) -> 0 | D8: =SUMIF('递延所得税资产明细表N1-2'!$B$11:$B$40,'递延所得税资产审定表N1-1'!$A8,'递延所得税资产明细表N1-2'!G$11:G$40) -> 0 | E8: =B8+C8+D8 -> 0 | F8: =SUMIF('递延所得税资产明细表N1-2'!$B$11:$B$40,'递延所得税资产审定表N1-1'!$A8,'递延所得税资产明细表N1-2'!K$11:K$40) -> 0 | G8: =SUMIF('递延所得税资产明细表N1-2'!$B$11:$B$40,'递延所得税资产审定表N1-1'!$A8,'递延所得税资产明细表N1-2'!L$11:L$40) -> 0 | H8: =SUMIF('递延所得税资产明细表N1-2'!$B$11:$B$40,'递延所得税资产审定表N1-1'!$A8,'递延所得税资产明细表N1-2'!M$11:M$40) -> 0 | I8: =F8+G8+H8 -> 0 | J8: =F8-B8 -> 0 | K8: =IF(AND(B8=0,J8=0),0,IF(AND(B8=0,J8>0),1,J8/B8)) -> 0 | L8: =I8-E8 -> 0 | M8: =IF(AND(E8=0,L8=0),0,IF(AND(E8=0,L8>0),1,L8/E8)) -> 0
A9: 内部交易未实现利润 | B9: =SUMIF('递延所得税资产明细表N1-2'!$B$11:$B$40,'递延所得税资产审定表N1-1'!$A9,'递延所得税资产明细表N1-2'!E$11:E$40) -> 0 | C9: =SUMIF('递延所得税资产明细表N1-2'!$B$11:$B$40,'递延所得税资产审定表N1-1'!$A9,'递延所得税资产明细表N1-2'!F$11:F$40) -> 0 | D9: =SUMIF('递延所得税资产明细表N1-2'!$B$11:$B$40,'递延所得税资产审定表N1-1'!$A9,'递延所得税资产明细表N1-2'!G$11:G$40) -> 0 | E9: =B9+C9+D9 -> 0 | F9: =SUMIF('递延所得税资产明细表N1-2'!$B$11:$B$40,'递延所得税资产审定表N1-1'!$A9,'递延所得税资产明细表N1-2'!K$11:K$40) -> 0 | G9: =SUMIF('递延所得税资产明细表N1-2'!$B$11:$B$40,'递延所得税资产审定表N1-1'!$A9,'递延所得税资产明细表N1-2'!L$11:L$40) -> 0 | H9: =SUMIF('递延所得税资产明细表N1-2'!$B$11:$B$40,'递延所得税资产审定表N1-1'!$A9,'递延所得税资产明细表N1-2'!M$11:M$40) -> 0 | I9: =F9+G9+H9 -> 0 | J9: =F9-B9 -> 0 | K9: =IF(AND(B9=0,J9=0),0,IF(AND(B9=0,J9>0),1,J9/B9)) -> 0 | L9: =I9-E9 -> 0 | M9: =IF(AND(E9=0,L9=0),0,IF(AND(E9=0,L9>0),1,L9/E9)) -> 0
A10: 公允价值变动 | B10: =SUMIF('递延所得税资产明细表N1-2'!$B$11:$B$40,'递延所得税资产审定表N1-1'!$A10,'递延所得税资产明细表N1-2'!E$11:E$40) -> 0 | C10: =SUMIF('递延所得税资产明细表N1-2'!$B$11:$B$40,'递延所得税资产审定表N1-1'!$A10,'递延所得税资产明细表N1-2'!F$11:F$40) -> 0 | D10: =SUMIF('递延所得税资产明细表N1-2'!$B$11:$B$40,'递延所得税资产审定表N1-1'!$A10,'递延所得税资产明细表N1-2'!G$11:G$40) -> 0 | E10: =B10+C10+D10 -> 0 | F10: =SUMIF('递延所得税资产明细表N1-2'!$B$11:$B$40,'递延所得税资产审定表N1-1'!$A10,'递延所得税资产明细表N1-2'!K$11:K$40) -> 0 | G10: =SUMIF('递延所得税资产明细表N1-2'!$B$11:$B$40,'递延所得税资产审定表N1-1'!$A10,'递延所得税资产明细表N1-2'!L$11:L$40) -> 0 | H10: =SUMIF('递延所得税资产明细表N1-2'!$B$11:$B$40,'递延所得税资产审定表N1-1'!$A10,'递延所得税资产明细表N1-2'!M$11:M$40) -> 0 | I10: =F10+G10+H10 -> 0 | J10: =F10-B10 -> 0 | K10: =IF(AND(B10=0,J10=0),0,IF(AND(B10=0,J10>0),1,J10/B10)) -> 0 | L10: =I10-E10 -> 0 | M10: =IF(AND(E10=0,L10=0),0,IF(AND(E10=0,L10>0),1,L10/E10)) -> 0
A11: 租赁负债 | B11: =SUMIF('递延所得税资产明细表N1-2'!$B$11:$B$40,'递延所得税资产审定表N1-1'!$A11,'递延所得税资产明细表N1-2'!E$11:E$40) -> 0 | C11: =SUMIF('递延所得税资产明细表N1-2'!$B$11:$B$40,'递延所得税资产审定表N1-1'!$A11,'递延所得税资产明细表N1-2'!F$11:F$40) -> 0 | D11: =SUMIF('递延所得税资产明细表N1-2'!$B$11:$B$40,'递延所得税资产审定表N1-1'!$A11,'递延所得税资产明细表N1-2'!G$11:G$40) -> 0 | E11: =B11+C11+D11 -> 0 | F11: =SUMIF('递延所得税资产明细表N1-2'!$B$11:$B$40,'递延所得税资产审定表N1-1'!$A11,'递延所得税资产明细表N1-2'!K$11:K$40) -> 0 | G11: =SUMIF('递延所得税资产明细表N1-2'!$B$11:$B$40,'递延所得税资产审定表N1-1'!$A11,'递延所得税资产明细表N1-2'!L$11:L$40) -> 0 | H11: =SUMIF('递延所得税资产明细表N1-2'!$B$11:$B$40,'递延所得税资产审定表N1-1'!$A11,'递延所得税资产明细表N1-2'!M$11:M$40) -> 0 | I11: =F11+G11+H11 -> 0 | J11: =F11-B11 -> 0 | K11: =IF(AND(B11=0,J11=0),0,IF(AND(B11=0,J11>0),1,J11/B11)) -> 0 | L11: =I11-E11 -> 0 | M11: =IF(AND(E11=0,L11=0),0,IF(AND(E11=0,L11>0),1,L11/E11)) -> 0
A12: 购入摊销年限小于税法规定的资产 | B12: =SUMIF('递延所得税资产明细表N1-2'!$B$11:$B$40,'递延所得税资产审定表N1-1'!$A12,'递延所得税资产明细表N1-2'!E$11:E$40) -> 0 | C12: =SUMIF('递延所得税资产明细表N1-2'!$B$11:$B$40,'递延所得税资产审定表N1-1'!$A12,'递延所得税资产明细表N1-2'!F$11:F$40) -> 0 | D12: =SUMIF('递延所得税资产明细表N1-2'!$B$11:$B$40,'递延所得税资产审定表N1-1'!$A12,'递延所得税资产明细表N1-2'!G$11:G$40) -> 0 | E12: =B12+C12+D12 -> 0 | F12: =SUMIF('递延所得税资产明细表N1-2'!$B$11:$B$40,'递延所得税资产审定表N1-1'!$A12,'递延所得税资产明细表N1-2'!K$11:K$40) -> 0 | G12: =SUMIF('递延所得税资产明细表N1-2'!$B$11:$B$40,'递延所得税资产审定表N1-1'!$A12,'递延所得税资产明细表N1-2'!L$11:L$40) -> 0 | H12: =SUMIF('递延所得税资产明细表N1-2'!$B$11:$B$40,'递延所得税资产审定表N1-1'!$A12,'递延所得税资产明细表N1-2'!M$11:M$40) -> 0 | I12: =F12+G12+H12 -> 0 | J12: =F12-B12 -> 0 | K12: =IF(AND(B12=0,J12=0),0,IF(AND(B12=0,J12>0),1,J12/B12)) -> 0 | L12: =I12-E12 -> 0 | M12: =IF(AND(E12=0,L12=0),0,IF(AND(E12=0,L12>0),1,L12/E12)) -> 0
A13: 其他 | B13: =SUMIF('递延所得税资产明细表N1-2'!$B$11:$B$40,'递延所得税资产审定表N1-1'!$A13,'递延所得税资产明细表N1-2'!E$11:E$40) -> 0 | C13: =SUMIF('递延所得税资产明细表N1-2'!$B$11:$B$40,'递延所得税资产审定表N1-1'!$A13,'递延所得税资产明细表N1-2'!F$11:F$40) -> 0 | D13: =SUMIF('递延所得税资产明细表N1-2'!$B$11:$B$40,'递延所得税资产审定表N1-1'!$A13,'递延所得税资产明细表N1-2'!G$11:G$40) -> 0 | E13: =B13+C13+D13 -> 0 | F13: =SUMIF('递延所得税资产明细表N1-2'!$B$11:$B$40,'递延所得税资产审定表N1-1'!$A13,'递延所得税资产明细表N1-2'!K$11:K$40) -> 0 | G13: =SUMIF('递延所得税资产明细表N1-2'!$B$11:$B$40,'递延所得税资产审定表N1-1'!$A13,'递延所得税资产明细表N1-2'!L$11:L$40) -> 0 | H13: =SUMIF('递延所得税资产明细表N1-2'!$B$11:$B$40,'递延所得税资产审定表N1-1'!$A13,'递延所得税资产明细表N1-2'!M$11:M$40) -> 0 | I13: =F13+G13+H13 -> 0 | J13: =F13-B13 -> 0 | K13: =IF(AND(B13=0,J13=0),0,IF(AND(B13=0,J13>0),1,J13/B13)) -> 0 | L13: =I13-E13 -> 0 | M13: =IF(AND(E13=0,L13=0),0,IF(AND(E13=0,L13>0),1,L13/E13)) -> 0
B14: =SUMIF('递延所得税资产明细表N1-2'!$B$11:$B$40,'递延所得税资产审定表N1-1'!$A14,'递延所得税资产明细表N1-2'!E$11:E$40) -> 0 | C14: =SUMIF('递延所得税资产明细表N1-2'!$B$11:$B$40,'递延所得税资产审定表N1-1'!$A14,'递延所得税资产明细表N1-2'!F$11:F$40) -> 0 | D14: =SUMIF('递延所得税资产明细表N1-2'!$B$11:$B$40,'递延所得税资产审定表N1-1'!$A14,'递延所得税资产明细表N1-2'!G$11:G$40) -> 0 | E14: =B14+C14+D14 -> 0 | F14: =SUMIF('递延所得税资产明细表N1-2'!$B$11:$B$40,'递延所得税资产审定表N1-1'!$A14,'递延所得税资产明细表N1-2'!K$11:K$40) -> 0 | G14: =SUMIF('递延所得税资产明细表N1-2'!$B$11:$B$40,'递延所得税资产审定表N1-1'!$A14,'递延所得税资产明细表N1-2'!L$11:L$40) -> 0 | H14: =SUMIF('递延所得税资产明细表N1-2'!$B$11:$B$40,'递延所得税资产审定表N1-1'!$A14,'递延所得税资产明细表N1-2'!M$11:M$40) -> 0 | I14: =F14+G14+H14 -> 0 | J14: =F14-B14 -> 0 | K14: =IF(AND(B14=0,J14=0),0,IF(AND(B14=0,J14>0),1,J14/B14)) -> 0 | L14: =I14-E14 -> 0 | M14: =IF(AND(E14=0,L14=0),0,IF(AND(E14=0,L14>0),1,L14/E14)) -> 0
B15: =SUMIF('递延所得税资产明细表N1-2'!$B$11:$B$40,'递延所得税资产审定表N1-1'!$A15,'递延所得税资产明细表N1-2'!E$11:E$40) -> 0 | C15: =SUMIF('递延所得税资产明细表N1-2'!$B$11:$B$40,'递延所得税资产审定表N1-1'!$A15,'递延所得税资产明细表N1-2'!F$11:F$40) -> 0 | D15: =SUMIF('递延所得税资产明细表N1-2'!$B$11:$B$40,'递延所得税资产审定表N1-1'!$A15,'递延所得税资产明细表N1-2'!G$11:G$40) -> 0 | E15: =B15+C15+D15 -> 0 | F15: =SUMIF('递延所得税资产明细表N1-2'!$B$11:$B$40,'递延所得税资产审定表N1-1'!$A15,'递延所得税资产明细表N1-2'!K$11:K$40) -> 0 | G15: =SUMIF('递延所得税资产明细表N1-2'!$B$11:$B$40,'递延所得税资产审定表N1-1'!$A15,'递延所得税资产明细表N1-2'!L$11:L$40) -> 0 | H15: =SUMIF('递延所得税资产明细表N1-2'!$B$11:$B$40,'递延所得税资产审定表N1-1'!$A15,'递延所得税资产明细表N1-2'!M$11:M$40) -> 0 | I15: =F15+G15+H15 -> 0 | J15: =F15-B15 -> 0 | K15: =IF(AND(B15=0,J15=0),0,IF(AND(B15=0,J15>0),1,J15/B15)) -> 0 | L15: =I15-E15 -> 0 | M15: =IF(AND(E15=0,L15=0),0,IF(AND(E15=0,L15>0),1,L15/E15)) -> 0
A16: 合计 | B16: =SUM(B7:B15) -> 0 | C16: =SUM(C7:C15) -> 0 | D16: =SUM(D7:D15) -> 0 | E16: =SUM(E7:E15) -> 0 | F16: =SUM(F7:F15) -> 0 | G16: =SUM(G7:G15) -> 0 | H16: =SUM(H7:H15) -> 0 | I16: =SUM(I7:I15) -> 0 | J16: =SUM(J7:J15) -> 0 | K16: =IF(AND(B16=0,J16=0),0,IF(AND(B16=0,J16>0),1,J16/B16)) -> 0 | L16: =I16-E16 -> 0 | M16: =IF(AND(E16=0,L16=0),0,IF(AND(E16=0,L16>0),1,L16/E16)) -> 0
A17: 试算平衡表数
A18: 差异数 | E18: =E16-E17 -> 0 | I18: =I16-I17 -> 0
A19: 1.审计说明
A20: （1）期末余额较期初余额增加（负数为减少）：
A21: 主要原因（比例超过30%的）：
A23: （2）未确认递延所得税资产的可抵扣暂时性差异、可抵扣亏损等的金额（存在到期日的，应披露到期日）
A25: （3）情况说明
A27: 2.审计结论
A29: [注1]取得税务同意抵扣依据的开办费摊销差异。
A30: [注2]预计辞退福利费须解除劳动关系。
A31: [注3]若有其他项目，需详加说明内容。如税款抵减等。
A32: [注4] 预计递延所得税资产（负债）转回时适用的所得税税率。相关证明文件索引号为：

Sheet 附注披露信息（上市公司）
A1: 致同会计师事务所
A2: 附注披露信息（上市公司）
A3: =底稿目录!A2 -> 被审计单位名称： | B3: =底稿目录!A4 -> 编制人： | D3: =底稿目录!A5 -> 编制日期： | E3: 索引：
A4: =底稿目录!A3 -> 截止日：202X年12月31日 | B4: =底稿目录!A6 -> 复核人： | D4: =底稿目录!A7 -> 复核日期： | E4: 页次：1
A6: 附注披露信息：
A8: 递延所得税资产与递延所得税负债
A9: （1）未经抵销的递延所得税资产和递延所得税负债
A10: 项 目 | B10: 期末余额 | D10: 上年年末余额
B11: 可抵扣/应纳税暂时性差异 | C11: 递延所得税资产/负债 | D11: 可抵扣/应纳税暂时性差异 | E11: 递延所得税资产/负债
A12: 递延所得税资产：
A13: 资产减值准备
A14: 可抵扣亏损
A15: 内部交易未实现利润
A16: 公允价值变动
A17: 租赁负债
A18: 购入摊销年限小于税法规定的资产
A19: 其他
A21: 小 计 | B21: =SUM(B13:B20) -> 0 | C21: =SUM(C13:C20) -> 0 | D21: =SUM(D13:D20) -> 0 | E21: =SUM(E13:E20) -> 0
A22: 递延所得税负债： | F22: 递延所得税负债数据来源于递延所得税负债底稿
A23: 购入摊销年限大于税法规定的资产
A24: 可供出售金融资产公允价值变动
A25: 投资性房地产公允价值变动
A26: 使用权资产
A27: 其他
A29: 小计 | B29: =SUM(B23:B28) -> 0 | C29: =SUM(C23:C28) -> 0 | D29: =SUM(D23:D28) -> 0 | E29: =SUM(E23:E28) -> 0
A30: 说明：其中一年后预期转回的递延所得税资产和递延所得税负债分别为X.XX元、X.XX元。
A31: 【提示：连续亏损的情况下，仍将较大金额的未抵扣亏损确认递延所得税资产，对当期净利润影响较大，甚至扭亏为盈，应当披露相关判断依据】
A32: 【提示：产生递延所得税资产的资产减值准备中包括持有待售资产的资产减值准备。】
A33: （2）以抵销后净额列示的递延所得税资产或负债（不适用的删除）
A34: 项 目 | B34: 递延所得税资产和负债期末互抵金额 | C34: 抵销后递延所得税资产或负债期末余额 | D34: 递延所得税资产和负债期初互抵金额 | E34: 抵销后递延所得税资产或负债期初余额
A35: 递延所得税资产
A36: 递延所得税负债
A37: （3）未确认递延所得税资产的可抵扣暂时性差异及可抵扣亏损明细
A38: 项 目 | B38: 期末余额 | C38: 上年年末余额
A39: 可抵扣暂时性差异
A40: 可抵扣亏损
A42: 合 计 | B42: =B39+B40 -> 0 | C42: =C39+C40 -> 0
A43: 注：列示由于未来能否获得足够的应纳税所得额具有不确定性，因此没有确认为递延所得税资产的可抵扣暂时性差异和可抵扣亏损。
A44: （4）未确认递延所得税资产的可抵扣亏损将于以下年度到期
A45: 年 份 | B45: 期末余额 | C45: 上年年末余额 | D45: 备注
...

Sheet 附注披露信息（国企）
A1: 致同会计师事务所
A2: 附注披露信息（国企）
A3: =底稿目录!A2 -> 被审计单位名称： | B3: =底稿目录!A4 -> 编制人： | D3: =底稿目录!A5 -> 编制日期： | E3: 索引号：
A4: =底稿目录!A3 -> 截止日：202X年12月31日 | B4: =底稿目录!A6 -> 复核人： | D4: =底稿目录!A7 -> 复核日期： | E4: 页次：
A5: 附注披露信息:
A6: 递延所得税资产和递延所得税负债
A7: 递延所得税资产和递延所得税负债不以抵销后的净额列示的，按（1）披露；若递延所得税资产和递延所得税负债以抵销后的净额列示的，按（2）披露。
A8: （1）递延所得税资产和递延所得税负债不以抵销后的净额列示
A9: A、已确认递延所得税资产和递延所得税负债
A10: 项 目 | B10: 期末余额 | D10: 年初余额
B11: 递延所得税资产/负债 | C11: 可抵扣/应纳税暂时性差异 | D11: 递延所得税资产/负债 | E11: 可抵扣/应纳税暂时性差异
A12: 一、递延所得税资产
A13: ='附注披露信息（上市公司）'!A13 -> 资产减值准备 | F13: ,
A14: ='附注披露信息（上市公司）'!A14 -> 可抵扣亏损 | F14: ,
A15: ='附注披露信息（上市公司）'!A15 -> 内部交易未实现利润 | F15: ,
A16: ='附注披露信息（上市公司）'!A16 -> 公允价值变动 | F16: ,
A17: ='附注披露信息（上市公司）'!A17 -> 租赁负债 | F17: ,
A18: ='附注披露信息（上市公司）'!A18 -> 购入摊销年限小于税法规定的资产 | F18: ,
A19: ='附注披露信息（上市公司）'!A19 -> 其他 | F19: ,
F20: , | G20: =A20&F20 -> ,
A21: 小 计 | B21: =SUM(B13:B19) -> 0 | C21: =SUM(C13:C19) -> 0 | D21: =SUM(D13:D19) -> 0 | E21: =SUM(E13:E19) -> 0
A22: 递延所得税负债： | F22: 递延所得税负债数据来源于递延所得税负债底稿
A23: 购入摊销年限大于税法规定的资产
A24: 可供出售金融资产公允价值变动
A25: 投资性房地产公允价值变动
A26: 租赁形成
A27: 其他
A29: 小计 | B29: =SUM(B23:B28) -> 0 | C29: =SUM(C23:C28) -> 0 | D29: =SUM(D23:D28) -> 0 | E29: =SUM(E23:E28) -> 0
A30: 【提示：资产减值准备，含“持有待售资产减值准备”】
A31: 【注：计入其他综合收益的其他金融资产为计入其他综合收益的其他债权投资、其他权益工具投资。】
A32: （2）递延所得税资产和递延所得税负债以抵销后的净额列示
A33: A、互抵后的递延所得税资产或负债及对应的互抵后可抵扣或应纳税暂时性差异
A34: 项 目 | B34: 报告期末互抵后的递延所得税资产或负债 | C34: 报告期末互抵后的可抵扣或应纳税暂时性差异 | D34: 报告年初互抵后的递延所得税资产或负债 | E34: 报告年初互抵后的可抵扣或应纳税暂时性差异
A35: 一、递延所得税资产
A36: =A13 -> 资产减值准备
A37: =A14 -> 可抵扣亏损
A38: =A15 -> 内部交易未实现利润
A39: =A16 -> 公允价值变动
A40: =A17 -> 租赁负债
A41: =A18 -> 购入摊销年限小于税法规定的资产
...

Sheet 递延所得税资产明细表N1-2
A1: 致同会计师事务所
A2: 递延所得税资产明细表
A3: =底稿目录!A2 -> 被审计单位名称： | D3: =底稿目录!A4 -> 编制人： | H3: =底稿目录!A5 -> 编制日期： | M3: 索引号： | N3: N1-2
A4: =底稿目录!A3 -> 截止日：202X年12月31日 | D4: =底稿目录!A6 -> 复核人： | H4: =底稿目录!A7 -> 复核日期： | M4: 页次：
A5: 一、审计目标
A6: 递延所得税资产以恰当的金额包括在财务报表中，与之相关的计价调整已恰当记录。
A7: 二、审计过程
A8: 【项目组根据被审计单位税收情况增减项目】
A9: 项 目 | C9: 期初 | I9: 期末
B10: 类别 | C10: 暂时性差异 | D10: 适用税率 | E10: 递延所得税资产期初余额 | F10: 账项调整 | G10: 重分类调整 | H10: 递延所得税资产期初审定数 | I10: 暂时性差异 | J10: 适用税率 | K10: 递延所得税资产期末余额 | L10: 账项调整 | M10: 重分类调整 | N10: 递延所得税资产期末审定数
A11: 交易性金融资产（公允价值与初始账面成本差异） | B11: 公允价值变动 | E11: =ROUND(C11*D11,2) -> 0 | H11: =F11+E11 -> 0 | K11: =ROUND(I11*J11,2) -> 0 | N11: =L11+K11 -> 0
A12: 应收账款（坏账准备） | B12: 资产减值准备 | E12: =ROUND(C12*D12,2) -> 0 | H12: =F12+E12 -> 0 | K12: =ROUND(I12*J12,2) -> 0 | N12: =L12+K12 -> 0
A13: 其他应收款（坏账准备） | B13: 资产减值准备 | E13: =ROUND(C13*D13,2) -> 0 | H13: =F13+E13 -> 0 | K13: =ROUND(I13*J13,2) -> 0 | N13: =L13+K13 -> 0
A14: 存货（跌价准备） | B14: 资产减值准备 | E14: =ROUND(C14*D14,2) -> 0 | H14: =F14+E14 -> 0 | K14: =ROUND(I14*J14,2) -> 0 | N14: =L14+K14 -> 0
A15: 应收款项融资（公允价值与经实际利率法摊销后账面金额的差异） | B15: 公允价值变动 | E15: =ROUND(C15*D15,2) -> 0 | H15: =F15+E15 -> 0 | K15: =ROUND(I15*J15,2) -> 0 | N15: =L15+K15 -> 0
A16: 合同资产（减值准备） | B16: 资产减值准备 | E16: =ROUND(C16*D16,2) -> 0 | H16: =F16+E16 -> 0 | K16: =ROUND(I16*J16,2) -> 0 | N16: =L16+K16 -> 0
A17: 其他债权投资（公允价值与经实际利率法摊销后账面金额的差异） | B17: 公允价值变动 | E17: =ROUND(C17*D17,2) -> 0 | H17: =F17+E17 -> 0 | K17: =ROUND(I17*J17,2) -> 0 | N17: =L17+K17 -> 0
A18: 其他权益工具投资（公允价值与初始账面成本差异） | B18: 公允价值变动 | E18: =ROUND(C18*D18,2) -> 0 | H18: =F18+E18 -> 0 | K18: =ROUND(I18*J18,2) -> 0 | N18: =L18+K18 -> 0
A19: 债权投资（减值准备） | B19: 资产减值准备 | E19: =ROUND(C19*D19,2) -> 0 | H19: =F19+E19 -> 0 | K19: =ROUND(I19*J19,2) -> 0 | N19: =L19+K19 -> 0
A20: 长期股权投资（减值准备） | B20: 资产减值准备 | E20: =ROUND(C20*D20,2) -> 0 | H20: =F20+E20 -> 0 | K20: =ROUND(I20*J20,2) -> 0 | N20: =L20+K20 -> 0
A21: 投资性房地产（公允价值与账面差异） | B21: 公允价值变动 | E21: =ROUND(C21*D21,2) -> 0 | H21: =F21+E21 -> 0 | K21: =ROUND(I21*J21,2) -> 0 | N21: =L21+K21 -> 0
A22: 投资性房地产（折旧） | E22: =ROUND(C22*D22,2) -> 0 | H22: =F22+E22 -> 0 | K22: =ROUND(I22*J22,2) -> 0 | N22: =L22+K22 -> 0
A23: 固定资产（减值准备） | B23: 资产减值准备 | E23: =ROUND(C23*D23,2) -> 0 | H23: =F23+E23 -> 0 | K23: =ROUND(I23*J23,2) -> 0 | N23: =L23+K23 -> 0
A24: 固定资产折旧（年限、残值） | E24: =ROUND(C24*D24,2) -> 0 | H24: =F24+E24 -> 0 | K24: =ROUND(I24*J24,2) -> 0 | N24: =L24+K24 -> 0
A25: 在建工程（减值准备） | B25: 资产减值准备 | E25: =ROUND(C25*D25,2) -> 0 | H25: =F25+E25 -> 0 | K25: =ROUND(I25*J25,2) -> 0 | N25: =L25+K25 -> 0
A26: 使用权资产（减值准备） | B26: 资产减值准备 | E26: =ROUND(C26*D26,2) -> 0 | H26: =F26+E26 -> 0 | K26: =ROUND(I26*J26,2) -> 0 | N26: =L26+K26 -> 0
A27: 无形资产（减值准备、摊销） | B27: 资产减值准备 | E27: =ROUND(C27*D27,2) -> 0 | H27: =F27+E27 -> 0 | K27: =ROUND(I27*J27,2) -> 0 | N27: =L27+K27 -> 0
A28: 无形资产（研发费用资本化） | E28: =ROUND(C28*D28,2) -> 0 | H28: =F28+E28 -> 0 | K28: =ROUND(I28*J28,2) -> 0 | N28: =L28+K28 -> 0
A29: 开办费（摊销方法）[注1] | E29: =ROUND(C29*D29,2) -> 0 | H29: =F29+E29 -> 0 | K29: =ROUND(I29*J29,2) -> 0 | N29: =L29+K29 -> 0
A30: 交易性金融负债（公允价值与账面差异） | B30: 公允价值变动 | E30: =ROUND(C30*D30,2) -> 0 | H30: =F30+E30 -> 0 | K30: =ROUND(I30*J30,2) -> 0 | N30: =L30+K30 -> 0
A31: 应付职工薪酬（已计提未支付） | B31: 其他 | E31: =ROUND(C31*D31,2) -> 0 | H31: =F31+E31 -> 0 | K31: =ROUND(I31*J31,2) -> 0 | N31: =L31+K31 -> 0
A32: 应付职工薪酬（预计辞退福利费）[注2] | B32: 其他 | E32: =ROUND(C32*D32,2) -> 0 | H32: =F32+E32 -> 0 | K32: =ROUND(I32*J32,2) -> 0 | N32: =L32+K32 -> 0
A33: 预提费用 | B33: 其他 | E33: =ROUND(C33*D33,2) -> 0 | H33: =F33+E33 -> 0 | K33: =ROUND(I33*J33,2) -> 0 | N33: =L33+K33 -> 0
A34: 递延收益 | B34: 其他 | E34: =ROUND(C34*D34,2) -> 0 | H34: =F34+E34 -> 0 | K34: =ROUND(I34*J34,2) -> 0 | N34: =L34+K34 -> 0
A35: 预计负债（预计产品保修费用等） | B35: 其他 | E35: =ROUND(C35*D35,2) -> 0 | H35: =F35+E35 -> 0 | K35: =ROUND(I35*J35,2) -> 0 | N35: =L35+K35 -> 0
A36: 收入（预收款项） | B36: 其他 | E36: =ROUND(C36*D36,2) -> 0 | H36: =F36+E36 -> 0 | K36: =ROUND(I36*J36,2) -> 0 | N36: =L36+K36 -> 0
A37: 销售费用（广告费和业务宣传费） | B37: 其他 | E37: =ROUND(C37*D37,2) -> 0 | H37: =F37+E37 -> 0 | K37: =ROUND(I37*J37,2) -> 0 | N37: =L37+K37 -> 0
A38: 可用以后年度税前利润弥补的亏损 | B38: 可抵扣亏损 | E38: =ROUND(C38*D38,2) -> 0 | H38: =F38+E38 -> 0 | K38: =ROUND(I38*J38,2) -> 0 | N38: =L38+K38 -> 0
A39: 除上述项目以外的其他[注3] | B39: 其他 | E39: =ROUND(C39*D39,2) -> 0 | H39: =F39+E39 -> 0 | K39: =ROUND(I39*J39,2) -> 0 | N39: =L39+K39 -> 0
A40: …… | E40: =ROUND(C40*D40,2) -> 0 | H40: =F40+E40 -> 0 | K40: =ROUND(I40*J40,2) -> 0 | N40: =L40+K40 -> 0
...

Sheet 调整分录汇总N1-3
A1: 致同会计师事务所
A2: 递延所得税资产调整分录汇总表
A3: =底稿目录!A2 -> 被审计单位名称： | D3: =底稿目录!A4 -> 编制人： | G3: =底稿目录!A5 -> 编制日期： | I3: 索引号： | J3: N1-3
A4: =底稿目录!A3 -> 截止日：202X年12月31日 | D4: =底稿目录!A6 -> 复核人： | G4: =底稿目录!A7 -> 复核日期： | I4: 页次：
A5: 调整事项说明 | B5: 类别（报表调整/账项调整/其他） | C5: 报表项目 | D5: 科目名称 | E5: 附注项目 | F5: …… | G5: 借方调整金额 | H5: 贷方调整金额 | I5: 索引 | J5: 备注
A21: 1.审计说明
A25: 2.审计结论
A27: 提示：本底稿适用于调整分录较多、较复杂的项目，且仅列示与本报表项目相关的审计调整。项目组可根据项目实际情况选择是否使用该底稿。

Sheet 递延所得税资产（负债）测算表N1-4
A1: 致同会计师事务所
A2: 递延所得税资产（负债）测算表
A3: =底稿目录!A2 -> 被审计单位名称： | E3: =底稿目录!$A$4 -> 编制人： | I3: =底稿目录!$A$5 -> 编制日期： | M3: 索引号： | N3: N1-4
A4: =底稿目录!A3 -> 截止日：202X年12月31日 | E4: =底稿目录!$A$6 -> 复核人： | I4: =底稿目录!$A$7 -> 复核日期： | M4: 页次：
A5: 一、审计目标
A6: 递延所得税资产以恰当的金额包括在财务报表中，与之相关的计价或分摊调整已恰当记录，相关披露已得到恰当计量和描述 。
A7: 二、审计过程
A8: 【项目组根据被审计单位税收情况增减项目】
A9: 项目 | B9: 账面价值 (借方余额+/贷方余额-） | C9: 计税基础 (借方余额+/贷方余额-） | D9: 适用税率 [注4] | E9: 暂时性差异 | G9: 应确认递延所得税资产期末余额 （1） | H9: 对方科目 | I9: 递延所得税资产期末账面余额 （2） | J9: 差异 （3）=（1）-（2） | K9: 应确认递延所得税负债期末余额 （4） | L9: 对方科目 | M9: 递延所得税负债期末账面余额 （5） | N9: 差异 （6）=（4）-（5）
E10: 可抵扣 | F10: 应纳税
A11: ='递延所得税资产明细表N1-2'!A11 -> 交易性金融资产（公允价值与初始账面成本差异） | E11: =IF(B11-C11<0,C11-B11,0) -> 0 | F11: =IF(B11-C11>0,B11-C11,0) -> 0 | G11: =IF(E11=0,0,D11*E11) -> 0 | I11: =SUM(H11:H11) -> 0 | J11: =G11-I11 -> 0 | K11: =IF(F11=0,0,D11*F11) -> 0 | N11: =K11-M11 -> 0
A12: ='递延所得税资产明细表N1-2'!A12 -> 应收账款（坏账准备） | E12: =IF(B12-C12<0,C12-B12,0) -> 0 | F12: =IF(B12-C12>0,B12-C12,0) -> 0 | G12: =IF(E12=0,0,D12*E12) -> 0 | J12: =G12-I12 -> 0 | K12: =IF(F12=0,0,D12*F12) -> 0 | N12: =K12-M12 -> 0
A13: ='递延所得税资产明细表N1-2'!A13 -> 其他应收款（坏账准备） | E13: =IF(B13-C13<0,C13-B13,0) -> 0 | F13: =IF(B13-C13>0,B13-C13,0) -> 0 | G13: =IF(E13=0,0,D13*E13) -> 0 | J13: =G13-I13 -> 0 | K13: =IF(F13=0,0,D13*F13) -> 0 | N13: =K13-M13 -> 0
A14: ='递延所得税资产明细表N1-2'!A14 -> 存货（跌价准备） | E14: =IF(B14-C14<0,C14-B14,0) -> 0 | F14: =IF(B14-C14>0,B14-C14,0) -> 0 | G14: =IF(E14=0,0,D14*E14) -> 0 | J14: =G14-I14 -> 0 | K14: =IF(F14=0,0,D14*F14) -> 0 | N14: =K14-M14 -> 0
A15: ='递延所得税资产明细表N1-2'!A15 -> 应收款项融资（公允价值与经实际利率法摊销后账面金额的差异） | E15: =IF(B15-C15<0,C15-B15,0) -> 0 | F15: =IF(B15-C15>0,B15-C15,0) -> 0 | G15: =IF(E15=0,0,D15*E15) -> 0 | J15: =G15-I15 -> 0 | K15: =IF(F15=0,0,D15*F15) -> 0 | N15: =K15-M15 -> 0
A16: ='递延所得税资产明细表N1-2'!A16 -> 合同资产（减值准备） | E16: =IF(B16-C16<0,C16-B16,0) -> 0 | F16: =IF(B16-C16>0,B16-C16,0) -> 0 | G16: =IF(E16=0,0,D16*E16) -> 0 | J16: =G16-I16 -> 0 | K16: =IF(F16=0,0,D16*F16) -> 0
A17: ='递延所得税资产明细表N1-2'!A17 -> 其他债权投资（公允价值与经实际利率法摊销后账面金额的差异） | E17: =IF(B17-C17<0,C17-B17,0) -> 0 | F17: =IF(B17-C17>0,B17-C17,0) -> 0 | G17: =IF(E17=0,0,D17*E17) -> 0 | J17: =G17-I17 -> 0 | K17: =IF(F17=0,0,D17*F17) -> 0 | N17: =K17-M17 -> 0
A18: ='递延所得税资产明细表N1-2'!A18 -> 其他权益工具投资（公允价值与初始账面成本差异） | E18: =IF(B18-C18<0,C18-B18,0) -> 0 | F18: =IF(B18-C18>0,B18-C18,0) -> 0 | G18: =IF(E18=0,0,D18*E18) -> 0 | J18: =G18-I18 -> 0 | K18: =IF(F18=0,0,D18*F18) -> 0 | N18: =K18-M18 -> 0
A19: ='递延所得税资产明细表N1-2'!A19 -> 债权投资（减值准备） | E19: =IF(B19-C19<0,C19-B19,0) -> 0 | F19: =IF(B19-C19>0,B19-C19,0) -> 0 | G19: =IF(E19=0,0,D19*E19) -> 0 | J19: =G19-I19 -> 0 | K19: =IF(F19=0,0,D19*F19) -> 0 | N19: =K19-M19 -> 0
A20: ='递延所得税资产明细表N1-2'!A20 -> 长期股权投资（减值准备） | E20: =IF(B20-C20<0,C20-B20,0) -> 0 | F20: =IF(B20-C20>0,B20-C20,0) -> 0 | G20: =IF(E20=0,0,D20*E20) -> 0 | J20: =G20-I20 -> 0 | K20: =IF(F20=0,0,D20*F20) -> 0 | N20: =K20-M20 -> 0
A21: ='递延所得税资产明细表N1-2'!A21 -> 投资性房地产（公允价值与账面差异） | E21: =IF(B21-C21<0,C21-B21,0) -> 0 | F21: =IF(B21-C21>0,B21-C21,0) -> 0 | G21: =IF(E21=0,0,D21*E21) -> 0 | J21: =G21-I21 -> 0 | K21: =IF(F21=0,0,D21*F21) -> 0 | N21: =K21-M21 -> 0
A22: ='递延所得税资产明细表N1-2'!A22 -> 投资性房地产（折旧） | E22: =IF(B22-C22<0,C22-B22,0) -> 0 | F22: =IF(B22-C22>0,B22-C22,0) -> 0 | G22: =IF(E22=0,0,D22*E22) -> 0 | J22: =G22-I22 -> 0 | K22: =IF(F22=0,0,D22*F22) -> 0 | N22: =K22-M22 -> 0
A23: ='递延所得税资产明细表N1-2'!A23 -> 固定资产（减值准备） | E23: =IF(B23-C23<0,C23-B23,0) -> 0 | F23: =IF(B23-C23>0,B23-C23,0) -> 0 | G23: =IF(E23=0,0,D23*E23) -> 0 | J23: =G23-I23 -> 0 | K23: =IF(F23=0,0,D23*F23) -> 0 | N23: =K23-M23 -> 0
A24: ='递延所得税资产明细表N1-2'!A24 -> 固定资产折旧（年限、残值） | E24: =IF(B24-C24<0,C24-B24,0) -> 0 | F24: =IF(B24-C24>0,B24-C24,0) -> 0 | G24: =IF(E24=0,0,D24*E24) -> 0 | J24: =G24-I24 -> 0 | K24: =IF(F24=0,0,D24*F24) -> 0 | N24: =K24-M24 -> 0
A25: ='递延所得税资产明细表N1-2'!A25 -> 在建工程（减值准备） | E25: =IF(B25-C25<0,C25-B25,0) -> 0 | F25: =IF(B25-C25>0,B25-C25,0) -> 0 | G25: =IF(E25=0,0,D25*E25) -> 0 | J25: =G25-I25 -> 0 | K25: =IF(F25=0,0,D25*F25) -> 0 | N25: =K25-M25 -> 0
A26: ='递延所得税资产明细表N1-2'!A26 -> 使用权资产（减值准备） | E26: =IF(B26-C26<0,C26-B26,0) -> 0 | F26: =IF(B26-C26>0,B26-C26,0) -> 0 | G26: =IF(E26=0,0,D26*E26) -> 0 | J26: =G26-I26 -> 0 | K26: =IF(F26=0,0,D26*F26) -> 0
A27: ='递延所得税资产明细表N1-2'!A27 -> 无形资产（减值准备、摊销） | E27: =IF(B27-C27<0,C27-B27,0) -> 0 | F27: =IF(B27-C27>0,B27-C27,0) -> 0 | G27: =IF(E27=0,0,D27*E27) -> 0 | J27: =G27-I27 -> 0 | K27: =IF(F27=0,0,D27*F27) -> 0 | N27: =K27-M27 -> 0
A28: ='递延所得税资产明细表N1-2'!A28 -> 无形资产（研发费用资本化） | E28: =IF(B28-C28<0,C28-B28,0) -> 0 | F28: =IF(B28-C28>0,B28-C28,0) -> 0 | G28: =IF(E28=0,0,D28*E28) -> 0 | J28: =G28-I28 -> 0 | K28: =IF(F28=0,0,D28*F28) -> 0 | N28: =K28-M28 -> 0
A29: ='递延所得税资产明细表N1-2'!A29 -> 开办费（摊销方法）[注1] | E29: =IF(B29-C29<0,C29-B29,0) -> 0 | F29: =IF(B29-C29>0,B29-C29,0) -> 0 | G29: =IF(E29=0,0,D29*E29) -> 0 | J29: =G29-I29 -> 0 | K29: =IF(F29=0,0,D29*F29) -> 0 | N29: =K29-M29 -> 0
A30: ='递延所得税资产明细表N1-2'!A30 -> 交易性金融负债（公允价值与账面差异） | E30: =IF(B30-C30<0,C30-B30,0) -> 0 | F30: =IF(B30-C30>0,B30-C30,0) -> 0 | G30: =IF(E30=0,0,D30*E30) -> 0 | J30: =G30-I30 -> 0 | K30: =IF(F30=0,0,D30*F30) -> 0 | N30: =K30-M30 -> 0
A31: ='递延所得税资产明细表N1-2'!A31 -> 应付职工薪酬（已计提未支付） | E31: =IF(B31-C31<0,C31-B31,0) -> 0 | F31: =IF(B31-C31>0,B31-C31,0) -> 0 | G31: =IF(E31=0,0,D31*E31) -> 0 | J31: =G31-I31 -> 0 | K31: =IF(F31=0,0,D31*F31) -> 0 | N31: =K31-M31 -> 0
A32: ='递延所得税资产明细表N1-2'!A32 -> 应付职工薪酬（预计辞退福利费）[注2] | E32: =IF(B32-C32<0,C32-B32,0) -> 0 | F32: =IF(B32-C32>0,B32-C32,0) -> 0 | G32: =IF(E32=0,0,D32*E32) -> 0 | J32: =G32-I32 -> 0 | K32: =IF(F32=0,0,D32*F32) -> 0 | N32: =K32-M32 -> 0
A33: ='递延所得税资产明细表N1-2'!A33 -> 预提费用 | E33: =IF(B33-C33<0,C33-B33,0) -> 0 | F33: =IF(B33-C33>0,B33-C33,0) -> 0 | G33: =IF(E33=0,0,D33*E33) -> 0 | J33: =G33-I33 -> 0 | K33: =IF(F33=0,0,D33*F33) -> 0 | N33: =K33-M33 -> 0
A34: ='递延所得税资产明细表N1-2'!A34 -> 递延收益 | E34: =IF(B34-C34<0,C34-B34,0) -> 0 | F34: =IF(B34-C34>0,B34-C34,0) -> 0 | G34: =IF(E34=0,0,D34*E34) -> 0 | J34: =G34-I34 -> 0 | K34: =IF(F34=0,0,D34*F34) -> 0 | N34: =K34-M34 -> 0
A35: ='递延所得税资产明细表N1-2'!A35 -> 预计负债（预计产品保修费用等） | E35: =IF(B35-C35<0,C35-B35,0) -> 0 | F35: =IF(B35-C35>0,B35-C35,0) -> 0 | G35: =IF(E35=0,0,D35*E35) -> 0 | J35: =G35-I35 -> 0 | K35: =IF(F35=0,0,D35*F35) -> 0 | N35: =K35-M35 -> 0
A36: ='递延所得税资产明细表N1-2'!A36 -> 收入（预收款项） | E36: =IF(B36-C36<0,C36-B36,0) -> 0 | F36: =IF(B36-C36>0,B36-C36,0) -> 0 | G36: =IF(E36=0,0,D36*E36) -> 0 | J36: =G36-I36 -> 0 | K36: =IF(F36=0,0,D36*F36) -> 0 | N36: =K36-M36 -> 0
A37: ='递延所得税资产明细表N1-2'!A37 -> 销售费用（广告费和业务宣传费） | E37: =IF(B37-C37<0,C37-B37,0) -> 0 | F37: =IF(B37-C37>0,B37-C37,0) -> 0 | G37: =IF(E37=0,0,D37*E37) -> 0 | J37: =G37-I37 -> 0 | K37: =IF(F37=0,0,D37*F37) -> 0 | N37: =K37-M37 -> 0
A38: ='递延所得税资产明细表N1-2'!A38 -> 可用以后年度税前利润弥补的亏损 | E38: =IF(B38-C38<0,C38-B38,0) -> 0 | F38: =IF(B38-C38>0,B38-C38,0) -> 0 | G38: =IF(E38=0,0,D38*E38) -> 0 | J38: =G38-I38 -> 0 | K38: =IF(F38=0,0,D38*F38) -> 0 | N38: =K38-M38 -> 0
... A40: ='递延所得税资产明细表N1-2'!A40 -> …… | E40: =IF(B40-C40<0,C40-B40,0) -> 0 | F40: =IF(B40-C40>0,B40-C40,0) -> 0 | G40: =IF(E40=0,0,D40*E40) -> 0 | J40: =G40-I40 -> 0 | K40: =IF(F40=0,0,D40*F40) -> 0 | N40: =K40-M40 -> 0
A41: 合计 | B41: =SUM(B11:B40) -> 0 | C41: =SUM(C11:C40) -> 0 | E41: =SUM(E11:E40) -> 0 | F41: =SUM(F11:F40) -> 0 | G41: =SUM(G11:G40) -> 0 | H41: =SUM(H11:H40) -> 0 | I41: =SUM(I11:I40) -> 0 | J41: =SUM(J11:J40) -> 0 | K41: =SUM(K11:K40) -> 0 | L41: =SUM(L11:L40) -> 0 | ... N41: =SUM(N11:N40) -> 0
...

Sheet 可用以后年度税前利润弥补的亏损检查表的N1-5
A1: 致同会计师事务所
A2: 可用以后年度税前利润弥补的亏损检查表
A3: =底稿目录!A2 -> 被审计单位名称： | E3: =底稿目录!$A$4 -> 编制人： | I3: =底稿目录!$A$5 -> 编制日期： | L3: 索引号： | M3: N1-5
A4: =底稿目录!A3 -> 截止日：202X年12月31日 | E4: =底稿目录!$A$6 -> 复核人： | I4: =底稿目录!$A$7 -> 复核日期： | L4: 页次：
A5: 一、审计目标
A6: 递延所得税资产以恰当的金额包括在财务报表中，与之相关的计价或分摊调整已恰当记录，相关披露已得到恰当计量和描述 。
A7: 二、审计过程
A8: 1.获取未弥补亏损清单：
A9: （1）确定已确认递延所得税资产的可抵扣亏损到期前是否有足够应纳税所得额；
A10: （2）确定未确认递延所得税资产的可抵扣亏损到期期间
A11: 2.……
A12: 项目 | B12: 上期不确认递延所得税资产的可弥补亏损 | C12: 本期数 | F12: 确认递延所得税资产的可弥补亏损 | G12: 不确认递延所得税资产的可弥补亏损 | H12: 依据 | I12: 可抵扣亏损到期前是否有足够的应纳税所得额（是或否） | J12: 其中：预计应纳税所得额来源于生产经营所得（∨） | K12: 其中：预计应纳税所得额来源于以前期间产生的应纳税暂时性差异转回（∨） | L12: 其中：预计应纳税所得额来源于其他原因（∨） | M12: 检查底稿索引
C13: 账面金额 | D13: 审计调整 | E13: 审定金额
A14: 期末未分配利润 | E14: =C14+D14 -> 0
A15: 其中：可抵扣亏损 | E15: =C15+D15 -> 0
A16: 可抵扣亏损到期年度
A17: 2022年 | E17: =C17+D17 -> 0
A18: 2023年 | E18: =C18+D18 -> 0
A19: 2024年 | E19: =C19+D19 -> 0
A20: 2025年 | E20: =C20+D20 -> 0
A21: 2026年 | E21: =C21+D21 -> 0
A22: 2027年 | E22: =C22+D22 -> 0
E23: =C23+D23 -> 0
E24: =C24+D24 -> 0
E25: =C25+D25 -> 0
E26: =C26+D26 -> 0
A27: 合 计 | B27: =SUM(B14:B26) -> 0 | C27: =SUM(C14:C26) -> 0 | D27: =SUM(D14:D26) -> 0 | E27: =SUM(E14:E26) -> 0 | F27: =SUM(F14:F26) -> 0 | G27: =SUM(G14:G26) -> 0
A28: 三、审计说明
A30: 四、审计结论

Sheet GT_Custom
A1: C1 | B1: Custom 1
A2: C2 | B2: Custom 2
A3: C3 | B3: Custom 3
A4: C4 | B4: Custom 4
A5: C5 | B5: Custom 5
A6: C6 | B6: Custom 6
A7: C7 | B7: Custom 7
A8: C8 | B8: Custom 8
