Workbook

Sheet 底稿目录
A1: 底稿开列时，可先在以下单元格填写有关内容，以便其他底稿引用有关数据：
A2: 被审计单位： | D2: 序号 | E2: 内容 | F2: 索引号
A3: 会计期间：202X年度 | D3: 1 | E3: 税金及附加实质性程序表 | F3: N4A
A4: 编制人： | D4: 2 | E4: 税金及附加审定表 | F4: N4-1
A5: 编制日期： | D5: 3 | E5: 附注披露信息（上市公司） | G5: 无需打印
A6: 复核人： | D6: 4 | E6: 附注披露信息（国企） | G6: 无需打印
A7: 复核日期： | D7: 5 | E7: 税金及附加明细表 | F7: N4-2
D8: 6 | E8: 调整分录汇总表 | F8: N4-3
A9: 关于工作底稿与审计程序索引号对应的说明
A10: 1.编制的审计工作底稿应与审计程序对应。审计项目组应根据被审计单位实际情况和风险评估情况在实质性程序表中裁剪、修改或增加审计程序，根据实际执行的审计程序完成相应审计工作底稿，编制的工作底稿中应按自然顺序依次编制索引号，并通过唯一的索引号将与实质性程序表中的程序对应关联（即将工作底稿的索引号填入实质性程序表中的底稿索引号列）。
A14: 2.获取的支持性证据应与审计底稿或程序对应。审计项目组在完成底稿时获取的支持性证据应根据底稿索引号编制下一级按自然顺序排序的索引号（如D1-2-1、D1-2-2、……），并在底稿中说明引用的支持性证据、关联索引号。
A17: 3.工作底稿索引号的编码规则：实质性程序索引号按循环从“D”到“N”,循环内账户以顺序号排列，模板中底稿索引号按账户顺序+自然数顺序（即模板中索引号按二级自然顺序排列，如D1-1、D1-2、D1-3、……D1-N）。

Sheet 税金及附加审计程序表N4A 
A1: 致同会计师事务所
A2: 税金及附加实质性程序表
A3: =底稿目录!A2 -> 被审计单位： | D3: =底稿目录!A4 -> 编制人： | F3: =底稿目录!A5 -> 编制日期： | I3: 索引号： | J3: N4A
A4: =底稿目录!A3 -> 会计期间：202X年度 | D4: =底稿目录!A6 -> 复核人： | F4: 日期： | I4: 页次：
A5: 一、本账户涉及的科目
A6: 税金及附加
A7: 二、审计目标与认定的对应关系
A8: 审计目标 | H8: 财务报表的认定
A9: A.利润表中记录的税金及附加已发生，且与被审计单位有关，已记录于恰当的账户 | H9: 发生
A10: B.所有应当记录的税金及附加均已记录，所有应当包括在财务报表中的相关披露均已包括 | H10: 完整性
A11: C.与税金及附加有关的金额及其他数据已恰当记录，相关披露已得到恰当计量和描述 | H11: 准确性
A12: D.与税金及附加有关的交易和事项已记录于正确的会计期间 | H12: 截止性
A13: E.税金及附加已被恰当地汇总或分解且表述清楚，相关披露在按照企业会计准则的编制基础下是相关的、可理解的 | H13: 列报
A14: 三、计划实施的实质性程序
A15: 序号 | B15: 对应LEAP程序 | C15: 审计程序 | D15: 程序分类 | E15: 财务报表认定 | J15: 底稿索引号
E16: 发生 | F16: 完整性 | G16: 准确性 | H16: 截止性 | I16: 列报 | K16: 根据被审计单位实际情况和风险评估情况裁剪、修改或增加审计程序
A17: 1 | B17: 常规程序 | C17: 获取税金及附加；明细表。编制审定表： （1）复核加计正确； （2）将总金额与总账核对。 | D17: 常规★ | E17: √ | F17: √ | H17: √ | J17: N4-1 /N4-2
A18: 2 | B18: IPE程序 | C18: 在使用手工编制、自定义信息报告、系统生成的非固定格式报告等由被审计单位生成的信息时，测试有关信息准确性和完整性，并考虑针对编制和维护由被审计单位生成的信息的相关控制实施控制测试，以评价该信息是否能够为实现审计目的提供基础。 | D18: 常规★ | F18: √ | G18: √ | J18: T1
A19: 3 | B19: 应对措施-检查 | C19: 结合应交税费科目的审计，复核其与相关税费的测算数是否勾稽。 | D19: 常规★ | E19: √ | F19: √ | G19: √ | H19: √ | J19: N2-8 /N2-9 /N2-10
A20: 4 | C20: 根据评估的舞弊风险等因素增加的审计程序。 | D20: IPO/上市公司/新三板舞弊应对
A21: 5 | B21: 常规程序 | C21: 检查税金及附加是否已按企业会计准则或其他适用的规定在财务报表中做出恰当列报和披露。 | D21: 常规★ | I21: √ | J21: A1-1/A1-15 /A1-16

Sheet 税金及附加审计程序表O2A（原底稿）
A1: 致同会计师事务所
A2: 税金及附加实质性程序表
A3: =[1]底稿目录!A2 -> 被审计单位： | D3: =[1]底稿目录!A4 -> #REF! | G3: =[2]底稿目录!A5 -> 编制日期： | J3: 索引号：O2A
A4: =[2]底稿目录!A3 -> 会计期间：2023X年度 | D4: =[2]底稿目录!A6 -> 复核人： | G4: 日期： | J4: 页 次：
A5: 一、本账户涉及的科目
A6: 税金及附加
A7: 二、重大错报风险需从实质性程序获取的保证程度
A8: 审计目标与认定对应关系 | D8: 财务报表的认定 | I8: 信赖/不信赖/不适用 | J8: 索引号
D9: 发生 | E9: 完整性 | F9: 准确 | G9: 分类 | H9: 列报与披露
A10: A.确定利润表中记录的税金及附加已发生，且与被审计单位有关。 | D10: √
A11: B.确定所有应当记录的税金及附加均已记录。 | E11: √
A12: C.确定与税金及附加有关的金额及其他数据已恰当记录于正确会计期间。 | F12: √
A13: D.确定税金及附加中的交易和事项已记录于恰当的账户。 | G13: √
A14: E.税金及附加已按照企业会计准则的规定在财务报表中作出恰当列报或披露。 | H14: √
A15: 三、计划实施的实质性程序
A16: 序号 | B16: 对应LEAP程序 | C16: 审计程序 | D16: 程序分类 | E16: 审计目标 | I16: 执行情况说明 （含底稿索引）
A17: （一） | B17: 常规程序 | C17: 编制审定表 | D17: 常规★ | E17: C | I17: O2 | K17: 整合
A18: （二） | B18: 常规程序 | C18: 获取税金及附加明细表。 | D18: 常规★ | E18: C | I18: O2-2
A19: 1 | B19: 常规程序 | C19: 复核加计正确 | D19: 常规★
A20: 2 | B20: 常规程序 | C20: 将总金额与总账核对。 | D20: 常规★
A21: （三） | B21: IPE程序 | C21: 在使用被审计单位生成的信息（IPE）时，应当评价该信息对实现审计目的是否足够可靠，包括根据具体情况在必要时实施下列程序： | D21: 常规★ | E21: B | I21: T1 | K21: 整合
A22: 1 | B22: IPE程序 | C22: 获取有关信息准确性和完整性的审计证据。
A23: 2 | B23: IPE程序 | C23: 评价信息对实现审计目的是否足够准确和详细。
A24: （四） | B24: 期初余额/常规程序 | C24: 对于上期税金及附加发生额（适用于首次审计时对期初余额的审计）： | D24: 备选 | E24: C | I24: O2-2
A25: 1 | B25: 期初余额/常规程序 | C25: 获取前期纳税申报表和其他有持续影响的税收文件资料（适用于首次审计）。 | D25: 备选
A26: （五） | B26: 期初余额/常规程序 | C26: 取得税务部门汇算清缴或其他确认文件、有关政府部门的专项检查报告、税务代理机构专业报告、被审计单位纳税申报资料等，分析其有效性，并与上述明细表及账面数据进行核对。对于超过法定交纳期限的税费，取得主管税务机关的批准文件。 | D26: 常规★ | E26: ABCD | I26: O2-2
A27: （六） | B27: 应对措施-检查 | C27: 对于应交和已交消费税、资源税、城建税、教育费附加、地方教育费附加、车船税、房产税、土地使用税及土地增值税等其他税项进行测算，核对计提金额是否正确，会计处理是否适当。 | D27: 常规★ | E27: ABD | I27: O1-6、O1-7 | K27: 修改 | L27: 结合应交税费科目的审计，复核其与相关税费的测算数是否勾稽。
A28: 1 | B28: 应对措施-检查 | C28: 检查各应税项目的计算是否正确。 | D28: 常规
A29: 2 | B29: 应对措施-检查 | C29: 结合税金及附加等项目的审计，根据审定的当期营业额、或其他计税基础等相关数据，检查各项税费的计税依据是否正确，适用税率是否符合税法规定，是否按规定进行了会计处理，并分项复核本期应交数。 | D29: 常规
A30: 3 | B30: 应对措施-检查 | C30: 检查本期已交税款，确定已交税款的正确性。 | D30: 常规
A31: 4 | B31: 应对措施-检查 | C31: 与纳税申报表核对，复核应交税费余额的合理性。 | D31: 常规
A32: 5 | B32: 应对措施-检查 | C32: 检查期后缴纳的税费凭证，关注期末应交税费完整性、真实性。 | D32: 常规
A33: 6 | B33: 应对措施-检查 | C33: 检查应交土地增值税的计算是否正确，是否按规定进行了会计处理： | D33: 常规
A34: （1） | B34: 应对措施-检查 | C34: 根据审定的预售房地产的预收账款，复核预交税款是否准确； | D34: 常规
A35: （2） | B35: 应对措施-检查 | C35: 对符合项目清算条件的房地产开发项目，检查被审计单位是否按规定进行土地增值税清算；如果被审计单位已聘请中介机构办理土地增值税清算鉴证的，应检查、核对相关鉴证报告； | D35: 常规
A36: （3） | B36: 应对措施-检查 | C36: 如果被审计单位被主管税务机关核定征收土地增值税的，应检查、核对相关的手续。 | D36: 常规
A37: （七） | B37: 应对措施-检查 | C37: 确定当期企业的各项税费申报计缴情况是否被税务机关检查，如是，则： | D37: 常规 | E37: CDE | K37: 删除
A38: 1 | B38: 应对措施-检查 | C38: 对于已完成的检查，获取检查报告复印件及税务部门对额外金额的评估。 | D38: 常规
A39: 2 | B39: 应对措施-检查 | C39: 对于正在进行的检查，确定是否需要额外的预提。 | D39: 常规
A40: 3 | B40: 应对措施-检查 | C40: 确定必要的税务调整是否已适当记录。 | D40: 常规
...

Sheet 税金及附加审定表N4-1
A1: 致同会计师事务所
A2: 税金及附加审定表
A3: =底稿目录!A2 -> 被审计单位： | E3: =底稿目录!A4 -> 编制人： | I3: =底稿目录!A5 -> 编制日期： | M3: 索引号： | N3: N4-1
A4: =底稿目录!A3 -> 会计期间：202X年度 | E4: =底稿目录!A6 -> 复核人： | I4: 日期： | M4: 页次：
A5: 项目 | B5: 上年数 | F5: 本期数 | J5: 本期未审数与上期 未审数的比较 | L5: 本期审定数与上期 审定数的比较 | N5: 原因分析
B6: 未审数 | C6: 账项调整 | D6: 重分类调整 | E6: 审定数 | F6: 未审数 | G6: 账项调整 | H6: 重分类调整 | I6: 审定数 | J6: 变动额 | K6: 变动率 | L6: 变动额 | M6: 变动率
A7: ='税金及附加明细表N4-2'!A9 -> 消费税 | B7: ='税金及附加明细表N4-2'!F9 -> 0 | C7: ='税金及附加明细表N4-2'!G9 -> 0 | D7: ='税金及附加明细表N4-2'!H9 -> 0 | E7: =B7+C7+D7 -> 0 | F7: ='税金及附加明细表N4-2'!B9 -> 0 | G7: ='税金及附加明细表N4-2'!C9 -> 0 | H7: ='税金及附加明细表N4-2'!D9 -> 0 | I7: =F7+G7+H7 -> 0 | J7: =F7-B7 -> 0 | K7: =IF(AND(B7=0,J7=0),0,IF(AND(B7=0,J7>0),1,J7/B7)) -> 0 | L7: =I7-E7 -> 0 | M7: =IF(AND(E7=0,L7=0),0,IF(AND(E7=0,L7>0),1,L7/E7)) -> 0
A8: ='税金及附加明细表N4-2'!A10 -> 城市维护建设税 | B8: ='税金及附加明细表N4-2'!F10 -> 0 | C8: ='税金及附加明细表N4-2'!G10 -> 0 | D8: ='税金及附加明细表N4-2'!H10 -> 0 | E8: =B8+C8+D8 -> 0 | F8: ='税金及附加明细表N4-2'!B10 -> 0 | G8: ='税金及附加明细表N4-2'!C10 -> 0 | H8: ='税金及附加明细表N4-2'!D10 -> 0 | I8: =F8+G8+H8 -> 0 | J8: =F8-B8 -> 0 | K8: =IF(AND(B8=0,J8=0),0,IF(AND(B8=0,J8>0),1,J8/B8)) -> 0 | L8: =I8-E8 -> 0 | M8: =IF(AND(E8=0,L8=0),0,IF(AND(E8=0,L8>0),1,L8/E8)) -> 0
A9: ='税金及附加明细表N4-2'!A11 -> 教育费附加 | B9: ='税金及附加明细表N4-2'!F11 -> 0 | C9: ='税金及附加明细表N4-2'!G11 -> 0 | D9: ='税金及附加明细表N4-2'!H11 -> 0 | E9: =B9+C9+D9 -> 0 | F9: ='税金及附加明细表N4-2'!B11 -> 0 | G9: ='税金及附加明细表N4-2'!C11 -> 0 | H9: ='税金及附加明细表N4-2'!D11 -> 0 | I9: =F9+G9+H9 -> 0 | J9: =F9-B9 -> 0 | K9: =IF(AND(B9=0,J9=0),0,IF(AND(B9=0,J9>0),1,J9/B9)) -> 0 | L9: =I9-E9 -> 0 | M9: =IF(AND(E9=0,L9=0),0,IF(AND(E9=0,L9>0),1,L9/E9)) -> 0
A10: ='税金及附加明细表N4-2'!A12 -> 资源税 | B10: ='税金及附加明细表N4-2'!F12 -> 0 | C10: ='税金及附加明细表N4-2'!G12 -> 0 | D10: ='税金及附加明细表N4-2'!H12 -> 0 | E10: =B10+C10+D10 -> 0 | F10: ='税金及附加明细表N4-2'!B12 -> 0 | G10: ='税金及附加明细表N4-2'!C12 -> 0 | H10: ='税金及附加明细表N4-2'!D12 -> 0 | I10: =F10+G10+H10 -> 0 | J10: =F10-B10 -> 0 | K10: =IF(AND(B10=0,J10=0),0,IF(AND(B10=0,J10>0),1,J10/B10)) -> 0 | L10: =I10-E10 -> 0 | M10: =IF(AND(E10=0,L10=0),0,IF(AND(E10=0,L10>0),1,L10/E10)) -> 0
A11: ='税金及附加明细表N4-2'!A13 -> 房产税 | B11: ='税金及附加明细表N4-2'!F13 -> 0 | C11: ='税金及附加明细表N4-2'!G13 -> 0 | D11: ='税金及附加明细表N4-2'!H13 -> 0 | E11: =B11+C11+D11 -> 0 | F11: ='税金及附加明细表N4-2'!B13 -> 0 | G11: ='税金及附加明细表N4-2'!C13 -> 0 | H11: ='税金及附加明细表N4-2'!D13 -> 0 | I11: =F11+G11+H11 -> 0 | J11: =F11-B11 -> 0 | K11: =IF(AND(B11=0,J11=0),0,IF(AND(B11=0,J11>0),1,J11/B11)) -> 0 | L11: =I11-E11 -> 0 | M11: =IF(AND(E11=0,L11=0),0,IF(AND(E11=0,L11>0),1,L11/E11)) -> 0
A12: ='税金及附加明细表N4-2'!A14 -> 土地使用税 | B12: ='税金及附加明细表N4-2'!F14 -> 0 | C12: ='税金及附加明细表N4-2'!G14 -> 0 | D12: ='税金及附加明细表N4-2'!H14 -> 0 | E12: =B12+C12+D12 -> 0 | F12: ='税金及附加明细表N4-2'!B14 -> 0 | G12: ='税金及附加明细表N4-2'!C14 -> 0 | H12: ='税金及附加明细表N4-2'!D14 -> 0 | I12: =F12+G12+H12 -> 0 | J12: =F12-B12 -> 0 | K12: =IF(AND(B12=0,J12=0),0,IF(AND(B12=0,J12>0),1,J12/B12)) -> 0 | L12: =I12-E12 -> 0 | M12: =IF(AND(E12=0,L12=0),0,IF(AND(E12=0,L12>0),1,L12/E12)) -> 0
A13: ='税金及附加明细表N4-2'!A15 -> 车船使用税 | B13: ='税金及附加明细表N4-2'!F15 -> 0 | C13: ='税金及附加明细表N4-2'!G15 -> 0 | D13: ='税金及附加明细表N4-2'!H15 -> 0 | E13: =B13+C13+D13 -> 0 | F13: ='税金及附加明细表N4-2'!B15 -> 0 | G13: ='税金及附加明细表N4-2'!C15 -> 0 | H13: ='税金及附加明细表N4-2'!D15 -> 0 | I13: =F13+G13+H13 -> 0 | J13: =F13-B13 -> 0 | K13: =IF(AND(B13=0,J13=0),0,IF(AND(B13=0,J13>0),1,J13/B13)) -> 0 | L13: =I13-E13 -> 0 | M13: =IF(AND(E13=0,L13=0),0,IF(AND(E13=0,L13>0),1,L13/E13)) -> 0
A14: ='税金及附加明细表N4-2'!A16 -> 印花税 | B14: ='税金及附加明细表N4-2'!F16 -> 0 | C14: ='税金及附加明细表N4-2'!G16 -> 0 | D14: ='税金及附加明细表N4-2'!H16 -> 0 | E14: =B14+C14+D14 -> 0 | F14: ='税金及附加明细表N4-2'!B16 -> 0 | G14: ='税金及附加明细表N4-2'!C16 -> 0 | H14: ='税金及附加明细表N4-2'!D16 -> 0 | I14: =F14+G14+H14 -> 0 | J14: =F14-B14 -> 0 | K14: =IF(AND(B14=0,J14=0),0,IF(AND(B14=0,J14>0),1,J14/B14)) -> 0 | L14: =I14-E14 -> 0 | M14: =IF(AND(E14=0,L14=0),0,IF(AND(E14=0,L14>0),1,L14/E14)) -> 0
A15: ='税金及附加明细表N4-2'!A17 -> 0 | B15: ='税金及附加明细表N4-2'!F17 -> 0 | C15: ='税金及附加明细表N4-2'!G17 -> 0 | D15: ='税金及附加明细表N4-2'!H17 -> 0 | E15: =B15+C15+D15 -> 0 | F15: ='税金及附加明细表N4-2'!B17 -> 0 | G15: ='税金及附加明细表N4-2'!C17 -> 0 | H15: ='税金及附加明细表N4-2'!D17 -> 0 | I15: =F15+G15+H15 -> 0 | J15: =F15-B15 -> 0 | K15: =IF(AND(B15=0,J15=0),0,IF(AND(B15=0,J15>0),1,J15/B15)) -> 0 | L15: =I15-E15 -> 0 | M15: =IF(AND(E15=0,L15=0),0,IF(AND(E15=0,L15>0),1,L15/E15)) -> 0
A16: 合计 | B16: =SUM(B7:B15) -> 0 | C16: =SUM(C7:C15) -> 0 | D16: =SUM(D7:D15) -> 0 | E16: =SUM(E7:E15) -> 0 | F16: =SUM(F7:F15) -> 0 | G16: =SUM(G7:G15) -> 0 | H16: =SUM(H7:H15) -> 0 | I16: =SUM(I7:I15) -> 0 | J16: =F16-B16 -> 0 | K16: =IF(AND(B16=0,J16=0),0,IF(AND(B16=0,J16>0),1,J16/B16)) -> 0 | L16: =I16-E16 -> 0 | M16: =IF(AND(E16=0,L16=0),0,IF(AND(E16=0,L16>0),1,L16/E16)) -> 0
A17: 试算平衡表数
A18: 差异数 | E18: =E16-E17 -> 0 | I18: =I16-I17 -> 0
A19: 1.审计说明：
A21: 2.审计结论

Sheet 附注披露信息（上市公司）
A1: 致同会计师事务所
A2: 附注披露信息（上市公司）
A3: =底稿目录!A2 -> 被审计单位： | C3: =底稿目录!A4 -> 编制人： | D3: =底稿目录!A5 -> 编制日期： | E3: 索引：
A4: =底稿目录!A3 -> 会计期间：202X年度 | C4: =底稿目录!A6 -> 复核人： | D4: =底稿目录!A7 -> 复核日期： | E4: 页次：1
A5: 附注披露信息：
A6: 税金及附加
A7: 项 目 | B7: 本期发生额 | C7: 上期发生额
A8: ='税金及附加审定表N4-1'!A7 -> 消费税 | B8: ='税金及附加审定表N4-1'!I7 -> 0 | C8: ='税金及附加审定表N4-1'!E7 -> 0
A9: ='税金及附加审定表N4-1'!A8 -> 城市维护建设税 | B9: ='税金及附加审定表N4-1'!I8 -> 0 | C9: ='税金及附加审定表N4-1'!E8 -> 0
A10: ='税金及附加审定表N4-1'!A9 -> 教育费附加 | B10: ='税金及附加审定表N4-1'!I9 -> 0 | C10: ='税金及附加审定表N4-1'!E9 -> 0
A11: ='税金及附加审定表N4-1'!A10 -> 资源税 | B11: ='税金及附加审定表N4-1'!I10 -> 0 | C11: ='税金及附加审定表N4-1'!E10 -> 0
A12: ='税金及附加审定表N4-1'!A11 -> 房产税 | B12: ='税金及附加审定表N4-1'!I11 -> 0 | C12: ='税金及附加审定表N4-1'!E11 -> 0
A13: ='税金及附加审定表N4-1'!A12 -> 土地使用税 | B13: ='税金及附加审定表N4-1'!I12 -> 0 | C13: ='税金及附加审定表N4-1'!E12 -> 0
A14: ='税金及附加审定表N4-1'!A13 -> 车船使用税 | B14: ='税金及附加审定表N4-1'!I13 -> 0 | C14: ='税金及附加审定表N4-1'!E13 -> 0
A15: ='税金及附加审定表N4-1'!A14 -> 印花税 | B15: ='税金及附加审定表N4-1'!I14 -> 0 | C15: ='税金及附加审定表N4-1'!E14 -> 0
A17: 合 计 | B17: =SUM(B8:B16) -> 0 | C17: =SUM(C8:C16) -> 0
A18: 说明：各项税金及附加的计缴标准详见附注四、税项。

Sheet 附注披露信息（国企）
A1: 致同会计师事务所
A2: 附注披露信息(国企)
A3: =底稿目录!A2 -> 被审计单位： | B3: =底稿目录!A4 -> 编制人： | D3: =底稿目录!A5 -> 编制日期： | E3: 索引：
A4: =底稿目录!A3 -> 会计期间：202X年度 | B4: =底稿目录!A6 -> 复核人： | D4: =底稿目录!A7 -> 复核日期：
A5: 附注披露信息：
A6: 无

Sheet 税金及附加明细表N4-2
A1: 致同会计师事务所
A2: 税金及附加明细表
A3: =底稿目录!A2 -> 被审计单位： | E3: =底稿目录!A4 -> 编制人： | H3: =底稿目录!A5 -> 编制日期： | J3: 索引号： | K3: N4-2
A4: =底稿目录!A3 -> 会计期间：202X年度 | E4: =底稿目录!A6 -> 复核人： | H4: =底稿目录!A7 -> 复核日期： | J4: 页次：
A5: 一、审计目标：
A6: 与税金及附加有关的金额及其他数据已恰当记录，相关披露已得到恰当计量和描述
A7: 二、审计过程：
A8: 项目 | B8: 本期未审数 | C8: 账项调整 | D8: 重分类调整 | E8: 本期审定数 | F8: 上期未审数 | G8: 账项调整 | H8: 重分类调整 | I8: 上期审定数 | J8: 应交税费贷方金额 | K8: 与应交税费贷方差异
A9: 消费税 | E9: =B9+C9+N4 -> 0 | I9: =F9+G9+H9 -> 0 | K9: =E9-J9 -> 0
A10: 城市维护建设税 | E10: =B10+C10+D10 -> 0 | I10: =F10+G10+H10 -> 0 | K10: =E10-J10 -> 0
A11: 教育费附加 | E11: =B11+C11+D11 -> 0 | I11: =F11+G11+H11 -> 0 | K11: =E11-J11 -> 0
A12: 资源税 | E12: =B12+C12+D12 -> 0 | I12: =F12+G12+H12 -> 0 | K12: =E12-J12 -> 0
A13: 房产税 | E13: =B13+C13+D13 -> 0 | I13: =F13+G13+H13 -> 0 | K13: =E13-J13 -> 0
A14: 土地使用税 | E14: =B14+C14+D14 -> 0 | I14: =F14+G14+H14 -> 0 | K14: =E14-J14 -> 0
A15: 车船使用税 | E15: =B15+C15+D15 -> 0 | I15: =F15+G15+H15 -> 0 | K15: =E15-J15 -> 0
A16: 印花税 | E16: =B16+C16+D16 -> 0 | I16: =F16+G16+H16 -> 0 | K16: =E16-J16 -> 0
E17: =B17+C17+D17 -> 0 | I17: =F17+G17+H17 -> 0 | K17: =E17-J17 -> 0
E18: =B18+C18+D18 -> 0 | I18: =F18+G18+H18 -> 0 | K18: =E18-J18 -> 0
A19: 合计 | B19: =SUM(B9:B18) -> 0 | C19: =SUM(C9:C18) -> 0 | D19: =SUM(D4:N18) -> 0 | E19: =SUM(E9:E18) -> 0 | F19: =SUM(F9:F18) -> 0 | G19: =SUM(G9:G18) -> 0 | H19: =SUM(H9:H18) -> 0 | I19: =SUM(I9:I18) -> 0 | J19: =SUM(J9:J18) -> 0 | K19: =SUM(K9:K18) -> 0
A20: 三、审计说明：
A23: 四、审计结论：
A25: 提示：本科目核算企业经营活动发生的消费税、城市维护建设税、资源税和教育费附加等相关税费。房产税、车船使用税、土地使用税、印花税在“管理费用”科目核算，但与投资性房地产相关的房产税、土地使用税在本科目核算。

Sheet 调整分录汇总表N4-3
A1: 致同会计师事务所
A2: 调整分录汇总表
A3: =底稿目录!A2 -> 被审计单位： | D3: =底稿目录!A4 -> 编制人： | F3: =底稿目录!A5 -> 编制日期： | I3: 索引号： | J3: N4-3
A4: =底稿目录!A3 -> 会计期间：202X年度 | D4: =底稿目录!A6 -> 复核人： | F4: =底稿目录!A7 -> 复核日期： | I4: 页次：
A5: 调整事项说明 | B5: 类别（报表调整/账项调整/其他） | C5: 报表项目 | D5: 科目名称 | E5: 附注项目 | F5: …… | G5: 借方调整金额 | H5: 贷方调整金额 | I5: 索引 | J5: 备注
A21: 提示：本底稿适用于调整分录较多、较复杂的项目，且仅列示与本报表项目相关的审计调整。项目组可根据项目实际情况选择是否使用该底稿。

Sheet GT_Custom
A1: C1 | B1: Custom 1
A2: C2 | B2: Custom 2
A3: C3 | B3: Custom 3
A4: C4 | B4: Custom 4
A5: C5 | B5: Custom 5
A6: C6 | B6: Custom 6
A7: C7 | B7: Custom 7
A8: C8 | B8: Custom 8
