Workbook
Name _.dbf: #REF!
Name _002年6月收入及成本报表: #REF!
Name _002年6月制造及辅助生产表: #REF!
Name _1.管理费收入20401.xls: #REF!
Name _13: #REF!
Name _19: #REF!
Name _1901借: #REF!
Name _1固定资产数据库_筛选打印: #REF!
Name _1余额表_一级_.dbf: #REF!
Name _209: #REF!
Name _2年裙房收入.dbf: #REF!
Name _2余额表_一级_.dbf: #REF!
Name _c600000: #REF!
Name _c65537: #REF!
Name _c65538: #REF!
Name _c65539: #REF!
Name _c65540: #REF!
Name _c65550: #REF!
Name _c655534: #REF!
Name _c655535: #REF!
Name _c655540: #REF!
Name _c66000: #REF!
Name _c69000: #REF!
Name _DAT10: '[1]收入明细－按客户'!#REF!
Name _DAT11: '[1]收入明细－按客户'!#REF!
Name _DAT12: '[1]收入明细－按客户'!#REF!
Name _DAT13: '[1]收入明细－按客户'!#REF!
Name _DAT16: '[1]收入明细－按客户'!#REF!
Name _DAT17: '[1]收入明细－按客户'!#REF!
Name _DAT3: '[1]收入明细－按客户'!#REF!
Name _DAT4: '[1]收入明细－按客户'!#REF!
Name _DAT5: '[1]收入明细－按客户'!#REF!
Name _DAT6: '[1]收入明细－按客户'!#REF!
Name _DAT7: '[1]收入明细－按客户'!#REF!
Name _SH1: #REF!
Name _UFP2005: #REF!
Name _yf.dbf: #REF!
Name _YS1: #REF!
Name _YS2: '[2]YS02-02'!#REF!
Name A: #REF!
Name actual: #REF!
Name approve: #REF!
Name ATTACH_A: '[3]Economic evaluation - FY98 base'!#REF!
Name B.dbf: #REF!
Name cp: #REF!
Name cus: #REF!
Name data: #REF!
Name data2: #REF!
Name DEPR_ALL: '[3]Economic evaluation - FY98 base'!#REF!
Name DEPR_BOOK: '[3]Economic evaluation - FY98 base'!#REF!
Name DEPR_TAX: '[3]Economic evaluation - FY98 base'!#REF!
Name dt.dbf: #REF!
Name duanqi: #REF!
Name ed: #REF!
Name er: #REF!
Name fix2000.dbf: #REF!
Name fixlj2000.dbf: #REF!
Name frst: #REF!,#REF!
Name F机器设备: #REF!
Name gdzc: #REF!

Sheet 底稿目录
A1: 底稿开列时，可先在以下单元格填写有关内容，以便其他底稿引用有关数据：
A2: 被审计单位： | D2: 序号 | E2: 内容 | F2: 索引号
A3: 会计期间：202X年度 | D3: 1 | E3: 所得税审计程序表 | F3: N5A
A4: 编制人： | D4: 2 | E4: 所得税费用审定表 | F4: N5-1
A5: 编制日期： | D5: 3 | E5: 附注披露信息（上市公司） | G5: 无需打印
A6: 复核人: | D6: 4 | E6: 附注披露信息（国企） | G6: 无需打印
A7: 复核日期: | D7: 5 | E7: 所得税费用明细表 | F7: N5-2
D8: 6 | E8: 调整分录汇总表 | F8: N5-3
A9: 关于工作底稿与审计程序索引号对应的说明 | D9: 7 | E9: 当期所得税费用计算表 | F9: N5-4
A10: 1.编制的审计工作底稿应与审计程序对应。审计项目组应根据被审计单位实际情况和风险评估情况在实质性程序表中裁剪、修改或增加审计程序，根据实际执行的审计程序完成相应审计工作底稿，编制的工作底稿中应按自然顺序依次编制索引号，并通过唯一的索引号将与实质性程序表中的程序对应关联（即将工作底稿的索引号填入实质性程序表中的底稿索引号列）。 | D10: 8 | E10: 纳税调整明细表 | F10: N5-5
D11: 9 | E11: 税收优惠明细表 | F11: N5-6
D12: 10 | E12: 加计扣除研发费用情况明细表 | F12: N5-6-1
D13: 11 | E13: 高新技术企业认定条件检查表 | F13: N5-6-2
A14: 2.获取的支持性证据应与审计底稿或程序对应。审计项目组在完成底稿时获取的支持性证据应根据底稿索引号编制下一级按自然顺序排序的索引号（如D1-2-1、D1-2-2、……），并在底稿中说明引用的支持性证据、关联索引号。 | D14: 12 | E14: 财产损失明细表 | F14: N5-7
D15: 13 | E15: 递延所得税费用计算表 | F15: N5-8
A17: 3.工作底稿索引号的编码规则：实质性程序索引号按循环从“D”到“N”,循环内账户以顺序号排列，模板中底稿索引号按账户顺序+自然数顺序（即模板中索引号按二级自然顺序排列，如D1-1、D1-2、D1-3、……D1-N）。

Sheet 所得税审计程序表N5A
A1: 致同会计师事务所
A2: 所得税费用实质性程序表
A3: =底稿目录!A2 -> 被审计单位： | D3: =底稿目录!A4 -> 编制人： | G3: =底稿目录!A5 -> 编制日期： | I3: 索引号： | J3: N5A
A4: =底稿目录!A3 -> 会计期间：202X年度 | D4: =底稿目录!A6 -> 复核人: | G4: =底稿目录!A7 -> 复核日期: | I4: 页次：
A5: 一、本账户涉及的科目
A6: 所得税费用
A7: 二、审计目标与财务报表的认定
A8: 审计目标 | H8: 财务报表的认定
A9: A.利润表中记录的所得税费用已发生，且与被审计单位有关，已记录于恰当的账户 | H9: 发生
A10: B.所有应当记录的所得税费用均已记录，所有应当包括在财务报表中的相关披露均已包括 | H10: 完整性
A11: C.与所得税费用有关的金额及其他数据已恰当记录，相关披露已得到恰当计量和描述 | H11: 准确性
A12: D.与所得税费用有关的交易和事项已记录于正确的会计期间 | H12: 截止性
A13: E.所得税费用已被恰当地汇总或分解且表述清楚，相关披露在按照企业会计准则的编制基础下是相关的、可理解的 | H13: 列报
A14: 三、计划实施的实质性程序
A15: 序号 | B15: 对应LEAP程序 | C15: 审计程序 | D15: 程序分类 | E15: 财务报表的认定 | J15: 底稿索引号
E16: 发生 | F16: 完整性 | G16: 准确性 | H16: 截止性 | I16: 列报 | K16: 根据被审计单位实际情况和风险评估情况裁剪、修改或增加审计程序
A17: 1 | B17: 常规程序 | C17: 获取所得税费用明细表，编制审定表，并完成以下工作： （1）复核加计正确，将总金额与总账、明细账合计数核对相符； （2）核对期初余额与上期审定期末余额、纳税申报表及税务机关的认定数是否相符。 （4）如期初存在延期纳税的事项，检查是否经过税务机关批准。 | D17: 常规★ | E17: √ | F17: √ | G17: √ | J17: N5-1 /N5-2
A18: 2 | B18: IPE程序 | C18: 在使用手工编制、自定义信息报告、系统生成的非固定格式报告等由被审计单位生成的信息时，测试有关信息准确性和完整性，并考虑针对编制和维护由被审计单位生成的信息的相关控制实施控制测试，以评价该信息是否能够为实现审计目的提供基础。 | D18: 常规★ | F18: √ | G18: √ | J18: T1 | K18: 可参见《审计手册》4.2.6，由被审计单位生成的信息可能是由系统生成的、或手工编制的、或二者兼而有之的方式生成的。例如，由被审计单位生成的信息可能包括： • 不涉及自定义的、由系统生成的报告（如，固定格式报告）； • 可能通过人工自定义的、由系统生成的报告，例如，（计算机）查询信息或特别定制的报告； • 手工编制的信息，例如，汇总信息的电子表格或用以支持分配、计算以及调节的电子表格； • 其他系统生成或手工编制的信息，例如，由被审计单位编制的客户发票； • 通过影印、拍摄、扫描或其他方式转换成电子形式的文件记录。
A19: 3 | B19: 期初余额 | C19: 对于上期所得税相关项目金额，获得并查阅上期所得税明细表，确定采用的会计政策和程序是适当的，检查申报金额与纳税申报表一致，获取前期纳税申报表和其他有持续影响的税收文件资料，就任何激进的或可疑的税务状况向我们的税务专家咨询。（适用于首次承接） | D19: 备选 | E19: √ | F19: √ | G19: √ | H19: √ | K19: 由被审计单位生成的信息不包括： • 总分类账或明细分类账、试算平衡表、或经审计的财务报表； • 第三方（除了服务机构）的报表或报告，例如，原始银行对账单，或函证的回函； • 外部数据（例如，第三方发布的数据，如，定价来源）。
A20: 4 | B20: 应对措施-检查 | C20: 获取被审计单位本期所得税纳税申报表、所得税鉴证报告、主管税务机关备案登记表，与账面相关记录进行核对。 | D20: 常规★ | E20: √ | F20: √ | G20: √ | H20: √
A21: 5 | B21: 应对措施-检查 | C21: 结合其他科目的审计和税法规定，核实当期的纳税调整事项，确定应纳税所得额，检查会计处理是否正确。 | D21: 常规★ | G21: √ | J21: /N5-5 /N5-6 /N5-7 /N5-8
A22: 6 | B22: 应对措施-检查 | C22: 针对税收优惠政策，应执行以下程序： （1）对于涉及高新技术企业资格认定的，检查批文，确定被审计单位是否符合实质条件；了解复审的情况，获取企业管理层对其高新技术企业资格是否能够延续的书面评价材料，确定采用的税率是否适当； （2）如果适用研发费用加计扣除的，检查被审计单位是否已完成科委鉴定、税务鉴证并向主管税务机关备案等三项工作。 （3）报告期执行的税收优惠政策与国家法规政策不符的，应获得当地税务主管机关的意见和认定；同时由原股东出具承诺，承担相应的补缴风险。 （4）对于申报期内的核定征收改为查账征收的，应补提企业所得税，实际控制人或股东应出具补交以前税款的承诺。 （5）对于申请减免税的企业，需要税务机关审批的，应检查准予减免税的书面决定；对于需要减免税备案的企业，应检查企业是否按照税务机关的要求备案。 | D22: 常规★ | E22: √ | F22: √ | G22: √ | J22: N5-6 /N5-6-1 /N5-6-2
A23: 7 | B23: 应对措施-检查 | C23: 确定当期企业的各项税费申报计缴情况是否被税务机关检查，如是，则对于已完成的检查，获取检查报告复印件及税务部门对额外金额的评估。 对于正在进行的检查，确定是否需要额外的预提。确定必要的税务调整是否已适当记录,确定重大罚款或其他涉税负债的会计处理是否正确。 | D23: 常规★ | E23: √ | F23: √ | G23: √
A24: 8 | B24: 应对措施-检查 | C24: 重新计算当期所得税费用 | D24: 常规★ | G24: √ | J24: N5-4
A25: 9 | B25: 应对措施-期初余额/检查 | C25: 获取报告期及以前一至两年主要税种纳税申报表和所得税汇算清缴表、纳税鉴证报告（如有），将其中的收入、利润、税项等相关数据与各年度财务报表核对，分析差异及变动趋势，并验证其合理性。 | D25: /IPO/上市公司/新三板/重组/舞弊应对 | E25: √ | F25: √ | G25: √
A26: 10 | B26: 应对措施-期初余额/检查 | C26: 考虑取得税务机关出具的纳税证明文件的复印件，并与网上电子数据核对。 | D26: /IPO/上市公司/新三板/重组/舞弊应对 | E26: √ | F26: √ | G26: √
A27: 11 | C27: 根据评估的舞弊风险等因素增加的审计程序。 | D27: /IPO/上市公司/新三板/重组/舞弊应对
A28: 12 | B28: 常规程序 | C28: 检查所得税费用是否已按企业会计准则或其他适用的规定在财务报表中做出恰当列报和披露。 | D28: 常规★ | I28: √ | J28: A1-1/A1-15 /A1-16

Sheet 所得税审计程序表N3A (原底稿)
A1: 致同会计师事务所
A2: 所得税实质性程序表
A3: =[4]底稿目录!A2 -> 客户名称： | D3: =[4]底稿目录!A4 -> 编制人： | G3: =[4]底稿目录!A5 -> 编制日期： | J3: 索引号：N3A
A4: =[4]底稿目录!A3 -> 会计期间：202X年度 | D4: =[4]底稿目录!A6 -> 复核人: | G4: =[4]底稿目录!A7 -> 复核日期: | J4: 页 次：
A5: 一、本账户涉及的科目
A6: 所得税费用
A7: 二、重大错报风险需从实质性程序获取的保证程度
A8: 审计目标与认定对应关系 | D8: 财务报表的认定 | I8: 信赖/不信赖/不适用 | J8: 索引号
D9: 发生 | E9: 完整性 | F9: 准确性 | G9: 分类 | H9: 列报
A10: A.利润表中记录的所得税费用已发生，且与被审计单位有关。 | D10: √
A11: B.所有应当记录的所得税费用均已记录。 | E11: √
A12: C.与所得税费用有关的金额及其他数据已恰当记录于正确会计期间。 | F12: √
A13: D.被审计单位记录的所得税费用记录于恰当的账户。 | G13: √
A14: E.所得税费用已按照企业会计准则的规定在财务报表中作出恰当列报。 | H14: √
A15: 三、计划实施的实质性程序
A16: 序号 | B16: 对应LEAP程序 | C16: 审计程序 | D16: 程序分类 | E16: 审计目标 | I16: 执行情况说明 （含底稿索引）
A17: （一） | B17: 常规程序 | C17: 编制审定表 | D17: 常规★ | E17: C | I17: N3
A18: （二） | B18: 常规程序 | C18: 获取所得税费用明细表。 | D18: 常规★ | E18: C | I18: O1-2、O1-3
A19: 1 | B19: 常规程序 | C19: 复核加计正确 | D19: 常规★
A20: 2 | B20: 常规程序 | C20: 将总金额与总账、明细账合计数核对相符 | D20: 常规★
A21: 3 | B21: 常规程序 | C21: 核对期初余额与上期审定期末余额、纳税申报表及税务机关的认定数是否相符。 | D21: 常规
A22: 4 | B22: 常规程序 | C22: 如期初存在延期纳税的事项，检查是否经过税务机关批准。 | D22: 常规
A23: （三） | B23: IPE程序 | C23: 在使用被审计单位生成的信息（IPE）时，应当评价该信息对实现审计目的是否足够可靠，包括根据具体情况在必要时实施下列程序： | D23: 常规★ | E23: B | I23: T1
A24: 1 | B24: IPE程序 | C24: 获取有关信息准确性和完整性的审计证据。
A25: 2 | B25: IPE程序 | C25: 评价信息对实现审计目的是否足够准确和详细。
A26: （四） | B26: 期初余额 | C26: 对于上期期末所得税相关项目余额：(适用于首次承接） | D26: 备选 | E26: ABC | I26: N3-2
A27: 1 | B27: 期初余额 | C27: 获得并查阅账户余额明细表。 | D27: 备选
A28: 2 | B28: 期初余额 | C28: 确定采用的会计政策和程序是适当的。 | D28: 备选
A29: 3 | B29: 期初余额 | C29: 确定暂时性差异的合理性。 | D29: 备选
A30: 4 | B30: 期初余额 | C30: 确定余额与纳税申报表一致。 | D30: 备选
A31: 5 | B31: 期初余额 | C31: 就任何激进的或可疑的税务状况向我们的税务专家咨询。 | D31: 备选
A32: 6 | B32: 期初余额 | C32: 获取前期纳税申报表和其他有持续影响的税收文件资料（适用于首次承接）。 | D32: 备选
A33: （五） | B33: 应对措施-检查 | C33: 获取被审计单位本期所得税纳税申报表、所得税签证报告、主管税务机关备案登记表，与账面相关记录进行核对。 | D33: 常规★ | E33: ABCD | I33: O1-2
A34: （六） | B34: 应对措施-检查 | C34: 结合其他账项的审计和税法规定，核实当期的纳税调整事项，确定应纳税所得额，检查会计处理是否正确。 | D34: 常规★ | E34: ABCD | I34: N3-3、N3-4、N3-5、N3-6
A35: （七） | B35: 应对措施-检查 | C35: 针对税收优惠政策，应执行以下程序： | D35: 备选 | E35: ABC | I35: N3-5
A36: 1 | B36: 应对措施-检查 | C36: 对于涉及高新技术企业资格认定的，检查批文，确定被审计单位是否符合实质条件；了解复审的情况，获取企业管理层对其高新技术企业资格是否能够延续的书面评价材料，确定采用的税率是否适当；如果适用研发费用加计扣除的，检查被审计单位是否已完成科委鉴定、税务鉴证并向主管税务机关备案等三项工作。 | D36: 备选
A37: 2 | B37: 应对措施-检查 | C37: 报告期执行的税收优惠政策与国家法规政策不符的，应获得当地税务主管机关的意见和认定；同时由原股东出具承诺，承担相应的补缴风险。 | D37: 备选
A38: 3 | B38: 应对措施-检查 | C38: 对于申报期内的核定征收改为查账征收的，应补提企业所得税，实际控制人或股东应出具补交以前税款的承诺。 | D38: 备选
A39: 4 | B39: 应对措施-检查 | C39: 对于申请减免税的企业，需要税务机关审批的，应检查准予减免税的书面决定；对于需要减免税备案的企业，应检查企业是否按照税务机关的要求备案。 | D39: 备选
A40: （八） | B40: 应对措施-检查 | C40: 确定当期企业的各项税费申报计缴情况是否被税务机关检查，如是，则： | D40: 常规 | E40: ABC
...

Sheet 所得税费用审定表N5-1
A1: 致同会计师事务所
A2: 所得税费用审定表
A3: =底稿目录!A2 -> 被审计单位： | E3: =底稿目录!A4 -> 编制人： | I3: =底稿目录!A5 -> 编制日期： | M3: 索引号： | N3: N5-1
A4: =底稿目录!A3 -> 会计期间：202X年度 | E4: =底稿目录!A6 -> 复核人: | I4: =底稿目录!A7 -> 复核日期: | M4: 页次：
A5: 项目 | B5: 上期数 | F5: 本期数 | J5: 本期未审数与上期 未审数的比较 | L5: 本期审定数与上期 审定数的比较 | N5: 原因分析
B6: 未审数 | C6: 账项调整 | D6: 重分类调整 | E6: 审定数 | F6: 未审数 | G6: 账项调整 | H6: 重分类调整 | I6: 审定数 | J6: 变动额 | K6: 变动率 | L6: 变动额 | M6: 变动率
A7: 当期所得税费用 | B7: ='所得税费用明细表N5-2'!D22 -> 0 | E7: =B7+C7+D7 -> 0 | F7: ='所得税费用明细表N5-2'!B22 -> 0 | I7: =F7+G7+H7 -> 0 | J7: =F7-B7 -> 0 | K7: =IF(AND(B7=0,J7=0),0,IF(AND(B7=0,J7>0),1,J7/B7)) -> 0 | L7: =I7-E7 -> 0 | M7: =IF(AND(E7=0,L7=0),0,IF(AND(E7=0,L7>0),1,L7/E7)) -> 0
A8: 递延所得税费用 | B8: ='所得税费用明细表N5-2'!D22-'所得税费用审定表N5-1'!B7 -> 0 | E8: =B8+C8+D8 -> 0 | F8: ='所得税费用明细表N5-2'!B22-'所得税费用审定表N5-1'!F7 -> 0 | I8: =F8+G8+H8 -> 0 | J8: =F8-B8 -> 0 | K8: =IF(AND(B8=0,J8=0),0,IF(AND(B8=0,J8>0),1,J8/B8)) -> 0 | L8: =I8-E8 -> 0 | M8: =IF(AND(E8=0,L8=0),0,IF(AND(E8=0,L8>0),1,L8/E8)) -> 0
A9: 合计 | B9: =SUM(B7:B8) -> 0 | C9: =SUM(C7:C8) -> 0 | D9: =SUM(D7:D8) -> 0 | E9: =B9+C9+D9 -> 0 | F9: =SUM(F7:F8) -> 0 | G9: =SUM(G7:G8) -> 0 | H9: =SUM(H7:H8) -> 0 | I9: =F9+G9+H9 -> 0 | J9: =F9-B9 -> 0 | K9: =IF(AND(B9=0,J9=0),0,IF(AND(B9=0,J9>0),1,J9/B9)) -> 0 | L9: =I9-E9 -> 0 | M9: =IF(AND(E9=0,L9=0),0,IF(AND(E9=0,L9>0),1,L9/E9)) -> 0
A10: 试算平衡表数
A11: 差异数 | E11: =E9-E10 -> 0 | I11: =I9-I10 -> 0
A12: 1.审计说明
A13: （1）所得税费用本期较上期增加（负数为减少）：
A14: 主要原因（比例超过30%的）：
A17: （2）情况说明。
A21: 2.审计结论

Sheet 附注披露信息（上市公司）
A1: 致同会计师事务所
A2: 附注披露信息（上市公司）
A3: =底稿目录!A2 -> 被审计单位： | B3: =底稿目录!A4 -> 编制人： | C3: =底稿目录!A5 -> 编制日期： | D3: 索引：N3-1
A4: =底稿目录!A3 -> 会计期间：202X年度 | B4: =底稿目录!A6 -> 复核人: | C4: =底稿目录!A7 -> 复核日期: | D4: 页次：1
A5: 附注披露信息：
A6: 所得税费用
A7: （1）所得税费用明细
A8: 项 目 | C8: 本期发生额 | D8: 上期发生额
A9: 按税法及相关规定计算的当期所得税 | C9: ='所得税费用审定表N5-1'!I7 -> 0 | D9: ='所得税费用审定表N5-1'!E7 -> 0
A10: 递延所得税费用 | C10: ='所得税费用审定表N5-1'!I8 -> 0 | D10: ='所得税费用审定表N5-1'!E8 -> 0
A11: 合 计 | C11: =SUM(C9:C10) -> 0 | D11: =SUM(D9:D10) -> 0
A12: （2）所得税费用与利润总额的关系列示如下：（不适用项目可删除，“其他”金额不应过大）
A13: 项 目 | C13: 本期发生额 | D13: 上期发生额
A14: ='所得税费用明细表N5-2'!A9 -> 审定利润总额 | C14: ='所得税费用明细表N5-2'!B9 -> 0 | D14: ='所得税费用明细表N5-2'!D9 -> 0
A15: ='所得税费用明细表N5-2'!A10 -> 按法定（或适用）税率计算的所得税费用（利润总额*xx%） | C15: ='所得税费用明细表N5-2'!B10 -> 0 | D15: ='所得税费用明细表N5-2'!D10 -> 0
A16: ='所得税费用明细表N5-2'!A11 -> 某些子公司适用不同税率的影响 | C16: ='所得税费用明细表N5-2'!B11 -> 0 | D16: ='所得税费用明细表N5-2'!D11 -> 0
A17: ='所得税费用明细表N5-2'!A12 -> 对以前期间当期税项的调整 | C17: ='所得税费用明细表N5-2'!B12 -> 0 | D17: ='所得税费用明细表N5-2'!D12 -> 0
A18: ='所得税费用明细表N5-2'!A13 -> 权益法核算的合营企业和联营企业损益 | C18: ='所得税费用明细表N5-2'!B13 -> 0 | D18: ='所得税费用明细表N5-2'!D13 -> 0
A19: ='所得税费用明细表N5-2'!A14 -> 无须纳税的收入 | C19: ='所得税费用明细表N5-2'!B14 -> 0 | D19: ='所得税费用明细表N5-2'!D14 -> 0
A20: ='所得税费用明细表N5-2'!A15 -> 不可抵扣的税项费用的纳税影响 | C20: ='所得税费用明细表N5-2'!B15 -> 0 | D20: ='所得税费用明细表N5-2'!D15 -> 0
A21: ='所得税费用明细表N5-2'!A16 -> 税率变动对期初递延所得税余额的影响 | C21: ='所得税费用明细表N5-2'!B16 -> 0 | D21: ='所得税费用明细表N5-2'!D16 -> 0
A22: ='所得税费用明细表N5-2'!A17 -> 利用以前年度未确认可抵扣亏损和可抵扣暂时性差异的纳税影响 | C22: ='所得税费用明细表N5-2'!B17 -> 0 | D22: ='所得税费用明细表N5-2'!D17 -> 0
A23: ='所得税费用明细表N5-2'!A18 -> 未确认可抵扣亏损和可抵扣暂时性差异的纳税影响 | C23: ='所得税费用明细表N5-2'!B18 -> 0 | D23: ='所得税费用明细表N5-2'!D18 -> 0
A24: ='所得税费用明细表N5-2'!A19 -> 研究开发费加成扣除的纳税影响 | C24: ='所得税费用明细表N5-2'!B19 -> 0 | D24: ='所得税费用明细表N5-2'!D19 -> 0
A25: ='所得税费用明细表N5-2'!A20 -> 其他 | C25: ='所得税费用明细表N5-2'!B20 -> 0 | D25: ='所得税费用明细表N5-2'!D20 -> 0
A27: 【注：上表中，所得税费用等于第二行至倒数第二行之和；
A28: 对以前期间当期所得税的调整：是指，对以前年度所得税进行汇算清缴的结果与以前年度确认的金额不同而调整本年所得税费用的金额。
A29: “不可抵扣的成本、费用和损失”、“未确认可抵扣亏损和可抵扣暂时性差异的纳税影响”不应为负数。】

Sheet 附注披露信息（国企
A1: 致同会计师事务所
A2: 附注披露信息（国企）
A3: =底稿目录!A2 -> 被审计单位： | B3: =底稿目录!A4 -> 编制人： | C3: =底稿目录!A5 -> 编制日期： | D3: 索引号：N3-1
A4: =底稿目录!A3 -> 会计期间：202X年度 | B4: =底稿目录!A6 -> 复核人: | C4: =底稿目录!A7 -> 复核日期: | D4: 页次：
A5: 附注披露信息:
A6: 所得税费用
A7: 项 目 | C7: 本期发生额 | D7: 上期发生额
A8: 当期所得税费用 | C8: ='所得税费用审定表N5-1'!I7 -> 0 | D8: ='所得税费用审定表N5-1'!E7 -> 0
A9: 递延所得税调整 | C9: ='所得税费用审定表N5-1'!I8 -> 0 | D9: ='所得税费用审定表N5-1'!E8 -> 0
A10: 其他
A11: 合 计 | C11: =SUM(C8:C10) -> 0 | D11: =SUM(D8:D10) -> 0
A13: （2）会计利润与所得税费用调整过程：（国资委格式未要求披露，建议披露）
A14: 项 目 | C14: 本期发生额 | D14: 上期发生额
A15: ='所得税费用明细表N5-2'!A9 -> 审定利润总额 | C15: ='所得税费用明细表N5-2'!B9 -> 0 | D15: ='所得税费用明细表N5-2'!D9 -> 0
A16: ='所得税费用明细表N5-2'!A10 -> 按法定（或适用）税率计算的所得税费用（利润总额*xx%） | C16: ='所得税费用明细表N5-2'!B10 -> 0 | D16: ='所得税费用明细表N5-2'!D10 -> 0
A17: ='所得税费用明细表N5-2'!A11 -> 某些子公司适用不同税率的影响 | C17: ='所得税费用明细表N5-2'!B11 -> 0 | D17: ='所得税费用明细表N5-2'!D11 -> 0
A18: ='所得税费用明细表N5-2'!A12 -> 对以前期间当期税项的调整 | C18: ='所得税费用明细表N5-2'!B12 -> 0 | D18: ='所得税费用明细表N5-2'!D12 -> 0
A19: ='所得税费用明细表N5-2'!A13 -> 权益法核算的合营企业和联营企业损益 | C19: ='所得税费用明细表N5-2'!B13 -> 0 | D19: ='所得税费用明细表N5-2'!D13 -> 0
A20: ='所得税费用明细表N5-2'!A14 -> 无须纳税的收入 | C20: ='所得税费用明细表N5-2'!B14 -> 0 | D20: ='所得税费用明细表N5-2'!D14 -> 0
A21: ='所得税费用明细表N5-2'!A15 -> 不可抵扣的税项费用的纳税影响 | C21: ='所得税费用明细表N5-2'!B15 -> 0 | D21: ='所得税费用明细表N5-2'!D15 -> 0
A22: ='所得税费用明细表N5-2'!A16 -> 税率变动对期初递延所得税余额的影响 | C22: ='所得税费用明细表N5-2'!B16 -> 0 | D22: ='所得税费用明细表N5-2'!D16 -> 0
A23: ='所得税费用明细表N5-2'!A17 -> 利用以前年度未确认可抵扣亏损和可抵扣暂时性差异的纳税影响 | C23: ='所得税费用明细表N5-2'!B17 -> 0 | D23: ='所得税费用明细表N5-2'!D17 -> 0
A24: ='所得税费用明细表N5-2'!A18 -> 未确认可抵扣亏损和可抵扣暂时性差异的纳税影响 | C24: ='所得税费用明细表N5-2'!B18 -> 0 | D24: ='所得税费用明细表N5-2'!D18 -> 0
A25: ='所得税费用明细表N5-2'!A19 -> 研究开发费加成扣除的纳税影响 | C25: ='所得税费用明细表N5-2'!B19 -> 0 | D25: ='所得税费用明细表N5-2'!D19 -> 0
A26: ='所得税费用明细表N5-2'!A20 -> 其他 | C26: ='所得税费用明细表N5-2'!B20 -> 0 | D26: ='所得税费用明细表N5-2'!D20 -> 0
... A28: ='所得税费用明细表N5-2'!A22 -> 所得税费用未审数 | C28: ='所得税费用明细表N5-2'!B22 -> 0 | D28: ='所得税费用明细表N5-2'!D22 -> 0
A30: 【注：上表中，所得税费用等于第二行至倒数第二行之和；
A31: 对以前期间当期所得税的调整：是指，对以前年度所得税进行汇算清缴的结果与以前年度确认的金额不同而调整本年所得税费用的金额。
A32: “不可抵扣的成本、费用和损失”、“未确认可抵扣亏损和可抵扣暂时性差异的纳税影响”不应为负数。】

Sheet 所得税费用明细表N5-2
A1: 致同会计师事务所
A2: 所得税费用明细表
A3: =底稿目录!A2 -> 被审计单位： | B3: =底稿目录!A4 -> 编制人： | D3: =底稿目录!A5 -> 编制日期： | E3: 索引号： | F3: N5-2
A4: =底稿目录!A3 -> 会计期间：202X年度 | B4: =底稿目录!A6 -> 复核人: | D4: =底稿目录!A7 -> 复核日期: | E4: 页次：
A5: 一、审计目标
A6: 与所得税费用有关的金额及其他数据已恰当记录，相关披露已得到恰当计量和描述
A7: 二、审计过程
A8: 项目 | B8: 本期数 | C8: 索引号 | D8: 上期数 | E8: 索引号 | F8: 备注
A9: 审定利润总额 | B9: 0 | F9: 税率
A10: 按法定（或适用）税率计算的所得税费用（利润总额*xx%） | B10: =B9*25% -> 0 | D10: =D9*25% -> 0 | F10: 0.25
A11: 某些子公司适用不同税率的影响
A12: 对以前期间当期税项的调整
A13: 权益法核算的合营企业和联营企业损益
A14: 无须纳税的收入
A15: 不可抵扣的税项费用的纳税影响
A16: 税率变动对期初递延所得税余额的影响
A17: 利用以前年度未确认可抵扣亏损和可抵扣暂时性差异的纳税影响
A18: 未确认可抵扣亏损和可抵扣暂时性差异的纳税影响
A19: 研究开发费加成扣除的纳税影响
A20: 其他
A21: 所得税费用审定数 | B21: =SUM(B10:B20) -> 0 | D21: =SUM(D10:D20) -> 0
A22: 所得税费用未审数
A23: 审计调整 | B23: =B21-B22 -> 0 | D23: =D21-D22 -> 0
A24: 三、审计说明：
A28: 四、审计结论：
A30: 提示：
A31: 1.根据企业情况删减和添加项目；
A32: 2.项目“某些子公司适用不同税率的影响”在单体报表中不应该出现数据，只有在合并报表和报表主体适用不同税率的情况下放出现；
A33: 3.项目“对以前期间当期税项的调整”反映本期补缴或退回以前年度缴纳的当期所得税费用。
A34: 4.对于当期发生所得税费用大额的调整、冲回的情况，应考虑利用税务专家工作。

Sheet 调整分录汇总表N5-3
A1: 致同会计师事务所
A2: 所得税费用调整分录汇总表
A3: =底稿目录!A2 -> 被审计单位： | D3: =底稿目录!$A$4 -> 编制人： | G3: =底稿目录!$A$5 -> 编制日期： | I3: 索引号： | J3: N5-3
A4: =底稿目录!A3 -> 会计期间：202X年度 | D4: =底稿目录!$A$6 -> 复核人: | G4: =底稿目录!$A$7 -> 复核日期: | I4: 页次：
A5: 调整事项说明 | B5: 类别（报表调整/账项调整/其他） | C5: 报表项目 | D5: 科目名称 | E5: 附注项目 | F5: …… | G5: 借方调整金额 | H5: 贷方调整金额 | I5: 索引 | J5: 备注
A21: 1.审计说明
A25: 2.审计结论
A27: 提示：本底稿适用于调整分录较多、较复杂的项目，且仅列示与本报表项目相关的审计调整。项目组可根据项目实际情况选择是否使用该底稿。

Sheet 当期所得税费用计算表N5-4
A1: 致同会计师事务所
A2: 当期所得税费用计算表
A3: =底稿目录!A2 -> 被审计单位： | B3: =底稿目录!$A$4 -> 编制人： | C3: =底稿目录!$A$5 -> 编制日期： | D3: 索引号： | E3: N5-4
A4: =底稿目录!A3 -> 会计期间：202X年度 | B4: =底稿目录!$A$6 -> 复核人: | C4: =底稿目录!$A$7 -> 复核日期: | D4: 页次：
A5: 一、审计目标
A6: 1.利润表中记录的所得税费用已发生，且与被审计单位有关，已记录于恰当的账户
A7: 2.所有应当记录的所得税费用均已记录，所有应当包括在财务报表中的相关披露均已包括
A8: 3.与所得税费用有关的金额及其他数据已恰当记录，相关披露已得到恰当计量和描述
A9: 二、审计过程
A10: 1.结合其他账项的审计和税法规定，核实当期的纳税调整事项，确定应纳税所得额，检查会计处理是否正确。
A11: 2.对所得税费费用和相关的短期应交税金余额的计算进行测试，确定计算的准确性。
A12: 3.通过支持性文件核实重大的永久性差异。
A13: 4.确认该计算值是否适当地反映了递延所得税账户余额的变动。
A14: 5.确定外国税收和直接退税是否被识别，并在计算中得到正确的反映。
A15: 6.调查异常分录。
A16: 7.审查用于计算的比率是否合理。
... A18: 9.核对期末余额与总账是否一致。
A19: 项目 | B19: 未审数 | C19: 调整数 | D19: 审定数 | E19: 索引号
A20: 本期应纳所得税额
A21: 一、期初欠缴数 | D21: =B21+C21 -> 0
A22: 二、本期应交数 | B22: —— | C22: —— | D22: ——
A23: 1、利润总额 | D23: =B23+C23 -> 0
A24: 加：纳税调整增加额 | B24: =SUM(B25:B44) -> 0 | C24: =SUM(C25:C44) -> 0 | D24: =SUM(D25:D44) -> 0
A25: 其中：工资薪金支出 | C25: ='纳税调整明细表N5-5'!G7 -> 0 | D25: =B25+C25 -> 0
A26: 职工福利费支出 | C26: ='纳税调整明细表N5-5'!G14 -> 0 | D26: =B26+C26 -> 0
A27: 职工教育经费支出 | C27: ='纳税调整明细表N5-5'!G20 -> 0 | D27: =B27+C27 -> 0
A28: 工会经费支出 | C28: ='纳税调整明细表N5-5'!G27 -> 0 | D28: =B28+C28 -> 0
A29: 业务招待费支出 | C29: ='纳税调整明细表N5-5'!G33 -> 0 | D29: =B29+C29 -> 0
A30: 广告费和业务宣传费支出 | C30: ='纳税调整明细表N5-5'!G38 -> 0 | D30: =B30+C30 -> 0
A31: 捐赠支出 | C31: ='纳税调整明细表N5-5'!G44 -> 0 | D31: =B31+C31 -> 0
A32: 罚金、罚款、税收滞纳金和被没收财物的损失 | C32: ='纳税调整明细表N5-5'!G50 -> 0 | D32: =B32+C32 -> 0
A33: 赞助支出 | C33: ='纳税调整明细表N5-5'!G55 -> 0 | D33: =B33+C33 -> 0
A34: 养老保险、医疗保险、住房公积金 | C34: ='纳税调整明细表N5-5'!G63 -> 0 | D34: =B34+C34 -> 0
A35: 与未实现融资收益相关在当期确认的财务费用 | C35: ='纳税调整明细表N5-5'!G72 -> 0 | D35: =B35+C35 -> 0
A36: 减值准备 | C36: ='纳税调整明细表N5-5'!G78 -> 0 | D36: =B36+C36 -> 0
A37: 折旧、摊销 | C37: ='纳税调整明细表N5-5'!G88+'纳税调整明细表N5-5'!G96 -> 0 | D37: =B37+C37 -> 0
A38: 与取得收入无关的支出 | D38: =B38+C38 -> 0
A39: 不征税收入用于支出所形成的费用 | D39: =B39+C39 -> 0
A40: 未经税务机关备案的财产损失 | D40: =B40+C40 -> 0
A41: 房地产企业当期预售收入计算的预计利润 | D41: =B41+C41 -> 0
...

Sheet 纳税调整明细表N5-5
A1: 致同会计师事务所
A2: 纳税调整明细表
A3: =底稿目录!A2 -> 被审计单位： | D3: =底稿目录!$A$4 -> 编制人： | F3: =底稿目录!$A$5 -> 编制日期： | G3: 索引号： | H3: N5-5
A4: =底稿目录!A3 -> 会计期间：202X年度 | D4: =底稿目录!$A$6 -> 复核人: | F4: =底稿目录!$A$7 -> 复核日期: | G4: 页次：
A5: 一、工资薪金支出
B6: 项目 | E6: 本期计提 | F6: 实际支付 | G6: 调增数 | H6: 备注
B7: 工资薪金支出 | G7: =E7-F7 -> 0
B8: 工资薪金：
B9: 1.企业发生的合理的工资薪金支出，准予扣除。
B10: 2.工资薪金，是指企业每一纳税年度支付给在本企业任职或者受雇的员工的所有现金形式或者非现金形式的劳动报酬，包括基本工资、奖金、津贴、补贴、年终加薪、加班工资，以及与员工任职或者受雇有关的其他支出。也包括企业因雇用季节工、临时工、实习生、返聘离退休人员以及接受外部劳务派遣用工所实际发生的工资薪金性支出。
B11: 3.可税前列支额，通常为：当期实际支付额-本期支付但上期已税前扣除的金额+次年汇算清缴之前已实际支付的本期工资薪金。也可能为：当期按收付实现制原则实际发生的金额。
A12: 二、职工福利费支出
B13: 项目 | C13: 工资薪金总额 | D13: 税前列支标准 | E13: 实际发生 | F13: 可税前列支 | G13: 调增数 | H13: 备注
B14: 职工福利费支出 | C14: =F7 -> 0 | D14: 0.14 | F14: =ROUND(C14*D14,2) -> 0 | G14: =IF(E14>F14,E14-F14,0) -> 0
B15: 职工福利费：
B16: 1.企业发生的职工福利费支出，不超过工资薪金总额14%的部分，准予扣除。
B17: 2.职工福利费支出也包括企业因雇用季节工、临时工、实习生、返聘离退休人员以及接受外部劳务派遣用工所实际发生的福利性性支出。
A18: 三、职工教育经费支出
B19: 项目 | C19: 工资薪金总额 | D19: 税前列支标准 | E19: 实际发生 | F19: 可税前列支 | G19: 调增数 | H19: 备注
B20: 职工教育经费支出 | C20: =E7 -> 0 | D20: 0.025 | F20: =ROUND(C20*D20,2) -> 0 | G20: =IF(E20>F20,E20-F20,0) -> 0
B21: 职工教育经费：
B22: 1.企业发生的职工教育经费支出，不超过工资薪金总额2.5%的部分，准予扣除；超过部分，准予在以后纳税年度结转扣除。
B23: 2.服务外包示范城市的技术先进型服务企业发生的职工教育经费支出，不超过工资薪金总额8%的部分，准予在计算应纳税所得额时扣除；超过部分，准予在以后纳税年度结转扣除。
B24: 3.软件生产企业发生的职工教育经费中的职工培训费用，可以全额在企业所得税前扣除。
A25: 四、工会经费支出
B26: 项目 | C26: 工资薪金总额 | D26: 税前列支标准 | E26: 实际发生 | F26: 可税前列支 | G26: 调增数 | H26: 备注
B27: 工会经费支出 | C27: =E7 -> 0 | D27: 0.02 | F27: =ROUND(C27*D27,2) -> 0 | G27: =IF(E27>F27,E27-F27,0) -> 0
B28: 工会经费：
B29: 企业拨缴的工会经费，不超过工资薪金总额2%的部分，准予扣除。须取得《工会经费收入专用收据》或者税务机关代收
B30: 工会经费的合法有效凭证，否则不能扣除。
A31: 五、业务招待费支出
B32: 项目 | C32: 营业收入 | D32: 税前列支标准 | E32: 实际发生 | F32: 可税前列支 | G32: 调增数 | H32: 备注
B33: 业务招待费支出 | D33: 0.005 | F33: =MIN(E33*60%,ROUND(C33*D33,2)) -> 0 | G33: =E33-F33 -> 0
B34: 业务招待费：
B35: 企业发生的与生产经营活动有关的业务招待费支出，按照发生额的60%扣除，但最高不得超过当年销售（营业）收入的5‰。
A36: 六、广告费和业务宣传费支出
B37: 项目 | C37: 营业收入 | D37: 税前列支标准 | E37: 实际发生 | F37: 可税前列支 | G37: 调增数 | H37: 备注
B38: 广告费和业务宣传费支出 | C38: =C33 -> 0 | D38: 0.15 | F38: =MIN(E38,ROUND(C38*D38,2)) -> 0 | G38: =E38-F38 -> 0
B39: 广告费和业务宣传费：
B40: 1.企业发生的符合条件的广告费和业务宣传费支出，除国务院财政、税务主管部门另有规定外，不超过当年销售（营业）收入15%的部分，准予扣除；超过部分，准予在以后纳税年度结转扣除。
...

Sheet 税收优惠明细表N5-6
A1: 致同会计师事务所
A2: 税收优惠明细表
A3: =底稿目录!A2 -> 被审计单位： | C3: =底稿目录!$A$4 -> 编制人： | D3: =底稿目录!$A$5 -> 编制日期： | E3: 索引号： | F3: N5-6
A4: =底稿目录!A3 -> 会计期间：202X年度 | C4: =底稿目录!$A$6 -> 复核人: | D4: =底稿目录!$A$7 -> 复核日期: | E4: 页次：
A5: 行次 | B5: 项目 | E5: 企业填列数 | F5: 审计确认数(审定数）
A6: 1 | B6: 一、免税收入（2＋3＋4＋5） | E6: =E7+E8+E9+E10 -> 0 | F6: =F7+F8+F9+F10 -> 0
A7: 2 | B7: 1、国债利息收入
A8: 3 | B8: 2、符合条件的居民企业之间的股息、红利等权益性投资收益
A9: 4 | B9: 3、符合条件的非营利组织的收入
A10: 5 | B10: 4、其他
A11: 6 | B11: 二、减计收入（7＋8） | E11: =E12+E13 -> 0 | F11: =F12+F13 -> 0
A12: 7 | B12: 1、企业综合利用资源,生产符合国家产业政策规定的产品所取得的收入
A13: 8 | B13: 2、其他
A14: 9 | B14: 三、加计扣除额合计（10＋11＋12＋13） | E14: =E15+E16+E17+E18 -> 0 | F14: =F15+F16+F17+F18 -> 0
A15: 10 | B15: 1、开发新技术、新产品、新工艺发生的研究开发费用
A16: 11 | B16: 2、安置残疾人员所支付的工资
A17: 12 | B17: 3、国家鼓励安置的其他就业人员支付的工资
A18: 13 | B18: 4、其他
A19: 14 | B19: 四、减免所得额合计（15＋25＋29＋30＋31＋32） | E19: =E20+E30+E34+E35+E36+E37 -> 0 | F19: =F20+F30+F34+F35+F36+F37 -> 0
A20: 15 | B20: （一）免税所得（16＋17＋…＋24） | E20: =E21+E22+E23+E24+E25+E26+E27+E28+E29 -> 0 | F20: =F21+F22+F23+F24+F25+F26+F27+F28+F29 -> 0
A21: 16 | B21: 1、蔬菜、谷物、薯类、油料、豆类、棉花、麻类、糖料、水果、坚果的种植
A22: 17 | B22: 2、农作物新品种的选育
A23: 18 | B23: 3、中药材的种植
A24: 19 | B24: 4、林木的培育和种植
A25: 20 | B25: 5、牲畜、家禽的饲养
A26: 21 | B26: 6、林产品的采集
A27: 22 | B27: 7、灌溉、农产品初加工、兽医、农技推广、农机作业和维修等农、林、牧、渔服务业项目
A28: 23 | B28: 8、远洋捕捞
A29: 24 | B29: 9、其他
A30: 25 | B30: （二）减税所得（26＋27＋28） | E30: =E31+E32+E33 -> 0 | F30: =F31+F32+F33 -> 0
A31: 26 | B31: 1、花卉、茶以及其他饮料作物和香料作物的种植
A32: 27 | B32: 2、海水养殖、内陆养殖
A33: 28 | B33: 3、其他
A34: 29 | B34: （三）从事国家重点扶持的公共基础设施项目投资经营的所得
A35: 30 | B35: （四）从事符合条件的环境保护、节能节水项目的所得
A36: 31 | B36: （五）符合条件的技术转让所得
A37: 32 | B37: （六）其他
A38: 33 | B38: 五、减免税合计（34＋35＋36＋37＋38） | E38: =E39+E40+E41+E42+E43 -> 0 | F38: =F39+F40+F41+F42+F43 -> 0
A39: 34 | B39: （一）符合条件的小型微利企业
A40: 35 | B40: （二）国家需要重点扶持的高新技术企业
...

Sheet 加计扣除研发费用情况明细表N5-6-1
A1: 致同会计师事务所
A2: 加计扣除研究开发费用情况明细表
A3: =底稿目录!A2 -> 被审计单位： | C3: =底稿目录!$A$4 -> 编制人： | D3: =底稿目录!$A$5 -> 编制日期： | E3: 索引号： | F3: N5-6-1
A4: =底稿目录!A3 -> 会计期间：202X年度 | C4: =底稿目录!$A$6 -> 复核人: | D4: =底稿目录!$A$7 -> 复核日期: | E4: 页次：
A5: 序号 | B5: 项 目 | C5: 未审金额 | D5: 审计调整额 | E5: 审计确认额 | F5: 备注
A6: 1 | B6: 一、研发活动直接消耗的材料、燃料和动力费用 | C6: =SUM(C7:C10) -> 0 | D6: =SUM(D7:D10) -> 0 | E6: =C6+D6 -> 0
A7: 2 | B7: 1.材料 | E7: =C7+D7 -> 0
A8: 3 | B8: 2.燃料 | E8: =C8+D8 -> 0
A9: 4 | B9: 3.动力费用 | E9: =C9+D9 -> 0
A10: 5 | E10: =C10+D10 -> 0
A11: 6 | B11: 二、直接从事研发活动的本企业在职人员费用 | C11: =SUM(C12:C16) -> 0 | D11: =SUM(D5:N16) -> 0 | E11: =C11+D11 -> 0
A12: 7 | B12: 1.工资、薪金 | E12: =C12+N5 -> 0
A13: 8 | B13: 2.津贴、补贴 | E13: =C13+D13 -> 0
A14: 9 | B14: 3.奖金 | E14: =C14+D14 -> 0
A15: 10 | E15: =C15+D15 -> 0
A16: 11 | E16: =C16+D16 -> 0
A17: 12 | B17: 三、专门用于研发活动的有关折旧费（按规定一次或分次摊入管理费的仪器和设备除外） | C17: =SUM(C18:C20) -> 0 | D17: =SUM(D18:D20) -> 0 | E17: =C17+D17 -> 0
A18: 13 | B18: 1.仪器 | E18: =C18+D18 -> 0
A19: 14 | B19: 2.设备 | E19: =C19+D19 -> 0
A20: 15 | E20: =C20+D20 -> 0
A21: 16 | B21: 四、专门用于研发活动的有关租赁费 | C21: =SUM(C22:C24) -> 0 | D21: =SUM(D22:D24) -> 0 | E21: =C21+D21 -> 0
A22: 17 | B22: 1.仪器 | E22: =C22+D22 -> 0
A23: 18 | B23: 2.设备 | E23: =C23+D23 -> 0
A24: 19 | E24: =C24+D24 -> 0
A25: 20 | B25: 五、专门用于研发活动的有关无形资产摊销费 | C25: =SUM(C26:C29) -> 0 | D25: =SUM(D26:D29) -> 0 | E25: =C25+D25 -> 0
A26: 21 | B26: 1.软件 | E26: =C26+D26 -> 0
A27: 22 | B27: 2.专利权 | E27: =C27+D27 -> 0
A28: 23 | B28: 3.非专利技术 | E28: =C28+D28 -> 0
A29: 24 | E29: =C29+D29 -> 0
A30: 25 | B30: 六、专门用于中间试验和产品试制的模具、工艺装备开发及制造费 | E30: =C30+D30 -> 0
A31: 26 | E31: =C31+D31 -> 0
A32: 27 | B32: 七、研发成果论证、鉴定、评审、验收费用 | E32: =C32+D32 -> 0
A33: 28 | E33: =C33+D33 -> 0
A34: 29 | B34: 八、与研发活动直接相关的其它费用 | C34: =SUM(C35:C39) -> 0 | D34: =SUM(D35:D39) -> 0 | E34: =C34+D34 -> 0
A35: 30 | B35: 1.新产品设计费 | E35: =C35+D35 -> 0
A36: 31 | B36: 2.新工艺规程制定费 | E36: =C36+D36 -> 0
A37: 32 | B37: 3.技术图书资料费 | E37: =C37+D37 -> 0
A38: 33 | B38: 4.资料翻译费 | E38: =C38+D38 -> 0
A39: 34 | E39: =C39+D39 -> 0
A40: 35 | B40: 合计 | C40: =C6+C11+C17+C21+C25+C30+C32+C34 -> 0 | D40: =D6+D11+D17+D21+D25+D30+D32+D34 -> 0 | E40: =C40+D40 -> 0
...

Sheet 高新技术企业认定条件检查表N5-6-2
A1: 致同会计师事务所
A2: 高新技术企业认定条件检查表
A3: =底稿目录!A2 -> 被审计单位： | E3: =底稿目录!$A$4 -> 编制人： | H3: =底稿目录!$A$5 -> 编制日期： | L3: 索引号： | M3: N5-6-2
A4: =底稿目录!A3 -> 会计期间：202X年度 | E4: =底稿目录!$A$6 -> 复核人: | H4: =底稿目录!$A$7 -> 复核日期: | L4: 页次：
A5: 检查内容 | F5: 检查过程及结果 | L5: 结论 | M5: 查验数据索引
A6: （一）主要产品（服务）的核心技术拥有自主知识产权
A7: （二）产品（服务）属于《国家重点支持的高新技术领域》规定的范围；
A8: （三）具有大学专科以上学历的科技人员占企业当年职工总数的30%以上，其中研发人员占企业当年职工总数的10%以上； | F8: 其中当年职工人数： | H8: 大专以上学历科技人员人数： | J8: 比例： | K8: =IF(G8=0,0,I8/G8) -> 0
H9: 研发人员人数： | J9: 比例： | K9: =IF(G8=0,0,I9/G8) -> 0
A10: （四）研究开发费用总额占销售收入总额的比例符合如下要求：
A11: 1. 最近一年销售收入小于5,000万元的企业，比例不低于6%； | F11: 本年审计调整后研发费用： | H11: 按税务机关要求的研发费用结构明细表填列金额，注意与所得税加计扣除的研发费用金额有区别）
A12: 2. 最近一年销售收入在5,000万元至20,000万元的企业，比例不低于4%； | F12: 本年审计调整后销售收入：
A13: 3. 最近一年销售收入在20,000万元以上的企业，比例不低于3%。 | F13: 比例： | G13: =IF(G12=0,0,G11/G12) -> 0
A14: 其中，企业在中国境内发生的研究开发费用总额占全部研究开发费用总额的比例不低于60%。
A15: （五）高新技术产品（服务）收入占企业当年总收入的60%以上； | F15: 本年高新技术产品收入： | H15: 本年总收入： | J15: 比例： | K15: =IF(I15=0,0,I15/G15) -> 0
A16: （六）企业研究开发组织管理水平、科技成果转化能力、自主知识产权数量、销售与总资产成长性等指标符合《高新技术企业认定管理工作指引》的要求。
A17: (七）索取向当地税务机关报送的减免税的备案资料
A18: (八）查阅税务师事务所出具的认定报告

Sheet 财产损失明细表N5-7
A1: 致同会计师事务所
A2: 财产损失明细表
A3: =底稿目录!A2 -> 被审计单位： | C3: =底稿目录!$A$4 -> 编制人： | D3: =底稿目录!$A$5 -> 编制日期： | E3: 索引号： | F3: N5-7
A4: =底稿目录!A3 -> 会计期间：202X年度 | C4: =底稿目录!$A$6 -> 复核人: | D4: =底稿目录!$A$7 -> 复核日期: | E4: 页次：
A5: 财产损失种类 | B5: 核算科目 | C5: 损失金额 | D5: 审批情况 | F5: 纳税调整金额
D6: 审批文号 | E6: 审批金额
F7: =C7-E7 -> 0
F8: =C8-E8 -> 0
F9: =C9-E9 -> 0
F10: =C10-E10 -> 0
F11: =C11-E11 -> 0
F12: =C12-E12 -> 0
F13: =C13-E13 -> 0
F14: =C14-E14 -> 0
A15: 合计 | C15: =SUM(C7:C14) -> 0 | E15: =SUM(E7:E14) -> 0 | F15: =SUM(F7:F14) -> 0

Sheet 递延所得税费用核对表N5-8
A1: 致同会计师事务所
A2: 递延所得税核对表
A3: =底稿目录!A2 -> 被审计单位： | C3: =底稿目录!$A$4 -> 编制人： | F3: =底稿目录!$A$5 -> 编制日期： | I3: 索引号： | J3: N5-8
A4: =底稿目录!A3 -> 会计期间：202X年度 | C4: =底稿目录!$A$6 -> 复核人: | F4: =底稿目录!$A$7 -> 复核日期: | I4: 页次：
A5: 一、审计目标
A6: 与所得税费用有关的金额及其他数据已恰当记录，相关披露已得到恰当计量和描述
A7: 二、审计过程
A8: 项目 | B8: 期末审计确认的递延所得税资产(计入所得税费用部分） | C8: 期初审计确认的递延所得税资产(计入所得税费用部分） | D8: 期末审计确认的递延所得税负债(计入所得税费用部分） | E8: 期初审计确认的递延所得税负债(计入所得税费用部分） | F8: 期末审计确认的其他综合收益(计入所得税费用部分） | G8: 期初审计确认的其他综合收益(计入所得税费用部分） | H8: 本期应计递延所得税费用 | I8: 本期已计递延所得税费用 | J8: 差异
B9: ① | C9: ② | D9: ③ | E9: ④ | F9: ⑤ | G9: ⑥ | H9: ⑦=②-①+③-④+⑥-⑤ | I9: ⑧ | J9: ⑨=⑦-⑧
A10: 交易性金融资产（公允价值与初始账面成本差异） | H10: =C10-B10+D10-E10-F10+G10 -> 0 | J10: =H10-I10 -> 0
A11: 应收账款（坏账准备） | H11: =C11-B11+D11-E11-F11+G11 -> 0 | J11: =H11-I11 -> 0
A12: 其他应收款（坏账准备） | H12: =C12-B12+N5-E12-F12+G12 -> 0 | J12: =H12-I12 -> 0
A13: 存货（跌价准备） | H13: =C13-B13+D13-E13-F13+G13 -> 0 | J13: =H13-I13 -> 0
A14: 合同资产（减值准备） | H14: =C14-B14+D14-E14-F14+G14 -> 0 | J14: =H14-I14 -> 0
A15: 债权投资（减值准备） | H15: =C15-B15+D15-E15-F15+G15 -> 0 | J15: =H15-I15 -> 0
A16: 应收款项融资（减值准备） | H16: =C16-B16+D16-E16-F16+G16 -> 0 | J16: =H16-I16 -> 0
A17: 其他债权投资（减值准备） | H17: =C17-B17+D17-E17-F17+G17 -> 0 | J17: =H17-I17 -> 0
A18: 长期股权投资（减值准备） | H18: =C18-B18+D18-E18-F18+G18 -> 0 | J18: =H18-I18 -> 0
A19: 投资性房地产（公允价值与账面差异） | H19: =C19-B19+D19-E19-F19+G19 -> 0 | J19: =H19-I19 -> 0
A20: 投资性房地产（折旧） | H20: =C20-B20+D20-E20-F20+G20 -> 0 | J20: =H20-I20 -> 0
A21: 固定资产（减值准备） | H21: =C21-B21+D21-E21-F21+G21 -> 0 | J21: =H21-I21 -> 0
A22: 固定资产折旧（年限、残值） | H22: =C22-B22+D22-E22-F22+G22 -> 0 | J22: =H22-I22 -> 0
A23: 使用权资产（减值准备） | H23: =C23-B23+D23-E23-F23+G23 -> 0
A24: 在建工程（减值准备） | H24: =C24-B24+D24-E24-F24+G24 -> 0 | J24: =H24-I24 -> 0
A25: 无形资产（减值准备、摊销） | H25: =C25-B25+D25-E25-F25+G25 -> 0 | J25: =H25-I25 -> 0
A26: 无形资产（研发费用资本化） | H26: =C26-B26+D26-E26-F26+G26 -> 0 | J26: =H26-I26 -> 0
A27: 开办费（摊销方法） | H27: =C27-B27+D27-E27-F27+G27 -> 0 | J27: =H27-I27 -> 0
A28: 交易性金融负债（公允价值与账面差异） | H28: =C28-B28+D28-E28-F28+G28 -> 0 | J28: =H28-I28 -> 0
A29: 应付职工薪酬（已计提未支付） | H29: =C29-B29+D29-E29-F29+G29 -> 0 | J29: =H29-I29 -> 0
A30: 应付职工薪酬（预计辞退福利费） | H30: =C30-B30+D30-E30-F30+G30 -> 0 | J30: =H30-I30 -> 0
A31: 预提费用 | H31: =C31-B31+D31-E31-F31+G31 -> 0 | J31: =H31-I31 -> 0
A32: 递延收益 | H32: =C32-B32+D32-E32-F32+G32 -> 0 | J32: =H32-I32 -> 0
A33: 预计负债（预计产品保修费用等） | H33: =C33-B33+D33-E33-F33+G33 -> 0 | J33: =H33-I33 -> 0
A34: 收入（预收款项） | H34: =C34-B34+D34-E34-F34+G34 -> 0 | J34: =H34-I34 -> 0
A35: 销售费用（广告费和业务宣传费） | H35: =C35-B35+D35-E35-F35+G35 -> 0 | J35: =H35-I35 -> 0
... A38: …… | H38: =C38-B38+D38-E38-F38+G38 -> 0 | J38: =H38-I38 -> 0
A39: 合计 | B39: =SUM(B10:B38) -> 0 | C39: =SUM(C10:C38) -> 0 | D39: =SUM(D10:D38) -> 0 | E39: =SUM(E10:E38) -> 0 | H39: =SUM(H10:H38) -> 0 | I39: =SUM(I10:I38) -> 0 | J39: =SUM(J10:J38) -> 0
A40: 三、审计说明：
A44: 四、审计结论：

Sheet GT_Custom
A1: C1 | B1: Custom 1
A2: C2 | B2: Custom 2
A3: C3 | B3: Custom 3
A4: C4 | B4: Custom 4
A5: C5 | B5: Custom 5
A6: C6 | B6: Custom 6
A7: C7 | B7: Custom 7
A8: C8 | B8: Custom 8
