Workbook

Sheet 底稿目录
A1: 底稿开列时，可先在以下单元格填写有关内容，以便其他底稿引用有关数据：
A2: 被审计单位： | D2: 序号 | E2: 内容 | F2: 索引号
A3: 截止日：202X年12月31日 | D3: 1 | E3: 其他权益工具实质性程序表 | F3: M10A
A4: 编制人： | D4: 2 | E4: 其他权益工具审定表 | F4: M10-1
A5: 编制日期： | D5: 3 | E5: 附注披露信息(上市公司) | G5: 无需打印
A6: 复核人： | D6: 4 | E6: 附注披露信息(国企) | G6: 无需打印
A7: 复核日期： | D7: 5 | E7: 其他权益工具明细表 | F7: M10-2
D8: 6 | E8: 调整分录汇总 | F8: M10-3
A9: 关于工作底稿与审计程序索引号对应的说明 | D9: 7 | E9: 负债与权益区分检查表 | F9: M10-4
A10: 1.编制的审计工作底稿应与审计程序对应。审计项目组应根据被审计单位实际情况和风险评估情况在实质性程序表中裁剪、修改或增加审计程序，根据实际执行的审计程序完成相应审计工作底稿，编制的工作底稿中应按自然顺序依次编制索引号，并通过唯一的索引号将与实质性程序表中的程序对应关联（即将工作底稿的索引号填入实质性程序表中的底稿索引号列）。 | D10: 8 | E10: 其他权益工具检查表 | F10: M10-5
A14: 2.获取的支持性证据应与审计底稿或程序对应。审计项目组在完成底稿时获取的支持性证据应根据底稿索引号编制下一级按自然顺序排序的索引号（如D1-2-1、D1-2-2、……），并在底稿中说明引用的支持性证据、关联索引号。
A17: 3.工作底稿索引号的编码规则：实质性程序索引号按循环从“D”到“N”,循环内账户以顺序号排列，模板中底稿索引号按账户顺序+自然数顺序（即模板中索引号按二级自然顺序排列，如D1-1、D1-2、D1-3、……D1-N）。

Sheet 其他权益工具实质性程序表 M10A
A1: 致同会计师事务所
A2: 其他权益工具实质性程序
A3: =底稿目录!A2 -> 被审计单位： | C3: =底稿目录!A4 -> 编制人： | E3: =底稿目录!A5 -> 编制日期： | H3: 索引号： | I3: M10A
A4: =底稿目录!A3 -> 截止日：202X年12月31日 | C4: =底稿目录!A6 -> 复核人： | E4: =底稿目录!A7 -> 复核日期： | H4: 页 次：
A5: 一、本账户涉及的科目
A6: 其他权益工具
A7: 二、审计目标与认定的对应关系
A8: 审计目标 | G8: 财务报表的认定
A9: A. 资产负债表中记录的其他综合收益是存在的，且已经记录在恰当的账户中 | G9: 存在
A10: B. 所有应记录的其他综合收益均已记录，所有应当包括在财务报表中的相关披露均已包括 | G10: 完整性
A11: C. 记录的其他综合收益由被审计单位拥有或控制 | G11: 权利和义务
A12: D. 其他综合收益以恰当的金额包括在财务报表中，与之相关的计价或分摊调整已恰当记录，相关披露已得到恰当计量和描述 | G12: 准确性、计价和分摊
A13: E. 其他综合收益已被恰当地汇总或分解且表述清楚，相关披露在按照企业会计准则的编制基础下是相关的、可理解的 | G13: 列报
A14: 三、计划实施的实质性程序
A15: 序号 | B15: 审计程序 | C15: 程序分类 | D15: 财务报表的认定 | I15: 底稿索引号
D16: 存在 | E16: 完整性 | F16: 权利和 义务 | G16: 准确性、计价和分摊 | H16: 列报 | J16: 根据被审计单位实际情况和风险评估情况裁剪、修改或增加审计程序
A17: 1 | B17: 获取或编制实收资本（股本）明细表，完成以下工作，并编制审定表 （1）复核加计是否正确，与总账、明细账合计数核对是否相符，期初余额与上期审定期末余额是否相符； （2）以非记账本位币出资的，检查其折算汇率是否符合规定，折算差额的会计处理是否正确。 | C17: 常规★ | D17: √ | E17: √ | G17: √ | I17: M10-1 /M10-2
A18: 2 | B18: 在使用手工编制、自定义信息报告、系统生成的非固定格式报告等由被审计单位生成的信息时，测试有关信息准确性和完整性，并考虑针对编制和维护由被审计单位生成的信息的相关控制实施控制测试，以评价该信息是否能够为实现审计目的提供基础。 | C18: 常规★ | E18: √ | G18: √ | I18: T1/ | J18: 可参见《审计手册》4.2.6，由被审计单位生成的信息可能是由系统生成的、或手工编制的、或二者兼而有之的方式生成的。例如，由被审计单位生成的信息可能包括： • 不涉及自定义的、由系统生成的报告（如，固定格式报告）； • 可能通过人工自定义的、由系统生成的报告，例如，（计算机）查询信息或特别定制的报告； • 手工编制的信息，例如，汇总信息的电子表格或用以支持分配、计算以及调节的电子表格； • 其他系统生成或手工编制的信息，例如，由被审计单位编制的客户发票； • 通过影印、拍摄、扫描或其他方式转换成电子形式的文件记录。
A19: 3 | B19: 对于上期其他权益工具的期末余额，取得发行该项工具的决议、协议、募集说明书等发行文件、审批文件等，检查与账面记录是否一致，检查上期其他权益工具在本期减少情况。（适用于首次承接） | C19: 备选 | D19: √ | E19: √ | F19: √ | G19: √ | I19: M10- | J19: 由被审计单位生成的信息不包括： • 总分类账或明细分类账、试算平衡表、或经审计的财务报表； • 第三方（除了服务机构）的报表或报告，例如，原始银行对账单，或函证的回函； • 外部数据（例如，第三方发布的数据，如，定价来源）。
A20: 4 | B20: 对本期增加的优先股、永续债等其他权益工具投资，获取公司章程、股东（大）会/董事会决议、协议、募集说明书等发行文件、政府主管部门批复等相关文件，检查重要条款，判断分类为其他权益工具投资是否恰当。 | C20: 常规★ | D20: √ | E20: √ | F20: √ | H20: √ | I20: M10-4
A21: 5 | B21: 检查股权协议，考虑是否有需要单独确认的嵌入式衍生工具。如果有，完成金融工具审计程序。 | C21: 备选 | D21: √ | E21: √
A22: 6 | B22: 检查可转换公司债券是否将负债和权益成份分拆，结合长期债券的审计，检查相关的法律文件，手续是否办理，检查入账金额和会计处理是否正确，其持有的债券转为股票时其会计处理是否正确。 （1）获取发行文件，检查对发行人的全部合同义务的约定条款； （2）根据或有结算条款和结算选择权、可回售工具或清算产生的义务等因素，判断被审计单位选取的会计分类是否符合企业会计准则的要求； （3）考虑是否需要对复合型金融产品各成分的拆分。 | C22: 备选 | D22: √ | E22: √ | F22: √ | G22: √
A23: 7 | B23: 检查与其他权益工具有关的的记账凭证和相应的支持性证据，入账金额是否正确、会计处理是否正确。 | C23: 常规★ | D23: √ | F23: √ | G23: √ | I23: M10-5
A24: 8 | B24: 检查其他权益工具是否已按企业会计准则或其他适用的规定在财务报表中做出恰当列报和披露。 | C24: 常规★ | H24: √ | I24: A1-1/A1-15 /A1-16

Sheet 其他权益工具实质性程序表 Q10A (修订前)
A1: 致同会计师事务所
A2: 其他权益工具实质性程序
A3: =底稿目录!A2 -> 被审计单位： | C3: =底稿目录!A4 -> 编制人： | F3: =底稿目录!A5 -> 编制日期： | I3: 索引号： | J3: Q10A
A4: =底稿目录!A3 -> 截止日：202X年12月31日 | C4: =底稿目录!A6 -> 复核人： | F4: =底稿目录!A7 -> 复核日期： | I4: 页 次：
A5: 一、本账户涉及的科目
A6: 其他权益工具
A7: 二、重大错报风险需从实质性程序获取的保证程度
A8: 审计目标与认定对应关系 | C8: 财务报表的认定 | H8: 信赖/不信赖/不适用 | I8: 索引号
C9: 存在 | D9: 完整性 | E9: 权利和义务 | F9: 计价和分摊 | G9: 列报与披露
A10: A. 资产负债表中记录的其他权益工具是存在的。 | C10: √
A11: B. 所有应记录的其他权益工具均已记录，其他权益工具的增减变动符合法律、法规和合同、章程的规定。 | D11: √
A12: C. 其他权益工具以恰当的金额包括在财务报表中。 | F12: √
A13: D. 其他权益工具已按照企业会计准则的规定在财务报表中作出恰当列报和披露。 | G13: √
A15: 三、计划实施的实质性程序
A16: 序号 | B16: 审计程序 | D16: 程序分类 | E16: 对应的认定/风险 | I16: 执行情况说明 （含底稿索引）
A17: （一） | B17: 编制审定表 | D17: 常规★ | E17: B | I17: Q10 | K17: 整合 | L17: 获取或编制实收资本（股本）明细表，完成以下工作，并编制审定表 （1）复核加计是否正确，与总账、明细账合计数核对是否相符，期初余额与上期审定期末余额是否相符； （2）以非记账本位币出资的，检查其折算汇率是否符合规定，折算差额的会计处理是否正确。
A18: （二） | B18: 获取或编制其他权益工具明细表，并完成以下工作： | D18: 常规★ | E18: C | I18: Q10-2 | K18: 整合
A19: 1 | B19: 复核加计正确 。 | D19: 常规★ | E19: C | K19: 整合
A20: 2 | B20: 将总金额与总账核对。 | D20: 常规★ | E20: C | K20: 整合
A21: 3 | B21: 确定计算的准确性。 | D21: 常规 | E21: C | K21: 整合
A22: 4 | B22: 将期初额与上年度工作底稿或前期财务报表核对。 | D22: 常规 | E22: C | K22: 整合
A23: 5 | B23: 将期末余额与总分类账核对一致。 | D23: 常规 | E23: C | K23: 整合
A24: 6 | B24: 以非记账本位币出资的，检查其折算汇率是否符合规定，折算差额的会计处理是否正确。 | D24: 常规★ | E24: C | K24: 整合
A25: （三） | B25: 在使用被审计单位生成的信息（IPE）时，应当评价该信息对实现审计目的是否足够可靠，包括根据具体情况在必要时实施下列程序： | D25: 常规★ | E25: B | I25: T1 | K25: 整合 | L25: 在使用手工编制、自定义信息报告、系统生成的非固定格式报告等由被审计单位生成的信息时，测试有关信息准确性和完整性，并考虑针对编制和维护由被审计单位生成的信息的相关控制实施控制测试，以评价该信息是否能够为实现审计目的提供基础。
A26: 1 | B26: 获取有关信息准确性和完整性的审计证据。 | K26: 整合
A27: 2 | B27: 评价信息对实现审计目的是否足够准确和详细。 | K27: 整合
A28: （四） | B28: 对于上期其他权益工具账户的期末余额（适用于首次承接时对期初余额的审计）： | D28: 备选 | E28: AB | I28: Q10-2 | K28: 修改 | L28: 对于上期其他权益工具的期末余额，取得发行该项工具的决议、协议、募集说明书等发行文件、审批文件等，检查与账面记录是否一致，检查上期其他权益工具在本期减少情况。（适用于首次承接）
A29: （五） | B29: 取得其他权益工具账户当期交易活动的明细表，检查增减变动的原因，对每一项增加或减少，关注有关交易的性质，检查法律性文件是否齐全，相关的手续是否办理，以及其会计处理是否正确： | D29: 常规★ | E29: AB | I29: Q10-2 | K29: 修改 | L29: 对本期增加的优先股、永续债等其他权益工具投资，获取公司章程、股东（大）会/董事会决议、协议、募集说明书等发行文件、政府主管部门批复等相关文件，检查重要条款，判断分类为其他权益工具投资是否恰当。
A30: 1 | B30: 对于每一增减变动，确定交易的是否恰当，会计处理是否正确。 | D30: 常规★ | E30: AB | K30: 修改
A31: 2 | B31: 通过查阅上述会议记录，确定每笔交易是否都已通过授权。 | D31: 常规 | E31: AB | K31: 修改
A32: 3 | B32: 审阅公司章程、股东（大）会、董事会会议记录中相关规定。收集与所有者权益账户变动有关的董股东（大）会决议、事会会议纪要、合同、协议、公司章程及营业执照，公司设立批文、验资报告以及政府主管部门、财政部门批复、资产评估报告等文件资料，并更新永久性档案。 | D32: 常规★ | E32: AB | K32: 修改
A33: 4 | B33: 获取所有者权益账户结转明细，并确认入账是否恰当。 | D33: 常规 | E33: AB | K33: 修改
A34: 5 | B34: 检查股权协议，考虑是否有需要单独确认的嵌入式衍生工具。如果有，完成金融工具审计程序。 | D34: 备选 | E34: AB | K34: 删除
A35: （1） | B35: 检查股票回购的交易活动。检查的内容包括已发行股票的登记簿、回购的股票、银行对账单、会计账面记录等； | D35: 备选 | E35: AB | K35: 删除
A36: （2） | B36: 以回购股票以及其他法定程序报经批准减资的，检查股东会决议以及相关的法律文件，手续是否办理，检查其是否按注销的股票面值总额和所注销的库存股的账面余额，冲减资本公积，会计处理是否正确； | D36: 备选 | E36: AB | K36: 删除
A37: 6 | B37: 对可转换公司债券持有人行使转换权利转为股本和形成的股本溢价，结合长期债券的审计，检查相关的法律文件，手续是否办理，检查入账金额和会计处理是否正确； | D37: 备选 | E37: AB | K37: 整合
A38: （六） | B38: 检查可转换公司债券是否将负债和权益成份分拆，可转换公司债券持有人行使转换权利，将其持有的债券转为股票时其会计处理是否正确。 | D38: 常规 | E38: E | K38: 整合 | L38: 检查可转换公司债券是否将负债和权益成份分拆，结合长期债券的审计，检查相关的法律文件，手续是否办理，检查入账金额和会计处理是否正确，其持有的债券转为股票时其会计处理是否正确。 （1）获取发行文件，检查对发行人的全部合同义务的约定条款； （2）根据或有结算条款和结算选择权、可回售工具或清算产生的义务等因素，判断被审计单位选取的会计分类是否符合企业会计准则的要求； （3）考虑是否需要对复合型金融产品各成分的拆分。
A39: 1 | B39: 获取发行文件，梳理对发行人的全部合同义务的约定条款。 | D39: 常规 | E39: BE | K39: 整合
A40: 2 | B40: 根据或有结算条款和结算选择权、可回售工具或清算产生的义务等因素，判断被审计单位选取的会计分类是否符合企业会计准则的要求。 | D40: 常规 | E40: BE | K40: 整合
A41: 3 | B41: 考虑是否需要对复合型金融产品各成分的拆分。 | D41: 常规 | E41: BE | K41: 整合
...

Sheet 审定表M10-1
A1: 致同会计师事务所
A2: 其他权益工具审定表
A3: =底稿目录!A2 -> 被审计单位： | E3: =底稿目录!A4 -> 编制人： | H3: =底稿目录!A5 -> 编制日期： | K3: 索引号： | L3: =底稿目录!F4 -> M10-1
A4: =底稿目录!A3 -> 截止日：202X年12月31日 | E4: =底稿目录!A6 -> 复核人： | H4: =底稿目录!A7 -> 复核日期： | K4: 页 次：
A5: 项目 | B5: 期初数 | F5: 期末数 | J5: 本期与上期审定数比较 | L5: 原因分析
B6: 未审数 | C6: 账项调整 | D6: 重分类调整 | E6: 审定数 | F6: 未审数 | G6: 账项调整 | H6: 重分类调整 | I6: 审定数 | J6: 变动额 | K6: 变动率
A7: 一、优先股
E8: =B8+C8+D8 -> 0 | I8: =F8+G8+H8 -> 0 | J8: =I8-E8 -> 0 | K8: =IF(AND(E8=0,I8=0),"",IF(AND(E8=0,I8>0),1,J8/E8))
E9: =B9+C9+D9 -> 0 | I9: =F9+G9+H9 -> 0 | J9: =I9-E9 -> 0 | K9: =IF(AND(E9=0,I9=0),"",IF(AND(E9=0,I9>0),1,J9/E9))
E10: =B10+C10+D10 -> 0 | I10: =F10+G10+H10 -> 0 | J10: =I10-E10 -> 0 | K10: =IF(AND(E10=0,I10=0),"",IF(AND(E10=0,I10>0),1,J10/E10))
A11: 小计 | B11: =SUM(B8:B10) -> 0 | C11: =SUM(C8:C10) -> 0 | D11: =SUM(D8:D10) -> 0 | E11: =SUM(E8:E10) -> 0 | F11: =SUM(F8:F10) -> 0 | G11: =SUM(G8:G10) -> 0 | H11: =SUM(H8:H10) -> 0 | I11: =SUM(I8:I10) -> 0 | J11: =I11-E11 -> 0 | K11: =IF(AND(E11=0,I11=0),"",IF(AND(E11=0,I11>0),1,J11/E11))
A12: 二、永续债(含永续中票、无固定期限委托贷款等）
E13: =B13+C13+D13 -> 0 | I13: =F13+G13+H13 -> 0 | J13: =I13-E13 -> 0 | K13: =IF(AND(E13=0,I13=0),"",IF(AND(E13=0,I13>0),1,J13/E13))
E14: =B14+C14+D14 -> 0 | I14: =F14+G14+H14 -> 0 | J14: =I14-E14 -> 0 | K14: =IF(AND(E14=0,I14=0),"",IF(AND(E14=0,I14>0),1,J14/E14))
E15: =B15+C15+D15 -> 0 | I15: =F15+G15+H15 -> 0 | J15: =I15-E15 -> 0 | K15: =IF(AND(E15=0,I15=0),"",IF(AND(E15=0,I15>0),1,J15/E15))
A16: 小计 | B16: =SUM(B13:B15) -> 0 | C16: =SUM(C13:C15) -> 0 | D16: =SUM(D13:D15) -> 0 | E16: =SUM(E13:E15) -> 0 | F16: =SUM(F13:F15) -> 0 | G16: =SUM(G13:G15) -> 0 | H16: =SUM(H13:H15) -> 0 | I16: =SUM(I13:I15) -> 0 | J16: =I16-E16 -> 0 | K16: =IF(AND(E16=0,I16=0),"",IF(AND(E16=0,I16>0),1,J16/E16))
A17: 三、转股特征(如可转债权益成分）
E18: =B18+C18+D18 -> 0 | I18: =F18+G18+H18 -> 0 | J18: =I18-E18 -> 0 | K18: =IF(AND(E18=0,I18=0),"",IF(AND(E18=0,I18>0),1,J18/E18))
E19: =B19+C19+D19 -> 0 | I19: =F19+G19+H19 -> 0 | J19: =I19-E19 -> 0 | K19: =IF(AND(E19=0,I19=0),"",IF(AND(E19=0,I19>0),1,J19/E19))
E20: =B20+C20+D20 -> 0 | I20: =F20+G20+H20 -> 0 | J20: =I20-E20 -> 0 | K20: =IF(AND(E20=0,I20=0),"",IF(AND(E20=0,I20>0),1,J20/E20))
A21: 小计 | B21: =SUM(B18:B20) -> 0 | C21: =SUM(C18:C20) -> 0 | D21: =SUM(D18:D20) -> 0 | E21: =SUM(E18:E20) -> 0 | F21: =SUM(F18:F20) -> 0 | G21: =SUM(G18:G20) -> 0 | H21: =SUM(H18:H20) -> 0 | I21: =SUM(I18:I20) -> 0 | J21: =I21-E21 -> 0 | K21: =IF(AND(E21=0,I21=0),"",IF(AND(E21=0,I21>0),1,J21/E21))
A22: 其他权益工具合计 | B22: =SUM(B11,B16,B21) -> 0 | C22: =SUM(C11,C16,C21) -> 0 | D22: =SUM(D11,D16,D21) -> 0 | E22: =SUM(E11,E16,E21) -> 0 | F22: =SUM(F11,F16,F21) -> 0 | G22: =SUM(G11,G16,G21) -> 0 | H22: =SUM(H11,H16,H21) -> 0 | I22: =SUM(I11,I16,I21) -> 0 | J22: =I22-E22 -> 0 | K22: =IF(AND(E22=0,I22=0),"",IF(AND(E22=0,I22>0),1,J22/E22))
A23: 试算平衡表数
A24: 差异数 | E24: =E22-E23 -> 0 | I24: =I22-I23 -> 0
A25: 1、审计说明
A26: （1）其他权益工具本期较上期增加（负数为减少）： | E26: =IF(AND(E22=0,I22=0),0,IF(AND(E22=0,I22>0),1,(I22-E22)/E22)) -> 0
A27: 主要原因（比例超过30%的）：
A29: （2）情况说明
A31: 2、审计结论
A34: 提示：
A35: 1.权益工具，是指能证明拥有某个企业在扣除所有负债后的资产中的剩余权益的合同。，“其他权益工具”核算企业发行的除普通股以外的归类为权益工具的各种金融工具；
A36: 2.分类为其他权益工具的金融工具，在存续期间分派股利（含分类为权益工具的工具所产生的“利息”）的，作为利润分配处理。
A37: 3.发行复合金融工具发生的交易费用，应当在负债成分和权益成分之间按照各自占总发行价款的比例进行分摊。
A38: 4.考虑融资工具是否在合并报表层面进行了适当的会计处理。

Sheet 附注披露信息核对（上市公司）
A1: 致同会计师事务所
A2: 其他权益工具附注披露信息
A3: =底稿目录!A2 -> 被审计单位： | D3: =底稿目录!A4 -> 编制人： | G3: =底稿目录!A5 -> 编制日期： | I3: 索引号：
A4: =底稿目录!A3 -> 截止日：202X年12月31日 | D4: =底稿目录!A6 -> 复核人： | G4: =底稿目录!A7 -> 复核日期： | I4: 页次：
A5: 附注披露信息（上市公司）
A6: 发行在外的金融工具 | B6: 发行时间 | C6: 会计分类 | D6: 股利率或利息率 | E6: 发行价格 | F6: 数量 | G6: 金额 | H6: 到期日或续期情况 | I6: 转股条件 | J6: 转换情况
A12: 可无限加行
A13: 合计 | G13: =SUM(G7:G12) -> 0
A14: 【提示：
A15: 1、“会计分类”栏应填写“金融负债”、“权益工具”或“复合金融工具”等，对于整体指定以公允价值计量且其变动计入当期损益的金融负债，在“会计分类”栏中只需注明“整体指定”即可。
A16: 2、“转股条件”栏应当披露合同中是否包含强制转股、自愿转股等条款。
A17: 3、“金额”栏以发行价格乘以发行数量填列。】
A18: （披露以下信息：
A19: ①工具1的主要条款说明以及股利的设定机制
A20: 【包括本金是否可赎回，企业是否有权自主决定股利或利息支付政策，是否可转换为普通股以及发行合同关于转股价格或数量的约定等其他影响该类工具会计分类的重要特征。】
A21: 【提示：如果发行方发行的分类为权益工具的金融工具为累积的，即发行方当期未分配的股利或利息可累积至以后期间分配的，应当在财务报表附注中披露累积未分配的股利；如果发行方发行的其他权益工具为可参与剩余利润分配的，即可与普通股股东一起参加剩余利润分配的，应当披露可参与分配的事实及分配的方法等信息。】
A22: ②工具2的主要条款说明以及利息的设定机制：
A23: ……
A24: 【如果企业受特定监管规则约束，还需披露该金融工具是否被相关监管部门认定为合格的监管资本以及对本企业监管资本水平的影响。】
A25: 期末发行在外的优先股、永续债等其他金融工具变动情况表：
A26: 发行在外的金融工具 | B26: 期初余额 | D26: 本期增加 | F26: 本期减少 | H26: 期末余额
B27: 数量 | C27: 账面价值 | D27: 数量 | E27: 账面价值 | F27: 数量 | G27: 账面价值 | H27: 数量 | I27: 账面价值
A34: 合 计 | B34: =SUM(B28:B33) -> 0 | C34: =SUM(C28:C33) -> 0 | D34: =SUM(D28:D33) -> 0 | E34: =SUM(E28:E33) -> 0 | F34: =SUM(F28:F33) -> 0 | G34: =SUM(G28:G33) -> 0 | H34: =SUM(H28:H33) -> 0 | I34: =SUM(I28:I33) -> 0
A35: 说明：其他权益工具的本期增减变动情况、变动原因，以及相关会计处理依据。
A36: 权益工具持有者的相关信息【根据《企业会计准则第37号——金融工具列报》的要求披露】
A37: 项 目 | B37: 期末余额/本期发生额 | C37: 上年年末余额/上期发生额
A38: 1.归属于母公司所有者的权益（股东权益）
A39: （1）归属于母公司普通股持有者的权益
A40: （2）归属于母公司其他权益持有者的权益
A41: 其中：净利润
A42: 综合收益总额
A43: 当期已分配股利
A44: 累积未分配股利
A45: 2.归属于少数股东的权益
A46: （1）归属于普通股少数股东的权益
A47: （2）归属于少数股东其他权益工具持有者的权益

Sheet 附注披露信息核对（国企）
A1: 致同会计师事务所
A2: 其他权益工具附注披露信息
A3: =底稿目录!A2 -> 被审计单位： | D3: =底稿目录!A4 -> 编制人： | G3: =底稿目录!A5 -> 编制日期： | J3: 索引号：
A4: =底稿目录!A3 -> 截止日：202X年12月31日 | D4: =底稿目录!A6 -> 复核人： | G4: =底稿目录!A7 -> 复核日期： | J4: 页次：
A5: 附注披露信息（国企）
A6: 发行在外的金融工具 | B6: 期初 | D6: 本期增加 | F6: 本期减少 | H6: 期末
B7: 数量 | C7: 账面价值 | D7: 数量 | E7: 账面价值 | F7: 数量 | G7: 账面价值 | H7: 数量 | I7: 账面价值
A11: 合 计 | B11: =SUM(B8:B10) -> 0 | C11: =SUM(C8:C10) -> 0 | D11: =SUM(D8:D10) -> 0 | E11: =SUM(E8:E10) -> 0 | F11: =SUM(F8:F10) -> 0 | G11: =SUM(G8:G10) -> 0 | H11: =SUM(H8:H10) -> 0 | I11: =SUM(I8:I10) -> 0
A12: 注：企业应详细说明期末发行在外的优先股、永续债等其他金融工具基本情况。

Sheet 明细表M10-2
A1: 致同会计师事务所
A2: 其他权益工具明细表
A3: =底稿目录!A2 -> 被审计单位： | G3: =底稿目录!A4 -> 编制人： | N3: =底稿目录!A5 -> 编制日期： | AC3: 索引号： | AD3: =底稿目录!F7 -> M10-2
A4: =底稿目录!A3 -> 截止日：202X年12月31日 | G4: =底稿目录!A6 -> 复核人： | N4: =底稿目录!A7 -> 复核日期： | AC4: 页 次：
A5: 一、审计目标
A6: 1.资产负债表中记录的其他综合收益是存在的，且已经记录在恰当的账户中。 | I6: 2.所有应记录的其他综合收益均已记录，所有应当包括在财务报表中的相关披露均已包括。
A7: 3.其他综合收益以恰当的金额包括在财务报表中，与之相关的计价或分摊调整已恰当记录，相关披露已得到恰当计量和描述。
A8: 二、审计过程
A9: 融资工具种类 | B9: 发行时间 | C9: 股利率或利息率 | D9: 发行价格 | E9: 数量 | F9: 到期日或续期情况 | G9: 会计分类 | H9: 发行总额（面值） | I9: 期初账面价值 | K9: 本期发行 | O9: 本期减少 | S9: 期末账面价值 | U9: 审计调整（增加） | W9: 审计调整（减少） | Y9: 审计调整后期末账面价值 | AA9: 转股条件 | AB9: 转换情况 | AC9: 备注 | AD9: 文件索引号
I10: 数量 | J10: 金额 | K10: 数量 | L10: 金额 | M10: 交易费用 | N10: 账面价值 | O10: 数量 | P10: 金额 | Q10: 其他变动 | R10: 小计 | S10: 数量 | T10: 金额 | U10: 数量 | V10: 金额 | W10: 数量 | X10: 金额 | Y10: 数量 | Z10: 金额
A11: 一、优先股
N12: =L12-M12 -> 0 | R12: =SUM(P12:Q12) -> 0 | S12: =I12+K12-O12 -> 0 | T12: =J12+N12-R12 -> 0 | Y12: =S12+U12-W12 -> 0 | Z12: =T12+V12-X12 -> 0
N13: =L13-M13 -> 0 | R13: =SUM(P13:Q13) -> 0 | S13: =I13+K13-O13 -> 0 | T13: =J13+N13-R13 -> 0 | Y13: =S13+U13-W13 -> 0 | Z13: =T13+V13-X13 -> 0
N14: =L14-M14 -> 0 | R14: =SUM(P14:Q14) -> 0 | S14: =I14+K14-O14 -> 0 | T14: =J14+N14-R14 -> 0 | Y14: =S14+U14-W14 -> 0 | Z14: =T14+V14-X14 -> 0
A15: 小计 | H15: =SUM(H12:H14) -> 0 | J15: =SUM(J12:J14) -> 0 | K15: =SUM(K12:K14) -> 0 | M15: =SUM(M12:M14) -> 0 | N15: =SUM(N12:N14) -> 0 | O15: =SUM(O12:O14) -> 0 | Q15: =SUM(Q12:Q14) -> 0 | R15: =SUM(R12:R14) -> 0 | S15: =SUM(S12:S14) -> 0 | T15: =SUM(T12:T14) -> 0 | U15: =U14+U13+U12 -> 0 | V15: =V14+V13+V12 -> 0 | W15: =W14+W13+W12 -> 0 | X15: =X14+X13+X12 -> 0 | Y15: =SUM(Y12:Y14) -> 0 | Z15: =SUM(Z12:Z14) -> 0
A16: 二、永续债(含永续中票、无固定期限委托贷款等）
N17: =L17-M17 -> 0 | R17: =SUM(P17:Q17) -> 0 | S17: =I17+K17-O17 -> 0 | T17: =J17+N17-R17 -> 0 | Y17: =S17+U17-W17 -> 0 | Z17: =T17+V17-X17 -> 0
N18: =L18-M18 -> 0 | R18: =SUM(P18:Q18) -> 0 | S18: =I18+K18-O18 -> 0 | T18: =J18+N18-R18 -> 0 | Y18: =S18+U18-W18 -> 0 | Z18: =T18+V18-X18 -> 0
N19: =L19-M19 -> 0 | R19: =SUM(P19:Q19) -> 0 | S19: =I19+K19-O19 -> 0 | T19: =J19+N19-R19 -> 0 | Y19: =S19+U19-W19 -> 0 | Z19: =T19+V19-X19 -> 0
A20: 小计 | H20: =SUM(H17:H19) -> 0 | J20: =SUM(J17:J19) -> 0 | K20: =SUM(K17:K19) -> 0 | M20: =SUM(M17:M19) -> 0 | N20: =SUM(N17:N19) -> 0 | O20: =SUM(O17:O19) -> 0 | Q20: =SUM(Q17:Q19) -> 0 | R20: =SUM(R17:R19) -> 0 | S20: =SUM(S17:S19) -> 0 | T20: =SUM(T17:T19) -> 0 | U20: =U19+U18+U17 -> 0 | V20: =V19+V18+V17 -> 0 | W20: =W19+W18+W17 -> 0 | X20: =X19+X18+X17 -> 0 | Y20: =SUM(Y17:Y19) -> 0 | Z20: =SUM(Z17:Z19) -> 0
A21: 三、转股特征(如可转债权益成分）
N22: =L22-M22 -> 0 | R22: =SUM(P22:Q22) -> 0 | S22: =I22+K22-O22 -> 0 | T22: =J22+N22-R22 -> 0 | Y22: =S22+U22-W22 -> 0 | Z22: =T22+V22-X22 -> 0
N23: =L23-M23 -> 0 | R23: =SUM(P23:Q23) -> 0 | S23: =I23+K23-O23 -> 0 | T23: =J23+N23-R23 -> 0 | Y23: =S23+U23-W23 -> 0 | Z23: =T23+V23-X23 -> 0
N24: =L24-M24 -> 0 | R24: =SUM(P24:Q24) -> 0 | S24: =I24+K24-O24 -> 0 | T24: =J24+N24-R24 -> 0 | Y24: =S24+U24-W24 -> 0 | Z24: =T24+V24-X24 -> 0
A25: 小计 | H25: =SUM(H22:H24) -> 0 | J25: =SUM(J22:J24) -> 0 | K25: =SUM(K22:K24) -> 0 | M25: =SUM(M22:M24) -> 0 | N25: =SUM(N22:N24) -> 0 | O25: =SUM(O22:O24) -> 0 | Q25: =SUM(Q22:Q24) -> 0 | R25: =SUM(R22:R24) -> 0 | S25: =SUM(S22:S24) -> 0 | T25: =SUM(T22:T24 ) -> 0 | U25: =U24+U23+U22 -> 0 | V25: =V24+V23+V22 -> 0 | W25: =W24+W23+W22 -> 0 | X25: =X24+X23+X22 -> 0 | Y25: =S25+U25-W25 -> 0 | Z25: =T25+V25-X25 -> 0
A26: 合计 | H26: =SUM(H15,H20) -> 0 | J26: =SUM(J15,J20) -> 0 | K26: =SUM(K15,K20) -> 0 | M26: =SUM(M15,M20) -> 0 | N26: =SUM(N15,N20) -> 0 | O26: =SUM(O15,O20) -> 0 | Q26: =SUM(Q15,Q20) -> 0 | R26: =SUM(R15,R20) -> 0 | S26: =SUM(S15,S20) -> 0 | T26: =SUM(T15,T20) -> 0 | U26: =U25+U20+U15 -> 0 | V26: =V25+V20+V15 -> 0 | W26: =W25+W20+W15 -> 0 | X26: =X25+X20+X15 -> 0 | Y26: =S26+U26-W26 -> 0 | Z26: =T26+V26-X26 -> 0
A28: 三、审计说明：
A32: 四、审计结论：
A35: 提示：
A36: 1.权益工具，是指能证明拥有某个企业在扣除所有负债后的资产中的剩余权益的合同。
A37: 如果企业不能无条件地避免以交付现金或其他金融资产来履行一项合同义务，则该合同义务符合金融负债的定义。
A38: 如果企业能够无条件地避免交付现金或其他金融资产，例如能够根据相应的议事机制自主决定是否支付股息（即无支付股息的义务），同时所发行的金融工具没有到期日且合同对手没有回售权，
A39: 或虽有固定期限但发行方有权无限期递延（即无支付本金的义务），则此类交付现金或其他金融资产的结算条款不构成金融负债。
A40: 2.审计说明可以概述：（1）程序的测试情况、结果；（2）拟调整事项及其调整分录、未调整事项及其影响，审计范围受到限制情况及其影响。
A41: 3.审计结论可参考：A、未见异常。B、除上述重大不符事项应当作为调整事项予以调整外，其余未见异常。C、由于存在以下重大未调整事项(或审计范围受到限制无法获取充分、适当证据），不可确认。

Sheet 调整分录汇总M10-3
A1: 致同会计师事务所
A2: 其他权益工具调整分录汇总表
A3: =底稿目录!A2 -> 被审计单位： | D3: =底稿目录!A4 -> 编制人： | G3: =底稿目录!A5 -> 编制日期： | I3: 索引号： | J3: =底稿目录!F8 -> M10-3
A4: =底稿目录!A3 -> 截止日：202X年12月31日 | D4: =底稿目录!A6 -> 复核人： | G4: =底稿目录!A7 -> 复核日期： | I4: 页 次：
A5: 调整事项说明 | B5: 类别（报表调整/账项调整/其他） | C5: 报表项目 | D5: 科目名称 | E5: 附注项目 | F5: …… | G5: 借方调整金额 | H5: 贷方调整金额 | I5: 索引 | J5: 备注
A25: 【注：本底稿适用于调整分录较多、较复杂的项目，且仅列示与本报表项目相关的审计调整。项目组可根据项目实际情况选择是否使用该底稿。】

Sheet 负债与权益区分检查表M10-4
A1: 致同会计师事务所
A2: 金融负债和权益工具的区分检查表
A3: =底稿目录!A2 -> 被审计单位： | C3: =底稿目录!A4 -> 编制人： | D3: =底稿目录!A5 -> 编制日期： | E3: 索引号： | F3: =底稿目录!F9 -> M10-4
A4: =底稿目录!A3 -> 截止日：202X年12月31日 | C4: =底稿目录!A6 -> 复核人： | D4: =底稿目录!A7 -> 复核日期： | E4: 页 次：
A5: 一、审计目标
A6: 1.检查被审计单位发行的优先股、永续债等工具已按照企业会计准则的规定在财务报表中作出恰当列报和披露。
A7: 二、审计过程
A8: 1.获取发行文件，梳理对发行人的全部合同义务的约定条款。
A9: 2.根据或有结算条款和结算选择权、可回售工具或清算产生的义务等因素，判断被审计单位选取的会计分类是否符合企业会计准则的要求。
A10: 3.考虑是否需要对复合型金融产品各成分进行拆分。 | D10: 4.如果发现会计分类方面的重大差异，应与管理层沟通，并执行其他补充审计程序。
A11: 项目 | C11: 注意事项 | D11: XX优先股 | E11: XX永续中票
A12: 发行时间 | C12: --
A13: 发行总额（面值） | C13: --
A14: 期末账面价值 | C14: --
A15: 本金相关分析 | B15: 存续期限或续期情况 | C15: 应无到期期限或可通过展期长期存续 | D15: 无到期期限 | E15: 长期存续
B16: 回购/赎回条件 | C16: 如果发行方不能无条件避免的赎回，则符合金融负债的定义 | D16: N/A | E16: 仅发行方有权选择赎回
A17: 股利/利息相关分析 | B17: 股息确定方式 | C17: 跳升总幅度较小且封顶利率未超过同期同行业同类型工具平均的利率水平，可能不构成间接义务 | D17: 重定价日的基准利率加首次定价时所确定的固定溢价 | E17: 当期基准利率+初始利差+300bps
B18: 强制付息事件 | C18: 如果强制付息事件不能由发行方自主决定（例如控股股东变更，存在普通股隐性强制分红义务），则存在强制付息义务 | D18: 向普通股股东分红 | E18: 向普通股股东分红；减少注册资本。
B19: 股息递延或取消 | C19: 应能够根据相应的议事机制自主决定是否支付股息（即无支付股息的义务） | D19: 公司有权全部或部分取消优先股股息的宣派和支付，且不构成违约事件 | E19: 发行人可自行选择将当期利息以及此前已经递延的所有利息及其孳息推迟至下一个付息日支付，且不受到任何递延支付利息次数的限制
A20: 或有结算条款 | B20: 违约事件 | C20: 发行方不能控制能否按时偿债、是否会发生超过净资产10%以上重大损失、财务指标承诺能否达标、财务状况是否发生重大变化、控制权是否会变更或信用等级是否会被降级、是否会发生其他投资者认定足以影响债权实现的事项等情形。因此，包含此类条款的永续债会触发投资者保护机制。 | D20: N/A | E20: 公司破产、全面无力偿债、拖欠到期应付款项、停止/暂停支付所有或大部份债务或终止经营其业务，或公司根据《破产法》规定进入破产程序。
B21: 应急事件 | D21: N/A | E21: 本公司发生未能清偿到期债务的违约情况；本公司或本公司的高级管理层出现严重违法、违规案件；本公司发生超过净资产10%以上重大损失；本公司受到重大行政处分、罚款或涉及重大诉讼或司法强制执行等事件；其他可能引起投资者重大损失的事件。
B22: 事先约束条款 | D22: N/A | E22: 发行人在本期债务融资工具存续期间应当确保发行人的合并财务报表资产负债率不超过85%
A23: 投资者保护机制 | C23: 除非发行方可以拒绝履行持有人会议要求赎回、提供担保的决议，或持有人会议无权要求发行方回购或提供担保（但可以要求有限度的利率跳升），否则发行方不能无条件避免合同义务。 | D23: N/A | E23: 永续债持有人有权对如下处理方案进行表决：（1）无条件豁免违反约定；（2）有条件豁免违反约定，即如果发行人采取了补救方案（如增加担保），并在30 日内完成相关法律手续的，则豁免违反约定。 如上述豁免的方案经表决生效，发行人应无条件接受持有人会议作出的上述决议，并于30 个工作日内完成相关法律手续。如上述方案未获表决通过，则永续债本息应在持有人会议召开日的次日立即到期应付。
A24: 转股特征 | B24: 转股条件 | D24: 当公司核心一级资本充足率降至5.125%（或以下）时，由公司董事会决定，本次发行的优先股应按照强制转股价格全额或部分转为公司A股普通股 | E24: N/A
B25: 转股价格 | C25: 应当不包括交付可变数量的自身权益工具进行结算的合同义务，或者满足“固定换固定”原则，通常表现为转股价初始固定 | D25: 10.96元/股 | E25: N/A
B26: 转股价格调整 | C26: 按照转股价格调整公式进行“反稀释”调整，是的持有人相对利益保持不变 | D26: 送红股或转增股本：P1=P0/（1+n） 增发新股或配股：P1= P0×（N+Q×（A/M））/（N+Q） 本次优先股的强制转股价格不因公司派发普通股现金股利的行为而进行调整。 | E26: N/A
A27: 清算偿付顺序 | C27: 清算时永续债与发行方发行的普通债券和其他债务处于相同清偿顺序的，应当审慎考虑此清偿顺序是否会导致持有方对发行方承担交付现金或其他金融资产合同义务的预期，并据此确定其会计分类 | D27: 本次发行的优先股股东受偿顺序位列存款人、一般债权人和次级债务（包括但不限于次级债、混合资本债券、二级资本工具等）之后，先于公司普通股股东 | E27: 本期中期票据的本金和利息在破产清算时的清偿顺序等同于发行人其他待偿还债务融资工具
A28: 其他相关条款分析 | B28: 发行方或其控股股东固定价格回购承诺 | C28: 签出看跌期权使集团整体承担了不能无条件避免的支付现金的合同义务 | D28: N/A | E28: N/A
B29: 信用增级 | C29: 不应包含其他合同义务 | D29: N/A | E29: 本期中期票据不设担保
A30: 会计属性区分 | C30: 应当按照该金融工具的合同条款及其所反映的经济实质而非法律形式进行区分 | D30: 公司支付固定股息的义务可以无条件取消；本金有权（但无需）赎回；转股权满足换取固定数量的自身权益工具的标准，不存在或有结算条款。因此，属于权益工具 | E30: 存在或有结算条款，且相关事件发生后发行方无法控制持有人大会是否会通过豁免的方案。而当持有人大会决定不豁免时，永续债本息就到期应付。此外，清偿顺序于普通债务等同，会导致持有方对发行方承担交付现金或其他金融资产合同义务的预期。因此，该永续债属于金融负债。
A31: 发行文件索引号 | C31: --
A33: 三、审计说明：
A36: 四、审计结论
A39: 注释：优先股合同条款与分类的倾向意见
A40: 项目 | B40: 优先股条款 | D40: 分类时的考虑
A41: 本金的赎回 | B41: 本金无需赎回，或发行方可自主决定是否赎回 | D41: 可能表明具有权益特征，但须分析股息的支付机制。若必须支付股息，则负债部分等于支付的永续股利的现值；若自主决定是否支付股息，则属于权益。
D42: 若发行方可自行选择在某一未来日期赎回，则发行方以现金赎回股票的看涨期权是一项嵌入衍生工具。
B43: 需在某固定或未来日期按照固定或可确定的金额强制赎回 | D43: 负债，还需分析股息的支付机制。若必须支付股息，则整体为负债；若自主决定是否支付股息，则负债部分等于赎回金额的现值，权益部分等于发行收入减去负债部分。
A44: 股息支付 | B44: 发行方可自主决定是否支付或无限期地递延股息而无任何支付义务（即使股息可累积） | D44: 可能表明具有权益特征，还需分析本金的赎回机制。若本金无需赎回或发行方可自主决定是否赎回，则属于权益；若本金需强制赎回，则负债部分等于赎回金额的现值，权益部分等于发行收入减去负债部分。
B45: 强制付息——固定股息，发行方不能递延支付 | D45: 负债。若本金无需赎回或发行方可自主决定是否赎回，则负债部分等于支付的永续股利的现值；若本金需强制赎回，则整体为负债。
...

Sheet 其他权益工具检查表M10-5
A1: 致同会计师事务所
A2: 其他权益工具检查表
A3: =底稿目录!A2 -> 被审计单位： | E3: =底稿目录!A4 -> 编制人： | H3: =底稿目录!A5 -> 编制日期： | O3: 索引号： | P3: =底稿目录!F10 -> M10-5
A4: =底稿目录!A3 -> 截止日：202X年12月31日 | E4: =底稿目录!A6 -> 复核人： | H4: =底稿目录!A7 -> 复核日期： | O4: 页 次：
A5: 一、审计目标:
A6: 1.其他综合收益以恰当的金额包括在财务报表中，与之相关的计价或分摊调整已恰当记录，相关披露已得到恰当计量和描述。
A7: 二、测试：
A8: 测试内容说明：1.原始凭证是否齐全； 2.记账凭证与原始凭证是否相符；3.账务处理是否正确；4.是否记录于恰当的会计期间；5.……
A9: 记账凭证 | H9: 支持性文件 | I9: 核对内容 | N9: 索引号 | O9: 是否异常 | P9: 备注说明
A10: 日期 | B10: 凭证编号 | C10: 业务内容 | D10: 对方科目 | E10: 对方明细科目 | F10: 借方金额 | G10: 贷方金额 | I10: 1 | J10: 2 | K10: 3 | L10: 4 | M10: 5
A19: 合计 | F19: =SUM(F11:F18) -> 0 | G19: =SUM(G11:G18) -> 0
A20: 本期发生额 | F20: ='明细表M10-2'!R26 -> 0 | G20: ='明细表M10-2'!N26 -> 0
A21: 检查比例 | F21: =F19/F20 -> #DIV/0! | G21: =G19/G20 -> #DIV/0!
A22: 五、审计说明：
A25: 六、审计结论：

Sheet GT_Custom
A1: C1 | B1: Custom 1
A2: C2 | B2: Custom 2
A3: C3 | B3: Custom 3
A4: C4 | B4: Custom 4
A5: C5 | B5: Custom 5
A6: C6 | B6: Custom 6
A7: C7 | B7: Custom 7
A8: C8 | B8: Custom 8
