Workbook
Name _jds82: '附注披露信息(上市公司)'!$A$7
Name _jds83: '附注披露信息(上市公司)'!$A$22
Name _jds85: '附注披露信息(上市公司)'!$A$66
Name _jds86: '附注披露信息(上市公司)'!$A$76
Name _jds87: '附注披露信息(上市公司)'!$A$86
Name _jds88: '附注披露信息(上市公司)'!$A$96
Name _jds89: '附注披露信息(上市公司)'!$A$106
Name _jds91: '附注披露信息(上市公司)'!$A$116
Name _jds92: '附注披露信息(上市公司)'!$A$125
Name _jds93: '附注披露信息(上市公司)'!$A$137
Name _jds94: '附注披露信息(上市公司)'!$A$140
Name _jds95: '附注披露信息(上市公司)'!$A$153
Name _jds96: '附注披露信息(上市公司)'!$A$162
Name _jds97: '附注披露信息(上市公司)'!$A$174
Name _jds98: '附注披露信息(上市公司)'!$A$51
Name _Ref82415221: '附注披露信息(上市公司)'!$A$21
Name _Ref82415222: '附注披露信息(上市公司)'!$A$115

Sheet 底稿目录
A1: 底稿开列时，可先在以下单元格填写有关内容，以便其他底稿引用有关数据：
A2: 被审计单位名称：
A3: 截止日：202X年12月31日 | D3: 序号 | E3: 内容 | F3: 索引号
A4: 编制人： | D4: 1 | E4: 应收账款实质性程序表 | F4: D2A
A5: 编制日期： | D5: 2 | E5: 应收账款审定表 | F5: D2-1
A6: 复核人： | D6: 3 | E6: 附注披露信息（上市公司） | G6: 无需打印
A7: 复核日期： | D7: 4 | E7: 附注披露信息(国企) | G7: 无需打印
D8: 5 | E8: 明细表 | F8: D2-2
A9: 关于工作底稿与审计程序索引号对应的说明 | D9: 6 | E9: 坏账准备明细表 | F9: D2-3
A10: 1.编制的审计工作底稿应与审计程序对应。审计项目组应根据被审计单位实际情况和风险评估情况在实质性程序表中裁剪、修改或增加审计程序，根据实际执行的审计程序完成相应审计工作底稿，编制的工作底稿中应按自然顺序依次编制索引号，并通过唯一的索引号将与实质性程序表中的程序对应关联（即将工作底稿的索引号填入实质性程序表中的底稿索引号列）。 | D10: 7 | E10: 调整分录汇总表 | F10: D2-4
A14: 2.获取的支持性证据应与审计底稿或程序对应。审计项目组在完成底稿时获取的支持性证据应根据底稿索引号编制下一级按自然顺序排序的索引号（如D1-2-1、D1-2-2、……），并在底稿中说明引用的支持性证据、关联索引号。
A17: 3.工作底稿索引号的编码规则：实质性程序索引号按循环从“D”到“N”,循环内账户以顺序号排列，模板中底稿索引号按账户顺序+自然数顺序（即模板中索引号按二级自然顺序排列，如D1-1、D1-2、D1-3、……D1-N）。

Sheet 应收账款实质性程序表D2A
A1: 致同会计师事务所
A2: 应收账款实质性程序表
A3: =底稿目录!A2 -> 被审计单位名称： | C3: =底稿目录!A4 -> 编制人： | F3: =底稿目录!A5 -> 编制日期： | H3: 索引号： | I3: D2A
A4: =底稿目录!A3 -> 截止日：202X年12月31日 | C4: =底稿目录!A6 -> 复核人： | F4: =底稿目录!A7 -> 复核日期： | H4: 页次：
A5: 一、本账户涉及的科目
A6: 应收账款
A7: 二、审计目标和财务报表的认定
A8: 审计目标 | G8: 财务报表的认定
A9: A.资产负债表中记录的应收账款是存在的，且已经记录在恰当的账户中 | G9: 存在
A10: B.所有应记录的应收账款均已记录，所有应当包括在财务报表中的相关披露均已包括 | G10: 完整性
A11: C.记录的应收账款由被审计单位拥有或控制 | G11: 权利和义务
A12: D.应收账款以恰当的金额包括在财务报表中，与之相关的计价或分摊调整已恰当记录，相关披露已得到恰当计量和描述 | G12: 准确性、计价和分摊
A13: E.应收账款已被恰当地汇总或分解且表述清楚，相关披露在按照企业会计准则的编制基础下是相关的、可理解的 | G13: 列报
A14: 三、计划实施的实质性程序
A15: 序号 | B15: 审计程序 | C15: 程序分类 | D15: 审计目标 | I15: 底稿索引号
D16: 存在 | E16: 完整性 | F16: 权利和义务 | G16: 准确性、计价和分摊 | H16: 列报 | J16: 根据被审计单位实际情况和风险评估情况裁剪、修改或增加审计程序
A17: 1 | B17: 获取或编制应收账款明细表，执行以下程序，并编制审定表： （1）复核加计是否正确，与总账、明细账合计数核对是否相符，期初余额与上期审定期末余额是否相符； （3）检查非记账本位币应收账款的折算汇率及折算是否正确。 （4）分析有贷方余额的项目，查明原因，必要时，作重分类调整。 （5）结合其他应收款、合同负债、预收款项等往来项目的明细余额，调查有无同一客户多处挂账、异常余额或与销售无关的其他款项（如代销账户、关联方账户或雇员账户）。如有，应做出记录，必要时作调整。 （6）请被审计单位协助，在应收账款明细表上标出至审计时已收到的应收账款金额，对已收回金额较大的款项进行检查至支持性文件。 | C17: 常规★ | D17: √ | E17: √ | G17: √ | I17: D2-1 /D2-2 /D2-3
A18: 2 | B18: 在使用手工编制、自定义信息报告、系统生成的非固定格式报告等由被审计单位生成的信息时，测试有关信息准确性和完整性，并考虑针对编制和维护由被审计单位生成的信息的相关控制实施控制测试，以评价该信息是否能够为实现审计目的提供基础。 | C18: 常规★ | E18: √ | G18: √ | I18: T1 /D2-0 / | J18: 可参见《审计手册》4.2.6，由被审计单位生成的信息可能是由系统生成的、或手工编制的、或二者兼而有之的方式生成的。例如，由被审计单位生成的信息可能包括： • 不涉及自定义的、由系统生成的报告（如，固定格式报告）； • 可能通过人工自定义的、由系统生成的报告，例如，（计算机）查询信息或特别定制的报告； • 手工编制的信息，例如，汇总信息的电子表格或用以支持分配、计算以及调节的电子表格； • 其他系统生成或手工编制的信息，例如，由被审计单位编制的客户发票； • 通过影印、拍摄、扫描或其他方式转换成电子形式的文件记录。
A19: 3 | B19: 取得应收账款期初余额明细表复核加计是否正确，与总账、明细账合计数是否相符；检查上期应收账款在本期收回情况；函证期初余额以及其他必要追加的审计程序。（适用于首次承接） | C19: 备选 | D19: √ | E19: √ | F19: √ | G19: √ | J19: 由被审计单位生成的信息不包括： • 总分类账或明细分类账、试算平衡表、或经审计的财务报表； • 第三方（除了服务机构）的报表或报告，例如，原始银行对账单，或函证的回函； • 外部数据（例如，第三方发布的数据，如，定价来源）。
A20: 4 | B20: 获取应收账款账龄明细表： (1）确定计算准确性并与总账核对一致； (2）对重要应收账款账龄进行重新计算，与被审计单位提供的账龄表进行比较； (3）对于发现的重大不一致，询问客户内部适当人员，并检查原始凭证，测试账龄划分的准确性。 | C20: 常规★ | G20: √ | I20: D2-2
A21: 5 | B21: 实施分析性程序： （1）计算除销比例、应收账款周转率及应收账款周转天数等指标，与被审计单位以前年度指标、同行业同期相关指标对比分析，检查是否存在异常； （2）分析借贷方发生额，与对应科目比较是否存在异常； （3）比较主要客户应收账款余额变动情况，分析合理性； （4）与期初余额账龄比较，分析变动合理性。 | C21: 常规★ | D21: √ | G21: √ | I21: D2-5
A22: 6 | B22: 实施函证程序： （1）以积极方式对预付账款进行函证，设计询证函、发函前核实被函证单位信息； （2）注册会计师独立收发询证函； （3）编制函证结果汇总表，检查发函、回函物流信息和轨迹、比对回函印章和签字等以核实回函的真实性，检查回函是否相符，对不符事项查明原因确定是否存在错报； （4）如果未收到回函，应当考虑与被询证者联系，要求对方作出回应或再次寄发询证函，无法收到的回函实施替代程序； （5）如果管理层不允许寄发询证函的，询问管理层不允许寄发的原因，并就其原因的正当、合理性收集证据；考虑实施替代审计程序以获取相关、可靠的审计证据； （6）如果管理层不允许寄发询证函的原因不合理、或者认为回函不可靠，评价对评估的重大错报风险以及其他审计程序的性质、时间安排和范围的影响，并确定其对审计工作和审计意见的影响。 | C22: 常规★ | D22: √ | E22: √ | F22: √ | G22: √ | I22: D2-0
A23: 7 | B23: 检查应收关联方款项： （1）了解交易的商业理由、交易事项的目的、价格和条件，考虑对关联方应收账款的合理性、合法性； （2）检查证实交易的支持性文件（例如，发票、合同、协议和运输单据等相关文件）、检查会计处理是否正确； （3）考虑向关联方或其他注册会计师函证重大的关联销售交易（包括担保和其他重要信息）； （4）必要时，向与交易相关的人员和机构（如银行、律师）函证或与其讨论有关信息。 （5）考虑是否存在未识别的关联方，关联交易和余额披露是否正确。 | C23: 常规★ | D23: √ | E23: √ | F23: √ | G23: √ | H23: √ | I23: D2-6 /D2-7 /D0
A24: 8 | B24: 对未函证的应收账款，抽取适当的样本检查相关支持性文件（如销售合同、销售订单、销售发票副本、发运凭证及回款单据），确定会计处理是否正确。 | C24: 常规★ | D24: √ | F24: √ | G24: √ | I24: D2-7
A25: 9 | B25: 浏览应收账款发生额，关注有无不属于结算业务的债权。如有，检查至相关支持性文件，确定债权性质。 | C25: 常规★ | D25: √ | F25: √ | I25: D2-7
A26: 10 | B26: 检查应收账款坏账准备计提是否正确： （1）了解应收票据坏账准备计提会计政策，确定应收账款坏账准备是否以预期信用损失为基础计提，计提政策是否恰当，是否一贯执行。必要时，与同行业其他公司的会计政策进行对比，关注其是否利用会计政策和会计估计变更操纵利润 （2）重新计算应计提的坏账准备，与被审计单位已记录的坏账准备进行比较。 （3）关注大额坏账准备转回是否合理。实际发生坏账损失的，检查转销依据是否符合有关规定，会计处理是否正确。已经确认并转销的坏账重新收回的，检查其会计处理是否正确。 | C26: 常规★ | G26: √ | I26: D2-9 /D2-10 /D2-11
A27: 11 | B27: 检查应收账款中是否存在债务人破产或者死亡，以其破产财产或者遗产清偿后仍无法收回，或者债务人长期未履行偿债义务的情况，如是，应提请被审计单位处理。 | C27: 常规★ | G27: √
A28: 12 | B28: 对于大额应收账款客户： (1)检查报告期公司应收账款（含余额及发生额）主要客户与营业收入主要客户是否匹配，新增客户的应收账款余额与向该客户的销售是否匹配； (2)检查大额应收款项是否能够按合同约定期收回以及期末收到的销售款项是否存在期后不正常流出的情况。 （3）检查是否存在改变客户信用期、放宽付款条件以促进短期销售增长，从而导致应收账款增加，分析判断是否属于人为改变正常经营活动，是否满足收入确认条件。 | C28: IPO/上市/新三板/重组/舞弊应对 | D28: √
A29: 13 | B29: 结合销售合同中与收款、验收相关的主要条款，对于大额应收账长期未收回的客户，分析被审计单位仍向其进行销售的合理性和真实性。 | C29: IPO/上市/新三板/重组/舞弊应对 | D29: √
A30: 14 | B30: 结合营业收入审计，对重要的客户进行背景调查、电话访谈、实地走访等，核实应收账款真实性。 | C30: IPO/上市/新三板/重组/舞弊应对 | D30: √ | E30: √ | F30: √ | G30: √ | I30: D4-28 /D4-29 /D4-30 /D4-31 /D4-32
A31: 15 | B31: 对于应收账款保理、出售、资产证券化等业务：检查保理、资产证券化等交易的整套协议和相关会计处理是否恰当，关注交易的真实性；考虑函证重要项目。 | C31: 备选 | E31: √ | F31: √ | I31: D2-12
A32: 16 | B32: 检查应收账款询证函回函、会议纪要、借款协议和其他文件，确定应收账款是否已被质押或出售。 | C32: 常规★ | F32: √ | I32: D2-12
A33: 17 | B33: 了解被审计单位管理应收账款的业务模式，判断应收账款分类是否正确。 | C33: 常规★ | D33: √ | I33: D2-13
A34: 18 | B34: 通过检查自资产负债表日至___日止被审计单位授予欠款单位的、金额大于___的减免应收账款的支持性文件，以及资产负债表日前后销售退回和赊销水平，确定应收账款是否真实存在。 | C34: 常规★ | D34: √ | I34: D2-7
A35: 19 | B35: 针对评估的舞弊风险等因素增加的审计程序。 | C35: IPO/上市/新三板/重组/舞弊应对
A36: 20 | B36: 检查应收账款是否已按企业会计准则或其他适用的规定在财务报表中做出恰当列报和披露。 | C36: 常规★ | H36: √ | I36: A 1-1/A1-15 /A1-16

Sheet 审定表D2-1
A1: 致同会计师事务所
A2: 应收账款审定表
A3: =底稿目录!A2 -> 被审计单位名称： | E3: =底稿目录!A4 -> 编制人： | H3: =底稿目录!A5 -> 编制日期： | K3: 索引号： | L3: =底稿目录!F5 -> D2-1
A4: =底稿目录!A3 -> 截止日：202X年12月31日 | E4: =底稿目录!A6 -> 复核人： | H4: =底稿目录!A7 -> 复核日期： | K4: 页次：
A5: 项目 | B5: 期初数 | F5: 期末数 | J5: 本期与上期审定数比较 | L5: 原因分析
B6: 未审数 | C6: 账项调整 | D6: 重分类调整 | E6: 审定数 | F6: 未审数 | G6: 账项调整 | H6: 重分类调整 | I6: 审定数 | J6: 变动额 | K6: 变动率
A7: 一、应收账款原值
A8: 单项计提坏账准备 | E8: =B8+C8+D8 -> 0 | F8: =SUMIF('明细表D2-2'!$AI$13:$AI$25,"单项计提",'明细表D2-2'!$S$13:$S$25) -> 0 | G8: =SUMIF('明细表D2-2'!$AI$13:$AI$25,"单项计提",'明细表D2-2'!$Z$13:$Z$25) -> 0 | H8: =SUMIF('明细表D2-2'!$AI$13:$AI$25,"单项计提",'明细表D2-2'!$AA$13:$AA$25) -> 0 | I8: =F8+G8+H8 -> 0 | J8: =I8-E8 -> 0 | K8: =IF(AND(E8=0,I8=0),"",IF(AND(E8=0,I8>0),1,J8/E8))
A9: 按组合计提坏账准备 | B9: =SUM(B10:B12) -> 0 | C9: =SUM(C10:C12) -> 0 | D9: =SUM(D10:D12) -> 0 | E9: =SUM(E10:E12) -> 0 | F9: =SUM(F10:F12) -> 0 | G9: =SUM(G10:G12) -> 0 | H9: =SUM(H10:H12) -> 0 | I9: =SUM(I10:I12) -> 0 | J9: =I9-E9 -> 0 | K9: =IF(AND(E9=0,I9=0),"",IF(AND(E9=0,I9>0),1,J9/E9))
A10: 账龄组合 | E10: =B10+C10+D10 -> 0 | F10: =SUMIF('明细表D2-2'!$AI$13:$AI$25,"账龄组合",'明细表D2-2'!$S$13:$S$25) -> 0 | G10: =SUMIF('明细表D2-2'!$AI$13:$AI$25,"账龄组合",'明细表D2-2'!$Z$13:$Z$25) -> 0 | H10: =SUMIF('明细表D2-2'!$AI$13:$AI$25,"账龄组合",'明细表D2-2'!$AA$13:$AA$25) -> 0 | I10: =F10+G10+H10 -> 0 | J10: =I10-E10 -> 0 | K10: =IF(AND(E10=0,I10=0),"",IF(AND(E10=0,I10>0),1,J10/E10))
A11: 客户类型组合 | E11: =B11+C11+D11 -> 0 | F11: =SUMIF('明细表D2-2'!$AI$13:$AI$25,"客户类型组合",'明细表D2-2'!$S$13:$S$25) -> 0 | G11: =SUMIF('明细表D2-2'!$AI$13:$AI$25,"客户类型组合",'明细表D2-2'!$Z$13:$Z$25) -> 0 | H11: =SUMIF('明细表D2-2'!$AI$13:$AI$25,"客户类型组合",'明细表D2-2'!$AA$13:$AA$25) -> 0 | I11: =F11+G11+H11 -> 0 | J11: =I11-E11 -> 0 | K11: =IF(AND(E11=0,I11=0),"",IF(AND(E11=0,I11>0),1,J11/E11))
A12: ……组合 | E12: =B12+C12+D12 -> 0 | I12: =F12+G12+H12 -> 0 | J12: =I12-E12 -> 0 | K12: =IF(AND(E12=0,I12=0),"",IF(AND(E12=0,I12>0),1,J12/E12))
A13: 小计 | B13: =SUM(B8,B9) -> 0 | C13: =SUM(C8,C9) -> 0 | D13: =SUM(D8,D9) -> 0 | E13: =SUM(E8,E9) -> 0 | F13: =SUM(F8,F9) -> 0 | G13: =SUM(G8,G9) -> 0 | H13: =SUM(H8,H9) -> 0 | I13: =SUM(I8,I9) -> 0 | J13: =I13-E13 -> 0 | K13: =IF(AND(E13=0,I13=0),"",IF(AND(E13=0,I13>0),1,J13/E13))
A14: 二、应收账款坏账准备
A15: =A8 -> 单项计提坏账准备 | E15: =B15+C15+D15 -> 0 | I15: =F15+G15+H15 -> 0 | J15: =I15-E15 -> 0 | K15: =IF(AND(E15=0,I15=0),"",IF(AND(E15=0,I15>0),1,J15/E15))
A16: =A9 -> 按组合计提坏账准备 | B16: =SUM(B17:B19) -> 0 | C16: =SUM(C17:C19) -> 0 | D16: =SUM(D17:D19) -> 0 | E16: =SUM(E17:E19) -> 0 | F16: =SUM(F17:F19) -> 0 | G16: =SUM(G17:G19) -> 0 | H16: =SUM(H17:H19) -> 0 | I16: =SUM(I17:I19) -> 0 | J16: =I16-E16 -> 0 | K16: =IF(AND(E16=0,I16=0),"",IF(AND(E16=0,I16>0),1,J16/E16))
A17: =A10 -> 账龄组合 | E17: =B17+C17+D17 -> 0 | I17: =F17+G17+H17 -> 0 | J17: =I17-E17 -> 0 | K17: =IF(AND(E17=0,I17=0),"",IF(AND(E17=0,I17>0),1,J17/E17))
A18: =A11 -> 客户类型组合 | E18: =B18+C18+D18 -> 0 | I18: =F18+G18+H18 -> 0 | J18: =I18-E18 -> 0 | K18: =IF(AND(E18=0,I18=0),"",IF(AND(E18=0,I18>0),1,J18/E18))
A19: =A12 -> ……组合 | E19: =B19+C19+D19 -> 0 | I19: =F19+G19+H19 -> 0 | J19: =I19-E19 -> 0 | K19: =IF(AND(E19=0,I19=0),"",IF(AND(E19=0,I19>0),1,J19/E19))
A20: 小计 | B20: =SUM(B15,B16) -> 0 | C20: =SUM(C15,C16) -> 0 | D20: =SUM(D15,D16) -> 0 | E20: =SUM(E15,E16) -> 0 | F20: =SUM(F15,F16) -> 0 | G20: =SUM(G15,G16) -> 0 | H20: =SUM(H15,H16) -> 0 | I20: =SUM(I15,I16) -> 0 | J20: =I20-E20 -> 0 | K20: =IF(AND(E20=0,I20=0),"",IF(AND(E20=0,I20>0),1,J20/E20))
A21: 三、应收账款净值
A22: =A8 -> 单项计提坏账准备 | B22: =B8-B15 -> 0 | C22: =C8-C15 -> 0 | D22: =D8-D15 -> 0 | E22: =E8-E15 -> 0 | F22: =F8-F15 -> 0 | G22: =G8-G15 -> 0 | H22: =H8-H15 -> 0 | I22: =I8-I15 -> 0 | J22: =I22-E22 -> 0 | K22: =IF(AND(E22=0,I22=0),"",IF(AND(E22=0,I22>0),1,J22/E22))
A23: =A9 -> 按组合计提坏账准备 | B23: =SUM(B24:B26) -> 0 | C23: =SUM(C24:C26) -> 0 | D23: =SUM(D24:D26) -> 0 | E23: =SUM(E24:E26) -> 0 | F23: =SUM(F24:F26) -> 0 | G23: =SUM(G24:G26) -> 0 | H23: =SUM(H24:H26) -> 0 | I23: =SUM(I24:I26) -> 0 | J23: =I23-E23 -> 0 | K23: =IF(AND(E23=0,I23=0),"",IF(AND(E23=0,I23>0),1,J23/E23))
A24: =A10 -> 账龄组合 | B24: =B10-B17 -> 0 | C24: =C10-C17 -> 0 | D24: =D10-D17 -> 0 | E24: =E10-E17 -> 0 | F24: =F10-F17 -> 0 | G24: =G10-G17 -> 0 | H24: =H10-H17 -> 0 | I24: =I10-I17 -> 0 | J24: =I24-E24 -> 0 | K24: =IF(AND(E24=0,I24=0),"",IF(AND(E24=0,I24>0),1,J24/E24))
A25: =A11 -> 客户类型组合 | B25: =B11-B18 -> 0 | C25: =C11-C18 -> 0 | D25: =D11-D18 -> 0 | E25: =E11-E18 -> 0 | F25: =F11-F18 -> 0 | G25: =G11-G18 -> 0 | H25: =H11-H18 -> 0 | I25: =I11-I18 -> 0 | J25: =I25-E25 -> 0 | K25: =IF(AND(E25=0,I25=0),"",IF(AND(E25=0,I25>0),1,J25/E25))
A26: =A12 -> ……组合 | B26: =B12-B19 -> 0 | C26: =C12-C19 -> 0 | D26: =D12-D19 -> 0 | E26: =E12-E19 -> 0 | F26: =F12-F19 -> 0 | G26: =G12-G19 -> 0 | H26: =H12-H19 -> 0 | I26: =I12-I19 -> 0 | J26: =I26-E26 -> 0 | K26: =IF(AND(E26=0,I26=0),"",IF(AND(E26=0,I26>0),1,J26/E26))
A27: 合计 | B27: =SUM(B22,B23) -> 0 | C27: =SUM(C22,C23) -> 0 | D27: =SUM(D22,D23) -> 0 | E27: =SUM(E22,E23) -> 0 | F27: =SUM(F22,F23) -> 0 | G27: =SUM(G22,G23) -> 0 | H27: =SUM(H22,H23) -> 0 | I27: =SUM(I22,I23) -> 0 | J27: =I27-E27 -> 0 | K27: =IF(AND(E27=0,I27=0),"",IF(AND(E27=0,I27>0),1,J27/E27))
A28: （一）账龄组合原值
A29: 一年以内 | E29: =B29+C29+D29 -> 0 | I29: =F29+G29+H29 -> 0 | J29: =I29-E29 -> 0 | K29: =IF(AND(E29=0,I29=0),"",IF(AND(E29=0,I29>0),1,J29/E29))
A30: 一到二年 | E30: =B30+C30+D30 -> 0 | I30: =F30+G30+H30 -> 0 | J30: =I30-E30 -> 0 | K30: =IF(AND(E30=0,I30=0),"",IF(AND(E30=0,I30>0),1,J30/E30))
A31: 二到三年 | E31: =B31+C31+D31 -> 0 | I31: =F31+G31+H31 -> 0 | J31: =I31-E31 -> 0 | K31: =IF(AND(E31=0,I31=0),"",IF(AND(E31=0,I31>0),1,J31/E31))
A32: 三到四年 | E32: =B32+C32+D32 -> 0 | I32: =F32+G32+H32 -> 0 | J32: =I32-E32 -> 0 | K32: =IF(AND(E32=0,I32=0),"",IF(AND(E32=0,I32>0),1,J32/E32))
A33: 四到五年 | E33: =B33+C33+D33 -> 0 | I33: =F33+G33+H33 -> 0 | J33: =I33-E33 -> 0 | K33: =IF(AND(E33=0,I33=0),"",IF(AND(E33=0,I33>0),1,J33/E33))
A34: 五年以上 | E34: =B34+C34+D34 -> 0 | I34: =F34+G34+H34 -> 0 | J34: =I34-E34 -> 0 | K34: =IF(AND(E34=0,I34=0),"",IF(AND(E34=0,I34>0),1,J34/E34))
A35: 小计 | B35: =SUM(B29:B34) -> 0 | C35: =SUM(C29:C34) -> 0 | D35: =SUM(D29:D34) -> 0 | E35: =SUM(E29:E34) -> 0 | F35: =SUM(F29:F34) -> 0 | G35: =SUM(G29:G34) -> 0 | H35: =SUM(H29:H34) -> 0 | I35: =SUM(I29:I34) -> 0 | J35: =I35-E35 -> 0 | K35: =IF(AND(E35=0,I35=0),"",IF(AND(E35=0,I35>0),1,J35/E35))
A36: （二）账龄组合坏账准备
A37: =A29 -> 一年以内 | E37: =B37+C37+D37 -> 0 | I37: =F37+G37+H37 -> 0 | J37: =I37-E37 -> 0 | K37: =IF(AND(E37=0,I37=0),"",IF(AND(E37=0,I37>0),1,J37/E37))
A38: =A30 -> 一到二年 | E38: =B38+C38+D38 -> 0 | I38: =F38+G38+H38 -> 0 | J38: =I38-E38 -> 0 | K38: =IF(AND(E38=0,I38=0),"",IF(AND(E38=0,I38>0),1,J38/E38))
A39: =A31 -> 二到三年 | E39: =B39+C39+D39 -> 0 | I39: =F39+G39+H39 -> 0 | J39: =I39-E39 -> 0 | K39: =IF(AND(E39=0,I39=0),"",IF(AND(E39=0,I39>0),1,J39/E39))
A40: =A32 -> 三到四年 | E40: =B40+C40+D40 -> 0 | I40: =F40+G40+H40 -> 0 | J40: =I40-E40 -> 0 | K40: =IF(AND(E40=0,I40=0),"",IF(AND(E40=0,I40>0),1,J40/E40))
...

Sheet 附注披露信息(上市公司）D2-1
A1: 致同会计师事务所
A2: 附注披露信息（上市公司）
A3: =底稿目录!A2 -> 被审计单位名称： | C3: =底稿目录!A4 -> 编制人： | E3: =底稿目录!A5 -> 编制日期： | F3: 索引：D2-1
A4: =底稿目录!A3 -> 截止日：202X年12月31日 | C4: =底稿目录!A6 -> 复核人： | E4: =底稿目录!A7 -> 复核日期： | F4: 页次：
A5: 附注披露信息：
A6: 应收账款（以下不适用的，请删除）
A7: （1）应收账款按种类披露
A8: 种类 | B8: 期末数
B9: 金 额 | C9: 比例% | D9: 坏账准备 | E9: 计提比例% | F9: 净额
A10: 单项计提坏账准备的应收账款 | B10: =#REF! -> #REF! | C10: =B10/$B$17 -> #REF! | D10: =#REF! -> #REF! | E10: =IF(B10=0,,D10/B10) -> #REF! | F10: =B10-D10 -> #REF!
A11: 按组合计提坏账准备的应收账款
A12: 其中：账龄组合 | B12: =#REF! -> #REF! | C12: =B12/$B$17 -> #REF! | D12: =#REF! -> #REF! | E12: =IF(B12=0,,D12/B12) -> #REF! | F12: =B12-D12 -> #REF!
A13: 客户类型组合 | B13: =#REF! -> #REF! | C13: =B13/$B$17 -> #REF! | D13: =#REF! -> #REF! | E13: =IF(B13=0,,D13/B13) -> #REF! | F13: =B13-D13 -> #REF!
A14: 产品类型组合 | C14: =B14/$B$17 -> #REF! | E14: =IF(B14=0,,D14/B14) -> 0 | F14: =B14-D14 -> 0
A15: ……组合 | C15: =B15/$B$17 -> #REF! | E15: =IF(B15=0,,D15/B15) -> 0 | F15: =B15-D15 -> 0
A16: 组合小计 | B16: =SUM(B12:B15) -> #REF! | C16: =B16/$B$17 -> #REF! | D16: =SUM(D12:D15) -> #REF! | E16: =IF(B16=0,,D16/B16) -> #REF! | F16: =SUM(F12:F15) -> #REF!
A17: 合 计 | B17: =SUM(B10+B16) -> #REF! | C17: =B17/B17 -> #REF! | D17: =SUM(D10+D16) -> #REF! | E17: =IF(B17=0,,D17/B17) -> #REF! | F17: =SUM(F10+F16) -> #REF!
A18: 应收账款按种类披露（续）
A19: 种类 | B19: 期初数
B20: 金 额 | C20: 比例% | D20: 坏账准备 | E20: 计提比例% | F20: 净额
A21: 单项计提坏账准备的应收账款 | C21: =IF($B$28=0,0,B21/$B$28) -> 0 | E21: =IF(B21=0,0,D21/B21) -> 0 | F21: =B21-D21 -> 0
A22: 按组合计提坏账准备的应收账款
A23: 其中：账龄组合 | C23: =IF($B$28=0,0,B23/$B$28) -> 0 | E23: =IF(B23=0,0,D23/B23) -> 0 | F23: =B23-D23 -> 0
A24: 客户类型组合 | C24: =IF($B$28=0,0,B24/$B$28) -> 0 | E24: =IF(B24=0,0,D24/B24) -> 0 | F24: =B24-D24 -> 0
A25: 产品类型组合 | C25: =IF($B$28=0,0,B25/$B$28) -> 0 | E25: =IF(B25=0,0,D25/B25) -> 0 | F25: =B25-D25 -> 0
A26: ……组合 | C26: =IF($B$28=0,0,B26/$B$28) -> 0 | E26: =IF(B26=0,0,D26/B26) -> 0 | F26: =SUM(F23:F25) -> 0
A27: 组合小计 | B27: =SUM(B23:B26) -> 0 | C27: =SUM(C23:C26) -> 0 | D27: =SUM(D23:D26) -> 0 | E27: =SUM(E23:E26) -> 0 | F27: =B27-D27 -> 0
A28: 合 计 | B28: =SUM(B21+B27) -> 0 | C28: =SUM(C21+C27) -> 0 | D28: =SUM(D21+D27) -> 0 | E28: =SUM(E21+E27) -> 0 | F28: =SUM(F21+F27) -> 0
A29: 注：填写组合名称。账面余额中的比例按期末该类应收账款除以应收账款合计数计算，坏账准备比例按该类应收账款期末已计提坏账准备除以期末该类应收账款余额计算。
A30: 说明：
A31: ①期末单项计提坏账准备的应收账款
A32: 应收账款（按单位） | B32: 账面余额 | C32: 坏账准备 | D32: 计提比例% | E32: 计提理由
D33: =IF(B33=0,0,C33/B33) -> 0
D34: =IF(B34=0,0,C34/B34) -> 0
D35: =IF(B35=0,0,C35/B35) -> 0
D36: =IF(B36=0,0,C36/B36) -> 0
D37: =IF(B37=0,0,C37/B37) -> 0
A38: 合 计 | B38: =SUM(B33:B37) -> 0 | C38: =SUM(C33:C37) -> 0 | D38: =IF(B38=0,0,C38/B38) -> 0
A39: ②按账龄组合计提坏账准备的应收账款：（不适用的删除）
A40: 账 龄 | B40: 期末数
...

Sheet 附注披露信息（国企）D2-1
A1: 致同会计师事务所
A2: 附注披露信息（国企）
A3: =底稿目录!A2 -> 被审计单位名称： | C3: =底稿目录!A4 -> 编制人： | E3: =底稿目录!A5 -> 编制日期： | G3: 索引：D2-1
A4: =底稿目录!A3 -> 截止日：202X年12月31日 | C4: =底稿目录!A6 -> 复核人： | E4: =底稿目录!A7 -> 复核日期： | G4: 页次：1
A5: 附注披露信息：
A6: 应收账款
A7: 应收账款按种类披露
A8: 种 类 | B8: 期末数
B9: 账面余额 | C9: 比例% | D9: 坏账准备 | E9: 比例%
A10: 单项计提坏账准备的应收账款 | B10: =#REF! -> #REF! | C10: =IF($B$17=0,0,B10/$B$17) -> #REF! | D10: =#REF! -> #REF! | E10: =IF(B10=0,0,D10/B10) -> #REF!
A11: 按组合计提坏账准备的应收账款
A12: 其中：账龄组合 | B12: =#REF! -> #REF! | C12: =IF($B$17=0,0,B12/$B$17) -> #REF! | D12: =#REF! -> #REF! | E12: =IF(B12=0,0,D12/B12) -> #REF!
A13: 客户类型组合 | B13: =#REF! -> #REF! | C13: =IF($B$17=0,0,B13/$B$17) -> #REF! | D13: =#REF! -> #REF! | E13: =IF(B13=0,0,D13/B13) -> #REF!
A14: 产品类型组合 | C14: =IF($B$17=0,0,B14/$B$17) -> #REF! | E14: =IF(B14=0,0,D14/B14) -> 0
A15: ……组合 | C15: =IF($B$17=0,0,B15/$B$17) -> #REF! | E15: =IF(B15=0,0,D15/B15) -> 0
A16: 组合小计 | B16: =SUM(B12:B15) -> #REF! | C16: =IF($B$17=0,0,B16/$B$17) -> #REF! | D16: =SUM(D12:D15) -> #REF! | E16: =IF(B16=0,0,D16/B16) -> #REF!
A17: 合 计 | B17: =SUM(B10+B16) -> #REF! | C17: =SUM(C10+C16) -> #REF! | D17: =SUM(D10+D16) -> #REF! | E17: =IF(B17=0,0,D17/B17) -> #REF!
A18: 应收账款按种类披露（续）
A19: 种 类 | B19: 年初数
B20: 账面余额 | C20: 比例% | D20: 坏账准备 | E20: 比例%
A21: 单项计提坏账准备的应收账款 | C21: =IF($B$28=0,0,B21/$B$28) -> 0 | E21: =IF(B21=0,0,D21/B21) -> 0
A22: 按组合计提坏账准备的应收账款
A23: 其中：账龄组合 | C23: =IF($B$28=0,0,B23/$B$28) -> 0 | E23: =IF(B23=0,0,D23/B23) -> 0
A24: 客户类型组合 | C24: =IF($B$28=0,0,B24/$B$28) -> 0 | E24: =IF(B24=0,0,D24/B24) -> 0
A25: 产品类型组合 | C25: =IF($B$28=0,0,B25/$B$28) -> 0 | E25: =IF(B25=0,0,D25/B25) -> 0
A26: ……组合 | C26: =IF($B$28=0,0,B26/$B$28) -> 0 | E26: =IF(B26=0,0,D26/B26) -> 0
A27: 组合小计 | B27: =SUM(B23:B26) -> 0 | C27: =IF($B$28=0,0,B27/$B$28) -> 0 | D27: =SUM(D23:D26) -> 0 | E27: =IF(B27=0,0,D27/B27) -> 0
A28: 合 计 | B28: =SUM(B21+B26+B27) -> 0 | C28: =SUM(C21+C26+C27) -> 0 | D28: =SUM(D21+D26+D27) -> 0 | E28: =IF(B28=0,0,D28/B28) -> 0
A29: （注：①填写组合名称。②账面余额中的比例按年末该类应收账款除以应收账款余额合计数计算，坏账准备比例按该类应收账款年末已计提坏账准备除以年末该类应收账款余额计算。）
A30: （1）按组合计提坏账准备的应收账款
A31: A、采用账龄分析法计提坏账准备的应收账款
A32: 账 龄 | B32: 期末数 | E32: 年初数
B33: 账面余额 | D33: 坏账准备 | E33: 账面余额 | G33: 坏账准备
B34: 金额 | C34: 比例(%) | E34: 金额 | F34: 比例(%)
A35: =#REF! -> #REF! | B35: =#REF! -> #REF! | C35: =IF(B35=0,0,B35/$B$41) -> #REF! | D35: =#REF! -> #REF! | F35: =IF(E35=0,0,E35/$E$41) -> 0
A36: =#REF! -> #REF! | B36: =#REF! -> #REF! | C36: =IF(B36=0,0,B36/$B$41) -> #REF! | D36: =#REF! -> #REF! | F36: =IF(E36=0,0,E36/$E$41) -> 0
A37: =#REF! -> #REF! | B37: =#REF! -> #REF! | C37: =IF(B37=0,0,B37/$B$41) -> #REF! | D37: =#REF! -> #REF! | F37: =IF(E37=0,0,E37/$E$41) -> 0
A38: =#REF! -> #REF! | B38: =#REF! -> #REF! | C38: =IF(B38=0,0,B38/$B$41) -> #REF! | D38: =#REF! -> #REF! | F38: =IF(E38=0,0,E38/$E$41) -> 0
A39: =#REF! -> #REF! | B39: =#REF! -> #REF! | C39: =IF(B39=0,0,B39/$B$41) -> #REF! | D39: =#REF! -> #REF! | F39: =IF(E39=0,0,E39/$E$41) -> 0
A40: =#REF! -> #REF! | B40: =#REF! -> #REF! | C40: =IF(B40=0,0,B40/$B$41) -> #REF! | D40: =#REF! -> #REF! | F40: =IF(E40=0,0,E40/$E$41) -> 0
...

Sheet 附注披露信息(上市公司)
A1: 致同会计师事务所
A2: 附注披露信息（上市公司）
A3: =底稿目录!A2 -> 被审计单位名称： | C3: =底稿目录!A4 -> 编制人： | E3: =底稿目录!A5 -> 编制日期： | H3: 索引号：
A4: =底稿目录!A3 -> 截止日：202X年12月31日 | C4: =底稿目录!A6 -> 复核人： | E4: =底稿目录!A7 -> 复核日期： | H4: 页 次：
A5: 应收账款附注
A6: （1）按账龄披露
A7: 账 龄 | B7: 期末余额 | C7: 上年年末余额
A8: 1年以内 | B8: ='明细表D2-2'!AC26 -> 0 | C8: ='明细表D2-2'!I26 -> 0
A9: 其中：0-X个月
A10: X-Y个月
A12: 1年以内小计： | B12: =SUM(B9:B11) -> 0 | C12: =SUM(C9:C11) -> 0
A13: 1至2年 | B13: ='明细表D2-2'!AD26 -> 0 | C13: ='明细表D2-2'!J26 -> 0
A14: 2至3年 | B14: ='明细表D2-2'!AE26 -> 0 | C14: ='明细表D2-2'!K26 -> 0
A15: 3至4年 | B15: ='明细表D2-2'!AF26 -> 0 | C15: ='明细表D2-2'!L26 -> 0
A16: 4至5年 | B16: ='明细表D2-2'!AG26 -> 0 | C16: ='明细表D2-2'!M26 -> 0
A17: 5年以上 | B17: ='明细表D2-2'!AH26 -> 0 | C17: ='明细表D2-2'!N26 -> 0
A18: 小 计 | B18: =SUM(B12:B17) -> 0 | C18: =SUM(C12:C17) -> 0
A19: 减：坏账准备
A20: 合 计 | B20: =B18-B19 -> 0 | C20: =C18-C19 -> 0
A21: （2）按坏账计提方法分类披露
A22: 类 别 | B22: 期末余额
B23: 账面余额 | D23: 坏账准备 | F23: 账面价值
B24: 金额 | C24: 比例(%) | D24: 金额 | E24: 预期信用损失率(%)
A25: 按单项计提坏账准备 | C25: =IFERROR(B25/$B$36,0) -> 0 | E25: =IFERROR(D25/B25,0) -> 0 | F25: =B25-D25 -> 0
A26: 其中：
C27: =IFERROR(B27/$B$36,0) -> 0 | E27: =IFERROR(D27/B27,0) -> 0 | F27: =B27-D27 -> 0
C28: =IFERROR(B28/$B$36,0) -> 0 | E28: =IFERROR(D28/B28,0) -> 0 | F28: =B28-D28 -> 0
A29: 按组合计提坏账准备【注意：与会计政策中披露的组合保持一致】 | C29: =IFERROR(B29/$B$36,0) -> 0 | E29: =IFERROR(D29/B29,0) -> 0 | F29: =B29-D29 -> 0
A30: 其中： | F30: =B30-D30 -> 0
C31: =IFERROR(B31/$B$36,0) -> 0 | E31: =IFERROR(D31/B31,0) -> 0 | F31: =B31-D31 -> 0
C32: =IFERROR(B32/$B$36,0) -> 0
C33: =IFERROR(B33/$B$36,0) -> 0
C34: =IFERROR(B34/$B$36,0) -> 0
C35: =IFERROR(B35/$B$36,0) -> 0 | E35: =IFERROR(D35/B35,0) -> 0 | F35: =B35-D35 -> 0
A36: 合 计 | B36: =B25+B29 -> 0 | D36: =D25+D29 -> 0 | E36: =IFERROR(D36/B36,0) -> 0 | F36: =B36-D36 -> 0
A37: 续：
A38: 类 别 | B38: 上年年末余额
B39: 账面余额 | D39: 坏账准备 | F39: 账面价值
B40: 金额 | C40: 比例(%) | D40: 金额 | E40: 预期信用损失率(%)
A41: 按单项计提坏账准备 | C41: =IFERROR(B41/$B$36,0) -> 0 | E41: =IFERROR(D41/B41,0) -> 0 | F41: =B41-D41 -> 0
...

Sheet 附注披露信息(国企)
A1: 致同会计师事务所
A2: 附注披露信息（国企）
A3: =底稿目录!A2 -> 被审计单位名称： | C3: =底稿目录!A4 -> 编制人： | E3: =底稿目录!A5 -> 编制日期： | J3: 索引号：
A4: =底稿目录!A3 -> 截止日：202X年12月31日 | C4: =底稿目录!A6 -> 复核人： | E4: =底稿目录!A7 -> 复核日期： | J4: 页 次：
A5: 应收账款附注
A6: 账 龄 | B6: 期末数 | C6: 期初数
A7: 1年以内（含1年） | B7: ='明细表D2-2'!AC26 -> 0 | C7: ='明细表D2-2'!I26 -> 0
A8: 1至2年 | B8: ='明细表D2-2'!AD26 -> 0 | C8: ='明细表D2-2'!J26 -> 0
A9: 2至3年 | B9: ='明细表D2-2'!AE26 -> 0 | C9: ='明细表D2-2'!K26 -> 0
A10: 3至4年 | B10: ='明细表D2-2'!AF26 -> 0 | C10: ='明细表D2-2'!L26 -> 0
A11: 4至5年 | B11: ='明细表D2-2'!AG26 -> 0 | C11: ='明细表D2-2'!M26 -> 0
A12: 5年以上 | B12: ='明细表D2-2'!AH26 -> 0 | C12: ='明细表D2-2'!N26 -> 0
A13: 小 计 | B13: =SUM(B7:B12) -> 0 | C13: =SUM(C7:C12) -> 0
A14: 减：坏账准备
A15: 合 计 | B15: =C13-B14 -> 0 | C15: =C13-C14 -> 0
A16: （1）按坏账准备计提方法分类披露应收账款
A17: 类 别 | B17: 期末数 | G17: 期初数
B18: 账面余额 | D18: 坏账准备 | F18: 账面 | G18: 账面余额 | I18: 坏账准备 | K18: 账面
B19: 金额 | C19: 比例(%) | D19: 金额 | E19: 预期信用损失率(%) | F19: 价值 | G19: 金额 | H19: 比例(%) | I19: 金额 | J19: 预期信用损失率(%) | K19: 价值
A20: 按单项计提坏账准备 | C20: =IFERROR(B20/$B$28*100,0) -> 0 | E20: =IFERROR(D20/B20*100,0) -> 0 | F20: =B20-D20 -> 0 | H20: =IFERROR(G20/$G$28*100,0) -> 0 | J20: =IFERROR(I20/G20*100,0) -> 0 | K20: =G20-I20 -> 0
A21: 按组合计提坏账准备 | C21: =IFERROR(B21/$B$28*100,0) -> 0 | E21: =IFERROR(D21/B21*100,0) -> 0 | F21: =B21-D21 -> 0 | H21: =IFERROR(G21/$G$28*100,0) -> 0 | J21: =IFERROR(I21/G21*100,0) -> 0 | K21: =G21-I21 -> 0
A22: 其中：
A23: =#REF! -> #REF! | C23: =IFERROR(B23/$B$28*100,0) -> 0 | E23: =IFERROR(D23/B23*100,0) -> 0 | F23: =B23-D23 -> 0 | H23: =IFERROR(G23/$G$28*100,0) -> 0 | J23: =IFERROR(I23/G23*100,0) -> 0 | K23: =G23-I23 -> 0
A24: =#REF! -> #REF! | C24: =IFERROR(B24/$B$28*100,0) -> 0 | E24: =IFERROR(D24/B24*100,0) -> 0 | F24: =B24-D24 -> 0 | H24: =IFERROR(G24/$G$28*100,0) -> 0 | J24: =IFERROR(I24/G24*100,0) -> 0 | K24: =G24-I24 -> 0
A25: =#REF! -> #REF! | C25: =IFERROR(B25/$B$28*100,0) -> 0 | E25: =IFERROR(D25/B25*100,0) -> 0 | F25: =B25-D25 -> 0 | H25: =IFERROR(G25/$G$28*100,0) -> 0 | J25: =IFERROR(I25/G25*100,0) -> 0 | K25: =G25-I25 -> 0
A26: =#REF! -> #REF! | C26: =IFERROR(B26/$B$28*100,0) -> 0 | E26: =IFERROR(D26/B26*100,0) -> 0 | F26: =B26-D26 -> 0 | H26: =IFERROR(G26/$G$28*100,0) -> 0 | J26: =IFERROR(I26/G26*100,0) -> 0 | K26: =G26-I26 -> 0
A27: =#REF! -> #REF! | C27: =IFERROR(B27/$B$28*100,0) -> 0 | E27: =IFERROR(D27/B27*100,0) -> 0 | F27: =B27-D27 -> 0 | H27: =IFERROR(G27/$G$28*100,0) -> 0 | J27: =IFERROR(I27/G27*100,0) -> 0 | K27: =G27-I27 -> 0
A28: 合 计 | B28: =B20+B21 -> 0 | C28: =IFERROR(B28/$B$28*100,0) -> 0 | D28: =D20+D21 -> 0 | E28: =IFERROR(D28/B28*100,0) -> 0 | F28: =F20+F21 -> 0 | G28: =G20+G21 -> 0 | H28: =IFERROR(G28/$G$28*100,0) -> 0 | I28: =I20+I21 -> 0 | J28: =IFERROR(I28/G28*100,0) -> 0 | K28: =K20+K21 -> 0
A29: 期末，按单项计提坏账准备的应收账款：
A30: 债务人名称 | B30: 账面余额 | C30: 坏账准备 | D30: 账龄 | E30: 预期信用损失率（%）
A33: 合 计 | B33: =SUM(B31:B32) -> 0 | C33: =SUM(C31:C32) -> 0 | D33: —— | E33: —— | F33: ——
A34: 按信用风险特征组合计提坏账准备的应收账款：
A35: 组合计提项目：组合1
A36: 账龄 | B36: 期末数
B37: 账面余额 | D37: 坏账准备
B38: 应收账款 | C38: 比例（%）
A39: 1年以内（含1年）
A40: 1至2年
A41: 2至3年
A42: 3至4年
...

Sheet 明细表D2-2
A1: 致同会计师事务所 | T1: 致同会计师事务所
A2: 应收账款原值明细表 | T2: 应收账款原值明细表
A3: =底稿目录!A2 -> 被审计单位名称： | F3: =底稿目录!A4 -> 编制人： | J3: =底稿目录!A5 -> 编制日期： | R3: 索引号： | S3: D2-2 | T3: =底稿目录!A2 -> 被审计单位名称： | AB3: =底稿目录!A4 -> 编制人： | AG3: =底稿目录!A5 -> 编制日期： | AL3: 索引号： | AM3: D2-2
A4: =底稿目录!A3 -> 截止日：202X年12月31日 | F4: =底稿目录!A6 -> 复核人： | J4: =底稿目录!A7 -> 复核日期： | R4: 页次： | T4: =底稿目录!A3 -> 截止日：202X年12月31日 | AB4: =底稿目录!A6 -> 复核人： | AG4: =底稿目录!A7 -> 复核日期： | AL4: 页次：
A5: 一、审计目标:
A6: 应收账款以恰当的金额包括在财务报表中，与之相关的计价调整已恰当记录。
A7: 二、审计过程：
A8: 1.列示科目明细表，关注应收账款贷方非收款减少和借方其他调整的情况。 | H8: 4. 对挂账时间超过三年以上本期又没有发生额或发生额很小的应收账款，要求企业说明原因提供对方单位情况，根据情况进行调整。
A9: 2.与客户讨论并记录各主要明细项目的性质，并对波动较大的内容进行分析。根据相关审计情况，确定调整事项。 | H9: 5. 关注关联方（包括持股5%以上(含5%)股东）款项的变动情况，对异常情况要查明原因。
A10: 3.对应收账款进行账龄分析，结合账龄的分析关注长期收不回款项的性质。
A11: 序号 | B11: 客户名称 | C11: 公司代码 | D11: 关联方类型 | E11: 期初未审余额 | F11: 期初账项调整 | G11: 期初重分类调整 | H11: 期初审定余额 | I11: 期初审定账龄 | O11: 借方发生 | P11: 贷方发生 | Q11: 期末余额 | R11: 被审计单位重分类调整 | S11: 期末未审余额 | T11: 期末未审账龄 | Z11: 账项调整 | AA11: 重分类调整 | AB11: 期末审定余额 | AC11: 期末审定账龄 | AI11: 信用风险组合方式 | AJ11: 组合名称 | AK11: 是否函证 | AL11: 期后回款 | AM11: 备注
I12: 1年以内 | J12: 1-2年 | K12: 2-3年 | L12: 3-4年 | M12: 4-5年 | N12: 5年以上 | Q12: 期末余额 | S12: 期末余额 | T12: 1年以内 | U12: 1-2年 | V12: 2-3年 | W12: 3-4年 | X12: 4-5年 | Y12: 5年以上 | AC12: 1年以内 | AD12: 1-2年 | AE12: 2-3年 | AF12: 3-4年 | AG12: 4-5年 | AH12: 5年以上
A13: 1 | Q13: =E13+O13-P13 -> 0 | S13: =Q13+R13 -> 0 | AB13: =S13+Z13+AA13 -> 0 | AI13: 单项计提 | AJ13: 单项计提
A14: 2 | Q14: =E14+O14-P14 -> 0 | S14: =Q14+R14 -> 0 | AB14: =S14+Z14+AA14 -> 0 | AI14: 客户类型组合 | AJ14: 组合1
A15: 3 | Q15: =E15+O15-P15 -> 0 | S15: =Q15+R15 -> 0 | AB15: =S15+Z15+AA15 -> 0 | AI15: 客户类型组合 | AJ15: 组合2
A16: 4 | Q16: =E16+O16-P16 -> 0 | S16: =Q16+R16 -> 0 | AB16: =S16+Z16+AA16 -> 0 | AI16: 客户类型组合 | AJ16: 组合3
A17: 5 | Q17: =E17+O17-P17 -> 0 | S17: =Q17+R17 -> 0 | AB17: =S17+Z17+AA17 -> 0 | AI17: 客户类型组合 | AJ17: 组合4
A18: 6 | Q18: =E18+O18-P18 -> 0 | S18: =Q18+R18 -> 0 | AB18: =S18+Z18+AA18 -> 0 | AI18: 客户类型组合 | AJ18: 组合X
A19: 7 | Q19: =E19+O19-P19 -> 0 | S19: =Q19+R19 -> 0 | AB19: =S19+Z19+AA19 -> 0
A20: 8 | Q20: =E20+O20-P20 -> 0 | S20: =Q20+R20 -> 0 | AB20: =S20+Z20+AA20 -> 0
A21: 9 | Q21: =E21+O21-P21 -> 0 | S21: =Q21+R21 -> 0 | AB21: =S21+Z21+AA21 -> 0
A22: 10 | Q22: =E22+O22-P22 -> 0 | S22: =Q22+R22 -> 0 | AB22: =S22+Z22+AA22 -> 0
A23: 11 | Q23: =E23+O23-P23 -> 0 | S23: =Q23+R23 -> 0 | AB23: =S23+Z23+AA23 -> 0
A24: 12 | Q24: =E24+O24-P24 -> 0 | S24: =Q24+R24 -> 0 | AB24: =S24+Z24+AA24 -> 0
A25: …… | Q25: =E25+O25-P25 -> 0 | S25: =Q25+R25 -> 0 | AB25: =S25+Z25+AA25 -> 0
A26: 合计 | E26: =SUM(E13:E25) -> 0 | F26: =SUM(F13:F25) -> 0 | G26: =SUM(G13:G25) -> 0 | H26: =SUM(H13:H25) -> 0 | I26: =SUM(I13:I25) -> 0 | J26: =SUM(J13:J25) -> 0 | K26: =SUM(K13:K25) -> 0 | L26: =SUM(L13:L25) -> 0 | ... AH26: =SUM(AH13:AH25) -> 0
A27: 账龄占比 | H27: =IF((H26-SUM(I26:N26)=0),"OK","账龄与审定不匹配") -> OK | I27: =ROUND(I26/$H$26,4) -> #DIV/0! | J27: =ROUND(J26/$H$26,4) -> #DIV/0! | K27: =ROUND(K26/$H$26,4) -> #DIV/0! | L27: =ROUND(L26/$H$26,4) -> #DIV/0! | M27: =ROUND(M26/$H$26,4) -> #DIV/0! | N27: =ROUND(N26/$H$26,4) -> #DIV/0! | S27: =IF((S26=E26+O26-P26),"OK","否") -> OK | T27: =ROUND(T26/$S$26,4) -> #DIV/0! | U27: =ROUND(U26/$S$26,4) -> #DIV/0! | V27: =ROUND(V26/$S$26,4) -> #DIV/0! | W27: =ROUND(W26/$S$26,4) -> #DIV/0! | X27: =ROUND(X26/$S$26,4) -> #DIV/0! | Y27: =ROUND(Y26/$S$26,4) -> #DIV/0! | AB27: =IF((AB26-SUM(AC26:AH26)=0),"OK","账龄与审定不匹配") -> OK | AC27: =ROUND(AC26/$AB$26,4) -> #DIV/0! | AD27: =ROUND(AD26/$AB$26,4) -> #DIV/0! | AE27: =ROUND(AE26/$AB$26,4) -> #DIV/0! | AF27: =ROUND(AF26/$AB$26,4) -> #DIV/0! | AG27: =ROUND(AG26/$AB$26,4) -> #DIV/0! | AH27: =ROUND(AH26/$AB$26,4) -> #DIV/0!
A28: 账龄逻辑校验 | AD28: =IF(AD26<=T26,TRUE,FALSE) -> TRUE | AE28: =IF(AE26<=J26,TRUE,FALSE) -> TRUE | AF28: =IF(AF26<=K26,TRUE,FALSE) -> TRUE | AG28: =IF(AG26<=L26,TRUE,FALSE) -> TRUE | AH28: =IF(AH26<=(M26+N26),TRUE,FALSE) -> TRUE
A29: 三、审计说明：
A33: 四、审计结论：

Sheet 坏账准备明细表D2-3
A1: 致同会计师事务所
A2: 应收账款坏账准备明细表
A3: =底稿目录!A2 -> 被审计单位名称： | E3: =底稿目录!A4 -> 编制人： | I3: =底稿目录!A5 -> 编制日期： | M3: 索引号： | N3: D2-3
A4: =底稿目录!A3 -> 截止日：202X年12月31日 | E4: =底稿目录!A6 -> 复核人： | I4: =底稿目录!A7 -> 复核日期： | M4: 页次：
A5: 一、审计目标:
A6: 应收账款以恰当的金额包括在财务报表中，与之相关的计价调整已恰当记录。
A7: 二、审计过程：
A8: 1.……
A10: 项目 | B10: 期初数 | F10: 本期增加 | H10: 本期减少 | K10: 期末数
B11: 期初未审数 | C11: 期初账项调整 | D11: 重分类调整 | E11: 期初审定数 | F11: 计提 | G11: 其他增加 | H11: 转回 | I11: 核销 | J11: 其他减少 | K11: 期末未审数 | L11: 期末账项调整 | M11: 重分类调整 | N11: 期末审定数
A12: 按单项评估计提 | B12: =SUM(B13:B16) -> 0 | C12: =SUM(C13:C16) -> 0 | D12: =SUM(D13:D16) -> 0 | E12: =SUM(E13:E16) -> 0 | F12: =SUM(F13:F16) -> 0 | G12: =SUM(G13:G16) -> 0 | H12: =SUM(H13:H16) -> 0 | I12: =SUM(I13:I16) -> 0 | ... N12: =SUM(N13:N16) -> 0
A13: 其中： | E13: =B13+C13+D13 -> 0 | K13: =B13+SUM(F13:G13)-SUM(H13:J13) -> 0 | N13: =K13+L13+M13 -> 0
E14: =B14+C14+D14 -> 0 | K14: =B14+SUM(F14:G14)-SUM(H14:J14) -> 0 | N14: =K14+L14+M14 -> 0
E15: =B15+C15+D15 -> 0 | K15: =B15+SUM(F15:G15)-SUM(H15:J15) -> 0 | N15: =K15+L15+M15 -> 0
E16: =B16+C16+D16 -> 0 | K16: =B16+SUM(F16:G16)-SUM(H16:J16) -> 0 | N16: =K16+L16+M16 -> 0
A17: 信用风险组合计提 | B17: =SUM(B18:B20) -> 0 | C17: =SUM(C18:C20) -> 0 | D17: =SUM(D18:D20) -> 0 | E17: =SUM(E18:E21) -> 0 | F17: =SUM(F18:F20) -> 0 | G17: =SUM(G18:G20) -> 0 | H17: =SUM(H18:H20) -> 0 | I17: =SUM(I18:I20) -> 0 | J17: =SUM(J18:J20) -> 0 | K17: =SUM(K18:K21) -> 0 | L17: =SUM(L18:L20) -> 0 | M17: =SUM(M18:M20) -> 0 | N17: =SUM(N18:N21) -> 0
A18: 其中： | E18: =B18+C18+D18 -> 0 | K18: =B18+SUM(F18:G18)-SUM(H18:J18) -> 0 | N18: =K18+L18 -> 0
E19: =B19+C19+D19 -> 0 | K19: =B19+SUM(F19:G19)-SUM(H19:J19) -> 0 | N19: =K19+L19 -> 0
E20: =B20+C20+D20 -> 0 | K20: =B20+SUM(F20:G20)-SUM(H20:J20) -> 0 | N20: =K20+L20 -> 0
E21: =B21+C21+D21 -> 0 | K21: =B21+SUM(F21:G21)-SUM(H21:J21) -> 0 | N21: =K21+L21 -> 0
A22: 合计 | B22: =B12+B17 -> 0 | C22: =C12+C17 -> 0 | D22: =D12+D17 -> 0 | E22: =E12+E17 -> 0 | F22: =F12+F17 -> 0 | G22: =G12+G17 -> 0 | H22: =H12+H17 -> 0 | I22: =I12+I17 -> 0 | ... N22: =N12+N17 -> 0
A23: 三、审计说明：
A27: 四、审计结论：

Sheet 调整分录汇总表D2-4
A1: 致同会计师事务所
A2: 应收账款调整分录汇总表
A3: =底稿目录!A2 -> 被审计单位名称： | D3: =底稿目录!A4 -> 编制人： | G3: =底稿目录!A5 -> 编制日期： | I3: 索引号： | J3: D2-4
A4: =底稿目录!A3 -> 截止日：202X年12月31日 | D4: =底稿目录!A6 -> 复核人： | G4: =底稿目录!A7 -> 复核日期： | I4: 页次：
A5: 调整事项说明 | B5: 类别（报表调整/账项调整/其他） | C5: 报表项目 | D5: 科目名称 | E5: 附注项目 | F5: …… | G5: 借方调整金额 | H5: 贷方调整金额 | I5: 索引 | J5: 备注
A23: 提示：本底稿适用于调整分录较多、较复杂的项目，且仅列示与本报表项目相关的审计调整。项目组可根据项目实际情况选择是否使用该底稿。

Sheet GT_Custom
A1: C1 | B1: Custom 1
A2: C2 | B2: Custom 2
A3: C3 | B3: Custom 3
A4: C4 | B4: Custom 4
A5: C5 | B5: Custom 5
A6: C6 | B6: Custom 6
A7: C7 | B7: Custom 7
A8: C8 | B8: Custom 8
