Workbook

Sheet 附注披露信息(上市公司）D2-1
A1: 致同会计师事务所
A2: 附注披露信息（上市公司）
A3: =#REF! -> #REF! | C3: =#REF! -> #REF! | E3: =#REF! -> #REF! | F3: 索引：D2-1
A4: =#REF! -> #REF! | C4: =#REF! -> #REF! | E4: =#REF! -> #REF! | F4: 页次：
A5: 附注披露信息：
A6: 应收账款（以下不适用的，请删除）
A7: （1）应收账款按种类披露
A8: 种类 | B8: 期末数
B9: 金 额 | C9: 比例% | D9: 坏账准备 | E9: 计提比例% | F9: 净额
A10: 单项计提坏账准备的应收账款 | B10: =#REF! -> #REF! | C10: =B10/$B$17 -> #REF! | D10: =#REF! -> #REF! | E10: =IF(B10=0,,D10/B10) -> #REF! | F10: =B10-D10 -> #REF!
A11: 按组合计提坏账准备的应收账款
A12: 其中：账龄组合 | B12: =#REF! -> #REF! | C12: =B12/$B$17 -> #REF! | D12: =#REF! -> #REF! | E12: =IF(B12=0,,D12/B12) -> #REF! | F12: =B12-D12 -> #REF!
A13: 客户类型组合 | B13: =#REF! -> #REF! | C13: =B13/$B$17 -> #REF! | D13: =#REF! -> #REF! | E13: =IF(B13=0,,D13/B13) -> #REF! | F13: =B13-D13 -> #REF!
A14: 产品类型组合 | C14: =B14/$B$17 -> #REF! | E14: =IF(B14=0,,D14/B14) -> 0 | F14: =B14-D14 -> 0
A15: ……组合 | C15: =B15/$B$17 -> #REF! | E15: =IF(B15=0,,D15/B15) -> 0 | F15: =B15-D15 -> 0
A16: 组合小计 | B16: =SUM(B12:B15) -> #REF! | C16: =B16/$B$17 -> #REF! | D16: =SUM(D12:D15) -> #REF! | E16: =IF(B16=0,,D16/B16) -> #REF! | F16: =SUM(F12:F15) -> #REF!
A17: 合 计 | B17: =SUM(B10+B16) -> #REF! | C17: =B17/B17 -> #REF! | D17: =SUM(D10+D16) -> #REF! | E17: =IF(B17=0,,D17/B17) -> #REF! | F17: =SUM(F10+F16) -> #REF!
A18: 应收账款按种类披露（续）
A19: 种类 | B19: 期初数
B20: 金 额 | C20: 比例% | D20: 坏账准备 | E20: 计提比例% | F20: 净额
A21: 单项计提坏账准备的应收账款 | C21: =IF($B$28=0,0,B21/$B$28) -> 0 | E21: =IF(B21=0,0,D21/B21) -> 0 | F21: =B21-D21 -> 0
A22: 按组合计提坏账准备的应收账款
A23: 其中：账龄组合 | C23: =IF($B$28=0,0,B23/$B$28) -> 0 | E23: =IF(B23=0,0,D23/B23) -> 0 | F23: =B23-D23 -> 0
A24: 客户类型组合 | C24: =IF($B$28=0,0,B24/$B$28) -> 0 | E24: =IF(B24=0,0,D24/B24) -> 0 | F24: =B24-D24 -> 0
A25: 产品类型组合 | C25: =IF($B$28=0,0,B25/$B$28) -> 0 | E25: =IF(B25=0,0,D25/B25) -> 0 | F25: =B25-D25 -> 0
A26: ……组合 | C26: =IF($B$28=0,0,B26/$B$28) -> 0 | E26: =IF(B26=0,0,D26/B26) -> 0 | F26: =SUM(F23:F25) -> 0
A27: 组合小计 | B27: =SUM(B23:B26) -> 0 | C27: =SUM(C23:C26) -> 0 | D27: =SUM(D23:D26) -> 0 | E27: =SUM(E23:E26) -> 0 | F27: =B27-D27 -> 0
A28: 合 计 | B28: =SUM(B21+B27) -> 0 | C28: =SUM(C21+C27) -> 0 | D28: =SUM(D21+D27) -> 0 | E28: =SUM(E21+E27) -> 0 | F28: =SUM(F21+F27) -> 0
A29: 注：填写组合名称。账面余额中的比例按期末该类应收账款除以应收账款合计数计算，坏账准备比例按该类应收账款期末已计提坏账准备除以期末该类应收账款余额计算。
A30: 说明：
A31: ①期末单项计提坏账准备的应收账款
A32: 应收账款（按单位） | B32: 账面余额 | C32: 坏账准备 | D32: 计提比例% | E32: 计提理由
D33: =IF(B33=0,0,C33/B33) -> 0
D34: =IF(B34=0,0,C34/B34) -> 0
D35: =IF(B35=0,0,C35/B35) -> 0
D36: =IF(B36=0,0,C36/B36) -> 0
D37: =IF(B37=0,0,C37/B37) -> 0
A38: 合 计 | B38: =SUM(B33:B37) -> 0 | C38: =SUM(C33:C37) -> 0 | D38: =IF(B38=0,0,C38/B38) -> 0
A39: ②按账龄组合计提坏账准备的应收账款：（不适用的删除）
A40: 账 龄 | B40: 期末数
...

Sheet 附注披露信息（国企）D2-1
A1: 致同会计师事务所
A2: 附注披露信息（国企）
A3: =#REF! -> #REF! | C3: =#REF! -> #REF! | E3: =#REF! -> #REF! | G3: 索引：D2-1
A4: =#REF! -> #REF! | C4: =#REF! -> #REF! | E4: =#REF! -> #REF! | G4: 页次：1
A5: 附注披露信息：
A6: 应收账款
A7: 应收账款按种类披露
A8: 种 类 | B8: 期末数
B9: 账面余额 | C9: 比例% | D9: 坏账准备 | E9: 比例%
A10: 单项计提坏账准备的应收账款 | B10: =#REF! -> #REF! | C10: =IF($B$17=0,0,B10/$B$17) -> #REF! | D10: =#REF! -> #REF! | E10: =IF(B10=0,0,D10/B10) -> #REF!
A11: 按组合计提坏账准备的应收账款
A12: 其中：账龄组合 | B12: =#REF! -> #REF! | C12: =IF($B$17=0,0,B12/$B$17) -> #REF! | D12: =#REF! -> #REF! | E12: =IF(B12=0,0,D12/B12) -> #REF!
A13: 客户类型组合 | B13: =#REF! -> #REF! | C13: =IF($B$17=0,0,B13/$B$17) -> #REF! | D13: =#REF! -> #REF! | E13: =IF(B13=0,0,D13/B13) -> #REF!
A14: 产品类型组合 | C14: =IF($B$17=0,0,B14/$B$17) -> #REF! | E14: =IF(B14=0,0,D14/B14) -> 0
A15: ……组合 | C15: =IF($B$17=0,0,B15/$B$17) -> #REF! | E15: =IF(B15=0,0,D15/B15) -> 0
A16: 组合小计 | B16: =SUM(B12:B15) -> #REF! | C16: =IF($B$17=0,0,B16/$B$17) -> #REF! | D16: =SUM(D12:D15) -> #REF! | E16: =IF(B16=0,0,D16/B16) -> #REF!
A17: 合 计 | B17: =SUM(B10+B16) -> #REF! | C17: =SUM(C10+C16) -> #REF! | D17: =SUM(D10+D16) -> #REF! | E17: =IF(B17=0,0,D17/B17) -> #REF!
A18: 应收账款按种类披露（续）
A19: 种 类 | B19: 年初数
B20: 账面余额 | C20: 比例% | D20: 坏账准备 | E20: 比例%
A21: 单项计提坏账准备的应收账款 | C21: =IF($B$28=0,0,B21/$B$28) -> 0 | E21: =IF(B21=0,0,D21/B21) -> 0
A22: 按组合计提坏账准备的应收账款
A23: 其中：账龄组合 | C23: =IF($B$28=0,0,B23/$B$28) -> 0 | E23: =IF(B23=0,0,D23/B23) -> 0
A24: 客户类型组合 | C24: =IF($B$28=0,0,B24/$B$28) -> 0 | E24: =IF(B24=0,0,D24/B24) -> 0
A25: 产品类型组合 | C25: =IF($B$28=0,0,B25/$B$28) -> 0 | E25: =IF(B25=0,0,D25/B25) -> 0
A26: ……组合 | C26: =IF($B$28=0,0,B26/$B$28) -> 0 | E26: =IF(B26=0,0,D26/B26) -> 0
A27: 组合小计 | B27: =SUM(B23:B26) -> 0 | C27: =IF($B$28=0,0,B27/$B$28) -> 0 | D27: =SUM(D23:D26) -> 0 | E27: =IF(B27=0,0,D27/B27) -> 0
A28: 合 计 | B28: =SUM(B21+B26+B27) -> 0 | C28: =SUM(C21+C26+C27) -> 0 | D28: =SUM(D21+D26+D27) -> 0 | E28: =IF(B28=0,0,D28/B28) -> 0
A29: （注：①填写组合名称。②账面余额中的比例按年末该类应收账款除以应收账款余额合计数计算，坏账准备比例按该类应收账款年末已计提坏账准备除以年末该类应收账款余额计算。）
A30: （1）按组合计提坏账准备的应收账款
A31: A、采用账龄分析法计提坏账准备的应收账款
A32: 账 龄 | B32: 期末数 | E32: 年初数
B33: 账面余额 | D33: 坏账准备 | E33: 账面余额 | G33: 坏账准备
B34: 金额 | C34: 比例(%) | E34: 金额 | F34: 比例(%)
A35: =#REF! -> #REF! | B35: =#REF! -> #REF! | C35: =IF(B35=0,0,B35/$B$41) -> #REF! | D35: =#REF! -> #REF! | F35: =IF(E35=0,0,E35/$E$41) -> 0
A36: =#REF! -> #REF! | B36: =#REF! -> #REF! | C36: =IF(B36=0,0,B36/$B$41) -> #REF! | D36: =#REF! -> #REF! | F36: =IF(E36=0,0,E36/$E$41) -> 0
A37: =#REF! -> #REF! | B37: =#REF! -> #REF! | C37: =IF(B37=0,0,B37/$B$41) -> #REF! | D37: =#REF! -> #REF! | F37: =IF(E37=0,0,E37/$E$41) -> 0
A38: =#REF! -> #REF! | B38: =#REF! -> #REF! | C38: =IF(B38=0,0,B38/$B$41) -> #REF! | D38: =#REF! -> #REF! | F38: =IF(E38=0,0,E38/$E$41) -> 0
A39: =#REF! -> #REF! | B39: =#REF! -> #REF! | C39: =IF(B39=0,0,B39/$B$41) -> #REF! | D39: =#REF! -> #REF! | F39: =IF(E39=0,0,E39/$E$41) -> 0
A40: =#REF! -> #REF! | B40: =#REF! -> #REF! | C40: =IF(B40=0,0,B40/$B$41) -> #REF! | D40: =#REF! -> #REF! | F40: =IF(E40=0,0,E40/$E$41) -> 0
...

Sheet 应收账款分析表D2-5
A1: 致同会计师事务所
A2: 应收账款分析表
A3: =[4]底稿目录!$A$2 -> 被审计单位名称： | C3: =[4]底稿目录!$A$4 -> 编制人： | E3: =[4]底稿目录!$A$5 -> 编制日期： | G3: 索引号： | H3: D2-5
A4: =[4]底稿目录!$A$3 -> 截止日：202X年12月31日 | C4: =[4]底稿目录!$A$6 -> 复核人： | E4: =[4]底稿目录!$A$7 -> 复核日期： | G4: 页次：
A5: 一、审计目标
A6: 1.资产负债表中记录的应收账款是存在的。2.所有应当记录的应收账款均已记录。3. 应收账款以恰当的金额包括在财务报表中，与之相关的计价调整已恰当记录。
A7: 二、审计过程
A8: 1.……
A10: （一）应收账款重要指标分析
A11: 见<D4-6>营业收入重要指标分析底稿
A12: （二）应收账款借方发生额与收入核对
A13: 项目 | B13: 金额 | C13: 数据来源 | D13: 备注
A14: 本期主营业务收入
A15: 增值税率
A16: 收入价税合计 | B16: =B14*(1+B15) -> 0
A17: 本期应收账款借方发生额合计
A18: 收入价税合计与应收账款借方发生额差异 | B18: =B16-B17 -> 0
A19: 差异原因
A20: （三）应收账款贷方发生额分析
B21: 金额 | C21: 数据来源 | D21: 与对方科目核对 | E21: 说明
A22: 本期贷方发生额合计 | C22: 应收账款总账 | D22: N/A | E22: N/A
A23: 其中：银行存款收回款项 | E23: 与银行存款借方发生额核对
A24: 计入应收票据 | E24: 与应收票据借方发生额核对
A25: ……
A26: 差异原因
A27: （四）期末应收账款前十名分析
A28: 客户名称 | B28: 期末账面余额 | C28: 期初账面余额 | D28: 变动金额 | E28: 变动比例 | F28: 账龄 | G28: 信用期 | H28: 逾期金额
A29: 客户1 | D29: =B29-C29 -> 0 | E29: =D29/C29 -> #DIV/0!
A30: 客户2 | D30: =B30-C30 -> 0 | E30: =D30/C30 -> #DIV/0!
A31: 客户3 | D31: =B31-C31 -> 0 | E31: =D31/C31 -> #DIV/0!
A32: 客户4 | D32: =B32-C32 -> 0 | E32: =D32/C32 -> #DIV/0!
A33: 客户5 | D33: =B33-C33 -> 0 | E33: =D33/C33 -> #DIV/0!
A34: 客户6 | D34: =B34-C34 -> 0 | E34: =D34/C34 -> #DIV/0!
A35: 客户7 | D35: =B35-C35 -> 0 | E35: =D35/C35 -> #DIV/0!
A36: 客户8 | D36: =B36-C36 -> 0 | E36: =D36/C36 -> #DIV/0!
A37: 客户9 | D37: =B37-C37 -> 0 | E37: =D37/C37 -> #DIV/0!
A38: 客户10 | D38: =B38-C38 -> 0 | E38: =D38/C38 -> #DIV/0!
A39: 合计 | B39: =SUM(B29:B38) -> 0 | C39: =SUM(C29:C38) -> 0 | D39: =SUM(D29:D38) -> 0 | E39: =D39/C39 -> #DIV/0! | H39: =SUM(H29:H38) -> 0
A40: （五）近两年账龄结构分析
A41: 账龄 | B41: 期末账面余额 | C41: 各账龄占比 | D41: 期初账面余额 | E41: 各账龄占比 | F41: 变动金额 | G41: 变动比例 | H41: 原因分析
...

Sheet GT_Custom
A1: C1 | B1: Custom 1
A2: C2 | B2: Custom 2
A3: C3 | B3: Custom 3
A4: C4 | B4: Custom 4
A5: C5 | B5: Custom 5
A6: C6 | B6: Custom 6
A7: C7 | B7: Custom 7
A8: C8 | B8: Custom 8
