Workbook
Name _1、: #REF!
Name _1、: #REF!
Name _1、: #REF!
Name _1、: #REF!
Name _1、: #REF!
Name _1、: #REF!
Name _1、: #REF!
Name _1、: #REF!
Name _1、受本循环影响的相关交易和账户余额: #REF!
Name _1、受本循环影响的相关交易和账户余额: #REF!
Name _1、受本循环影响的相关交易和账户余额: #REF!
Name _1、受本循环影响的相关交易和账户余额: #REF!
Name _1、受本循环影响的相关交易和账户余额: #REF!
Name _1、受本循环影响的相关交易和账户余额: #REF!
Name _1、受本循环影响的相关交易和账户余额: #REF!
Name _1、受本循环影响的相关交易和账户余额: #REF!
Name _2、主要业务活动: #REF!
Name _2、主要业务活动: #REF!
Name _2、主要业务活动: #REF!
Name _2、主要业务活动: #REF!
Name _2、主要业务活动: #REF!
Name _2、主要业务活动: #REF!
Name _2、主要业务活动: #REF!
Name _2、主要业务活动: #REF!
Name _2、注册会计师通常应在本循环中了解与上述业务活动相关的内部控制_如果计划在其他业务循环中对上述: #REF!
Name _2、注册会计师通常应在本循环中了解与上述业务活动相关的内部控制_如果计划在其他业务循环中对上述: #REF!
Name _2、注册会计师通常应在本循环中了解与上述业务活动相关的内部控制_如果计划在其他业务循环中对上述: #REF!
Name _2、注册会计师通常应在本循环中了解与上述业务活动相关的内部控制_如果计划在其他业务循环中对上述: #REF!
Name _2、注册会计师通常应在本循环中了解与上述业务活动相关的内部控制_如果计划在其他业务循环中对上述: #REF!
Name _2、注册会计师通常应在本循环中了解与上述业务活动相关的内部控制_如果计划在其他业务循环中对上述: #REF!
Name _2、注册会计师通常应在本循环中了解与上述业务活动相关的内部控制_如果计划在其他业务循环中对上述: #REF!
Name _2、注册会计师通常应在本循环中了解与上述业务活动相关的内部控制_如果计划在其他业务循环中对上述: #REF!
Name a暗暗: [1]企业表一!$F$20
Name CarryKnown: #REF!
Name CarryKnown: #REF!
Name CarryKnown: #REF!
Name CarryKnown: #REF!
Name CarryKnown: #REF!
Name CarryKnown: #REF!
Name CarryKnown: #REF!
Name CarryKnown: #REF!
Name CarryKnownTable: #REF!
Name CarryKnownTable: #REF!
Name CarryKnownTable: #REF!
Name CarryKnownTable: #REF!
Name CarryKnownTable: #REF!
Name CarryKnownTable: #REF!
Name CarryKnownTable: #REF!
Name CarryKnownTable: #REF!
Name CarryLikely: #REF!
Name CarryLikely: #REF!
Name CarryLikely: #REF!
Name CarryLikely: #REF!
Name CarryLikely: #REF!
Name CarryLikely: #REF!
Name CarryLikely: #REF!
Name CarryLikely: #REF!
Name CarryLikelyTable: #REF!
Name CarryLikelyTable: #REF!
Name CarryLikelyTable: #REF!

Sheet 预期信用损失的计量测试D2-10
A1: 致同会计师事务所
A2: 预期信用损失的计量测试表（账龄组合）
A3: =[9]底稿目录!$A$2 -> 被审计单位名称： | C3: =[9]底稿目录!$A$4 -> 编制人： | E3: =[9]底稿目录!$A$5 -> 编制日期： | G3: 索引号： | H3: D2-10
A4: =[9]底稿目录!$A$3 -> 截止日：202X年12月31日 | C4: =[9]底稿目录!$A$6 -> 复核人： | E4: =[9]底稿目录!$A$7 -> 复核日期： | G4: 页次：
A5: 一、审计目标：
A6: 评价被审计单位计量金融工具预期信用损失的方法是否反映：通过评价一系列可能的结果而确定的无偏概率加权平均金额，货币时间价值，在资产负债表日无须付出不必要的额外成本或努力即可获得的有关过去事项、当前状况以及未来经济状况预测的合理且有依据的信息。
A7: 二、审计过程：
A8: 1.评价企业评估信用损失的基础是否恰当
A9: 1.1 了解企业是以单项金融工具还是以金融工具组合为基础评估信用损失；
A10: 1.2 评价企业划分信用组合是否以共同风险特征为依据（如类型、风险评级、初始确认日期、剩余合同期间等）。
A11: 2.评价信用损失的计量是否正确
A12: 2.1 评价信用损失是否反映了企业按照原实际利率折现的、根据合同应收的所有合同现金流量与预期收取的所有现金流量之间的差额，即全部现金短缺的现值；
A13: 2.2 评价企业计量金融工具预期信用损失的方法是否反映通过评价一系列可能的结果而确定的无偏概率加权平均金额； | I13: 估计预期信用损失的目的并非对最坏的情形或最好的情形作出估计，取而代之的是，预期信用损失的估计应当始终反映发生信用损失的可能性以及不发生信用损失的可能性。
A14: 2.2 评价企业计量金融工具预期信用损失的方法是否反映货币时间价值； | I14: 由于预期信用损失考虑付款的金额和时间分布，因此即使企业预计可以全额收款但收款时间晚于合同规定的到期期限，也会产生信用损失。
A15: 2.2 评价企业计量金融工具预期信用损失的方法是否反映在资产负债表日无须付出不必要的额外成本或努力即可获得的有关过去事项、当前状况以及未来经济状况预测的合理且有依据的信息。 | I15: 企业对预期信用损失的估计，应当反映相关可观察数据的变化并与其保持方向一致（例如，就业率、房价、商品价格的变化可能导致一项或一组金融工具信用损失的变化）。
A16: （一）在账龄组合基础上计算预期信用损失
A17: 根据历史经验，不同细分客户群体发生损失的情况没有显著差异，因此在根据逾期信息计算减值准备时未进一步区分不同的客户群体。 | I17: 如果企业的历史经验表明不同细分客户群体发生损失的情况存在显著差异，那么企业应当对客户群体进行恰当的分组，在分组基础上运用上述简便方法。企业可用于对资产进行分组的标准可能包括：地理区域、产品类型、客户评级、担保物以及客户类型（如批发和零售客户）。
A18: 账龄划分：
A19: 1年以内 | C19: 或 | D19: 未逾期
A20: 1年-2年 | D20: 逾期30天以内
A21: 2年-3年 | D21: 逾期30-90天
A22: 3年-4年 | D22: 逾期90天-1年
A23: 4年-5年 | D23: 逾期1年-2年
A24: 5年以上 | D24: 逾期2年以上
A25: 不同初始确认日期的信用风险不同，组合划分以账龄/逾期特征为依据，不同组合有不同的预期信用损失。
A27: （二）单项计提的预期信用损失率的确定
A28: 单项计提 | B28: 账面余额 | C28: 不同情形下的未来现金流量① | D28: 折现值② | F28: 发生概率③ | G28: 概率加权④=②×③ | H28: 预期信用损失率⑤ | I28: 对于资产负债表日已发生信用减值但并非购买或源生已发生信用减值的金融资产，信用损失为该金融资产账面余额与按原实际利率折现的估计未来现金流量的现值之间的差额。
D29: 1年 | E29: 2年
A30: XX公司 | B30: 100 | C30: 80 | D30: =40/(1+$B$33)^1 -> 38.095238 | E30: =40/(1+$B$33)^2 -> 36.281179 | F30: 0.75 | G30: =(D30+E30)*F30 -> 55.782313 | I30: 估计预期信用损失的目的并非对最坏的情形或最好的情形作出估计，取而代之的是，预期信用损失的估计应当始终反映发生信用损失的可能性以及不发生信用损失的可能性。
C31: 70 | D31: =30/(1+$B$33)^1 -> 28.571429 | E31: =40/(1+$B$33)^2 -> 36.281179 | F31: 0.15 | G31: =(D31+E31)*F31 -> 9.7278912
C32: 50 | E32: =50/(1+$B$33)^2 -> 45.351474 | F32: 0.1 | G32: =(D32+E32)*F32 -> 4.5351474 | I32: 由于预期信用损失考虑付款的金额和时间分布，因此即使企业预计可以全额收款但收款时间晚于合同规定的到期期限，也会产生信用损失。
A33: 实际利率 | B33: 0.05 | C33: 合计 | D33: -- | E33: -- | F33: =IF(B30=0,"",SUM(F30:F32)) -> 1 | G33: =SUM(G30:G32) -> 70.045351 | H33: =IF(B30=0,"",(B30-G33)/B30) -> 0.29954649
G34: =(D34+E34)*F34 -> 0 | I34: 企业应当采用相关金融工具初始确认时确定的实际利率或其近似值，将现金流缺口折现为资产负债表日的现值。
G35: =(D35+E35)*F35 -> 0
G36: =(D36+E36)*F36 -> 0
C37: 合计 | D37: -- | E37: -- | F37: =IF(B34=0,"",SUM(F34:F36)) | G37: =SUM(G34:G36) -> 0 | H37: =IF(B34=0,"",(B34-G37)/B34)
G38: =(D38+E38)*F38 -> 0
G39: =(D39+E39)*F39 -> 0
G40: =(D40+E40)*F40 -> 0
C41: 合计 | D41: -- | E41: -- | F41: =IF(B38=0,"",SUM(F38:F40)) | G41: =SUM(G38:G40) -> 0 | H41: =IF(B38=0,"",(B38-G41)/B38)
...

Sheet 预期信用损失的计量测试D2-10 
A1: 致同会计师事务所
A2: 预期信用损失的计量测试表（分组合后按账龄计提）
A3: =[9]底稿目录!$A$2 -> 被审计单位名称： | C3: =[9]底稿目录!$A$4 -> 编制人： | E3: =[9]底稿目录!$A$5 -> 编制日期： | G3: 索引号： | H3: D2-10
A4: =[9]底稿目录!$A$3 -> 截止日：202X年12月31日 | C4: =[9]底稿目录!$A$6 -> 复核人： | E4: =[9]底稿目录!$A$7 -> 复核日期： | G4: 页次：
A5: 一、审计目标：
A6: 评价被审计单位计量金融工具预期信用损失的方法是否反映：通过评价一系列可能的结果而确定的无偏概率加权平均金额，货币时间价值，在资产负债表日无须付出不必要的额外成本或努力即可获得的有关过去事项、当前状况以及未来经济状况预测的合理且有依据的信息。
A7: 二、审计过程：
A8: 1.评价企业评估信用损失的基础是否恰当
A9: 1.1 了解企业是以单项金融工具还是以金融工具组合为基础评估信用损失；
A10: 1.2 评价企业划分信用组合是否以共同风险特征为依据（如类型、风险评级、初始确认日期、剩余合同期间等）。
A11: 2.评价信用损失的计量是否正确
A12: 2.1 评价信用损失是否反映了企业按照原实际利率折现的、根据合同应收的所有合同现金流量与预期收取的所有现金流量之间的差额，即全部现金短缺的现值； | I12: 由于预期信用损失考虑付款的金额和时间分布，因此即使企业预计可以全额收款但收款时间晚于合同规定的到期期限，也会产生信用损失。
A13: 2.2 评价企业计量金融工具预期信用损失的方法是否反映通过评价一系列可能的结果而确定的无偏概率加权平均金额； | I13: 估计预期信用损失的目的并非对最坏的情形或最好的情形作出估计，取而代之的是，预期信用损失的估计应当始终反映发生信用损失的可能性以及不发生信用损失的可能性。
A14: 2.2 评价企业计量金融工具预期信用损失的方法是否反映货币时间价值； | I14: 由于预期信用损失考虑付款的金额和时间分布，因此即使企业预计可以全额收款但收款时间晚于合同规定的到期期限，也会产生信用损失。
A15: 2.2 评价企业计量金融工具预期信用损失的方法是否反映在资产负债表日无须付出不必要的额外成本或努力即可获得的有关过去事项、当前状况以及未来经济状况预测的合理且有依据的信息。 | I15: 企业对预期信用损失的估计，应当反映相关可观察数据的变化并与其保持方向一致（例如，就业率、房价、商品价格的变化可能导致一项或一组金融工具信用损失的变化）。
A16: （一）分组合后按账龄计提预期信用损失
A17: 确定组合的依据如下： | I17: 如果企业的历史经验表明不同细分客户群体发生损失的情况存在显著差异，那么企业应当对客户群体进行恰当的分组，在分组基础上运用上述简便方法。企业可用于对资产进行分组的标准可能包括：地理区域、产品类型、客户评级、担保物以及客户类型（如批发和零售客户）。
A18: 应收账款组合1： | B18: 应收国有企业客户
A19: 应收账款组合2： | B19: 应收海外企业客户
A20: 应收账款组合3： | B20: 应收关联方
A21: 应收账款组合4： | B21: 应收其他客户
A23: 不不同客户信用评级不同，组合划分以共同风险特征为依据，不同组合有不同的预期信用损失。
A25: （二）单项计提的应收账款预期信用损失率的确定
A26: 单项计提 | B26: 账面余额 | C26: 不同情形下的未来现金流量① | D26: 折现值② | E26: 发生概率③ | F26: 概率加权④=②×③ | G26: 预期信用损失率⑤ | H26: 上期预期信用损失率 | I26: 对于资产负债表日已发生信用减值但并非购买或源生已发生信用减值的金融资产，信用损失为该金融资产账面余额与按原实际利率折现的估计未来现金流量的现值之间的差额。
D27: 0
A28: XX公司 | B28: 100 | C28: 80 | D28: =C28/(1+$D$27)^1 -> 80 | E28: 0.75 | F28: =D28*E28 -> 60 | I28: 估计预期信用损失的目的并非对最坏的情形或最好的情形作出估计，取而代之的是，预期信用损失的估计应当始终反映发生信用损失的可能性以及不发生信用损失的可能性。
C29: 70 | D29: =C29/(1+$D$27)^1 -> 70 | E29: 0.15 | F29: =D29*E29 -> 10.5
C30: 50 | D30: =C30/(1+$D$27)^1 -> 50 | E30: 0.1 | F30: =D30*E30 -> 5 | I30: 由于预期信用损失考虑付款的金额和时间分布，因此即使企业预计可以全额收款但收款时间晚于合同规定的到期期限，也会产生信用损失。
C31: 合计 | D31: -- | E31: =IF(B28=0,"",SUM(E28:E30)) -> 1 | F31: =SUM(F28:F30) -> 75.5 | G31: =IF(B28=0,"",(B28-F31)/B28) -> 0.245
F32: =D32*E32 -> 0 | I32: 企业应当采用相关金融工具初始确认时确定的实际利率或其近似值，将现金流缺口折现为资产负债表日的现值。
F33: =D33*E33 -> 0
F34: =D34*E34 -> 0
C35: 合计 | D35: -- | E35: =IF(B32=0,"",SUM(E32:E34)) | F35: =SUM(F32:F34) -> 0 | G35: =IF(B32=0,"",(B32-F35)/B32)
F36: =D36*E36 -> 0
F37: =D37*E37 -> 0
F38: =D38*E38 -> 0
C39: 合计 | D39: -- | E39: =IF(B36=0,"",SUM(E36:E38)) | F39: =SUM(F36:F38) -> 0 | G39: =IF(B36=0,"",(B36-F39)/B36)
A41: 组合1：
A42: （三）计算历史损失率（示例方法仅供参考）-本示例仅计算了1年的回收率，实务中可以计算多期后考虑平均。 | H42: 【方法可选】
A43: 账龄 | B43: 20X7年末余额 | C43: 20X8收回金额 | D43: 20X8年末余额 | E43: 校验 | F43: 实际回收率 | G43: 历史损失率 | H43: 上期历史损失率
...

Sheet 前瞻性调整D2-10-1（打分卡)
A1: 致同会计师事务所
A2: 前瞻性调整（宏观指标打分卡）
A3: =[9]底稿目录!$A$2 -> 被审计单位名称： | D3: =[9]底稿目录!$A$4 -> 编制人： | G3: =[9]底稿目录!$A$5 -> 编制日期： | I3: 索引号： | J3: D2-10-1
A4: =[9]底稿目录!$A$3 -> 截止日：202X年12月31日 | D4: =[9]底稿目录!$A$6 -> 复核人： | G4: =[9]底稿目录!$A$7 -> 复核日期： | I4: 页 次：
A5: 一、审计目标：
A6: 评价被审计单位计量金融工具预期信用损失的方法是否反映在资产负债表日无须付出不必要的额外成本或努力即可获得的有关过去事项、当前状况以及未来经济状况预测的合理且有依据的信息。 | K6: 企业对预期信用损失的估计，应当反映相关可观察数据的变化并与其保持方向一致（例如，就业率、房价、商品价格的变化可能导致一项或一组金融工具信用损失的变化）。
A7: 二、审计过程：
A8: 1.评价企业选择的用于前瞻性调整的经济指标； | K8: 历史信息是企业计量预期信用损失的重要基准。某些情形下，未经调整的历史信息可能是最佳的合理且有依据的信息。而其他情形下，企业可能需要使用当期数据对历史数据进行调整，以反映当前状况和未来预测的影响，并剔除与未来现金流量不相关的历史因素的影响。 企业对预期信用损失的估计，应当反映相关可观察数据的变化并与其保持方向一致（例如，就业率、房价、商品价格的变化可能导致一项或一组金融工具信用损失的变化）。
A9: 2. 设定评分标准和权重；
A10: 3. 基于历史数据设定评分值与前瞻性调整系数的对照表；
A11: 4. 取得预测的未来经济指标；
A12: 5. 根据评分表确认总得分，然后根据对照表确定前瞻性调整系数。
A13: （一）经济指标
A14: 年度 | B14: GDP增长率 | C14: 广义货币（M2）增长率 | D14: 社会消费品零售总额 | E14: 居民消费者价格指数（CPI） | F14: CPI滞后2季度 | G14: CPI滞后3季度 | H14: 城镇固定资产投资 | I14: 损失率变动 | J14: 备注
A15: 本年度 | B15: 0.061 | C15: 0.13 | D15: 0.083 | E15: 0.028 | F15: 0.027 | G15: 0.023 | H15: -0.3265 | I15: =(I31-G31)/G31 -> 0.16627452
A16: 过去1年 | B16: 0.066 | C16: 0.0699 | D16: 0.09 | E16: 0.019 | F16: 0.019 | G16: 0.021 | H16: -0.5343 | I16: =(G31-E31)/E31 -> 0.31737063
A17: 过去2年 | B17: 0.069 | C17: 0.0811 | D17: 0.102 | E17: 0.018 | F17: 0.015 | G17: 0.009 | H17: -0.0229 | I17: 0.25
A18: 过去3年 | B18: 0.073 | C18: 0.1133 | D18: 0.104 | E18: 0.021 | F18: 0.019 | G18: 0.023 | H18: 0.0652 | I18: 0.185
A19: 过去4年 | B19: 0.078 | C19: 0.1334 | D19: 0.107 | E19: 0.016 | F19: 0.014 | G19: 0.014 | H19: 0.0681 | I19: 0.16
A20: 过去5年 | B20: 0.079 | C20: 0.1101 | D20: 0.1195 | E20: 0.015 | F20: 0.023 | G20: 0.024 | H20: 0.1258 | I20: 0.14
A21: ……
A22: 经济指标说明： | K22: 一般需要选择三项经济指标，且需包含GDP。
A23: 因变量（Y）的来源
A24: 账龄 | B24: 20X5年至20X6年迁徙率 | C24: 20X6年历史损失率 | D24: 20X6年至20X7年迁徙率 | E24: 20X7年历史损失率 | F24: 20X7年至20X8年迁徙率 | G24: 20X8年历史损失率 | H24: 20X8年至20X9年迁徙率 | I24: 20X9年历史损失率 | J24: 平均损失率 | K24: 回归分析中，一般要求样本量是自变量个数的10倍（10 EPV），可通过使用季度数据来增加样本量
A25: ='预期信用损失的计量测试D2-10'!A75 -> 1年以内 | B25: ='预期信用损失的计量测试D2-10'!B75 -> 0 | C25: =B25*C26 -> 0 | D25: ='预期信用损失的计量测试D2-10'!C75 -> 0.21428571 | E25: =D25*E26 -> 0.046875 | F25: ='预期信用损失的计量测试D2-10'!D75 -> 0.22727273 | G25: =F25*G26 -> 0.060606061 | H25: ='预期信用损失的计量测试D2-10'!E75 -> 0.21341463 | I25: =H25*I26 -> 0.058536585 | J25: =AVERAGE(E25,G25,I25) -> 0.055339215
A26: ='预期信用损失的计量测试D2-10'!A76 -> 1年-2年 | B26: ='预期信用损失的计量测试D2-10'!B76 -> 0 | C26: =B26*C27 -> 0 | D26: ='预期信用损失的计量测试D2-10'!C76 -> 0.4375 | E26: =D26*E27 -> 0.21875 | F26: ='预期信用损失的计量测试D2-10'!D76 -> 0.46666667 | G26: =F26*G27 -> 0.26666667 | H26: ='预期信用损失的计量测试D2-10'!E76 -> 0.48 | I26: =H26*I27 -> 0.27428571 | J26: =AVERAGE(E26,G26,I26) -> 0.25323413
A27: ='预期信用损失的计量测试D2-10'!A77 -> 2年-3年 | B27: ='预期信用损失的计量测试D2-10'!B77 -> 0 | C27: =B27*C28 -> 0 | D27: ='预期信用损失的计量测试D2-10'!C77 -> 0.5 | E27: =D27*E28 -> 0.5 | F27: ='预期信用损失的计量测试D2-10'!D77 -> 0.57142857 | G27: =F27*G28 -> 0.57142857 | H27: ='预期信用损失的计量测试D2-10'!E77 -> 0.57142857 | I27: =H27*I28 -> 0.57142857 | J27: =AVERAGE(E27,G27,I27) -> 0.54761905
A28: ='预期信用损失的计量测试D2-10'!A78 -> 3年以上 | B28: ='预期信用损失的计量测试D2-10'!B78 -> 0 | C28: =B28 -> 0 | D28: ='预期信用损失的计量测试D2-10'!C78 -> 1 | E28: =D28 -> 1 | F28: ='预期信用损失的计量测试D2-10'!D78 -> 1 | G28: =F28 -> 1 | H28: ='预期信用损失的计量测试D2-10'!E78 -> 1 | I28: =H28 -> 1 | J28: =AVERAGE(E28,G28,I28) -> 1
A31: 合计 | B31: -- | D31: -- | E31: {=SUM(E25:E28*'预期信用损失的计量测试D2-10'!D67:D70)/'预期信用损失的计量测试D2-10'!D73} -> 0.093390805 | F31: -- | G31: {=SUM(G25:G28*'预期信用损失的计量测试D2-10'!E67:E70)/'预期信用损失的计量测试D2-10'!E73} -> 0.1230303 | H31: -- | I31: {=SUM(I25:I28*'预期信用损失的计量测试D2-10'!F67:F70)/'预期信用损失的计量测试D2-10'!F73} -> 0.14348711 | J31: =AVERAGE(E31,G31,I31) -> 0.11996941
A32: 历史期间系数 | G32: =G31/E31 -> 1.3173706 | I32: =I31/G31 -> 1.1662745
A33: （二）评价标准和权重
A34: 经济指标 | B34: 评分标准 | F34: 百分制赋分 | G34: 权重 | H34: 选择的情形 | I34: 选择原因 | J34: 加权后得分
A35: GDP增长率 | B35: A | C35: 预计提高20%以上 | F35: 100 | G35: 0.35 | H35: D | I35: （四） | J35: =VLOOKUP(H35,B35:F41,5,0)*G35 -> 17.5 | K35: 经济指标根据企业实际情况修改，选择与信用损失相关性高的指标
B36: B | C36: 预计提高10%-20% | F36: 80 | K36: 评分标准、分值根据经济状况修改，反映合理可能的变动幅度
B37: C | C37: 预计提高5%-10% | F37: 65 | K37: 权重根据企业实际情况修改，反映经济指标相关性的高低和不同期间的变化
B38: D | C38: 预计持平（上下变动5%以内） | F38: 50 | K38: 若本年为6%，持平是指预计下年在[6%*(1-5%)]-[6%*(1+5%)]之间
B39: E | C39: 预计降低5%-10% | F39: 35
B40: F | C40: 预计降低10%-20% | F40: 20
B41: G | C41: 预计降低20%以上 | F41: 0
A42: M2增长率 | B42: A | C42: 预计提高20%以上 | F42: 100 | G42: 0.35 | H42: D | I42: （四） | J42: =VLOOKUP(H42,B42:F48,5,0)*G42 -> 17.5
...

Sheet 前瞻性调整D2-10-1（量化分析）
A1: 致同会计师事务所
A2: 前瞻性调整（相关性分析）
A3: =[9]底稿目录!$A$2 -> 被审计单位名称： | D3: =[9]底稿目录!$A$4 -> 编制人： | G3: =[9]底稿目录!$A$5 -> 编制日期： | I3: 索引号： | J3: D2-10-1
A4: =[9]底稿目录!$A$3 -> 截止日：202X年12月31日 | D4: =[9]底稿目录!$A$6 -> 复核人： | G4: =[9]底稿目录!$A$7 -> 复核日期： | I4: 页 次：
A5: 一、审计目标：
A6: 评价被审计单位计量金融工具预期信用损失的方法是否反映在资产负债表日无须付出不必要的额外成本或努力即可获得的有关过去事项、当前状况以及未来经济状况预测的合理且有依据的信息。 | K6: 企业对预期信用损失的估计，应当反映相关可观察数据的变化并与其保持方向一致（例如，就业率、房价、商品价格的变化可能导致一项或一组金融工具信用损失的变化）。
A7: 二、审计过程：
A8: 1.评价企业选择的用于前瞻性调整的经济指标； | K8: 历史信息是企业计量预期信用损失的重要基准。某些情形下，未经调整的历史信息可能是最佳的合理且有依据的信息。而其他情形下，企业可能需要使用当期数据对历史数据进行调整，以反映当前状况和未来预测的影响，并剔除与未来现金流量不相关的历史因素的影响。 企业对预期信用损失的估计，应当反映相关可观察数据的变化并与其保持方向一致（例如，就业率、房价、商品价格的变化可能导致一项或一组金融工具信用损失的变化）。
A9: 2. 计算因变量；
A10: 3. 通过回归分析确定经济指标历史上与损失率或损失率调整之间的关系；
A11: 4. 取得预测的未来经济指标；
A12: 5. 回归方程计算确定前瞻性调整数值。
A13: （一）经济指标
A14: 年度 | B14: GDP增长率 | C14: 广义货币（M2）增长率 | D14: 社会消费品零售总额 | E14: 居民消费者价格指数（CPI） | F14: CPI滞后2季度 | G14: CPI滞后3季度 | H14: 城镇固定资产投资 | I14: 损失率变动Y | J14: 备注
A15: 本年度 | B15: 0.061 | C15: 0.13 | D15: 0.083 | E15: 0.028 | F15: 0.027 | G15: 0.023 | H15: -0.3265 | I15: =(I31-G31)/G31 -> 0.16627452
A16: 过去1年 | B16: 0.066 | C16: 0.0699 | D16: 0.09 | E16: 0.019 | F16: 0.019 | G16: 0.021 | H16: -0.5343 | I16: =(G31-E31)/E31 -> 0.31737063
A17: 过去2年 | B17: 0.069 | C17: 0.0811 | D17: 0.102 | E17: 0.018 | F17: 0.015 | G17: 0.009 | H17: -0.0229 | I17: 0.25
A18: 过去3年 | B18: 0.073 | C18: 0.1133 | D18: 0.104 | E18: 0.021 | F18: 0.019 | G18: 0.023 | H18: 0.0652 | I18: 0.185
A19: 过去4年 | B19: 0.078 | C19: 0.1334 | D19: 0.107 | E19: 0.016 | F19: 0.014 | G19: 0.014 | H19: 0.0681 | I19: 0.16
A20: 过去5年 | B20: 0.079 | C20: 0.1101 | D20: 0.1195 | E20: 0.015 | F20: 0.023 | G20: 0.024 | H20: 0.1258 | I20: 0.14
A21: ……
A22: 经济指标说明： | K22: 一般需要选择两、三项经济指标，且需包含GDP。
A23: （二）因变量（Y）的来源
A24: 账龄 | B24: 20X5年至20X6年迁徙率 | C24: 20X6年历史损失率 | D24: 20X6年至20X7年迁徙率 | E24: 20X7年历史损失率 | F24: 20X7年至20X8年迁徙率 | G24: 20X8年历史损失率 | H24: 20X8年至20X9年迁徙率 | I24: 20X9年历史损失率 | J24: 平均损失率 | K24: 回归分析中，一般要求样本量是自变量个数的10倍（10 EPV），可通过使用季度数据来增加样本量
A25: ='预期信用损失的计量测试D2-10'!A75 -> 1年以内 | B25: ='预期信用损失的计量测试D2-10'!B75 -> 0 | C25: =B25*C26 -> 0 | D25: ='预期信用损失的计量测试D2-10'!C75 -> 0.21428571 | E25: =D25*E26 -> 0.046875 | F25: ='预期信用损失的计量测试D2-10'!D75 -> 0.22727273 | G25: =F25*G26 -> 0.060606061 | H25: ='预期信用损失的计量测试D2-10'!E75 -> 0.21341463 | I25: =H25*I26 -> 0.058536585 | J25: =AVERAGE(E25,G25,I25) -> 0.055339215
A26: ='预期信用损失的计量测试D2-10'!A76 -> 1年-2年 | B26: ='预期信用损失的计量测试D2-10'!B76 -> 0 | C26: =B26*C27 -> 0 | D26: ='预期信用损失的计量测试D2-10'!C76 -> 0.4375 | E26: =D26*E27 -> 0.21875 | F26: ='预期信用损失的计量测试D2-10'!D76 -> 0.46666667 | G26: =F26*G27 -> 0.26666667 | H26: ='预期信用损失的计量测试D2-10'!E76 -> 0.48 | I26: =H26*I27 -> 0.27428571 | J26: =AVERAGE(E26,G26,I26) -> 0.25323413
A27: ='预期信用损失的计量测试D2-10'!A77 -> 2年-3年 | B27: ='预期信用损失的计量测试D2-10'!B77 -> 0 | C27: =B27*C28 -> 0 | D27: ='预期信用损失的计量测试D2-10'!C77 -> 0.5 | E27: =D27*E28 -> 0.5 | F27: ='预期信用损失的计量测试D2-10'!D77 -> 0.57142857 | G27: =F27*G28 -> 0.57142857 | H27: ='预期信用损失的计量测试D2-10'!E77 -> 0.57142857 | I27: =H27*I28 -> 0.57142857 | J27: =AVERAGE(E27,G27,I27) -> 0.54761905
A28: ='预期信用损失的计量测试D2-10'!A78 -> 3年以上 | B28: ='预期信用损失的计量测试D2-10'!B78 -> 0 | C28: =B28 -> 0 | D28: ='预期信用损失的计量测试D2-10'!C78 -> 1 | E28: =D28 -> 1 | F28: ='预期信用损失的计量测试D2-10'!D78 -> 1 | G28: =F28 -> 1 | H28: ='预期信用损失的计量测试D2-10'!E78 -> 1 | I28: =H28 -> 1 | J28: =AVERAGE(E28,G28,I28) -> 1
A31: 合计 | B31: -- | D31: -- | E31: {=SUM(E25:E28*'预期信用损失的计量测试D2-10'!D67:D70)/'预期信用损失的计量测试D2-10'!D73} -> 0.093390805 | F31: -- | G31: {=SUM(G25:G28*'预期信用损失的计量测试D2-10'!E67:E70)/'预期信用损失的计量测试D2-10'!E73} -> 0.1230303 | H31: -- | I31: {=SUM(I25:I28*'预期信用损失的计量测试D2-10'!F67:F70)/'预期信用损失的计量测试D2-10'!F73} -> 0.14348711 | J31: =AVERAGE(E31,G31,I31) -> 0.11996941
A32: 若直接将前瞻性信息用于损失率的调整，则因变量为历史期间损失率的变动比率。
A33: 比较准确的方法应该是将各年损失率偏离长期平均损失率的程度作为因变量。
A34: （三）回归分析
A35: 年度 | B35: X1 | C35: X2 | D35: X3 | E35: X1X2 | F35: X1X3 | G35: X2X3 | H35: X1^2 | I35: X2^2 | J35: X3^2 | K35: 如果企业没有关于特定金融工具的数据来源或此类来源的数据不够充分，那么企业可以使用同行业内对类似金融工具（或一组类似金融工具）的经验数据。
A36: =A15 -> 本年度 | B36: =B15 -> 0.061 | C36: =C15 -> 0.13 | D36: =D15 -> 0.083 | E36: =B36*C36 -> 0.00793 | F36: =B36*D36 -> 0.005063 | G36: =C36*D36 -> 0.01079 | H36: =B36^2 -> 0.003721 | I36: =C36^2 -> 0.0169 | J36: =D36^2 -> 0.006889
A37: =A16 -> 过去1年 | B37: =B16 -> 0.066 | C37: =C16 -> 0.0699 | D37: =D16 -> 0.09 | E37: =B37*C37 -> 0.0046134 | F37: =B37*D37 -> 0.00594 | G37: =C37*D37 -> 0.006291 | H37: =B37^2 -> 0.004356 | I37: =C37^2 -> 0.00488601 | J37: =D37^2 -> 0.0081
A38: =A17 -> 过去2年 | B38: =B17 -> 0.069 | C38: =C17 -> 0.0811 | D38: =D17 -> 0.102 | E38: =B38*C38 -> 0.0055959 | F38: =B38*D38 -> 0.007038 | G38: =C38*D38 -> 0.0082722 | H38: =B38^2 -> 0.004761 | I38: =C38^2 -> 0.00657721 | J38: =D38^2 -> 0.010404
A39: =A18 -> 过去3年 | B39: =B18 -> 0.073 | C39: =C18 -> 0.1133 | D39: =D18 -> 0.104 | E39: =B39*C39 -> 0.0082709 | F39: =B39*D39 -> 0.007592 | G39: =C39*D39 -> 0.0117832 | H39: =B39^2 -> 0.005329 | I39: =C39^2 -> 0.01283689 | J39: =D39^2 -> 0.010816
A40: =A19 -> 过去4年 | B40: =B19 -> 0.078 | C40: =C19 -> 0.1334 | D40: =D19 -> 0.107 | E40: =B40*C40 -> 0.0104052 | F40: =B40*D40 -> 0.008346 | G40: =C40*D40 -> 0.0142738 | H40: =B40^2 -> 0.006084 | I40: =C40^2 -> 0.01779556 | J40: =D40^2 -> 0.011449
A41: =A20 -> 过去5年 | B41: =B20 -> 0.079 | C41: =C20 -> 0.1101 | D41: =D20 -> 0.1195 | E41: =B41*C41 -> 0.0086979 | F41: =B41*D41 -> 0.0094405 | G41: =C41*D41 -> 0.01315695 | H41: =B41^2 -> 0.006241 | I41: =C41^2 -> 0.01212201 | J41: =D41^2 -> 0.01428025
A43: 年度 | B43: X1 | C43: X2 | D43: X3
...

Sheet 变量相关性分析D2-10-2
A1: 致同会计师事务所
A2: 变量相关性分析
A3: =[9]底稿目录!$A$2 -> 被审计单位名称： | D3: =[9]底稿目录!$A$4 -> 编制人： | G3: =[9]底稿目录!$A$5 -> 编制日期： | I3: 索引号： | J3: D2-10-2
A4: =[9]底稿目录!$A$3 -> 截止日：202X年12月31日 | D4: =[9]底稿目录!$A$6 -> 复核人： | G4: =[9]底稿目录!$A$7 -> 复核日期： | I4: 页 次：
A5: 一、审计目标：
A6: 选取相关性最高的指标
A7: 二、审计过程：
A8: （一）经济指标
A9: 年度 | B9: ='前瞻性调整D2-10-1（量化分析）'!B14 -> GDP增长率 | C9: ='前瞻性调整D2-10-1（量化分析）'!C14 -> 广义货币（M2）增长率 | D9: ='前瞻性调整D2-10-1（量化分析）'!D14 -> 社会消费品零售总额 | E9: ='前瞻性调整D2-10-1（量化分析）'!E14 -> 居民消费者价格指数（CPI） | F9: ='前瞻性调整D2-10-1（量化分析）'!F14 -> CPI滞后2季度 | G9: ='前瞻性调整D2-10-1（量化分析）'!G14 -> CPI滞后3季度 | H9: ='前瞻性调整D2-10-1（量化分析）'!H14 -> 城镇固定资产投资 | I9: ='前瞻性调整D2-10-1（量化分析）'!I14 -> 损失率变动Y | J9: 备注
A10: 本年度 | B10: ='前瞻性调整D2-10-1（量化分析）'!B15 -> 0.061 | C10: ='前瞻性调整D2-10-1（量化分析）'!C15 -> 0.13 | D10: ='前瞻性调整D2-10-1（量化分析）'!D15 -> 0.083 | E10: ='前瞻性调整D2-10-1（量化分析）'!E15 -> 0.028 | F10: ='前瞻性调整D2-10-1（量化分析）'!F15 -> 0.027 | G10: ='前瞻性调整D2-10-1（量化分析）'!G15 -> 0.023 | H10: ='前瞻性调整D2-10-1（量化分析）'!H15 -> -0.3265 | I10: ='前瞻性调整D2-10-1（量化分析）'!I15 -> 0.16627452
A11: 过去1年 | B11: ='前瞻性调整D2-10-1（量化分析）'!B16 -> 0.066 | C11: ='前瞻性调整D2-10-1（量化分析）'!C16 -> 0.0699 | D11: ='前瞻性调整D2-10-1（量化分析）'!D16 -> 0.09 | E11: ='前瞻性调整D2-10-1（量化分析）'!E16 -> 0.019 | F11: ='前瞻性调整D2-10-1（量化分析）'!F16 -> 0.019 | G11: ='前瞻性调整D2-10-1（量化分析）'!G16 -> 0.021 | H11: ='前瞻性调整D2-10-1（量化分析）'!H16 -> -0.5343 | I11: ='前瞻性调整D2-10-1（量化分析）'!I16 -> 0.31737063
A12: 过去2年 | B12: ='前瞻性调整D2-10-1（量化分析）'!B17 -> 0.069 | C12: ='前瞻性调整D2-10-1（量化分析）'!C17 -> 0.0811 | D12: ='前瞻性调整D2-10-1（量化分析）'!D17 -> 0.102 | E12: ='前瞻性调整D2-10-1（量化分析）'!E17 -> 0.018 | F12: ='前瞻性调整D2-10-1（量化分析）'!F17 -> 0.015 | G12: ='前瞻性调整D2-10-1（量化分析）'!G17 -> 0.009 | H12: ='前瞻性调整D2-10-1（量化分析）'!H17 -> -0.0229 | I12: ='前瞻性调整D2-10-1（量化分析）'!I17 -> 0.25
A13: 过去3年 | B13: ='前瞻性调整D2-10-1（量化分析）'!B18 -> 0.073 | C13: ='前瞻性调整D2-10-1（量化分析）'!C18 -> 0.1133 | D13: ='前瞻性调整D2-10-1（量化分析）'!D18 -> 0.104 | E13: ='前瞻性调整D2-10-1（量化分析）'!E18 -> 0.021 | F13: ='前瞻性调整D2-10-1（量化分析）'!F18 -> 0.019 | G13: ='前瞻性调整D2-10-1（量化分析）'!G18 -> 0.023 | H13: ='前瞻性调整D2-10-1（量化分析）'!H18 -> 0.0652 | I13: ='前瞻性调整D2-10-1（量化分析）'!I18 -> 0.185
A14: 过去4年 | B14: ='前瞻性调整D2-10-1（量化分析）'!B19 -> 0.078 | C14: ='前瞻性调整D2-10-1（量化分析）'!C19 -> 0.1334 | D14: ='前瞻性调整D2-10-1（量化分析）'!D19 -> 0.107 | E14: ='前瞻性调整D2-10-1（量化分析）'!E19 -> 0.016 | F14: ='前瞻性调整D2-10-1（量化分析）'!F19 -> 0.014 | G14: ='前瞻性调整D2-10-1（量化分析）'!G19 -> 0.014 | H14: ='前瞻性调整D2-10-1（量化分析）'!H19 -> 0.0681 | I14: ='前瞻性调整D2-10-1（量化分析）'!I19 -> 0.16
A15: 过去5年 | B15: ='前瞻性调整D2-10-1（量化分析）'!B20 -> 0.079 | C15: ='前瞻性调整D2-10-1（量化分析）'!C20 -> 0.1101 | D15: ='前瞻性调整D2-10-1（量化分析）'!D20 -> 0.1195 | E15: ='前瞻性调整D2-10-1（量化分析）'!E20 -> 0.015 | F15: ='前瞻性调整D2-10-1（量化分析）'!F20 -> 0.023 | G15: ='前瞻性调整D2-10-1（量化分析）'!G20 -> 0.024 | H15: ='前瞻性调整D2-10-1（量化分析）'!H20 -> 0.1258 | I15: ='前瞻性调整D2-10-1（量化分析）'!I20 -> 0.14
A16: ……
A17: 准确起见，要考虑经济指标的滞后性，如GDP滞后2季度、货币供应量滞后2季度、消费者物价指数滞后1季度等等
A18: （二）指标相关性
A19: CPI指标相关性较低，选取GDP（X1）、M2（X2）、社会消费品零售总额（X3）、城镇固定资产投资增长率（X4）进行多重共线性分析。
A20: 还可以考虑增加自变量X1*X2、X1*X3、X1*X4、X2*X3、X2*X4、X3*X4，以及X12、X22、X32、X42。
A22: =B9 -> GDP增长率
A23: SUMMARY OUTPUT
A25: 回归统计
A26: Multiple R | B26: 0.48139796
A27: R Square | B27: 0.23174399
A28: Adjusted R Square | B28: 0.039679992
A29: 标准误差 | B29: 0.066145913
A30: 观测值 | B30: 6
A32: 方差分析
B33: df | C33: SS | D33: MS | E33: F | F33: Significance F
A34: 回归分析 | B34: 1 | C34: 0.0052792051 | D34: 0.0052792051 | E34: 1.2065978 | F34: 0.33368361
A35: 残差 | B35: 4 | C35: 0.017501127 | D35: 0.0043752817
A36: 总计 | B36: 5 | C36: 0.022780332
B38: Coefficients | C38: 标准误差 | D38: t Stat | E38: P-value | F38: Lower 95% | G38: Upper 95% | H38: 下限 95.0% | I38: 上限 95.0%
A39: Intercept | B39: 0.532016 | C39: 0.30064417 | D39: 1.7695869 | E39: 0.15151256 | F39: -0.30270604 | G39: 1.366738 | H39: -0.30270604 | I39: 1.366738
A40: X Variable 1 | B40: -4.6325137 | C40: 4.2173094 | D40: -1.0984524 | E40: 0.33368361 | F40: -16.341642 | G40: 7.0766142 | H40: -16.341642 | I40: 7.0766142
A44: =C9 -> 广义货币（M2）增长率
A45: SUMMARY OUTPUT
A47: 回归统计
A48: Multiple R | B48: 0.89105273
...

Sheet 多重共线性分析D2-10-2
A1: 致同会计师事务所
A2: 多重共线性分析
A3: =[9]底稿目录!$A$2 -> 被审计单位名称： | D3: =[9]底稿目录!$A$4 -> 编制人： | F3: =[9]底稿目录!$A$5 -> 编制日期： | I3: 索引号： | J3: D2-11-2
A4: =[9]底稿目录!$A$3 -> 截止日：202X年12月31日 | D4: =[9]底稿目录!$A$6 -> 复核人： | F4: =[9]底稿目录!$A$7 -> 复核日期： | I4: 页 次：
A5: 一、审计目标：
A6: 消除因子之间的高度相关性关系对于模型结果的影响
A7: 二、审计过程：
A8: （一）经济指标
A9: 年度 | B9: ='前瞻性调整D2-10-1（量化分析）'!B14 -> GDP增长率 | C9: ='前瞻性调整D2-10-1（量化分析）'!C14 -> 广义货币（M2）增长率 | D9: ='前瞻性调整D2-10-1（量化分析）'!D14 -> 社会消费品零售总额 | E9: ='变量相关性分析D2-10-2'!H9 -> 城镇固定资产投资 | I9: ='前瞻性调整D2-10-1（量化分析）'!I14 -> 损失率变动Y | J9: 备注
A10: 本年度 | B10: ='前瞻性调整D2-10-1（量化分析）'!B15 -> 0.061 | C10: ='前瞻性调整D2-10-1（量化分析）'!C15 -> 0.13 | D10: ='前瞻性调整D2-10-1（量化分析）'!D15 -> 0.083 | E10: ='变量相关性分析D2-10-2'!H10 -> -0.3265 | I10: ='前瞻性调整D2-10-1（量化分析）'!I15 -> 0.16627452
A11: 过去1年 | B11: ='前瞻性调整D2-10-1（量化分析）'!B16 -> 0.066 | C11: ='前瞻性调整D2-10-1（量化分析）'!C16 -> 0.0699 | D11: ='前瞻性调整D2-10-1（量化分析）'!D16 -> 0.09 | E11: ='变量相关性分析D2-10-2'!H11 -> -0.5343 | I11: ='前瞻性调整D2-10-1（量化分析）'!I16 -> 0.31737063
A12: 过去2年 | B12: ='前瞻性调整D2-10-1（量化分析）'!B17 -> 0.069 | C12: ='前瞻性调整D2-10-1（量化分析）'!C17 -> 0.0811 | D12: ='前瞻性调整D2-10-1（量化分析）'!D17 -> 0.102 | E12: ='变量相关性分析D2-10-2'!H12 -> -0.0229 | I12: ='前瞻性调整D2-10-1（量化分析）'!I17 -> 0.25
A13: 过去3年 | B13: ='前瞻性调整D2-10-1（量化分析）'!B18 -> 0.073 | C13: ='前瞻性调整D2-10-1（量化分析）'!C18 -> 0.1133 | D13: ='前瞻性调整D2-10-1（量化分析）'!D18 -> 0.104 | E13: ='变量相关性分析D2-10-2'!H13 -> 0.0652 | I13: ='前瞻性调整D2-10-1（量化分析）'!I18 -> 0.185
A14: 过去4年 | B14: ='前瞻性调整D2-10-1（量化分析）'!B19 -> 0.078 | C14: ='前瞻性调整D2-10-1（量化分析）'!C19 -> 0.1334 | D14: ='前瞻性调整D2-10-1（量化分析）'!D19 -> 0.107 | E14: ='变量相关性分析D2-10-2'!H14 -> 0.0681 | I14: ='前瞻性调整D2-10-1（量化分析）'!I19 -> 0.16
A15: 过去5年 | B15: ='前瞻性调整D2-10-1（量化分析）'!B20 -> 0.079 | C15: ='前瞻性调整D2-10-1（量化分析）'!C20 -> 0.1101 | D15: ='前瞻性调整D2-10-1（量化分析）'!D20 -> 0.1195 | E15: ='变量相关性分析D2-10-2'!H15 -> 0.1258 | I15: ='前瞻性调整D2-10-1（量化分析）'!I20 -> 0.14
A16: ……
A17: 准确起见，要考虑经济指标的滞后性，如GDP滞后2季度、货币供应量滞后2季度、消费者物价指数滞后1季度等等
A18: （二）多重共线性
B19: =B9 -> GDP增长率 | C19: =C9 -> 广义货币（M2）增长率 | D19: =D9 -> 社会消费品零售总额 | E19: =E9 -> 城镇固定资产投资
A20: =B9 -> GDP增长率 | B20: =CORREL($B$10:$B$15,B10:B15) -> 1 | C20: =CORREL($B$10:$B$15,C10:C15) -> 0.25396635 | D20: =CORREL($B$10:$B$15,D10:D15) -> 0.94757356 | E20: =CORREL($B$10:$B$15,E10:E15) -> 0.81592784
A21: =C9 -> 广义货币（M2）增长率 | C21: =CORREL($C$10:$C$15,C10:C15) -> 1 | D21: =CORREL($C$10:$C$15,D10:D15) -> 0.1217613 | E21: =CORREL($C$10:$C$15,E10:E15) -> 0.44060359
A22: =D9 -> 社会消费品零售总额 | D22: =CORREL($D$10:$D$15,D10:D15) -> 1 | E22: =CORREL($D$10:$D$15,E10:E15) -> 0.85279465
A23: =E9 -> 城镇固定资产投资 | E23: =CORREL($E$10:$E$15,E10:E15) -> 1
A28: 三、审计说明：
A29: 本次检验过程中的阀值设为0.8。得到最终的用于回归方程的宏观指标：GDP、M2、社会消费品零售总额。 当两个指标的相关性较高时，剔除与单变量分析中与违约概率相关性较低的指标。
A30: 四、审计结论：

Sheet 应收账款保理合同检查（示例）
A1: 致同会计师事务所
A2: 应收账款保理业务检查表（示例）
A3: =[9]底稿目录!$A$2 -> 被审计单位名称： | D3: =[9]底稿目录!$A$4 -> 编制人： | G3: =[9]底稿目录!$A$5 -> 编制日期： | H3: 索引号： | I3: D2-
A4: =[9]底稿目录!$A$3 -> 截止日：202X年12月31日 | D4: =[9]底稿目录!$A$6 -> 复核人： | G4: =[9]底稿目录!$A$7 -> 复核日期： | H4: 页 次：
A5: 一、审计目标
A6: 确定应收账款保理或资产证券化业务确认是否恰当
A7: 二、审计过程
A8: 1.获取保理业务相关合同，分析合同主要条款是否符合企业会计准则终止确认规定。
A10: （一）保理合同主要条款分析
A11: 分析项目 | C11: 注意事项 | F11: XX保理合同主要条款 | H11: 终止确认分析
A12: 关键定义 | B12: “商业纠纷” | C12: 可终止确认时，保理商应承担买方信用风险（及延迟支付风险、提前偿付风险）。买方信用风险应只排除严格限定的仅由商业风险因素导致的商业纠纷。 商业纠纷（贸易争议/争议）的定义不能过于宽泛，使得保理商实质不承担债务人任何信用风险。 | F12: 下述任一事项均构成保理申请人的违约：（2） 保理申请人与购货方发生商业纠纷（包括但不限于质量、技术、服务方面的纠纷），导致购货方未能在购销或服务合同规定的期限内向保理银行支付应付账款…… | H12: “商业纠纷”的定义并不限于商业风险，未明确排除商业风险以外的风险因素，导致保理商实质上可以将商务合同买方任何风险归于此条，从而触发转让方回购。
C13: 参考定义：商业纠纷，指商务合同买方与应收账款转出方之间因相关的货物或发票或其他因商务合同事由出现争议而造成商务合同买方对本协议项下应收账款提出的抗辩、反索或抵销或类似行为；发生争议的，即为发生商务合同交易风险。 参考定义：商业纠纷，指债务人因对甲方在商务合同项下的义务履行提出异议（包括但不限于交易商品的品质、交货方式及期限、价格、数量、付款方式及商业纠纷解决方式等）而对有关应收账款提出抗辩、拒绝全额或部分付款、反追索或抵销等主张或出现第三人对应收账款提出权利主张的情形。 | F13: 商业纠纷：是指因买方信用风险以外的任何原因导致乙方受让的应收账款不能按时足额回收的任何情形，包括但不限于：债务人因对甲方在基础商务合同项下的义务履行提出异议而对有关应收账款提出抗辩、拒绝按时全额付款、提出反追索或抵销等主张，或债务人对甲方在其他合同/协议/约定项下的义务履行提出异议而对应收账款提出抗辩、拒绝按时全额付款、提出反追索或抵销等主张，或出现第三人对应收账款提出任何权利主张的情形。 | H13: “商业纠纷”涵盖了其他合同/协议/约定项下的抗辩，即未明确排除商业风险以外的风险因素，在该应收账款保理业务下，也可能由于债务人信用风险、迟付风险等因素导致辩、拒绝按时全额付款、提出反追索或抵销等主张，从而触发转让方需要回购应收账款，在此情况下，转让方保留了应收账款的信用风险。
B14: “买方信用风险” | C14: 可终止确认时，保理商应承担买方信用风险（及延迟支付风险、提前偿付风险）。买方信用风险应只排除严格限定的商业纠纷。 | F14: 信用风险：指最终付款人因自身财务状况和支付能力缘故，拒绝付款、拖延付款或无力偿付应收账款债务，使应收账款债权全部或部分不能得到清偿的风险。 | H14: 信用风险的定义未考虑最终付款人主观故意不付款的情形，仅考虑了客观无力支付，若历史上或预计会存在主观故意不付款的情形，则并未转移几乎所有的风险。
C15: 参考定义：信用风险，指债务人由于自身状况的缘故（包括客观上无力还款和主观上无理拒付两种情况），拒绝付款、拖延付款或无力偿付商务合同债务，使应收账款债权不能完全或部分实现的风险，但不包括债务人因商业纠纷或因不可抗力拒付的风险。 参考定义：买方信用风险，是指债务人因破产、倒闭、无支付能力或恶意拖欠导致其未能在应收账款到期日足额付款的风险。“恶意拖欠”是指债务人未能在保理应收账款回款宽限期届满前足额付款且未提出商业纠纷的情形。 | F15: 信用风险，仅指因买方破产、倒闭、无支付能力或恶意拖欠所导致的买方未能在应收账款付款日后（不超过30天）天内足额付款。 “买方信用风险”是指除《交易合同》项下发生符合本合同约定的商业纠纷外，买方在催账期届满时无力支付或破产、清盘等情况下的风险。 | H15: 信用风险的定义限于例外事件（破产、倒闭、无支付能力）和恶意拖欠，且限于若干天内，即保理商不承担超过若干天的延迟支付风险和买方临时周转不利的拖欠。若该款项的主要风险是“超过若干天的延迟支付风险或临时周转不利的拖欠”，则主要风险并未转移。
B16: “合格应收账款” | C16: 对合格应收账款的定义应只与出售日的资产状况以及是否存在有效的应收款项相关，不应与应收账款相关的财务风险相关，不应与未来履约情况的风险和利益相关。 | F16: 本合同中所转让的应收账款应当符合以下条件： ……任何时候，商务合同不存在任何欺诈、贸易争议、瑕疵或纠纷 | H16: 未定义“纠纷”，使得保理商可能将任何买方的违约均归于交易纠纷，从而保理商可以不承担任何风险。
F17: 第二条（三）满足以下条件的应收账款为合格应收账款： ……7.乙方（保理商）要求的其他条件。 第十四条（四）发生以下情况，乙方可自行决定将相关应收账款从应收账款池中剔除： ……3.乙方合理认为应予以剔除的其他情况。 | H17: 合格应收账款及可剔除应收账款的条件过于宽泛。使得保理商可以随时认定转让方违约或应收账款不合格，从而反转让。
A18: 逾期支付违约金 | C18: 保理合同计算折扣或费用均不应涉及后续的催账期/逾期支付违约金。可以终止确认的保理业务中，转出方使用收到的转让价款的代价应在转让时即确定，后续不应因为已终止确认的应收账款的保理期间或催账期而发生任何成本。 当保理的应收账款逾期，保理商仍未从付款方收回款项时，转让方需针对该逾期未收到的应收款项向保理商支付利息或罚息，直至保理商收回全部款项，该项安排中转让方实质上承担了应收款项延迟付款风险。 | F18: 逾期支付违约金： 指本协议规定的融资逾期后，商务合同买方因未及时付款或付款不足额或乙方已收到商务合同买方的间接付款却未及时足额转付给甲方，导致甲方受让的应收账款债权没有及时受偿所产生的资金损失，按逾期发生日中国人民银行规定的逾期贷款利率计算。 | H18: 当保理的应收账款逾期，保理商仍未从付款方收回款项时，转让方需针对该逾期未收到的应收款项向保理商支付利息或罚息，直至保理商收回全部款项，该项安排中转让方实质上承担了应收款项延迟付款风险。
A19: 保理融资额为发票金额的一定比例（即可能存在超额担保） | B19: 保理余款 | C19: 公司将一笔或多笔应收账款的90%转让至保理商而自留10%部分，同时约定当从付款方收到款项时优先支付给保理商，直至保理商受让的应收款项全部收回。该项安排中，公司实质上以自留份额为保理商回收应收账款提供担保，该应收账款很可能不能终止确认。 | F19: 保理申请人将应收账款债权及相关权利转让给保理银行，经保理银行审查确认后，按照本合同项下每笔应收账款实有金额对应的保理融资金额（见附件《应收账款转让清单》）之和的 % ，给予保理申请人总额为人民币 元的保理业务融资。 保理银行在收到部分或全额付款后，应与本合同项下保理业务对应的应收账款逐笔勾对，确认无误的，该笔应收账款对应的融资从《应收账款转让清单》勾销，如有保理余款的，保理银行应及时将保理余款给付保理申请人。 保理余款：指保理银行实际收回的应收账款扣除保理本金、保理利息、逾期罚息及有关费用后的剩余资金。 | H19: 保理融资额为发票金额的一定比例（假设为90%），存在超额抵押，转让方实质上以自留份额为保理商回收应收账款提供担保——除非发票金额对应的收款额全部归保理商（即不存在多退少补）或每收到100元转让方与保理商按比例分配（即公司取得10元、保理商取得90元）。由保理余款退还给转让人的约定可知，保理商多收以后要退还给转让方，存在超额担保，报酬并未转移。
B20: 追加收购款 | C20: 保理融资额为发票金额的一定比例（假设为90%），存在超额抵押，转让方实质上以自留份额为保理商回收应收账款提供担保——除非发票金额对应的收款额全部归保理商（即不存在多退少补）或每收到100元转让方与保理商按比例分配（即公司取得10元、保理商取得90元；此时则还需进一步量化分析）。 | F20: 收购款。（一）基本收购款。基本收购款为所转让应收账款金额的X%； （二）追加收购款。甲方根据以下情况决定是否发放追加收购款： 1．在甲方所受让的应收账款获得完全付款的情况下，由甲方按照Y%×本合同所转让应收账款债权额-相关逾期支付违约金及实际发生的管理及追索费用后作为追加收购款支付给乙方； 上述“完全付款”包括但不限于应收账款本金、逾期违约金或类似性质的责任赔偿金、滞纳金、罚金等的完全收回。 | H20: 保理融资额为发票金额的一定比例（假设为90%），存在超额抵押，转让方（乙方）实质上以自留份额为保理商回收应收账款提供担保——除非发票金额对应的收款额全部归保理商（即不存在多退少补）或每收到100元转让方与保理商按比例分配（即公司取得10元、保理商取得90元）。由追加收购款支付给乙方的约定可知，商多收以后要退还给乙方，存在超额担保，报酬并未转移。此外，逾期支付违约金的存在表明风险（延迟支付风险）并未转移。
A21: 交叉违约条款 | C21: 交叉保护条款和一般保护性条款/违约条款虽然一般取决于转出方自身信用状况，不与原始债务人的信用风险相关，但从经济实质上考虑，保理商不会增加过多“无实质意义”的“一般性保护条款”，需要综合考虑各条款和条件的综合影响。并且，不能因为这些条款与债务人无关就直接认定不影响风险和报酬转移，当对应的情形很可能发生或者保理商可以自行认定是否已经发生时，保理商实质上可以通过这些条款不承担债务人的信用风险或延迟支付风险。 | F21: 交叉违约事件： （1）乙方（转让方）超过 万元的任何其他债务在约定的到期日之前需要支付或被宣布为应支付；（2）乙方任何其他债务在约定的到期日未能支付；（3）任何其他债权人取得乙方的全部或任何部分业务或资产的所有权，或针对乙方任何资产的裁决或判决被强制执行，从而实质上地影响乙方履行本合同项下义务的能力。 | H21: “交叉违约”触发回购，实质上可能使得保理商可在承租人违约情况下自行解释为乙方违约，并要求乙方回购，从而保理商不承担承租人任何风险。
A22: 回购 | B22: 追索/反索 | C22: 反转让条款或违约事件应明确限定于商业纠纷、对初始资产状况（合格应收账款）的约定或减资、修改章程、破产等例外事项，而非宽泛的转让方任何违约。 | F22: 即使甲方未出具《保理回购通知书》，甲方亦有权在保理期间逾期而未足额受偿时直接对乙方（转让方）行使追索权。 在不损害甲方依据本合同享有的任何权利的条件下，如任何一笔交易债权在到期日未获得全部清偿，甲方有权随时向乙方发出《债权回让函告》，将届时的剩余交易债权转让给乙方。 | H22: 追索不以商业纠纷或违约为前提，保理上实质上不承担商务合同买方任何风险。
B23: 回购 | C23: 反转让条款的范围不能过于宽泛，不应包含兜底条款，例如：“其他损害保理商权益的情况”、“保理商认为债权人或债务人的行为造成应收账款无法回收的情形”——可能导致保理商在任何情况下都不承担风险。 | F23: 如发生下列情形之一，乙方（转让方）须回购转让给甲方的应收账款： 债务人对有关应收账款提出异议、抗辩、反诉或抵销，影响甲方应收账款收回的…… | H23: 发生“异议、抗辩、反诉”即触发回购，应区分该“异议、抗辩、反诉”仅包括商业风险因素导致的、还是也包含因债务人信用风险等因素导致的，在协议中并未明确仅包括商业风险（或未明确排除商业风险以外的风险因素）
A24: 违约事件 | C24: 违约事件的范围不能过于宽泛，不应包含兜底条款，例如：“其他损害保理商权益的情况”、“保理商认为债权人或债务人的行为造成应收账款无法回收的情形”等 | F24: 出现下列任何一种情形，即构成一般违约事件：5．其他损害甲方权益的情况。 | H24: 存在兜底条款，导致保理商实质上可以将商务合同买方任何风险归于此条，从而触发转让方违约进而回购。
A25: 转让方的陈述与保证/承诺与保证 | C25: 保理协议通常会要求转出方作出“承诺与保证”，这些条款若仅用于保护保理商不承担商业纠纷导致的风险，或者用于发生商业纠纷从而反索时保护保理商可以足额收款，则属于常规声明和保证。 但若保理协议要求转出方对款项未来的可收回性作出承诺，或者设定了其他对可收回性兜底的约定，则该等承诺与保证将导致风险和报酬并未实质上转移。例如转出方承诺：转出方已按商务合同约定充分、合法地履行了全部义务，并且该履行将不会引致商务合同买方对应收账款付款的任何抗辩。 | F25: （一）在签订本协议之前乙方、商务合同买方之间不存在任何与本协议有关的或其他贸易争议或经济纠纷，且今后双方之间发生的任何事件均不影响本协议相关债务的履行……（十六）发生以下情况，乙方应在发生之日起 5 日内通知甲方，并按甲方的要求落实好本协议项下甲方债权保障措施：1.发生任何违约事件或可能导致违约的事件…… （二十二）当甲方向商务合同买方行使追索权时，乙方应配合甲方提供一切足以证明债权的材料；当甲方认为必要的时候，有权要求乙方与自己联名对商务合同买方采取诉讼和其他依法强制措施，并由乙方承担由此产生的一切费用。 | H25: 要求转让方（乙方）对未来提出保证，未定义“经济纠纷”，未明确排除商业风险以外的风险因素，且存在兜底条款，导致保理商实质上可以将商务合同买方任何风险归于此条，从而触发乙方回购。 乙方有义务配合甲方向商务合同买方行使追索权并承担一切费用，导致保理商即使因为买方信用风险不能向乙方追索，也不会实际承担任何损失。买方信用风险和延迟支付风险并未转移。
C26: 对于“债务纠纷、债务追索”触发回购的情况下，则应区分该“债务纠纷、债务追索”仅包括商业风险因素导致的、还是也包含因债务人信用风险等因素导致的。如果在合同并未明确仅包括商业风险（或未明确排除商业风险以外的风险因素），即在该应收账款保理业务下，也可能由于买方信用风险、迟付风险等因素导致债务纠纷或债务追偿并导致应收账款无法收回，从而触发转让方需要回购应收账款，在此情况下，转让方保留了应收账款的信用风险。 | F26: 乙方（转让方）的陈述与保证 在本协议签署之日以及乙方每次向甲方申请办理保理业务并转让应收账款时，乙方重复陈述和保证如下： （三） 乙方与债务人之间无任何未决商业纠纷或债权债务纠纷。 （九） 以上陈述和保证在本协议有效期内持续有效。乙方承认，甲方是基于乙方的上述陈述和保证才签订本协议的。 | H26: 由于合同要转让方的陈述与保证在协议有效期内持续有效，应区分“商业纠纷”“债权债务纠纷”是仅包括商业风险因素导致的、还是也包含因债务人信用风险等因素导致的，在合同中并未明确仅包括商业风险（或未明确排除商业风险以外的风险因素），即在该应收账款保理业务下，也可能由于债务人信用风险、迟付风险等因素导致双方之间的纠纷并导致应收账款无法按期收回，从而触发转让方违约，进而需要回购应收账款。
F27: 下述各项承诺与保证在所有重要方面于本合同签署之日均属真实、完整和准确，并保证自应收账款债权转让日应收账款债权清偿完毕之日持续有效： 卖方信用质量良好，无重大不良记录，卖方的经营状况、财务状况没有发生重大不利变化，且在过去一年中未因产品/服务质量或履约期限等问题而发生商业纠纷，与买方或其关联方之间无任何未决争议或债权债务纠纷。
A28: 其他相关条款 | C28: 保理商优先收款权的存在可能导致保理商实质上几乎不承担买方信用风险。 | F28: 本合同项下应收账款到期收取方式为由债务人直接向保理商付款，转让方承诺已通知债务人付款至保理商指定账户，并同意商务合同项下的全部应收账款（包括未转让的）优先支付至保理商账户。 | H28: 实质上以应收债务人的所有款项为保理的应收账款做了担保
A29: 分析结论 | C29: 应结合应收账款的信用风险特征进行分析，不能因为形式上无追索权而直接终止确认该应收账款。 | F29: -- | H29: 保留了几乎所有的风险和报酬，不能终止确认
A30: 三、审计说明
A33: 四、审计结论
A35: 提示：终止确认分析流程参考
A36: 判断步骤 | B36: 判断要点 | E36: 注意事项
A37: 步骤一：确定适用金融资产终止确认规定的报告主体层面 | B37: 如果是合并财务报表，企业应当首先按照《企业会计准则第33号——合并财务报表》及《企业会计准则解释第8号》等有关规定合并所有子公司（含结构化主体），然后将金融资产转移准则的规定应用于合并财务报表 | E37: 在资产证券化实务中，企业通常设立“信托计划”“专项支持计划”等结构化主体作为结构化融资的载体
A38: 步骤二：确定金融资产是部分还是整体适用终止确认原则 | B38: 除非特定可辨认或完全成比例，有关金融资产终止确认的相关规定适用于金融资产的整体。 | E38: 优先受偿的特定部分现金流既不是能够明确辨认的现金流量也不是全部或部分现金流量的完全成比例的一个份额 | G38: 对应收账款保理业务而言，通常不能按终止确认规则对应收账款的一部分（优先档/折后部分）进行处理
A39: 步骤三：确定收取金融资产现金流量的合同权利是否终止 | B39: 若收取金融资产的现金流量的合同权利没有终止，企业应当判断是否转移了金融资产，并根据以下有关金融资产转移的相关判断标准确定是否应当终止确认被转移金融资产。 | E39: 对保理或证券的应收账款而言，通常收取金融资产的现金流量的合同权利没有终止
A40: 步骤四：判断企业是否已转移收取金融资产现金流量的权利 | B40: 通常表现为金融资产的合法出售或者金融资产现金流量权利的合法转移（例如办理了转让登记） | E40: 在这种情形下，转入方拥有了获取被转移金融资产所有未来现金流量的权利
A41: 步骤五：是否通过“过手安排”测试 | B41: 企业保留了收取金融资产现金流量的合同权利，但承担了将收取的该现金流量支付给一个或多个最终收款方的合同义务。这种金融资产转移情形常见于资产证券化业务 | E41: 当且仅当同时符合三个条件（不垫付、不控制、不延误）时，才能按照金融资产转移的情形进行后续分析及处理，否则，应予以继续确认
A42: 步骤六：是否转移了金融资产所有权上几乎所有风险和报酬 | B42: 对于短期应收账款而言，面临的主要风险是信用风险（即付款人无法还款的风险）和延迟支付风险（即付款人逾期未支付的风险），而对于期限较长的应收款项，可能还会面临提前偿付风险 | E42: 应当考虑在转让后保留的风险和报酬与转让前的风险和报酬相比是否不再重大。历史上没有违约和逾期未付的记录并不能证明转让的应收账款没有风险。 | G42: 销售商给客户提供的数量折扣条件无需纳入风险和报酬分析，因为数量折扣与销售商与其客户之间的总体合同关系相关，不与应收款项本身相关。
A43: 步骤七：是否保留了金融资产所有权上几乎所有风险和报酬 | B43: 若回购是针对出售日应收账款是否存在以及发生商业纠纷（明确定义为由商业风险因素导致的）等导致债务人违约等与应收账款所对应商业交易相关的条款，则一般不影响与应收账款相关的风险和报酬转移程度的分析 | E43: 以自留部分为转让部分提供信用增级、触发回购的情形未明确仅包括商业风险（或未明确排除商业风险以外的风险因素）、承担延迟付款风险 | G43: 保理融资额为发票金额的一定比例（假设为90%），存在超额抵押，转让方实质上以自留份额为保理商回收应收账款提供担保——除非发票金额对应的收款额全部归保理商（即不存在多退少补）。
A44: 步骤八：分析企业是否保留了控制 | B44: 如果转入方能够单独将转入的金融资产整体出售给与其不存在关联方关系的第三方，且没有额外条件对此项出售加以限制，说明转入方有出售该金融资产的实际能力 | E44: 应当重点关注转入方出售该金融资产的实际能力，而不是仅关注合同赋予的权利。
...
