Workbook

Sheet 底稿目录
A1: 底稿开列时，可先在以下单元格填写有关内容，以便其他底稿引用有关数据： | B1: 目录
A2: 被审计单位：
A3: 截止日：202X年12月31日 | B3: 序号 | C3: 内容 | D3: 索引号 | E3: 备注
A4: 编制人： | B4: 1 | C4: 无形资产实质性程序 | D4: I1A
A5: 编制日期： | B5: 2 | C5: 审定表 | D5: I1-1
A6: 复核人： | B6: 3 | C6: 附注披露表（上市公司） | F6: 无需打印
A7: 复核日期： | B7: 4 | C7: 附注披露表（国有企业） | F7: 无需打印
A8: 无形资产类别设置（以下内容请根据实际情况修改）： | B8: 5 | C8: 明细表 | D8: I1-2
A9: 土地使用权 | B9: 6 | C9: 调整分录汇总 | D9: I1-3 | E9: 备选
A10: 住房使用权 | B10: 7 | C10: 摊销政策检查表 | D10: I1-4
A11: 专利权 | B11: 8 | C11: 增加检查表 | D11: I1-5
A12: 非专利技术 | B12: 9 | C12: 减少检查表 | D12: I1-6
A13: 商标权 | B13: 10 | C13: 使用寿命检查表 | D13: I1-7
A14: 著作权 | B14: 11 | C14: 权属检查表 | D14: I1-8
A15: 特许经营权 | B15: 12 | C15: 摊销分配分析表 | D15: I1-9
A16: 软件 | B16: 13 | C16: 摊销测算表（剩余年限法） | D16: I1-10
A17: 矿产权 | B17: 14 | C17: 摊销测算表 | D17: I1-11
A18: 数据资源 | B18: 15 | C18: 减值准备测试表 | D18: I1-12
A19: 其他 | B19: 16 | C19: 可收回金额测试 | D19: I1-13
A20: ……
A22: 关于工作底稿与审计程序索引号对应的说明
A23: 1.编制的审计工作底稿应与审计程序对应。审计项目组应根据被审计单位实际情况和风险评估情况在实质性程序表中裁剪、修改或增加审计程序，根据实际执行的审计程序完成相应审计工作底稿，编制的工作底稿中应按自然顺序依次编制索引号，并通过唯一的索引号将与实质性程序表中的程序对应关联（即将工作底稿的索引号填入实质性程序表中的底稿索引号列）。
A27: 2.获取的支持性证据应与审计底稿或程序对应。审计项目组在完成底稿时获取的支持性证据应根据底稿索引号编制下一级按自然顺序排序的索引号（如D1-2-1、D1-2-2、……），并在底稿中说明引用的支持性证据、关联索引号。
A30: 3.工作底稿索引号的编码规则：实质性程序索引号按循环从“D”到“N”,循环内账户以顺序号排列，模板中底稿索引号按账户顺序+自然数顺序（即模板中索引号按二级自然顺序排列，如D1-1、D1-2、D1-3、……D1-N）。

Sheet 无形资产实质性程序 I1A
A1: 致同会计师事务所
A2: 无形资产实质性程序
A3: =底稿目录!A2 -> 被审计单位： | C3: =底稿目录!A4 -> 编制人： | E3: =底稿目录!A5 -> 编制日期： | H3: 索引号： | I3: I1A
A4: 会计期间：202X年 | C4: =底稿目录!A6 -> 复核人： | E4: =底稿目录!A7 -> 复核日期： | H4: 页 次：
A5: 一、本账户涉及的科目
A6: 无形资产
A7: 二、审计目标与认定的对应关系
A8: 审计目标 | G8: 财务报表的认定
A9: A. 资产负债表中记录的无形资产是存在的，且已经记录在恰当的账户中 | G9: 存在
A10: B. 所有应记录的无形资产均已记录，所有应当包括在财务报表中的相关披露均已包括 | G10: 完整性
A11: C. 记录的无形资产由被审计单位拥有或控制 | G11: 权利和义务
A12: D. 无形资产以恰当的金额包括在财务报表中，与之相关的计价或分摊调整已恰当记录，相关披露已得到恰当计量和描述 | G12: 准确性、计价和分摊
A13: E. 无形资产已被恰当地汇总或分解且表述清楚，相关披露在按照企业会计准则的编制基础下是相关的、可理解的 | G13: 列报
A14: 三、计划实施的实质性程序
A15: 序号 | B15: 审计程序 | C15: 程序分类 | D15: 财务报表的认定 | I15: 底稿索引号
D16: 存在 | E16: 完整性 | F16: 权利和 义务 | G16: 准确性、计价和分摊 | H16: 列报 | J16: 根据被审计单位实际情况和风险评估情况裁剪、修改或增加审计程序
A17: 1 | B17: 获取或编制无形资产的明细表，复核加计是否正确，与总账、明细账合计数核对是否相符，期初余额与上期审定期末余额是否相符，并编制审定表。 | C17: 常规★ | D17: √ | E17: √ | G17: √ | I17: I1-1 /I1-2
A18: 2 | B18: 在使用手工编制、自定义信息报告、系统生成的非固定格式报告等由被审计单位生成的信息时，测试有关信息准确性和完整性，并考虑针对编制和维护由被审计单位生成的信息的相关控制实施控制测试，以评价该信息是否能够为实现审计目的提供基础。 | C18: 常规★ | E18: √ | G18: √ | I18: T1 | J18: 可参见《审计手册》4.2.6，由被审计单位生成的信息可能是由系统生成的、或手工编制的、或二者兼而有之的方式生成的。例如，由被审计单位生成的信息可能包括： • 不涉及自定义的、由系统生成的报告（如，固定格式报告）； • 可能通过人工自定义的、由系统生成的报告，例如，（计算机）查询信息或特别定制的报告； • 手工编制的信息，例如，汇总信息的电子表格或用以支持分配、计算以及调节的电子表格； • 其他系统生成或手工编制的信息，例如，由被审计单位编制的客户发票； • 通过影印、拍摄、扫描或其他方式转换成电子形式的文件记录。
A19: 3 | B19: 取得无形资产期初余额明细表复核加计是否正确，与总账、明细账合计数是否相符；如适用，测试累计摊销。对单项金额重大资产，检查支持性文件或实地查看资产，其他必要追加的审计程序。（适用于首次承接） | C19: 备选 | D19: √ | E19: √ | F19: √ | G19: √ | J19: 由被审计单位生成的信息不包括： • 总分类账或明细分类账、试算平衡表、或经审计的财务报表； • 第三方（除了服务机构）的报表或报告，例如，原始银行对账单，或函证的回函； • 外部数据（例如，第三方发布的数据，如，定价来源）。
A20: 4 | B20: 关注会计政策、会计估计合理性、一贯性，关注其是否利用会计政策和会计估计及其变更操纵利润。必要时与同行业其他公司会计政策、会计估计进行对比，主要会计政策和估计包括： （1）无形资产的初始计量； （2）无形资产摊销/减值的政策和方法； | C20: 常规★ | D20: √ | E20: √ | G20: √ | I20: I1-4 | J20: 无形资产中的由被审计单位生成的信息例如：手工编制的无形资产摊销计算表等
A21: 5 | B21: 对于本期新增的无形资产，根据具体情况，需要检查的项目包括但不限于： （1）检查无形资产的权属证书、非专利技术的持有和保密状况； （2）检查投资者投入的无形资产是否按投资各方确认的价值入账，并检查确认价值是否公允，交接手续是否齐全；涉及国有资产的，是否有评估报告并经国有资产管理部门评审备案或核准确认； （3）购入或接受捐赠的无形资产，检查其法律程序是否完备； （4）对债务重组或非货币性资产交换取得的无形资产，检查有关协议等资料。 （5）对自行研发取得的，结合开发支出的审计检查会计处理是否正确。 （6）检查本期购入土地使用权相关税费计算清缴情况。 （7）关注企业合并中取得的无形资产的完整性，以及初始确认及后续计量的准确性，必要时应利用专家工作。 （8）针对矿产权、特许使用权等合同或法律有关权利，关注相关初始计量准确性，必要时是否利用专家工作。 | C21: 常规★ | D21: √ | E21: √ | F21: √ | G21: √ | I21: I1-5
A22: 6 | B22: 对于本期减少的无形资产，根据具体情况，需要检查的项目包括但不限于： （1）根据具体情况，按下述3条所述流程，执行相关程序。 检查与资产处置相关的合同、发票及其他文件；重新计算相关的利得或损失；确定会计处理是否恰当。 （2）检查房地产开发企业取得的土地用于建造对外出售的房屋建筑物，相关的土地使用权是否转入所建造房屋建筑物的成本；在土地上自行开发建造厂房等建筑物的，土地使用权和地上建筑物是否分别进行摊销和计提折旧； （3）当土地使用权用于出租或增值目的时，检查其是否转为投资性房地产核算，会计处理是否正确。 | C22: 常规★ | D22: √ | E22: √ | G22: √ | I22: I1-6
A23: 7 | B23: 对于使用寿命有限的无形资产的本期摊销，执行以下程序： （1）获取或编制使用寿命有限的无形资产的累计摊销明细表，复核加计正确，并与总账数和明细账合计数核对相符。 （2）确认摊销方法是否一致，是否合理。 确定摊销年限是否适当，重新测算摊销金额，形成本期摊销费用的期望，与已记录的金额对比。 （3）确定分配到各项资产/费用项目的摊销金额是否合理。 | C23: 常规★ | G23: √ | I23: I1-7 /I1-9 /I1-10 /I1-11
A24: 8 | B24: 检查无形资产的权属，确定是否存在受限情况： （1）结合银行借款等项目的检查，并同时查看资产权属证明原件，了解是否设定对外抵押，如有，则详细记录，并提请被审计单位进行充分披露，并取得复印件作为工作底稿。 （2）对于正在办理权属证明的大额资产，应了解权属证明办理情况，确认是否存在权属纠纷或实质性障碍。 | C24: 常规★ | F24: √ | I24: I1-8
A25: 9 | B25: 针对存在减值迹象的无形资产，考虑执行下列程序： （1）获取无形资产的减值明细表； （2）记录对无形资产可能造成减值的事件或环境变化； （3）复核用于减值测试的资产分组的合理性； （4）关注并复核公司确定的减值测试方法与模型是否恰当；关注并复核公司进行减值测试所依据的基础数据是否准确、所选取的关键参数是否恰当，评价所采用的关键假设、所作出的重大估计和判断、所选取的价值类型是否合理，分析减值测试方法与价值类型是否匹配； （5）取得相关的资产现金流分析。确定相关资产的预测的未来现金流量是合理的；如果现金流量预测表明，资产的账面价值无法收回，获得企业对资产组的公允价值的分析；评价每个评估专家的资质和工作（是否第三方或客户员工），并对完成“专家资质”和“专家工作”的审计程序。确定是否需要在审计项目组中增加一个估值专家，以帮助对公允价值/可收回金额的计算进行评价。 （6）比预期所估计减值准备和已记录的金额，调查所有重大差异； （7）确定潜在减值是否恰当。 （8）确定上期确认的长期资产减值准备在本期的变动是否适当。 | C25: 常规★ | G25: √ | I25: I1-7 /I1-12 /I1-13
A26: 10 | B26: 对财务报表整体有重大影响的异常、偶发或交易标的不具备实物形态（例如技术转让合同、技术服务合同、特许权使用合同等）、交易价格明显偏离正常市场价格、交易标的对交易对手而言不具有合理用途的交易）、缺乏商业理由的交易；关注相关交易的形成原因和真实性，考虑函证交易金额和合同条款、查询工商资料等核查交易对手。 | C26: IPO/上市/新三板/重组/舞弊应对 | D26: √ | G26: √
A27: 11 | B27: 根据评估的舞弊风险等因素增加的审计程序。 | C27: IPO/上市/新三板/重组/舞弊应对
A28: 12 | B28: 检查无形资产是否已按企业会计准则或其他适用的规定在财务报表中做出恰当列报和披露。 | C28: 常规★ | H28: √ | I28: A1-1/A1-15 /A1-16

Sheet 审定表I1
A1: 致同会计师事务所
A2: 无形资产、累计摊销及减值准备审定表
A3: =底稿目录!A2 -> 被审计单位： | C3: =底稿目录!A4 -> 编制人： | F3: =底稿目录!A5 -> 编制日期： | H3: 索引号： | I3: I1-1
A4: =底稿目录!A3 -> 截止日：202X年12月31日 | C4: =底稿目录!A6 -> 复核人： | F4: =底稿目录!A7 -> 复核日期： | H4: 页次：
A5: 项目 | B5: 期初数 | E5: 期末数 | H5: 本期审定数与上期 审定数的比较
B6: 未审数 | C6: 账项调整 | D6: 审定数 | E6: 未审数 | F6: 账项调整 | G6: 审定数 | H6: 变动额 | I6: 变动率
A7: 一、无形资产原值
A8: =底稿目录!A9 -> 土地使用权 | B8: ='明细表I1-2'!C20 -> 0 | C8: ='明细表I1-2'!I20 -> 0 | D8: ='明细表I1-2'!L20 -> 0 | E8: ='明细表I1-2'!H20 -> 0 | F8: ='明细表I1-2'!I20+'明细表I1-2'!J20-'明细表I1-2'!K20 -> 0 | G8: ='明细表I1-2'!O20 -> 0 | H8: =G8-D8 -> 0 | I8: =IF(AND(D8=0,H8=0),0,IF(AND(D8=0,H8>0),1,H8/D8)) -> 0
A9: =底稿目录!A10 -> 住房使用权 | B9: ='明细表I1-2'!C21 -> 0 | C9: ='明细表I1-2'!I21 -> 0 | D9: ='明细表I1-2'!L21 -> 0 | E9: ='明细表I1-2'!H21 -> 0 | F9: ='明细表I1-2'!I21+'明细表I1-2'!J21-'明细表I1-2'!K21 -> 0 | G9: ='明细表I1-2'!O21 -> 0 | H9: =G9-D9 -> 0 | I9: =IF(AND(D9=0,H9=0),0,IF(AND(D9=0,H9>0),1,H9/D9)) -> 0
A10: =底稿目录!A11 -> 专利权 | B10: ='明细表I1-2'!C22 -> 0 | C10: ='明细表I1-2'!I22 -> 0 | D10: ='明细表I1-2'!L22 -> 0 | E10: ='明细表I1-2'!H22 -> 0 | F10: ='明细表I1-2'!I22+'明细表I1-2'!J22-'明细表I1-2'!K22 -> 0 | G10: ='明细表I1-2'!O22 -> 0 | H10: =G10-D10 -> 0 | I10: =IF(AND(D10=0,H10=0),0,IF(AND(D10=0,H10>0),1,H10/D10)) -> 0
A11: =底稿目录!A12 -> 非专利技术 | B11: ='明细表I1-2'!C23 -> 0 | C11: ='明细表I1-2'!I23 -> 0 | D11: ='明细表I1-2'!L23 -> 0 | E11: ='明细表I1-2'!H23 -> 0 | F11: ='明细表I1-2'!I23+'明细表I1-2'!J23-'明细表I1-2'!K23 -> 0 | G11: ='明细表I1-2'!O23 -> 0 | H11: =G11-D11 -> 0 | I11: =IF(AND(D11=0,H11=0),0,IF(AND(D11=0,H11>0),1,H11/D11)) -> 0
A12: =底稿目录!A13 -> 商标权 | B12: ='明细表I1-2'!C24 -> 0 | C12: ='明细表I1-2'!I24 -> 0 | D12: ='明细表I1-2'!L24 -> 0 | E12: ='明细表I1-2'!H24 -> 0 | F12: ='明细表I1-2'!I24+'明细表I1-2'!J24-'明细表I1-2'!K24 -> 0 | G12: ='明细表I1-2'!O24 -> 0 | H12: =G12-D12 -> 0 | I12: =IF(AND(D12=0,H12=0),0,IF(AND(D12=0,H12>0),1,H12/D12)) -> 0
A13: =底稿目录!A14 -> 著作权 | B13: ='明细表I1-2'!C25 -> 0 | C13: ='明细表I1-2'!I25 -> 0 | D13: ='明细表I1-2'!L25 -> 0 | E13: ='明细表I1-2'!H25 -> 0 | F13: ='明细表I1-2'!I25+'明细表I1-2'!J25-'明细表I1-2'!K25 -> 0 | G13: ='明细表I1-2'!O25 -> 0 | H13: =G13-D13 -> 0 | I13: =IF(AND(D13=0,H13=0),0,IF(AND(D13=0,H13>0),1,H13/D13)) -> 0
A14: =底稿目录!A15 -> 特许经营权 | B14: ='明细表I1-2'!C26 -> 0 | C14: ='明细表I1-2'!I26 -> 0 | D14: ='明细表I1-2'!L26 -> 0 | E14: ='明细表I1-2'!H26 -> 0 | F14: ='明细表I1-2'!I26+'明细表I1-2'!J26-'明细表I1-2'!K26 -> 0 | G14: ='明细表I1-2'!O26 -> 0 | H14: =G14-D14 -> 0 | I14: =IF(AND(D14=0,H14=0),0,IF(AND(D14=0,H14>0),1,H14/D14)) -> 0
A15: =底稿目录!A16 -> 软件 | B15: ='明细表I1-2'!C27 -> 0 | C15: ='明细表I1-2'!I27 -> 0 | D15: ='明细表I1-2'!L27 -> 0 | E15: ='明细表I1-2'!H27 -> 0 | F15: ='明细表I1-2'!I27+'明细表I1-2'!J27-'明细表I1-2'!K27 -> 0 | G15: ='明细表I1-2'!O27 -> 0 | H15: =G15-D15 -> 0 | I15: =IF(AND(D15=0,H15=0),0,IF(AND(D15=0,H15>0),1,H15/D15)) -> 0
A16: =底稿目录!A17 -> 矿产权 | B16: ='明细表I1-2'!C28 -> 0 | C16: ='明细表I1-2'!I28 -> 0 | D16: ='明细表I1-2'!L28 -> 0 | E16: ='明细表I1-2'!H28 -> 0 | F16: ='明细表I1-2'!I28+'明细表I1-2'!J28-'明细表I1-2'!K28 -> 0 | G16: ='明细表I1-2'!O28 -> 0 | H16: =G16-D16 -> 0 | I16: =IF(AND(D16=0,H16=0),0,IF(AND(D16=0,H16>0),1,H16/D16)) -> 0
A17: =底稿目录!A19 -> 其他 | B17: ='明细表I1-2'!C30 -> 0 | C17: ='明细表I1-2'!I30 -> 0 | D17: ='明细表I1-2'!L30 -> 0 | E17: ='明细表I1-2'!H30 -> 0 | F17: ='明细表I1-2'!I30+'明细表I1-2'!J30-'明细表I1-2'!K30 -> 0 | G17: ='明细表I1-2'!O30 -> 0 | H17: =G17-D17 -> 0 | I17: =IF(AND(D17=0,H17=0),0,IF(AND(D17=0,H17>0),1,H17/D17)) -> 0
A18: 合计 | B18: =SUM(B8:B17) -> 0 | C18: =SUM(C8:C17) -> 0 | D18: =SUM(D8:D17) -> 0 | E18: =SUM(E8:E17) -> 0 | F18: =SUM(F8:F17) -> 0 | G18: =SUM(G8:G17) -> 0 | H18: =G18-D18 -> 0 | I18: =IF(AND(D18=0,H18=0),0,IF(AND(D18=0,H18>0),1,H18/D18)) -> 0
A19: 二、累计摊销
A20: =A8 -> 土地使用权 | B20: ='明细表I1-2'!P20 -> 0 | C20: ='明细表I1-2'!V20 -> 0 | D20: ='明细表I1-2'!Y20 -> 0 | E20: ='明细表I1-2'!U20 -> 0 | F20: ='明细表I1-2'!V20+'明细表I1-2'!W20-'明细表I1-2'!X20 -> 0 | G20: ='明细表I1-2'!AB20 -> 0 | H20: =G20-D20 -> 0 | I20: =IF(AND(D20=0,H20=0),0,IF(AND(D20=0,H20>0),1,H20/D20)) -> 0
A21: =A9 -> 住房使用权 | B21: ='明细表I1-2'!P21 -> 0 | C21: ='明细表I1-2'!V21 -> 0 | D21: ='明细表I1-2'!Y21 -> 0 | E21: ='明细表I1-2'!U21 -> 0 | F21: ='明细表I1-2'!V21+'明细表I1-2'!W21-'明细表I1-2'!X21 -> 0 | G21: ='明细表I1-2'!AB21 -> 0 | H21: =G21-D21 -> 0 | I21: =IF(AND(D21=0,H21=0),0,IF(AND(D21=0,H21>0),1,H21/D21)) -> 0
A22: =A10 -> 专利权 | B22: ='明细表I1-2'!P22 -> 0 | C22: ='明细表I1-2'!V22 -> 0 | D22: ='明细表I1-2'!Y22 -> 0 | E22: ='明细表I1-2'!U22 -> 0 | F22: ='明细表I1-2'!V22+'明细表I1-2'!W22-'明细表I1-2'!X22 -> 0 | G22: ='明细表I1-2'!AB22 -> 0 | H22: =G22-D22 -> 0 | I22: =IF(AND(D22=0,H22=0),0,IF(AND(D22=0,H22>0),1,H22/D22)) -> 0
A23: =A11 -> 非专利技术 | B23: ='明细表I1-2'!P23 -> 0 | C23: ='明细表I1-2'!V23 -> 0 | D23: ='明细表I1-2'!Y23 -> 0 | E23: ='明细表I1-2'!U23 -> 0 | F23: ='明细表I1-2'!V23+'明细表I1-2'!W23-'明细表I1-2'!X23 -> 0 | G23: ='明细表I1-2'!AB23 -> 0 | H23: =G23-D23 -> 0 | I23: =IF(AND(D23=0,H23=0),0,IF(AND(D23=0,H23>0),1,H23/D23)) -> 0
A24: =A12 -> 商标权 | B24: ='明细表I1-2'!P24 -> 0 | C24: ='明细表I1-2'!V24 -> 0 | D24: ='明细表I1-2'!Y24 -> 0 | E24: ='明细表I1-2'!U24 -> 0 | F24: ='明细表I1-2'!V24+'明细表I1-2'!W24-'明细表I1-2'!X24 -> 0 | G24: ='明细表I1-2'!AB24 -> 0 | H24: =G24-D24 -> 0 | I24: =IF(AND(D24=0,H24=0),0,IF(AND(D24=0,H24>0),1,H24/D24)) -> 0
A25: =A13 -> 著作权 | B25: ='明细表I1-2'!P25 -> 0 | C25: ='明细表I1-2'!V25 -> 0 | D25: ='明细表I1-2'!Y25 -> 0 | E25: ='明细表I1-2'!U25 -> 0 | F25: ='明细表I1-2'!V25+'明细表I1-2'!W25-'明细表I1-2'!X25 -> 0 | G25: ='明细表I1-2'!AB25 -> 0 | H25: =G25-D25 -> 0 | I25: =IF(AND(D25=0,H25=0),0,IF(AND(D25=0,H25>0),1,H25/D25)) -> 0
A26: =A14 -> 特许经营权 | B26: ='明细表I1-2'!P26 -> 0 | C26: ='明细表I1-2'!V26 -> 0 | D26: ='明细表I1-2'!Y26 -> 0 | E26: ='明细表I1-2'!U26 -> 0 | F26: ='明细表I1-2'!V26+'明细表I1-2'!W26-'明细表I1-2'!X26 -> 0 | G26: ='明细表I1-2'!AB26 -> 0 | H26: =G26-D26 -> 0 | I26: =IF(AND(D26=0,H26=0),0,IF(AND(D26=0,H26>0),1,H26/D26)) -> 0
A27: =A15 -> 软件 | B27: ='明细表I1-2'!P27 -> 0 | C27: ='明细表I1-2'!V27 -> 0 | D27: ='明细表I1-2'!Y27 -> 0 | E27: ='明细表I1-2'!U27 -> 0 | F27: ='明细表I1-2'!V27+'明细表I1-2'!W27-'明细表I1-2'!X27 -> 0 | G27: ='明细表I1-2'!AB27 -> 0 | H27: =G27-D27 -> 0 | I27: =IF(AND(D27=0,H27=0),0,IF(AND(D27=0,H27>0),1,H27/D27)) -> 0
A28: =A16 -> 矿产权 | B28: ='明细表I1-2'!P28 -> 0 | C28: ='明细表I1-2'!V28 -> 0 | D28: ='明细表I1-2'!Y28 -> 0 | E28: ='明细表I1-2'!U28 -> 0 | F28: ='明细表I1-2'!V28+'明细表I1-2'!W28-'明细表I1-2'!X28 -> 0 | G28: ='明细表I1-2'!AB28 -> 0 | H28: =G28-D28 -> 0 | I28: =IF(AND(D28=0,H28=0),0,IF(AND(D28=0,H28>0),1,H28/D28)) -> 0
A29: =A17 -> 其他 | B29: ='明细表I1-2'!P30 -> 0 | C29: ='明细表I1-2'!V30 -> 0 | D29: ='明细表I1-2'!Y30 -> 0 | E29: ='明细表I1-2'!U30 -> 0 | F29: ='明细表I1-2'!V30+'明细表I1-2'!W30-'明细表I1-2'!X30 -> 0 | G29: ='明细表I1-2'!AB30 -> 0 | H29: =G29-D29 -> 0 | I29: =IF(AND(D29=0,H29=0),0,IF(AND(D29=0,H29>0),1,H29/D29)) -> 0
A30: 合计 | B30: =SUM(B20:B29) -> 0 | C30: =SUM(C20:C29) -> 0 | D30: =SUM(D20:D29) -> 0 | E30: =SUM(E20:E29) -> 0 | F30: =SUM(F20:F29) -> 0 | G30: =SUM(G20:G29) -> 0 | H30: =G30-D30 -> 0 | I30: =IF(AND(D30=0,H30=0),0,IF(AND(D30=0,H30>0),1,H30/D30)) -> 0
A31: 三、减值准备
A32: =A8 -> 土地使用权 | B32: ='明细表I1-2'!AC20 -> 0 | C32: ='明细表I1-2'!AI20 -> 0 | D32: ='明细表I1-2'!AL20 -> 0 | E32: ='明细表I1-2'!AH20 -> 0 | F32: ='明细表I1-2'!AI20+'明细表I1-2'!AJ20-'明细表I1-2'!AK20 -> 0 | G32: ='明细表I1-2'!AO20 -> 0 | H32: =G32-D32 -> 0 | I32: =IF(AND(D32=0,H32=0),0,IF(AND(D32=0,H32>0),1,H32/D32)) -> 0
A33: =A9 -> 住房使用权 | B33: ='明细表I1-2'!AC21 -> 0 | C33: ='明细表I1-2'!AI21 -> 0 | D33: ='明细表I1-2'!AL21 -> 0 | E33: ='明细表I1-2'!AH21 -> 0 | F33: ='明细表I1-2'!AI21+'明细表I1-2'!AJ21-'明细表I1-2'!AK21 -> 0 | G33: ='明细表I1-2'!AO21 -> 0 | H33: =G33-D33 -> 0 | I33: =IF(AND(D33=0,H33=0),0,IF(AND(D33=0,H33>0),1,H33/D33)) -> 0
A34: =A10 -> 专利权 | B34: ='明细表I1-2'!AC22 -> 0 | C34: ='明细表I1-2'!AI22 -> 0 | D34: ='明细表I1-2'!AL22 -> 0 | E34: ='明细表I1-2'!AH22 -> 0 | F34: ='明细表I1-2'!AI22+'明细表I1-2'!AJ22-'明细表I1-2'!AK22 -> 0 | G34: ='明细表I1-2'!AO22 -> 0 | H34: =G34-D34 -> 0 | I34: =IF(AND(D34=0,H34=0),0,IF(AND(D34=0,H34>0),1,H34/D34)) -> 0
A35: =A11 -> 非专利技术 | B35: ='明细表I1-2'!AC23 -> 0 | C35: ='明细表I1-2'!AI23 -> 0 | D35: ='明细表I1-2'!AL23 -> 0 | E35: ='明细表I1-2'!AH23 -> 0 | F35: ='明细表I1-2'!AI23+'明细表I1-2'!AJ23-'明细表I1-2'!AK23 -> 0 | G35: ='明细表I1-2'!AO23 -> 0 | H35: =G35-D35 -> 0 | I35: =IF(AND(D35=0,H35=0),0,IF(AND(D35=0,H35>0),1,H35/D35)) -> 0
A36: =A12 -> 商标权 | B36: ='明细表I1-2'!AC24 -> 0 | C36: ='明细表I1-2'!AI24 -> 0 | D36: ='明细表I1-2'!AL24 -> 0 | E36: ='明细表I1-2'!AH24 -> 0 | F36: ='明细表I1-2'!AI24+'明细表I1-2'!AJ24-'明细表I1-2'!AK24 -> 0 | G36: ='明细表I1-2'!AO24 -> 0 | H36: =G36-D36 -> 0 | I36: =IF(AND(D36=0,H36=0),0,IF(AND(D36=0,H36>0),1,H36/D36)) -> 0
A37: =A13 -> 著作权 | B37: ='明细表I1-2'!AC25 -> 0 | C37: ='明细表I1-2'!AI25 -> 0 | D37: ='明细表I1-2'!AL25 -> 0 | E37: ='明细表I1-2'!AH25 -> 0 | F37: ='明细表I1-2'!AI25+'明细表I1-2'!AJ25-'明细表I1-2'!AK25 -> 0 | G37: ='明细表I1-2'!AO25 -> 0 | H37: =G37-D37 -> 0 | I37: =IF(AND(D37=0,H37=0),0,IF(AND(D37=0,H37>0),1,H37/D37)) -> 0
A38: =A14 -> 特许经营权 | B38: ='明细表I1-2'!AC26 -> 0 | C38: ='明细表I1-2'!AI26 -> 0 | D38: ='明细表I1-2'!AL26 -> 0 | E38: ='明细表I1-2'!AH26 -> 0 | F38: ='明细表I1-2'!AI26+'明细表I1-2'!AJ26-'明细表I1-2'!AK26 -> 0 | G38: ='明细表I1-2'!AO26 -> 0 | H38: =G38-D38 -> 0 | I38: =IF(AND(D38=0,H38=0),0,IF(AND(D38=0,H38>0),1,H38/D38)) -> 0
A39: =A15 -> 软件 | B39: ='明细表I1-2'!AC27 -> 0 | C39: ='明细表I1-2'!AI27 -> 0 | D39: ='明细表I1-2'!AL27 -> 0 | E39: ='明细表I1-2'!AH27 -> 0 | F39: ='明细表I1-2'!AI27+'明细表I1-2'!AJ27-'明细表I1-2'!AK27 -> 0 | G39: ='明细表I1-2'!AO27 -> 0 | H39: =G39-D39 -> 0 | I39: =IF(AND(D39=0,H39=0),0,IF(AND(D39=0,H39>0),1,H39/D39)) -> 0
A40: =A16 -> 矿产权 | B40: ='明细表I1-2'!AC28 -> 0 | C40: ='明细表I1-2'!AI28 -> 0 | D40: ='明细表I1-2'!AL28 -> 0 | E40: ='明细表I1-2'!AH28 -> 0 | F40: ='明细表I1-2'!AI28+'明细表I1-2'!AJ28-'明细表I1-2'!AK28 -> 0 | G40: ='明细表I1-2'!AO28 -> 0 | H40: =G40-D40 -> 0 | I40: =IF(AND(D40=0,H40=0),0,IF(AND(D40=0,H40>0),1,H40/D40)) -> 0
...

Sheet 附注披露信息（上市公司）
A1: 致同会计师事务所
A2: 无形资产、累计摊销及减值准备附注披露表（上市公司）
A3: =底稿目录!A2 -> 被审计单位： | D3: =底稿目录!A4 -> 编制人： | H3: =底稿目录!A5 -> 编制日期： | L3: 索引号： | M3: K1-1
A4: =底稿目录!A3 -> 截止日：202X年12月31日 | D4: =底稿目录!A6 -> 复核人： | H4: =底稿目录!A7 -> 复核日期： | L4: 页次：
A5: （1）无形资产情况
A6: 致同会计师事务所
A7: 无形资产、累计摊销及减值准备附注披露表（国有企业）
A8: =底稿目录!A2 -> 被审计单位： | B8: =底稿目录!A4 -> 编制人： | E8: =底稿目录!A6 -> 复核人： | L8: 索引号：
A9: =底稿目录!A3 -> 截止日：202X年12月31日 | B9: =底稿目录!A5 -> 编制日期： | E9: =底稿目录!A7 -> 复核日期： | L9: 页次：
A10: 项目 | B10: =底稿目录!A9 -> 土地使用权 | C10: =底稿目录!A10 -> 住房使用权 | D10: =底稿目录!A11 -> 专利权 | E10: =底稿目录!A12 -> 非专利技术 | F10: =底稿目录!A13 -> 商标权 | G10: =底稿目录!A14 -> 著作权 | H10: =底稿目录!A15 -> 特许经营权 | I10: =底稿目录!A16 -> 软件 | J10: =底稿目录!A17 -> 矿产权 | K10: 数据资源 | L10: =底稿目录!A19 -> 其他 | M10: 合计
A11: 一、账面原值
A12: 1.期初余额 | B12: ='明细表I1-2'!L20 -> 0 | C12: ='明细表I1-2'!L21 -> 0 | D12: ='明细表I1-2'!L22 -> 0 | E12: ='明细表I1-2'!L23 -> 0 | F12: ='明细表I1-2'!L24 -> 0 | G12: ='明细表I1-2'!L25 -> 0 | H12: ='明细表I1-2'!L26 -> 0 | I12: ='明细表I1-2'!L27 -> 0 | J12: ='明细表I1-2'!L28 -> 0 | K12: ='明细表I1-2'!M29 -> 0 | L12: ='明细表I1-2'!L30 -> 0 | M12: =SUM(B12:L12) -> 0
A13: 2.本期增加金额 | B13: =SUM(B14:B18) -> 0 | C13: =SUM(C14:C18) -> 0 | D13: =SUM(D14:D18) -> 0 | E13: =SUM(E14:E18) -> 0 | F13: =SUM(F14:F18) -> 0 | G13: =SUM(G14:G18) -> 0 | H13: =SUM(H14:H18) -> 0 | I13: =SUM(I14:I18) -> 0 | ... L13: =SUM(L14:L18) -> 0 | M13: =SUM(B13:L13) -> 0
A14: （1）购置 | B14: =IF('明细表I1-2'!$E$20="购置",'明细表I1-2'!$M$20,0) -> 0 | C14: =IF('明细表I1-2'!$E$21="购置",'明细表I1-2'!$M$21,0) -> 0 | D14: =IF('明细表I1-2'!$E$22="购置",'明细表I1-2'!$M$22,0) -> 0 | E14: =IF('明细表I1-2'!$E$23="购置",'明细表I1-2'!$M$23,0) -> 0 | F14: =IF('明细表I1-2'!$E$24="购置",'明细表I1-2'!$M$24,0) -> 0 | G14: =IF('明细表I1-2'!$E$25="购置",'明细表I1-2'!$M$25,0) -> 0 | H14: =IF('明细表I1-2'!$E$26="购置",'明细表I1-2'!$M$26,0) -> 0 | I14: =IF('明细表I1-2'!$E$27="购置",'明细表I1-2'!$M$27,0) -> 0 | J14: =IF('明细表I1-2'!$E$28="购置",'明细表I1-2'!$M$28,0) -> 0 | K14: =IF('明细表I1-2'!$E$29="购置",'明细表I1-2'!$M$29,0) -> 0 | L14: =IF('明细表I1-2'!$E$30="购置",'明细表I1-2'!$M$30,0) -> 0 | M14: =SUM(B14:L14) -> 0
A15: （2）内部研发 | B15: =IF('明细表I1-2'!$E$20="内部研发",'明细表I1-2'!$M$20,0) -> 0 | C15: =IF('明细表I1-2'!$E$21="内部研发",'明细表I1-2'!$M$21,0) -> 0 | D15: =IF('明细表I1-2'!$E$22="内部研发",'明细表I1-2'!$M$22,0) -> 0 | E15: =IF('明细表I1-2'!$E$23="内部研发",'明细表I1-2'!$M$23,0) -> 0 | F15: =IF('明细表I1-2'!$E$24="内部研发",'明细表I1-2'!$M$24,0) -> 0 | G15: =IF('明细表I1-2'!$E$25="内部研发",'明细表I1-2'!$M$25,0) -> 0 | H15: =IF('明细表I1-2'!$E$26="内部研发",'明细表I1-2'!$M$26,0) -> 0 | I15: =IF('明细表I1-2'!$E$27="内部研发",'明细表I1-2'!$M$27,0) -> 0 | J15: =IF('明细表I1-2'!$E$28="内部研发",'明细表I1-2'!$M$28,0) -> 0 | K15: =IF('明细表I1-2'!$E$29="内部研发",'明细表I1-2'!$M$29,0) -> 0 | L15: =IF('明细表I1-2'!$E$30="内部研发",'明细表I1-2'!$M$30,0) -> 0 | M15: =SUM(B15:L15) -> 0
A16: （3）企业合并增加 | B16: =IF('明细表I1-2'!$E$20="企业合并增加",'明细表I1-2'!$M$20,0) -> 0 | C16: =IF('明细表I1-2'!$E$21="企业合并增加",'明细表I1-2'!$M$21,0) -> 0 | D16: =IF('明细表I1-2'!$E$22="企业合并增加",'明细表I1-2'!$M$22,0) -> 0 | E16: =IF('明细表I1-2'!$E$23="企业合并增加",'明细表I1-2'!$M$23,0) -> 0 | F16: =IF('明细表I1-2'!$E$24="企业合并增加",'明细表I1-2'!$M$24,0) -> 0 | G16: =IF('明细表I1-2'!$E$25="企业合并增加",'明细表I1-2'!$M$25,0) -> 0 | H16: =IF('明细表I1-2'!$E$26="企业合并增加",'明细表I1-2'!$M$26,0) -> 0 | I16: =IF('明细表I1-2'!$E$27="企业合并增加",'明细表I1-2'!$M$27,0) -> 0 | J16: =IF('明细表I1-2'!$E$28="企业合并增加",'明细表I1-2'!$M$28,0) -> 0 | K16: =IF('明细表I1-2'!$E$29="企业合并增加",'明细表I1-2'!$M$29,0) -> 0 | L16: =IF('明细表I1-2'!$E$30="企业合并增加",'明细表I1-2'!$M$30,0) -> 0 | M16: =SUM(B16:L16) -> 0
A17: （4）其他增加 | B17: =IF('明细表I1-2'!$E$20="其他增加",'明细表I1-2'!$M$20,0) -> 0 | C17: =IF('明细表I1-2'!$E$21="其他增加",'明细表I1-2'!$M$21,0) -> 0 | D17: =IF('明细表I1-2'!$E$22="其他增加",'明细表I1-2'!$M$22,0) -> 0 | E17: =IF('明细表I1-2'!$E$23="其他增加",'明细表I1-2'!$M$23,0) -> 0 | F17: =IF('明细表I1-2'!$E$24="其他增加",'明细表I1-2'!$M$24,0) -> 0 | G17: =IF('明细表I1-2'!$E$25="其他增加",'明细表I1-2'!$M$25,0) -> 0 | H17: =IF('明细表I1-2'!$E$26="其他增加",'明细表I1-2'!$M$26,0) -> 0 | I17: =IF('明细表I1-2'!$E$27="其他增加",'明细表I1-2'!$M$27,0) -> 0 | J17: =IF('明细表I1-2'!$E$28="其他增加",'明细表I1-2'!$M$28,0) -> 0 | K17: =IF('明细表I1-2'!$E$29="其他增加",'明细表I1-2'!$M$29,0) -> 0 | L17: =IF('明细表I1-2'!$E$30="其他增加",'明细表I1-2'!$M$30,0) -> 0 | M17: =SUM(B17:L17) -> 0
A18: …… | M18: =SUM(B18:L18) -> 0
A19: 3.本期减少金额 | B19: =SUM(B20:B22) -> 0 | C19: =SUM(C20:C22) -> 0 | D19: =SUM(D20:D22) -> 0 | E19: =SUM(E20:E22) -> 0 | F19: =SUM(F20:F22) -> 0 | G19: =SUM(G20:G22) -> 0 | H19: =SUM(H20:H22) -> 0 | I19: =SUM(I20:I22) -> 0 | ... L19: =SUM(L20:L22) -> 0 | M19: =SUM(B19:L19) -> 0
A20: （1）处置 | B20: =IF('明细表I1-2'!$G$20="处置",'明细表I1-2'!$N$20,0) -> 0 | C20: =IF('明细表I1-2'!$G$21="处置",'明细表I1-2'!$N$21,0) -> 0 | D20: =IF('明细表I1-2'!$G$22="购置",'明细表I1-2'!$N$22,0) -> 0 | E20: =IF('明细表I1-2'!$G$23="购置",'明细表I1-2'!$N$23,0) -> 0 | F20: =IF('明细表I1-2'!$G$24="购置",'明细表I1-2'!$N$24,0) -> 0 | G20: =IF('明细表I1-2'!$G$25="购置",'明细表I1-2'!$N$25,0) -> 0 | H20: =IF('明细表I1-2'!$G$26="购置",'明细表I1-2'!$N$26,0) -> 0 | I20: =IF('明细表I1-2'!$G$27="购置",'明细表I1-2'!$N$27,0) -> 0 | J20: =IF('明细表I1-2'!$G$28="购置",'明细表I1-2'!$N$28,0) -> 0 | K20: =IF('明细表I1-2'!$G$29="购置",'明细表I1-2'!$N$29,0) -> 0 | L20: =IF('明细表I1-2'!$G$30="购置",'明细表I1-2'!$N$30,0) -> 0 | M20: =SUM(B20:L20) -> 0
A21: （2）失效且终止确认的部分 | B21: =IF('明细表I1-2'!$G$20="失效且终止确认的部分",'明细表I1-2'!$N$20,0) -> 0 | C21: =IF('明细表I1-2'!$G$21="失效且终止确认的部分",'明细表I1-2'!$N$21,0) -> 0 | D21: =IF('明细表I1-2'!$G$22="失效且终止确认的部分",'明细表I1-2'!$N$22,0) -> 0 | E21: =IF('明细表I1-2'!$G$23="失效且终止确认的部分",'明细表I1-2'!$N$23,0) -> 0 | F21: =IF('明细表I1-2'!$G$24="失效且终止确认的部分",'明细表I1-2'!$N$24,0) -> 0 | G21: =IF('明细表I1-2'!$G$25="失效且终止确认的部分",'明细表I1-2'!$N$25,0) -> 0 | H21: =IF('明细表I1-2'!$G$26="失效且终止确认的部分",'明细表I1-2'!$N$26,0) -> 0 | I21: =IF('明细表I1-2'!$G$27="失效且终止确认的部分",'明细表I1-2'!$N$27,0) -> 0 | J21: =IF('明细表I1-2'!$G$28="失效且终止确认的部分",'明细表I1-2'!$N$28,0) -> 0 | K21: =IF('明细表I1-2'!$G$29="失效且终止确认的部分",'明细表I1-2'!$N$29,0) -> 0 | L21: =IF('明细表I1-2'!$G$30="失效且终止确认的部分",'明细表I1-2'!$N$30,0) -> 0 | M21: =SUM(B21:L21) -> 0
A22: （3）其他减少 | B22: =IF('明细表I1-2'!$G$20="其他减少",'明细表I1-2'!$N$20,0) -> 0 | C22: =IF('明细表I1-2'!$G$21="其他减少",'明细表I1-2'!$N$21,0) -> 0 | D22: =IF('明细表I1-2'!$G$22="其他减少",'明细表I1-2'!$N$22,0) -> 0 | E22: =IF('明细表I1-2'!$G$23="其他减少",'明细表I1-2'!$N$23,0) -> 0 | F22: =IF('明细表I1-2'!$G$24="其他减少",'明细表I1-2'!$N$24,0) -> 0 | G22: =IF('明细表I1-2'!$G$25="其他减少",'明细表I1-2'!$N$25,0) -> 0 | H22: =IF('明细表I1-2'!$G$26="其他减少",'明细表I1-2'!$N$26,0) -> 0 | I22: =IF('明细表I1-2'!$G$27="其他减少",'明细表I1-2'!$N$27,0) -> 0 | J22: =IF('明细表I1-2'!$G$28="其他减少",'明细表I1-2'!$N$28,0) -> 0 | K22: =IF('明细表I1-2'!$G$29="其他减少",'明细表I1-2'!$N$29,0) -> 0 | L22: =IF('明细表I1-2'!$G$30="其他减少",'明细表I1-2'!$N$30,0) -> 0 | M22: =SUM(B22:L22) -> 0
A23: 4.期末余额 | B23: =B12+B13-B19 -> 0 | C23: =C12+C13-C19 -> 0 | D23: =D12+D13-D19 -> 0 | E23: =E12+E13-E19 -> 0 | F23: =F12+F13-F19 -> 0 | G23: =G12+G13-G19 -> 0 | H23: =H12+H13-H19 -> 0 | I23: =I12+I13-I19 -> 0 | ... L23: =L12+L13-L19 -> 0 | M23: =SUM(B23:L23) -> 0
A24: 二、累计摊销 | M24: =SUM(B24:L24) -> 0
A25: 1.期初余额 | B25: ='明细表I1-2'!Y20 -> 0 | C25: ='明细表I1-2'!Y21 -> 0 | D25: ='明细表I1-2'!Y22 -> 0 | E25: ='明细表I1-2'!Y23 -> 0 | F25: ='明细表I1-2'!Y24 -> 0 | G25: ='明细表I1-2'!Y25 -> 0 | H25: ='明细表I1-2'!Y26 -> 0 | I25: ='明细表I1-2'!Y27 -> 0 | J25: ='明细表I1-2'!Y28 -> 0 | K25: ='明细表I1-2'!Z29 -> 0 | L25: ='明细表I1-2'!Y30 -> 0 | M25: =SUM(B25:L25) -> 0
A26: 2.本期增加金额 | B26: =SUM(B27:B29) -> 0 | C26: =SUM(C27:C29) -> 0 | D26: =SUM(D27:D29) -> 0 | E26: =SUM(E27:E29) -> 0 | F26: =SUM(F27:F29) -> 0 | G26: =SUM(G27:G29) -> 0 | H26: =SUM(H27:H29) -> 0 | I26: =SUM(I27:I29) -> 0 | ... L26: =SUM(L27:L29) -> 0 | M26: =SUM(B26:L26) -> 0
A27: （1）计提 | M27: =SUM(B27:L27) -> 0
A28: （2）其他增加 | M28: =SUM(B28:L28) -> 0
A29: …… | M29: =SUM(B29:L29) -> 0
A30: 3.本期减少金额 | B30: =SUM(B31:B33) -> 0 | C30: =SUM(C31:C33) -> 0 | D30: =SUM(D31:D33) -> 0 | E30: =SUM(E31:E33) -> 0 | F30: =SUM(F31:F33) -> 0 | G30: =SUM(G31:G33) -> 0 | H30: =SUM(H31:H33) -> 0 | I30: =SUM(I31:I33) -> 0 | ... L30: =SUM(L31:L33) -> 0 | M30: =SUM(B30:L30) -> 0
A31: （1）处置 | M31: =SUM(B31:L31) -> 0
A32: （2）失效且终止确认的部分 | M32: =SUM(B32:L32) -> 0
A33: （3）其他减少 | M33: =SUM(B33:L33) -> 0
A34: 4.期末余额 | B34: =B25+B26-B30 -> 0 | C34: =C25+C26-C30 -> 0 | D34: =D25+D26-D30 -> 0 | E34: =E25+E26-E30 -> 0 | F34: =F25+F26-F30 -> 0 | G34: =G25+G26-G30 -> 0 | H34: =H25+H26-H30 -> 0 | I34: =I25+I26-I30 -> 0 | ... L34: =L25+L26-L30 -> 0 | M34: =SUM(B34:L34) -> 0
A35: 三、减值准备 | M35: =SUM(B35:L35) -> 0
A36: 1.期初余额 | B36: ='明细表I1-2'!AL20 -> 0 | C36: ='明细表I1-2'!AL21 -> 0 | D36: ='明细表I1-2'!AL22 -> 0 | E36: ='明细表I1-2'!AL23 -> 0 | F36: ='明细表I1-2'!AL24 -> 0 | G36: ='明细表I1-2'!AL25 -> 0 | H36: ='明细表I1-2'!AL26 -> 0 | I36: ='明细表I1-2'!AL27 -> 0 | J36: ='明细表I1-2'!AL28 -> 0 | K36: ='明细表I1-2'!AM29 -> 0 | L36: ='明细表I1-2'!AL30 -> 0 | M36: =SUM(B36:L36) -> 0
A37: 2.本期增加金额 | B37: =SUM(B38:B40) -> 0 | C37: =SUM(C38:C40) -> 0 | D37: =SUM(D38:D40) -> 0 | E37: =SUM(E38:E40) -> 0 | F37: =SUM(F38:F40) -> 0 | G37: =SUM(G38:G40) -> 0 | H37: =SUM(H38:H40) -> 0 | I37: =SUM(I38:I40) -> 0 | ... L37: =SUM(L38:L40) -> 0 | M37: =SUM(B37:L37) -> 0
A38: （1）计提 | M38: =SUM(B38:L38) -> 0
A39: （2）其他增加 | M39: =SUM(B39:L39) -> 0
A40: …… | M40: =SUM(B40:L40) -> 0
...

Sheet 附注披露信息（国有企业）
A1: 致同会计师事务所
A2: 无形资产、累计摊销及减值准备附注披露表（国有企业）
A3: =底稿目录!A2 -> 被审计单位： | B3: =底稿目录!A4 -> 编制人： | C3: =底稿目录!A5 -> 编制日期： | D3: 索引号：
A4: =底稿目录!A3 -> 截止日：202X年12月31日 | B4: =底稿目录!A6 -> 复核人： | C4: =底稿目录!A7 -> 复核日期： | D4: 页次：
A5: 无形资产
A6: （1）无形资产分类
A7: 项 目 | B7: 期初余额 | C7: 本期增加 | D7: 本期减少 | E7: 期末余额
A8: 一、原价合计 | B8: =SUM(B9:B20) -> 0 | C8: =SUM(C9:C20) -> 0 | D8: =SUM(D9:D20) -> 0 | E8: =SUM(E9:E20) -> 0
A9: 其中：土地使用权 | B9: ='明细表I1-2'!L20 -> 0 | C9: ='明细表I1-2'!M20 -> 0 | D9: ='明细表I1-2'!N20 -> 0 | E9: =B9+C9-D9 -> 0
A10: 住房使用权 | B10: ='明细表I1-2'!L21 -> 0 | C10: ='明细表I1-2'!M21 -> 0 | D10: ='明细表I1-2'!N21 -> 0 | E10: =B10+C10-D10 -> 0
A11: 专利权 | B11: ='明细表I1-2'!L22 -> 0 | C11: ='明细表I1-2'!M22 -> 0 | D11: ='明细表I1-2'!N22 -> 0 | E11: =B11+C11-D11 -> 0
A12: 非专利技术 | B12: ='明细表I1-2'!L23 -> 0 | C12: ='明细表I1-2'!M23 -> 0 | D12: ='明细表I1-2'!N23 -> 0 | E12: =B12+C12-D12 -> 0
A13: 商标权 | B13: ='明细表I1-2'!L24 -> 0 | C13: ='明细表I1-2'!M24 -> 0 | D13: ='明细表I1-2'!N24 -> 0 | E13: =B13+C13-D13 -> 0
A14: 著作权 | B14: ='明细表I1-2'!L25 -> 0 | C14: ='明细表I1-2'!M25 -> 0 | D14: ='明细表I1-2'!N25 -> 0 | E14: =B14+C14-D14 -> 0
A15: 特许经营权 | B15: ='明细表I1-2'!L26 -> 0 | C15: ='明细表I1-2'!M26 -> 0 | D15: ='明细表I1-2'!N26 -> 0 | E15: =B15+C15-D15 -> 0
A16: 软件 | B16: ='明细表I1-2'!L27 -> 0 | C16: ='明细表I1-2'!M27 -> 0 | D16: ='明细表I1-2'!N27 -> 0 | E16: =B16+C16-D16 -> 0
A17: 矿产权 | B17: ='明细表I1-2'!L28 -> 0 | C17: ='明细表I1-2'!M28 -> 0 | D17: ='明细表I1-2'!N28 -> 0 | E17: =B17+C17-D17 -> 0
A18: 数据资源 | B18: ='明细表I1-2'!L29 -> 0 | C18: ='明细表I1-2'!M29 -> 0 | D18: ='明细表I1-2'!N29 -> 0 | E18: =B18+C18-D18 -> 0
A19: 其他 | B19: ='明细表I1-2'!L30 -> 0 | C19: ='明细表I1-2'!M30 -> 0 | D19: ='明细表I1-2'!N30 -> 0 | E19: =B19+C19-D19 -> 0
A20: …… | B20: ='明细表I1-2'!L31 -> 0 | C20: ='明细表I1-2'!M31 -> 0 | D20: ='明细表I1-2'!N31 -> 0 | E20: =B20+C20-D20 -> 0
A21: 二、累计摊销合计 | B21: =SUM(B22:B33) -> 0 | C21: =SUM(C22:C33) -> 0 | D21: =SUM(D22:D33) -> 0 | E21: =SUM(E22:E33) -> 0
A22: 其中：土地使用权 | B22: ='明细表I1-2'!Y20 -> 0 | C22: ='明细表I1-2'!Z20 -> 0 | D22: ='明细表I1-2'!AA20 -> 0 | E22: =B22+C22-D22 -> 0
A23: 住房使用权 | B23: ='明细表I1-2'!Y21 -> 0 | C23: ='明细表I1-2'!Z21 -> 0 | D23: ='明细表I1-2'!AA21 -> 0 | E23: =B23+C23-D23 -> 0
A24: 专利权 | B24: ='明细表I1-2'!Y22 -> 0 | C24: ='明细表I1-2'!Z22 -> 0 | D24: ='明细表I1-2'!AA22 -> 0 | E24: =B24+C24-D24 -> 0
A25: 非专利技术 | B25: ='明细表I1-2'!Y23 -> 0 | C25: ='明细表I1-2'!Z23 -> 0 | D25: ='明细表I1-2'!AA23 -> 0 | E25: =B25+C25-D25 -> 0
A26: 商标权 | B26: ='明细表I1-2'!Y24 -> 0 | C26: ='明细表I1-2'!Z24 -> 0 | D26: ='明细表I1-2'!AA24 -> 0 | E26: =B26+C26-D26 -> 0
A27: 著作权 | B27: ='明细表I1-2'!Y25 -> 0 | C27: ='明细表I1-2'!Z25 -> 0 | D27: ='明细表I1-2'!AA25 -> 0 | E27: =B27+C27-D27 -> 0
A28: 特许经营权 | B28: ='明细表I1-2'!Y26 -> 0 | C28: ='明细表I1-2'!Z26 -> 0 | D28: ='明细表I1-2'!AA26 -> 0 | E28: =B28+C28-D28 -> 0
A29: 软件 | B29: ='明细表I1-2'!Y27 -> 0 | C29: ='明细表I1-2'!Z27 -> 0 | D29: ='明细表I1-2'!AA27 -> 0 | E29: =B29+C29-D29 -> 0
A30: 矿产权 | B30: ='明细表I1-2'!Y28 -> 0 | C30: ='明细表I1-2'!Z28 -> 0 | D30: ='明细表I1-2'!AA28 -> 0 | E30: =B30+C30-D30 -> 0
A31: 数据资源 | B31: ='明细表I1-2'!Y29 -> 0 | C31: ='明细表I1-2'!Z29 -> 0 | D31: ='明细表I1-2'!AA29 -> 0 | E31: =B31+C31-D31 -> 0
A32: 其他 | B32: ='明细表I1-2'!Y30 -> 0 | C32: ='明细表I1-2'!Z30 -> 0 | D32: ='明细表I1-2'!AA30 -> 0 | E32: =B32+C32-D32 -> 0
A33: …… | B33: ='明细表I1-2'!Y31 -> 0 | C33: ='明细表I1-2'!Z31 -> 0 | D33: ='明细表I1-2'!AA31 -> 0 | E33: =B33+C33-D33 -> 0
A34: 三、无形资产减值准备合计 | B34: =SUM(B35:B46) -> 0 | C34: =SUM(C35:C46) -> 0 | D34: =SUM(D35:D46) -> 0 | E34: =SUM(E35:E46) -> 0
A35: 其中：土地使用权 | B35: ='明细表I1-2'!AL20 -> 0 | C35: ='明细表I1-2'!AM20 -> 0 | D35: ='明细表I1-2'!AN20 -> 0 | E35: =B35+C35-D35 -> 0
A36: 住房使用权 | B36: ='明细表I1-2'!AL21 -> 0 | C36: ='明细表I1-2'!AM21 -> 0 | D36: ='明细表I1-2'!AN21 -> 0 | E36: =B36+C36-D36 -> 0
A37: 专利权 | B37: ='明细表I1-2'!AL22 -> 0 | C37: ='明细表I1-2'!AM22 -> 0 | D37: ='明细表I1-2'!AN22 -> 0 | E37: =B37+C37-D37 -> 0
A38: 非专利技术 | B38: ='明细表I1-2'!AL23 -> 0 | C38: ='明细表I1-2'!AM23 -> 0 | D38: ='明细表I1-2'!AN23 -> 0 | E38: =B38+C38-D38 -> 0
A39: 商标权 | B39: ='明细表I1-2'!AL24 -> 0 | C39: ='明细表I1-2'!AM24 -> 0 | D39: ='明细表I1-2'!AN24 -> 0 | E39: =B39+C39-D39 -> 0
A40: 著作权 | B40: ='明细表I1-2'!AL25 -> 0 | C40: ='明细表I1-2'!AM25 -> 0 | D40: ='明细表I1-2'!AN25 -> 0 | E40: =B40+C40-D40 -> 0
...

Sheet 明细表I1-2
A1: 致同会计师事务所 | P1: 致同会计师事务所 | AC1: 致同会计师事务所
A2: 无形资产、累计摊销及减值准备明细表 | P2: 无形资产、累计摊销及减值准备明细表 | AC2: 无形资产、累计摊销及减值准备明细表
A3: =底稿目录!A2 -> 被审计单位： | G3: =底稿目录!A4 -> 编制人： | K3: =底稿目录!A5 -> 编制日期： | N3: 索引号： | O3: I1-2 | U3: =G3 -> 编制人： | AA3: 索引号： | AB3: I1-2 | AH3: =G3 -> 编制人： | AN3: =K3 -> 编制日期： | AT3: 索引号： | AU3: I1-2
A4: =底稿目录!A3 -> 截止日：202X年12月31日 | G4: =底稿目录!A6 -> 复核人： | K4: =底稿目录!A7 -> 复核日期： | N4: 页次： | U4: =底稿目录!A6 -> 复核人： | AA4: 页次： | AH4: =底稿目录!A6 -> 复核人： | AN4: =底稿目录!A7 -> 复核日期： | AT4: 页次：
A5: 一、审计目标: | P5: 一、审计目标: | AC5: 一、审计目标:
A6: 核对明细账、总账、报表、上年审计报告审定数金额是否相符，确定期初、期末余额是否正确。 | P6: 核对明细账、总账、报表、上年审计报告审定数金额是否相符，确定期初、期末余额是否正确。 | AC6: 1 | AD6: 核对明细账、总账、报表、上年审计报告审定数金额是否相符，确定期初、期末余额是否正确。
A7: 二、审计过程： | P7: 二、审计过程： | AC7: 二、审计过程：
A8: 无形资产项目 | B8: 无形资产类别 | C8: 无形资产原值 | P8: 累计摊销 | AC8: 减值准备 | AP8: 期初净值 | AR8: 期末净值 | AT8: 是否有权属证明 | AU8: 是否抵押受限
C9: 未审数 | I9: 期初调整 | J9: 账项调整 | L9: 审定数 | P9: 未审数 | V9: 期初调整 | W9: 账项调整 | Y9: 审定数 | AC9: 未审数 | AI9: 期初调整 | AJ9: 账项调整 | AL9: 审定数
C10: 期初数 | D10: 本期增加 | F10: 本期减少 | H10: 期末数 | I10: 账项调整 | J10: 本期增加 | K10: 本期减少 | L10: 期初数 | M10: 本期增加 | N10: 本期减少 | O10: 期末数 | P10: 期初数 | Q10: 本期增加 | S10: 本期减少 | U10: 期末数 | V10: 账项调整 | W10: 本期增加 | X10: 本期减少 | Y10: 期初数 | Z10: 本期增加 | AA10: 本期减少 | AB10: 期末数 | AC10: 期初数 | AD10: 本期增加 | AF10: 本期减少 | AH10: 期末数 | AI10: 账项调整 | AJ10: 本期增加 | AK10: 本期减少 | AL10: 期初数 | AM10: 本期增加 | AN10: 本期减少 | AO10: 期末数 | AP10: 未审净值 | AQ10: 审定净值 | AR10: 未审净值 | AS10: 审定净值
D11: 金额 | E11: 增加方式 | F11: 金额 | G11: 减少方式 | Q11: 本期摊销 | R11: 其他增加 | S11: 处置 | T11: 其他减少 | AD11: 本期计提 | AE11: 其他增加 | AF11: 处置 | AG11: 其他减少
A12: A | H12: =SUM(C12:D12)-F12 -> 0 | L12: =C12+I12 -> 0 | M12: =D12+J12 -> 0 | N12: =F12+K12 -> 0 | O12: =L12+M12-N12 -> 0 | U12: =SUM(P12:Q12)-S12 -> 0 | Y12: =P12+V12 -> 0 | Z12: =Q12+W12+R12 -> 0 | AA12: =S12+X12+T12 -> 0 | AB12: =Y12+Z12-AA12 -> 0 | AH12: =SUM(AC12:AE12)-SUM(AF12:AG12) -> 0 | AL12: =AC12+AI12 -> 0 | AM12: =AD12+AJ12+AE12 -> 0 | AN12: =AF12+AK12+AG12 -> 0 | AO12: =AL12+AM12-AN12 -> 0 | AP12: =C12-P12-AC12 -> 0 | AQ12: =L12-Y12-AL12 -> 0 | AR12: =H12-U12-AH12 -> 0 | AS12: =O12-AB12-AO12 -> 0
A13: B | H13: =SUM(C13:D13)-F13 -> 0 | L13: =C13+I13 -> 0 | M13: =D13+J13 -> 0 | N13: =F13+K13 -> 0 | O13: =L13+M13-N13 -> 0 | U13: =SUM(P13:Q13)-S13 -> 0 | Y13: =P13+V13 -> 0 | Z13: =Q13+W13+R13 -> 0 | AA13: =S13+X13+T13 -> 0 | AB13: =Y13+Z13-AA13 -> 0 | AH13: =SUM(AC13:AE13)-SUM(AF13:AG13) -> 0 | AL13: =AC13+AI13 -> 0 | AM13: =AD13+AJ13+AE13 -> 0 | AN13: =AF13+AK13+AG13 -> 0 | AO13: =AL13+AM13-AN13 -> 0 | AP13: =C13-P13-AC13 -> 0 | AQ13: =L13-Y13-AL13 -> 0 | AR13: =H13-U13-AH13 -> 0 | AS13: =O13-AB13-AO13 -> 0
A14: C | H14: =SUM(C14:D14)-F14 -> 0 | L14: =C14+I14 -> 0 | M14: =D14+J14 -> 0 | N14: =F14+K14 -> 0 | O14: =L14+M14-N14 -> 0 | U14: =SUM(P14:Q14)-S14 -> 0 | Y14: =P14+V14 -> 0 | Z14: =Q14+W14+R14 -> 0 | AA14: =S14+X14+T14 -> 0 | AB14: =Y14+Z14-AA14 -> 0 | AH14: =SUM(AC14:AE14)-SUM(AF14:AG14) -> 0 | AL14: =AC14+AI14 -> 0 | AM14: =AD14+AJ14+AE14 -> 0 | AN14: =AF14+AK14+AG14 -> 0 | AO14: =AL14+AM14-AN14 -> 0 | AP14: =C14-P14-AC14 -> 0 | AQ14: =L14-Y14-AL14 -> 0 | AR14: =H14-U14-AH14 -> 0 | AS14: =O14-AB14-AO14 -> 0
A15: D | H15: =SUM(C15:D15)-F15 -> 0 | L15: =C15+I15 -> 0 | M15: =D15+J15 -> 0 | N15: =F15+K15 -> 0 | O15: =L15+M15-N15 -> 0 | U15: =SUM(P15:Q15)-S15 -> 0 | Y15: =P15+V15 -> 0 | Z15: =Q15+W15+R15 -> 0 | AA15: =S15+X15+T15 -> 0 | AB15: =Y15+Z15-AA15 -> 0 | AH15: =SUM(AC15:AE15)-SUM(AF15:AG15) -> 0 | AL15: =AC15+AI15 -> 0 | AM15: =AD15+AJ15+AE15 -> 0 | AN15: =AF15+AK15+AG15 -> 0 | AO15: =AL15+AM15-AN15 -> 0 | AP15: =C15-P15-AC15 -> 0 | AQ15: =L15-Y15-AL15 -> 0 | AR15: =H15-U15-AH15 -> 0 | AS15: =O15-AB15-AO15 -> 0
A16: … | H16: =SUM(C16:D16)-F16 -> 0 | L16: =C16+I16 -> 0 | M16: =D16+J16 -> 0 | N16: =F16+K16 -> 0 | O16: =L16+M16-N16 -> 0 | U16: =SUM(P16:Q16)-S16 -> 0 | Y16: =P16+V16 -> 0 | Z16: =Q16+W16+R16 -> 0 | AA16: =S16+X16+T16 -> 0 | AB16: =Y16+Z16-AA16 -> 0 | AH16: =SUM(AC16:AE16)-SUM(AF16:AG16) -> 0 | AL16: =AC16+AI16 -> 0 | AM16: =AD16+AJ16+AE16 -> 0 | AN16: =AF16+AK16+AG16 -> 0 | AO16: =AL16+AM16-AN16 -> 0 | AP16: =C16-P16-AC16 -> 0 | AQ16: =L16-Y16-AL16 -> 0 | AR16: =H16-U16-AH16 -> 0 | AS16: =O16-AB16-AO16 -> 0
H17: =SUM(C17:D17)-F17 -> 0 | L17: =C17+I17 -> 0 | M17: =D17+J17 -> 0 | N17: =F17+K17 -> 0 | O17: =L17+M17-N17 -> 0 | U17: =SUM(P17:Q17)-S17 -> 0 | Y17: =P17+V17 -> 0 | Z17: =Q17+W17+R17 -> 0 | AA17: =S17+X17+T17 -> 0 | AB17: =Y17+Z17-AA17 -> 0 | AH17: =SUM(AC17:AE17)-SUM(AF17:AG17) -> 0 | AL17: =AC17+AI17 -> 0 | AM17: =AD17+AJ17+AE17 -> 0 | AN17: =AF17+AK17+AG17 -> 0 | AO17: =AL17+AM17-AN17 -> 0 | AP17: =C17-P17-AC17 -> 0 | AQ17: =L17-Y17-AL17 -> 0 | AR17: =H17-U17-AH17 -> 0 | AS17: =O17-AB17-AO17 -> 0
A18: 合计 | C18: =SUM(C12:C17) -> 0 | D18: =SUM(D12:D17) -> 0 | F18: =SUM(F12:F17) -> 0 | H18: =SUM(H12:H17) -> 0 | I18: =SUM(I12:I17) -> 0 | J18: =SUM(J12:J17) -> 0 | K18: =SUM(K12:K17) -> 0 | L18: =SUM(L12:L17) -> 0 | M18: =SUM(M12:M17) -> 0 | N18: =SUM(N12:N17) -> 0 | O18: =SUM(O12:O17) -> 0 | ... AS18: =SUM(AS12:AS17) -> 0
A19: 其中：
A20: =底稿目录!A9 -> 土地使用权 | C20: {=SUMPRODUCT(($B$12:$B$17=$A20)*(C$12:C$17))} -> 0 | D20: {=SUMPRODUCT(($B$12:$B$17=$A20)*(D$12:D$17))} -> 0 | F20: =SUMPRODUCT(($B$12:$B$17=$A20)*(F$12:F$17)) -> 0 | H20: {=SUMPRODUCT(($B$12:$B$17=$A20)*(H$12:H$17))} -> 0 | I20: {=SUMPRODUCT(($B$12:$B$17=$A20)*(I$12:I$17))} -> 0 | J20: {=SUMPRODUCT(($B$12:$B$17=$A20)*(J$12:J$17))} -> 0 | K20: {=SUMPRODUCT(($B$12:$B$17=$A20)*(K$12:K$17))} -> 0 | L20: {=SUMPRODUCT(($B$12:$B$17=$A20)*(L$12:L$17))} -> 0 | M20: {=SUMPRODUCT(($B$12:$B$17=$A20)*(M$12:M$17))} -> 0 | N20: {=SUMPRODUCT(($B$12:$B$17=$A20)*(N$12:N$17))} -> 0 | O20: {=SUMPRODUCT(($B$12:$B$17=$A20)*(O$12:O$17))} -> 0 | ... Y20: {=SUMPRODUCT(($B$12:$B$17=$A20)*(Y$12:Y$17))} -> 0 | Z20: =SUMPRODUCT(($B$12:$B$17=$A20)*(Z$12:Z$17)) -> 0 | AA20: {=SUMPRODUCT(($B$12:$B$17=$A20)*(AA$12:AA$17))} -> 0 | AB20: {=SUMPRODUCT(($B$12:$B$17=$A20)*(AB$12:AB$17))} -> 0 | AC20: {=SUMPRODUCT(($B$12:$B$17=$A20)*(AC$12:AC$17))} -> 0 | AD20: {=SUMPRODUCT(($B$12:$B$17=$A20)*(AD$12:AD$17))} -> 0 | AE20: {=SUMPRODUCT(($B$12:$B$17=$A20)*(AE$12:AE$17))} -> 0 | AF20: {=SUMPRODUCT(($B$12:$B$17=$A20)*(AF$12:AF$17))} -> 0 | AG20: {=SUMPRODUCT(($B$12:$B$17=$A20)*(AG$12:AG$17))} -> 0 | AH20: {=SUMPRODUCT(($B$12:$B$17=$A20)*(AH$12:AH$17))} -> 0 | ... AS20: {=SUMPRODUCT(($B$12:$B$17=$A20)*(AS$12:AS$17))} -> 0
A21: =底稿目录!A10 -> 住房使用权 | C21: {=SUMPRODUCT(($B$12:$B$17=$A21)*(C$12:C$17))} -> 0 | D21: {=SUMPRODUCT(($B$12:$B$17=$A21)*(D$12:D$17))} -> 0 | F21: {=SUMPRODUCT(($B$12:$B$17=$A21)*(F$12:F$17))} -> 0 | H21: {=SUMPRODUCT(($B$12:$B$17=$A21)*(H$12:H$17))} -> 0 | I21: {=SUMPRODUCT(($B$12:$B$17=$A21)*(I$12:I$17))} -> 0 | J21: {=SUMPRODUCT(($B$12:$B$17=$A21)*(J$12:J$17))} -> 0 | K21: {=SUMPRODUCT(($B$12:$B$17=$A21)*(K$12:K$17))} -> 0 | L21: {=SUMPRODUCT(($B$12:$B$17=$A21)*(L$12:L$17))} -> 0 | M21: {=SUMPRODUCT(($B$12:$B$17=$A21)*(M$12:M$17))} -> 0 | N21: {=SUMPRODUCT(($B$12:$B$17=$A21)*(N$12:N$17))} -> 0 | O21: {=SUMPRODUCT(($B$12:$B$17=$A21)*(O$12:O$17))} -> 0 | ... AS21: {=SUMPRODUCT(($B$12:$B$17=$A21)*(AS$12:AS$17))} -> 0
A22: =底稿目录!A11 -> 专利权 | C22: {=SUMPRODUCT(($B$12:$B$17=$A22)*(C$12:C$17))} -> 0 | D22: {=SUMPRODUCT(($B$12:$B$17=$A22)*(D$12:D$17))} -> 0 | F22: {=SUMPRODUCT(($B$12:$B$17=$A22)*(F$12:F$17))} -> 0 | H22: {=SUMPRODUCT(($B$12:$B$17=$A22)*(H$12:H$17))} -> 0 | I22: {=SUMPRODUCT(($B$12:$B$17=$A22)*(I$12:I$17))} -> 0 | J22: {=SUMPRODUCT(($B$12:$B$17=$A22)*(J$12:J$17))} -> 0 | K22: {=SUMPRODUCT(($B$12:$B$17=$A22)*(K$12:K$17))} -> 0 | L22: {=SUMPRODUCT(($B$12:$B$17=$A22)*(L$12:L$17))} -> 0 | M22: {=SUMPRODUCT(($B$12:$B$17=$A22)*(M$12:M$17))} -> 0 | N22: {=SUMPRODUCT(($B$12:$B$17=$A22)*(N$12:N$17))} -> 0 | O22: {=SUMPRODUCT(($B$12:$B$17=$A22)*(O$12:O$17))} -> 0 | ... AS22: {=SUMPRODUCT(($B$12:$B$17=$A22)*(AS$12:AS$17))} -> 0
A23: =底稿目录!A12 -> 非专利技术 | C23: {=SUMPRODUCT(($B$12:$B$17=$A23)*(C$12:C$17))} -> 0 | D23: {=SUMPRODUCT(($B$12:$B$17=$A23)*(D$12:D$17))} -> 0 | F23: {=SUMPRODUCT(($B$12:$B$17=$A23)*(F$12:F$17))} -> 0 | H23: {=SUMPRODUCT(($B$12:$B$17=$A23)*(H$12:H$17))} -> 0 | I23: {=SUMPRODUCT(($B$12:$B$17=$A23)*(I$12:I$17))} -> 0 | J23: {=SUMPRODUCT(($B$12:$B$17=$A23)*(J$12:J$17))} -> 0 | K23: {=SUMPRODUCT(($B$12:$B$17=$A23)*(K$12:K$17))} -> 0 | L23: {=SUMPRODUCT(($B$12:$B$17=$A23)*(L$12:L$17))} -> 0 | M23: {=SUMPRODUCT(($B$12:$B$17=$A23)*(M$12:M$17))} -> 0 | N23: {=SUMPRODUCT(($B$12:$B$17=$A23)*(N$12:N$17))} -> 0 | O23: {=SUMPRODUCT(($B$12:$B$17=$A23)*(O$12:O$17))} -> 0 | ... AS23: {=SUMPRODUCT(($B$12:$B$17=$A23)*(AS$12:AS$17))} -> 0
A24: =底稿目录!A13 -> 商标权 | C24: {=SUMPRODUCT(($B$12:$B$17=$A24)*(C$12:C$17))} -> 0 | D24: {=SUMPRODUCT(($B$12:$B$17=$A24)*(D$12:D$17))} -> 0 | F24: {=SUMPRODUCT(($B$12:$B$17=$A24)*(F$12:F$17))} -> 0 | H24: {=SUMPRODUCT(($B$12:$B$17=$A24)*(H$12:H$17))} -> 0 | I24: {=SUMPRODUCT(($B$12:$B$17=$A24)*(I$12:I$17))} -> 0 | J24: {=SUMPRODUCT(($B$12:$B$17=$A24)*(J$12:J$17))} -> 0 | K24: {=SUMPRODUCT(($B$12:$B$17=$A24)*(K$12:K$17))} -> 0 | L24: {=SUMPRODUCT(($B$12:$B$17=$A24)*(L$12:L$17))} -> 0 | M24: {=SUMPRODUCT(($B$12:$B$17=$A24)*(M$12:M$17))} -> 0 | N24: {=SUMPRODUCT(($B$12:$B$17=$A24)*(N$12:N$17))} -> 0 | O24: {=SUMPRODUCT(($B$12:$B$17=$A24)*(O$12:O$17))} -> 0 | ... AS24: {=SUMPRODUCT(($B$12:$B$17=$A24)*(AS$12:AS$17))} -> 0
A25: =底稿目录!A14 -> 著作权 | C25: {=SUMPRODUCT(($B$12:$B$17=$A25)*(C$12:C$17))} -> 0 | D25: {=SUMPRODUCT(($B$12:$B$17=$A25)*(D$12:D$17))} -> 0 | F25: {=SUMPRODUCT(($B$12:$B$17=$A25)*(F$12:F$17))} -> 0 | H25: {=SUMPRODUCT(($B$12:$B$17=$A25)*(H$12:H$17))} -> 0 | I25: {=SUMPRODUCT(($B$12:$B$17=$A25)*(I$12:I$17))} -> 0 | J25: {=SUMPRODUCT(($B$12:$B$17=$A25)*(J$12:J$17))} -> 0 | K25: {=SUMPRODUCT(($B$12:$B$17=$A25)*(K$12:K$17))} -> 0 | L25: {=SUMPRODUCT(($B$12:$B$17=$A25)*(L$12:L$17))} -> 0 | M25: {=SUMPRODUCT(($B$12:$B$17=$A25)*(M$12:M$17))} -> 0 | N25: {=SUMPRODUCT(($B$12:$B$17=$A25)*(N$12:N$17))} -> 0 | O25: {=SUMPRODUCT(($B$12:$B$17=$A25)*(O$12:O$17))} -> 0 | ... AS25: {=SUMPRODUCT(($B$12:$B$17=$A25)*(AS$12:AS$17))} -> 0
A26: =底稿目录!A15 -> 特许经营权 | C26: {=SUMPRODUCT(($B$12:$B$17=$A26)*(C$12:C$17))} -> 0 | D26: {=SUMPRODUCT(($B$12:$B$17=$A26)*(D$12:D$17))} -> 0 | F26: {=SUMPRODUCT(($B$12:$B$17=$A26)*(F$12:F$17))} -> 0 | H26: {=SUMPRODUCT(($B$12:$B$17=$A26)*(H$12:H$17))} -> 0 | I26: {=SUMPRODUCT(($B$12:$B$17=$A26)*(I$12:I$17))} -> 0 | J26: {=SUMPRODUCT(($B$12:$B$17=$A26)*(J$12:J$17))} -> 0 | K26: {=SUMPRODUCT(($B$12:$B$17=$A26)*(K$12:K$17))} -> 0 | L26: {=SUMPRODUCT(($B$12:$B$17=$A26)*(L$12:L$17))} -> 0 | M26: {=SUMPRODUCT(($B$12:$B$17=$A26)*(M$12:M$17))} -> 0 | N26: {=SUMPRODUCT(($B$12:$B$17=$A26)*(N$12:N$17))} -> 0 | O26: {=SUMPRODUCT(($B$12:$B$17=$A26)*(O$12:O$17))} -> 0 | ... AS26: {=SUMPRODUCT(($B$12:$B$17=$A26)*(AS$12:AS$17))} -> 0
A27: =底稿目录!A16 -> 软件 | C27: {=SUMPRODUCT(($B$12:$B$17=$A27)*(C$12:C$17))} -> 0 | D27: {=SUMPRODUCT(($B$12:$B$17=$A27)*(D$12:D$17))} -> 0 | F27: {=SUMPRODUCT(($B$12:$B$17=$A27)*(F$12:F$17))} -> 0 | H27: {=SUMPRODUCT(($B$12:$B$17=$A27)*(H$12:H$17))} -> 0 | I27: {=SUMPRODUCT(($B$12:$B$17=$A27)*(I$12:I$17))} -> 0 | J27: {=SUMPRODUCT(($B$12:$B$17=$A27)*(J$12:J$17))} -> 0 | K27: {=SUMPRODUCT(($B$12:$B$17=$A27)*(K$12:K$17))} -> 0 | L27: {=SUMPRODUCT(($B$12:$B$17=$A27)*(L$12:L$17))} -> 0 | M27: {=SUMPRODUCT(($B$12:$B$17=$A27)*(M$12:M$17))} -> 0 | N27: {=SUMPRODUCT(($B$12:$B$17=$A27)*(N$12:N$17))} -> 0 | O27: {=SUMPRODUCT(($B$12:$B$17=$A27)*(O$12:O$17))} -> 0 | ... AS27: {=SUMPRODUCT(($B$12:$B$17=$A27)*(AS$12:AS$17))} -> 0
A28: =底稿目录!A17 -> 矿产权 | C28: {=SUMPRODUCT(($B$12:$B$17=$A28)*(C$12:C$17))} -> 0 | D28: {=SUMPRODUCT(($B$12:$B$17=$A28)*(D$12:D$17))} -> 0 | F28: {=SUMPRODUCT(($B$12:$B$17=$A28)*(F$12:F$17))} -> 0 | H28: {=SUMPRODUCT(($B$12:$B$17=$A28)*(H$12:H$17))} -> 0 | I28: {=SUMPRODUCT(($B$12:$B$17=$A28)*(I$12:I$17))} -> 0 | J28: {=SUMPRODUCT(($B$12:$B$17=$A28)*(J$12:J$17))} -> 0 | K28: {=SUMPRODUCT(($B$12:$B$17=$A28)*(K$12:K$17))} -> 0 | L28: {=SUMPRODUCT(($B$12:$B$17=$A28)*(L$12:L$17))} -> 0 | M28: {=SUMPRODUCT(($B$12:$B$17=$A28)*(M$12:M$17))} -> 0 | N28: {=SUMPRODUCT(($B$12:$B$17=$A28)*(N$12:N$17))} -> 0 | O28: {=SUMPRODUCT(($B$12:$B$17=$A28)*(O$12:O$17))} -> 0 | ... AS28: {=SUMPRODUCT(($B$12:$B$17=$A28)*(AS$12:AS$17))} -> 0
A29: 数据资源 | C29: {=SUMPRODUCT(($B$12:$B$17=$A29)*(C$12:C$17))} -> 0 | D29: {=SUMPRODUCT(($B$12:$B$17=$A29)*(D$12:D$17))} -> 0 | F29: {=SUMPRODUCT(($B$12:$B$17=$A29)*(F$12:F$17))} -> 0 | H29: {=SUMPRODUCT(($B$12:$B$17=$A29)*(H$12:H$17))} -> 0 | I29: {=SUMPRODUCT(($B$12:$B$17=$A29)*(I$12:I$17))} -> 0 | J29: {=SUMPRODUCT(($B$12:$B$17=$A29)*(J$12:J$17))} -> 0 | K29: {=SUMPRODUCT(($B$12:$B$17=$A29)*(K$12:K$17))} -> 0 | L29: {=SUMPRODUCT(($B$12:$B$17=$A29)*(L$12:L$17))} -> 0 | M29: {=SUMPRODUCT(($B$12:$B$17=$A29)*(M$12:M$17))} -> 0 | N29: {=SUMPRODUCT(($B$12:$B$17=$A29)*(N$12:N$17))} -> 0 | O29: {=SUMPRODUCT(($B$12:$B$17=$A29)*(O$12:O$17))} -> 0 | ... AS29: {=SUMPRODUCT(($B$12:$B$17=$A29)*(AS$12:AS$17))} -> 0
A30: =底稿目录!A19 -> 其他 | C30: {=SUMPRODUCT(($B$12:$B$17=$A30)*(C$12:C$17))} -> 0 | D30: {=SUMPRODUCT(($B$12:$B$17=$A30)*(D$12:D$17))} -> 0 | F30: {=SUMPRODUCT(($B$12:$B$17=$A30)*(F$12:F$17))} -> 0 | H30: {=SUMPRODUCT(($B$12:$B$17=$A30)*(H$12:H$17))} -> 0 | I30: {=SUMPRODUCT(($B$12:$B$17=$A30)*(I$12:I$17))} -> 0 | J30: {=SUMPRODUCT(($B$12:$B$17=$A30)*(J$12:J$17))} -> 0 | K30: {=SUMPRODUCT(($B$12:$B$17=$A30)*(K$12:K$17))} -> 0 | L30: {=SUMPRODUCT(($B$12:$B$17=$A30)*(L$12:L$17))} -> 0 | M30: {=SUMPRODUCT(($B$12:$B$17=$A30)*(M$12:M$17))} -> 0 | N30: {=SUMPRODUCT(($B$12:$B$17=$A30)*(N$12:N$17))} -> 0 | O30: {=SUMPRODUCT(($B$12:$B$17=$A30)*(O$12:O$17))} -> 0 | ... AS30: {=SUMPRODUCT(($B$12:$B$17=$A30)*(AS$12:AS$17))} -> 0
A31: 三、审计说明：
A33: 四、审计结论：
A38: 编制说明：
A39: 1、本科目核算企业持有的无形资产成本，包括专利权、非专利技术、商标权、著作权、土地使用权等。
A40: 2、对于使用寿命不确定的无形资产，每年进行减值测试。
A41: 3、对于尚未达到可使用状态的无形资产，由于其价值通常具有较大的不确定性，也应当每年进行减值测试。

Sheet 调整分录汇总I1-3
A1: 致同会计师事务所
A2: 无形资产调整分录汇总表
A3: =底稿目录!A2 -> 被审计单位： | C3: =底稿目录!A4 -> 编制人： | F3: =底稿目录!A5 -> 编制日期： | I3: 索引号： | J3: I1-3
A4: =底稿目录!A3 -> 截止日：202X年12月31日 | C4: =底稿目录!A6 -> 复核人： | F4: =底稿目录!A7 -> 复核日期： | I4: 页次：
A5: 调整事项说明 | B5: 类别（报表调整/账项调整/其他） | C5: 报表项目 | D5: 科目名称 | E5: 附注项目 | F5: …… | G5: 借方调整金额 | H5: 贷方调整金额 | I5: 索引 | J5: 备注
A21: 【注：本底稿适用于调整分录较多、较复杂的项目，且仅列示与本报表项目相关的审计调整。项目组可根据项目实际情况选择是否使用该底稿。】

Sheet 无形资产摊销减值政策检查表I1-4
A1: 致同会计师事务所
A2: 无形资产摊销政策检查表
A3: =底稿目录!A2 -> 被审计单位： | D3: =底稿目录!A4 -> 编制人： | G3: =底稿目录!A5 -> 编制日期： | I3: 索引号： | J3: I1-4
A4: =底稿目录!A3 -> 截止日：202X年12月31日 | D4: =底稿目录!A6 -> 复核人： | G4: =底稿目录!A7 -> 复核日期： | I4: 页次：
A5: 一、审计目标:
A6: 判断无形资产相关重大会计政策和会计估计合理性检查
A7: 二、审计过程：
A8: （一）被审计单位的无形资产摊销政策：
A9: 序号 | B9: 类别 | C9: 使用寿命 | D9: 摊销方法 | E9: 是否符合实际经营情况和会计准则的要求 | F9: 是否与相关资产所包含的经济利益预期实现方式相一致 | G9: 与同行业公司相比，会计政策是否合理 | H9: 是否存在会计政策/会计估计变更 | I9: 会计政策/会计估计变更是否合理 | J9: 备注
A10: 1
A11: 2
A12: 3
A13: 4
A14: 5
A15: 6
A16: （二）同行业其他公司的无形资产摊销政策
A17: 序号 | B17: 类别 | C17: 同行业公司1 | E17: 同行业公司2 | G17: 同行业公司3 | I17: 同行业公司4
C18: 使用寿命 | D18: 摊销方法 | E18: 使用寿命 | F18: 摊销方法 | G18: 使用寿命 | H18: 摊销方法 | I18: 使用寿命 | J18: 摊销方法
A19: 1
A20: 2
A21: 3
A22: 4
A23: 如本期存在会计估计变更，原会计估计如下：
A24: 序号 | B24: 类别 | C24: 使用寿命 | D24: 摊销方法
A25: 1
A26: 2
A27: 3
A28: 4
A29: 三、审计说明：
A32: 四、审计结论：

Sheet 无形资产增加检查表I1-5
A1: 致同会计师事务所
A2: 无形资产增加检查表
A3: =底稿目录!A2 -> 被审计单位： | E3: =底稿目录!A4 -> 编制人： | L3: =底稿目录!A5 -> 编制日期： | R3: 索引号： | S3: I1-5
A4: =底稿目录!A3 -> 截止日：202X年12月31日 | E4: =底稿目录!A6 -> 复核人： | L4: =底稿目录!A7 -> 复核日期： | R4: 页次：
A5: 一、审计目标:
A6: 通过检查合同、凭证及其他相关资料，验证无形资产增加情况的存在/发生、所有权、计价和分摊。
A7: 二、审计过程：
A8: 资产名称 | B8: 入账金额 | C8: 购买 | F8: 股东投入方式 | I8: 具有融资性质 | M8: 企业合并取得 | P8: 其他取得方式 | R8: 备注 | S8: 附件
C9: 合同是否齐全 | D9: 付款是否经审批 | E9: 入账是否正确 | F9: 是否经国家批准 | G9: 手续是否完备 | H9: 协议金额是否公允 | I9: 入账金额 | J9: 实际利率 | K9: 融资费用 | L9: 合同金额 | M9: 是否满足确认条件 | N9: PPA分摊是否经过专估值家复核 | O9: 利用专家工作底稿索引号 | P9: 取得方式 | Q9: 是否符合规定
A23: 合计 | B23: =SUM(B10:B22) -> 0 | I23: =SUM(I10:I22) -> 0 | K23: =SUM(K10:K22) -> 0 | L23: =SUM(L10:L22) -> 0
A24: 本期发生额 | B24: ='明细表I1-2'!AM18 -> 0
A25: 检查比例 | B25: =B23/B24 -> #DIV/0!
A26: 三、审计说明：
A29: 四、审计结论：
A31: 提示：
A32: 1、检查当年增加的无形资产：
A33: 存在/发生：审核当年增加的重要发票及其原始凭证、购货合同，会议记录、交接手续等内容
A34: 计价正确：检查其原始凭证、关注土地使用权相关税费计缴情况
A35: 2、检查无形资产的权属证书原件（土地使用证、采矿权证、协议）、非专利技术的持有和保密状况的性质、构成内容、计价依据、使用状况和受益期限，确定无形资产的所有权。
A36: 3、根据《中国注册会计师审计准则问题解答第18号——识别和应对第三方配合实施财务舞弊》：当期存在大额长期资产采购或对外投资时，需考虑是否存在通过虚增在建工程、固定资产、无形资产等长期资产采购价格套取资金，
A37: 如果还识别出被审计单位存在可能导致关联方资金占用以及其他套取资金行为的舞弊风险因素，则很可能表面存在第三方配合舞弊，应采取恰当的措施应对。

Sheet 无形资产减少明细表I1-6
A1: 致同会计师事务所
A2: 无形资产减少检查表
A3: =底稿目录!A2 -> 被审计单位： | D3: =底稿目录!A4 -> 编制人： | I3: =底稿目录!A5 -> 编制日期： | M3: 索引号： | N3: I1-6
A4: =底稿目录!A3 -> 截止日：202X年12月31日 | D4: =底稿目录!A6 -> 复核人： | I4: =底稿目录!A7 -> 复核日期： | M4: 页次：
A5: 一、审计目标:
A6: 通过检查合同、凭证及其他相关资料，验证无形资产减少情况的存在/发生、所有权、计价和分摊。
A7: 二、审计过程：
A8: 资产名称 | B8: 核销 | F8: 出售 | I8: 其他减少方式 | K8: 备注 | L8: 日期 | M8: 凭证编号 | N8: 附件(相关文件、协议索引号)
B9: 对方科目 | C9: 是否经审批 | D9: 结转的金额正确 | E9: 入账是否正确 | F9: 是否经审批 | G9: 手续是否完备 | H9: 协议金额是否公允 | I9: 减少方式 | J9: 是否符合规定
A18: 合计
A19: 资产名称 | B19: 本期减少的无形资产情况 | F19: 处置日期 | G19: 清理费用 | H19: 清理收入 | I19: 清理净损失或收益 | J19: 是否与相关科目勾稽一致
B20: 账面原值 | C20: 累计摊销 | D20: 减值准备 | E20: 账面价值
E21: =B21-C21-D21 -> 0 | I21: =H21-G21-E21 -> 0
E22: =B22-C22-D22 -> 0 | I22: =H22-G22-E22 -> 0
E23: =B23-C23-D23 -> 0 | I23: =H23-G23-E23 -> 0
E24: =B24-C24-D24 -> 0 | I24: =H24-G24-E24 -> 0
E25: =B25-C25-D25 -> 0 | I25: =H25-G25-E25 -> 0
E26: =B26-C26-D26 -> 0 | I26: =H26-G26-E26 -> 0
E27: =B27-C27-D27 -> 0 | I27: =H27-G27-E27 -> 0
E28: =B28-C28-D28 -> 0 | I28: =H28-G28-E28 -> 0
A29: 合计 | B29: =SUM(B21:B28) -> 0 | C29: =SUM(C21:C28) -> 0 | D29: =SUM(D21:D28) -> 0 | E29: =SUM(E21:E28) -> 0 | G29: =SUM(G21:G28) -> 0 | H29: =SUM(H21:H28) -> 0 | I29: =SUM(I21:I28) -> 0
A30: 三、审计说明：
A35: 四、审计结论：
A39: 编制说明：
A40: 房地产开发企业取得的土地用于建造对外出售的房屋建筑物，相关的土地使用权应转入所建造房屋建筑物的成本；
A41: 在土地上自行开发建造厂房等建筑物的，土地使用权和地上建筑物应分别进行摊销和计提折旧。

Sheet 使用寿命检查表I1-7
A1: 致同会计师事务所
A2: 无形资产使用寿命检查表
A3: =底稿目录!A2 -> 被审计单位： | D3: =底稿目录!A4 -> 编制人： | G3: =底稿目录!A5 -> 编制日期： | L3: 索引号： | M3: I1-7
A4: =底稿目录!A3 -> 截止日：202X年12月31日 | D4: =底稿目录!A6 -> 复核人： | G4: =底稿目录!A7 -> 复核日期： | L4: 页次：
A5: 一、审计目标:
A6: 检查被审计单位确定无形资产使用寿命的依据，分析其合理性
A7: 二、审计过程：
A8: 资产名称 | B8: 合同性权利或其他法定权利 | E8: 权利到期后续约的情况 | H8: 没有法定使用年限 | J8: 是否属于使用寿命不确定 | K8: 被审计单位管理层对于“使用寿命不确定性”的判断依据 | L8: 相关文件索引号 | M8: 备注
B9: 是否适用 | C9: 规定年限 | D9: 已确定的使用寿命 | E9: 是否适用 | F9: 续约期计入使用寿命的年限 | G9: 已确定的使用寿命 | H9: 是否估计使用寿命 | I9: 是否合理
A18: 对于使用寿命不确定的无形资产，询问被审计单位管理层本期是否识别出任何潜在因素导致该项资产拥有有限的使用寿命，以及被审计单位是否按照原定用途继续使用该资产。
A19: 资产名称 | B19: 账面净值 | C19: 询问管理层
C20: 是否识别出任何潜在因素导致该项资产拥有有限的使用寿命 | F20: 是否按照原定用途继续使用该资产 | I20: 备注（记录相关发现）
A25: 三、审计说明：
A27: 四、审计结论：

Sheet 无形资产权属检查表I1-8
A1: 致同会计师事务所
A2: 无形资产权属检查表
A3: =底稿目录!A2 -> 被审计单位： | D3: =底稿目录!A4 -> 编制人： | H3: =底稿目录!A5 -> 编制日期： | L3: 索引号： | M3: I1-8
A4: =底稿目录!A3 -> 截止日：202X年12月31日 | D4: =底稿目录!A6 -> 复核人： | H4: =底稿目录!A7 -> 复核日期： | L4: 页次：
A5: 一、审计目标:
A6: 检查产权证原件，明确归属，是否存在担保、抵押等情况
A7: 一、审计过程：
A8: 资产名称 | B8: 权证记载 | G8: 财务账面记载 | K8: 抵押情况
B9: 权证编号 | C9: 权利人名称 | D9: 登记日期 | E9: 权利起止日 | F9: 权证复印件索引 | G9: 原值 | H9: 累计折旧 | I9: 减值准备 | J9: 净值 | K9: 是否抵押受限 | L9: 抵押价值 | M9: 抵押性质
J10: =G10-H10-I10 -> 0
J11: =G11-H11-I11 -> 0
J12: =G12-H12-I12 -> 0
J13: =G13-H13-I13 -> 0
J14: =G14-H14-I14 -> 0
J15: =G15-H15-I15 -> 0
J16: =G16-H16-I16 -> 0
A17: 合计 | J17: =G17-H17-I17 -> 0
A18: 三、审计说明：
A21: 四、审计结论：
A27: 根据《首发业务若干问题解答》（2020年6月修订版） 问题31、部分首发企业在合并中识别并确认无形资产，以及对外购买客户资源或客户关系等事项，实务中应注意哪些方面？ 答：对于无形资产的确认，应符合《企业会计准则第6号——无形资产》的相关规定。根据《企业会计准则第6号——无形资产》，符合无形资产的可辨认性应源自合同性权利或其他法定权利，并且只有在与该无形资产有关的经济利益很可能流入企业，该无形资产的成本能够可靠地计量，才能确认无形资产；企业在判断无形资产产生的经济利益是否很可能流入时，应当对无形资产在预计使用寿命内可能存在的各种经济因素作出合理估计，并且应当有明确证据支持。 对于客户资源或客户关系，只有在合同或其他法定权利支持，确保企业在较长时期内获得稳定收益且能够核算价值的情况下，才能确认为无形资产。如果企业无法控制客户关系、人力资源等带来的未来经济利益，则不符合无形资产的定义，不应将其确认为无形资产。发行人在开拓市场过程中支付的正常营销费用，或仅从出售方购买了相关客户资料，而客户并未与上述出售方签订独家或长期买卖合同，即在没有明确合同或其他法定权利支持情况下，“客户资源”或“客户关系”通常理解为发行人为获取客户渠道而发生的费用。若确认为无形资产，发行人应详细说明确认的依据，是否符合无形资产的确认条件，保荐机构及申报会计师应针对上述事项谨慎发表明确意见。 对于非同一控制下企业合并中无形资产的识别与确认，根据证监会发布的《2013年上市公司年报会计监管报告》的有关要求，购买方在初始确认企业合并中购入的被购买方资产时，应充分识别被购买方拥有的、但在其财务报表中未确认的无形资产，对于满足会计准则规定确认条件的，应当确认为无形资产。 在上述企业合并确认无形资产的过程中，发行人应保持专业谨慎，充分论证是否存在确凿的证据、合理的理由以及可计量、可确认的条件，评估师应按照公认可靠的评估方法确认其公允价值，不存在其他相反的证据。保荐机构和申报会计师应保持应有的职业谨慎，详细核查发行人确认的无形资产是否符合准则规定的确认条件和计量要求，是否存在虚构无形资产情形，是否存在估值风险和减值风险。

Sheet 摊销分配分析表I1-9
A1: 致同会计师事务所
A2: 无形资产摊销分配分析表
A3: =底稿目录!A2 -> 被审计单位： | D3: =底稿目录!A4 -> 编制人： | G3: =底稿目录!A5 -> 编制日期： | I3: 索引号： | J3: I1-9
A4: =底稿目录!A3 -> 截止日：202X年12月31日 | D4: =底稿目录!A6 -> 复核人： | G4: =底稿目录!A7 -> 复核日期： | I4: 页次：
A5: 一、审计目标:
A6: 检查无形资产本期计提的摊销分配是否合理
A7: 二、审计过程：
A8: 1.检查摊销分配到各种费用的情况，将“累计摊销”账户贷方的本期计提摊销额与相应成本费用中的摊销费用明细账户的借方相比较，以查明所计提摊销金额是否已全部摊入本期产品成本或费用；
A9: 2.确定分配方法是否合理，本期分配方法与上期是否一致；
A10: 摊销费用分配分析表
A11: 序号 | B11: 无形资产类别 | C11: 生产成本 | D11: 制造费用 | E11: 销售费用 | F11: 管理费用 | G11: 研发费用 | H11: … | I11: 合计 | J11: 备注
A12: 1 | B12: 土地使用权 | I12: =SUM(C12:H12) -> 0
A13: 2 | B13: 住房使用权 | I13: =SUM(C13:H13) -> 0
A14: 3 | B14: 专利权 | I14: =SUM(C14:H14) -> 0
A15: 4 | B15: 非专利技术 | I15: =SUM(C15:H15) -> 0
A16: 5 | B16: 商标权 | I16: =SUM(C16:H16) -> 0
A17: 6 | B17: 著作权 | I17: =SUM(C17:H17) -> 0
A18: 7 | B18: 特许经营权 | I18: =SUM(C18:H18) -> 0
A19: 8 | B19: 软件 | I19: =SUM(C19:H19) -> 0
A20: 9 | B20: 矿产权 | I20: =SUM(C20:H20) -> 0
A21: 10 | B21: 数据资源 | I21: =SUM(C21:H21) -> 0
A22: 11 | B22: 其他 | I22: =SUM(C22:H22) -> 0
A23: 合计 | C23: =SUM(C12:C22) -> 0 | D23: =SUM(D12:D22) -> 0 | E23: =SUM(E12:E22) -> 0 | F23: =SUM(F12:F22) -> 0 | G23: =SUM(G12:G22) -> 0 | H23: =SUM(H12:H22) -> 0 | I23: =SUM(I12:I22) -> 0
A24: 三、审计说明：
A26: 四、审计结论：
A29: 注释：企业合并取得的PPA分摊形成的无形资产也需要摊销；自行研发无形资产的摊销，应计入研发费用。

Sheet 摊销测算表（不含减值）I1-10（剩余年限法）
A1: 致同会计师事务所
A2: 无形资产摊销测算表
A3: =底稿目录!A2 -> 被审计单位： | D3: =底稿目录!A4 -> 编制人： | K3: =底稿目录!A5 -> 编制日期： | O3: 索引号： | P3: I1-10
A4: =底稿目录!A3 -> 截止日：202X年12月31日 | D4: =底稿目录!A6 -> 复核人： | K4: =底稿目录!A7 -> 复核日期： | O4: 页次：
A5: 一、审计目标:
A6: 检查无形资产本期应计提的摊销是否合理。
A7: 二、审计过程：
A8: 期初： | B8: 45658 | C8: 折旧期末： | D8: 46022
A9: 无形资产类别 | B9: 明细项目 | C9: 期初无形资产 | G9: 开始使用日期 | H9: 使用期限（年） | I9: 使用期限（月） | J9: 剩余摊销月份 | K9: 测算每月摊销额 | L9: 本期月数 | M9: 测算本期摊销额 | N9: 账面本期摊销额 | O9: 本期摊销额差异（应补摊） | P9: 累计摊销额差异
C10: 原值 | D10: 累计摊销 | E10: 减值准备 | F10: 价值
B11: ='明细表I1-2'!A12 -> A | C11: ='明细表I1-2'!L12 -> 0 | D11: ='明细表I1-2'!Y12 -> 0 | E11: ='明细表I1-2'!AL12 -> 0 | F11: =C11-D11-E11 -> 0 | I11: =IF(H11=0,0,IF(RIGHT(H11,1)<>"年",H11*12,IF(LEN(H11)=3,VALUE(LEFT(H11,2))*12,IF(LEN(H11)=2,VALUE(LEFT(H11,1))*12,"??")))) -> 0 | J11: =IF(I11=0,,I11-((YEAR($B$8)-YEAR(G11))*12+MONTH($B$8)-MONTH(G11))) -> 0 | K11: =IF(F11=0,0,F11/J11) -> 0 | L11: =IF(G11="",0,DATEDIF(G11,$D$8,"M")+1) -> 0 | M11: =K11*L11 -> 0 | N11: ='明细表I1-2'!Q12+'明细表I1-2'!R12 -> 0 | O11: =M11-N11 -> 0
B12: ='明细表I1-2'!A13 -> B | C12: ='明细表I1-2'!L13 -> 0 | D12: ='明细表I1-2'!Y13 -> 0 | E12: ='明细表I1-2'!AL13 -> 0 | F12: =C12-D12-E12 -> 0 | I12: =IF(H12=0,0,IF(RIGHT(H12,1)<>"年",H12*12,IF(LEN(H12)=3,VALUE(LEFT(H12,2))*12,IF(LEN(H12)=2,VALUE(LEFT(H12,1))*12,"??")))) -> 0 | J12: =IF(I12=0,,I12-((YEAR($B$8)-YEAR(G12))*12+MONTH($B$8)-MONTH(G12))) -> 0 | K12: =IF(F12=0,0,F12/J12) -> 0 | L12: =IF(G12="",0,DATEDIF(G12,$D$8,"M")+1) -> 0 | M12: =K12*L12 -> 0 | N12: ='明细表I1-2'!Q13+'明细表I1-2'!R13 -> 0 | O12: =M12-N12 -> 0
B13: ='明细表I1-2'!A14 -> C | C13: ='明细表I1-2'!L14 -> 0 | D13: ='明细表I1-2'!Y14 -> 0 | E13: ='明细表I1-2'!AL14 -> 0 | F13: =C13-D13-E13 -> 0 | I13: =IF(H13=0,0,IF(RIGHT(H13,1)<>"年",H13*12,IF(LEN(H13)=3,VALUE(LEFT(H13,2))*12,IF(LEN(H13)=2,VALUE(LEFT(H13,1))*12,"??")))) -> 0 | J13: =IF(I13=0,,I13-((YEAR($B$8)-YEAR(G13))*12+MONTH($B$8)-MONTH(G13))) -> 0 | K13: =IF(F13=0,0,F13/J13) -> 0 | L13: =IF(G13="",0,DATEDIF(G13,$D$8,"M")+1) -> 0 | M13: =K13*L13 -> 0 | N13: ='明细表I1-2'!Q14+'明细表I1-2'!R14 -> 0 | O13: =M13-N13 -> 0
B14: ='明细表I1-2'!A15 -> D | C14: ='明细表I1-2'!L15 -> 0 | D14: ='明细表I1-2'!Y15 -> 0 | E14: ='明细表I1-2'!AL15 -> 0 | F14: =C14-D14-E14 -> 0 | I14: =IF(H14=0,0,IF(RIGHT(H14,1)<>"年",H14*12,IF(LEN(H14)=3,VALUE(LEFT(H14,2))*12,IF(LEN(H14)=2,VALUE(LEFT(H14,1))*12,"??")))) -> 0 | J14: =IF(I14=0,,I14-((YEAR($B$8)-YEAR(G14))*12+MONTH($B$8)-MONTH(G14))) -> 0 | K14: =IF(F14=0,0,F14/J14) -> 0 | L14: =IF(G14="",0,DATEDIF(G14,$D$8,"M")+1) -> 0 | M14: =K14*L14 -> 0 | N14: ='明细表I1-2'!Q15+'明细表I1-2'!R15 -> 0 | O14: =M14-N14 -> 0
B15: ='明细表I1-2'!A16 -> … | C15: ='明细表I1-2'!L16 -> 0 | D15: ='明细表I1-2'!Y16 -> 0 | E15: ='明细表I1-2'!AL16 -> 0 | F15: =C15-D15-E15 -> 0 | I15: =IF(H15=0,0,IF(RIGHT(H15,1)<>"年",H15*12,IF(LEN(H15)=3,VALUE(LEFT(H15,2))*12,IF(LEN(H15)=2,VALUE(LEFT(H15,1))*12,"??")))) -> 0 | J15: =IF(I15=0,,I15-((YEAR($B$8)-YEAR(G15))*12+MONTH($B$8)-MONTH(G15))) -> 0 | K15: =IF(F15=0,0,F15/J15) -> 0 | L15: =IF(G15="",0,DATEDIF(G15,$D$8,"M")+1) -> 0 | M15: =K15*L15 -> 0 | N15: ='明细表I1-2'!Q16+'明细表I1-2'!R16 -> 0 | O15: =M15-N15 -> 0
B16: ='明细表I1-2'!A17 -> 0 | C16: ='明细表I1-2'!L17 -> 0 | D16: ='明细表I1-2'!Y17 -> 0 | E16: ='明细表I1-2'!AL17 -> 0 | F16: =C16-D16-E16 -> 0 | I16: =IF(H16=0,0,IF(RIGHT(H16,1)<>"年",H16*12,IF(LEN(H16)=3,VALUE(LEFT(H16,2))*12,IF(LEN(H16)=2,VALUE(LEFT(H16,1))*12,"??")))) -> 0 | J16: =IF(I16=0,,I16-((YEAR($B$8)-YEAR(G16))*12+MONTH($B$8)-MONTH(G16))) -> 0 | K16: =IF(F16=0,0,F16/J16) -> 0 | L16: =IF(G16="",0,DATEDIF(G16,$D$8,"M")+1) -> 0 | M16: =K16*L16 -> 0 | N16: ='明细表I1-2'!Q17+'明细表I1-2'!R17 -> 0 | O16: =M16-N16 -> 0
A17: 合计 | C17: =SUM(C11:C16) -> 0 | D17: =SUM(D11:D16) -> 0 | E17: =SUM(E11:E16) -> 0 | F17: =SUM(F11:F16) -> 0 | K17: =SUM(K11:K16) -> 0 | M17: =SUM(M11:M16) -> 0 | N17: =SUM(N11:N16) -> 0 | O17: =SUM(O11:O16) -> 0 | P17: =SUM(P11:P16) -> 0
A18: 其中：
A19: =底稿目录!A9 -> 土地使用权 | C19: {=SUMPRODUCT(($A$11:$A$16=$A19)*(C$11:C$16))} -> 0 | D19: {=SUMPRODUCT(($A$11:$A$16=$A19)*(D$11:D$16))} -> 0 | E19: {=SUMPRODUCT(($A$11:$A$16=$A19)*(E$11:E$16))} -> 0 | F19: {=SUMPRODUCT(($A$11:$A$16=$A19)*(F$11:F$16))} -> 0 | K19: {=SUMPRODUCT(($A$11:$A$16=$A19)*(K$11:K$16))} -> 0 | M19: {=SUMPRODUCT(($A$11:$A$16=$A19)*(M$11:M$16))} -> 0 | N19: {=SUMPRODUCT(($A$11:$A$16=$A19)*(N$11:N$16))} -> 0 | O19: {=SUMPRODUCT(($A$11:$A$16=$A19)*(O$11:O$16))} -> 0 | P19: {=SUMPRODUCT(($A$11:$A$16=$A19)*(P$11:P$16))} -> 0
A20: =底稿目录!A10 -> 住房使用权 | C20: {=SUMPRODUCT(($A$11:$A$16=$A20)*(C$11:C$16))} -> 0 | D20: {=SUMPRODUCT(($A$11:$A$16=$A20)*(D$11:D$16))} -> 0 | E20: {=SUMPRODUCT(($A$11:$A$16=$A20)*(E$11:E$16))} -> 0 | F20: {=SUMPRODUCT(($A$11:$A$16=$A20)*(F$11:F$16))} -> 0 | K20: {=SUMPRODUCT(($A$11:$A$16=$A20)*(K$11:K$16))} -> 0 | M20: {=SUMPRODUCT(($A$11:$A$16=$A20)*(M$11:M$16))} -> 0 | N20: {=SUMPRODUCT(($A$11:$A$16=$A20)*(N$11:N$16))} -> 0 | O20: {=SUMPRODUCT(($A$11:$A$16=$A20)*(O$11:O$16))} -> 0 | P20: {=SUMPRODUCT(($A$11:$A$16=$A20)*(P$11:P$16))} -> 0
A21: =底稿目录!A11 -> 专利权 | C21: {=SUMPRODUCT(($A$11:$A$16=$A21)*(C$11:C$16))} -> 0 | D21: {=SUMPRODUCT(($A$11:$A$16=$A21)*(D$11:D$16))} -> 0 | E21: {=SUMPRODUCT(($A$11:$A$16=$A21)*(E$11:E$16))} -> 0 | F21: {=SUMPRODUCT(($A$11:$A$16=$A21)*(F$11:F$16))} -> 0 | K21: {=SUMPRODUCT(($A$11:$A$16=$A21)*(K$11:K$16))} -> 0 | M21: {=SUMPRODUCT(($A$11:$A$16=$A21)*(M$11:M$16))} -> 0 | N21: {=SUMPRODUCT(($A$11:$A$16=$A21)*(N$11:N$16))} -> 0 | O21: {=SUMPRODUCT(($A$11:$A$16=$A21)*(O$11:O$16))} -> 0 | P21: {=SUMPRODUCT(($A$11:$A$16=$A21)*(P$11:P$16))} -> 0
A22: =底稿目录!A12 -> 非专利技术 | C22: {=SUMPRODUCT(($A$11:$A$16=$A22)*(C$11:C$16))} -> 0 | D22: {=SUMPRODUCT(($A$11:$A$16=$A22)*(D$11:D$16))} -> 0 | E22: {=SUMPRODUCT(($A$11:$A$16=$A22)*(E$11:E$16))} -> 0 | F22: {=SUMPRODUCT(($A$11:$A$16=$A22)*(F$11:F$16))} -> 0 | K22: {=SUMPRODUCT(($A$11:$A$16=$A22)*(K$11:K$16))} -> 0 | M22: {=SUMPRODUCT(($A$11:$A$16=$A22)*(M$11:M$16))} -> 0 | N22: {=SUMPRODUCT(($A$11:$A$16=$A22)*(N$11:N$16))} -> 0 | O22: {=SUMPRODUCT(($A$11:$A$16=$A22)*(O$11:O$16))} -> 0 | P22: {=SUMPRODUCT(($A$11:$A$16=$A22)*(P$11:P$16))} -> 0
A23: =底稿目录!A13 -> 商标权 | C23: {=SUMPRODUCT(($A$11:$A$16=$A23)*(C$11:C$16))} -> 0 | D23: {=SUMPRODUCT(($A$11:$A$16=$A23)*(D$11:D$16))} -> 0 | E23: {=SUMPRODUCT(($A$11:$A$16=$A23)*(E$11:E$16))} -> 0 | F23: {=SUMPRODUCT(($A$11:$A$16=$A23)*(F$11:F$16))} -> 0 | K23: {=SUMPRODUCT(($A$11:$A$16=$A23)*(K$11:K$16))} -> 0 | M23: {=SUMPRODUCT(($A$11:$A$16=$A23)*(M$11:M$16))} -> 0 | N23: {=SUMPRODUCT(($A$11:$A$16=$A23)*(N$11:N$16))} -> 0 | O23: {=SUMPRODUCT(($A$11:$A$16=$A23)*(O$11:O$16))} -> 0 | P23: {=SUMPRODUCT(($A$11:$A$16=$A23)*(P$11:P$16))} -> 0
A24: =底稿目录!A14 -> 著作权 | C24: {=SUMPRODUCT(($A$11:$A$16=$A24)*(C$11:C$16))} -> 0 | D24: {=SUMPRODUCT(($A$11:$A$16=$A24)*(D$11:D$16))} -> 0 | E24: {=SUMPRODUCT(($A$11:$A$16=$A24)*(E$11:E$16))} -> 0 | F24: {=SUMPRODUCT(($A$11:$A$16=$A24)*(F$11:F$16))} -> 0 | K24: {=SUMPRODUCT(($A$11:$A$16=$A24)*(K$11:K$16))} -> 0 | M24: {=SUMPRODUCT(($A$11:$A$16=$A24)*(M$11:M$16))} -> 0 | N24: {=SUMPRODUCT(($A$11:$A$16=$A24)*(N$11:N$16))} -> 0 | O24: {=SUMPRODUCT(($A$11:$A$16=$A24)*(O$11:O$16))} -> 0 | P24: {=SUMPRODUCT(($A$11:$A$16=$A24)*(P$11:P$16))} -> 0
A25: =底稿目录!A15 -> 特许经营权 | C25: {=SUMPRODUCT(($A$11:$A$16=$A25)*(C$11:C$16))} -> 0 | D25: {=SUMPRODUCT(($A$11:$A$16=$A25)*(D$11:D$16))} -> 0 | E25: {=SUMPRODUCT(($A$11:$A$16=$A25)*(E$11:E$16))} -> 0 | F25: {=SUMPRODUCT(($A$11:$A$16=$A25)*(F$11:F$16))} -> 0 | K25: {=SUMPRODUCT(($A$11:$A$16=$A25)*(K$11:K$16))} -> 0 | M25: {=SUMPRODUCT(($A$11:$A$16=$A25)*(M$11:M$16))} -> 0 | N25: {=SUMPRODUCT(($A$11:$A$16=$A25)*(N$11:N$16))} -> 0 | O25: {=SUMPRODUCT(($A$11:$A$16=$A25)*(O$11:O$16))} -> 0 | P25: {=SUMPRODUCT(($A$11:$A$16=$A25)*(P$11:P$16))} -> 0
A26: =底稿目录!A16 -> 软件 | C26: {=SUMPRODUCT(($A$11:$A$16=$A26)*(C$11:C$16))} -> 0 | D26: {=SUMPRODUCT(($A$11:$A$16=$A26)*(D$11:D$16))} -> 0 | E26: {=SUMPRODUCT(($A$11:$A$16=$A26)*(E$11:E$16))} -> 0 | F26: {=SUMPRODUCT(($A$11:$A$16=$A26)*(F$11:F$16))} -> 0 | K26: {=SUMPRODUCT(($A$11:$A$16=$A26)*(K$11:K$16))} -> 0 | M26: {=SUMPRODUCT(($A$11:$A$16=$A26)*(M$11:M$16))} -> 0 | N26: {=SUMPRODUCT(($A$11:$A$16=$A26)*(N$11:N$16))} -> 0 | O26: {=SUMPRODUCT(($A$11:$A$16=$A26)*(O$11:O$16))} -> 0 | P26: {=SUMPRODUCT(($A$11:$A$16=$A26)*(P$11:P$16))} -> 0
A27: =底稿目录!A17 -> 矿产权 | C27: {=SUMPRODUCT(($A$11:$A$16=$A27)*(C$11:C$16))} -> 0 | D27: {=SUMPRODUCT(($A$11:$A$16=$A27)*(D$11:D$16))} -> 0 | E27: {=SUMPRODUCT(($A$11:$A$16=$A27)*(E$11:E$16))} -> 0 | F27: {=SUMPRODUCT(($A$11:$A$16=$A27)*(F$11:F$16))} -> 0 | K27: {=SUMPRODUCT(($A$11:$A$16=$A27)*(K$11:K$16))} -> 0 | M27: {=SUMPRODUCT(($A$11:$A$16=$A27)*(M$11:M$16))} -> 0 | N27: {=SUMPRODUCT(($A$11:$A$16=$A27)*(N$11:N$16))} -> 0 | O27: {=SUMPRODUCT(($A$11:$A$16=$A27)*(O$11:O$16))} -> 0 | P27: {=SUMPRODUCT(($A$11:$A$16=$A27)*(P$11:P$16))} -> 0
A28: 数据资源 | C28: {=SUMPRODUCT(($A$11:$A$16=$A28)*(C$11:C$16))} -> 0 | D28: {=SUMPRODUCT(($A$11:$A$16=$A28)*(D$11:D$16))} -> 0 | E28: {=SUMPRODUCT(($A$11:$A$16=$A28)*(E$11:E$16))} -> 0 | F28: {=SUMPRODUCT(($A$11:$A$16=$A28)*(F$11:F$16))} -> 0 | K28: {=SUMPRODUCT(($A$11:$A$16=$A28)*(K$11:K$16))} -> 0 | M28: {=SUMPRODUCT(($A$11:$A$16=$A28)*(M$11:M$16))} -> 0 | N28: {=SUMPRODUCT(($A$11:$A$16=$A28)*(N$11:N$16))} -> 0 | O28: {=SUMPRODUCT(($A$11:$A$16=$A28)*(O$11:O$16))} -> 0 | P28: {=SUMPRODUCT(($A$11:$A$16=$A28)*(P$11:P$16))} -> 0
A29: =底稿目录!A19 -> 其他 | C29: {=SUMPRODUCT(($A$11:$A$16=$A29)*(C$11:C$16))} -> 0 | D29: {=SUMPRODUCT(($A$11:$A$16=$A29)*(D$11:D$16))} -> 0 | E29: {=SUMPRODUCT(($A$11:$A$16=$A29)*(E$11:E$16))} -> 0 | F29: {=SUMPRODUCT(($A$11:$A$16=$A29)*(F$11:F$16))} -> 0 | K29: {=SUMPRODUCT(($A$11:$A$16=$A29)*(K$11:K$16))} -> 0 | M29: {=SUMPRODUCT(($A$11:$A$16=$A29)*(M$11:M$16))} -> 0 | N29: {=SUMPRODUCT(($A$11:$A$16=$A29)*(N$11:N$16))} -> 0 | O29: {=SUMPRODUCT(($A$11:$A$16=$A29)*(O$11:O$16))} -> 0 | P29: {=SUMPRODUCT(($A$11:$A$16=$A29)*(P$11:P$16))} -> 0
A30: 三、审计说明：
A33: 四、审计结论：

Sheet 摊销测算表（含减值）I1-11
A1: 致同会计师事务所
A2: 累计摊销测算表
A3: =底稿目录!A2 -> 被审计单位： | H3: =底稿目录!A4 -> 编制人： | Q3: =底稿目录!A5 -> 编制日期： | W3: 索引号： | X3: I1-11
A4: =底稿目录!A3 -> 截止日：202X年12月31日 | H4: =底稿目录!A6 -> 复核人： | Q4: =底稿目录!A7 -> 复核日期： | W4: 页次：
A5: 一、审计目标:
A6: 检查无形资产本期应计提的摊销是否合理。
A7: 二、审计过程：
A8: 期初： | B8: 43831 | C8: 折旧期末： | D8: 44196 | E8: 计提减值准备日期 | F8: 43529
A9: 无形资产类别 | B9: 明细项目 | C9: 原值 | D9: 累计摊销 | E9: 减值准备 | F9: 开始使用日期 | G9: 使用期限（年） | H9: 账面月摊销额 | I9: 摊销期限（月） | J9: 测算到期日 | K9: 已摊销月份 | L9: 剩余摊销月份 | M9: 截止计提减值准备日摊销月份 | N9: 本期折旧月份 | O9: 本期摊销月份（减值前） | P9: 本期摊销月份（减值后） | Q9: 计提减值准备前月摊销 | R9: 计提减值准备前累计摊销 | S9: 计提减值准备后月摊销 | T9: 当期摊销费用 | U9: 月摊销额差异 | V9: 累计摊销 | W9: 累计摊销额差异 | X9: 累计摊销额差异
