Workbook

Sheet 底稿目录
A1: 底稿开列时，可先在以下单元格填写有关内容，以便其他底稿引用有关数据： | B1: 目录
A2: 被审计单位：
A3: 截止日：202X年12月31日 | B3: 序号 | C3: 内容 | D3: 索引号 | E3: 备注
A4: 编制人： | B4: 1 | C4: 开发支出实质性程序 | D4: I2A
A5: 编制日期： | B5: 2 | C5: 开发支出审定表 | D5: I2-1
A6: 复核人： | B6: 3 | C6: 开发支出附注披露表（上市公司） | F6: 无需打印
A7: 复核日期： | B7: 4 | C7: 开发支出附注披露表（国有企业） | F7: 无需打印
B8: 5 | C8: 开发支出明细表 | D8: I2-2
B9: 6 | C9: 调整分录汇总 | D9: I2-3 | E9: 备选
A10: 关于工作底稿与审计程序索引号对应的说明 | B10: 7 | C10: 会计政策检查 | D10: I2-4
A11: 1.编制的审计工作底稿应与审计程序对应。审计项目组应根据被审计单位实际情况和风险评估情况在实质性程序表中裁剪、修改或增加审计程序，根据实际执行的审计程序完成相应审计工作底稿，编制的工作底稿中应按自然顺序依次编制索引号，并通过唯一的索引号将与实质性程序表中的程序对应关联（即将工作底稿的索引号填入实质性程序表中的底稿索引号列）。 | B11: 8 | C11: 实质性分析 | D11: I2-5
B12: 9 | C12: 研发项目资本化时点判断 | D12: I2-6
B13: 10 | C13: 研发项目构成明细表 | D13: I2-7
B14: 11 | C14: 研发材料投入检查表 | D14: I2-8
A15: 2.获取的支持性证据应与审计底稿或程序对应。审计项目组在完成底稿时获取的支持性证据应根据底稿索引号编制下一级按自然顺序排序的索引号（如D1-2-1、D1-2-2、……），并在底稿中说明引用的支持性证据、关联索引号。 | B15: 12 | C15: 研发人员认定检查表 | D15: I2-9
B16: 13 | C16: 研发人员工时检查表 | D16: I2-10
B17: 14 | C17: 委外研发检查表 | D17: I2-11
A18: 3.工作底稿索引号的编码规则：实质性程序索引号按循环从“D”到“N”,循环内账户以顺序号排列，模板中底稿索引号按账户顺序+自然数顺序（即模板中索引号按二级自然顺序排列，如D1-1、D1-2、D1-3、……D1-N）。 | B18: 15 | C18: 针对性检查表 | D18: I2-12
B19: 16 | C19: 截止性测试（账到单据） | D19: I2-13
B20: 17 | C20: 截止性测试（单据到账） | D20: I2-14
B21: 18 | C21: 减值准备测试表 | D21: I2-15
B22: 19 | C22: 可收回金额测试 | D22: I2-16

Sheet 开发支出实质性程序I2A
A1: 致同会计师事务所
A2: 开发支出实质性程序
A3: =底稿目录!A2 -> 被审计单位： | C3: =底稿目录!A4 -> 编制人： | E3: =底稿目录!A5 -> 编制日期： | H3: 索引号： | I3: =底稿目录!D4 -> I2A
A4: =底稿目录!A3 -> 截止日：202X年12月31日 | C4: =底稿目录!A6 -> 复核人： | E4: =底稿目录!A7 -> 复核日期： | H4: 页 次：
A5: 一、本账户涉及的科目
A6: 开发支出
A7: 二、审计目标与认定的对应关系
A8: 审计目标 | G8: 财务报表的认定
A9: A. 资产负债表中记录的开发支出是存在的，且已经记录在恰当的账户中 | G9: 存在
A10: B. 所有应记录的开发支出均已记录，所有应当包括在财务报表中的相关披露均已包括 | G10: 完整性
A11: C. 记录的开发支出由被审计单位拥有或控制 | G11: 权利和义务
A12: D. 开发支出以恰当的金额包括在财务报表中，与之相关的计价或分摊调整已恰当记录，相关披露已得到恰当计量和描述 | G12: 准确性、计价和分摊
A13: E. 开发支出已被恰当地汇总或分解且表述清楚，相关披露在按照企业会计准则的编制基础下是相关的、可理解的 | G13: 列报
A14: 三、计划实施的实质性程序
A15: 序号 | B15: 审计程序 | C15: 程序分类 | D15: 财务报表的认定 | I15: 底稿索引号
D16: 存在 | E16: 完整性 | F16: 权利和 义务 | G16: 准确性、计价和分摊 | H16: 列报 | J16: 根据被审计单位实际情况和风险评估情况裁剪、修改或增加审计程序
A17: 1 | B17: 获取或编制开发支出明细表，复核加计是否正确，并与总账数和明细账合计数核对是否相符，编制审定表，结合开发支出报表数核对是否相符。 | C17: 常规★ | D17: √ | E17: √ | G17: √ | I17: I2-1 /I2-2
A18: 2 | B18: 在使用手工编制、自定义信息报告、系统生成的非固定格式报告等由被审计单位生成的信息时，测试有关信息准确性和完整性，并考虑针对编制和维护由被审计单位生成的信息的相关控制实施控制测试，以评价该信息是否能够为实现审计目的提供基础。 | C18: 常规★ | E18: √ | G18: √ | I18: T1 / | J18: 可参见《审计手册》4.2.6，由被审计单位生成的信息可能是由系统生成的、或手工编制的、或二者兼而有之的方式生成的。例如，由被审计单位生成的信息可能包括： • 不涉及自定义的、由系统生成的报告（如，固定格式报告）； • 可能通过人工自定义的、由系统生成的报告，例如，（计算机）查询信息或特别定制的报告； • 手工编制的信息，例如，汇总信息的电子表格或用以支持分配、计算以及调节的电子表格； • 其他系统生成或手工编制的信息，例如，由被审计单位编制的客户发票； • 通过影印、拍摄、扫描或其他方式转换成电子形式的文件记录。
A19: 3 | B19: 对期初余额的审计，取得开发支出期初余额明细表复核加计是否正确，与总账、明细账合计数是否相符，检查上期开发支出在本期结转情况，执行期初截止性测试以及其他必要追加的审计程序。（适用于首次承接） | C19: 备选 | D19: √ | E19: √ | F19: √ | G19: √ | J19: 由被审计单位生成的信息不包括： • 总分类账或明细分类账、试算平衡表、或经审计的财务报表； • 第三方（除了服务机构）的报表或报告，例如，原始银行对账单，或函证的回函； • 外部数据（例如，第三方发布的数据，如，定价来源）。
A20: 4 | B20: 关注会计政策、会计估计合理性、一贯性，关注其是否利用会计政策和会计估计及其变更操纵利润。 （1）检查研发支出资本化的会计政策是否符合会计准则要求，是否符合研发业务特点，是否符合行业惯例；检查研究阶段和开发阶段界定时点是否合理，开发完成的时点的界定是否合理； （2）将被审计单位本期的会计政策、会计估计与前期进行对比，分析其是否前后一致。对于存在会计政策、会计估计变更的情形，判断是否合理，会计处理是否正确； （3）与同行业其他公司的会计政策、会计估计进行对比，关注其是否利用会计政策和会计估计变更操纵利润。 | C20: 常规★ | D20: √ | E20: √ | G20: √ | I20: I2-4
A21: 5 | B21: 实施分析性程序： （1）将本期明细表与上期审定数据、本期各明细项目占主营业务收入的比重与上年同期的占比进行比较，分析两期波动的原因及合理性； （2）计算各类费用增长率，与主营业务收入增长率进行比较，并与同行业公司进行比较，分析总体合理性； （3）分析明细中是否存在不符合往年常态的项目，不符合企业经营状况，存在异常变动的项目，检查相关支持性文件； （4）计算人均经费、平均薪酬等，与上年同期数据进行比较，并与同行业公司进行比较； （5）将费用实际金额与预算金额进行比较，对具体费用项目与相关财务数据及非财务数据的匹配性进行测试。 | C21: 常规★ | D21: √ | E21: √ | G21: √ | I21: I2-5
A22: 6 | B22: 对于研发项目资本化时点的判断，根据具体情况，需要检查的支持性文件包括但不限于： （1）获取有关协议和董事会纪要、可行性研究报告等文件，检查企业研发活动的立项情况，确定研发项目处于研究阶段还是开发阶段； （2）关注资本化的条件和依据，检查研究阶段和开发阶段界定时点是否合理，开发完成的时点的界定是否合理；检查开发阶段的支出资本化，是否满足准则规定的“五个条件”，并获取通过研发活动明显增强盈利能力、明显改善资产质量的证据（如研发形成专利，开发出新的产品，产品档次明显提升等）；对于确实无法区分研究阶段的支出和开发阶段的支出，检查是否将其所发生的研发支出全部费用化。 | C22: 常规★ | D22: √ | E22: √ | F22: √ | G22: √ | I22: I2-6
A23: 7 | B23: 取得或编制研发项目支出构成明细表，判断研发支出构成是否合理。 | C23: 常规★ | D23: √ | G23: √ | I23: I2-7
A24: 8 | B24: 对于研发材料投入，根据具体情况，需要检查的支持性文件包括但不限于： （1）获取研发领料单，检查其审批流程是否完整、领用部门是否为研发部门； （2）抽取样本检查领料单与研发项目的对应关系，验证其合理性； （3）检查研发材料实际使用情况，是否存在挪用于生产或其他用途； （4）研发形成产品或副产品的，检查其成本是否已从研发费用中转出。 | C24: 常规★ | D24: √ | E24: √ | F24: √ | G24: √ | I24: I2-8
A25: 9 | B25: 对于研发人员认定，根据具体情况，需要检查的支持性文件包括但不限于： （1）获取研发人员花名册、劳动合同、工作职责、工时记录，核实研发人员身份真实性； （2）核实研发人员专业背景和工作经历是否与发行人研发活动相匹配等情形，重点关注相关人员是否具备从事研发活动的能力，是否真正从事研发活动并作出实际贡献，是否属于发行人研发工作所需的必要人员，发行人研发人员数量和占比是否符合行业特点； （3）核实研发人员学历、专业、从业和任职年限、全时与非全时分布等是否符合行业特点；研发人员普遍任职年限较短的，应关注原因及对发行人研发能力的影响；研发人员主要由非全时人员或未签订劳动合同人员构成的，应关注其合理性。 | C25: 常规★ | D25: √ | E25: √ | F25: √ | G25: √ | I25: I2-9
A26: 10 | B26: 对于研发工时，根据具体情况，需要检查的支持性文件包括但不限于： （1）获取研发人员工资计提表，检查研发人员认定、工时统计、薪酬分摊是否准确合理； （2）检查研发人员考勤记录等，验证其是否真实参与研发活动； （3）结合应付职工薪酬审计，将薪酬计提与支付记录、社保缴纳记录等进行核对； （4）检查是否存在非研发人员（如高管）薪酬计入研发费用，若存在，检查其工时记录及分摊的合理性。 | C26: 常规★ | D26: √ | E26: √ | F26: √ | G26: √ | I26: I2-10
A27: 11 | B27: 对于委托研发，根据具体情况，需要检查的支持性文件包括但不限于： （1）检查委托开发合同，关注研发成果所有权归属，判断支出应计入研发费用还是营业成本； （2）检查付款审批记录、发票、验收证明等支持性文件； （3）对受托方执行函证程序，确认交易真实性、金额准确性。 | C27: 常规★ | D27: √ | E27: √ | F27: √ | G27: √ | I27: I2-11
A28: 12 | B28: 对于存在委外研发、在研发过程中产出的产品或副产品、按照客户需求进行定制化研发、履行定制化研发合同过程中发生的研发支出、承担由国家或指定方拨付款项的研发项目等情形，重点核查相关会计处理是否符合《企业会计准则》相关规定。 | C28: 备选 | D28: √ | F28: √
A29: 13 | B29: 检查本期新增其他开发支出的记账凭证和相关支持性文件，关注资本化支出范围是否合理，对应当资本化的支出划分是否正确。 | C29: 常规★ | D29: √ | F29: √ | G29: √ | I29: I2-12
A30: 14 | B30: 检查本期减少开发支出的记账凭证和相关支持性文件，结合研发费用科目的审计，检查费用化的结转处理是否正确；检查结转无形资产依据是否充分，结合无形资产科目审计检查已经在用或已经达到预定用途的研究开发项目是否已结转至相关资产项目。 | C30: 常规★ | D30: √ | E30: √ | F30: √ | G30: √ | I30: I2-12
A31: 15 | B31: 开发支出的截止测试： （1）获取资产负债表日前后若干天、一定金额以上的会计记录，与相关支出凭单等信息核对，确定开发支出是否记入了恰当的期间。 （2）获取资产负债表日前后若干天、一定金额以上的相关支出凭单等，与会计记录信息核对，确定是否存在开发支出跨期。 | C31: 常规★ | G31: √ | I31: I2-13 /I2-14
A32: 16 | B32: 针对存在减值迹象的开发支出，考虑执行下列程序： （1）获取开发支出的减值明细表； （2）记录对开发支出可能造成减值的事件或环境变化； （3）复核用于减值测试的资产分组的合理性； （4）关注并复核公司确定的减值测试方法与模型是否恰当；关注并复核公司进行减值测试所依据的基础数据是否准确、所选取的关键参数是否恰当，评价所采用的关键假设、所作出的重大估计和判断、所选取的价值类型是否合理，分析减值测试方法与价值类型是否匹配； （5）取得相关的资产现金流分析。确定相关资产的预测的未来现金流量是合理的；如果现金流量预测表明，资产的账面价值无法收回，获得企业对资产组的公允价值的分析；评价每个评估专家的资质和工作（是否第三方或客户员工），并对完成“专家资质”和“专家工作”的审计程序。确定是否需要在审计项目组中增加一个估值专家，以帮助对公允价值/可收回金额的计算进行评价。 （6）比预期所估计减值准备和已记录的金额，调查所有重大差异； （7）确定潜在减值是否恰当。 （8）确定上期确认的长期资产减值准备在本期的变动是否适当。 | C32: 常规★ | G32: √ | I32: I2-15 /I2-16
A33: 17 | B33: 根据评估的舞弊风险等因素增加的审计程序。 | C33: IPO/上市/新三板/重组/舞弊应对
A34: 18 | B34: 检查开发支出是否已按企业会计准则或其他适用的规定在财务报表中做出恰当列报和披露。 | C34: 常规★ | H34: √ | I34: A1-1/A1-15 /A1-16

Sheet 审定表I2-1
A1: 致同会计师事务所
A2: 开发支出审定表
A3: =底稿目录!A2 -> 被审计单位： | D3: =底稿目录!A4 -> 编制人： | G3: =底稿目录!A5 -> 编制日期： | I3: 索引号： | J3: =底稿目录!D5 -> I2-1
A4: =底稿目录!A3 -> 截止日：202X年12月31日 | D4: =底稿目录!A6 -> 复核人： | G4: =底稿目录!A7 -> 复核日期： | I4: 页次：
A5: 项目 | B5: 期初数 | E5: 期末数 | H5: 本期审定数与上期 审定数的比较 | J5: 原因分析
B6: 未审数 | C6: 账项调整 | D6: 审定数 | E6: 未审数 | F6: 账项调整 | G6: 审定数 | H6: 变动额 | I6: 变动率
A7: ='明细表I2-2'!A13 -> 课题 | B7: ='明细表I2-2'!B13 -> 0 | C7: ='明细表I2-2'!H13 -> 0 | D7: ='明细表I2-2'!L13 -> 0 | E7: ='明细表I2-2'!G13 -> 0 | F7: ='明细表I2-2'!H13+'明细表I2-2'!I13-'明细表I2-2'!J13-'明细表I2-2'!K13 -> 0 | G7: ='明细表I2-2'!P13 -> 0 | H7: =G7-D7 -> 0 | I7: =IF(AND(D7=0,H7=0),0,IF(AND(D7=0,H7>0),1,H7/D7)) -> 0
A8: ='明细表I2-2'!A14 -> 课题1 | B8: ='明细表I2-2'!B14 -> 0 | C8: ='明细表I2-2'!H14 -> 0 | D8: ='明细表I2-2'!L14 -> 0 | E8: ='明细表I2-2'!G14 -> 0 | F8: ='明细表I2-2'!H14+'明细表I2-2'!I14-'明细表I2-2'!J14-'明细表I2-2'!K14 -> 0 | G8: ='明细表I2-2'!P14 -> 0 | H8: =G8-D8 -> 0 | I8: =IF(AND(D8=0,H8=0),0,IF(AND(D8=0,H8>0),1,H8/D8)) -> 0
A9: ='明细表I2-2'!A15 -> 课题2 | B9: ='明细表I2-2'!B15 -> 0 | C9: ='明细表I2-2'!H15 -> 0 | D9: ='明细表I2-2'!L15 -> 0 | E9: ='明细表I2-2'!G15 -> 0 | F9: ='明细表I2-2'!H15+'明细表I2-2'!I15-'明细表I2-2'!J15-'明细表I2-2'!K15 -> 0 | G9: ='明细表I2-2'!P15 -> 0 | H9: =G9-D9 -> 0 | I9: =IF(AND(D9=0,H9=0),0,IF(AND(D9=0,H9>0),1,H9/D9)) -> 0
A10: ='明细表I2-2'!A16 -> 课题3 | B10: ='明细表I2-2'!B16 -> 0 | C10: ='明细表I2-2'!H16 -> 0 | D10: ='明细表I2-2'!L16 -> 0 | E10: ='明细表I2-2'!G16 -> 0 | F10: ='明细表I2-2'!H16+'明细表I2-2'!I16-'明细表I2-2'!J16-'明细表I2-2'!K16 -> 0 | G10: ='明细表I2-2'!P16 -> 0 | H10: =G10-D10 -> 0 | I10: =IF(AND(D10=0,H10=0),0,IF(AND(D10=0,H10>0),1,H10/D10)) -> 0
A11: ='明细表I2-2'!A17 -> 数据资源 | B11: ='明细表I2-2'!B17 -> 0 | C11: ='明细表I2-2'!H17 -> 0 | D11: ='明细表I2-2'!L17 -> 0 | E11: ='明细表I2-2'!G17 -> 0 | F11: ='明细表I2-2'!H17+'明细表I2-2'!I17-'明细表I2-2'!J17-'明细表I2-2'!K17 -> 0 | G11: ='明细表I2-2'!P17 -> 0 | H11: =G11-D11 -> 0 | I11: =IF(AND(D11=0,H11=0),0,IF(AND(D11=0,H11>0),1,H11/D11)) -> 0
A12: ='明细表I2-2'!A18 -> …… | B12: ='明细表I2-2'!B18 -> 0 | C12: ='明细表I2-2'!H18 -> 0 | D12: ='明细表I2-2'!L18 -> 0 | E12: ='明细表I2-2'!G18 -> 0 | F12: ='明细表I2-2'!H18+'明细表I2-2'!I18-'明细表I2-2'!J18-'明细表I2-2'!K18 -> 0 | G12: ='明细表I2-2'!P18 -> 0 | H12: =G12-D12 -> 0 | I12: =IF(AND(D12=0,H12=0),0,IF(AND(D12=0,H12>0),1,H12/D12)) -> 0
A13: 合计 | B13: =SUM(B7:B12) -> 0 | C13: =SUM(C7:C12) -> 0 | D13: =SUM(D7:D12) -> 0 | E13: =SUM(E7:E12) -> 0 | F13: =SUM(F7:F12) -> 0 | G13: =SUM(G7:G12) -> 0 | H13: =G13-D13 -> 0 | I13: =IF(AND(D13=0,H13=0),0,IF(AND(D13=0,H13>0),1,H13/D13)) -> 0
A14: TB数据：
A15: 差异 | B15: =B13-B14 -> 0 | C15: =C13-C14 -> 0 | D15: =D13-D14 -> 0 | E15: =E13-E14 -> 0 | F15: =F13-F14 -> 0 | G15: =G13-G14 -> 0
A17: 1、审计说明：
A20: 2、审计结论：
A23: 提示：
A24: 重大事项说明（如适用，根据1131号等审计准则和指南的要求编制，说明涉及事项内容、应对措施、审计结论或解决方法，以及可能对审计报告的影响）
A25: A、风险评估结果和内控了解、测试情况（不适用则说明：不存在重大错报风险。)
A26: (识别和实际评估的重大错报风险、尤其识特别风险，以及对内控了解和控制测试情况〔采用综合方案时〕）；
A27: （提示：a、收入科目应当假定存在舞弊的特别风险，如不存在，应说明理由）
A28: b、涉及特别风险时，应当重点说明有关事项、应当措施、结果〔可索引有关底稿〕。特别风险涉及的事项包括但不限于：
A29: (1)舞弊风险（如1141准则的示例）；(2)重大非常规交易（如企业购并、债务重组、非货币性资产交换、重大或有事项、持续经营、违反法律法规等）；
A30: (3)重大关联交易；(4)重大判断事项（如重大会计估计、会计政策及其变更）；(5)重大复杂交易；(6)仅通过实质性程序无法应对的重大错报风险（如日常交易采用高度自动化处理）等等）)
A31: B、发现的重大不符事项（如适用）
A32: （按调整事项，逐笔概述调整原因及对本科目的调整金额，并说明相关底稿的索引号〔即具体事项内容和调整分录，见经索引的本科目或相关科目的检查表或测算表〕）；

Sheet 附注披露（上市公司）
A1: 致同会计师事务所
A2: 开发支出附注披露表（上市公司）
A3: =底稿目录!A2 -> 被审计单位： | C3: =底稿目录!A4 -> 编制人： | E3: =底稿目录!A5 -> 编制日期： | F3: 索引号：
A4: =底稿目录!A3 -> 截止日：202X年12月31日 | C4: =底稿目录!A6 -> 复核人： | E4: =底稿目录!A7 -> 复核日期： | F4: 页次：
A5: 研发支出
A6: （按费用性质披露研发支出本期发生额、上期发生额，包括费用化研发支出和资本化研发支出。（15号文第二十六条））
A7: 项 目 | B7: 本期发生额 | D7: 上期发生额
B8: 费用化金额 | C8: 资本化金额 | D8: 费用化金额 | E8: 资本化金额
A9: 人工费
A10: 材料费
A11: 水电燃气费
A12: 折旧费
A13: 无形资产摊销
A14: 外购在研项目
A15: ……
A16: 合 计
A17: 【提示：根据财会〔2019〕6号，“研发费用”项目，反映企业进行研究与开发过程中发生的费用化支出，以及计入管理费用的自行开发无形资产的摊销。】
A18: 【费用化金额列请与研发费用对应，资本化金额请与开发支出对应。】
A19: 开发支出
A20: 项 目 | B20: 期初数 | C20: 本期增加 | E20: 本期减少 | G20: 期末数
C21: 内部开发支出 | D21: 其他增加 | E21: 确认为无形资产 | F21: 计入当期损益
A22: ='明细表I2-2'!A13 -> 课题 | B22: ='明细表I2-2'!L13 -> 0 | C22: =IF('明细表I2-2'!$D13="内部开发支出",'明细表I2-2'!$M13,0) -> 0 | D22: =IF('明细表I2-2'!$D13="其他增加",'明细表I2-2'!$M13,0) -> 0 | E22: ='明细表I2-2'!N13 -> 0 | F22: ='明细表I2-2'!O13 -> 0 | G22: =B22+C22+D22-E22-F22 -> 0
A23: ='明细表I2-2'!A14 -> 课题1 | B23: ='明细表I2-2'!L14 -> 0 | C23: =IF('明细表I2-2'!$D14="内部开发支出",'明细表I2-2'!$M14,0) -> 0 | D23: =IF('明细表I2-2'!$D14="其他增加",'明细表I2-2'!$M14,0) -> 0 | E23: ='明细表I2-2'!N14 -> 0 | F23: ='明细表I2-2'!O14 -> 0 | G23: =B23+C23+D23-E23-F23 -> 0
A24: ='明细表I2-2'!A15 -> 课题2 | B24: ='明细表I2-2'!L15 -> 0 | C24: =IF('明细表I2-2'!$D15="内部开发支出",'明细表I2-2'!$M15,0) -> 0 | D24: =IF('明细表I2-2'!$D15="其他增加",'明细表I2-2'!$M15,0) -> 0 | E24: ='明细表I2-2'!N15 -> 0 | F24: ='明细表I2-2'!O15 -> 0 | G24: =B24+C24+D24-E24-F24 -> 0
A25: ='明细表I2-2'!A16 -> 课题3 | B25: ='明细表I2-2'!L16 -> 0 | C25: =IF('明细表I2-2'!$D16="内部开发支出",'明细表I2-2'!$M16,0) -> 0 | D25: =IF('明细表I2-2'!$D16="其他增加",'明细表I2-2'!$M16,0) -> 0 | E25: ='明细表I2-2'!N16 -> 0 | F25: ='明细表I2-2'!O16 -> 0 | G25: =B25+C25+D25-E25-F25 -> 0
A26: ='明细表I2-2'!A17 -> 数据资源 | B26: ='明细表I2-2'!L17 -> 0 | C26: =IF('明细表I2-2'!$D17="内部开发支出",'明细表I2-2'!$M17,0) -> 0 | D26: =IF('明细表I2-2'!$D17="其他增加",'明细表I2-2'!$M17,0) -> 0 | E26: ='明细表I2-2'!N17 -> 0 | F26: ='明细表I2-2'!O17 -> 0 | G26: =B26+C26+D26-E26-F26 -> 0
A27: ='明细表I2-2'!A18 -> …… | B27: ='明细表I2-2'!L18 -> 0 | C27: =IF('明细表I2-2'!$D18="内部开发支出",'明细表I2-2'!$M18,0) -> 0 | D27: =IF('明细表I2-2'!$D18="其他增加",'明细表I2-2'!$M18,0) -> 0 | E27: ='明细表I2-2'!N18 -> 0 | F27: ='明细表I2-2'!O18 -> 0 | G27: =B27+C27+D27-E27-F27 -> 0
A28: ='明细表I2-2'!A19 -> 0 | B28: ='明细表I2-2'!L19 -> 0 | C28: =IF('明细表I2-2'!$D19="内部开发支出",'明细表I2-2'!$M19,0) -> 0 | D28: =IF('明细表I2-2'!$D19="其他增加",'明细表I2-2'!$M19,0) -> 0 | E28: ='明细表I2-2'!N19 -> 0 | F28: ='明细表I2-2'!O19 -> 0 | G28: =B28+C28+D28-E28-F28 -> 0
A29: ='明细表I2-2'!A20 -> 0 | B29: ='明细表I2-2'!L20 -> 0 | C29: =IF('明细表I2-2'!$D20="内部开发支出",'明细表I2-2'!$M20,0) -> 0 | D29: =IF('明细表I2-2'!$D20="其他增加",'明细表I2-2'!$M20,0) -> 0 | E29: ='明细表I2-2'!N20 -> 0 | F29: ='明细表I2-2'!O20 -> 0 | G29: =B29+C29+D29-E29-F29 -> 0
A30: ='明细表I2-2'!A21 -> 0 | B30: ='明细表I2-2'!L21 -> 0 | C30: =IF('明细表I2-2'!$D21="内部开发支出",'明细表I2-2'!$M21,0) -> 0 | D30: =IF('明细表I2-2'!$D21="其他增加",'明细表I2-2'!$M21,0) -> 0 | E30: ='明细表I2-2'!N21 -> 0 | F30: ='明细表I2-2'!O21 -> 0 | G30: =B30+C30+D30-E30-F30 -> 0
A31: 合 计 | B31: =SUM(B22:B30) -> 0 | C31: =SUM(C22:C30) -> 0 | D31: =SUM(D22:D30) -> 0 | E31: =SUM(E22:E30) -> 0 | F31: =SUM(F22:F30) -> 0 | G31: =SUM(G22:G30) -> 0
A32: 【增减变动因素可根据实际情况自行添加】
A33: 续：
A34: 项 目 | B34: 资本化开始时点 | C34: 资本化的具体依据 | D34: 截至期末的研发进度
A35: =#REF! -> #REF! | B35: =#REF! -> #REF! | C35: =#REF! -> #REF! | D35: =#REF! -> #REF!
A36: =#REF! -> #REF! | B36: =#REF! -> #REF! | C36: =#REF! -> #REF! | D36: =#REF! -> #REF!
A37: =#REF! -> #REF! | B37: =#REF! -> #REF! | C37: =#REF! -> #REF! | D37: =#REF! -> #REF!
A38: =#REF! -> #REF! | B38: =#REF! -> #REF! | C38: =#REF! -> #REF! | D38: =#REF! -> #REF!
A39: =#REF! -> #REF! | B39: =#REF! -> #REF! | C39: =#REF! -> #REF! | D39: =#REF! -> #REF!
A40: 合 计 | B40: =SUM(B35:B39) -> #REF! | C40: =SUM(C35:C39) -> #REF! | D40: =SUM(D35:D39) -> #REF!
...

Sheet 附注披露（国有企业）
A1: 致同会计师事务所
A2: 开发支出附注披露表（国有企业）
A3: =底稿目录!A2 -> 被审计单位： | C3: =底稿目录!A4 -> 编制人： | E3: =底稿目录!A5 -> 编制日期： | G3: 索引号：
A4: =底稿目录!A3 -> 截止日：202X年12月31日 | C4: =底稿目录!A6 -> 复核人： | E4: =底稿目录!A7 -> 复核日期： | G4: 页次：
A5: 开发支出
A6: 项 目 | B6: 期初余额 | C6: 本期增加 | E6: 本期减少 | H6: 期末余额
C7: 内部开发支出 | D7: 其他 | E7: 确认为无形资产 | F7: 转入当期损益 | G7: 其他
A8: ='明细表I2-2'!A13 -> 课题 | B8: ='明细表I2-2'!L13 -> 0 | C8: =IF('明细表I2-2'!$D13="内部开发支出",'明细表I2-2'!$M13,0) -> 0 | D8: =IF('明细表I2-2'!$D13="其他增加",'明细表I2-2'!$M13,0) -> 0 | E8: ='明细表I2-2'!N13 -> 0 | F8: ='明细表I2-2'!O13 -> 0 | H8: =B8+C8+D8-E8-F8-G8 -> 0
A9: ='明细表I2-2'!A14 -> 课题1 | B9: ='明细表I2-2'!L14 -> 0 | C9: =IF('明细表I2-2'!$D14="内部开发支出",'明细表I2-2'!$M14,0) -> 0 | D9: =IF('明细表I2-2'!$D14="其他增加",'明细表I2-2'!$M14,0) -> 0 | E9: ='明细表I2-2'!N14 -> 0 | F9: ='明细表I2-2'!O14 -> 0 | H9: =B9+C9+D9-E9-F9-G9 -> 0
A10: ='明细表I2-2'!A15 -> 课题2 | B10: ='明细表I2-2'!L15 -> 0 | C10: =IF('明细表I2-2'!$D15="内部开发支出",'明细表I2-2'!$M15,0) -> 0 | D10: =IF('明细表I2-2'!$D15="其他增加",'明细表I2-2'!$M15,0) -> 0 | E10: ='明细表I2-2'!N15 -> 0 | F10: ='明细表I2-2'!O15 -> 0 | H10: =B10+C10+D10-E10-F10-G10 -> 0
A11: ='明细表I2-2'!A16 -> 课题3 | B11: ='明细表I2-2'!L16 -> 0 | C11: =IF('明细表I2-2'!$D16="内部开发支出",'明细表I2-2'!$M16,0) -> 0 | D11: =IF('明细表I2-2'!$D16="其他增加",'明细表I2-2'!$M16,0) -> 0 | E11: ='明细表I2-2'!N16 -> 0 | F11: ='明细表I2-2'!O16 -> 0 | H11: =B11+C11+D11-E11-F11-G11 -> 0
A12: ='明细表I2-2'!A17 -> 数据资源 | B12: ='明细表I2-2'!L17 -> 0 | C12: =IF('明细表I2-2'!$D17="内部开发支出",'明细表I2-2'!$M17,0) -> 0 | D12: =IF('明细表I2-2'!$D17="其他增加",'明细表I2-2'!$M17,0) -> 0 | E12: ='明细表I2-2'!N17 -> 0 | F12: ='明细表I2-2'!O17 -> 0 | H12: =B12+C12+D12-E12-F12-G12 -> 0
A13: ='明细表I2-2'!A18 -> …… | B13: ='明细表I2-2'!L18 -> 0 | C13: =IF('明细表I2-2'!$D18="内部开发支出",'明细表I2-2'!$M18,0) -> 0 | D13: =IF('明细表I2-2'!$D18="其他增加",'明细表I2-2'!$M18,0) -> 0 | E13: ='明细表I2-2'!N18 -> 0 | F13: ='明细表I2-2'!O18 -> 0 | H13: =B13+C13+D13-E13-F13-G13 -> 0
A14: ='明细表I2-2'!A19 -> 0 | B14: ='明细表I2-2'!L19 -> 0 | C14: =IF('明细表I2-2'!$D19="内部开发支出",'明细表I2-2'!$M19,0) -> 0 | D14: =IF('明细表I2-2'!$D19="其他增加",'明细表I2-2'!$M19,0) -> 0 | E14: ='明细表I2-2'!N19 -> 0 | F14: ='明细表I2-2'!O19 -> 0 | H14: =B14+C14+D14-E14-F14-G14 -> 0
A15: ='明细表I2-2'!A20 -> 0 | B15: ='明细表I2-2'!L20 -> 0 | C15: =IF('明细表I2-2'!$D20="内部开发支出",'明细表I2-2'!$M20,0) -> 0 | D15: =IF('明细表I2-2'!$D20="其他增加",'明细表I2-2'!$M20,0) -> 0 | E15: ='明细表I2-2'!N20 -> 0 | F15: ='明细表I2-2'!O20 -> 0 | H15: =B15+C15+D15-E15-F15-G15 -> 0
A16: ='明细表I2-2'!A21 -> 0 | B16: ='明细表I2-2'!L21 -> 0 | C16: =IF('明细表I2-2'!$D21="内部开发支出",'明细表I2-2'!$M21,0) -> 0 | D16: =IF('明细表I2-2'!$D21="其他增加",'明细表I2-2'!$M21,0) -> 0 | E16: ='明细表I2-2'!N21 -> 0 | F16: ='明细表I2-2'!O21 -> 0 | H16: =B16+C16+D16-E16-F16-G16 -> 0
A17: 合 计 | B17: =SUM(B8:B16) -> 0 | C17: =SUM(C8:C16) -> 0 | D17: =SUM(D8:D16) -> 0 | E17: =SUM(E8:E16) -> 0 | F17: =SUM(F8:F16) -> 0 | G17: =SUM(G8:G16) -> 0 | H17: =SUM(H8:H16) -> 0

Sheet 明细表I2-2
A1: 致同会计师事务所
A2: 开发支出明细表
A3: =底稿目录!A2 -> 被审计单位： | H3: =底稿目录!A4 -> 编制人： | L3: =底稿目录!A5 -> 编制日期： | S3: 索引号： | T3: =底稿目录!D8 -> I2-2
A4: =底稿目录!A3 -> 截止日：202X年12月31日 | H4: =底稿目录!A6 -> 复核人： | L4: =底稿目录!A7 -> 复核日期： | S4: 页次：
A5: 一、审计目标:
A6: 1.资产负债表中记录的开发支出已发生，且与被审计单位有关，已记录于恰当的账户；
A7: 2.所有应当记录的开发支出均已记录，所有应当包括在财务报表中的相关披露均已包括；
A8: 3. 与开发支出有关的金额及其他数据已恰当记录，相关披露已得到恰当计量和描述
A9: 二、审计过程：
A10: 研究开发项目名称 | B10: 未审数 | H10: 期初调整 | I10: 账项调整 | L10: 审定数 | Q10: 无形资产/存货科目记录期末审定数 | R10: 差异 | S10: 截至期末的研发进度 | T10: 备注
B11: 期初数 | C11: 本期增加 | E11: 本期减少 | G11: 期末数 | H11: 账项调整 | I11: 本期增加 | J11: 本期减少 | L11: 期初数 | M11: 本期增加 | N11: 本期减少 | P11: 期末数
C12: 金额 | D12: 增加方式 | E12: 计入无形资产/存货 | F12: 计入当期损益 | J12: 计入无形资产/存货 | K12: 计入当期损益 | N12: 计入无形资产/存货 | O12: 计入当期损益
A13: 课题 | G13: =B13+C13-E13-F13 -> 0 | L13: =B13+H13 -> 0 | M13: =C13+I13 -> 0 | N13: =E13+J13 -> 0 | O13: =F13+K13 -> 0 | P13: =L13+M13-N13-O13 -> 0 | R13: =P13-Q13 -> 0
A14: 课题1 | G14: =B14+C14-E14-F14 -> 0 | L14: =B14+H14 -> 0 | M14: =C14+I14 -> 0 | N14: =E14+J14 -> 0 | O14: =F14+K14 -> 0 | P14: =L14+M14-N14-O14 -> 0 | R14: =P14-Q14 -> 0
A15: 课题2 | G15: =B15+C15-E15-F15 -> 0 | L15: =B15+H15 -> 0 | M15: =C15+I15 -> 0 | N15: =E15+J15 -> 0 | O15: =F15+K15 -> 0 | P15: =L15+M15-N15-O15 -> 0 | R15: =P15-Q15 -> 0
A16: 课题3 | G16: =B16+C16-E16-F16 -> 0 | L16: =B16+H16 -> 0 | M16: =C16+I16 -> 0 | N16: =E16+J16 -> 0 | O16: =F16+K16 -> 0 | P16: =L16+M16-N16-O16 -> 0 | R16: =P16-Q16 -> 0
A17: 数据资源 | G17: =B17+C17-E17-F17 -> 0 | L17: =B17+H17 -> 0 | M17: =C17+I17 -> 0 | N17: =E17+J17 -> 0 | O17: =F17+K17 -> 0 | P17: =L17+M17-N17-O17 -> 0 | R17: =P17-Q17 -> 0
A18: …… | G18: =B18+C18-E18-F18 -> 0 | L18: =B18+H18 -> 0 | M18: =C18+I18 -> 0 | N18: =E18+J18 -> 0 | O18: =F18+K18 -> 0 | P18: =L18+M18-N18-O18 -> 0 | R18: =P18-Q18 -> 0
G19: =B19+C19-E19-F19 -> 0 | L19: =B19+H19 -> 0 | M19: =C19+I19 -> 0 | N19: =E19+J19 -> 0 | O19: =F19+K19 -> 0 | P19: =L19+M19-N19-O19 -> 0 | R19: =P19-Q19 -> 0
G20: =B20+C20-E20-F20 -> 0 | L20: =B20+H20 -> 0 | M20: =C20+I20 -> 0 | N20: =E20+J20 -> 0 | O20: =F20+K20 -> 0 | P20: =L20+M20-N20-O20 -> 0 | R20: =P20-Q20 -> 0
G21: =B21+C21-E21-F21 -> 0 | L21: =B21+H21 -> 0 | M21: =C21+I21 -> 0 | N21: =E21+J21 -> 0 | O21: =F21+K21 -> 0 | P21: =L21+M21-N21-O21 -> 0 | R21: =P21-Q21 -> 0
G22: =B22+C22-E22-F22 -> 0 | L22: =B22+H22 -> 0 | M22: =C22+I22 -> 0 | N22: =E22+J22 -> 0 | O22: =F22+K22 -> 0 | P22: =L22+M22-N22-O22 -> 0 | R22: =P22-Q22 -> 0
A23: 合计 | B23: =SUM(B13:B22) -> 0 | C23: =SUM(C13:C22) -> 0 | E23: =SUM(E13:E22) -> 0 | F23: =SUM(F13:F22) -> 0 | G23: =SUM(G13:G22) -> 0 | H23: =SUM(H13:H22) -> 0 | I23: =SUM(I13:I22) -> 0 | J23: =SUM(J13:J22) -> 0 | K23: =SUM(K13:K22) -> 0 | L23: =SUM(L13:L22) -> 0 | ... P23: =SUM(P13:P22) -> 0 | R23: =P23-Q23 -> 0
A24: 三、审计说明：
A27: 四、审计结论：
A32: 编制说明：
A33: 1、本科目核算企业进行研究与开发无形资产过程中发生的各项支出。
A34: 本科目可按研究开发项目，分别“费用化支出”、“资本化支出”进行明细核算。
A35: 期（月）末，应将本科目归集的费用化支出金额转入“管理费用”科目，借记“管理费用”科目，贷记本科目（费用化支出）。
A36: 研发费用核算时，应从开发支出的贷方转出，不能直接列支在损益中。
A37: 2、本工作底稿应列入开发支出的每一明细账户，经审核后，作为本底稿附件。
A38: 3、备注栏可填写项目内容及异常情况说明。

Sheet 调整分录汇总I2-3
A1: 致同会计师事务所
A2: 开发支出调整分录汇总表
A3: =底稿目录!A2 -> 被审计单位： | C3: =底稿目录!A4 -> 编制人： | F3: =底稿目录!A5 -> 编制日期： | I3: 索引号： | J3: =底稿目录!D9 -> I2-3
A4: =底稿目录!A3 -> 截止日：202X年12月31日 | C4: =底稿目录!A6 -> 复核人： | F4: =底稿目录!A7 -> 复核日期： | I4: 页次：
A5: 调整事项说明 | B5: 类别（报表调整/账项调整/其他） | C5: 报表项目 | D5: 科目名称 | E5: 附注项目 | F5: …… | G5: 借方调整金额 | H5: 贷方调整金额 | I5: 索引 | J5: 备注
A25: 【注：本底稿适用于调整分录较多、较复杂的项目，且仅列示与本报表项目相关的审计调整。项目组可根据项目实际情况选择是否使用该底稿。】

Sheet 会计政策检查I2-4
A1: 致同会计师事务所
A2: 会计政策检查
A3: =底稿目录!A2 -> 被审计单位： | B3: =底稿目录!$A$4 -> 编制人： | G3: =底稿目录!$A$5 -> 编制日期： | J3: 索引号： | K3: =底稿目录!D10 -> I2-4
A4: =底稿目录!A3 -> 截止日：202X年12月31日 | B4: =底稿目录!$A$6 -> 复核人： | G4: =底稿目录!$A$7 -> 复核日期： | J4: 页次：
A5: 一、审计目标
A6: 与研发费用/开发支出有关的金额及其他数据已恰当记录，相关披露已得到恰当计量和描述
A7: 二、审计过程
A8: 1.访谈XX公司管理层XXX，了解XX公司业务类型、研发项目流程、研发模式，针对不同业务或模式，检查会计政策的合理性及与前期的一致性
A9: 2.……
A10: （一）研发流程
A11: 1.立项报告
A12: 2.可行性研究
A13: 3.技术路线图及创新点
A14: 4.实验记录
A15: 5.结题报告
A16: 6.研发场地、设备使用情况检查
... A37: 著差异，且得到一贯性地执行。

Sheet 实质性分析I2-5
A1: 致同会计师事务所
A2: 实质性分析
A3: =底稿目录!A2 -> 被审计单位： | C3: =底稿目录!A4 -> 编制人： | F3: =底稿目录!A5 -> 编制日期： | J3: 索引号： | K3: =底稿目录!D11 -> I2-5
A4: =底稿目录!A3 -> 截止日：202X年12月31日 | C4: =底稿目录!A6 -> 复核人： | F4: =底稿目录!A7 -> 复核日期： | J4: 页 次：
A5: 一、审计目标:
A6: 1.利润表中记录的研发费用已发生，且与被审计单位有关，已记录于恰当的账户。 | F6: 2.与研发费用有关的金额及其他数据已恰当记录，相关披露已得到恰当计量和描述。
A7: 二、审计过程：
A8: （一）研发费用构成分析表
A9: 项目 | B9: 本期合计 | C9: 结构比 | D9: 占主营业务收入比率 | E9: 上年同期 | F9: 结构比 | G9: 占主营业务收入比率 | H9: 增长比例 | I9: 占主营业务收入比率变动 | J9: 变动分析
A10: ='[1]明细表I6-2'!A9 -> 人工费 | B10: ='[1]明细表I6-2'!Q9 -> 0 | C10: =IF(B10=0,0,B10/$B$17) -> 0 | D10: =IF(B10=0,0,B10/$B$18) -> 0 | E10: 6 | F10: =IF(E10=0,0,E10/$E$17) -> 1 | G10: =IF(E10=0,0,E10/$E$18) -> #DIV/0! | H10: =IF(AND(E10=0,B10>0),1,IF(AND(E10=0,B10=0),0,(B10-E10)/E10)) -> -1 | I10: =D10-G10 -> #DIV/0!
A11: ='[1]明细表I6-2'!A10 -> 材料费 | B11: ='[1]明细表I6-2'!Q10 -> 0 | C11: =IF(B11=0,0,B11/$B$17) -> 0 | D11: =IF(B11=0,0,B11/$B$18) -> 0 | E11: 0 | F11: =IF(E11=0,0,E11/$E$17) -> 0 | G11: =IF(E11=0,0,E11/$E$18) -> 0 | H11: =IF(AND(E11=0,B11>0),1,IF(AND(E11=0,B11=0),0,(B11-E11)/E11)) -> 0 | I11: =D11-G11 -> 0
A12: ='[1]明细表I6-2'!A11 -> 制造费用分摊 | B12: ='[1]明细表I6-2'!Q11 -> 0 | C12: =IF(B12=0,0,B12/$B$17) -> 0 | D12: =IF(B12=0,0,B12/$B$18) -> 0 | E12: 0 | F12: =IF(E12=0,0,E12/$E$17) -> 0 | G12: =IF(E12=0,0,E12/$E$18) -> 0 | H12: =IF(AND(E12=0,B12>0),1,IF(AND(E12=0,B12=0),0,(B12-E12)/E12)) -> 0 | I12: =D12-G12 -> 0
A13: ='[1]明细表I6-2'!A12 -> 无形资产摊销 | B13: ='[1]明细表I6-2'!Q12 -> 0 | C13: =IF(B13=0,0,B13/$B$17) -> 0 | D13: =IF(B13=0,0,B13/$B$18) -> 0 | E13: 0 | F13: =IF(E13=0,0,E13/$E$17) -> 0 | G13: =IF(E13=0,0,E13/$E$18) -> 0 | H13: =IF(AND(E13=0,B13>0),1,IF(AND(E13=0,B13=0),0,(B13-E13)/E13)) -> 0 | I13: =D13-G13 -> 0
A14: ='[1]明细表I6-2'!A13 -> 0 | B14: ='[1]明细表I6-2'!Q13 -> 0 | C14: =IF(B14=0,0,B14/$B$17) -> 0 | D14: =IF(B14=0,0,B14/$B$18) -> 0 | E14: 0 | F14: =IF(E14=0,0,E14/$E$17) -> 0 | G14: =IF(E14=0,0,E14/$E$18) -> 0 | H14: =IF(AND(E14=0,B14>0),1,IF(AND(E14=0,B14=0),0,(B14-E14)/E14)) -> 0 | I14: =D14-G14 -> 0
A15: ='[1]明细表I6-2'!A14 -> 0 | B15: ='[1]明细表I6-2'!Q14 -> 0 | C15: =IF(B15=0,0,B15/$B$17) -> 0 | D15: =IF(B15=0,0,B15/$B$18) -> 0 | E15: 0 | F15: =IF(E15=0,0,E15/$E$17) -> 0 | G15: =IF(E15=0,0,E15/$E$18) -> 0 | H15: =IF(AND(E15=0,B15>0),1,IF(AND(E15=0,B15=0),0,(B15-E15)/E15)) -> 0 | I15: =D15-G15 -> 0
A16: ='[1]明细表I6-2'!A15 -> 0 | B16: ='[1]明细表I6-2'!Q15 -> 0 | C16: =IF(B16=0,0,B16/$B$17) -> 0 | D16: =IF(B16=0,0,B16/$B$18) -> 0 | E16: 0 | F16: =IF(E16=0,0,E16/$E$17) -> 0 | G16: =IF(E16=0,0,E16/$E$18) -> 0 | H16: =IF(AND(E16=0,B16>0),1,IF(AND(E16=0,B16=0),0,(B16-E16)/E16)) -> 0 | I16: =D16-G16 -> 0
A17: 合计 | B17: =SUM(B10:B16) -> 0 | C17: =IF(B17=0,0,B17/$B$17) -> 0 | D17: =IF(B17=0,0,B17/$B$18) -> 0 | E17: =SUM(E10:E16) -> 6 | F17: =IF(E17=0,0,E17/$E$17) -> 1 | G17: =IF(E17=0,0,E17/$E$18) -> #DIV/0! | H17: =IF(AND(E17=0,B17>0),1,IF(AND(E17=0,B17=0),0,(B17-E17)/E17)) -> -1 | I17: =D17-G17 -> #DIV/0!
A18: 主营业务收入 | H18: =IF(AND(E18=0,B18>0),1,IF(AND(E18=0,B18=0),0,(B18-E18)/E18)) -> 0
A19: 研发费用占主营业务收入比率 | B19: =B17/B18 -> #DIV/0! | E19: =E17/E18 -> #DIV/0!
A21: （二）费用指标分析表（与同行业数据比较）
A22: 指标 | B22: 本期 | C22: 行业公司A | D22: 行业公司B | E22: 行业公司C | F22: 比较分析
A23: 研发费用占主营业务收入比率 | B23: =B19 -> #DIV/0!
A25: （三）人均费用指标同期对比分析表
A26: 本期 | F26: 上期 | K26: 两期对比分析
A27: 研发人员总数 | B27: 研发人员人均薪酬 | C27: 人均研发经费 | D27: 人均材料 | E27: … | F27: 研发人员总数 | G27: 研发人员人均薪酬 | H27: 人均研发经费 | I27: 人均材料 | J27: …
A31: （四）人均费用指标同行业对比分析表
A32: 公司名称 | B32: 研发人员总数 | C32: 研发人员人均薪酬 | D32: 人均研发经费 | E32: … | F32: 同行业对比分析
A33: 本公司
A34: 可比公司1
A35: 可比公司2
A36: 可比公司3
A39: 三、审计说明：
A40: 1.费用各项目近两年比重变动较大的原因： | E40: 2.与上年同期数据相比，费用指标异常的原因：
A41: a. | E41: a.
A42: b. | E42: b.
A43: 3.与同行业数据相比，费用指标异常的原因： | E43: 4.与预算金额及其他非财务数据相比，费用指标异常的原因：
A44: a. | E44: a.
A45: b. | E45: b.
A46: 5.人均费用指标异常的原因：
A47: a.
...

Sheet 研发项目资本化时点判断I2-6
A1: 致同会计师事务所
A2: 研发项目资本化时点判断
A3: =底稿目录!A2 -> 被审计单位： | J3: =底稿目录!$A$4 -> 编制人： | O3: =底稿目录!$A$5 -> 编制日期： | T3: 索引号： | U3: =底稿目录!D12 -> I2-6
A4: =底稿目录!A3 -> 截止日：202X年12月31日 | J4: =底稿目录!$A$6 -> 复核人： | O4: =底稿目录!$A$7 -> 复核日期： | T4: 页次：
A5: 一、审计目标:
A6: 1.检查研发支出资本化的会计政策是否符合会计准则要求，是否符合研发业务特点，是否符合行业惯例；
A7: 2.检查研究阶段和开发阶段界定时点是否合理，开发完成时点的界定是否合理；
A8: 二、审计过程：
A9: 研发项目名称 | B9: 开发支出总额 | D9: 研发项目具体内容 | E9: 研发项目预算 | I9: 研发人员构成 | J9: 资本化开始的时点 | K9: 资本化的具体依据 | L9: 开发阶段支出资本化确认为无形资产，必须同时满足下列条件 | Q9: 确认为无形资产金额 | R9: 是否与无形资产明细勾稽一致 | S9: 截至期末的研发进度 | T9: 支持性证据 | U9: 索引 | V9: 开发支出资本化判断示例：
B10: 研究阶段 | C10: 开发阶段 | E10: 直接材料 | F10: 直接人工 | G10: …… | H10: 其他费用 | L10: 使用和出售在技术上的可行性 | M10: 是否存在使用和出售该资产的意图 | N10: 是否存在市场和内部使用需求 | O10: 是否有足够的技术、财力支持完成无形资产的开发 | P10: 无形资产的开发支出是否单独核算并可靠计量 | V10: 开发支出资本化的条件 | W10: 条件分析 | X10: 具体情形
V11: 开发是指在进行商业性生产或使用前，将研究成果或其他知识应用于某项计划或设计，以生产出新的或具有实质性改进的材料、装置、产品等。 | W11: 为获取并理解新的科学或技术知识而进行的独创性的有计划调查属于研究，不是开发。 | X11: 开发活动的例子：生产前或使用前的原型和模型的设计、建造和测试；含新技术的工具、夹具、模具和冲模的设计；不具有商业性生产经济规模的试生产设施的设计、建造和运营；新的或改造的材料、设备、产品、工序、系统或服务所选定的替代品的设计、建造和测试等。
V12: 同时满足下列条件的，开发阶段的支出才能确认为无形资产： | W12: 开发阶段应当是已完成研究阶段的工作，在很大程度上具备了形成一项新产品或新技术的基本条件。 | X12: 游戏策划、创意等项目策划阶段与项目立项阶段属于研究阶段；项目计划阶段、项目实施与执行阶段和项目验收阶段属于开发阶段。【研究阶段起点为游戏策划，终点为立项评审通过；开发阶段的起点为项目开发计划，终点为项目相关测试完成后可进入商业运营。】
V13: （a）完成该无形资产以使其能够使用或出售在技术上具有可行性； | W13: 以目前阶段的成果为基础，不存在技术上的障碍或其他不确定性。 | X13: 已经完成了全部计划、设计和测试等使资产能够达到设计规划书中的功能、特征和技术所必需的活动； 经过专家鉴定。 开发新药物或疫苗的主体在获得监管机构最终批准之前通常不能将开发支出资本化，因为在此之前不能证明完成项目的技术可行性。
V14: （b）具有完成该无形资产并使用或出售的意图； | W14: 能够说明开发无形资产的目的 | X14: 自用或出售
V15: （c）无形资产产生经济利益的方式； | W15: 包括能够证明运用该无形资产生产的产品存在市场或无形资产自身存在市场，无形资产将在内部使用的，应当证明其有用性。 | X15: 对运用该无形资产生产产品的市场情况进行可靠预计，以证明所生产的产品存在市场并能够带来经济利益； 能够证明市场上存在对该无形资产的需求。 【基于谨慎性原则一般将商业化程度低的游戏研究开发支出计入费用化】
A16: 合计 | B16: =SUM(B11:B15) -> 0 | C16: =SUM(C11:C15) -> 0 | D16: =SUM(D11:D15) -> 0 | Q16: =SUM(Q11:Q15) -> 0 | V16: （d）有足够的技术、财务资源和其他资源支持，以完成该无形资产的开发，并有能力使用或出售该无形资产； | W16: 为完成该项无形资产开发具有技术上的可靠性，有足够的技术支持和技术能力； 财务资源和其他资源支持； 能够证明企业获取在开发过程中所需的技术、财务和其他资源，以及企业获得这些资源的相关计划等； 有能力使用或出售该无形资产以取得收益。 | X16: 自有资金不足以提供支持的，应能够证明存在外部其他方面的资金支持。
V17: （e）归属于该无形资产开发阶段的支出能够可靠地计量。 | W17: 对研究开发的支出应当单独核算，比如，直接发生的研发人员工资、材料费，以及相关设备折旧费等。 同时从事多项研究开发活动的，所发生的支出应当按照合理的标准在各项研究开发活动之间进行分配；无法合理分配的，应当计入当期损益 | X17: 可辨认，并且可归属于特定产品或项目。
A18: 三、审计说明：
A21: 四、审计结论：
A25: 编制说明：
A26: 一、企业内部研究开发项目研究阶段的支出，应当于发生时计入当期损益。
A27: 二、企业内部研究开发项目开发阶段的支出，同时满足下列条件的，才能确认为无形资产：
A28: （一）完成该无形资产以使其能够使用或出售在技术上具有可行性；
A29: （二）具有完成该无形资产并使用或出售的意图；
A30: （三）无形资产产生经济利益的方式，包括能够证明运用该无形资产生产的产品存在市场或无形资产自身存在市场，无形资产将在内部使用的，应当证明其有用性；
A31: （四）有足够的技术、财务资源和其他资源支持，以完成该无形资产的开发，并有能力使用或出售该无形资产；
A32: （五）归属于该无形资产开发阶段的支出能够可靠地计量。
A33: 三、当研究开发项目发生了同时满足上述列示的五大条件的开发阶段支出，且该研究开发项目尚未完成时本科目可以留有余额。
A34: 提示：
... A45: （10）获取被审计单位研发项目清单以及费用归集明细，检查研发支出的支持性文件，例如，合同、发票、单据、时间表和人工成本费率等，关注研发支出的成本费用归集范围是否恰当，研发支出的发生是否真实，是否与相关研发活动相关。

Sheet 研发项目构成明细表I2-7
A1: 致同会计师事务所
A2: 研发项目构成明细表
A3: =底稿目录!A2 -> 被审计单位： | O3: =底稿目录!$A$4 -> 编制人： | AC3: =底稿目录!$A$5 -> 编制日期： | AZ3: 索引号： | BA3: =底稿目录!D13 -> I2-7
A4: =底稿目录!A3 -> 截止日：202X年12月31日 | O4: =底稿目录!$A$6 -> 复核人： | AC4: =底稿目录!$A$7 -> 复核日期： | AZ4: 页次：
A5: 一、审计目标:
A6: 1.所有应当记录的开发支出/研发费用均已记录，所有应当包括在财务报表中的相关披露均已包括；
A7: 2.与开发支出/研发费用有关的金额及其他数据已恰当记录，相关披露已得到恰当计量和描述。
A8: 二、审计过程：
A9: 项目编码 | B9: 项目名称 | C9: 研发项目起止时间 | D9: 项目阶段 | E9: 账面期初余额 | M9: 账面本期增加金额 | U9: 账面本期减少金额 | AC9: 账面期末余额 | AK9: 审计调整 | AS9: 期末审定金额 | BA9: 备注
D10: 项目阶段 | E10: 直接材料 | F10: 直接人工 | G10: 折旧与摊销 | H10: 能耗 | I10: 委外研发费 | J10: 其他费用 | K10: 小计 | M10: 直接材料 | N10: 直接人工 | O10: 折旧与摊销 | P10: 能耗 | Q10: 委外研发费 | R10: 其他费用 | S10: 小计 | U10: 直接材料 | V10: 直接人工 | W10: 折旧与摊销 | X10: 能耗 | Y10: 委外研发费 | Z10: 其他费用 | AA10: 小计 | AC10: 直接材料 | AD10: 直接人工 | AE10: 折旧与摊销 | AF10: 能耗 | AG10: 委外研发费 | AH10: 其他费用 | AI10: 小计 | AK10: 直接材料 | AL10: 直接人工 | AM10: 折旧与摊销 | AN10: 能耗 | AO10: 委外研发费 | AP10: 其他费用 | AQ10: 小计 | AS10: 直接材料 | AT10: 直接人工 | AU10: 折旧与摊销 | AV10: 能耗 | AW10: 委外研发费 | AX10: 其他费用 | AY10: 小计
K11: 资本化金额 | L11: 费用化金额 | S11: 资本化金额 | T11: 费用化金额 | AA11: 资本化金额 | AB11: 费用化金额 | AI11: 资本化金额 | AJ11: 费用化金额 | AQ11: 资本化金额 | AR11: 费用化金额 | AY11: 资本化金额 | AZ11: 费用化金额
AC12: =E12+M12-U12 -> 0 | AD12: =F12+N12-V12 -> 0 | AE12: =G12+O12-W12 -> 0 | AF12: =H12+P12-X12 -> 0 | AG12: =I12+Q12-Y12 -> 0 | AH12: =J12+R12-Z12 -> 0 | AI12: =K12+S12-AA12 -> 0 | AJ12: =L12+T12-AB12 -> 0 | AS12: =AC12+AK12 -> 0 | AT12: =AD12+AL12 -> 0 | AU12: =AE12+AM12 -> 0 | AV12: =AF12+AN12 -> 0 | AW12: =AG12+AO12 -> 0 | AX12: =AH12+AP12 -> 0 | AY12: =AI12+AQ12 -> 0 | AZ12: =AJ12+AR12 -> 0
AC13: =E13+M13-U13 -> 0 | AD13: =F13+N13-V13 -> 0 | AE13: =G13+O13-W13 -> 0 | AF13: =H13+P13-X13 -> 0 | AG13: =I13+Q13-Y13 -> 0 | AH13: =J13+R13-Z13 -> 0 | AI13: =K13+S13-AA13 -> 0 | AJ13: =L13+T13-AB13 -> 0 | AS13: =AC13+AK13 -> 0 | AT13: =AD13+AL13 -> 0 | AU13: =AE13+AM13 -> 0 | AV13: =AF13+AN13 -> 0 | AW13: =AG13+AO13 -> 0 | AX13: =AH13+AP13 -> 0 | AY13: =AI13+AQ13 -> 0 | AZ13: =AJ13+AR13 -> 0
AC14: =E14+M14-U14 -> 0 | AD14: =F14+N14-V14 -> 0 | AE14: =G14+O14-W14 -> 0 | AF14: =H14+P14-X14 -> 0 | AG14: =I14+Q14-Y14 -> 0 | AH14: =J14+R14-Z14 -> 0 | AI14: =K14+S14-AA14 -> 0 | AJ14: =L14+T14-AB14 -> 0 | AS14: =AC14+AK14 -> 0 | AT14: =AD14+AL14 -> 0 | AU14: =AE14+AM14 -> 0 | AV14: =AF14+AN14 -> 0 | AW14: =AG14+AO14 -> 0 | AX14: =AH14+AP14 -> 0 | AY14: =AI14+AQ14 -> 0 | AZ14: =AJ14+AR14 -> 0
AC15: =E15+M15-U15 -> 0 | AD15: =F15+N15-V15 -> 0 | AE15: =G15+O15-W15 -> 0 | AF15: =H15+P15-X15 -> 0 | AG15: =I15+Q15-Y15 -> 0 | AH15: =J15+R15-Z15 -> 0 | AI15: =K15+S15-AA15 -> 0 | AJ15: =L15+T15-AB15 -> 0 | AS15: =AC15+AK15 -> 0 | AT15: =AD15+AL15 -> 0 | AU15: =AE15+AM15 -> 0 | AV15: =AF15+AN15 -> 0 | AW15: =AG15+AO15 -> 0 | AX15: =AH15+AP15 -> 0 | AY15: =AI15+AQ15 -> 0 | AZ15: =AJ15+AR15 -> 0
AC16: =E16+M16-U16 -> 0 | AD16: =F16+N16-V16 -> 0 | AE16: =G16+O16-W16 -> 0 | AF16: =H16+P16-X16 -> 0 | AG16: =I16+Q16-Y16 -> 0 | AH16: =J16+R16-Z16 -> 0 | AI16: =K16+S16-AA16 -> 0 | AJ16: =L16+T16-AB16 -> 0 | AS16: =AC16+AK16 -> 0 | AT16: =AD16+AL16 -> 0 | AU16: =AE16+AM16 -> 0 | AV16: =AF16+AN16 -> 0 | AW16: =AG16+AO16 -> 0 | AX16: =AH16+AP16 -> 0 | AY16: =AI16+AQ16 -> 0 | AZ16: =AJ16+AR16 -> 0
AC17: =E17+M17-U17 -> 0 | AD17: =F17+N17-V17 -> 0 | AE17: =G17+O17-W17 -> 0 | AF17: =H17+P17-X17 -> 0 | AG17: =I17+Q17-Y17 -> 0 | AH17: =J17+R17-Z17 -> 0 | AI17: =K17+S17-AA17 -> 0 | AJ17: =L17+T17-AB17 -> 0 | AS17: =AC17+AK17 -> 0 | AT17: =AD17+AL17 -> 0 | AU17: =AE17+AM17 -> 0 | AV17: =AF17+AN17 -> 0 | AW17: =AG17+AO17 -> 0 | AX17: =AH17+AP17 -> 0 | AY17: =AI17+AQ17 -> 0 | AZ17: =AJ17+AR17 -> 0
AC18: =E18+M18-U18 -> 0 | AD18: =F18+N18-V18 -> 0 | AE18: =G18+O18-W18 -> 0 | AF18: =H18+P18-X18 -> 0 | AG18: =I18+Q18-Y18 -> 0 | AH18: =J18+R18-Z18 -> 0 | AI18: =K18+S18-AA18 -> 0 | AJ18: =L18+T18-AB18 -> 0 | AS18: =AC18+AK18 -> 0 | AT18: =AD18+AL18 -> 0 | AU18: =AE18+AM18 -> 0 | AV18: =AF18+AN18 -> 0 | AW18: =AG18+AO18 -> 0 | AX18: =AH18+AP18 -> 0 | AY18: =AI18+AQ18 -> 0 | AZ18: =AJ18+AR18 -> 0
AC19: =E19+M19-U19 -> 0 | AD19: =F19+N19-V19 -> 0 | AE19: =G19+O19-W19 -> 0 | AF19: =H19+P19-X19 -> 0 | AG19: =I19+Q19-Y19 -> 0 | AH19: =J19+R19-Z19 -> 0 | AI19: =K19+S19-AA19 -> 0 | AJ19: =L19+T19-AB19 -> 0 | AS19: =AC19+AK19 -> 0 | AT19: =AD19+AL19 -> 0 | AU19: =AE19+AM19 -> 0 | AV19: =AF19+AN19 -> 0 | AW19: =AG19+AO19 -> 0 | AX19: =AH19+AP19 -> 0 | AY19: =AI19+AQ19 -> 0 | AZ19: =AJ19+AR19 -> 0
AC20: =E20+M20-U20 -> 0 | AD20: =F20+N20-V20 -> 0 | AE20: =G20+O20-W20 -> 0 | AF20: =H20+P20-X20 -> 0 | AG20: =I20+Q20-Y20 -> 0 | AH20: =J20+R20-Z20 -> 0 | AI20: =K20+S20-AA20 -> 0 | AJ20: =L20+T20-AB20 -> 0 | AS20: =AC20+AK20 -> 0 | AT20: =AD20+AL20 -> 0 | AU20: =AE20+AM20 -> 0 | AV20: =AF20+AN20 -> 0 | AW20: =AG20+AO20 -> 0 | AX20: =AH20+AP20 -> 0 | AY20: =AI20+AQ20 -> 0 | AZ20: =AJ20+AR20 -> 0
A21: 合计 | E21: =SUM(E12:E20) -> 0 | F21: =SUM(F12:F20) -> 0 | G21: =SUM(G12:G20) -> 0 | H21: =SUM(H12:H20) -> 0 | I21: =SUM(I12:I20) -> 0 | J21: =SUM(J12:J20) -> 0 | K21: =SUM(K12:K20) -> 0 | L21: =SUM(L12:L20) -> 0 | ... AZ21: =SUM(AZ12:AZ20) -> 0
A22: 三、审计说明：
A25: 四、审计结论：

Sheet 研发材料投入检查表I2-8
A1: 致同会计师事务所
A2: 研发材料投入检查表
A3: =底稿目录!A2 -> 被审计单位： | F3: =底稿目录!$A$4 -> 编制人： | J3: =底稿目录!$A$5 -> 编制日期： | P3: 索引号： | Q3: =底稿目录!D14 -> I2-8
A4: =底稿目录!A3 -> 截止日：202X年12月31日 | F4: =底稿目录!$A$6 -> 复核人： | J4: =底稿目录!$A$7 -> 复核日期： | P4: 页 次：
A5: 一、审计目标:
A6: 1.利润表中记录的研发费用已发生，且与被审计单位有关，已记录于恰当的账户。
A7: 2.与研发费用有关的金额及其他数据已恰当记录，相关披露已得到恰当计量和描述。
A8: 二、样本选取标准与规模：
A9: 测试总体： | B9: 如研发费用-研发材料借方发生额所有凭证共XX笔金额XX | G9: 特定样本： | H9: XX金额以上（大额）、关联方/关联交易形成的款项、XX异常款项全部测试，共XX笔
A10: 抽样总体： | B10: 测试总体扣除特定样本以外的样本，共XX笔、金额XX | G10: 确定的抽样样本量： | I10: 抽取XX笔 | J10: （如果使用了样本计算器计算样本量，样本量计算过程见<XX>底稿）
A11: 抽样方法： | B11: 随机选样/系统选样/货币单元抽样/随意选样（非统计抽样适用） | G11: 抽样过程： | H11: 使用IDEA（XX抽样工具）选择XX数量、金额XX的样本进行测试，抽样工具中的样本选择过程和结果见<XX>底稿
A12: 三、审计过程：
A13: 测试内容说明：1.原始凭证是否齐全； 2.记账凭证与原始凭证是否相符；3.账务处理是否正确；4.是否记录于恰当的会计期间；5.……
A14: 记账凭证 | J14: 出库单/领料单 | O14: …… | P14: 索引号 | Q14: 是否异常
A15: 项目名称 | B15: 凭证编号 | C15: 业务内容 | D15: 存货名称 | E15: 单位 | F15: 数量 | G15: 借方金额 | H15: 对方科目 | I15: 对方明细科目 | J15: 日期/编号 | K15: 领用人员 | L15: 领用部门 | M15: 研发项目 | N15: 数量
R16: 重点检查领用人员是否为该项目研发人员、出库单中研发项目是否与账面一致等
A31: 合计 | G31: =SUM(G16:G30) -> 0
A32: 本期发生额 | G32: ='研发项目构成明细表I2-7'!M21 -> 0
A33: 检查比例 | G33: =G31/G32 -> #DIV/0!
A34: 四、审计说明：
A38: 五、审计结论：

Sheet 研发人员认定检查表I2-9
A1: 致同会计师事务所
A2: 研发人员认定检查表
A3: =底稿目录!A2 -> 被审计单位： | E3: =底稿目录!$A$4 -> 编制人： | I3: =底稿目录!$A$5 -> 编制日期： | O3: 索引号： | P3: =底稿目录!D15 -> I2-9
A4: =底稿目录!A3 -> 截止日：202X年12月31日 | E4: =底稿目录!$A$6 -> 复核人： | I4: =底稿目录!$A$7 -> 复核日期： | O4: 页 次：
A5: 一、审计目标:
A6: 1.利润表中记录的研发费用已发生，且与被审计单位有关，已记录于恰当的账户。 | H6: 2.与研发费用有关的金额及其他数据已恰当记录，相关披露已得到恰当计量和描述。
A7: 二、审计过程：
A8: 序号 | B8: 姓名 | C8: 性别 | D8: 年龄 | E8: 学历 | F8: 毕业院校 | G8: 所学专业 | H8: 职称 | I8: 职务 | J8: 部门 | K8: 人员类别 | L8: 入职日期 | M8: 聘用形式 | N8: 是否全时参与该研发项目 | O8: … | P8: 附件索引号 | Q8: 【检查要素根据实际情况自行增减】
A21: 三、审计说明：
A24: 四、审计结论：
A27: 编制说明：
A28: 研发人员指直接从事研发活动的人员以及与研发活动密切相关的管理人员和直接服务人员。主要包括：在研发部门及相关职能部门中直接从事研发项目的专业人员；具有相关技术知识和经验，在专业人员指导下参与研发活动的技术人员；参与研发活动的技工等。发行人应准确、合理认定研发人员，不得将与研发活动无直接关系的人员，如从事后勤服务的文秘、前台、餐饮、安保等人员，认定为研发人员。
A29: 1.关于非全时研发人员
A30: 对于既从事研发活动又从事非研发活动的人员，当期研发工时占比低于50%的，原则上不应认定为研发人员。如将其认定为研发人员，发行人应结合该人员对研发活动的实际贡献等，审慎论证认定的合理性。
A31: 2.从事定制化产品研发生产或提供受托研发服务（以下简称受托研发）的人员
A32: 发行人与客户签订合同，为客户提供受托研发，除有充分证据表明履约过程中形成发行人能够控制的并预期能给发行人带来收益的研发成果外，原则上单纯从事受托研发的人员不能认定为研发人员。
A33: 3.关于研发人员聘用形式
A34: 研发人员原则上应为与发行人签订劳动合同的人员。劳务派遣人员原则上不能认定为研发人员。发行人将签订其他形式合同的人员认定为研发人员的，应当结合相关人员的专业背景、工作内容、未签订劳动合同的原因等，审慎论证认定的合理性。研发人员聘用形式的计算口径，应与按照《公开发行证券的公司信息披露内容与格式准则第57号——招股说明书》第四十二条披露的员工人数口径一致。

Sheet 研发人员工时检查表I2-10
A1: 致同会计师事务所
A2: 研发人员工时检查表
A3: =底稿目录!A2 -> 被审计单位： | D3: =底稿目录!$A$4 -> 编制人： | F3: =底稿目录!$A$5 -> 编制日期： | I3: 索引号： | J3: =底稿目录!D16 -> I2-10
A4: =底稿目录!A3 -> 截止日：202X年12月31日 | D4: =底稿目录!$A$6 -> 复核人： | F4: =底稿目录!$A$7 -> 复核日期： | I4: 页 次：
A5: 一、审计目标:
A6: 1.利润表中记录的研发费用已发生，且与被审计单位有关，已记录于恰当的账户。
A7: 2.与研发费用有关的金额及其他数据已恰当记录，相关披露已得到恰当计量和描述。
A8: 二、审计过程：
A9: 序号 | B9: 项目名称 | C9: 项目号 | D9: 项目起止时间 | E9: 研发人员姓名 | F9: 研发工时 | G9: 研发工时分配依据 | H9: 研发薪酬计提 | I9: … | J9: 附件索引号 | K9: 【检查要素根据实际情况自行增减】
A10: 1 | B10: ABC | C10: A20001 | D10: 20XX.X-20XX.XX | E10: AXX
A11: 2 | D11: 20XX.X-20XX.XX | E11: BXX
A12: 3 | D12: 20XX.X-20XX.XX | E12: CXX
A13: 4 | B13: DEF | C13: A20002 | D13: 20XX.X-20XX.XX | E13: DXX
A14: 5 | D14: 20XX.X-20XX.XX | E14: EXX
A15: 6 | D15: 20XX.X-20XX.XX | E15: FXX
A16: …
A17: 三、审计说明：
A20: 四、审计结论：
A23: 编制说明：
A24: 公开发行证券的公司发行人存在非全时研发人员的，应能够清晰统计相关人员从事不同职能的工时情况，按照企业会计准则的规定将属于从事研发活动的薪酬准确、合理分摊计入研发支出。发行人将股份支付费用计入研发支出的，应具有明确合理的依据，不存在利用股份支付调节研发投入指标的情形。

Sheet 委外研发检查表I2-11
A1: 致同会计师事务所
A2: 委外研发检查表
A3: =底稿目录!A2 -> 被审计单位： | G3: =底稿目录!$A$4 -> 编制人： | M3: =底稿目录!$A$5 -> 编制日期： | U3: 索引号： | V3: =底稿目录!D17 -> I2-11
A4: =底稿目录!A3 -> 截止日：202X年12月31日 | G4: =底稿目录!$A$6 -> 复核人： | M4: =底稿目录!$A$7 -> 复核日期： | U4: 页 次：
A5: 一、审计目标:
A6: 1.利润表中记录的研发费用已发生，且与被审计单位有关，已记录于恰当的账户。
A7: 2.与研发费用有关的金额及其他数据已恰当记录，相关披露已得到恰当计量和描述。
A8: 二、审计过程： | C8: 测试原因：大额（）关联方（）大额交易频繁（）异常（）其他（）
A9: 测试内容说明：1.原始凭证是否齐全； 2.记账凭证与原始凭证是否相符；3.账务处理是否正确；4.是否记录于恰当的会计期间；5.……
A10: 研发项目 | B10: 委外研发原因 | C10: 销售订单/销售合同 | H10: 受托方基本信息 | L10: 记账凭证 | P10: 研发项目验收单据 | S10: …… | U10: 是否异常 | V10: 索引号 | W10: 【检查要素根据实际情况自行增减】
C11: 日期 | D11: 合同号 | E11: 受托方 | F11: 研发内容 | G11: 研发成果知识产权归属 | H11: 资质 | I11: 注册资本 | J11: 参保人数 | K11: …… | L11: 日期 | M11: 编号 | N11: 业务内容 | O11: 金额 | P11: 日期 | Q11: 金额 | R11: …… | S11: …… | T11: ……
A21: 合计 | O21: =SUM(O12:O20) -> 0
A22: 本期发生额 | O22: ='研发项目构成明细表I2-7'!Q21 -> 0
A23: 检查比例 | O23: =O21/O22 -> #DIV/0!
A24: 三、审计说明：
A26: 四、审计结论：

Sheet 针对性检查表I2-12
A1: 致同会计师事务所
A2: 开（研）发支出针对性检查表
A3: =底稿目录!A2 -> 被审计单位： | F3: =底稿目录!A4 -> 编制人： | I3: =底稿目录!A5 -> 编制日期： | P3: 索引号： | Q3: =底稿目录!D18 -> I2-12
A4: =底稿目录!A3 -> 截止日：202X年12月31日 | F4: =底稿目录!A6 -> 复核人： | I4: =底稿目录!A7 -> 复核日期： | P4: 页次：
A5: 一、测试目标：
A6: 1.通过针对性测试，验证开（研）发支出的存在/发生、所有权、计价和分摊。
A7: 2. 检查人工费（研发人员）、材料费、制造费用分摊、委托研发等开发支出费用的真实性。
A8: 二、样本选取标准与规模：
A9: 测试总体： | B9: 如贷方发生额所有凭证共XX笔金额XX | F9: 特定样本： | G9: XX金额以上（大额）、关联方/关联交易形成的款项、XX异常款项全部测试，共XX笔
A10: 抽样总体： | B10: 测试总体扣除特定样本以外的样本，共XX笔、金额XX | F10: 确定的抽样样本量： | H10: 抽取XX笔 | I10: （如果使用了样本计算器计算样本量，样本量计算过程见<XX>底稿）
A11: 抽样方法： | B11: 随机选样/系统选样/货币单元抽样/随意选样（非统计抽样适用） | F11: 抽样过程： | G11: 使用IDEA（XX抽样工具）选择XX数量、金额XX的样本进行测试，抽样工具中的样本选择过程和结果见<XX>底稿
A12: 三、测试：
A13: 测试内容说明：1.原始凭证是否齐全； 2.记账凭证与原始凭证是否相符；3.账务处理是否正确；4.是否记录于恰当的会计期间；5.……
A14: 记账凭证 | I14: 支持性文件 | J14: 核对内容 | O14: 索引号 | P14: 是否异常 | Q14: 备注说明
A15: 开发支出项目明细 | B15: 日期 | C15: 凭证编号 | D15: 业务内容 | E15: 对方科目 | F15: 对方明细科目 | G15: 借方金额 | H15: 贷方金额 | J15: 1 | K15: 2 | L15: 3 | M15: 4 | N15: 5
A29: 四、审计说明：
A33: 五、审计结论：

Sheet 截止性测试（账到单据）I2-13
A1: 致同会计师事务所
A2: 开发支出截止测试
A3: =底稿目录!A2 -> 被审计单位： | D3: =底稿目录!A4 -> 编制人： | F3: =底稿目录!A5 -> 编制日期： | I3: 索引号： | J3: =底稿目录!D19 -> I2-13
A4: =底稿目录!A3 -> 截止日：202X年12月31日 | D4: =底稿目录!A6 -> 复核人： | F4: =底稿目录!A7 -> 复核日期： | I4: 页 次：
A5: 一、审计目标：
A6: 确认开发支出已记录于正确的会计期间。
A7: 二、样本选取标准与规模：
A8: 1.获取资产负债表日前（______）天、后（______）天，且金额大于______元的开发支出记账凭证与支出凭单等核对确认开发支出是否记入了恰当的期间；
A9: 2.对于首次承接的客户，执行前期期末的截止性测试。（适用于首次承接）
A10: 提示：如果存在跨期舞弊风险或者所检查样本中发现有跨期的，应扩大测试期间和样本，甚至可以考虑将截止测试期间延长至审计报告日。同时考虑是否存在内控缺陷。
A11: 三、测试：
A12: 序号 | B12: 记账凭证 | F12: 支出凭单 | I12: 是否跨期 | J12: 跨期金额
B13: 日期 | C13: 编号 | D13: 金额 | E13: 摘要 | F13: 凭单编号 | G13: 凭单日期 | H13: 金额
A14: 1
A15: 2
A16: 3
A17: 4
A18: 5
A19: 6
A20: 7
A21: 8
A22: 9
A23: 10
A24: ——————截止日期：20XX年12月31日——————
A25: 1
A26: 2
A27: 3
A28: 4
A29: 5
A30: 6
A31: 7
A32: 8
A33: 9
A34: 10
A35: 四、审计说明：
A38: 五、审计结论
A41: 提示：如果存在跨期舞弊风险或者所检查样本中发现有跨期的，应扩大测试期间和样本，甚至可以考虑将截止测试期间延长至审计报告日。同时考虑是否存在内控缺陷。

Sheet 截止性测试（单据到账）I2-14
A1: 致同会计师事务所
A2: 开发支出截止测试
A3: =底稿目录!A2 -> 被审计单位： | D3: =底稿目录!A4 -> 编制人： | F3: =底稿目录!A5 -> 编制日期： | I3: 索引号： | J3: =底稿目录!D20 -> I2-14
A4: =底稿目录!A3 -> 截止日：202X年12月31日 | D4: =底稿目录!A6 -> 复核人： | F4: =底稿目录!A7 -> 复核日期： | I4: 页 次：
A5: 一、审计目标：
A6: 确认开发支出已记录于正确的会计期间。
A7: 二、样本选取标准与规模：
A8: 1.抽取资产负债表日前（______）天、后（______）天，且金额大于______元的支出凭单等与开发支出记账凭证核对确认开发支出是否记入了恰当的期间；
A9: 2.对于首次承接的客户，执行前期期末的截止性测试。（适用于首次承接）
A10: 提示：如果存在跨期舞弊风险或者所检查样本中发现有跨期的，应扩大测试期间和样本，甚至可以考虑将截止测试期间延长至审计报告日。同时考虑是否存在内控缺陷。
A11: 三、测试：
A12: 序号 | B12: 支出凭单 | E12: 记账凭证 | I12: 是否跨期 | J12: 跨期金额
B13: 凭单编号 | C13: 凭单日期 | D13: 金额 | E13: 日期 | F13: 凭证号 | G13: 金额 | H13: 摘要
A14: 1
A15: 2
A16: 3
A17: 4
A18: 5
A19: 6
A20: 7
A21: 8
A22: 9
A23: 10
A24: ——————截止日期：20XX年12月31日——————
A25: 1
A26: 2
A27: 3
A28: 4
A29: 5
A30: 6
A31: 7
A32: 8
A33: 9
A34: 10
A35: 四、审计说明：
A38: 五、审计结论
A41: 提示：如果存在跨期舞弊风险或者所检查样本中发现有跨期的，应扩大测试期间和样本，甚至可以考虑将截止测试期间延长至审计报告日。同时考虑是否存在内控缺陷。

Sheet 减值准备测试表I2-15
A1: 致同会计师事务所
A2: 减值准备测试表
A3: =底稿目录!A2 -> 被审计单位： | E3: =底稿目录!$A$4 -> 编制人： | I3: =底稿目录!A5 -> 编制日期： | L3: 索引号： | M3: =底稿目录!D21 -> I2-15
A4: =底稿目录!A3 -> 截止日：202X年12月31日 | E4: =底稿目录!$A$6 -> 复核人： | I4: =底稿目录!A7 -> 复核日期： | L4: 页次：
A5: 一、审计目标:
A6: 检查期末开发支出应计提的减值准备是否合理。
A7: 二、审计过程：
A8: 开发支出项目名称 | B8: 是否存在减值迹象 | C8: 减值迹象描述 ① | D8: 是否进行减值测试 | E8: 账面价值 | F8: 可收回金额 | I8: 期末应计提的减值金额（当⑤＜①） | J8: 期末账面已计提的减值准备 | K8: 本期应补提 或冲回的减值准备 | L8: 工作底稿索引号 | M8: 备注
F9: 公允价值减处置费用的净额 | G9: 预计未来现金流量现值 | H9: 可收回金额（③、④较高者） | J9: 期末已计提 减值准备
E10: ② | F10: ③ | G10: ④ | H10: ⑤ | I10: ⑥＝⑤－① | J10: ⑦ | K10: ⑧=⑥-⑦
H11: =MAX(F11,G11) -> 0 | I11: =IF(H11>E11,0,E11-H11) -> 0 | K11: =I11-J11 -> 0
H12: =MAX(F12,G12) -> 0 | I12: =IF(H12>E12,0,E12-H12) -> 0 | K12: =I12-J12 -> 0
H13: =MAX(F13,G13) -> 0 | I13: =IF(H13>E13,0,E13-H13) -> 0 | K13: =I13-J13 -> 0
H14: =MAX(F14,G14) -> 0 | I14: =IF(H14>E14,0,E14-H14) -> 0 | K14: =I14-J14 -> 0
H15: =MAX(F15,G15) -> 0 | I15: =IF(H15>E15,0,E15-H15) -> 0 | K15: =I15-J15 -> 0
H16: =MAX(F16,G16) -> 0 | I16: =IF(H16>E16,0,E16-H16) -> 0 | K16: =I16-J16 -> 0
H17: =MAX(F17,G17) -> 0 | I17: =IF(H17>E17,0,E17-H17) -> 0 | K17: =I17-J17 -> 0
A18: 合计 | E18: =SUM(E11:E17) -> 0 | F18: =SUM(F11:F17) -> 0 | G18: =SUM(G11:G17) -> 0 | H18: =SUM(H11:H17) -> 0 | I18: =SUM(I11:I17) -> 0 | J18: =SUM(J11:J17) -> 0 | K18: =SUM(K11:K17) -> 0
A19: 三、审计说明：
A21: 四、审计结论：
A23: 提示：
A24: 注册会计师可以考虑实施以下审计程序：
A25: （1）检查被审计单位对于开发支出减值测试的方法及相关会计处理是否符合相关企业会计准则的要求并保持一贯性。
A26: （2）通过询问管理层对相关开发项目商业应用分析，并查阅与相关开发项目相关产品的市场研究报告，了解相关产品的市场状况及后续经营计划，评价管理层对开发支出是否存在减值的判断过程的恰当性。
A27: （3）通过对比历史业绩、管理层预测、可获得的可比公司和外部市场的数据，评价管理层在减值测试中采用的关键假设和判断的合理性。
A28: （4）利用专家的工作，协助评估管理层使用的减值测试模型及使用的关键假设以及参数的合理性，包括折现率等。如果管理层执行减值测试时涉及利用专家的工作，注册会计师需评价与管理层的专家工作相关内控的设计和执行情况,，并按照《中国注册会计师审计准则第1301号——审计证据》的要求，评价管理层的专家的胜任能力、专业素质和客观性。
A29: （5）通过将管理层在上年计算预计未来现金流量现值时采用的估计与本年实际情况进行比较，考虑管理层预测结果的准确性，并就识别出的任何重大差异向管理层询问原因，同时考虑相关因素是否已在本年度的预测中予以考虑。
A30: 同时，《中国注册会计师审计准则第1321号——审计会计估计（包括公允价值会计估计）和相关披露》及其应用指南对于注册会计师如何应对相关会计估计的不确定性导致的财务报表重大错报风险给出了指引。

Sheet 可收回金额测试I2-16
A1: 致同会计师事务所
A2: 减值准备测试表-可收回金额
A3: =底稿目录!A2 -> 被审计单位： | E3: =底稿目录!A4 -> 编制人： | J3: =底稿目录!A5 -> 编制日期： | N3: 索引号： | O3: =底稿目录!D22 -> I2-16
A4: =底稿目录!A3 -> 截止日：202X年12月31日 | E4: =底稿目录!A6 -> 复核人： | J4: =底稿目录!A7 -> 复核日期： | N4: 页次：
A5: 一、审计目标:
A6: 检查开发支出本期应计提的减值准备是否合理。
A7: 二、审计过程：
A8: （一）资产的公允价值减去处置费用后的净额
A9: 项目名称 | B9: 公允价值 | H9: 处置费用（资产处置的直接归属费用） | N9: 公允价值-处置费用 | O9: 备注
B10: 销售协议价格 | C10: 说明 | D10: 资产活跃市场价格 | E10: 说明 | F10: 估计价格 | G10: 说明 | H10: 法律费用 | I10: 相关税费 | J10: 搬运费 | K10: 直接费用 | L10: 其他费用 | M10: 处置费用合计
B11: 1000 | D11: 990 | F11: 990 | H11: 10 | I11: 20 | J11: 10 | K11: 10 | L11: 10 | M11: =SUM(H11:L11) -> 60 | N11: =IF(B11>0,B11,IF(D11>0,D11,F11))-M11 -> 940
M12: =SUM(H12:L12) -> 0 | N12: =IF(B12>0,B12,IF(D12>0,D12,F12))-M12 -> 0
M13: =SUM(H13:L13) -> 0 | N13: =IF(B13>0,B13,IF(D13>0,D13,F13))-M13 -> 0
A14: 合计 | B14: =SUM(B11:B13) -> 1000 | D14: =SUM(D11:D13) -> 990 | F14: =SUM(F11:F13) -> 990 | H14: =SUM(H11:H13) -> 10 | I14: =SUM(I11:I13) -> 20 | J14: =SUM(J11:J13) -> 10 | K14: =SUM(K11:K13) -> 10 | L14: =SUM(L11:L13) -> 10 | M14: =SUM(M11:M13) -> 60 | N14: =SUM(N11:N13) -> 940
A15: （二）资产预计未来现金流量的现值
A16: 预计未来现金流量 | B16: 预算或者预测期 | G16: 以后年度 | I16: 行业的长期平均增长率 | J16: 市场长期平均增长率 | K16: 所在国家或地区的长期平均增长率 | L16: 增长率确定依据 | M16: 预计未来现金流量的现值 | O16: 备注
B17: 第一年 | C17: 第二年 | D17: 第三年 | E17: 第四年 | F17: 第五年 | G17: 基数 | H17: 增长率
A18: 预计未来现金净流量 | B18: 200 | C18: 200 | D18: 200 | E18: 200 | F18: 200 | G18: =F18 -> 200
A19: 折现系数 | B19: =1/(1+$K$23)^1 -> 0.47498417 | C19: =1/(1+$K$23)^2 -> 0.22560996 | D19: =1/(1+$K$23)^3 -> 0.10716116 | E19: =1/(1+$K$23)^4 -> 0.050899854 | F19: =1/(1+$K$23)^5 -> 0.024176625 | G19: =(1+H18)/((K23-H18)*(1+K23)^5) -> 0.0218727 | H19: （企业管理层如能证明递增的增长率是合理的，可以以递增的增长率为基础。）
A20: 现值 | B20: =B18*B19 -> 94.996833 | C20: =C18*C19 -> 45.121992 | D20: =D18*D19 -> 21.432232 | E20: =E18*E19 -> 10.179971 | F20: =F18*F19 -> 4.8353249 | G20: =G18*G19 -> 4.37454 | H20: （建立在预算或者预测基础上的预计现金流量最多涵盖5年。） | N20: =SUM(B20:G20) -> 180.94089
A21: 折现率 | B21: 所得税率适用税率 | C21: 债务总额 | D21: 资本总额 | E21: 债务成本Kd | F21: 无风险报酬率Rf | G21: β系数 | H21: 平均风险股票必要报酬率Rm | I21: 资本成本Ke | J21: 折现率(税后) | K21: 折现率(税前) | L21: 税后折税前调整说明 | N21: 可收回金额 | O21: 备注
L22: 税率调整 | M22: 调整说明
A23: 加权平均资金成本 | B23: 0.25 | C23: 500 | D23: 1000 | E23: 0.1 | F23: 0.04 | G23: 1.1 | H23: 1.1 | I23: =F23+G23*(H23-F23) -> 1.206 | J23: =((C23*E23*(1-B23)+D23*I23))/(C23+D23) -> 0.829 | K23: =J23/(1-(B23+L23)) -> 1.1053333 | N23: =MAX(N14,N20) -> 940
A24: 三、审计说明：
A27: 四、审计结论：
A32: 编制说明：
A33: 1、可收回金额应当根据资产的公允价值减去处置费用后的净额与资产预计未来现金流量的现值两者之间较高者确定。
A35: 2、资产的公允价值减去处置费用后的净额，应当根据公平交易中销售协议价格减去可直接归属于该资产处置费用的金额确定。不存在销售协议但存在资产活跃市场的，
A36: 应当按照该资产的市场价格减去处置费用后的金额确定。资产的市场价格通常应当根据资产的买方出价确定。在不存在销售协议和资产活跃市场的情况下，应当
A37: 以可获取的最佳信息为基础，估计资产的公允价值减去处置费用后的净额，该净额可以参考同行业类似资产的最近交易价格或者结果进行估计。企业按照上述规定
A38: 仍然无法可靠估计资产的公允价值减去处置费用后的净额的，应当以该资产预计未来现金流量的现值作为其可收回金额。
A39: 3、处置费用包括与资产处置有关的法律费用、相关税费、搬运费以及为使资产达到可销售状态所发生的直接费用等。
A41: 4、资产预计未来现金流量的现值，应当按照资产在持续使用过程中和最终处置时所产生的预计未来现金流量，选择恰当的折现率对其进行折现后的金额加以确定。
A42: 5、预计资产的未来现金流量，应当以经企业管理层批准的最近财务预算或者预测数据，以及该预算或者预测期之后年份稳定的或者递减的增长率为基础。
A43: 预计的资产未来现金流量应当包括下列各项：
... A51: 加权平均资金成本（税后）:

Sheet GT_Custom
A1: C1 | B1: Custom 1
A2: C2 | B2: Custom 2
A3: C3 | B3: Custom 3
A4: C4 | B4: Custom 4
A5: C5 | B5: Custom 5
A6: C6 | B6: Custom 6
A7: C7 | B7: Custom 7
A8: C8 | B8: Custom 8
