Workbook

Sheet 底稿目录
A1: 底稿开列时，可先在以下单元格填写有关内容，以便其他底稿引用有关数据： | B1: 目录
A2: 被审计单位：
A3: 截止日：202X年12月31日 | B3: 序号 | C3: 内容 | D3: 索引号 | E3: 备注
A4: 编制人： | B4: 1 | C4: 商誉实质性程序 | D4: I3A
A5: 编制日期： | B5: 2 | C5: 商誉审定表 | D5: I3-1
A6: 复核人： | B6: 3 | C6: 商誉附注披露表（上市公司）
A7: 复核日期： | B7: 4 | C7: 商誉附注披露表（国有企业）
B8: 5 | C8: 商誉明细表 | D8: I3-2
B9: 6 | C9: 调整分录汇总 | D9: I3-3 | E9: 备选
A10: 关于工作底稿与审计程序索引号对应的说明 | B10: 7 | C10: 入账价值测算表 | D10: I3-4
A11: 1.编制的审计工作底稿应与审计程序对应。审计项目组应根据被审计单位实际情况和风险评估情况在实质性程序表中裁剪、修改或增加审计程序，根据实际执行的审计程序完成相应审计工作底稿，编制的工作底稿中应按自然顺序依次编制索引号，并通过唯一的索引号将与实质性程序表中的程序对应关联（即将工作底稿的索引号填入实质性程序表中的底稿索引号列）。 | B11: 8 | C11: 商誉针对性检查表 | D11: I3-5
B12: 9 | C12: 商誉减值准备测试表 | D12: I3-6
B13: 10 | C13: 商誉减值准备测试表-可收回金额 | D13: I3-7
B14: 11 | C14: 复核公司减值测试过程及结论 | D14: I3-8
A15: 2.获取的支持性证据应与审计底稿或程序对应。审计项目组在完成底稿时获取的支持性证据应根据底稿索引号编制下一级按自然顺序排序的索引号（如D1-2-1、D1-2-2、……），并在底稿中说明引用的支持性证据、关联索引号。
A18: 3.工作底稿索引号的编码规则：实质性程序索引号按循环从“D”到“N”,循环内账户以顺序号排列，模板中底稿索引号按账户顺序+自然数顺序（即模板中索引号按二级自然顺序排列，如D1-1、D1-2、D1-3、……D1-N）。

Sheet 商誉实质性程序 I3A
A1: 致同会计师事务所
A2: 商誉实质性程序
A3: =底稿目录!A2 -> 被审计单位： | C3: =底稿目录!A4 -> 编制人： | E3: =底稿目录!A5 -> 编制日期： | H3: 索引号： | I3: I3A
A4: =底稿目录!A3 -> 截止日：202X年12月31日 | C4: =底稿目录!A6 -> 复核人： | E4: =底稿目录!A7 -> 复核日期： | H4: 页 次：
A5: 一、本账户涉及的科目
A6: 商誉
A7: 二、审计目标与认定的对应关系
A8: 审计目标 | G8: 财务报表的认定
A9: A. 资产负债表中记录的商誉是存在的，且已经记录在恰当的账户中 | G9: 存在
A10: B. 所有应记录的商誉均已记录，所有应当包括在财务报表中的相关披露均已包括 | G10: 完整性
A11: C. 记录的商誉由被审计单位拥有或控制 | G11: 权利和义务
A12: D. 商誉以恰当的金额包括在财务报表中，与之相关的计价或分摊调整已恰当记录，相关披露已得到恰当计量和描述 | G12: 准确性、计价和分摊
A13: E. 商誉已被恰当地汇总或分解且表述清楚，相关披露在按照企业会计准则的编制基础下是相关的、可理解的 | G13: 列报
A14: 三、计划实施的实质性程序
A15: 序号 | B15: 审计程序 | C15: 程序分类 | D15: 财务报表的认定 | I15: 底稿索引号
D16: 存在 | E16: 完整性 | F16: 权利和 义务 | G16: 准确性、计价和分摊 | H16: 列报 | J16: 根据被审计单位实际情况和风险评估情况裁剪、修改或增加审计程序
A17: 1 | B17: 获取或编制应付账款的明细表，复核加计是否正确，与总账、明细账合计数核对是否相符，期初余额与上期审定期末余额是否相符，并编制审定表。 | C17: 常规★ | D17: √ | E17: √ | G17: √ | I17: I3-1 /I3-2
A18: 2 | B18: 在使用手工编制、自定义信息报告、系统生成的非固定格式报告等由被审计单位生成的信息时，测试有关信息准确性和完整性，并考虑针对编制和维护由被审计单位生成的信息的相关控制实施控制测试，以评价该信息是否能够为实现审计目的提供基础。 | C18: 常规★ | E18: √ | G18: √ | I18: T1 | J18: 可参见《审计手册》4.2.6，由被审计单位生成的信息可能是由系统生成的、或手工编制的、或二者兼而有之的方式生成的。例如，由被审计单位生成的信息可能包括： • 不涉及自定义的、由系统生成的报告（如，固定格式报告）； • 可能通过人工自定义的、由系统生成的报告，例如，（计算机）查询信息或特别定制的报告； • 手工编制的信息，例如，汇总信息的电子表格或用以支持分配、计算以及调节的电子表格； • 其他系统生成或手工编制的信息，例如，由被审计单位编制的客户发票； • 通过影印、拍摄、扫描或其他方式转换成电子形式的文件记录。
A19: 3 | B19: 对期初余额的审计，取得商誉期初余额明细表复核加计是否正确，与总账、明细账合计数是否相符，结合长期股权投资审计检查期初重要商业形成的支持性文件，以及其他必要追加的审计程序。（适用于首次承接） | C19: 备选 | D19: √ | E19: √ | F19: √ | G19: √ | J19: 由被审计单位生成的信息不包括： • 总分类账或明细分类账、试算平衡表、或经审计的财务报表； • 第三方（除了服务机构）的报表或报告，例如，原始银行对账单，或函证的回函； • 外部数据（例如，第三方发布的数据，如，定价来源）。
A20: 4 | B20: 关注会计政策、会计估计合理性、一贯性，关注其是否利用会计政策和会计估计及其变更操纵利润： （1）对于商誉，检查企业制定的商誉分摊、减值政策是否与会计准则一致； （2）将被审计单位本期的会计政策、会计估计与前期进行对比，分析其是否前后一致。对于存在会计政策、会计估计变更的情形，判断是否合理，会计处理是否正确； （3）与同行业其他公司的会计政策、会计估计进行对比，关注其是否利用会计政策和会计估计变更操纵利润； | C20: 常规★ | D20: √ | E20: √ | G20: √ | I20: I3-1 /I3-2
A21: 5 | B21: 对于本期新增的商誉，根据具体情况，结合长期股权投资的审计，检查的支持性文件包括但不限于： （1）获取有关合并协议和合并双方的董事会决议等文件、资料，判断合并是否属于非同一控制，了解企业合并的目的。如果合并属于非同一控制，则应判断购买日确定是否正确； （2）索取企业合并的相关审计报告、资产评估报告，分析其公允价值的合理性； （3）确定是否满足资产确认条件， | C21: 常规★ | D21: √ | E21: √ | F21: √ | G21: √ | I21: I3-1 /I3-2
A22: 6 | B22: 对于本期减少的商誉，根据具体情况，结合长期股权投资的审计，检查的支持性文件包括但不限于： （1）检查与资产处置相关的合同、发票及其他文件； （2）重新计算相关的利得或损失； （3）确定会计处理是否恰当，确定所采取的计价方法是否适当，会计处理是否正确。 | C22: 常规★ | D22: √ | E22: √ | G22: √ | I22: I3-1 /I3-2
A23: 7 | B23: 复核商誉减值测试： （1）获取开发支出的减值明细表； （2）记录对开发支出可能造成减值的事件或环境变化； （3）复核用于减值测试的资产分组的合理性； （4）关注并复核公司确定的减值测试方法与模型是否恰当；关注并复核公司进行减值测试所依据的基础数据是否准确、所选取的关键参数是否恰当，评价所采用的关键假设、所作出的重大估计和判断、所选取的价值类型是否合理，分析减值测试方法与价值类型是否匹配； （5）取得相关的资产现金流分析。确定相关资产的预测的未来现金流量是合理的；如果现金流量预测表明，资产的账面价值无法收回，获得企业对资产组的公允价值的分析；评价每个评估专家的资质和工作（是否第三方或客户员工），并对完成“专家资质”和“专家工作”的审计程序。确定是否需要在审计项目组中增加一个估值专家，以帮助对公允价值/可收回金额的计算进行评价。 （6）比预期所估计减值准备和已记录的金额，调查所有重大差异； （7）确定潜在减值是否恰当。 （8）确定上期确认的长期资产减值准备在本期的变动是否适当。 | C23: 常规★ | G23: √ | I23: I3-5 /I3-6 /I3-7 /I3-8
A24: 8 | B24: 根据评估的舞弊风险等因素增加的审计程序。 | C24: IPO/上市/新三板/重组/舞弊应对
A25: 9 | B25: 检查商誉是否已按企业会计准则或其他适用的规定在财务报表中做出恰当列报和披露。 | C25: 常规★ | H25: √ | I25: A1-1/A1-15 /A1-16

Sheet 审定表I3-1
A1: 致同会计师事务所
A2: 商誉审定表
A3: =底稿目录!A2 -> 被审计单位： | E3: =底稿目录!A4 -> 编制人： | I3: =底稿目录!A5 -> 编制日期： | L3: 索引号： | M3: I3-1
A4: =底稿目录!A3 -> 截止日：202X年12月31日 | E4: =底稿目录!A6 -> 复核人： | I4: =底稿目录!A7 -> 复核日期： | L4: 页次：
A5: 项目类别 | B5: 索引号 | C5: 未审数 | G5: 账项调整 | J5: 审定数
C6: 期初数 | D6: 本期增加 | E6: 本期减少 | F6: 期末数 | G6: 期初数 | H6: 本期增加 | I6: 本期减少 | J6: 期初数 | K6: 本期增加 | L6: 本期减少 | M6: 期末数
A7: 原始金额：
A8: ='明细表I3-2'!A14 -> 0 | C8: ='明细表I3-2'!D14 -> 0 | D8: ='明细表I3-2'!E14 -> 0 | E8: ='明细表I3-2'!G14 -> 0 | F8: =C8+D8-E8 -> 0 | G8: ='明细表I3-2'!J14 -> 0 | H8: ='明细表I3-2'!K14 -> 0 | I8: ='明细表I3-2'!L14 -> 0 | J8: =C8+G8 -> 0 | K8: =D8+H8 -> 0 | L8: =E8+I8 -> 0 | M8: =J8+K8-L8 -> 0
A9: ='明细表I3-2'!A15 -> 0 | C9: ='明细表I3-2'!D15 -> 0 | D9: ='明细表I3-2'!E15 -> 0 | E9: ='明细表I3-2'!G15 -> 0 | F9: =C9+D9-E9 -> 0 | G9: ='明细表I3-2'!J15 -> 0 | H9: ='明细表I3-2'!K15 -> 0 | I9: ='明细表I3-2'!L15 -> 0 | J9: =C9+G9 -> 0 | K9: =D9+H9 -> 0 | L9: =E9+I9 -> 0 | M9: =J9+K9-L9 -> 0
A10: ='明细表I3-2'!A16 -> 0 | C10: ='明细表I3-2'!D16 -> 0 | D10: ='明细表I3-2'!E16 -> 0 | E10: ='明细表I3-2'!G16 -> 0 | F10: =C10+D10-E10 -> 0 | G10: ='明细表I3-2'!J16 -> 0 | H10: ='明细表I3-2'!K16 -> 0 | I10: ='明细表I3-2'!L16 -> 0 | J10: =C10+G10 -> 0 | K10: =D10+H10 -> 0 | L10: =E10+I10 -> 0 | M10: =J10+K10-L10 -> 0
A11: ='明细表I3-2'!A17 -> 0 | C11: ='明细表I3-2'!D17 -> 0 | D11: ='明细表I3-2'!E17 -> 0 | E11: ='明细表I3-2'!G17 -> 0 | F11: =C11+D11-E11 -> 0 | G11: ='明细表I3-2'!J17 -> 0 | H11: ='明细表I3-2'!K17 -> 0 | I11: ='明细表I3-2'!L17 -> 0 | J11: =C11+G11 -> 0 | K11: =D11+H11 -> 0 | L11: =E11+I11 -> 0 | M11: =J11+K11-L11 -> 0
A12: ='明细表I3-2'!A18 -> 0 | C12: ='明细表I3-2'!D18 -> 0 | D12: ='明细表I3-2'!E18 -> 0 | E12: ='明细表I3-2'!G18 -> 0 | F12: =C12+D12-E12 -> 0 | G12: ='明细表I3-2'!J18 -> 0 | H12: ='明细表I3-2'!K18 -> 0 | I12: ='明细表I3-2'!L18 -> 0 | J12: =C12+G12 -> 0 | K12: =D12+H12 -> 0 | L12: =E12+I12 -> 0 | M12: =J12+K12-L12 -> 0
A13: ='明细表I3-2'!A19 -> 0 | C13: ='明细表I3-2'!D19 -> 0 | D13: ='明细表I3-2'!E19 -> 0 | E13: ='明细表I3-2'!G19 -> 0 | F13: =C13+D13-E13 -> 0 | G13: ='明细表I3-2'!J19 -> 0 | H13: ='明细表I3-2'!K19 -> 0 | I13: ='明细表I3-2'!L19 -> 0 | J13: =C13+G13 -> 0 | K13: =D13+H13 -> 0 | L13: =E13+I13 -> 0 | M13: =J13+K13-L13 -> 0
A14: ='明细表I3-2'!A20 -> 0 | C14: ='明细表I3-2'!D20 -> 0 | D14: ='明细表I3-2'!E20 -> 0 | E14: ='明细表I3-2'!G20 -> 0 | F14: =C14+D14-E14 -> 0 | G14: ='明细表I3-2'!J20 -> 0 | H14: ='明细表I3-2'!K20 -> 0 | I14: ='明细表I3-2'!L20 -> 0 | J14: =C14+G14 -> 0 | K14: =D14+H14 -> 0 | L14: =E14+I14 -> 0 | M14: =J14+K14-L14 -> 0
A15: ='明细表I3-2'!A21 -> 0 | C15: ='明细表I3-2'!D21 -> 0 | D15: ='明细表I3-2'!E21 -> 0 | E15: ='明细表I3-2'!G21 -> 0 | F15: =C15+D15-E15 -> 0 | G15: ='明细表I3-2'!J21 -> 0 | H15: ='明细表I3-2'!K21 -> 0 | I15: ='明细表I3-2'!L21 -> 0 | J15: =C15+G15 -> 0 | K15: =D15+H15 -> 0 | L15: =E15+I15 -> 0 | M15: =J15+K15-L15 -> 0
A16: ='明细表I3-2'!A22 -> 0 | C16: ='明细表I3-2'!D22 -> 0 | D16: ='明细表I3-2'!E22 -> 0 | E16: ='明细表I3-2'!G22 -> 0 | F16: =C16+D16-E16 -> 0 | G16: ='明细表I3-2'!J22 -> 0 | H16: ='明细表I3-2'!K22 -> 0 | I16: ='明细表I3-2'!L22 -> 0 | J16: =C16+G16 -> 0 | K16: =D16+H16 -> 0 | L16: =E16+I16 -> 0 | M16: =J16+K16-L16 -> 0
A17: 合计 | C17: =SUM(C8:C16) -> 0 | D17: =SUM(D8:D16) -> 0 | E17: =SUM(E8:E16) -> 0 | F17: =SUM(F8:F16) -> 0 | G17: =SUM(G8:G16) -> 0 | H17: =SUM(H8:H16) -> 0 | I17: =SUM(I8:I16) -> 0 | J17: =SUM(J8:J16) -> 0 | ... M17: =SUM(M8:M16) -> 0
A18: 减值准备：
A19: =A8 -> 0 | C19: ='明细表I3-2'!R14 -> 0 | D19: ='明细表I3-2'!S14+'明细表I3-2'!T14 -> 0 | E19: ='明细表I3-2'!U14+'明细表I3-2'!V14 -> 0 | F19: =C19+D19-E19 -> 0 | G19: ='明细表I3-2'!X14 -> 0 | H19: ='明细表I3-2'!Y14 -> 0 | I19: ='明细表I3-2'!Z14 -> 0 | J19: =C19+G19 -> 0 | K19: =D19+H19 -> 0 | L19: =E19+I19 -> 0 | M19: =J19+K19-L19 -> 0
A20: =A9 -> 0 | C20: ='明细表I3-2'!R15 -> 0 | D20: ='明细表I3-2'!S15+'明细表I3-2'!T15 -> 0 | E20: ='明细表I3-2'!U15+'明细表I3-2'!V15 -> 0 | F20: =C20+D20-E20 -> 0 | G20: ='明细表I3-2'!X15 -> 0 | H20: ='明细表I3-2'!Y15 -> 0 | I20: ='明细表I3-2'!Z15 -> 0 | J20: =C20+G20 -> 0 | K20: =D20+H20 -> 0 | L20: =E20+I20 -> 0 | M20: =J20+K20-L20 -> 0
A21: =A10 -> 0 | C21: ='明细表I3-2'!R16 -> 0 | D21: ='明细表I3-2'!S16+'明细表I3-2'!T16 -> 0 | E21: ='明细表I3-2'!U16+'明细表I3-2'!V16 -> 0 | F21: =C21+D21-E21 -> 0 | G21: ='明细表I3-2'!X16 -> 0 | H21: ='明细表I3-2'!Y16 -> 0 | I21: ='明细表I3-2'!Z16 -> 0 | J21: =C21+G21 -> 0 | K21: =D21+H21 -> 0 | L21: =E21+I21 -> 0 | M21: =J21+K21-L21 -> 0
A22: =A11 -> 0 | C22: ='明细表I3-2'!R17 -> 0 | D22: ='明细表I3-2'!S17+'明细表I3-2'!T17 -> 0 | E22: ='明细表I3-2'!U17+'明细表I3-2'!V17 -> 0 | F22: =C22+D22-E22 -> 0 | G22: ='明细表I3-2'!X17 -> 0 | H22: ='明细表I3-2'!Y17 -> 0 | I22: ='明细表I3-2'!Z17 -> 0 | J22: =C22+G22 -> 0 | K22: =D22+H22 -> 0 | L22: =E22+I22 -> 0 | M22: =J22+K22-L22 -> 0
A23: =A12 -> 0 | C23: ='明细表I3-2'!R18 -> 0 | D23: ='明细表I3-2'!S18+'明细表I3-2'!T18 -> 0 | E23: ='明细表I3-2'!U18+'明细表I3-2'!V18 -> 0 | F23: =C23+D23-E23 -> 0 | G23: ='明细表I3-2'!X18 -> 0 | H23: ='明细表I3-2'!Y18 -> 0 | I23: ='明细表I3-2'!Z18 -> 0 | J23: =C23+G23 -> 0 | K23: =D23+H23 -> 0 | L23: =E23+I23 -> 0 | M23: =J23+K23-L23 -> 0
A24: =A13 -> 0 | C24: ='明细表I3-2'!R19 -> 0 | D24: ='明细表I3-2'!S19+'明细表I3-2'!T19 -> 0 | E24: ='明细表I3-2'!U19+'明细表I3-2'!V19 -> 0 | F24: =C24+D24-E24 -> 0 | G24: ='明细表I3-2'!X19 -> 0 | H24: ='明细表I3-2'!Y19 -> 0 | I24: ='明细表I3-2'!Z19 -> 0 | J24: =C24+G24 -> 0 | K24: =D24+H24 -> 0 | L24: =E24+I24 -> 0 | M24: =J24+K24-L24 -> 0
A25: =A14 -> 0 | C25: ='明细表I3-2'!R20 -> 0 | D25: ='明细表I3-2'!S20+'明细表I3-2'!T20 -> 0 | E25: ='明细表I3-2'!U20+'明细表I3-2'!V20 -> 0 | F25: =C25+D25-E25 -> 0 | G25: ='明细表I3-2'!X20 -> 0 | H25: ='明细表I3-2'!Y20 -> 0 | I25: ='明细表I3-2'!Z20 -> 0 | J25: =C25+G25 -> 0 | K25: =D25+H25 -> 0 | L25: =E25+I25 -> 0 | M25: =J25+K25-L25 -> 0
A26: =A15 -> 0 | C26: ='明细表I3-2'!R21 -> 0 | D26: ='明细表I3-2'!S21+'明细表I3-2'!T21 -> 0 | E26: ='明细表I3-2'!U21+'明细表I3-2'!V21 -> 0 | F26: =C26+D26-E26 -> 0 | G26: ='明细表I3-2'!X21 -> 0 | H26: ='明细表I3-2'!Y21 -> 0 | I26: ='明细表I3-2'!Z21 -> 0 | J26: =C26+G26 -> 0 | K26: =D26+H26 -> 0 | L26: =E26+I26 -> 0 | M26: =J26+K26-L26 -> 0
A27: =A16 -> 0 | C27: ='明细表I3-2'!R22 -> 0 | D27: ='明细表I3-2'!S22+'明细表I3-2'!T22 -> 0 | E27: ='明细表I3-2'!U22+'明细表I3-2'!V22 -> 0 | F27: =C27+D27-E27 -> 0 | G27: ='明细表I3-2'!X22 -> 0 | H27: ='明细表I3-2'!Y22 -> 0 | I27: ='明细表I3-2'!Z22 -> 0 | J27: =C27+G27 -> 0 | K27: =D27+H27 -> 0 | L27: =E27+I27 -> 0 | M27: =J27+K27-L27 -> 0
A28: 合计 | C28: =SUM(C19:C27) -> 0 | D28: =SUM(D19:D27) -> 0 | E28: =SUM(E19:E27) -> 0 | F28: =SUM(F19:F27) -> 0 | G28: =SUM(G19:G27) -> 0 | H28: =SUM(H19:H27) -> 0 | I28: =SUM(I19:I27) -> 0 | J28: =SUM(J19:J27) -> 0 | ... M28: =SUM(M19:M27) -> 0
A29: 净值:
A30: =A8 -> 0 | C30: =C8-C19 -> 0 | D30: =D8-D19 -> 0 | E30: =E8-E19 -> 0 | F30: =F8-F19 -> 0 | G30: =G8-G19 -> 0 | H30: =H8-H19 -> 0 | I30: =I8-I19 -> 0 | J30: =J8-J19 -> 0 | ... M30: =M8-M19 -> 0
A31: =A9 -> 0 | C31: =C9-C20 -> 0 | D31: =D9-D20 -> 0 | E31: =E9-E20 -> 0 | F31: =F9-F20 -> 0 | G31: =G9-G20 -> 0 | H31: =H9-H20 -> 0 | I31: =I9-I20 -> 0 | J31: =J9-J20 -> 0 | ... M31: =M9-M20 -> 0
A32: =A10 -> 0 | C32: =C10-C21 -> 0 | D32: =D10-D21 -> 0 | E32: =E10-E21 -> 0 | F32: =F10-F21 -> 0 | G32: =G10-G21 -> 0 | H32: =H10-H21 -> 0 | I32: =I10-I21 -> 0 | J32: =J10-J21 -> 0 | ... M32: =M10-M21 -> 0
A33: =A11 -> 0 | C33: =C11-C22 -> 0 | D33: =D11-D22 -> 0 | E33: =E11-E22 -> 0 | F33: =F11-F22 -> 0 | G33: =G11-G22 -> 0 | H33: =H11-H22 -> 0 | I33: =I11-I22 -> 0 | J33: =J11-J22 -> 0 | ... M33: =M11-M22 -> 0
A34: =A12 -> 0 | C34: =C12-C23 -> 0 | D34: =D12-D23 -> 0 | E34: =E12-E23 -> 0 | F34: =F12-F23 -> 0 | G34: =G12-G23 -> 0 | H34: =H12-H23 -> 0 | I34: =I12-I23 -> 0 | J34: =J12-J23 -> 0 | ... M34: =M12-M23 -> 0
A35: =A13 -> 0 | C35: =C13-C24 -> 0 | D35: =D13-D24 -> 0 | E35: =E13-E24 -> 0 | F35: =F13-F24 -> 0 | G35: =G13-G24 -> 0 | H35: =H13-H24 -> 0 | I35: =I13-I24 -> 0 | J35: =J13-J24 -> 0 | ... M35: =M13-M24 -> 0
A36: =A14 -> 0 | C36: =C14-C25 -> 0 | D36: =D14-D25 -> 0 | E36: =E14-E25 -> 0 | F36: =F14-F25 -> 0 | G36: =G14-G25 -> 0 | H36: =H14-H25 -> 0 | I36: =I14-I25 -> 0 | J36: =J14-J25 -> 0 | ... M36: =M14-M25 -> 0
A37: =A15 -> 0 | C37: =C15-C26 -> 0 | D37: =D15-D26 -> 0 | E37: =E15-E26 -> 0 | F37: =F15-F26 -> 0 | G37: =G15-G26 -> 0 | H37: =H15-H26 -> 0 | I37: =I15-I26 -> 0 | J37: =J15-J26 -> 0 | ... M37: =M15-M26 -> 0
A38: =A16 -> 0 | C38: =C16-C27 -> 0 | D38: =D16-D27 -> 0 | E38: =E16-E27 -> 0 | F38: =F16-F27 -> 0 | G38: =G16-G27 -> 0 | H38: =H16-H27 -> 0 | I38: =I16-I27 -> 0 | J38: =J16-J27 -> 0 | ... M38: =M16-M27 -> 0
A39: 合计 | C39: =SUM(C30:C38) -> 0 | D39: =SUM(D30:D38) -> 0 | E39: =SUM(E30:E38) -> 0 | F39: =SUM(F30:F38) -> 0 | G39: =SUM(G30:G38) -> 0 | H39: =SUM(H30:H38) -> 0 | I39: =SUM(I30:I38) -> 0 | J39: =SUM(J30:J38) -> 0 | ... M39: =SUM(M30:M38) -> 0
A40: TB数据：
...

Sheet 附注披露（上市公司）
A1: 致同会计师事务所
A2: 商誉附注披露（上市公司）
A3: =底稿目录!A2 -> 被审计单位： | C3: =底稿目录!A4 -> 编制人： | E3: =底稿目录!A5 -> 编制日期： | G3: 索引号：
A4: =底稿目录!A3 -> 截止日：202X年12月31日 | C4: =底稿目录!A6 -> 复核人： | E4: =底稿目录!A7 -> 复核日期： | G4: 页次：
A5: 商誉
A6: （1）商誉账面原值
A7: 被投资单位名称或形成商誉的事项 | B7: 期初余额 | C7: 本期增加 | F7: 本期减少 | H7: 期末余额
C8: 企业合并形成 | D8: 取得构成业务的共同经营的利益份额形成 | E8: 其他 | F8: 处置 | G8: 其他
A9: ='明细表I3-2'!A14 -> 0 | B9: ='明细表I3-2'!M14 -> 0 | C9: =IF('明细表I3-2'!F14="企业合并形成",'明细表I3-2'!N14,0) -> 0 | D9: =IF('明细表I3-2'!F14="取得构成业务的共同经营的利益份额形成",'明细表I3-2'!N14,0) -> 0 | E9: =IF('明细表I3-2'!F14="其他",'明细表I3-2'!N14,0) -> 0 | F9: =IF('明细表I3-2'!H14="处置",'明细表I3-2'!O14,0) -> 0 | G9: =IF('明细表I3-2'!H14="其他减少",'明细表I3-2'!O14,0) -> 0 | H9: =B9+C9+D9+E9-F9-G9 -> 0
A10: ='明细表I3-2'!A15 -> 0 | B10: ='明细表I3-2'!M15 -> 0 | C10: =IF('明细表I3-2'!F15="企业合并形成",'明细表I3-2'!N15,0) -> 0 | D10: =IF('明细表I3-2'!F15="取得构成业务的共同经营的利益份额形成",'明细表I3-2'!N15,0) -> 0 | E10: =IF('明细表I3-2'!F15="其他",'明细表I3-2'!N15,0) -> 0 | F10: =IF('明细表I3-2'!H15="处置",'明细表I3-2'!O15,0) -> 0 | G10: =IF('明细表I3-2'!H15="其他减少",'明细表I3-2'!O15,0) -> 0 | H10: =B10+C10+D10+E10-F10-G10 -> 0
A11: ='明细表I3-2'!A16 -> 0 | B11: ='明细表I3-2'!M16 -> 0 | C11: =IF('明细表I3-2'!F16="企业合并形成",'明细表I3-2'!N16,0) -> 0 | D11: =IF('明细表I3-2'!F16="取得构成业务的共同经营的利益份额形成",'明细表I3-2'!N16,0) -> 0 | E11: =IF('明细表I3-2'!F16="其他",'明细表I3-2'!N16,0) -> 0 | F11: =IF('明细表I3-2'!H16="处置",'明细表I3-2'!O16,0) -> 0 | G11: =IF('明细表I3-2'!H16="其他减少",'明细表I3-2'!O16,0) -> 0 | H11: =B11+C11+D11+E11-F11-G11 -> 0
A12: ='明细表I3-2'!A17 -> 0 | B12: ='明细表I3-2'!M17 -> 0 | C12: =IF('明细表I3-2'!F17="企业合并形成",'明细表I3-2'!N17,0) -> 0 | D12: =IF('明细表I3-2'!F17="取得构成业务的共同经营的利益份额形成",'明细表I3-2'!N17,0) -> 0 | E12: =IF('明细表I3-2'!F17="其他",'明细表I3-2'!N17,0) -> 0 | F12: =IF('明细表I3-2'!H17="处置",'明细表I3-2'!O17,0) -> 0 | G12: =IF('明细表I3-2'!H17="其他减少",'明细表I3-2'!O17,0) -> 0 | H12: =B12+C12+D12+E12-F12-G12 -> 0
A13: ='明细表I3-2'!A18 -> 0 | B13: ='明细表I3-2'!M18 -> 0 | C13: =IF('明细表I3-2'!F18="企业合并形成",'明细表I3-2'!N18,0) -> 0 | D13: =IF('明细表I3-2'!F18="取得构成业务的共同经营的利益份额形成",'明细表I3-2'!N18,0) -> 0 | E13: =IF('明细表I3-2'!F18="其他",'明细表I3-2'!N18,0) -> 0 | F13: =IF('明细表I3-2'!H18="处置",'明细表I3-2'!O18,0) -> 0 | G13: =IF('明细表I3-2'!H18="其他减少",'明细表I3-2'!O18,0) -> 0 | H13: =B13+C13+D13+E13-F13-G13 -> 0
A14: ='明细表I3-2'!A19 -> 0 | B14: ='明细表I3-2'!M19 -> 0 | C14: =IF('明细表I3-2'!F19="企业合并形成",'明细表I3-2'!N19,0) -> 0 | D14: =IF('明细表I3-2'!F19="取得构成业务的共同经营的利益份额形成",'明细表I3-2'!N19,0) -> 0 | E14: =IF('明细表I3-2'!F19="其他",'明细表I3-2'!N19,0) -> 0 | F14: =IF('明细表I3-2'!H19="处置",'明细表I3-2'!O19,0) -> 0 | G14: =IF('明细表I3-2'!H19="其他减少",'明细表I3-2'!O19,0) -> 0 | H14: =B14+C14+D14+E14-F14-G14 -> 0
A15: ='明细表I3-2'!A20 -> 0 | B15: ='明细表I3-2'!M20 -> 0 | C15: =IF('明细表I3-2'!F20="企业合并形成",'明细表I3-2'!N20,0) -> 0 | D15: =IF('明细表I3-2'!F20="取得构成业务的共同经营的利益份额形成",'明细表I3-2'!N20,0) -> 0 | E15: =IF('明细表I3-2'!F20="其他",'明细表I3-2'!N20,0) -> 0 | F15: =IF('明细表I3-2'!H20="处置",'明细表I3-2'!O20,0) -> 0 | G15: =IF('明细表I3-2'!H20="其他减少",'明细表I3-2'!O20,0) -> 0 | H15: =B15+C15+D15+E15-F15-G15 -> 0
A16: ='明细表I3-2'!A21 -> 0 | B16: ='明细表I3-2'!M21 -> 0 | C16: =IF('明细表I3-2'!F21="企业合并形成",'明细表I3-2'!N21,0) -> 0 | D16: =IF('明细表I3-2'!F21="取得构成业务的共同经营的利益份额形成",'明细表I3-2'!N21,0) -> 0 | E16: =IF('明细表I3-2'!F21="其他",'明细表I3-2'!N21,0) -> 0 | F16: =IF('明细表I3-2'!H21="处置",'明细表I3-2'!O21,0) -> 0 | G16: =IF('明细表I3-2'!H21="其他减少",'明细表I3-2'!O21,0) -> 0 | H16: =B16+C16+D16+E16-F16-G16 -> 0
A17: ='明细表I3-2'!A22 -> 0 | B17: ='明细表I3-2'!M22 -> 0 | C17: =IF('明细表I3-2'!F22="企业合并形成",'明细表I3-2'!N22,0) -> 0 | D17: =IF('明细表I3-2'!F22="取得构成业务的共同经营的利益份额形成",'明细表I3-2'!N22,0) -> 0 | E17: =IF('明细表I3-2'!F22="其他",'明细表I3-2'!N22,0) -> 0 | F17: =IF('明细表I3-2'!H22="处置",'明细表I3-2'!O22,0) -> 0 | G17: =IF('明细表I3-2'!H22="其他减少",'明细表I3-2'!O22,0) -> 0 | H17: =B17+C17+D17+E17-F17-G17 -> 0
A18: 合 计 | B18: =SUM(B9:B17) -> 0 | C18: =SUM(C9:C17) -> 0 | D18: =SUM(D9:D17) -> 0 | E18: =SUM(E9:E17) -> 0 | F18: =SUM(F9:F17) -> 0 | G18: =SUM(G9:G17) -> 0 | H18: =SUM(H9:H17) -> 0
A19: （提示：其他增减变动原因包括境外子公司汇率变化的影响等）
A20: （2）商誉减值准备
A21: 被投资单位名称或形成商誉的事项 | B21: 期初余额 | C21: 本期增加 | E21: 本期减少 | G21: 期末余额
C22: 计提 | D22: 其他增加 | E22: 处置 | F22: 其他减少
A23: =A9 -> 0 | B23: ='明细表I3-2'!AA14 -> 0 | G23: =B23+C23+D23-E23-F23 -> 0
A24: =A10 -> 0 | B24: ='明细表I3-2'!AA15 -> 0 | G24: =B24+C24+D24-E24-F24 -> 0
A25: =A11 -> 0 | B25: ='明细表I3-2'!AA16 -> 0 | G25: =B25+C25+D25-E25-F25 -> 0
A26: =A12 -> 0 | B26: ='明细表I3-2'!AA17 -> 0 | G26: =B26+C26+D26-E26-F26 -> 0
A27: =A13 -> 0 | B27: ='明细表I3-2'!AA18 -> 0 | G27: =B27+C27+D27-E27-F27 -> 0
A28: =A14 -> 0 | B28: ='明细表I3-2'!AA19 -> 0 | G28: =B28+C28+D28-E28-F28 -> 0
A29: =A15 -> 0 | B29: ='明细表I3-2'!AA20 -> 0 | G29: =B29+C29+D29-E29-F29 -> 0
A30: =A16 -> 0 | B30: ='明细表I3-2'!AA21 -> 0 | G30: =B30+C30+D30-E30-F30 -> 0
A31: =A17 -> 0 | B31: ='明细表I3-2'!AA22 -> 0 | G31: =B31+C31+D31-E31-F31 -> 0
A32: 合 计 | B32: =SUM(B23:B31) -> 0 | C32: =SUM(C23:C31) -> 0 | D32: =SUM(D23:D31) -> 0 | E32: =SUM(E23:E31) -> 0 | F32: =SUM(F23:F31) -> 0 | G32: =SUM(G23:G31) -> 0
A33: （公司应披露商誉减值测试过程、参数及商誉减值损失的确认方法，包括但不限于以下内容： 1.商誉所属资产组或资产组组合的构成,所属经营分部和依据，以及是否与以前年度保持一致。资产组或资产组组合发生变化的，应披露变化前后的构成，以及导致变化的客观事实及依据。 2.可收回金额的具体确定方法。可收回金额按公允价值减去处置费用后的净额确定的，应披露公允价值和处置费用的确定方式、关键参数及其确定依据；若可收回金额按预计未来现金流量的现值确定的，应披露预测期的年限及预测期内的收入增长率、利润率等参数及其确定依据，以及稳定期增长率、利润率、折现率等参数及其确定依据。前述信息与以前年度减值测试采用的信息或外部信息明显不一致的，或公司以前年度减值测试采用信息与当年实际情况明显不一致的，应披露差异原因。 3.形成商誉时存在业绩承诺，且报告期或报告期上一期间处于业绩承诺期内的，应披露业绩承诺完成情况，以及报告期或报告期上一期间商誉减值情况。（15号文第十九条（二十））
A34: 说明：商誉所在资产组或资产组组合的相关信息
A35: 【提示：会计监管风险提示第8号要求，应充分披露商誉所在资产组或资产组组合的相关信息，包括该资产组或资产组组合的构成、账面金额、确定方法，并明确说明该资产组或资产组组合是否与购买日、以前年度商誉减值测试时所确定的资产组或资产组组合一致。如果资产组或资产组组合的构成发生变化，应在披露前后会计期间资产组或资产组组合构成的同时，充分披露导致其变化的主要事实与依据。】
A36: 说明：（商誉减值测试过程、参数及商誉减值损失的确认方法）
A37: 本公司采用预计未来现金流现值的方法计算资产组的可收回金额。本公司根据管理层批准的财务预算预计未来5年内现金流量，其后年度采用的现金流量增长率预计为XX%（上期：XX%），不会超过资产组经营业务的长期平均增长率。管理层根据过往表现及其对市场发展的预期编制上述财务预算。计算未来现金流现值所采用的税前折现率为XX%（上期：XX%），已反映了相对于有关分部的风险。根据减值测试的结果，本期期末商誉未发生减值（上期期末：无）。【或：本期期末对商誉计提减值准备XX元（上期期末：XX元）。】
A38: 【提示：会计监管风险提示第8号要求，详细披露商誉减值测试的过程与方法，包括但不限于可收回金额的确定方法、重要假设及其合理理由、关键参数（如预计未来现金流量现值时的预测期增长率、稳定期增长率、利润率、折现率、预测期等）及其确定依据等信息。如果前述信息与形成商誉时或以前年度商誉减值测试时的信息、公司历史经验或外部信息明显不一致，还应披露存在的差异及其原因。】
A39: 说明：（商誉减值测试的影响）
A40: 【提示：会计监管风险提示第8号要求，形成商誉时的并购重组相关方有业绩承诺的，应充分披露业绩承诺的完成情况及其对商誉减值测试的影响。】
...

Sheet 附注披露（国有企业）
A1: 致同会计师事务所
A2: 商誉附注披露（国有企业）
A3: =底稿目录!A2 -> 被审计单位： | C3: =底稿目录!A4 -> 编制人： | E3: =底稿目录!A5 -> 编制日期： | F3: 索引号：
A4: =底稿目录!A3 -> 截止日：202X年12月31日 | C4: =底稿目录!A6 -> 复核人： | E4: =底稿目录!A7 -> 复核日期： | F4: 页次：
A5: 商誉
A6: （1）商誉账面价值
A7: 被投资单位名称或形成商誉的事项 | B7: 期初余额 | C7: 本期增加 | D7: 本期减少 | E7: 期末余额
A8: ='明细表I3-2'!B14 -> 0 | B8: ='明细表I3-2'!M14 -> 0 | C8: ='明细表I3-2'!N14 -> 0 | D8: ='明细表I3-2'!O14 -> 0 | E8: =B8+C8-D8 -> 0
A9: ='明细表I3-2'!B15 -> 0 | B9: ='明细表I3-2'!M15 -> 0 | C9: ='明细表I3-2'!N15 -> 0 | D9: ='明细表I3-2'!O15 -> 0 | E9: =B9+C9-D9 -> 0
A10: ='明细表I3-2'!B16 -> 0 | B10: ='明细表I3-2'!M16 -> 0 | C10: ='明细表I3-2'!N16 -> 0 | D10: ='明细表I3-2'!O16 -> 0 | E10: =B10+C10-D10 -> 0
A11: ='明细表I3-2'!B17 -> 0 | B11: ='明细表I3-2'!M17 -> 0 | C11: ='明细表I3-2'!N17 -> 0 | D11: ='明细表I3-2'!O17 -> 0 | E11: =B11+C11-D11 -> 0
A12: ='明细表I3-2'!B18 -> 0 | B12: ='明细表I3-2'!M18 -> 0 | C12: ='明细表I3-2'!N18 -> 0 | D12: ='明细表I3-2'!O18 -> 0 | E12: =B12+C12-D12 -> 0
A13: ='明细表I3-2'!B19 -> 0 | B13: ='明细表I3-2'!M19 -> 0 | C13: ='明细表I3-2'!N19 -> 0 | D13: ='明细表I3-2'!O19 -> 0 | E13: =B13+C13-D13 -> 0
A14: ='明细表I3-2'!B20 -> 0 | B14: ='明细表I3-2'!M20 -> 0 | C14: ='明细表I3-2'!N20 -> 0 | D14: ='明细表I3-2'!O20 -> 0 | E14: =B14+C14-D14 -> 0
A15: ='明细表I3-2'!B21 -> 0 | B15: ='明细表I3-2'!M21 -> 0 | C15: ='明细表I3-2'!N21 -> 0 | D15: ='明细表I3-2'!O21 -> 0 | E15: =B15+C15-D15 -> 0
A16: ='明细表I3-2'!B22 -> 0 | B16: ='明细表I3-2'!M22 -> 0 | C16: ='明细表I3-2'!N22 -> 0 | D16: ='明细表I3-2'!O22 -> 0 | E16: =B16+C16-D16 -> 0
A17: 合 计 | B17: =SUM(B8:B16) -> 0 | C17: =SUM(C8:C16) -> 0 | D17: =SUM(D8:D16) -> 0 | E17: =SUM(E8:E16) -> 0
A18: （2）商誉减值准备
A19: 被投资单位名称或形成商誉的事项 | B19: 期初余额 | C19: 本期增加 | D19: 本期减少 | E19: 期末余额
A20: =A8 -> 0 | B20: ='明细表I3-2'!AA14 -> 0 | C20: ='明细表I3-2'!AB14 -> 0 | D20: ='明细表I3-2'!AC14 -> 0 | E20: =B20+C20-D20 -> 0
A21: =A9 -> 0 | B21: ='明细表I3-2'!AA15 -> 0 | C21: ='明细表I3-2'!AB15 -> 0 | D21: ='明细表I3-2'!AC15 -> 0 | E21: =B21+C21-D21 -> 0
A22: =A10 -> 0 | B22: ='明细表I3-2'!AA16 -> 0 | C22: ='明细表I3-2'!AB16 -> 0 | D22: ='明细表I3-2'!AC16 -> 0 | E22: =B22+C22-D22 -> 0
A23: =A11 -> 0 | B23: ='明细表I3-2'!AA17 -> 0 | C23: ='明细表I3-2'!AB17 -> 0 | D23: ='明细表I3-2'!AC17 -> 0 | E23: =B23+C23-D23 -> 0
A24: =A12 -> 0 | B24: ='明细表I3-2'!AA18 -> 0 | C24: ='明细表I3-2'!AB18 -> 0 | D24: ='明细表I3-2'!AC18 -> 0 | E24: =B24+C24-D24 -> 0
A25: =A13 -> 0 | B25: ='明细表I3-2'!AA19 -> 0 | C25: ='明细表I3-2'!AB19 -> 0 | D25: ='明细表I3-2'!AC19 -> 0 | E25: =B25+C25-D25 -> 0
A26: =A14 -> 0 | B26: ='明细表I3-2'!AA20 -> 0 | C26: ='明细表I3-2'!AB20 -> 0 | D26: ='明细表I3-2'!AC20 -> 0 | E26: =B26+C26-D26 -> 0
A27: =A15 -> 0 | B27: ='明细表I3-2'!AA21 -> 0 | C27: ='明细表I3-2'!AB21 -> 0 | D27: ='明细表I3-2'!AC21 -> 0 | E27: =B27+C27-D27 -> 0
A28: =A16 -> 0 | B28: ='明细表I3-2'!AA22 -> 0 | C28: ='明细表I3-2'!AB22 -> 0 | D28: ='明细表I3-2'!AC22 -> 0 | E28: =B28+C28-D28 -> 0
A29: 合 计 | B29: =SUM(B20:B28) -> 0 | C29: =SUM(C20:C28) -> 0 | D29: =SUM(D20:D28) -> 0 | E29: =SUM(E20:E28) -> 0
A30: 说明：（商誉的减值测试方法和减值准备计提方法，详细说明减值原因、减值金额确认依据。）
A31: 本公司采用预计未来现金流现值的方法计算资产组的可收回金额。本公司根据管理层批准的财务预算预计未来5年内现金流量，其后年度采用的现金流量增长率预计为XX%（上期：XX%），不会超过资产组经营业务的长期平均增长率。管理层根据过往表现及其对市场发展的预期编制上述财务预算。计算未来现金流现值所采用的税前折现率为XX%（上期：XX%），已反映了相对于有关分部的风险。根据减值测试的结果，本期期末商誉未发生减值（上期期末：无）。【或：本期期末对商誉计提减值准备XX元（上期期末：XX元）。】

Sheet 明细表I3-2
A1: 致同会计师事务所 | Q1: 致同会计师事务所
A2: 商誉明细表（原值） | Q2: 商誉明细表（减值准备）
A3: =底稿目录!A2 -> 被审计单位： | F3: =底稿目录!A4 -> 编制人： | L3: =底稿目录!A5 -> 编制日期： | O3: 索引号： | P3: I3-2 | Q3: =底稿目录!A2 -> 被审计单位： | W3: =底稿目录!A4 -> 编制人： | Z3: =底稿目录!A5 -> 编制日期： | AC3: 索引号： | AD3: I3-2
A4: =底稿目录!A3 -> 截止日：202X年12月31日 | F4: =底稿目录!A6 -> 复核人： | L4: =底稿目录!A7 -> 复核日期： | O4: 页次： | Q4: =底稿目录!A3 -> 截止日：202X年12月31日 | W4: =底稿目录!A6 -> 复核人： | Z4: =底稿目录!A7 -> 复核日期： | AC4: 页次：
A5: 一、审计目标: | Q5: 一、审计目标:
A6: 1. 资产负债表中记录的商誉是存在的，且已经记录在恰当的账户中； | Q6: 1. 资产负债表中记录的商誉是存在的，且已经记录在恰当的账户中；
A7: 2. 所有应记录的商誉均已记录，所有应当包括在财务报表中的相关披露均已包括； | Q7: 2. 所有应记录的商誉均已记录，所有应当包括在财务报表中的相关披露均已包括；
A8: 3. 商誉以恰当的金额包括在财务报表中，与之相关的计价或分摊调整已恰当记录，相关披露已得到恰当计量和描述 | Q8: 3. 商誉以恰当的金额包括在财务报表中，与之相关的计价或分摊调整已恰当记录，相关披露已得到恰当计量和描述
A9: 二、审计过程： | Q9: 二、审计过程：
A10: 被投资单位名称或形成商誉的事项 | C10: 商誉原值 | Q10: 被投资单位名称或形成商誉的事项 | R10: 减值准备
C11: 发生日期 | D11: 未审数 | J11: 期初调整 | K11: 账项调整 | M11: 审定数 | R11: 未审数 | X11: 期初调整 | Y11: 账项调整 | AA11: 审定数
D12: 期初数 | E12: 本期增加 | G12: 本期减少 | I12: 期末数 | J12: 账项调整 | K12: 本期增加 | L12: 本期减少 | M12: 期初数 | N12: 本期增加 | O12: 本期减少 | P12: 期末数 | R12: 期初数 | S12: 本期增加 | U12: 本期减少 | W12: 期末数 | X12: 账项调整 | Y12: 本期增加 | Z12: 本期减少 | AA12: 期初数 | AB12: 本期增加 | AC12: 本期减少 | AD12: 期末数
E13: 金额 | F13: 增加方式 | G13: 金额 | H13: 减少方式 | S13: 本期计提 | T13: 其他增加 | U13: 处置 | V13: 其他减少
M14: =D14+J14 -> 0 | N14: =E14+K14 -> 0 | O14: =G14+L14 -> 0 | P14: =M14+N14-O14 -> 0 | Q14: =A14 -> 0 | W14: =R14+S14+T14-U14-V14 -> 0 | AA14: =R14+X14 -> 0 | AB14: =S14+Y14+T14 -> 0 | AC14: =U14+Z14+V14 -> 0 | AD14: =AA14+AB14-AC14 -> 0
I15: =SUM(D15:E15)-G15 -> 0 | M15: =D15+J15 -> 0 | N15: =E15+K15 -> 0 | O15: =G15+L15 -> 0 | P15: =M15+N15-O15 -> 0 | Q15: =A15 -> 0 | W15: =R15+S15+T15-U15-V15 -> 0 | AA15: =R15+X15 -> 0 | AB15: =S15+Y15+T15 -> 0 | AC15: =U15+Z15+V15 -> 0 | AD15: =AA15+AB15-AC15 -> 0
I16: =SUM(D16:E16)-G16 -> 0 | M16: =D16+J16 -> 0 | N16: =E16+K16 -> 0 | O16: =G16+L16 -> 0 | P16: =M16+N16-O16 -> 0 | Q16: =A16 -> 0 | W16: =R16+S16+T16-U16-V16 -> 0 | AA16: =R16+X16 -> 0 | AB16: =S16+Y16+T16 -> 0 | AC16: =U16+Z16+V16 -> 0 | AD16: =AA16+AB16-AC16 -> 0
I17: =SUM(D17:E17)-G17 -> 0 | M17: =D17+J17 -> 0 | N17: =E17+K17 -> 0 | O17: =G17+L17 -> 0 | P17: =M17+N17-O17 -> 0 | Q17: =A17 -> 0 | W17: =R17+S17+T17-U17-V17 -> 0 | AA17: =R17+X17 -> 0 | AB17: =S17+Y17+T17 -> 0 | AC17: =U17+Z17+V17 -> 0 | AD17: =AA17+AB17-AC17 -> 0
I18: =SUM(D18:E18)-G18 -> 0 | M18: =D18+J18 -> 0 | N18: =E18+K18 -> 0 | O18: =G18+L18 -> 0 | P18: =M18+N18-O18 -> 0 | Q18: =A18 -> 0 | W18: =R18+S18+T18-U18-V18 -> 0 | AA18: =R18+X18 -> 0 | AB18: =S18+Y18+T18 -> 0 | AC18: =U18+Z18+V18 -> 0 | AD18: =AA18+AB18-AC18 -> 0
I19: =SUM(D19:E19)-G19 -> 0 | M19: =D19+J19 -> 0 | N19: =E19+K19 -> 0 | O19: =G19+L19 -> 0 | P19: =M19+N19-O19 -> 0 | Q19: =A19 -> 0 | W19: =R19+S19+T19-U19-V19 -> 0 | AA19: =R19+X19 -> 0 | AB19: =S19+Y19+T19 -> 0 | AC19: =U19+Z19+V19 -> 0 | AD19: =AA19+AB19-AC19 -> 0
I20: =SUM(D20:E20)-G20 -> 0 | M20: =D20+J20 -> 0 | N20: =E20+K20 -> 0 | O20: =G20+L20 -> 0 | P20: =M20+N20-O20 -> 0 | Q20: =A20 -> 0 | W20: =R20+S20+T20-U20-V20 -> 0 | AA20: =R20+X20 -> 0 | AB20: =S20+Y20+T20 -> 0 | AC20: =U20+Z20+V20 -> 0 | AD20: =AA20+AB20-AC20 -> 0
I21: =SUM(D21:E21)-G21 -> 0 | M21: =D21+J21 -> 0 | N21: =E21+K21 -> 0 | O21: =G21+L21 -> 0 | P21: =M21+N21-O21 -> 0 | Q21: =A21 -> 0 | W21: =R21+S21+T21-U21-V21 -> 0 | AA21: =R21+X21 -> 0 | AB21: =S21+Y21+T21 -> 0 | AC21: =U21+Z21+V21 -> 0 | AD21: =AA21+AB21-AC21 -> 0
I22: =SUM(D22:E22)-G22 -> 0 | M22: =D22+J22 -> 0 | N22: =E22+K22 -> 0 | O22: =G22+L22 -> 0 | P22: =M22+N22-O22 -> 0 | Q22: =A22 -> 0 | W22: =R22+S22+T22-U22-V22 -> 0 | AA22: =R22+X22 -> 0 | AB22: =S22+Y22+T22 -> 0 | AC22: =U22+Z22+V22 -> 0 | AD22: =AA22+AB22-AC22 -> 0
A23: 合计 | E23: =SUM(E14:E22) -> 0 | G23: =SUM(G14:G22) -> 0 | I23: =SUM(D23:E23)-G23 -> 0 | J23: =SUM(J14:J22) -> 0 | K23: =SUM(K14:K22) -> 0 | L23: =SUM(L14:L22) -> 0 | M23: =D23+J23 -> 0 | N23: =E23+K23 -> 0 | O23: =G23+L23 -> 0 | P23: =M23+N23-O23 -> 0 | Q23: 合计 | R23: =SUM(R14:R22) -> 0 | S23: =SUM(S14:S22) -> 0 | T23: =SUM(T14:T22) -> 0 | U23: =SUM(U14:U22) -> 0 | V23: =SUM(V14:V22) -> 0 | W23: =SUM(W14:W22) -> 0 | X23: =SUM(X14:X22) -> 0 | Y23: =SUM(Y14:Y22) -> 0 | Z23: =SUM(Z14:Z22) -> 0 | AA23: =SUM(AA27:AA30) -> 0 | AB23: =SUM(AB27:AB30) -> 0 | AC23: =SUM(AC27:AC30) -> 0 | AD23: =SUM(AD27:AD30) -> 0
A24: 三、审计说明：
A26: 四、审计结论：
B27: 编制说明：
B28: 1、在“备注”中注明非同一控制下企业合并情况。
B29: 2、对于通过非同一控制下企业合并形成的商誉，应列示商誉的计算过程。

Sheet 调整分录汇总I3-3
A1: 致同会计师事务所
A2: 商誉调整分录汇总表
A3: =底稿目录!A2 -> 被审计单位： | D3: =底稿目录!A4 -> 编制人： | F3: =底稿目录!A5 -> 编制日期： | I3: 索引号： | J3: I3-3
A4: =底稿目录!A3 -> 截止日：202X年12月31日 | D4: =底稿目录!A6 -> 复核人： | F4: =底稿目录!A7 -> 复核日期： | I4: 页次：
A5: 调整事项说明 | B5: 类别（报表调整/账项调整/其他） | C5: 报表项目 | D5: 科目名称 | E5: 附注项目 | F5: …… | G5: 借方调整金额 | H5: 贷方调整金额 | I5: 索引 | J5: 备注
A23: 【注：本底稿适用于调整分录较多、较复杂的项目，且仅列示与本报表项目相关的审计调整。项目组可根据项目实际情况选择是否使用该底稿。】

Sheet 入账价值测算表I3-4
A1: 致同会计师事务所
A2: 商誉入账价值测算表
A3: =底稿目录!A2 -> 被审计单位： | E3: =底稿目录!A4 -> 编制人： | I3: =底稿目录!A5 -> 编制日期： | L3: 索引号： | M3: I3-4
A4: =底稿目录!A3 -> 截止日：202X年12月31日 | E4: =底稿目录!A6 -> 复核人： | I4: =底稿目录!A7 -> 复核日期： | L4: 页次：
A5: 一、审计目标：
A6: 确定商誉是否存在，计价是否准确。
A7: 二、审计过程：
A8: 项目名称 | C8: 入账金额 | D8: 是否属于同一控制 | E8: 购买日的确定 | G8: 商誉的确定 | M8: 备注
E9: 具体日期 | F9: 是否符合规定 | G9: 合并成本 ① | H9: 被购买方可辨认净资产公允价值② | I9: 股权比例③ | J9: 应占份额 ④=②*③ | K9: 商誉(⑤>0) ⑤=①-④ | L9: 商誉的确定是否符合规定
A10: AAA公司 | C10: 1000 | D10: 否 | E10: 40553 | F10: 是 | G10: 1000 | H10: 1200 | I10: 0.7 | J10: =H10*I10 -> 840 | K10: =G10-J10 -> 160 | L10: 是
J11: =H11*I11 -> 0 | K11: =G11-J11 -> 0
J12: =H12*I12 -> 0 | K12: =G12-J12 -> 0
J13: =H13*I13 -> 0 | K13: =G13-J13 -> 0
J14: =H14*I14 -> 0 | K14: =G14-J14 -> 0
J15: =H15*I15 -> 0 | K15: =G15-J15 -> 0
J16: =H16*I16 -> 0 | K16: =G16-J16 -> 0
J17: =H17*I17 -> 0 | K17: =G17-J17 -> 0
A18: 合计 | C18: =SUM(C10:C17) -> 1000 | G18: =SUM(G10:G17) -> 1000 | H18: =SUM(H10:H17) -> 1200 | J18: =SUM(J10:J17) -> 840 | K18: =SUM(K10:K17) -> 160
A19: 三、审计说明：
A22: 四、审计结论

Sheet 针对性检查表I3-5
A1: 致同会计师事务所
A2: 商誉针对性检查表
A3: =底稿目录!A2 -> 被审计单位： | G3: =底稿目录!A4 -> 编制人： | I3: =底稿目录!A5 -> 编制日期： | O3: 索引号： | P3: I3-5
A4: =底稿目录!A3 -> 截止日：202X年12月31日 | G4: =底稿目录!A6 -> 复核人： | I4: =底稿目录!A7 -> 复核日期： | O4: 页次：
A5: 一、测试目标：
A6: 通过针对性测试，验证商誉的存在/发生计价和分摊。
A7: 二、测试： | C7: 测试原因：大额（）关联方（）大额交易频繁（）异常（）其他（）
A8: 测试内容说明：1.原始凭证是否齐全； 2.记账凭证与原始凭证是否相符；3.账务处理是否正确；4.是否记录于恰当的会计期间；5.……
A9: 记账凭证 | I9: 支持性文件 | J9: 核对内容 | O9: 索引号 | P9: 是否异常 | Q9: 备注说明
A10: 商誉项目明细 | B10: 日期 | C10: 凭证编号 | D10: 业务内容 | E10: 对方科目 | F10: 对方明细科目 | G10: 借方金额 | H10: 贷方金额 | J10: 1 | K10: 2 | L10: 3 | M10: 4 | N10: 5
A20: 合计 | G20: =SUM(G11:G19) -> 0 | H20: =SUM(H11:H19) -> 0
A21: 本期发生额 | G21: ='明细表I3-2'!N23 -> 0 | H21: ='明细表I3-2'!O23 -> 0
A22: 检查比例 | G22: =G20/G21 -> #DIV/0! | H22: =H20/H21 -> #DIV/0!
A23: 合计
A24: 四、审计说明：
A27: 五、审计结论：

Sheet 商誉减值测试I3-6
A1: 致同会计师事务所
A2: 商誉减值准备测试表
A3: =底稿目录!A2 -> 被审计单位： | E3: =底稿目录!A4 -> 编制人： | H3: =底稿目录!A5 -> 编制日期： | K3: 索引号： | L3: I3-6
A4: =底稿目录!A3 -> 截止日：202X年12月31日 | E4: =底稿目录!A6 -> 复核人： | H4: =底稿目录!A7 -> 复核日期： | K4: 页 次：
A5: 一、审计目标
B6: 确定商誉是否发生减值，减值金额计量是否恰当。
A7: 二、审计过程：
A8: （一）内外部环境变化可能对商誉减值产生的影响
A10: （二）商誉减值测试
B11: 项目名称 | C11: 账面价值：（1） | G11: 可收回金额（2） | I11: （3）=（1）-（2） | J11: 计提的减值准备[（3）>0] | K11: 导致资产减值的原因 | L11: 备注
C12: 对应资产组的账面价值(A) | D12: 应分配的商誉账面价值(B1) | E12: 未确认的归属于少数股东权益的商誉价值(B2) | F12: 合计 | G12: ① | H12: ②
F13: (A+B1+B2)
F14: =SUM(C14:E14) -> 0 | G14: ='可收回金额测试I3-7'!N8 -> 0 | H14: ='可收回金额测试I3-7'!N20 -> 0 | I14: =E14-MAX(G14,H14) -> 0 | J14: =IF(F14>0,IF(I14>0,I14,"未减值"),) -> 0
F15: =SUM(C15:E15) -> 0 | G15: ='可收回金额测试I3-7'!N9 -> 0 | I15: =E15-MAX(G15,H15) -> 0 | J15: =IF(F15>0,IF(I15>0,I15,"未减值"),) -> 0
F16: =SUM(C16:E16) -> 0 | G16: ='可收回金额测试I3-7'!N10 -> 0 | I16: =E16-MAX(G16,H16) -> 0 | J16: =IF(F16>0,IF(I16>0,I16,"未减值"),) -> 0
B17: 合 计 | C17: =SUM(C14:C16) -> 0 | D17: =SUM(D14:D16) -> 0 | E17: =SUM(E14:E16) -> 0 | F17: =SUM(F14:F16) -> 0 | G17: =SUM(G14:G16) -> 0 | H17: =SUM(H14:H16) -> 0 | I17: =SUM(I14:I16) -> 0 | J17: =SUM(J14:J16) -> 0
B18: 其中：(A)资产组的账面价值应是其在合并报表层面的账面价值，即资产组在购买日公允价值基础上持续计算的在本期资产负债表日的金额。
B19: ①为资产的公允价值减去处置费用后的净额；②资产预计未来现金流量的现值。
B20: 商誉的分摊 | C20: 账面价值 | D20: 未确认的少数股东权益 | E20: 调整后的名义账面价值 | F20: 可收回金额 | G20: 减值损失 | H20: 减值损失第一分配 | I20: 减值损失第二分配 | J20: 减值损失调整后 | K20: 合并报表确认减值损失 | L20: 备注
B21: 流动资产 | E21: =SUM(C21:D21) -> 0 | H21: =($G$26-$H$25)/SUM($E$21:$E$24)*E21 -> #DIV/0! | I21: 0 | J21: =E21-I21 -> 0 | K21: =I21 -> 0
B22: 固定资产 | E22: =SUM(C22:D22) -> 0 | H22: =($G$26-$H$25)/SUM($E$21:$E$24)*E22 -> #DIV/0! | I22: =H22+$H$21/SUM($E$22:$E$24)*C22 -> #DIV/0! | J22: =E22-I22 -> #DIV/0! | K22: =I22 -> #DIV/0!
B23: 无形资产 | E23: =SUM(C23:D23) -> 0 | H23: =($G$26-$H$25)/SUM($E$21:$E$24)*E23 -> #DIV/0! | I23: =H23+$H$21/SUM($E$22:$E$24)*C23 -> #DIV/0! | J23: =E23-I23 -> #DIV/0! | K23: =I23 -> #DIV/0!
B24: …… | E24: =SUM(C24:D24) -> 0 | H24: =($G$26-$H$25)/SUM($E$21:$E$24)*E24 -> #DIV/0! | I24: =H24+$H$21/SUM($E$22:$E$24)*C24 -> #DIV/0! | J24: =E24-I24 -> #DIV/0! | K24: =I24 -> #DIV/0!
B25: 商誉 | E25: =SUM(C25:D25) -> 0 | H25: =E25 -> 0 | I25: =H25 -> 0 | J25: =E25-I25 -> 0 | K25: =I25-D25 -> 0
B26: 合 计 | C26: =SUM(C21:C25) -> 0 | D26: =SUM(D21:D25) -> 0 | E26: =SUM(E21:E25) -> 0 | F26: ='可收回金额测试I3-7'!N23 -> 0 | G26: =E26-F26 -> 0 | H26: =SUM(H21:H25) -> #DIV/0! | I26: =SUM(I21:I25) -> #DIV/0! | J26: =SUM(J21:J25) -> #DIV/0! | K26: =SUM(K21:K25) -> #DIV/0!
B27: 审计说明：
A29: （三）商誉的可收回金额测试
B30: 见“K3-5-3商誉减值准备测试表-可收回金额”
A31: （四）利用专家的工作（如适用）
B32: 序号 | C32: 项目 | F32: 索引号
B33: 1 | C33: 利用专家（注册会计师的专家）的工作 | F33: S12
B34: 2 | C34: 利用管理层的专家编制的信息形成审计证据 | F34: S13
A35: 三、审计说明：
B36: 若认为商誉减值事项存在特别风险，还应当了解被审计单位与该风险相关的控制（包括控制活动）。详见B23-8、C9，B21、C25。
A37: 四、审计结论：
B41: 编制说明：
B42: 1、无论是否存在减值迹象，年末必须对“商誉”进行减值测试。
B43: 2、导致商誉发生减值的原因：
B44: （1）被审计单位经营所处的经济、技术或者法律等环境发生重大变化，从而对企业产生不利影响；
B45: （2）监管当局采取的不利行动和评价；
...

Sheet 可收回金额测试I3-7
A1: 致同会计师事务所
A2: 商誉减值准备测试表-可收回金额
A3: ='商誉减值测试I3-6'!A3 -> 被审计单位： | E3: ='商誉减值测试I3-6'!E3 -> 编制人： | J3: ='商誉减值测试I3-6'!H3 -> 编制日期： | N3: 索引号： | O3: I3-7
A4: ='商誉减值测试I3-6'!A4 -> 截止日：202X年12月31日 | E4: =底稿目录!A6 -> 复核人： | J4: =底稿目录!A7 -> 复核日期： | N4: 页 次：
A5: （一）资产的公允价值减去处置费用后的净额
A6: 项目名称 | B6: 公允价值 | H6: 处置费用（资产处置的直接归属费用） | N6: 公允价值-处置费用 | O6: 备注
B7: 销售协议价格 | C7: 说明 | D7: 资产活跃市场价格 | E7: 说明 | F7: 估计价格 | G7: 说明 | H7: 法律费用 | I7: 相关税费 | J7: 搬运费 | K7: 直接费用 | L7: 其他费用 | M7: 处置费用合计
M8: =SUM(H8:L8) -> 0 | N8: =IF(B8>0,B8,IF(D8>0,D8,F8))-M8 -> 0
M9: =SUM(H9:L9) -> 0 | N9: =IF(B9>0,B9,IF(D9>0,D9,F9))-M9 -> 0
M10: =SUM(H10:L10) -> 0 | N10: =IF(B10>0,B10,IF(D10>0,D10,F10))-M10 -> 0
A11: 合 计 | B11: =SUM(B8:B10) -> 0 | D11: =SUM(D8:D10) -> 0 | F11: =SUM(F8:F10) -> 0 | H11: =SUM(H8:H10) -> 0 | I11: =SUM(I8:I10) -> 0 | J11: =SUM(J8:J10) -> 0 | K11: =SUM(K8:K10) -> 0 | L11: =SUM(L8:L10) -> 0 | M11: =SUM(M8:M10) -> 0 | N11: =SUM(N8:N10) -> 0
A12: 审计说明：
A14: （二）资产预计未来现金流量的现值
A15: 1、项目名称： | B15: =A8 -> 0
A16: 预计未来现金流量 | B16: 预算或者预测期 | G16: 以后年度 | I16: 行业的长期平均增长率 | J16: 市场长期平均增长率 | K16: 所在国家或地区的长期平均增长率 | L16: 增长率确定依据 | N16: 预计未来现金流量的现值 | O16: 备注
B17: 第一年 | C17: 第二年 | D17: 第三年 | E17: 第四年 | F17: 第五年 | G17: 基数 | H17: 增长率
A18: 现金净流量（税前） | G18: =F18 -> 0
A19: 折现系数 | B19: =1/(1+$K$23)^1 -> 0.85748783 | C19: =1/(1+$K$23)^2 -> 0.73528538 | D19: =1/(1+$K$23)^3 -> 0.63049826 | E19: =1/(1+$K$23)^4 -> 0.54064458 | F19: =1/(1+$K$23)^5 -> 0.46359615 | G19: =(1+H18)/((J23-H18)*(1+K23)^5) -> 3.2816851 | H19: （企业管理层如能证明递增的增长率是合理的，可以以递增的增长率为基础。）
A20: 现值 | B20: =B18*B19 -> 0 | C20: =C18*C19 -> 0 | D20: =D18*D19 -> 0 | E20: =E18*E19 -> 0 | F20: =F18*F19 -> 0 | G20: =G18*G19 -> 0 | H20: （建立在预算或者预测基础上的预计现金流量最多涵盖5年。） | N20: =SUM(B20:G20) -> 0
A21: 折现率 | B21: 所得税率 | C21: 债务总额 D | D21: 资本总额 E | E21: 债务成本Kd | F21: 无风险报酬率Rf | G21: β系数 | H21: 市场平均收益率Rm | I21: 资本成本Ke | J21: WACC (税后) | K21: 折现率 (税前) | L21: 税后折税前调整说明 | N21: 可收回金额 | O21: 备注
B22: 适用税率 | L22: 税率调整 | M22: 调整说明
A23: 加权平均资金成本 | B23: 0.15 | C23: 300 | D23: 1100 | E23: 0.07 | F23: 0.0377 | G23: 1.02 | H23: 0.1611 | I23: =F23+G23*(H23-F23) -> 0.163568 | J23: =((C23*E23*(1-B23)+D23*I23))/(C23+D23) -> 0.14126771 | K23: =J23/(1-(B23+L23)) -> 0.16619731 | N23: =MAX(N11,N20) -> 0
A24: 2、项目名称： | B24: =A9 -> 0
A25: 预计未来现金流量 | B25: 预算或者预测期 | G25: 以后年度 | I25: 行业的长期平均增长率 | J25: 市场长期平均增长率 | K25: 所在国家或地区的长期平均增长率 | L25: 增长率确定依据 | N25: 预计未来现金流量的现值 | O25: 备注
B26: 第一年 | C26: 第二年 | D26: 第三年 | E26: 第四年 | F26: 第五年 | G26: 基数 | H26: 增长率
A27: 现金净流量（税前） | G27: =F27 -> 0
A28: 折现系数 | B28: =1/(1+$K$32)^1 -> 0.85748783 | C28: =1/(1+$K$32)^1 -> 0.85748783 | D28: =1/(1+$K$32)^1 -> 0.85748783 | E28: =1/(1+$K$32)^1 -> 0.85748783 | F28: =1/(1+$K$32)^1 -> 0.85748783 | G28: =(1+H27)/((J32-H27)*(1+K32)^5) -> 3.2816851 | H28: （企业管理层如能证明递增的增长率是合理的，可以以递增的增长率为基础。）
A29: 现值 | B29: =B27*B28 -> 0 | C29: =C27*C28 -> 0 | D29: =D27*D28 -> 0 | E29: =E27*E28 -> 0 | F29: =F27*F28 -> 0 | G29: =G27*G28 -> 0 | H29: （建立在预算或者预测基础上的预计现金流量最多涵盖5年。） | N29: =SUM(B29:G29) -> 0
A30: 折现率 | B30: 所得税率 | C30: 债务总额 D | D30: 资本总额 E | E30: 债务成本Kd | F30: 无风险报酬率Rf | G30: β系数 | H30: 市场平均收益率Rm | I30: 资本成本Ke | J30: WACC (税后) | K30: 折现率 (税前) | L30: 税后折税前调整说明 | N30: 可收回金额 | O30: 备注
B31: 适用税率 | L31: 税率调整 | M31: 调整说明
A32: 加权平均资金成本 | B32: 0.15 | C32: 300 | D32: 1100 | E32: 0.07 | F32: 0.0377 | G32: 1.02 | H32: 0.1611 | I32: =F32+G32*(H32-F32) -> 0.163568 | J32: =((C32*E32*(1-B32)+D32*I32))/(C32+D32) -> 0.14126771 | K32: =J32/(1-(B32+L32)) -> 0.16619731 | N32: =MAX(N10,N29) -> 0
A33: 3、项目名称： | B33: =M10 -> 0
A34: 预计未来现金流量 | B34: 预算或者预测期 | G34: 以后年度 | I34: 行业的长期平均增长率 | J34: 市场长期平均增长率 | K34: 所在国家或地区的长期平均增长率 | L34: 增长率确定依据 | N34: 预计未来现金流量的现值 | O34: 备注
B35: 第一年 | C35: 第二年 | D35: 第三年 | E35: 第四年 | F35: 第五年 | G35: 基数 | H35: 增长率
A36: 现金净流量（税前） | G36: =F36 -> 0
A37: 折现系数 | B37: =1/(1+$K$41)^1 -> 0.85748783 | C37: =1/(1+$K$41)^1 -> 0.85748783 | D37: =1/(1+$K$41)^1 -> 0.85748783 | E37: =1/(1+$K$41)^1 -> 0.85748783 | F37: =1/(1+$K$41)^1 -> 0.85748783 | G37: =(1+H36)/((J41-H36)*(1+K41)^5) -> 3.2816851 | H37: （企业管理层如能证明递增的增长率是合理的，可以以递增的增长率为基础。）
A38: 现值 | B38: =B36*B37 -> 0 | C38: =C36*C37 -> 0 | D38: =D36*D37 -> 0 | E38: =E36*E37 -> 0 | F38: =F36*F37 -> 0 | G38: =G36*G37 -> 0 | H38: （建立在预算或者预测基础上的预计现金流量最多涵盖5年。） | N38: =SUM(B38:G38) -> 0
A39: 折现率 | B39: 所得税率 | C39: 债务总额 D | D39: 资本总额 E | E39: 债务成本Kd | F39: 无风险报酬率Rf | G39: β系数 | H39: 市场平均收益率Rm | I39: 资本成本Ke | J39: WACC (税后) | K39: 折现率 (税前) | L39: 税后折税前调整说明 | N39: 可收回金额 | O39: 备注
B40: 适用税率 | L40: 税率调整 | M40: 调整说明
A41: 加权平均资金成本 | B41: 0.15 | C41: 300 | D41: 1100 | E41: 0.07 | F41: 0.0377 | G41: 1.02 | H41: 0.1611 | I41: =F41+G41*(H41-F41) -> 0.163568 | J41: =((C41*E41*(1-B41)+D41*I41))/(C41+D41) -> 0.14126771 | K41: =J41/(1-(B41+L41)) -> 0.16619731 | N41: =MAX(N10,N38) -> 0
...

Sheet 复核公司减值测试过程及结论I3-8
A1: 致同会计师事务所
A2: 复核被审计单位减值测试过程及结论
A3: =底稿目录!A2 -> 被审计单位： | E3: =底稿目录!A4 -> 编制人： | H3: =底稿目录!A5 -> 编制日期： | J3: 索引号： | K3: I3-8
A4: =底稿目录!A3 -> 截止日：202X年12月31日 | E4: =底稿目录!A6 -> 复核人： | H4: =底稿目录!A7 -> 复核日期： | J4: 页 次：
A5: 一、关注并复核公司商誉减值测试工作过程（适用于管理层和注册会计师均未利用专家的工作）
B6: 若管理层利用了专家的工作，则该底稿被S13-3-1或S13-3-2替代。
B7: 若项目组利用专家（注册会计师的专家）的工作，则该底稿被S12-3-1或S12-3-2替代。
B8: 1、公司对商誉减值迹象的判断是否合理
B9: 当存在减值迹象时，应随时进行减值测试。
B11: 2、公司对商誉所在资产组或资产组组合的划分是否合理，是否将商誉账面价值在资产组或资产组组合之间恰当分摊
B12: 因企业合并形成的商誉的账面价值，应当自购买日起按照合理的方法分摊至相关的资产组（购买方预计受益于企业合并的协同效应的资产组，可以包括购买方原有业务中的资产组）。 商誉的分摊，详见《会计提示第73号—商誉减值测试》附录2
B14: 3、公司确定的减值测试方法与模型是否恰当
B15: 将原收购的标的公司“全部资产和全部负债组成的资产组（股东权益）”界定为评估对象采用股东权益价值方法，不符合会计准则的要求。商誉减值测试的范围不是原标的公司的股权，而是被分摊商誉的资产组或资产组组合。
B17: 5、评价计算使用价值（预计未来现金流量的现值）选用的参数和具体处理
B18: （1）盈利预测是否有可靠的数据来源，是否与历史数据、运营计划、商业机会、行业数据、行业研究报告、宏观经济运行状况相符
L19: 资产组价值=企业自由现金流评估值（经营性资产价值）－期初营运资金 其中，企业自由现金流评估值（经营性资产价值）＝EBIT +折旧及摊销－营运资本增加额－资本性支出 EBIT=营业务收入－营业务成本－税金及附加－销售费用－管理费用 （为了便于评估资产组的未来现金流量，可以将营运资金纳入其现金流预测模型不予扣除，那么此时用于对比的包含商誉的资产组账面价值中也应包含营运资金）
B21: （2）对于营运资金的口径判断是否与非经营性资产负债一致
L22: 若在确定可收回金额的未来现金流量时考虑了期初营运资金的影响，则资产组的账面价值中也应包括营运资金，即资产组也不得扣除与经营相关的流动资产和流动负债。
B24: （3）资本性支出预测是否与预算、运营计划一致
L25: 资本性支出=资产性更新投资+新增长期资产投资（新增固定资产或其他长期资产）
B27: （4）折旧摊销费用预测是否合理
B30: （5）收益期（增长期及永续期）选择是否合理
L31: 在确定未来现金净流量的预测期时，应建立在经管理层批准的最近财务预算或预测数据基础上，原则上最多涵盖5年。
B33: （6）可比公司或可比交易的选择是否合理
B36: （7）折现率计算是否合理
L37: 对折现率预测时，是否与相应的宏观、行业、地域、特定市场、特定市场主体的风险因素相匹配，是否与未来现金净流量均一致采用税前口径。
B39: （8）终值的处理是否合理
L40: 假设使用后续现金流量永续增长模型，根据销售增长率估计现金流量增长率。绝大多数可以持续生存的企业，其销售增长率可以按宏观经济增长率估计。
B42: （9）对关键假设（如增长率、毛利率、折现率等）的敏感性分析结果
B45: 6、评价使用收益法确定公允价值的参数和具体处理【若适用】
B46: （1）盈利预测是否有可靠的数据来源，是否与历史数据、运营计划、商业机会、行业数据、行业研究报告、宏观经济运行状况相符
L47: 对未来现金净流量预测时，应以资产的当前状况为基础，以税前口径为预测依据，并充分关注选取的关键参数（包括但不限于销量、价格、成本、费用、预测期增长率、稳定期增长率）是否有可靠的数据来源，是否与历史数据、运营计划、商业机会、行业数据、行业研究报告、宏观经济运行状况相符；与此相关的重大假设是否与可获取的内部、外部信息相符，在不符时是否有合理理由支持。
B49: （2）对于营运资金的口径判断是否与非经营性资产负债一致
L50: 若在确定可收回金额的未来现金流量时考虑了期初营运资金的影响，则资产组的账面价值中也应包括营运资金，即资产组也不得扣除与经营相关的流动资产和流动负债。
B52: （3）资本性支出预测是否与预算、运营计划一致
L53: 资本性支出=资产性更新投资+新增长期资产投资（新增固定资产或其他长期资产）
B55: （4）折旧摊销费用预测是否合理
B58: （5）收益期（增长期及永续期）选择是否合理
B61: （6）可比公司或可比交易的选择是否合理
B64: （7）折现率计算是否合理
...

Sheet 市场平均收益率2017
B1: 市场平均收益率(2017年）
B2: 时间（年末） | C2: 上证综合指数 | D2: 收益率 | E2: 深证成份指数 | F2: 收益率 | G2: 市场收益率
B3: 0 | C3: 292.75 | E3: 963.57
B4: 1 | C4: 780.39 | D4: 1.6657216 | E4: 2309.77 | F4: 1.3970962
B5: 2 | C5: 833.8 | D5: 0.068440139 | E5: 2225.38 | F5: -0.036536105
B6: 3 | C6: 647.87 | D6: -0.22299112 | E6: 1271.06 | F6: -0.42883463
B7: 4 | C7: 555.29 | D7: -0.14289904 | E7: 987.75 | F7: -0.2228927
B8: 5 | C8: 917.02 | D8: 0.65142538 | E8: 3217.55 | F8: 2.2574538
B9: 6 | C9: 1194.11 | D9: 0.30216353 | E9: 4184.85 | F9: 0.30063247
B10: 7 | C10: 1146.71 | D10: -0.039694835 | E10: 2949.32 | F10: -0.29523878
B11: 8 | C11: 1366.59 | D11: 0.19174857 | E11: 3369.62 | F11: 0.14250743
B12: 9 | C12: 2073.48 | D12: 0.5172656 | E12: 4752.76 | F12: 0.41047358
B13: 10 | C13: 1645.98 | D13: -0.20617513 | E13: 3325.67 | F13: -0.30026553
B14: 11 | C14: 1357.66 | D14: -0.17516616 | E14: 2759.3 | F14: -0.17030253
B15: 12 | C15: 1497.05 | D15: 0.1026693 | E15: 3479.8 | F15: 0.26111695
... B29: 26 | C29: 3307.1721 | D29: 0.065579441 | E29: 11040.45 | F29: 0.084828574
C30: 算术平均收益率 | D30: 0.19463448 | E30: 算术平均收益率 | F30: 0.25099656 | G30: 0.22281552
C31: 几何平均收益率 | D31: 0.097737391 | E31: 几何平均收益率 | F31: 0.098334815 | G31: 0.098036103
B33: 时间（年末） | C33: 上证综合指数 | D33: 收益率 | E33: 深证成份指数 | F33: 收益率 | G33: 市场收益率
B34: 0 | C34: 1357.66 | E34: 2759.3
B35: 1 | C35: 1497.05 | D35: 0.1026693 | E35: 3479.8 | F35: 0.26111695
B36: 2 | C36: 1266.5 | D36: -0.15400287 | E36: 3067.57 | F36: -0.1184637
B37: 3 | C37: 1161.06 | D37: -0.08325306 | E37: 2863.62 | F37: -0.06648585
B38: 4 | C38: 2675.48 | D38: 1.3043426 | E38: 6647.14 | F38: 1.3212368
B39: 5 | C39: 5261.57 | D39: 0.96658917 | E39: 17700.63 | F39: 1.6628941
B40: 6 | C40: 1820.81 | D40: -0.65394169 | E40: 6485.52 | F40: -0.63359948
B41: 7 | C41: 3277.14 | D41: 0.79982535 | E41: 13699.98 | F41: 1.112395
B42: 8 | C42: 2808.08 | D42: -0.1431309 | E42: 12458.56 | F42: -0.090614731
B43: 9 | C43: 2199.42 | D43: -0.21675308 | E43: 8918.82 | F43: -0.28412112
B44: 10 | C44: 2236.46 | D44: 0.016840803 | E44: 9116.48 | F44: 0.022162125
B45: 11 | C45: 2236.46 | D45: 0 | E45: 8121.79 | F45: -0.109109
B46: 12 | C46: 3234.677 | D46: 0.44633796 | E46: 11014.624 | F46: 0.35618183
... B49: 15 | C49: 3307.1721 | D49: 0.065579441 | E49: 11040.45 | F49: 0.084828574
C50: 算术平均收益率 | D50: 0.16147847 | E50: 算术平均收益率 | F50: 0.23145449 | G50: 0.19646648
C51: 几何平均收益率 | D51: 0.061152296 | E51: 几何平均收益率 | F51: 0.096846508 | G51: 0.078999402
B53: 时间（年末） | C53: 上证综合指数 | D53: 收益率 | E53: 深证综合指数 | F53: 收益率 | G53: 市场收益率
B54: 0 | C54: 1357.66 | E54: 388.76
B55: 1 | C55: 1497.05 | D55: 0.1026693 | E55: 378.63 | F55: -0.026057208
B56: 2 | C56: 1266.5 | D56: -0.15400287 | E56: 315.81 | F56: -0.16591395
B57: 3 | C57: 1161.06 | D57: -0.08325306 | E57: 278.75 | F57: -0.11734904
...

Sheet 参考－商誉减值测试示例
A1: 致同会计师事务所
A2: 商誉减值准备测试表-可收回金额
A3: 客户名称： | E3: 编制人： | J3: 日期：2012.2.4 | N3: 索引号：
A4: 截止日： | E4: 复核人： | J4: 复核日期： | N4: 页 次： 1
A5: （一）资产的公允价值减去处置费用后的净额(RMB '0000)
A6: 项目名称 | B6: 公允价值 | H6: 处置费用（资产处置的直接归属费用） | N6: 公允价值-处置费用 | O6: 备注
B7: 销售协议价格 | C7: 说明 | D7: 资产活跃市场价格 | E7: 说明 | F7: 估计价格 | G7: 说明 | H7: 法律费用 | I7: 相关税费 | J7: 搬运费 | K7: 直接费用 | L7: 其他费用 | M7: 处置费用合计
F8: 850 | G8: NOTE1 | M8: =SUM(H8:L8) -> 0 | N8: =IF(B8>0,B8,IF(D8>0,D8,F8))-M8 -> 850
M9: =SUM(H9:L9) -> 0 | N9: =IF(B9>0,B9,IF(D9>0,D9,F9))-M9 -> 0
M10: =SUM(H10:L10) -> 0 | N10: =IF(B10>0,B10,IF(D10>0,D10,F10))-M10 -> 0
A11: 合 计 | B11: =SUM(B8:B10) -> 0 | D11: =SUM(D8:D10) -> 0 | F11: =SUM(F8:F10) -> 850 | H11: =SUM(H8:H10) -> 0 | I11: =SUM(I8:I10) -> 0 | J11: =SUM(J8:J10) -> 0 | K11: =SUM(K8:K10) -> 0 | L11: =SUM(L8:L10) -> 0 | M11: =SUM(M8:M10) -> 0 | N11: =SUM(N8:N10) -> 850
A12: 审计说明：
A13: NOTE1： | B13: 相似公司近期在公开市场出售价格。
A14: （二）资产预计未来现金流量的现值(RMB '0000)
A15: 预计未来现金流量 | B15: 预算或者预测期 | G15: 以后年度 | I15: 行业的长期平均增长率 | J15: 市场长期平均增长率 | K15: 所在国家或地区的长期平均增长率 | L15: 增长率确定依据 | N15: 预计未来现金流量的现值 | O15: 备注
B16: 第一年 | C16: 第二年 | D16: 第三年 | E16: 第四年 | F16: 第五年 | G16: 基数 | H16: 增长率
A17: 现金净流量（税前） | B17: 400 | C17: -50 | D17: 150 | E17: =D17*(1+$H$17) -> 156 | F17: =E17*(1+$H$17) -> 162.24 | G17: =F17 -> 162.24 | H17: 0.04 | K17: 0.04 | L17: 所在地区长期平均增长率
A18: 折现系数 | B18: =1/(1+$K$22)^1 -> 0.83418447 | C18: =1/(1+$K$22)^2 -> 0.69586373 | D18: =1/(1+$K$22)^3 -> 0.58047872 | E18: =1/(1+$K$22)^4 -> 0.48422633 | F18: =1/(1+$K$22)^5 -> 0.40393409 | G18: =(1+H17)/((K22-H17)*(1+K22)^5) -> 2.6458185 | H18: （企业管理层如能证明递增的增长率是合理的，可以以递增的增长率为基础。）
A19: 现值 | B19: =B17*B18 -> 333.67379 | C19: =C17*C18 -> -34.793187 | D19: =D17*D18 -> 87.071808 | E19: =E17*E18 -> 75.539308 | F19: =F17*F18 -> 65.534266 | G19: =G17*G18 -> 429.25759 | H19: （建立在预算或者预测基础上的预计现金流量最多涵盖5年。） | N19: =SUM(B19:G19) -> 956.28358
A20: 折现率 | B20: 所得税率 | C20: 债务总额 D | D20: 资本总额 E | E20: 债务成本Kd | F20: 无风险报酬率Rf | G20: β系数 | H20: 市场平均收益率Rm | I20: 资本成本Ke | J20: WACC (税后) | K20: 折现率 (税前) | L20: 税后折税前调整说明 | N20: 可收回金额 | O20: 备注
B21: 适用税率 | L21: 税率调整 | M21: 调整说明
A22: 加权平均资金成本 | B22: 0.25 | C22: 200 | D22: 1250 | E22: 0.085 | F22: 0.025 | G22: 1.18 | H22: 0.13 | I22: =F22+G22*(H22-F22) -> 0.1489 | J22: =((C22*E22*(1-B22)+D22*I22))/(C22+D22) -> 0.13715517 | K22: =J22/(1-(B22+L22)) -> 0.19877561 | L22: 0.06 | M22: NOTE2 | N22: =MAX(N11,N19) -> 956.28358
A23: 审计说明：
A24: NOTE2： | B24: 考虑企业的有效税率及税款的时间价值，估值专家建议调整。
A25: （三）可收回金额
B26: =MAX(N11,N22) -> 956.28358 | C26: 资产的公允价值减去处置费用后的净额与资产预计未来现金流量的现值两者之间较高者
A27: 1、CC公司的预计现金流量表
A28: 经营现金流（实体现金流）是指企业因销售商品或提供劳务等营业活动以及与此有关的生产性资产投资活动产生的现金流量。（与现金流量表中“经营活动产生的现金流量”不同）
A29: 项目 | B29: 基期 | C29: 2012年 | D29: 2013年 | E29: 2014年 | F29: 2015年 | G29: 2016年
A30: 营业收入 | H30: 建立在预算或者预测基础上的预计现金流量最多涵盖5年（涵盖更长的期间需证明合理性）。
A31: 减：营业成本
A32: 营业税金及附加 | H32: 不考虑债务利息支出，因其不属于经营活动。
A33: 销售和管理费用 | H33: 不考虑所得税费用，因为折现率一般是以税前基础确定，
A34: 税前经营利润 | H34: 与税前折现率对应的现金流量的预计也应建立在税前基础之上。
A35: 项目 | B35: 基期 | C35: 2012年 | D35: 2013年 | E35: 2014年 | F35: 2015年 | G35: 2016年 | H35: 以后年度
A36: 税前经营利润 | B36: 639.96 | C36: 680.4 | D36: 690.53 | E36: 690.18 | F36: 725.13 | G36: 774.8 | H36: 0.04
A37: 加：折旧与摊销 | B37: 344 | C37: 360.88 | D37: 390.57 | E37: 400.93 | F37: 433.85 | G37: 435.54 | H37: 假设使用后续现金流量永续增长模型，根据销售增长率估计现金流量增长率。
A38: =经营现金毛流量 | B38: =B36+B37 -> 983.96 | C38: =C36+C37 -> 1041.28 | D38: =D36+D37 -> 1081.1 | E38: =E36+E37 -> 1091.11 | F38: =F36+F37 -> 1158.98 | G38: =G36+G37 -> 1210.34 | H38: 根据竞争均衡理论，后续期的销售增长率大体上等于宏观经济的名义增长率。
A39: 减：经营营运资本增加 | C39: 140.4 | D39: 360.13 | E39: 199.47 | F39: 219.16 | G39: 228.46 | H39: 如果不考虑通货膨胀因素，宏观经济的增长率大多在2%-6%之间。
A40: =经营现金净流量 | C40: =C38-C39 -> 900.88 | D40: =D38-D39 -> 720.97 | E40: =E38-E39 -> 891.64 | F40: =F38-F39 -> 939.82 | G40: =G38-G39 -> 981.88 | H40: 即使是具有特殊优势的企业，后续期销售增长率超过宏观经济的幅度也不会超过2%。
...

Sheet GT_Custom
A1: C1 | B1: Custom 1
A2: C2 | B2: Custom 2
A3: C3 | B3: Custom 3
A4: C4 | B4: Custom 4
A5: C5 | B5: Custom 5
A6: C6 | B6: Custom 6
A7: C7 | B7: Custom 7
A8: C8 | B8: Custom 8
