Workbook
Name _1、: #REF!
Name _1、受本循环影响的相关交易和账户余额: #REF!
Name _2、主要业务活动: #REF!
Name _2、注册会计师通常应在本循环中了解与上述业务活动相关的内部控制_如果计划在其他业务循环中对上述: #REF!
Name _DAT1: #REF!
Name _DAT1: #REF!
Name _DAT10: #REF!
Name _DAT10: #REF!
Name _DAT11: #REF!
Name _DAT11: #REF!
Name _DAT2: #REF!
Name _DAT3: #REF!
Name _DAT4: #REF!
Name _DAT5: #REF!
Name _DAT6: #REF!
Name _DAT7: #REF!
Name _DAT8: #REF!
Name _DAT9: #REF!
Name AS2DocOpenMode: "AS2DocumentEdit"
Name a暗暗: [2]企业表一!$F$20
Name CarryKnown: #REF!
Name CarryKnown: #REF!
Name CarryKnownTable: #REF!
Name CarryKnownTable: #REF!
Name CarryLikely: #REF!
Name CarryLikely: #REF!
Name CarryLikelyTable: #REF!
Name CarryLikelyTable: #REF!
Name Carryover_Effect_of_Prior_Year: #REF!
Name Carryover_Effect_of_Prior_Year: #REF!
Name CarryoverTitle: #REF!
Name CarryoverTitle: #REF!
Name CC_Instruction: #REF!
Name CC_Instruction: #REF!
Name CE_CarryKnownProtection: #REF!
Name CE_CarryKnownProtection: #REF!
Name CE_CarryKnownTable: #REF!
Name CE_CarryKnownTable: #REF!
Name CE_CarryLikely1Protection: #REF!
Name CE_CarryLikely1Protection: #REF!
Name CE_CarryLikely1Table: #REF!
Name CE_CarryLikely1Table: #REF!
Name CE_CarryLikely2Protection: #REF!
Name CE_CarryLikely2Protection: #REF!
Name CE_CarryLikely2Table: #REF!
Name CE_CarryLikely2Table: #REF!
Name CE_CarryTaxable: #REF!
Name CE_CarryTaxable: #REF!
Name CE_Desc: #REF!
Name CE_Desc: #REF!
Name CE_Income: #REF!
Name CE_Income: #REF!
Name CE_KeepFormat: #REF!
Name CE_KeepFormat: #REF!
Name CE_KnownChange: #REF!
Name CE_KnownChange: #REF!
Name CE_KnownFormulaProtection: #REF!
Name CE_KnownFormulaProtection: #REF!
Name CE_KnownImpact: #REF!
Name CE_KnownImpact: #REF!

Sheet 底稿目录
A1: 底稿开列时，可先在以下单元格填写有关内容，以便其他底稿引用有关数据： | B1: 目录
A2: 被审计单位：
A3: 截止日：202X年12月31日 | B3: 序号 | C3: 内容 | D3: 索引号 | E3: 备注
A4: 编制人： | B4: 1 | C4: 长期待摊费用实质性程序 | D4: I4A
A5: 编制日期： | B5: 2 | C5: 长期待摊费用审定表 | D5: I4-1
A6: 复核人： | B6: 3 | C6: 长期待摊费用附注披露表（上市公司）
A7: 复核日期： | B7: 4 | C7: 长期待摊费用附注披露表（国有企业）
A8: 长期待摊费用类别设置（以下内容请根据实际情况修改）： | B8: 5 | C8: 长期待摊费用明细表 | D8: I4-2
A9: 类别A | B9: 6 | C9: 调整分录汇总 | D9: I4-3 | E9: 备选
A10: 类别B | B10: 7 | C10: 摊销政策检查表 | D10: I4-4
A11: 类别C | B11: 8 | C11: 针对性检查表 | D11: I4-5
A12: …… | B12: 9 | C12: 长期待摊费用摊销测算表 | D12: I4-6
B13: 10 | C13: 长期待摊费用摊销测算表（采用工作量法时使用） | D13: I4-7
A15: 关于工作底稿与审计程序索引号对应的说明
A16: 1.编制的审计工作底稿应与审计程序对应。审计项目组应根据被审计单位实际情况和风险评估情况在实质性程序表中裁剪、修改或增加审计程序，根据实际执行的审计程序完成相应审计工作底稿，编制的工作底稿中应按自然顺序依次编制索引号，并通过唯一的索引号将与实质性程序表中的程序对应关联（即将工作底稿的索引号填入实质性程序表中的底稿索引号列）。
A20: 2.获取的支持性证据应与审计底稿或程序对应。审计项目组在完成底稿时获取的支持性证据应根据底稿索引号编制下一级按自然顺序排序的索引号（如D1-2-1、D1-2-2、……），并在底稿中说明引用的支持性证据、关联索引号。
A23: 3.工作底稿索引号的编码规则：实质性程序索引号按循环从“D”到“N”,循环内账户以顺序号排列，模板中底稿索引号按账户顺序+自然数顺序（即模板中索引号按二级自然顺序排列，如D1-1、D1-2、D1-3、……D1-N）。

Sheet 长期待摊费用实质性程序 I4A
A1: 致同会计师事务所
A2: 长期待摊费用实质性程序
A3: =底稿目录!A2 -> 被审计单位： | C3: =底稿目录!A4 -> 编制人： | E3: =底稿目录!A5 -> 编制日期： | H3: 索引号： | I3: I4A
A4: 会计期间：202X年 | C4: =底稿目录!A6 -> 复核人： | E4: =底稿目录!A7 -> 复核日期： | H4: 页 次：
A5: 一、本账户涉及的科目
A6: 长期待摊费用
A7: 二、审计目标与认定的对应关系
A8: 审计目标 | G8: 财务报表的认定
A9: A. 资产负债表中记录的长期待摊费用是存在的，且已经记录在恰当的账户中 | G9: 存在
A10: B. 所有应记录的长期待摊费用均已记录，所有应当包括在财务报表中的相关披露均已包括 | G10: 完整性
A11: C. 记录的长期待摊费用由被审计单位拥有或控制 | G11: 权利和义务
A12: D. 长期待摊费用以恰当的金额包括在财务报表中，与之相关的计价或分摊调整已恰当记录，相关披露已得到恰当计量和描述 | G12: 准确性、计价和分摊
A13: E. 长期待摊费用已被恰当地汇总或分解且表述清楚，相关披露在按照企业会计准则的编制基础下是相关的、可理解的 | G13: 列报
A14: 三、计划实施的实质性程序
A15: 序号 | B15: 审计程序 | C15: 程序分类 | D15: 财务报表的认定 | I15: 底稿索引号
D16: 存在 | E16: 完整性 | F16: 权利和 义务 | G16: 准确性、计价和分摊 | H16: 列报 | J16: 根据被审计单位实际情况和风险评估情况裁剪、修改或增加审计程序
A17: 1 | B17: 获取或编制长期待摊费用的明细表，复核加计是否正确，与总账、明细账合计数核对是否相符，期初余额与上期审定期末余额是否相符，并编制审定表。 | C17: 常规★ | D17: √ | E17: √ | G17: √ | I17: I4-1 /I4-2
A18: 2 | B18: 在使用手工编制、自定义信息报告、系统生成的非固定格式报告等由被审计单位生成的信息时，测试有关信息准确性和完整性，并考虑针对编制和维护由被审计单位生成的信息的相关控制实施控制测试，以评价该信息是否能够为实现审计目的提供基础。 | C18: 常规★ | E18: √ | G18: √ | I18: T1 | J18: 可参见《审计手册》4.2.6，由被审计单位生成的信息可能是由系统生成的、或手工编制的、或二者兼而有之的方式生成的。例如，由被审计单位生成的信息可能包括： • 不涉及自定义的、由系统生成的报告（如，固定格式报告）； • 可能通过人工自定义的、由系统生成的报告，例如，（计算机）查询信息或特别定制的报告； • 手工编制的信息，例如，汇总信息的电子表格或用以支持分配、计算以及调节的电子表格； • 其他系统生成或手工编制的信息，例如，由被审计单位编制的客户发票； • 通过影印、拍摄、扫描或其他方式转换成电子形式的文件记录。
A19: 3 | B19: 取得长期待摊费用期初余额明细表复核加计是否正确，与总账、明细账合计数是否相符；如适用，测试累计摊销。确定是否需要补充必要的程序，如果是，执行适当的应对程序。（适用于首次承接） | C19: 期初余额 | D19: √ | E19: √ | F19: √ | G19: √ | J19: 由被审计单位生成的信息不包括： • 总分类账或明细分类账、试算平衡表、或经审计的财务报表； • 第三方（除了服务机构）的报表或报告，例如，原始银行对账单，或函证的回函； • 外部数据（例如，第三方发布的数据，如，定价来源）。
A20: 4 | B20: 关注会计政策、会计估计合理性、一贯性，关注其是否利用会计政策和会计估计及其变更操纵利润。 （1）对于长期待摊费用，了解各个长期待摊费用项目，及其摊销政策，摊销年限等，检查其是否符合企业会计准则的规定。； （2）将被审计单位本期的会计政策、会计估计与前期进行对比，分析其是否前后一致。对于存在会计政策、会计估计变更的情形，判断是否合理，会计处理是否正确； （3）与同行业其他公司的会计政策、会计估计进行对比，关注其是否利用会计政策和会计估计变更操纵利润； | C20: 常规★ | D20: √ | E20: √ | G20: √ | I20: I4-4
A21: 5 | B21: 检查与长期待摊费用增加有关的的记账凭证和原始凭证，检查长期待摊费用增加的合法性和真实性，查阅有关合同、协议等资料和支出凭证，是否经授权批准，会计处理是否正确；关注检查长期待摊费用中是否存在应计入期间费用的支出，租入固定资产改良支出与修理费的划分是否正确。 | C21: 常规★ | D21: √ | E21: √ | F21: √ | G21: √ | I21: I4-5
A22: 6 | B22: 对于本期摊销，执行以下程序： （1）获取或编制长期待摊费的累计摊销明细表，复核加计正确，并与总账数和明细账合计数核对相符。 （2）确认摊销方法是否一致，是否合理。 确定摊销年限是否适当，重新测算摊销金额，形成本期摊销费用的期望，与已记录的金额对比。 （3）确定分配到各项资产/费用项目的摊销金额是否合理。 | C22: 常规★ | G22: √ | I22: I4-6 /I4-7
A23: 7 | B23: 根据评估的舞弊风险等因素增加的审计程序。 | C23: IPO/上市/新三板/重组/舞弊应对
A24: 8 | B24: 检查长期待摊费用是否已按企业会计准则或其他适用的规定在财务报表中做出恰当列报和披露。 | C24: 常规★ | H24: √ | I24: A1-1/A1-15 /A1-16

Sheet 审定表I4-1
A1: 致同会计师事务所
A2: 长期待摊费用审定表
A3: =底稿目录!A2 -> 被审计单位： | D3: =底稿目录!A4 -> 编制人： | F3: =底稿目录!A5 -> 编制日期： | H3: 索引号： | I3: I4-1
A4: =底稿目录!A3 -> 截止日：202X年12月31日 | D4: =底稿目录!A6 -> 复核人： | F4: =底稿目录!A7 -> 复核日期： | H4: 页次：
A5: 项目类别 | B5: 期初数 | E5: 期末数 | H5: 本期审定数与上期 审定数的比较
B6: 未审数 | C6: 账项调整 | D6: 审定数 | E6: 未审数 | F6: 账项调整 | G6: 审定数 | H6: 变动额 | I6: 变动率
A7: =底稿目录!A9 -> 类别A | B7: ='明细表I4-2'!F25 -> 0 | C7: ='明细表I4-2'!K25 -> 0 | D7: ='明细表I4-2'!O25 -> 0 | E7: ='明细表I4-2'!J25 -> 0 | F7: ='明细表I4-2'!K25+'明细表I4-2'!L25-'明细表I4-2'!M25-'明细表I4-2'!N25 -> 0 | G7: ='明细表I4-2'!S25 -> 0 | H7: =G7-D7 -> 0 | I7: =IF(AND(D7=0,H7=0),0,IF(AND(D7=0,H7>0),1,H7/D7)) -> 0
A8: =底稿目录!A10 -> 类别B | B8: ='明细表I4-2'!F26 -> 0 | C8: ='明细表I4-2'!K26 -> 0 | D8: ='明细表I4-2'!O26 -> 0 | E8: ='明细表I4-2'!J26 -> 0 | F8: ='明细表I4-2'!K26+'明细表I4-2'!L26-'明细表I4-2'!M26-'明细表I4-2'!N26 -> 0 | G8: ='明细表I4-2'!S26 -> 0 | H8: =G8-D8 -> 0 | I8: =IF(AND(D8=0,H8=0),0,IF(AND(D8=0,H8>0),1,H8/D8)) -> 0
A9: =底稿目录!A11 -> 类别C | B9: ='明细表I4-2'!F27 -> 0 | C9: ='明细表I4-2'!K27 -> 0 | D9: ='明细表I4-2'!O27 -> 0 | E9: ='明细表I4-2'!J27 -> 0 | F9: ='明细表I4-2'!K27+'明细表I4-2'!L27-'明细表I4-2'!M27-'明细表I4-2'!N27 -> 0 | G9: ='明细表I4-2'!S27 -> 0 | H9: =G9-D9 -> 0 | I9: =IF(AND(D9=0,H9=0),0,IF(AND(D9=0,H9>0),1,H9/D9)) -> 0
A10: 合计 | B10: =SUM(B7:B9) -> 0 | C10: =SUM(C7:C9) -> 0 | D10: =SUM(D7:D9) -> 0 | E10: =SUM(E7:E9) -> 0 | F10: =SUM(F7:F9) -> 0 | G10: =SUM(G7:G9) -> 0 | H10: =G10-D10 -> 0 | I10: =IF(AND(D10=0,H10=0),0,IF(AND(D10=0,H10>0),1,H10/D10)) -> 0
A11: TB数据
A12: 差异 | B12: =B10-B11 -> 0 | C12: =C10-C11 -> 0 | D12: =D10-D11 -> 0 | E12: =E10-E11 -> 0 | F12: =F10-F11 -> 0 | G12: =G10-G11 -> 0
A14: 1、审计说明
A17: 2、审计结论：
A23: 编制说明：
A24: 1、本科目核算企业已经发生但应由本期和以后各期负担的分摊期限在1年以上的各项费用，如以经营租赁方式租入的固定资产发生的改良支出等。
A25: 2、长期待摊费用中在一年内(含一年)摊销的部分，在资产负债表“一年内到期的非流动资产”项目填列。
A26: 3、企业对自有固定资产进行的装修改造支出，符合固定资产确认条件的（使用寿命超过一个会计年度、金额确定），可以计入固定资产成本，不符合固定资产的确认条件的应当费用化，计入当期损益。
A27: 但因装修改造一般无残值、使用期限较短，实务中企业为简化核算，可将其计入长期待摊费用。
A28: 4、如适用，根据1131号等审计准则和指南的要求编制，说明涉及事项内容、应对措施、审计结论或解决方法，以及可能对审计报告的影响。
A30: 重大事项说明（如适用，根据1131号等审计准则和指南的要求编制，说明涉及事项内容、应对措施、审计结论或解决方法，以及可能对审计报告的影响）
A31: A、风险评估结果和内控了解、测试情况（不适用则说明：不存在重大错报风险。)
A32: (识别和实际评估的重大错报风险、尤其识特别风险，以及对内控了解和控制测试情况〔采用综合方案时〕）；
A33: 提示：a、收入科目应当假定存在舞弊的特别风险，如不存在，应说明理由；
... A46: 6、注释：对于按照相关会计准则采用折旧（或摊销、折耗）方法进行后续计量的固定资产、无形资产、长期待摊费用等非流动资产，折旧（或摊销、折耗）年限（或期限）只剩一年或不足一年的，无需转入“一年内到期的非流动资产”列报；预计在一年内（含一年）进行折旧（或摊销、折耗）的部分，无需转入“一年内到期的非流动资产”列报。

Sheet 附注披露（上市公司）
A1: 致同会计师事务所
A2: 长期待摊费用附注披露表（上市公司）
A3: =底稿目录!A2 -> 被审计单位： | C3: =底稿目录!A4 -> 编制人： | D3: =底稿目录!A5 -> 编制日期： | E3: 索引号：
A4: =底稿目录!A3 -> 截止日：202X年12月31日 | C4: =底稿目录!A6 -> 复核人： | D4: =底稿目录!A7 -> 复核日期： | E4: 页次：
A5: 项 目 | B5: 期初数 | C5: 本期增加 | D5: 本期减少 | F5: 期末数
D6: 本期摊销 | E6: 其他减少
A7: ='明细表I4-2'!$A11 -> 使用权资产改良及维护支出 | B7: =SUMIF('明细表I4-2'!$A:$A,$A7,'明细表I4-2'!O:O) -> 0 | C7: =SUMIF('明细表I4-2'!$A:$A,$A7,'明细表I4-2'!P:P) -> 0 | D7: =SUMIF('明细表I4-2'!$A:$A,$A7,'明细表I4-2'!Q:Q) -> 0 | E7: =SUMIF('明细表I4-2'!$A:$A,$A7,'明细表I4-2'!R:R) -> 0 | F7: =B7+C7-D7-E7 -> 0
A8: ='明细表I4-2'!$A12 -> 0 | B8: =SUMIF('明细表I4-2'!$A:$A,$A8,'明细表I4-2'!O:O) -> 0 | C8: =SUMIF('明细表I4-2'!$A:$A,$A8,'明细表I4-2'!P:P) -> 0 | D8: =SUMIF('明细表I4-2'!$A:$A,$A8,'明细表I4-2'!Q:Q) -> 0 | E8: =SUMIF('明细表I4-2'!$A:$A,$A8,'明细表I4-2'!R:R) -> 0 | F8: =B8+C8-D8-E8 -> 0
A9: ='明细表I4-2'!$A13 -> 0 | B9: =SUMIF('明细表I4-2'!$A:$A,$A9,'明细表I4-2'!O:O) -> 0 | C9: =SUMIF('明细表I4-2'!$A:$A,$A9,'明细表I4-2'!P:P) -> 0 | D9: =SUMIF('明细表I4-2'!$A:$A,$A9,'明细表I4-2'!Q:Q) -> 0 | E9: =SUMIF('明细表I4-2'!$A:$A,$A9,'明细表I4-2'!R:R) -> 0 | F9: =B9+C9-D9-E9 -> 0
A10: ='明细表I4-2'!$A14 -> 0 | B10: =SUMIF('明细表I4-2'!$A:$A,$A10,'明细表I4-2'!O:O) -> 0 | C10: =SUMIF('明细表I4-2'!$A:$A,$A10,'明细表I4-2'!P:P) -> 0 | D10: =SUMIF('明细表I4-2'!$A:$A,$A10,'明细表I4-2'!Q:Q) -> 0 | E10: =SUMIF('明细表I4-2'!$A:$A,$A10,'明细表I4-2'!R:R) -> 0 | F10: =B10+C10-D10-E10 -> 0
A11: ='明细表I4-2'!$A15 -> 0 | B11: =SUMIF('明细表I4-2'!$A:$A,$A11,'明细表I4-2'!O:O) -> 0 | C11: =SUMIF('明细表I4-2'!$A:$A,$A11,'明细表I4-2'!P:P) -> 0 | D11: =SUMIF('明细表I4-2'!$A:$A,$A11,'明细表I4-2'!Q:Q) -> 0 | E11: =SUMIF('明细表I4-2'!$A:$A,$A11,'明细表I4-2'!R:R) -> 0 | F11: =B11+C11-D11-E11 -> 0
A12: ='明细表I4-2'!$A16 -> 0 | B12: =SUMIF('明细表I4-2'!$A:$A,$A12,'明细表I4-2'!O:O) -> 0 | C12: =SUMIF('明细表I4-2'!$A:$A,$A12,'明细表I4-2'!P:P) -> 0 | D12: =SUMIF('明细表I4-2'!$A:$A,$A12,'明细表I4-2'!Q:Q) -> 0 | E12: =SUMIF('明细表I4-2'!$A:$A,$A12,'明细表I4-2'!R:R) -> 0 | F12: =B12+C12-D12-E12 -> 0
A13: 合 计 | B13: =SUM(B7:B12) -> 0 | C13: =SUM(C7:C12) -> 0 | D13: =SUM(D7:D12) -> 0 | E13: =SUM(E7:E12) -> 0 | F13: =SUM(F7:F12) -> 0
A14: 说明：1年内到期的长期待摊费用X.XX元，详见附注五、11。

Sheet 附注披露（国有企业）
A1: 致同会计师事务所
A2: 长期待摊费用附注披露（国有企业）
A3: =底稿目录!A2 -> 被审计单位： | C3: =底稿目录!A4 -> 编制人： | D3: =底稿目录!A5 -> 编制日期： | E3: 索引号：
A4: =底稿目录!A3 -> 截止日：202X年12月31日 | C4: =底稿目录!A6 -> 复核人： | D4: =底稿目录!A7 -> 复核日期： | E4: 页次：
A5: 项 目 | B5: 期初余额 | C5: 本期增加额 | D5: 本期摊销额 | E5: 其他减少额 | F5: 期末余额 | G5: 其他减少的原因
A6: ='明细表I4-2'!$A11 -> 使用权资产改良及维护支出 | B6: =SUMIF('明细表I4-2'!$A:$A,$A6,'明细表I4-2'!O:O) -> 0 | C6: =SUMIF('明细表I4-2'!$A:$A,$A6,'明细表I4-2'!P:P) -> 0 | D6: =SUMIF('明细表I4-2'!$A:$A,$A6,'明细表I4-2'!Q:Q) -> 0 | E6: =SUMIF('明细表I4-2'!$A:$A,$A6,'明细表I4-2'!R:R) -> 0 | F6: =B6+C6-D6-E6 -> 0
A7: ='明细表I4-2'!$A12 -> 0 | B7: =SUMIF('明细表I4-2'!$A:$A,$A7,'明细表I4-2'!O:O) -> 0 | C7: =SUMIF('明细表I4-2'!$A:$A,$A7,'明细表I4-2'!P:P) -> 0 | D7: =SUMIF('明细表I4-2'!$A:$A,$A7,'明细表I4-2'!Q:Q) -> 0 | E7: =SUMIF('明细表I4-2'!$A:$A,$A7,'明细表I4-2'!R:R) -> 0 | F7: =B7+C7-D7-E7 -> 0
A8: ='明细表I4-2'!$A13 -> 0 | B8: =SUMIF('明细表I4-2'!$A:$A,$A8,'明细表I4-2'!O:O) -> 0 | C8: =SUMIF('明细表I4-2'!$A:$A,$A8,'明细表I4-2'!P:P) -> 0 | D8: =SUMIF('明细表I4-2'!$A:$A,$A8,'明细表I4-2'!Q:Q) -> 0 | E8: =SUMIF('明细表I4-2'!$A:$A,$A8,'明细表I4-2'!R:R) -> 0 | F8: =B8+C8-D8-E8 -> 0
A9: ='明细表I4-2'!$A14 -> 0 | B9: =SUMIF('明细表I4-2'!$A:$A,$A9,'明细表I4-2'!O:O) -> 0 | C9: =SUMIF('明细表I4-2'!$A:$A,$A9,'明细表I4-2'!P:P) -> 0 | D9: =SUMIF('明细表I4-2'!$A:$A,$A9,'明细表I4-2'!Q:Q) -> 0 | E9: =SUMIF('明细表I4-2'!$A:$A,$A9,'明细表I4-2'!R:R) -> 0 | F9: =B9+C9-D9-E9 -> 0
A10: ='明细表I4-2'!$A15 -> 0 | B10: =SUMIF('明细表I4-2'!$A:$A,$A10,'明细表I4-2'!O:O) -> 0 | C10: =SUMIF('明细表I4-2'!$A:$A,$A10,'明细表I4-2'!P:P) -> 0 | D10: =SUMIF('明细表I4-2'!$A:$A,$A10,'明细表I4-2'!Q:Q) -> 0 | E10: =SUMIF('明细表I4-2'!$A:$A,$A10,'明细表I4-2'!R:R) -> 0 | F10: =B10+C10-D10-E10 -> 0
A11: ='明细表I4-2'!$A16 -> 0 | B11: =SUMIF('明细表I4-2'!$A:$A,$A11,'明细表I4-2'!O:O) -> 0 | C11: =SUMIF('明细表I4-2'!$A:$A,$A11,'明细表I4-2'!P:P) -> 0 | D11: =SUMIF('明细表I4-2'!$A:$A,$A11,'明细表I4-2'!Q:Q) -> 0 | E11: =SUMIF('明细表I4-2'!$A:$A,$A11,'明细表I4-2'!R:R) -> 0 | F11: =B11+C11-D11-E11 -> 0
A12: 合 计 | B12: =SUM(B6:B11) -> 0 | C12: =SUM(C6:C11) -> 0 | D12: =SUM(D6:D11) -> 0 | E12: =SUM(E6:E11) -> 0 | F12: =SUM(F6:F11) -> 0

Sheet 明细表I4-2
A1: 致同会计师事务所
A2: 长期待摊费用明细表
A3: =底稿目录!A2 -> 被审计单位： | K3: =底稿目录!A4 -> 编制人： | O3: =底稿目录!A5 -> 编制日期： | T3: 索引号： | U3: I4-2
A4: =底稿目录!A3 -> 截止日：202X年12月31日 | K4: =底稿目录!A6 -> 复核人： | O4: =底稿目录!A7 -> 复核日期： | T4: 页次：
A5: 一、审计目标:
A6: 核对明细账、总账、报表、上年审计报告审定数金额是否相符，确定期初、期末余额是否正确。
A7: 二、审计过程：
A8: 项目名称 | B8: 类别 | C8: 资产类型 | D8: 项目编码 | E8: 初始入账金额 | F8: 未审数 | K8: 期初调整 | L8: 账项调整 | O8: 审定数 | T8: 合同协议等索引号 | U8: 备注
F9: 期初数 | G9: 本期增加 | H9: 本期减少 | J9: 期末数 | K9: 账项调整 | L9: 本期增加 | M9: 本期减少 | O9: 期初数 | P9: 本期增加 | Q9: 本期减少 | S9: 期末数
H10: 本期摊销 | I10: 其他减少 | M10: 本期摊销 | N10: 其他减少 | Q10: 本期摊销 | R10: 其他减少
A11: 使用权资产改良及维护支出 | J11: =F11+G11-H11-I11 -> 0 | O11: =F11+K11 -> 0 | P11: =G11+L11 -> 0 | Q11: =H11+M11 -> 0 | R11: =I11+N11 -> 0 | S11: =O11+P11-Q11-R11 -> 0
J12: =F12+G12-H12-I12 -> 0 | O12: =F12+K12 -> 0 | P12: =G12+L12 -> 0 | Q12: =H12+M12 -> 0 | R12: =I12+N12 -> 0 | S12: =O12+P12-Q12-R12 -> 0
J13: =F13+G13-H13-I13 -> 0 | O13: =F13+K13 -> 0 | P13: =G13+L13 -> 0 | Q13: =H13+M13 -> 0 | R13: =I13+N13 -> 0 | S13: =O13+P13-Q13-R13 -> 0
J14: =F14+G14-H14-I14 -> 0 | O14: =F14+K14 -> 0 | P14: =G14+L14 -> 0 | Q14: =H14+M14 -> 0 | R14: =I14+N14 -> 0 | S14: =O14+P14-Q14-R14 -> 0
J15: =F15+G15-H15-I15 -> 0 | O15: =F15+K15 -> 0 | P15: =G15+L15 -> 0 | Q15: =H15+M15 -> 0 | R15: =I15+N15 -> 0 | S15: =O15+P15-Q15-R15 -> 0
J16: =F16+G16-H16-I16 -> 0 | O16: =F16+K16 -> 0 | P16: =G16+L16 -> 0 | Q16: =H16+M16 -> 0 | R16: =I16+N16 -> 0 | S16: =O16+P16-Q16-R16 -> 0
J17: =F17+G17-H17-I17 -> 0 | O17: =F17+K17 -> 0 | P17: =G17+L17 -> 0 | Q17: =H17+M17 -> 0 | R17: =I17+N17 -> 0 | S17: =O17+P17-Q17-R17 -> 0
J18: =F18+G18-H18-I18 -> 0 | O18: =F18+K18 -> 0 | P18: =G18+L18 -> 0 | Q18: =H18+M18 -> 0 | R18: =I18+N18 -> 0 | S18: =O18+P18-Q18-R18 -> 0
J19: =F19+G19-H19-I19 -> 0 | O19: =F19+K19 -> 0 | P19: =G19+L19 -> 0 | Q19: =H19+M19 -> 0 | R19: =I19+N19 -> 0 | S19: =O19+P19-Q19-R19 -> 0 | V19: =K23+L23-M23-N23 -> 0
J20: =F20+G20-H20-I20 -> 0 | O20: =F20+K20 -> 0 | P20: =G20+L20 -> 0 | Q20: =H20+M20 -> 0 | R20: =I20+N20 -> 0 | S20: =O20+P20-Q20-R20 -> 0
J21: =F21+G21-H21-I21 -> 0 | O21: =F21+K21 -> 0 | P21: =G21+L21 -> 0 | Q21: =H21+M21 -> 0 | R21: =I21+N21 -> 0 | S21: =O21+P21-Q21-R21 -> 0
J22: =F22+G22-H22-I22 -> 0 | O22: =F22+K22 -> 0 | P22: =G22+L22 -> 0 | Q22: =H22+M22 -> 0 | R22: =I22+N22 -> 0 | S22: =O22+P22-Q22-R22 -> 0
A23: 合计 | E23: =SUM(E11:E22) -> 0 | F23: =SUM(F11:F22) -> 0 | G23: =SUM(G11:G22) -> 0 | H23: =SUM(H11:H22) -> 0 | I23: =SUM(I11:I22) -> 0 | J23: =SUM(J11:J22) -> 0 | K23: =SUM(K11:K22) -> 0 | L23: =SUM(L11:L22) -> 0 | ... S23: =SUM(S11:S22) -> 0
A24: 其中：
A25: =底稿目录!A9 -> 类别A | E25: {=SUMPRODUCT(($B$11:$B$22=$A25)*(E$11:E$22))} -> 0 | F25: {=SUMPRODUCT(($B$11:$B$22=$A25)*(F$11:F$22))} -> 0 | G25: {=SUMPRODUCT(($B$11:$B$22=$A25)*(G$11:G$22))} -> 0 | H25: {=SUMPRODUCT(($B$11:$B$22=$A25)*(H$11:H$22))} -> 0 | I25: {=SUMPRODUCT(($B$11:$B$22=$A25)*(I$11:I$22))} -> 0 | J25: {=SUMPRODUCT(($B$11:$B$22=$A25)*(J$11:J$22))} -> 0 | K25: {=SUMPRODUCT(($B$11:$B$22=$A25)*(K$11:K$22))} -> 0 | L25: {=SUMPRODUCT(($B$11:$B$22=$A25)*(L$11:L$22))} -> 0 | ... S25: {=SUMPRODUCT(($B$11:$B$22=$A25)*(S$11:S$22))} -> 0
A26: =底稿目录!A10 -> 类别B | E26: {=SUMPRODUCT(($B$11:$B$22=$A26)*(E$11:E$22))} -> 0 | F26: {=SUMPRODUCT(($B$11:$B$22=$A26)*(F$11:F$22))} -> 0 | G26: {=SUMPRODUCT(($B$11:$B$22=$A26)*(G$11:G$22))} -> 0 | H26: {=SUMPRODUCT(($B$11:$B$22=$A26)*(H$11:H$22))} -> 0 | I26: {=SUMPRODUCT(($B$11:$B$22=$A26)*(I$11:I$22))} -> 0 | J26: {=SUMPRODUCT(($B$11:$B$22=$A26)*(J$11:J$22))} -> 0 | K26: {=SUMPRODUCT(($B$11:$B$22=$A26)*(K$11:K$22))} -> 0 | L26: {=SUMPRODUCT(($B$11:$B$22=$A26)*(L$11:L$22))} -> 0 | ... S26: {=SUMPRODUCT(($B$11:$B$22=$A26)*(S$11:S$22))} -> 0
A27: =底稿目录!A11 -> 类别C | E27: {=SUMPRODUCT(($B$11:$B$22=$A27)*(E$11:E$22))} -> 0 | F27: {=SUMPRODUCT(($B$11:$B$22=$A27)*(F$11:F$22))} -> 0 | G27: {=SUMPRODUCT(($B$11:$B$22=$A27)*(G$11:G$22))} -> 0 | H27: {=SUMPRODUCT(($B$11:$B$22=$A27)*(H$11:H$22))} -> 0 | I27: {=SUMPRODUCT(($B$11:$B$22=$A27)*(I$11:I$22))} -> 0 | J27: {=SUMPRODUCT(($B$11:$B$22=$A27)*(J$11:J$22))} -> 0 | K27: {=SUMPRODUCT(($B$11:$B$22=$A27)*(K$11:K$22))} -> 0 | L27: {=SUMPRODUCT(($B$11:$B$22=$A27)*(L$11:L$22))} -> 0 | ... S27: {=SUMPRODUCT(($B$11:$B$22=$A27)*(S$11:S$22))} -> 0
A28: =底稿目录!A12 -> …… | E28: {=SUMPRODUCT(($B$11:$B$22=$A28)*(E$11:E$22))} -> 0 | F28: {=SUMPRODUCT(($B$11:$B$22=$A28)*(F$11:F$22))} -> 0 | G28: {=SUMPRODUCT(($B$11:$B$22=$A28)*(G$11:G$22))} -> 0 | H28: {=SUMPRODUCT(($B$11:$B$22=$A28)*(H$11:H$22))} -> 0 | I28: {=SUMPRODUCT(($B$11:$B$22=$A28)*(I$11:I$22))} -> 0 | J28: {=SUMPRODUCT(($B$11:$B$22=$A28)*(J$11:J$22))} -> 0 | K28: {=SUMPRODUCT(($B$11:$B$22=$A28)*(K$11:K$22))} -> 0 | L28: {=SUMPRODUCT(($B$11:$B$22=$A28)*(L$11:L$22))} -> 0 | ... S28: {=SUMPRODUCT(($B$11:$B$22=$A28)*(S$11:S$22))} -> 0
A29: 三、审计说明：
A32: 四、审计结论
A35: 编制说明：
A36: 1、本科目核算企业已经发生但应由本期和以后各期负担的分摊期限在1年以上的各项费用，如以经营租赁方式租入的固定资产发生的改良支出等。
A37: 2、自有固定资产发生的改良支出，可以作为固定资产核算，也可以作为长期待摊费用核算。
A38: 3、关注是否应确认为资产（可带来未来收益）。
A39: 4、企业在筹建期间内发生的开办费，包括人员工资、办公费、培训费、差旅费、印刷费、注册登记费等在实际发生时，借记“管理费用-开办费”。
A40: 5、首次执行日企业的开办费余额，应当在首次执行日后第一个会计期间内全部确认为管理费用。
A42: 《企业所得税法》
A43: 第十三条在计算应纳税所得额时，企业发生的下列支出，作为长期待摊费用，按照规定摊销的，准予扣除：
A44: (一)已足额提取折旧的固定资产的改建支出；
A45: (二)租入固定资产的改建支出；
...

Sheet 调整分录汇总I4-3
A1: 致同会计师事务所
A2: 长期待摊费用调整分录汇总表
A3: =底稿目录!A2 -> 被审计单位： | D3: =底稿目录!A4 -> 编制人： | F3: =底稿目录!A5 -> 编制日期： | I3: 索引号： | J3: I4-3
A4: =底稿目录!A3 -> 截止日：202X年12月31日 | D4: =底稿目录!A6 -> 复核人： | F4: =底稿目录!A7 -> 复核日期： | I4: 页次：
A5: 调整事项说明 | B5: 类别（报表调整/账项调整/其他） | C5: 报表项目 | D5: 科目名称 | E5: 附注项目 | F5: …… | G5: 借方调整金额 | H5: 贷方调整金额 | I5: 索引 | J5: 备注
A22: 【注：本底稿适用于调整分录较多、较复杂的项目，且仅列示与本报表项目相关的审计调整。项目组可根据项目实际情况选择是否使用该底稿。】

Sheet 摊销政策检查表I4-4
A1: 致同会计师事务所
A2: 摊销政策检查表
A3: =底稿目录!A2 -> 被审计单位： | D3: =底稿目录!A4 -> 编制人： | G3: =底稿目录!A5 -> 编制日期： | I3: 索引号： | J3: I4-4
A4: =底稿目录!A3 -> 截止日：202X年12月31日 | D4: =底稿目录!A6 -> 复核人： | G4: =底稿目录!A7 -> 复核日期： | I4: 页次：
A5: 一、审计目标:
A6: 判断长期待摊费用相关重大会计政策和会计估计合理性检查
A7: 二、审计过程：
A8: 1、被审计单位的长期待摊费用摊销政策：
A11: 2、同行业其他公司的长期待摊费用摊销政策（如适用）
A14: 3、如本期存在会计估计变更，原会计估计如下：
A17: 三、审计说明：
A19: 四、审计结论：

Sheet 针对性检查表I4-5
A1: 致同会计师事务所
A2: 长期待摊费用针对性检查表
A3: =底稿目录!A2 -> 被审计单位： | F3: =底稿目录!A4 -> 编制人： | I3: =底稿目录!A5 -> 编制日期： | P3: 索引号： | Q3: I4-5
A4: =底稿目录!A3 -> 截止日：202X年12月31日 | F4: =底稿目录!A6 -> 复核人： | I4: =底稿目录!A7 -> 复核日期： | P4: 页次：
A5: 一、测试目标：
A6: 通过针对性测试，验证长期待摊费用的存在/发生、所有权、计价和分摊。
A7: 二、样本选取标准与规模：
A8: 测试总体： | B8: 如贷方发生额所有凭证共XX笔金额XX | G8: 特定样本： | H8: XX金额以上（大额）、关联方/关联交易形成的款项、XX异常款项全部测试，共XX笔
A9: 抽样总体： | B9: 测试总体扣除特定样本以外的样本，共XX笔、金额XX | G9: 确定的抽样样本量： | I9: 抽取XX笔（如果使用了样本计算器计算样本量，样本量计算过程见<XX>底稿）
A10: 抽样方法： | B10: 随机选样/系统选样/货币单元抽样/随意选样（非统计抽样适用） | G10: 抽样过程： | H10: 使用IDEA（XX抽样工具）选择XX数量、金额XX的样本进行测试，抽样工具中的样本选择过程和结果见<XX>底稿
A11: 三、测试：
A12: 测试内容说明：1.原始凭证是否齐全； 2.记账凭证与原始凭证是否相符；3.账务处理是否正确；4.是否记录于恰当的会计期间；5.……
A13: 记账凭证 | I13: 支持性文件 | J13: 核对内容 | O13: 索引号 | P13: 是否异常 | Q13: 备注说明
A14: 项目明细 | B14: 日期 | C14: 凭证编号 | D14: 业务内容 | E14: 对方科目 | F14: 对方明细科目 | G14: 借方金额 | H14: 贷方金额 | J14: 1 | K14: 2 | L14: 3 | M14: 4 | N14: 5
A26: 合计 | G26: =SUM(G15:G25) -> 0 | H26: =SUM(H15:H25) -> 0
A27: 本期发生额 | G27: ='明细表I4-2'!P23 -> 0 | H27: ='明细表I4-2'!R23 -> 0
A28: 检查比例 | G28: =G26/G27 -> #DIV/0! | H28: =H26/H27 -> #DIV/0!
A29: 四、审计说明：
A32: 五、审计结论：

Sheet 摊销测算I4-6
A1: 致同会计师事务所
A2: 长期待摊费用摊销测算表
A3: =底稿目录!A2 -> 被审计单位： | E3: =底稿目录!A4 -> 编制人： | L3: =底稿目录!A5 -> 编制日期： | P3: 索引号： | Q3: I4-6
A4: =底稿目录!A3 -> 截止日：202X年12月31日 | E4: =底稿目录!A6 -> 复核人： | L4: =底稿目录!A7 -> 复核日期： | P4: 页次：
A5: 一、审计目标:
A6: 检查长期待摊费用的摊销是否正确。
A7: 二、审计过程：
A8: 摊销期初： | B8: 41640 | C8: 摊销期末： | D8: 42004
A9: 类别名称 | B9: 明细项目 | C9: 原值 | D9: 累计摊销 | E9: 开始使用日期 | F9: 使用年限 | G9: 账面月摊销额 | H9: 使用月限 | I9: 测算到期日 | J9: 已摊销月份 | K9: 剩余摊销月份 | L9: 本期摊销月份 | M9: 测算月摊销额 | N9: 当期摊销 | O9: 月摊销额差异 | P9: 累计摊销费用 | Q9: 累计摊销额差异
B10: ='明细表I4-2'!A11 -> 使用权资产改良及维护支出 | H10: =IF(F10=0,0,IF(RIGHT(F10,1)<>"年",F10*12,IF(LEN(F10)=3,VALUE(LEFT(F10,2))*12,IF(LEN(F10)=2,VALUE(LEFT(F10,1))*12,"??")))) -> 0 | I10: =IF(E10=0,0,DATE(YEAR(E10),MONTH(E10)+H10,DAY(E10)-1)) -> 0 | J10: =IF(E10=0,0,IF(I10>$D$8,VALUE(DATEDIF(E10,MIN($D$8,I10),"m")+1),VALUE(DATEDIF(E10,MIN($D$8,I10),"m")+1))) -> 0 | K10: =(H10-J10) -> 0 | L10: =IF(E10=0,0,IF(AND(E10<=$B$8,I10>$D$8),VALUE(DATEDIF($B$8,$D$8,"m")+1),IF(AND(E10<=$B$8,I10<=$D$8),VALUE(DATEDIF($B$8,I10,"m")),IF(AND(E10>$B$8,I10>$D$8),VALUE(DATEDIF(E10,$D$8,"m")+1),IF(AND(E10>=$B$8,I10<=$D$8),VALUE(DATEDIF(E10,I10,"m")+1),))))) -> 0 | M10: =IF(H10=0,0,ROUND(((1-0)/H10)*C10,4)) -> 0 | N10: =ROUND(M10*L10,2) -> 0 | O10: =ROUND(G10-M10,2) -> 0 | P10: =ROUND(M10*J10,2) -> 0 | Q10: =ROUND(D10-P10,2) -> 0 | R10: 非专利技术
B11: ='明细表I4-2'!A12 -> 0 | H11: =IF(F11=0,0,IF(RIGHT(F11,1)<>"年",F11*12,IF(LEN(F11)=3,VALUE(LEFT(F11,2))*12,IF(LEN(F11)=2,VALUE(LEFT(F11,1))*12,"??")))) -> 0 | I11: =IF(E11=0,0,DATE(YEAR(E11),MONTH(E11)+H11,DAY(E11)-1)) -> 0 | J11: =IF(E11=0,0,IF(I11>$D$8,VALUE(DATEDIF(E11,MIN($D$8,I11),"m")+1),VALUE(DATEDIF(E11,MIN($D$8,I11),"m")+1))) -> 0 | K11: =(H11-J11) -> 0 | L11: =IF(E11=0,0,IF(AND(E11<=$B$8,I11>$D$8),VALUE(DATEDIF($B$8,$D$8,"m")+1),IF(AND(E11<=$B$8,I11<=$D$8),VALUE(DATEDIF($B$8,I11,"m")),IF(AND(E11>$B$8,I11>$D$8),VALUE(DATEDIF(E11,$D$8,"m")+1),IF(AND(E11>=$B$8,I11<=$D$8),VALUE(DATEDIF(E11,I11,"m")+1),))))) -> 0 | M11: =IF(H11=0,0,ROUND(((1-0)/H11)*C11,4)) -> 0 | N11: =ROUND(M11*L11,2) -> 0 | O11: =ROUND(G11-M11,2) -> 0 | P11: =ROUND(M11*J11,2) -> 0 | Q11: =ROUND(D11-P11,2) -> 0 | R11: 商标权
B12: ='明细表I4-2'!A13 -> 0 | H12: =IF(F12=0,0,IF(RIGHT(F12,1)<>"年",F12*12,IF(LEN(F12)=3,VALUE(LEFT(F12,2))*12,IF(LEN(F12)=2,VALUE(LEFT(F12,1))*12,"??")))) -> 0 | I12: =IF(E12=0,0,DATE(YEAR(E12),MONTH(E12)+H12,DAY(E12)-1)) -> 0 | J12: =IF(E12=0,0,IF(I12>$D$8,VALUE(DATEDIF(E12,MIN($D$8,I12),"m")+1),VALUE(DATEDIF(E12,MIN($D$8,I12),"m")+1))) -> 0 | K12: =(H12-J12) -> 0 | L12: =IF(E12=0,0,IF(AND(E12<=$B$8,I12>$D$8),VALUE(DATEDIF($B$8,$D$8,"m")+1),IF(AND(E12<=$B$8,I12<=$D$8),VALUE(DATEDIF($B$8,I12,"m")),IF(AND(E12>$B$8,I12>$D$8),VALUE(DATEDIF(E12,$D$8,"m")+1),IF(AND(E12>=$B$8,I12<=$D$8),VALUE(DATEDIF(E12,I12,"m")+1),))))) -> 0 | M12: =IF(H12=0,0,ROUND(((1-0)/H12)*C12,4)) -> 0 | N12: =ROUND(M12*L12,2) -> 0 | O12: =ROUND(G12-M12,2) -> 0 | P12: =ROUND(M12*J12,2) -> 0 | Q12: =ROUND(D12-P12,2) -> 0 | R12: 著作权
B13: ='明细表I4-2'!A14 -> 0 | H13: =IF(F13=0,0,IF(RIGHT(F13,1)<>"年",F13*12,IF(LEN(F13)=3,VALUE(LEFT(F13,2))*12,IF(LEN(F13)=2,VALUE(LEFT(F13,1))*12,"??")))) -> 0 | I13: =IF(E13=0,0,DATE(YEAR(E13),MONTH(E13)+H13,DAY(E13)-1)) -> 0 | J13: =IF(E13=0,0,IF(I13>$D$8,VALUE(DATEDIF(E13,MIN($D$8,I13),"m")+1),VALUE(DATEDIF(E13,MIN($D$8,I13),"m")+1))) -> 0 | K13: =(H13-J13) -> 0 | L13: =IF(E13=0,0,IF(AND(E13<=$B$8,I13>$D$8),VALUE(DATEDIF($B$8,$D$8,"m")+1),IF(AND(E13<=$B$8,I13<=$D$8),VALUE(DATEDIF($B$8,I13,"m")),IF(AND(E13>$B$8,I13>$D$8),VALUE(DATEDIF(E13,$D$8,"m")+1),IF(AND(E13>=$B$8,I13<=$D$8),VALUE(DATEDIF(E13,I13,"m")+1),))))) -> 0 | M13: =IF(H13=0,0,ROUND(((1-0)/H13)*C13,4)) -> 0 | N13: =ROUND(M13*L13,2) -> 0 | O13: =ROUND(G13-M13,2) -> 0 | P13: =ROUND(M13*J13,2) -> 0 | Q13: =ROUND(D13-P13,2) -> 0 | R13: 土地使用权
B14: ='明细表I4-2'!A15 -> 0 | H14: =IF(F14=0,0,IF(RIGHT(F14,1)<>"年",F14*12,IF(LEN(F14)=3,VALUE(LEFT(F14,2))*12,IF(LEN(F14)=2,VALUE(LEFT(F14,1))*12,"??")))) -> 0 | I14: =IF(E14=0,0,DATE(YEAR(E14),MONTH(E14)+H14,DAY(E14)-1)) -> 0 | J14: =IF(E14=0,0,IF(I14>$D$8,VALUE(DATEDIF(E14,MIN($D$8,I14),"m")+1),VALUE(DATEDIF(E14,MIN($D$8,I14),"m")+1))) -> 0 | K14: =(H14-J14) -> 0 | L14: =IF(E14=0,0,IF(AND(E14<=$B$8,I14>$D$8),VALUE(DATEDIF($B$8,$D$8,"m")+1),IF(AND(E14<=$B$8,I14<=$D$8),VALUE(DATEDIF($B$8,I14,"m")),IF(AND(E14>$B$8,I14>$D$8),VALUE(DATEDIF(E14,$D$8,"m")+1),IF(AND(E14>=$B$8,I14<=$D$8),VALUE(DATEDIF(E14,I14,"m")+1),))))) -> 0 | M14: =IF(H14=0,0,ROUND(((1-0)/H14)*C14,4)) -> 0 | N14: =ROUND(M14*L14,2) -> 0 | O14: =ROUND(G14-M14,2) -> 0 | P14: =ROUND(M14*J14,2) -> 0 | Q14: =ROUND(D14-P14,2) -> 0
B15: ='明细表I4-2'!A16 -> 0 | H15: =IF(F15=0,0,IF(RIGHT(F15,1)<>"年",F15*12,IF(LEN(F15)=3,VALUE(LEFT(F15,2))*12,IF(LEN(F15)=2,VALUE(LEFT(F15,1))*12,"??")))) -> 0 | I15: =IF(E15=0,0,DATE(YEAR(E15),MONTH(E15)+H15,DAY(E15)-1)) -> 0 | J15: =IF(E15=0,0,IF(I15>$D$8,VALUE(DATEDIF(E15,MIN($D$8,I15),"m")+1),VALUE(DATEDIF(E15,MIN($D$8,I15),"m")+1))) -> 0 | K15: =(H15-J15) -> 0 | L15: =IF(E15=0,0,IF(AND(E15<=$B$8,I15>$D$8),VALUE(DATEDIF($B$8,$D$8,"m")+1),IF(AND(E15<=$B$8,I15<=$D$8),VALUE(DATEDIF($B$8,I15,"m")),IF(AND(E15>$B$8,I15>$D$8),VALUE(DATEDIF(E15,$D$8,"m")+1),IF(AND(E15>=$B$8,I15<=$D$8),VALUE(DATEDIF(E15,I15,"m")+1),))))) -> 0 | M15: =IF(H15=0,0,ROUND(((1-0)/H15)*C15,4)) -> 0 | N15: =ROUND(M15*L15,2) -> 0 | O15: =ROUND(G15-M15,2) -> 0 | P15: =ROUND(M15*J15,2) -> 0 | Q15: =ROUND(D15-P15,2) -> 0
B16: ='明细表I4-2'!A17 -> 0 | H16: =IF(F16=0,0,IF(RIGHT(F16,1)<>"年",F16*12,IF(LEN(F16)=3,VALUE(LEFT(F16,2))*12,IF(LEN(F16)=2,VALUE(LEFT(F16,1))*12,"??")))) -> 0 | I16: =IF(E16=0,0,DATE(YEAR(E16),MONTH(E16)+H16,DAY(E16)-1)) -> 0 | J16: =IF(E16=0,0,IF(I16>$D$8,VALUE(DATEDIF(E16,MIN($D$8,I16),"m")+1),VALUE(DATEDIF(E16,MIN($D$8,I16),"m")+1))) -> 0 | K16: =(H16-J16) -> 0 | L16: =IF(E16=0,0,IF(AND(E16<=$B$8,I16>$D$8),VALUE(DATEDIF($B$8,$D$8,"m")+1),IF(AND(E16<=$B$8,I16<=$D$8),VALUE(DATEDIF($B$8,I16,"m")),IF(AND(E16>$B$8,I16>$D$8),VALUE(DATEDIF(E16,$D$8,"m")+1),IF(AND(E16>=$B$8,I16<=$D$8),VALUE(DATEDIF(E16,I16,"m")+1),))))) -> 0 | M16: =IF(H16=0,0,ROUND(((1-0)/H16)*C16,4)) -> 0 | N16: =ROUND(M16*L16,2) -> 0 | O16: =ROUND(G16-M16,2) -> 0 | P16: =ROUND(M16*J16,2) -> 0 | Q16: =ROUND(D16-P16,2) -> 0
B17: ='明细表I4-2'!A18 -> 0 | H17: =IF(F17=0,0,IF(RIGHT(F17,1)<>"年",F17*12,IF(LEN(F17)=3,VALUE(LEFT(F17,2))*12,IF(LEN(F17)=2,VALUE(LEFT(F17,1))*12,"??")))) -> 0 | I17: =IF(E17=0,0,DATE(YEAR(E17),MONTH(E17)+H17,DAY(E17)-1)) -> 0 | J17: =IF(E17=0,0,IF(I17>$D$8,VALUE(DATEDIF(E17,MIN($D$8,I17),"m")+1),VALUE(DATEDIF(E17,MIN($D$8,I17),"m")+1))) -> 0 | K17: =(H17-J17) -> 0 | L17: =IF(E17=0,0,IF(AND(E17<=$B$8,I17>$D$8),VALUE(DATEDIF($B$8,$D$8,"m")+1),IF(AND(E17<=$B$8,I17<=$D$8),VALUE(DATEDIF($B$8,I17,"m")),IF(AND(E17>$B$8,I17>$D$8),VALUE(DATEDIF(E17,$D$8,"m")+1),IF(AND(E17>=$B$8,I17<=$D$8),VALUE(DATEDIF(E17,I17,"m")+1),))))) -> 0 | M17: =IF(H17=0,0,ROUND(((1-0)/H17)*C17,4)) -> 0 | N17: =ROUND(M17*L17,2) -> 0 | O17: =ROUND(G17-M17,2) -> 0 | P17: =ROUND(M17*J17,2) -> 0 | Q17: =ROUND(D17-P17,2) -> 0
B18: ='明细表I4-2'!A19 -> 0 | H18: =IF(F18=0,0,IF(RIGHT(F18,1)<>"年",F18*12,IF(LEN(F18)=3,VALUE(LEFT(F18,2))*12,IF(LEN(F18)=2,VALUE(LEFT(F18,1))*12,"??")))) -> 0 | I18: =IF(E18=0,0,DATE(YEAR(E18),MONTH(E18)+H18,DAY(E18)-1)) -> 0 | J18: =IF(E18=0,0,IF(I18>$D$8,VALUE(DATEDIF(E18,MIN($D$8,I18),"m")+1),VALUE(DATEDIF(E18,MIN($D$8,I18),"m")+1))) -> 0 | K18: =(H18-J18) -> 0 | L18: =IF(E18=0,0,IF(AND(E18<=$B$8,I18>$D$8),VALUE(DATEDIF($B$8,$D$8,"m")+1),IF(AND(E18<=$B$8,I18<=$D$8),VALUE(DATEDIF($B$8,I18,"m")),IF(AND(E18>$B$8,I18>$D$8),VALUE(DATEDIF(E18,$D$8,"m")+1),IF(AND(E18>=$B$8,I18<=$D$8),VALUE(DATEDIF(E18,I18,"m")+1),))))) -> 0 | M18: =IF(H18=0,0,ROUND(((1-0)/H18)*C18,4)) -> 0 | N18: =ROUND(M18*L18,2) -> 0 | O18: =ROUND(G18-M18,2) -> 0 | P18: =ROUND(M18*J18,2) -> 0 | Q18: =ROUND(D18-P18,2) -> 0
B19: ='明细表I4-2'!A20 -> 0 | H19: =IF(F19=0,0,IF(RIGHT(F19,1)<>"年",F19*12,IF(LEN(F19)=3,VALUE(LEFT(F19,2))*12,IF(LEN(F19)=2,VALUE(LEFT(F19,1))*12,"??")))) -> 0 | I19: =IF(E19=0,0,DATE(YEAR(E19),MONTH(E19)+H19,DAY(E19)-1)) -> 0 | J19: =IF(E19=0,0,IF(I19>$D$8,VALUE(DATEDIF(E19,MIN($D$8,I19),"m")+1),VALUE(DATEDIF(E19,MIN($D$8,I19),"m")+1))) -> 0 | K19: =(H19-J19) -> 0 | L19: =IF(E19=0,0,IF(AND(E19<=$B$8,I19>$D$8),VALUE(DATEDIF($B$8,$D$8,"m")+1),IF(AND(E19<=$B$8,I19<=$D$8),VALUE(DATEDIF($B$8,I19,"m")),IF(AND(E19>$B$8,I19>$D$8),VALUE(DATEDIF(E19,$D$8,"m")+1),IF(AND(E19>=$B$8,I19<=$D$8),VALUE(DATEDIF(E19,I19,"m")+1),))))) -> 0 | M19: =IF(H19=0,0,ROUND(((1-0)/H19)*C19,4)) -> 0 | N19: =ROUND(M19*L19,2) -> 0 | O19: =ROUND(G19-M19,2) -> 0 | P19: =ROUND(M19*J19,2) -> 0 | Q19: =ROUND(D19-P19,2) -> 0
B20: ='明细表I4-2'!A21 -> 0 | H20: =IF(F20=0,0,IF(RIGHT(F20,1)<>"年",F20*12,IF(LEN(F20)=3,VALUE(LEFT(F20,2))*12,IF(LEN(F20)=2,VALUE(LEFT(F20,1))*12,"??")))) -> 0 | I20: =IF(E20=0,0,DATE(YEAR(E20),MONTH(E20)+H20,DAY(E20)-1)) -> 0 | J20: =IF(E20=0,0,IF(I20>$D$8,VALUE(DATEDIF(E20,MIN($D$8,I20),"m")+1),VALUE(DATEDIF(E20,MIN($D$8,I20),"m")+1))) -> 0 | K20: =(H20-J20) -> 0 | L20: =IF(E20=0,0,IF(AND(E20<=$B$8,I20>$D$8),VALUE(DATEDIF($B$8,$D$8,"m")+1),IF(AND(E20<=$B$8,I20<=$D$8),VALUE(DATEDIF($B$8,I20,"m")),IF(AND(E20>$B$8,I20>$D$8),VALUE(DATEDIF(E20,$D$8,"m")+1),IF(AND(E20>=$B$8,I20<=$D$8),VALUE(DATEDIF(E20,I20,"m")+1),))))) -> 0 | M20: =IF(H20=0,0,ROUND(((1-0)/H20)*C20,4)) -> 0 | N20: =ROUND(M20*L20,2) -> 0 | O20: =ROUND(G20-M20,2) -> 0 | P20: =ROUND(M20*J20,2) -> 0 | Q20: =ROUND(D20-P20,2) -> 0
B21: ='明细表I4-2'!A22 -> 0 | H21: =IF(F21=0,0,IF(RIGHT(F21,1)<>"年",F21*12,IF(LEN(F21)=3,VALUE(LEFT(F21,2))*12,IF(LEN(F21)=2,VALUE(LEFT(F21,1))*12,"??")))) -> 0 | I21: =IF(E21=0,0,DATE(YEAR(E21),MONTH(E21)+H21,DAY(E21)-1)) -> 0 | J21: =IF(E21=0,0,IF(I21>$D$8,VALUE(DATEDIF(E21,MIN($D$8,I21),"m")+1),VALUE(DATEDIF(E21,MIN($D$8,I21),"m")+1))) -> 0 | K21: =(H21-J21) -> 0 | L21: =IF(E21=0,0,IF(AND(E21<=$B$8,I21>$D$8),VALUE(DATEDIF($B$8,$D$8,"m")+1),IF(AND(E21<=$B$8,I21<=$D$8),VALUE(DATEDIF($B$8,I21,"m")),IF(AND(E21>$B$8,I21>$D$8),VALUE(DATEDIF(E21,$D$8,"m")+1),IF(AND(E21>=$B$8,I21<=$D$8),VALUE(DATEDIF(E21,I21,"m")+1),))))) -> 0 | M21: =IF(H21=0,0,ROUND(((1-0)/H21)*C21,4)) -> 0 | N21: =ROUND(M21*L21,2) -> 0 | O21: =ROUND(G21-M21,2) -> 0 | P21: =ROUND(M21*J21,2) -> 0 | Q21: =ROUND(D21-P21,2) -> 0
A22: 合计 | C22: =SUM(C10:C21) -> 0 | D22: =SUM(D10:D21) -> 0 | G22: =SUM(G10:G21) -> 0 | M22: =SUM(M10:M21) -> 0 | N22: =SUM(N10:N21) -> 0 | O22: =SUM(O10:O21) -> 0 | P22: =SUM(P10:P21) -> 0 | Q22: =SUM(Q10:Q21) -> 0
A23: 其中：
A24: =底稿目录!A9 -> 类别A | C24: {=SUMPRODUCT(($A$10:$A$21=$A24)*(C$10:C$21))} -> 0 | D24: {=SUMPRODUCT(($A$10:$A$21=$A24)*(D$10:D$21))} -> 0 | M24: {=SUMPRODUCT(($A$10:$A$21=$A24)*(M$10:M$21))} -> 0 | N24: {=SUMPRODUCT(($A$10:$A$21=$A24)*(N$10:N$21))} -> 0 | O24: {=SUMPRODUCT(($A$10:$A$21=$A24)*(O$10:O$21))} -> 0 | P24: {=SUMPRODUCT(($A$10:$A$21=$A24)*(P$10:P$21))} -> 0 | Q24: {=SUMPRODUCT(($A$10:$A$21=$A24)*(Q$10:Q$21))} -> 0
A25: =底稿目录!A10 -> 类别B | C25: {=SUMPRODUCT(($A$10:$A$21=$A25)*(C$10:C$21))} -> 0 | D25: {=SUMPRODUCT(($A$10:$A$21=$A25)*(D$10:D$21))} -> 0 | M25: {=SUMPRODUCT(($A$10:$A$21=$A25)*(M$10:M$21))} -> 0 | N25: {=SUMPRODUCT(($A$10:$A$21=$A25)*(N$10:N$21))} -> 0 | O25: {=SUMPRODUCT(($A$10:$A$21=$A25)*(O$10:O$21))} -> 0 | P25: {=SUMPRODUCT(($A$10:$A$21=$A25)*(P$10:P$21))} -> 0 | Q25: {=SUMPRODUCT(($A$10:$A$21=$A25)*(Q$10:Q$21))} -> 0
A26: =底稿目录!A11 -> 类别C | C26: {=SUMPRODUCT(($A$10:$A$21=$A26)*(C$10:C$21))} -> 0 | D26: {=SUMPRODUCT(($A$10:$A$21=$A26)*(D$10:D$21))} -> 0 | M26: {=SUMPRODUCT(($A$10:$A$21=$A26)*(M$10:M$21))} -> 0 | N26: {=SUMPRODUCT(($A$10:$A$21=$A26)*(N$10:N$21))} -> 0 | O26: {=SUMPRODUCT(($A$10:$A$21=$A26)*(O$10:O$21))} -> 0 | P26: {=SUMPRODUCT(($A$10:$A$21=$A26)*(P$10:P$21))} -> 0 | Q26: {=SUMPRODUCT(($A$10:$A$21=$A26)*(Q$10:Q$21))} -> 0
A27: =底稿目录!A12 -> …… | C27: {=SUMPRODUCT(($A$10:$A$21=$A27)*(C$10:C$21))} -> 0 | D27: {=SUMPRODUCT(($A$10:$A$21=$A27)*(D$10:D$21))} -> 0 | M27: {=SUMPRODUCT(($A$10:$A$21=$A27)*(M$10:M$21))} -> 0 | N27: {=SUMPRODUCT(($A$10:$A$21=$A27)*(N$10:N$21))} -> 0 | O27: {=SUMPRODUCT(($A$10:$A$21=$A27)*(O$10:O$21))} -> 0 | P27: {=SUMPRODUCT(($A$10:$A$21=$A27)*(P$10:P$21))} -> 0 | Q27: {=SUMPRODUCT(($A$10:$A$21=$A27)*(Q$10:Q$21))} -> 0
A28: 三、审计说明：
A30: 四、审计结论
A32: 编制说明：
A33: 1、使用寿命有限的无形资产应当摊销，使用寿命不确定的无形资产不予摊销。
A34: 2、来源于合同性权利或其他法定权利的无形资产，其使用寿命不应超过合同性权利或其他法定权利的期限；
A35: 合同性权利或其他法定权利在到期时因续约等延续、且有证据表明企业续约不需要付出大额成本的，续约期应当计入使用寿命。
A36: 3、合同或法律没有规定使用寿命的，企业应当综合各方面因素判断，以确定无形资产能为企业带来经济利益的期限。
A37: 4、按照上述方法仍无法合理确定无形资产为企业带来经济利益期限的，该项无形资产应作为使用寿命不确定的无形资产。
A38: 5、无形资产的摊销金额一般应当计入当期损益。某项无形资产包含的经济利益通过所生产的产品或其他资产实现的，其摊销金额应当计入相关资产的成本。
A62: 《企业所得税法实施条例》
A63: 第六十七条 无形资产按照直线法计算的摊销费用，准予扣除。
A64: 无形资产的摊销年限不得低于10年。
A65: 作为投资或者受让的无形资产，有关法律规定或者合同约定了使用年限的，可以按照规定或者约定的使用年限分期摊销。

Sheet 摊销测算表I4-7（工作量法）
A1: 致同会计师事务所
A2: 长期待摊费用摊销测算表
A3: =底稿目录!A2 -> 被审计单位： | F3: =底稿目录!A4 -> 编制人： | J3: =底稿目录!A5 -> 编制日期： | M3: 索引号： | N3: I4-7
A4: =底稿目录!A3 -> 截止日：202X年12月31日 | F4: =底稿目录!A6 -> 复核人： | J4: =底稿目录!A7 -> 复核日期： | M4: 页次：
A5: 一、审计目标:
A6: 确认长期待摊费用本期摊销金额是否合理。
A7: 二、审计过程：
A8: 类别名称 | B8: 明细项目 | C8: 原值 | D8: 开始使用日期 | E8: 工作标准 | G8: 工作量 | I8: 测算摊销额 | K8: 账面摊销额 | M8: 摊销额差异
F9: 摊销标准 | G9: 本期 | H9: 累计 | I9: 测算本年摊销额 | J9: 测算累计摊销额 | K9: 本期 | L9: 累计 | M9: 本期 | N9: 累计
B10: ='明细表I4-2'!A11 -> 使用权资产改良及维护支出 | I10: =G10*F10 -> 0 | J10: =H10*F10 -> 0 | M10: =I10-K10 -> 0 | N10: =J10-L10 -> 0 | O10: 非专利技术
B11: ='明细表I4-2'!A12 -> 0 | I11: =G11*F11 -> 0 | J11: =IF(D11=0,0,IF(#REF!>#REF!,VALUE(DATEDIF(D11,MIN(#REF!,#REF!),"m")+1),VALUE(DATEDIF(D11,MIN(#REF!,#REF!),"m")+1))) -> 0 | M11: =I11-K11 -> 0 | N11: =J11-L11 -> 0 | O11: 商标权
B12: ='明细表I4-2'!A13 -> 0 | I12: =G12*F12 -> 0 | J12: =IF(D12=0,0,IF(#REF!>#REF!,VALUE(DATEDIF(D12,MIN(#REF!,#REF!),"m")+1),VALUE(DATEDIF(D12,MIN(#REF!,#REF!),"m")+1))) -> 0 | M12: =I12-K12 -> 0 | N12: =J12-L12 -> 0 | O12: 著作权
B13: ='明细表I4-2'!A14 -> 0 | I13: =G13*F13 -> 0 | J13: =IF(D13=0,0,IF(#REF!>#REF!,VALUE(DATEDIF(D13,MIN(#REF!,#REF!),"m")+1),VALUE(DATEDIF(D13,MIN(#REF!,#REF!),"m")+1))) -> 0 | M13: =I13-K13 -> 0 | N13: =J13-L13 -> 0 | O13: 土地使用权
B14: ='明细表I4-2'!A15 -> 0 | I14: =G14*F14 -> 0 | J14: =IF(D14=0,0,IF(#REF!>#REF!,VALUE(DATEDIF(D14,MIN(#REF!,#REF!),"m")+1),VALUE(DATEDIF(D14,MIN(#REF!,#REF!),"m")+1))) -> 0 | M14: =I14-K14 -> 0 | N14: =J14-L14 -> 0
B15: ='明细表I4-2'!A16 -> 0 | I15: =G15*F15 -> 0 | J15: =IF(D15=0,0,IF(#REF!>#REF!,VALUE(DATEDIF(D15,MIN(#REF!,#REF!),"m")+1),VALUE(DATEDIF(D15,MIN(#REF!,#REF!),"m")+1))) -> 0 | M15: =I15-K15 -> 0 | N15: =J15-L15 -> 0
B16: ='明细表I4-2'!A17 -> 0 | I16: =G16*F16 -> 0 | J16: =IF(D16=0,0,IF(#REF!>#REF!,VALUE(DATEDIF(D16,MIN(#REF!,#REF!),"m")+1),VALUE(DATEDIF(D16,MIN(#REF!,#REF!),"m")+1))) -> 0 | M16: =I16-K16 -> 0 | N16: =J16-L16 -> 0
B17: ='明细表I4-2'!A18 -> 0 | I17: =G17*F17 -> 0 | J17: =IF(D17=0,0,IF(#REF!>#REF!,VALUE(DATEDIF(D17,MIN(#REF!,#REF!),"m")+1),VALUE(DATEDIF(D17,MIN(#REF!,#REF!),"m")+1))) -> 0 | M17: =I17-K17 -> 0 | N17: =J17-L17 -> 0
B18: ='明细表I4-2'!A19 -> 0 | I18: =G18*F18 -> 0 | J18: =IF(D18=0,0,IF(#REF!>#REF!,VALUE(DATEDIF(D18,MIN(#REF!,#REF!),"m")+1),VALUE(DATEDIF(D18,MIN(#REF!,#REF!),"m")+1))) -> 0 | M18: =I18-K18 -> 0 | N18: =J18-L18 -> 0
B19: ='明细表I4-2'!A20 -> 0 | I19: =G19*F19 -> 0 | J19: =IF(D19=0,0,IF(#REF!>#REF!,VALUE(DATEDIF(D19,MIN(#REF!,#REF!),"m")+1),VALUE(DATEDIF(D19,MIN(#REF!,#REF!),"m")+1))) -> 0 | M19: =I19-K19 -> 0 | N19: =J19-L19 -> 0
B20: ='明细表I4-2'!A21 -> 0 | I20: =G20*F20 -> 0 | J20: =IF(D20=0,0,IF(#REF!>#REF!,VALUE(DATEDIF(D20,MIN(#REF!,#REF!),"m")+1),VALUE(DATEDIF(D20,MIN(#REF!,#REF!),"m")+1))) -> 0 | M20: =I20-K20 -> 0 | N20: =J20-L20 -> 0
B21: ='明细表I4-2'!A22 -> 0 | I21: =G21*F21 -> 0 | J21: =IF(D21=0,0,IF(#REF!>#REF!,VALUE(DATEDIF(D21,MIN(#REF!,#REF!),"m")+1),VALUE(DATEDIF(D21,MIN(#REF!,#REF!),"m")+1))) -> 0 | M21: =I21-K21 -> 0 | N21: =J21-L21 -> 0
A22: 合计 | C22: =SUM(C10:C21) -> 0 | I22: =SUM(I10:I21) -> 0 | J22: =SUM(J10:J21) -> 0 | K22: =SUM(K10:K21) -> 0 | L22: =SUM(L10:L21) -> 0 | M22: =SUM(M10:M21) -> 0 | N22: =SUM(N10:N21) -> 0
A23: 其中：
A24: =底稿目录!A9 -> 类别A | C24: {=SUMPRODUCT(($A$10:$A$21=$A24)*(C$10:C$21))} -> 0 | I24: {=SUMPRODUCT(($A$10:$A$21=$A24)*(I$10:I$21))} -> 0 | J24: {=SUMPRODUCT(($A$10:$A$21=$A24)*(J$10:J$21))} -> 0 | K24: {=SUMPRODUCT(($A$10:$A$21=$A24)*(K$10:K$21))} -> 0 | L24: {=SUMPRODUCT(($A$10:$A$21=$A24)*(L$10:L$21))} -> 0 | M24: {=SUMPRODUCT(($A$10:$A$21=$A24)*(M$10:M$21))} -> 0 | N24: {=SUMPRODUCT(($A$10:$A$21=$A24)*(N$10:N$21))} -> 0
A25: =底稿目录!A10 -> 类别B | C25: {=SUMPRODUCT(($A$10:$A$21=$A25)*(C$10:C$21))} -> 0 | I25: {=SUMPRODUCT(($A$10:$A$21=$A25)*(I$10:I$21))} -> 0 | J25: {=SUMPRODUCT(($A$10:$A$21=$A25)*(J$10:J$21))} -> 0 | K25: {=SUMPRODUCT(($A$10:$A$21=$A25)*(K$10:K$21))} -> 0 | L25: {=SUMPRODUCT(($A$10:$A$21=$A25)*(L$10:L$21))} -> 0 | M25: {=SUMPRODUCT(($A$10:$A$21=$A25)*(M$10:M$21))} -> 0 | N25: {=SUMPRODUCT(($A$10:$A$21=$A25)*(N$10:N$21))} -> 0
A26: =底稿目录!A11 -> 类别C | C26: {=SUMPRODUCT(($A$10:$A$21=$A26)*(C$10:C$21))} -> 0 | I26: {=SUMPRODUCT(($A$10:$A$21=$A26)*(I$10:I$21))} -> 0 | J26: {=SUMPRODUCT(($A$10:$A$21=$A26)*(J$10:J$21))} -> 0 | K26: {=SUMPRODUCT(($A$10:$A$21=$A26)*(K$10:K$21))} -> 0 | L26: {=SUMPRODUCT(($A$10:$A$21=$A26)*(L$10:L$21))} -> 0 | M26: {=SUMPRODUCT(($A$10:$A$21=$A26)*(M$10:M$21))} -> 0 | N26: {=SUMPRODUCT(($A$10:$A$21=$A26)*(N$10:N$21))} -> 0
A27: =底稿目录!A12 -> …… | C27: {=SUMPRODUCT(($A$10:$A$21=$A27)*(C$10:C$21))} -> 0 | I27: {=SUMPRODUCT(($A$10:$A$21=$A27)*(I$10:I$21))} -> 0 | J27: {=SUMPRODUCT(($A$10:$A$21=$A27)*(J$10:J$21))} -> 0 | K27: {=SUMPRODUCT(($A$10:$A$21=$A27)*(K$10:K$21))} -> 0 | L27: {=SUMPRODUCT(($A$10:$A$21=$A27)*(L$10:L$21))} -> 0 | M27: {=SUMPRODUCT(($A$10:$A$21=$A27)*(M$10:M$21))} -> 0 | N27: {=SUMPRODUCT(($A$10:$A$21=$A27)*(N$10:N$21))} -> 0
A28: 三、审计说明：
A30: 四、审计结论
A32: 编制说明：
A33: 1、使用寿命有限的无形资产应当摊销，使用寿命不确定的无形资产不予摊销。
A34: 2、来源于合同性权利或其他法定权利的无形资产，其使用寿命不应超过合同性权利或其他法定权利的期限；
A35: 合同性权利或其他法定权利在到期时因续约等延续、且有证据表明企业续约不需要付出大额成本的，续约期应当计入使用寿命。
A36: 3、合同或法律没有规定使用寿命的，企业应当综合各方面因素判断，以确定无形资产能为企业带来经济利益的期限。
A37: 4、按照上述方法仍无法合理确定无形资产为企业带来经济利益期限的，该项无形资产应作为使用寿命不确定的无形资产。
A38: 5、无形资产的摊销金额一般应当计入当期损益。某项无形资产包含的经济利益通过所生产的产品或其他资产实现的，其摊销金额应当计入相关资产的成本。
A62: 《企业所得税法实施条例》
A63: 第六十七条 无形资产按照直线法计算的摊销费用，准予扣除。
A64: 无形资产的摊销年限不得低于10年。
A65: 作为投资或者受让的无形资产，有关法律规定或者合同约定了使用年限的，可以按照规定或者约定的使用年限分期摊销。

Sheet GT_Custom
A1: C1 | B1: Custom 1
A2: C2 | B2: Custom 2
A3: C3 | B3: Custom 3
A4: C4 | B4: Custom 4
A5: C5 | B5: Custom 5
A6: C6 | B6: Custom 6
A7: C7 | B7: Custom 7
A8: C8 | B8: Custom 8
