Workbook

Sheet 底稿目录
A1: 底稿开列时，可先在以下单元格填写有关内容，以便其他底稿引用有关数据：
A2: 被审计单位：
A3: 截止日：202X年12月31日
A4: 编制人： | D4: 序号 | E4: 内容 | F4: 索引号 | G4: 备注
A5: 编制日期： | D5: 1 | E5: 函证程序表 | F5: K0A
A6: 复核人： | D6: 2 | E6: 函证结果汇总表 | F6: K0-1
A7: 复核日期： | D7: 3 | E7: 核实被函证单位信息 | F7: K0-2
D8: 4 | E8: 跟函函证过程控制 | F8: K0-3
A9: 关于工作底稿与审计程序索引号对应的说明 | D9: 5 | E9: 函证差异调节表 | F9: K0-4
A10: 1.编制的审计工作底稿应与审计程序对应。审计项目组应根据被审计单位实际情况和风险评估情况在实质性程序表中裁剪、修改或增加审计程序，根据实际执行的审计程序完成相应审计工作底稿，编制的工作底稿中应按自然顺序依次编制索引号，并通过唯一的索引号将与实质性程序表中的程序对应关联（即将工作底稿的索引号填入实质性程序表中的底稿索引号列）。 | D10: 7 | E10: 其他应收款替代程序检查表 | F10: K0-5
D11: 8 | E11: 其他应付款替代程序检查表 | F11: K0-6
D12: 9 | E12: 邮件传真回函可靠性验证 | F12: K0-7
D13: 10 | E13: 函证程序舞弊风险评价表 | F13: K0-8
A14: 2.获取的支持性证据应与审计底稿或程序对应。审计项目组在完成底稿时获取的支持性证据应根据底稿索引号编制下一级按自然顺序排序的索引号（如D1-2-1、D1-2-2、……），并在底稿中说明引用的支持性证据、关联索引号。
A17: 3.工作底稿索引号的编码规则：实质性程序索引号按循环从“D”到“N”,循环内账户以顺序号排列，模板中底稿索引号按账户顺序+自然数顺序（即模板中索引号按二级自然顺序排列，如D1-1、D1-2、D1-3、……D1-N）。

Sheet 函证程序表K0A
A1: 致同会计师事务所
A2: 其他应收款/其他应付款/……函证程序
A3: =底稿目录!A2 -> 被审计单位： | C3: =底稿目录!A4 -> 编制人： | D3: =底稿目录!A5 -> 编制日期： | E3: 索引号： | F3: =底稿目录!F5 -> K0A
A4: =底稿目录!A3 -> 截止日：202X年12月31日 | C4: =底稿目录!A6 -> 复核人： | D4: =底稿目录!A7 -> 复核日期： | E4: 页 次：
A5: 序号 | B5: 审计程序 | D5: 程序分类 | E5: 底稿索引号
A6: 1 | B6: 以积极方式对其他应收款、其他应付款、……进行函证。 | D6: 常规★ | E6: K0-1
A7: 2 | B7: 比较当年度及以前年度的增减变动、具体构成、账龄及主要交易对手的变化，针对舞弊风险较大的债务/债权人，考虑对合同条款、交易条件、是否存在关联方关系、是否存在担保以及补充协议等实施函证程序。 | D7: 舞弊应对/IPO/上市/新三板/重组 | E7: K0-1
A8: 3 | B8: 设计询证函，考虑制作询证函防伪标识，并在发函前核实被函证单位信息（函证科目、单位名称、地址、联系人、联系电话、邮政编码、函证人等），对于函证地址与注册地址、办公地址等不一致，不同客户或供应商的函证地址相近、电话号段相邻，函证联系人非被询证单位员工等情况，需核查并记录原因。 | D8: 常规★ | E8: K0-2
A9: 4 | B9: 注册会计师直接收发询证函，跟函时观察实地场所以及函证核对过程，确认处理函证的人员身份和权限，防范询证函被拦截、篡改或发生串通舞弊，并在底稿中记录或留存控制过程； | D9: 常规★ | E9: K0-1/K0-3
A10: 5 | B10: 留存亲自寄发函证的寄送单回执及被审计单位盖章确认的询证函复印件，核实发函快递物流信息； | D10: 常规★ | E10: K0-1/K0-2
A11: 6 | B11: 收到的回函应为被询证者书面答复，可以采取纸质、电子或其它介质等形式： （1）确认与发出的询证函是否为同一份、是否为原件； （2）检查回函发出地址、快递物流信息，核实回函地址是否与发函收件地址一致，比对回函印章和签字，确认回函的真实性； （3）检查函证信息是否相符，对回函不符的询证函，查明不符事项的原因确定是否存在错报，考虑是否存在舞弊的可能性； | D11: 常规★ | E11: K0-1/K0-2//K0-4
A12: 7 | B12: 如果被询证者以传真、电子邮件等方式回函，审计项目组应当直接接收，并验证传真、电邮邮件回函的可靠性，要求被询证者在审计报告日之前寄回询证函原件 | D12: 备选 | E12: K0-1/K0-7
A13: 8 | B13: 如果利用第三方函证平台收发函证的，考虑评估第三方函证平台服务的可靠性，了解资质认证或有关控制设计及运行的有效性。 | D13: 备选 | G13: 提示：第三方电子询证函平台的安全性评估内容相关要点详见函证技术提示3号，链接为：https://www.gt-china.com.cn/article_view.php?id=9682；
A14: 9 | B14: 分析核实退回或无法寄到的函证、未回函、回函率较低的原因，考虑与被询证者联系，要求对方作出回应或再次寄发询证函，必要时增加现场走访等程序，关注是否存在账面记录与外部证据矛盾的审计证据； | D14: 常规★ | E14: K0-1/K0-2
A15: 10 | B15: 针对再次发函未回函的项目，评价其重大错报风险以及其他审计程序的性质、时间安排和范围的影响实施替代审计程序，包括： （1）检查交易发生的记账凭证和相关的支持性证据； （2）检查资产负债表日后收款、付款情况 | D15: 常规★ | E15: K0-1/K0-5/K0-6
A16: 11 | B16: 结合风险评估情况及函证程序执行过程中的舞弊风险迹象，考虑串通舞弊、伪造交易的可能性等，对函证程序的舞弊风险进行评价； | D16: 常规★ | E16: K0-8
A17: 12 | B17: 如果管理层不允许寄发询证函的原因不合理、或者认为回函不可靠，列出交易对手清单，实施替代审计程序，并评价对评估的重大错报风险以及其他审计程序的性质、时间安排和范围的影响，考虑其对审计工作和审计意见的影响； | D17: 常规★

Sheet 函证结果汇总表K0-1
A1: 致同会计师事务所 | S1: 致同会计师事务所
A2: 其他应收款/其他应付款/……函证结果汇总表 | S2: 其他应收款函证结果汇总表
C3: =底稿目录!A2 -> 被审计单位： | I3: =底稿目录!A4 -> 编制人： | M3: =底稿目录!A5 -> 编制日期： | Q3: 索引号： | R3: =底稿目录!F6 -> K0-1 | S3: =底稿目录!A2 -> 被审计单位： | W3: =底稿目录!A4 -> 编制人： | Y3: =底稿目录!A5 -> 编制日期： | AA3: 索引号： | AB3: =底稿目录!F6 -> K0-1
C4: =底稿目录!A3 -> 截止日：202X年12月31日 | I4: =底稿目录!A6 -> 复核人： | M4: =底稿目录!A7 -> 复核日期： | Q4: 页 次： | S4: =底稿目录!A3 -> 截止日：202X年12月31日 | W4: =底稿目录!A6 -> 复核人： | Y4: =底稿目录!A7 -> 复核日期： | AA4: 页 次：
A5: 序号 | B5: 询证函索引号 | C5: 发函询证纪要 | G5: 1、发函信息 | L5: 2、收到回函 | S5: 3、回函金额确认 | X5: 4、未收到回函的替代程序 | AB5: 审计结论
C6: 选取样本目的 | D6: 被询证单位名称 | E6: 账户/交易 | F6: 金额 | G6: 函证方式 | H6: 发函日期 | I6: 发函单号/跟函记录索引号 | J6: 收件地址 | K6: 地址核查是否一致 | L6: 是否收到回函 | M6: 回函方式 | N6: 是否相符 | O6: 回函日期 | P6: 回函快递单号 | Q6: 回函发出地址 | R6: 发函地址与回函地址是否一致 | S6: 回函金额 | T6: 差异 | U6: 可确认金额 | V6: 调节索引（K1-12） | W6: 其他说明/备注 | X6: 是否采取替代程序 | Y6: 替代后可确认金额 | Z6: 替代后不可确认金额 | AA6: 替代程序索引号
A7: 1 | D7: =VLOOKUP($B7,'核实被函证单位信息K0-2'!$A:$AL,2,0) -> #N/A | G7: =VLOOKUP($B7,'核实被函证单位信息K0-2'!$A:$AL,3,0) -> #N/A | J7: =VLOOKUP($B7,'核实被函证单位信息K0-2'!$A:$AL,4,0) -> #N/A | K7: =VLOOKUP($B7,'核实被函证单位信息K0-2'!$A:$AL,10,0) -> #N/A | M7: =VLOOKUP($B7,'核实被函证单位信息K0-2'!$A:$AL,16,0) -> #N/A | Q7: =VLOOKUP($B7,'核实被函证单位信息K0-2'!$A:$AL,19,0) -> #N/A | R7: =VLOOKUP($B7,'核实被函证单位信息K0-2'!$A:$AL,22,0) -> #N/A | T7: =IF(L7="是",S7-F7,"未回函") -> 未回函
A8: 2 | D8: =VLOOKUP($B8,'核实被函证单位信息K0-2'!$A:$AL,2,0) -> #N/A | G8: =VLOOKUP($B8,'核实被函证单位信息K0-2'!$A:$AL,3,0) -> #N/A | J8: =VLOOKUP($B8,'核实被函证单位信息K0-2'!$A:$AL,4,0) -> #N/A | K8: =VLOOKUP($B8,'核实被函证单位信息K0-2'!$A:$AL,10,0) -> #N/A | M8: =VLOOKUP($B8,'核实被函证单位信息K0-2'!$A:$AL,16,0) -> #N/A | Q8: =VLOOKUP($B8,'核实被函证单位信息K0-2'!$A:$AL,19,0) -> #N/A | R8: =VLOOKUP($B8,'核实被函证单位信息K0-2'!$A:$AL,22,0) -> #N/A | T8: =IF(L8="是",S8-F8,"未回函") -> 未回函
A9: 3 | D9: =VLOOKUP($B9,'核实被函证单位信息K0-2'!$A:$AL,2,0) -> #N/A | G9: =VLOOKUP($B9,'核实被函证单位信息K0-2'!$A:$AL,3,0) -> #N/A | J9: =VLOOKUP($B9,'核实被函证单位信息K0-2'!$A:$AL,4,0) -> #N/A | K9: =VLOOKUP($B9,'核实被函证单位信息K0-2'!$A:$AL,10,0) -> #N/A | M9: =VLOOKUP($B9,'核实被函证单位信息K0-2'!$A:$AL,16,0) -> #N/A | Q9: =VLOOKUP($B9,'核实被函证单位信息K0-2'!$A:$AL,19,0) -> #N/A | R9: =VLOOKUP($B9,'核实被函证单位信息K0-2'!$A:$AL,22,0) -> #N/A | T9: =IF(L9="是",S9-F9,"未回函") -> 未回函
A10: 4 | D10: =VLOOKUP($B10,'核实被函证单位信息K0-2'!$A:$AL,2,0) -> #N/A | G10: =VLOOKUP($B10,'核实被函证单位信息K0-2'!$A:$AL,3,0) -> #N/A | J10: =VLOOKUP($B10,'核实被函证单位信息K0-2'!$A:$AL,4,0) -> #N/A | K10: =VLOOKUP($B10,'核实被函证单位信息K0-2'!$A:$AL,10,0) -> #N/A | M10: =VLOOKUP($B10,'核实被函证单位信息K0-2'!$A:$AL,16,0) -> #N/A | Q10: =VLOOKUP($B10,'核实被函证单位信息K0-2'!$A:$AL,19,0) -> #N/A | R10: =VLOOKUP($B10,'核实被函证单位信息K0-2'!$A:$AL,22,0) -> #N/A | T10: =IF(L10="是",S10-F10,"未回函") -> 未回函
A11: 5 | D11: =VLOOKUP($B11,'核实被函证单位信息K0-2'!$A:$AL,2,0) -> #N/A | G11: =VLOOKUP($B11,'核实被函证单位信息K0-2'!$A:$AL,3,0) -> #N/A | J11: =VLOOKUP($B11,'核实被函证单位信息K0-2'!$A:$AL,4,0) -> #N/A | K11: =VLOOKUP($B11,'核实被函证单位信息K0-2'!$A:$AL,10,0) -> #N/A | M11: =VLOOKUP($B11,'核实被函证单位信息K0-2'!$A:$AL,16,0) -> #N/A | Q11: =VLOOKUP($B11,'核实被函证单位信息K0-2'!$A:$AL,19,0) -> #N/A | R11: =VLOOKUP($B11,'核实被函证单位信息K0-2'!$A:$AL,22,0) -> #N/A | T11: =IF(L11="是",S11-F11,"未回函") -> 未回函
A12: 6 | D12: =VLOOKUP($B12,'核实被函证单位信息K0-2'!$A:$AL,2,0) -> #N/A | G12: =VLOOKUP($B12,'核实被函证单位信息K0-2'!$A:$AL,3,0) -> #N/A | J12: =VLOOKUP($B12,'核实被函证单位信息K0-2'!$A:$AL,4,0) -> #N/A | K12: =VLOOKUP($B12,'核实被函证单位信息K0-2'!$A:$AL,10,0) -> #N/A | M12: =VLOOKUP($B12,'核实被函证单位信息K0-2'!$A:$AL,16,0) -> #N/A | Q12: =VLOOKUP($B12,'核实被函证单位信息K0-2'!$A:$AL,19,0) -> #N/A | R12: =VLOOKUP($B12,'核实被函证单位信息K0-2'!$A:$AL,22,0) -> #N/A | T12: =IF(L12="是",S12-F12,"未回函") -> 未回函
A13: 7 | D13: =VLOOKUP($B13,'核实被函证单位信息K0-2'!$A:$AL,2,0) -> #N/A | G13: =VLOOKUP($B13,'核实被函证单位信息K0-2'!$A:$AL,3,0) -> #N/A | J13: =VLOOKUP($B13,'核实被函证单位信息K0-2'!$A:$AL,4,0) -> #N/A | K13: =VLOOKUP($B13,'核实被函证单位信息K0-2'!$A:$AL,10,0) -> #N/A | M13: =VLOOKUP($B13,'核实被函证单位信息K0-2'!$A:$AL,16,0) -> #N/A | Q13: =VLOOKUP($B13,'核实被函证单位信息K0-2'!$A:$AL,19,0) -> #N/A | R13: =VLOOKUP($B13,'核实被函证单位信息K0-2'!$A:$AL,22,0) -> #N/A | T13: =IF(L13="是",S13-F13,"未回函") -> 未回函
A14: 8 | D14: =VLOOKUP($B14,'核实被函证单位信息K0-2'!$A:$AL,2,0) -> #N/A | G14: =VLOOKUP($B14,'核实被函证单位信息K0-2'!$A:$AL,3,0) -> #N/A | J14: =VLOOKUP($B14,'核实被函证单位信息K0-2'!$A:$AL,4,0) -> #N/A | K14: =VLOOKUP($B14,'核实被函证单位信息K0-2'!$A:$AL,10,0) -> #N/A | M14: =VLOOKUP($B14,'核实被函证单位信息K0-2'!$A:$AL,16,0) -> #N/A | Q14: =VLOOKUP($B14,'核实被函证单位信息K0-2'!$A:$AL,19,0) -> #N/A | R14: =VLOOKUP($B14,'核实被函证单位信息K0-2'!$A:$AL,22,0) -> #N/A | T14: =IF(L14="是",S14-F14,"未回函") -> 未回函
A15: 9 | D15: =VLOOKUP($B15,'核实被函证单位信息K0-2'!$A:$AL,2,0) -> #N/A | G15: =VLOOKUP($B15,'核实被函证单位信息K0-2'!$A:$AL,3,0) -> #N/A | J15: =VLOOKUP($B15,'核实被函证单位信息K0-2'!$A:$AL,4,0) -> #N/A | K15: =VLOOKUP($B15,'核实被函证单位信息K0-2'!$A:$AL,10,0) -> #N/A | M15: =VLOOKUP($B15,'核实被函证单位信息K0-2'!$A:$AL,16,0) -> #N/A | Q15: =VLOOKUP($B15,'核实被函证单位信息K0-2'!$A:$AL,19,0) -> #N/A | R15: =VLOOKUP($B15,'核实被函证单位信息K0-2'!$A:$AL,22,0) -> #N/A | T15: =IF(L15="是",S15-F15,"未回函") -> 未回函
A16: 10 | D16: =VLOOKUP($B16,'核实被函证单位信息K0-2'!$A:$AL,2,0) -> #N/A | G16: =VLOOKUP($B16,'核实被函证单位信息K0-2'!$A:$AL,3,0) -> #N/A | J16: =VLOOKUP($B16,'核实被函证单位信息K0-2'!$A:$AL,4,0) -> #N/A | K16: =VLOOKUP($B16,'核实被函证单位信息K0-2'!$A:$AL,10,0) -> #N/A | M16: =VLOOKUP($B16,'核实被函证单位信息K0-2'!$A:$AL,16,0) -> #N/A | Q16: =VLOOKUP($B16,'核实被函证单位信息K0-2'!$A:$AL,19,0) -> #N/A | R16: =VLOOKUP($B16,'核实被函证单位信息K0-2'!$A:$AL,22,0) -> #N/A | T16: =IF(L16="是",S16-F16,"未回函") -> 未回函
A17: 11 | D17: =VLOOKUP($B17,'核实被函证单位信息K0-2'!$A:$AL,2,0) -> #N/A | G17: =VLOOKUP($B17,'核实被函证单位信息K0-2'!$A:$AL,3,0) -> #N/A | J17: =VLOOKUP($B17,'核实被函证单位信息K0-2'!$A:$AL,4,0) -> #N/A | K17: =VLOOKUP($B17,'核实被函证单位信息K0-2'!$A:$AL,10,0) -> #N/A | M17: =VLOOKUP($B17,'核实被函证单位信息K0-2'!$A:$AL,16,0) -> #N/A | Q17: =VLOOKUP($B17,'核实被函证单位信息K0-2'!$A:$AL,19,0) -> #N/A | R17: =VLOOKUP($B17,'核实被函证单位信息K0-2'!$A:$AL,22,0) -> #N/A | T17: =IF(L17="是",S17-F17,"未回函") -> 未回函
A18: 12 | D18: =VLOOKUP($B18,'核实被函证单位信息K0-2'!$A:$AL,2,0) -> #N/A | G18: =VLOOKUP($B18,'核实被函证单位信息K0-2'!$A:$AL,3,0) -> #N/A | J18: =VLOOKUP($B18,'核实被函证单位信息K0-2'!$A:$AL,4,0) -> #N/A | K18: =VLOOKUP($B18,'核实被函证单位信息K0-2'!$A:$AL,10,0) -> #N/A | M18: =VLOOKUP($B18,'核实被函证单位信息K0-2'!$A:$AL,16,0) -> #N/A | Q18: =VLOOKUP($B18,'核实被函证单位信息K0-2'!$A:$AL,19,0) -> #N/A | R18: =VLOOKUP($B18,'核实被函证单位信息K0-2'!$A:$AL,22,0) -> #N/A | T18: =IF(L18="是",S18-F18,"未回函") -> 未回函
... A26: 20 | D26: =VLOOKUP($B26,'核实被函证单位信息K0-2'!$A:$AL,2,0) -> #N/A | G26: =VLOOKUP($B26,'核实被函证单位信息K0-2'!$A:$AL,3,0) -> #N/A | J26: =VLOOKUP($B26,'核实被函证单位信息K0-2'!$A:$AL,4,0) -> #N/A | K26: =VLOOKUP($B26,'核实被函证单位信息K0-2'!$A:$AL,10,0) -> #N/A | M26: =VLOOKUP($B26,'核实被函证单位信息K0-2'!$A:$AL,16,0) -> #N/A | Q26: =VLOOKUP($B26,'核实被函证单位信息K0-2'!$A:$AL,19,0) -> #N/A | R26: =VLOOKUP($B26,'核实被函证单位信息K0-2'!$A:$AL,22,0) -> #N/A | T26: =IF(L26="是",S26-F26,"未回函") -> 未回函
C27: 一、函证情况 | I27: 二、样本选择 | S27: 三、审计说明
C28: 项目 | E28: 其他应收款 | F28: 其他应付款 | I28: 测试范围： | J28: 如其他应收款账面余额XX、债务人XX个；其他应付款账面余额XX、债权人XX个；…… | S28: 1.对询证函保持的控制的说明 | X28: 2.对误差的分析
C29: 本期（期末）账面金额： | I29: 特定样本： | J29: 其他应收款XX金额以上（大额）……、关联方/关联交易形成的款项、XX异常款项全部测试，共XX个债务人； | X29: 界定误差构成条件：［不符事项的金额高于或低于账户余额人民币
C30: 抽取样本的发函金额： | E30: =SUMIF(E7:E26,E28,F7:F26) -> 0 | F30: =SUMIF(E7:E26,F28,F7:F26) -> 0 | I30: 抽样总体： | J30: 测试总体扣除特定样本以外的样本，其他应收款共XX个债务人、金额XX，其他应付款共XX个债权人、金额XX，……； | X30: （）万元，并且被审计单位不能合理解释其差异并提供相应依据］
C31: 发函金额占账面金额的比例(%)： | E31: =IF(ISERROR(E30/E29),0,E30/E29) -> 0 | F31: =IF(ISERROR(F30/F29),0,F30/F29) -> 0 | I31: 确定的抽样样本量： | J31: 其他应收款、其他应付款分别抽取XX个、XX个单位；
C32: 回函确认金额： | E32: =SUMIF(E7:E26,E28,U7:U26) -> 0 | F32: =SUMIF(E7:E26,F28,U7:U26) -> 0 | J32: （如果使用了样本计算器计算样本量，样本量计算过程见<XX>底稿） | S32: 3.对以传真或电子邮件形式收到的回函的可靠性的考虑（K0-6） | X32: 4.针对不符事项的程序
C33: 回函可确认金额占发函金额的比例(%)： | E33: =IF(ISERROR(E32/E30),0,E32/E30) -> 0 | F33: =IF(ISERROR(F32/F30),0,F32/F30) -> 0 | I33: 抽样方法： | J33: 随机选样/系统选样/货币单元抽样/随意选样 | S33: 如果回函中存在未函证的其他信息，应考虑未函证信息的影响，并考虑实施进一步审计程序
C34: 回函可确认金额占账面金额的比例(%)： | E34: =IF(ISERROR(E32/E29),0,E32/E29) -> 0 | F34: =IF(ISERROR(F32/F29),0,F32/F29) -> 0 | I34: 抽样过程： | J34: 使用IDEA（XX抽样工具）选取样本进行函证，其他应收款选择XX个债务人、金额XX的样本，
C35: 替代测试确认金额： | E35: =SUMIF(E7:E26,E28,Y7:Y26) -> 0 | F35: =SUMIF(E7:E26,F28,Y7:Y26) -> 0 | J35: 其他应付款选择XX个债权人、金额XX的样本，……
C36: 回函和替代确认金额占账面金额的比例(%)： | E36: =(E35+E32)/E29 -> #DIV/0! | F36: =(F35+F32)/F29 -> #DIV/0! | J36: 抽样工具中的样本选择过程和结果见<XX>底稿 | S36: 5.针对未回函的替代程序
C38: 四、审计结论
A40: 提示：如果被询证者以传真、电子邮件等方式回函，审计项目组应当直接接收，并验证传真、电子邮件回函的可靠性，要求被询证者在审计报告日之前寄回询证函原件
A42: 编制说明：
A43: 1、函证样本的选择：
A44: 《中国注册会计师审计准则第1312号——函证》第十条注册会计师采用审计抽样或其他选取测试项目的方法
A45: 选择函证样本时，样本应当足以代表总体，并包括：
A46: （一）金额较大的项目；
A47: （二）账龄较长的项目；
A48: （三）交易频繁但期末余额较小的项目；
A49: （四）重大关联方交易；
A50: （五）重大或异常的交易；
...

Sheet 核实被函证单位信息K0-2
A1: 致同会计师事务所 | P1: 致同会计师事务所 | AB1: 致同会计师事务所
A2: 核实被函证单位信息 | P2: 核实被函证单位信息 | AB2: 核实被函证单位信息
C3: =底稿目录!A2 -> 被审计单位： | F3: =底稿目录!A4 -> 编制人： | K3: =底稿目录!A5 -> 编制日期： | N3: 索引号： | O3: =底稿目录!F7 -> K0-2 | P3: =底稿目录!A2 -> 被审计单位： | T3: =底稿目录!A4 -> 编制人： | W3: =底稿目录!A5 -> 编制日期： | Z3: 索引号： | AA3: =底稿目录!F7 -> K0-2 | AB3: =底稿目录!A2 -> 被审计单位： | AE3: =底稿目录!A4 -> 编制人： | AH3: =底稿目录!A5 -> 编制日期： | AK3: 索引号： | AL3: =底稿目录!F7 -> K0-2
C4: =底稿目录!A3 -> 截止日：202X年12月31日 | F4: =底稿目录!A6 -> 复核人： | K4: =底稿目录!A7 -> 复核日期： | N4: 页 次： | P4: =底稿目录!A3 -> 截止日：202X年12月31日 | T4: =底稿目录!A6 -> 复核人： | W4: =底稿目录!A7 -> 复核日期： | Z4: 页 次： | AB4: =底稿目录!A3 -> 截止日：202X年12月31日 | AE4: =底稿目录!A6 -> 复核人： | AH4: =底稿目录!A7 -> 复核日期： | AK4: 页 次：
A5: 函证索引 | B5: 被审计单位提供的被函证单位信息及核对（核实被函证单位信息）（注1） | P5: 回函信息情况（回函核对记录） | AB5: 第一次发函结果？（送抵/退回）（注2） | AC5: 经核实的原因 | AD5: 该原因是否合理（是/否） （注3） | AE5: 是否进行第二次发函？ （是/否） | AF5: 第二次发函的被函证单位信息 | AL5: 第二次发函结果？（送抵/退回） （注4）
B6: 被询证单位全称 | C6: 函证方式 | D6: 收件地址 | E6: 邮编 | F6: 联系人 | G6: 联系电话 | H6: 邮箱/传真 | I6: 企查查地址 | J6: 发函地址与企查查地址是否一致 | K6: 地址核查不一致的说明 | L6: 地址不一致的核实方式 | M6: 核实的支持性文件或其他公开信息索引号 | N6: 不一致说明是否合理 | O6: 备注 | P6: 回函方式 | Q6: 是否为原件 | R6: 是否直接收到回函 | S6: 回函发出地址（含物流信息中的地址） | T6: 回函寄件人 | U6: 回函电话 | V6: 发函地址与回函地址是否一致 | W6: 发函收件人与回函寄件人是否一致 | X6: 发函收件人电话与回函寄件人电话是否一致 | Y6: 不一致的说明 | Z6: 核实支持性证据索引号 | AA6: 跟函函证控制过程（K1-11） | AF6: 地址 | AG6: 邮编 | AH6: 联系人 | AI6: 联系电话 | AJ6: 传真 | AK6: 信息是否核查一致
C25: 审计说明：1.采用电子函证方式的无需核对发函地址信息，无需核对回函发出地址、回函寄件人信息等；
C26: 2.采用电子函证方式的应记录并检查回函能够证明电子地址或身份的信息，关注被审计单位、注册会计师和被询证者在电子询证函平台操作的具体时间、回函经办人（如适用）、意见反馈等信息（如适用）
A27: 编制说明：
A28: 说明1：
A29: 进行核实的信息应该包括单位名称，地址，以及联系人和电话。
A30: 1.项目组可利用函证中心对接的企查查获取被函证单位地址，如果不一致的应使用多种方法来核实被函证单位的信息，如查找相关发票/合同，网站搜索，电话确认，邮件确认等，请详细记录核实的方式
A31: 2.若检查了相关支持性文件或其他公开信息，请记录所检查的详细内容。
A32: 3.请记录确认联系人身份的过程。注意：在银行函证中，也应注意核实联系人的身份并记录工号（若有）
A33: 4.在核实结果中，应注明所检查的信息（包括单位名称、地址、联系人及电话等）是否与被函证单位信息相符。
A34: 说明2：
A35: 请详细记录核实函证被退回原因所进行的程序， 例如：询问，检查等程序的具体内容
A36: 说明3：
A37: 若退回的原因不合理或存在舞弊可能，审计项目组人员应及时告知项目负责人，并咨询有关针对舞弊的审计应对措施
A38: 说明4：
... A41: 如果被询证者以传真、电子邮件方式回函，审计项目组应当直接接收，并验证传真、电子邮件回函的可靠性，要求被询证者在审计报告日之前寄回询证函原件

Sheet 跟函函证过程控制K0-3
A1: 致同会计师事务所
A2: 跟函函证过程控制
A3: =底稿目录!A2 -> 被审计单位： | C3: =底稿目录!A4 -> 编制人： | D3: =底稿目录!A5 -> 编制日期： | E3: 索引号： | F3: =底稿目录!F8 -> K0-3
A4: =底稿目录!A3 -> 截止日：202X年12月31日 | C4: =底稿目录!A6 -> 复核人： | D4: =底稿目录!A7 -> 复核日期： | E4: 页次：
A5: 直接至被函证方公司进行函证（“跟函”）程序的记录
A6: 提示：
A7: ·本记录是针对审计项目组成员不通过寄送，而是直接至被函证方公司进行函证（“跟函”）的情况。
A8: ·本记录应由执行跟函程序的项目组成员针对每一份经由跟函程序取得的函证编制，并由该跟函人员在记录底稿上手书签署姓名。
A9: ·[ ]中的斜体字请根据实际情况填写。
A10: 审计项目组成员[XXX…]于[202X年XX月XX日]与[被审计单位XX部XX]一同/或者在无被审计单位人员陪同下独立至
A11: [被函证方单位XX财务部/[或者其他执行类似职能的XXX部门]]（[地址]）执行函证程序。
A12: 该函证是在[XX公司]的财务部/[或者其他执行类似职能的XX部门]办理，确认函证的被函证单位工作人员姓名为[XX]，
A13: 工号为[XX]（如有），我们取得了由被函证方公司确认的函证，函证索引号为[XX]。
A14: *若被函证单位无法即时确认函证，而要求跟函人员将函证留下，待确认后再寄回事务所相关办公室则考虑使用以下内容
A15: 审计项目组成员[XX…]于[202X年XX月XX日]至[被函证单位全称]（[地址]）实行函证程序，被函证单位人员XX告知我/
A16: [我们]无法现场即时确认该函证，需要做详细查询后才可以确认，并同意将确认的函证直接寄回致同会计师事务XX办公室](可以根据实际情况进行修改)。
... A31: 观察处理询证函的人员是否按照正常流程认真处理询证函，例如，该人员是否在其计算机系统或相关记录中核对相关信息。

Sheet 函证差异调节表K0-4
A1: 致同会计师事务所
A2: 其他应收款/其他应付款/……函证差异调节表
A3: =底稿目录!A2 -> 被审计单位： | D3: =底稿目录!A4 -> 编制人： | G3: =底稿目录!A5 -> 编制日期： | H3: 索引号： | I3: =底稿目录!F9 -> K0-4
A4: =底稿目录!A3 -> 截止日：202X年12月31日 | D4: =底稿目录!A6 -> 复核人： | G4: =底稿目录!A7 -> 复核日期： | H4: 页次：
A5: 询证函索引号 | B5: 被询证单位名称 | C5: 账户/交易 | D5: 发函金额 | E5: 回函金额 | F5: 差异 | G5: 差异原因 | H5: 相关支持性证据 | I5: 是否调整
F6: =D6-E6 -> 0
F7: =D7-E7 -> 0
F8: =D8-E8 -> 0
F9: =D9-E9 -> 0
F10: =D10-E10 -> 0
F11: =D11-E11 -> 0
F12: =D12-E12 -> 0
F13: =D13-E13 -> 0
F14: =D14-E14 -> 0
F15: =D15-E15 -> 0
F16: =D16-E16 -> 0
F17: =D17-E17 -> 0
... F20: =D20-E20 -> 0
A21: 合计 | D21: =SUM(D6:D20) -> 0 | E21: =SUM(E6:E20) -> 0 | F21: =SUM(F6:F20) -> 0

Sheet 其他应收款替代程序K0-5
A1: 致同会计师事务所
A2: 其他应收款替代程序检查表-XX公司
A3: =底稿目录!A2 -> 被审计单位： | F3: =底稿目录!A4 -> 编制人： | I3: =底稿目录!A5 -> 编制日期： | M3: 索引号： | N3: =底稿目录!F10 -> K0-5
A4: =底稿目录!A3 -> 截止日：202X年12月31日 | F4: =底稿目录!A6 -> 复核人： | I4: =底稿目录!A7 -> 复核日期： | M4: 页次：
A5: 债务人名称：
A6: 一、样本选取标准与规模：
A7: 测试范围： | B7: 如借方发生额所有凭证共XX笔金额XX、贷方发生额所有凭证共XX笔金额XX | H7: 特定样本： | I7: XX金额以上（大额）、关联方/关联交易形成的款项、XX异常款项全部测试，共XX笔；
A8: 抽样总体： | B8: 测试总体扣除特定样本以外的样本，共XX笔、金额XX | H8: 确定的抽样样本量： | J8: 抽取XX笔（如果使用了样本计算器计算样本量，样本量计算过程见<XX>底稿）
A9: 抽样方法： | B9: 随机选样/系统选样/货币单元抽样/随意选样（非统计抽样适用） | H9: 抽样过程： | I9: 使用IDEA（XX抽样工具）选择XX数量占比XX%的样本进行测试，抽样工具中的样本选择过程和结果见XX底稿
A10: 二、检查过程记录：
A11: 函证项目 | B11: 年初余额 | C11: 借方发生额 | D11: 贷方发生额 | E11: 期末余额
A12: 其他应收款 | E12: =B12+C12-D12 -> 0
A14: 1.其他应收款检查-检查期后收款
A15: 记账凭证 | F15: 银行回单 | I15: 支持性文件1 | L15: …… | M15: 索引号 | N15: 是否异常 | O15: 检查的关键证据和要素根据被审计单位具体情况修改
A16: 日期 | B16: 凭证编号 | C16: 业务内容 | D16: 对方科目 | E16: 金额 | F16: 日期 | G16: 付款方 | H16: 金额 | I16: 识别特征 | J16: 信息1 | K16: 信息2
A23: 合计 | E23: =SUM(E17:E22) -> 0 | H23: =SUM(H17:H22) -> 0
A25: 2.其他应收款检查-形成期末余额的合同、付款审批单、支出凭单等支持性证据检查
A26: 记账凭证 | F26: 支持性文件1 | I26: 支持性文件2 | L26: …… | M26: 索引号 | N26: 是否异常 | O26: 检查的关键证据和要素根据被审计单位具体情况修改
A27: 日期 | B27: 凭证编号 | C27: 业务内容 | D27: 对方科目 | E27: 金额 | F27: 识别特征 | G27: 信息1 | H27: 信息2 | I27: 识别特征 | J27: 信息1 | K27: 信息2
A34: 合计 | E34: =SUM(E28:E33) -> 0
A36: 3.检查本期发生额：
A37: （1）本期借方发生额
A38: 记账凭证 | F38: 支持性文件1 | I38: 支持性文件2 | L38: …… | M38: 索引号 | N38: 是否异常 | O38: 检查的关键证据和要素根据被审计单位具体情况修改
A39: 日期 | B39: 凭证编号 | C39: 业务内容 | D39: 对方科目 | E39: 金额 | F39: 识别特征 | G39: 信息1 | H39: 信息2 | I39: 识别特征 | J39: 信息1 | K39: 信息2
A46: 合计 | E46: =SUM(E40:E45) -> 0 | M46: =SUM(M40:M45) -> 0
A47: （2）本期贷方发生额
A48: 记账凭证 | F48: 支持性文件1 | I48: 支持性文件2 | L48: …… | M48: 索引号 | N48: 是否异常
A49: 日期 | B49: 凭证编号 | C49: 业务内容 | D49: 对方科目 | E49: 金额 | F49: 识别特征 | G49: 信息1 | H49: 信息2 | I49: 识别特征 | J49: 信息1 | K49: 信息2
A56: 合计 | E56: =SUM(E50:E55) -> 0
A57: 三、审计说明：
A61: 四、审计结论：
A66: 编制说明：
A67: 1、函证替代程序：
B68: ①检查本期付款、期后收货或回收；
B69: ②检查原始凭证：合同、订货单、发票或收据、银行回单、支票存根等；
B70: ③对回函可能性不高的、余额重大的，发函同时执行替代程序。
A72: 2、概述：（1）程序的测试情况、结果；
A73: （2）拟调整事项及其调整分录、未调整事项及其影响，审计范围受到限制情况及其影响。

Sheet 其他应付款替代程序K0-6
A1: 致同会计师事务所
A2: 其他应付款替代程序检查表-XX公司
A3: =底稿目录!A2 -> 被审计单位： | F3: =底稿目录!A4 -> 编制人： | J3: =底稿目录!A5 -> 编制日期： | M3: 索引号： | N3: =底稿目录!F11 -> K0-6
A4: =底稿目录!A3 -> 截止日：202X年12月31日 | F4: =底稿目录!A6 -> 复核人： | J4: =底稿目录!A7 -> 复核日期： | M4: 页次：
A5: 债权人名称：
A6: 一、样本选取标准与规模：
A7: 测试范围： | B7: 如借方发生额所有凭证共XX笔金额XX、贷方发生额所有凭证共XX笔金额XX | H7: 特定样本： | I7: XX金额以上（大额）、关联方/关联交易形成的款项、XX异常款项全部测试，共XX笔；
A8: 抽样总体： | B8: 测试总体扣除特定样本以外的样本，共XX笔、金额XX | H8: 确定的抽样样本量： | J8: 抽取XX笔 | K8: （如果使用了样本计算器计算样本量，样本量计算过程见<XX>底稿）
A9: 抽样方法： | B9: 随机选样/系统选样/货币单元抽样/随意选样（非统计抽样适用） | H9: 抽样过程： | I9: 使用IDEA（XX抽样工具）选择XX数量占比XX%的样本进行测试，抽样工具中的样本选择过程和结果见XX底稿
A10: 二、检查过程记录：
A11: 函证项目 | B11: 年初余额 | C11: 借方发生额 | D11: 贷方发生额 | E11: 期末余额
A12: 其他应付款 | E12: =B12+C12-D12 -> 0
A14: 1.其他应付款检查-检查期后付款
A15: 记账凭证 | F15: 付款审批单 | H15: 银行回单 | K15: …… | L15: …… | M15: 索引号 | N15: 是否异常 | O15: 检查的关键证据和要素根据被审计单位具体情况修改
A16: 日期 | B16: 凭证编号 | C16: 业务内容 | D16: 对方科目 | E16: 金额 | F16: 日期/编号 | G16: 是否经过恰当审批 | H16: 日期 | I16: 收款方 | J16: 金额
A23: 合计 | E23: =SUM(E17:E22) -> 0 | J23: =SUM(J17:J22) -> 0
A25: 2.其他应付款检查-形成期末余额的合同、支出凭单、发票等支持性证据检查
A26: 记账凭证 | F26: 支持性文件1 | I26: 支持性文件2 | L26: …… | M26: 索引号 | N26: 是否异常 | O26: 检查的关键证据和要素根据被审计单位具体情况修改
A27: 日期 | B27: 凭证编号 | C27: 业务内容 | D27: 对方科目 | E27: 金额 | F27: 识别特征 | G27: 信息1 | H27: 信息2 | I27: 识别特征 | J27: 信息1 | K27: 信息2
A34: 合计 | E34: =SUM(E28:E33) -> 0
A36: 3.检查本期发生额：
A37: （1）本期借方发生额
A38: 记账凭证 | F38: 支持性文件1 | I38: 支持性文件2 | L38: …… | M38: 索引号 | N38: 是否异常 | O38: 检查的关键证据和要素根据被审计单位具体情况修改
A39: 日期 | B39: 凭证编号 | C39: 业务内容 | D39: 对方科目 | E39: 金额 | F39: 识别特征 | G39: 信息1 | H39: 信息2 | I39: 识别特征 | J39: 信息1 | K39: 信息2
A46: 合计 | E46: =SUM(E40:E45) -> 0
A47: （2）本期贷方发生额
A48: 记账凭证 | F48: 支持性文件1 | I48: 支持性文件2 | L48: …… | M48: 索引号 | N48: 是否异常
A49: 日期 | B49: 凭证编号 | C49: 业务内容 | D49: 对方科目 | E49: 金额 | F49: 识别特征 | G49: 信息1 | H49: 信息2 | I49: 识别特征 | J49: 信息1 | K49: 信息2
A56: 合计 | E56: =SUM(E50:E55) -> 0
A57: 三、审计说明：
A61: 四、审计结论：
A66: 编制说明：
A67: 1、函证替代程序：
B68: ①检查本期付款、期后收货或回收；
B69: ②检查原始凭证：合同、订货单、发票或收据、银行回单、支票存根等；
B70: ③对回函可能性不高的、余额重大的，发函同时执行替代程序。
A72: 2、概述：（1）程序的测试情况、结果；
A73: （2）拟调整事项及其调整分录、未调整事项及其影响，审计范围受到限制情况及其影响。

Sheet 邮件传真回函可靠性验证K0-7
A1: 致同会计师事务所
A2: 邮件/传真回函可靠性验证记录
A3: =底稿目录!A2 -> 被审计单位： | E3: =底稿目录!A4 -> 编制人： | H3: =底稿目录!A5 -> 编制日期： | M3: 索引号： | N3: =底稿目录!F12 -> K0-7
A4: =底稿目录!A3 -> 截止日：202X年12月31日 | E4: =底稿目录!A6 -> 复核人： | H4: =底稿目录!A7 -> 复核日期： | M4: 页次：
A5: 序号 | B5: 函证索引号 | C5: 被询证单位名称 | D5: 回函方式 | E5: 是否由审计项目组直接接收 | F5: 是否寄回原件 | G5: 期末未收回原件函证可靠性验证 | N5: 回函可靠性结论
G6: 被函证者身份确认（注1） | H6: 发函及回函传真信息及验证 | I6: 发函邮箱 | J6: 回函邮箱 | K6: 邮箱可靠性验证（注2） | L6: 是否致电被函证者确认 | M6: 对函证信息可靠性的考虑（注3）
A7: 1
A8: 2
A9: 3
A10: 4
A11: 5
A12: 6
A13: 7
A14: 8
A15: 9
A16: 10
A17: 审计说明：
A18: 应将将执行可靠性验证确认过程的审计人员姓名及日期、获得被询证者电话的方式、被询证者联络人员姓名及所属部门、沟通的过程及其结果等内容清晰地记录在审计工作底稿中
A20: 审计结论：
A23: 提示：对以电子形式收到的回函（如传真或电子邮件），由于回函者的身份及其授权情况很难确定，对回函的更改也难以发觉，因此可靠性存在风险。注册会计师和回函者采用一定的程序为电子形式的回函创造安全环境，可以降低该风险。
A24: 注1：回函者的身份确认
A25: 1、需确定回函者是否属于被询证者或由被询证者授权回函的人员，回函者对所函证信息是否知情、是否具有客观性。
A26: 2、身份确认方式：（1）获取回函者名片；（2）可通过被询证者的网站或其他公开网站核对回函者的姓名和身份信息；（3）将回函者的信息与被审计单位持有的相关信息
A27: （例如客户或供应商清单、相关销售或采购合同、被审计单位收到或开具的增值税发票等）中的联系人信息进行核对。
A28: 注2：回函邮箱的可靠性验证 | D28: 采用电子邮件方式收到回函的控制要点详见函证技术提示4号，链接为：https://www.gt-china.com.cn/article_view.php?id=9691；
A29: 1、从私人电子信箱发送的回函不可靠。
A30: 2、邮箱验证方式：（1）验证回函邮箱是否为回函者所在单位的工作邮箱（如后缀），验证公司邮箱发送的回函中电子数码签名的可靠性；（2）通过电话联系被询证者，确定
A31: 被询证者是否发送了回函，是否授权回函者回函。
A32: 2、电子签名：按照《电子签名法》要求，核查相关平台是否经国务院信息产业主管部门核准，并获取充分适当的审计证据，如相关平台的认证证书、境内核准情况等，在必要时，
A33: 可能还需要对相关平台的安全可靠性进行专门评价。
A34: 注3：函证信息可靠性的考虑
A35: 1、为了降低被询证者对所列示的信息不验证是否正确就予以回函确认的风险，注册会计师可以选择在询证函中不列明账户余额（或其他信息），而是要求被询证者填列有关信息
A36: 或进一步提供信息。
A37: 2、询证函应增加不可编辑的水印、不易复制的特定标识；收到回函后检查是否为发出的函件，是否存在篡改迹象，印章（如有）是否与其他文书一致。

Sheet 函证程序舞弊风险评价表K0-8
A1: 致同会计师事务所
A2: 函证程序舞弊风险评价表
A3: =底稿目录!A2 -> 被审计单位： | D3: =底稿目录!A4 -> 编制人： | F3: =底稿目录!A5 -> 编制日期： | H3: 索引号： | I3: =底稿目录!F13 -> K0-8
A4: =底稿目录!A3 -> 截止日：202X年12月31日 | D4: =底稿目录!A6 -> 复核人： | F4: =底稿目录!A7 -> 复核日期： | H4: 页次：
A5: 与函证程序有关的舞弊风险迹象 | G5: 是否存在 | H5: 索引号或信息来源 | I5: 应对措施
A6: 1.管理层不允许寄发询证函；
A7: 2.管理层过度热情配合函证程序；
A8: 3.管理层试图干预、拦截、篡改询证函或回函，如坚持以特定的方式发送询证函；
A9: 4.管理层提供的函证相关信息含糊、矛盾、不完整或有缺失；
A10: 5.被询证者将回函寄至被审计单位，被审计单位将其转交注册会计师；
A11: 6.注册会计师跟进访问被询证者，发现回函信息与被询证者记录不一致；
A12: 7.从私人电子信箱发送的回函；
A13: 8.收到同一日期发回的、相同笔迹的多份回函；
A14: 9.收到的回函与发出的询证函不是同一份、不是原件；
A15: 10.不同被询证者回函信封上的联系方式（地址、电话等）相同或相近；位于不同地址的多家被询证者的回函邮戳显示的发函地址相同；
A16: 11.印章模糊不清难以核对，或印章存在明显瑕疵，或与被询证者不一致；
A17: 12.收到不同被询证者用快递寄回的回函，但快递的交寄人或发件人是同一个人或是被审计单位的员工（或关联方），或者虽然寄件人名字不同，但手机号或其他联系方式相同，或者不同被询证者回函单号相连或相近；
A18: 13.回函显示的发函地址与被审计单位记录的被询证者的地址不一致；
A19: 14.不正常的回函率； | J19: 例如：银行函证未回函；与以前年度相比，回函率异常偏高或回函率重大变动；向被审计单位债权人发送的询证函回函率很低；
A20: 15.被询证者缺乏独立性；配合被审计单位，向注册会计师提供不真实或不准确的回函信息，隐瞒相关事实和情况； | J20: 例如：被审计单位及其管理层能够对被询证者施加重大影响以使其向注册会计师提供虚假或误导信息（如被审计单位是被询证者唯一或重要的客户或供应商）；被询证者既是被审计单位资产的保管人又是资产的管理者。
A21: 16.管理层不愿意提高函证所涉及信息（如抵押、担保等信息）的披露质量，使财务报表更为完整透明，但又不能提供合理解释；
A22: 17.回函印章与以前期间收到的回函印章不一致
A23: 18.回函中包含免责或其他限制性条款
A24: 19.第三方对函证信息有误的询证函作出与函证信息相符的回函，或对前后两次函证信息有差异的询证函均作出信息相符的回函。
A25: ……
A26: 汇总上述所有已发现的舞弊迹象，在“汇总识别的风险因素”中记录并区分财务报表层次的风险和认定层次的风险，制订初步的应对措施。 | H26: B50
A27: 审计说明：
A29: 审计结论：
A31: 编制说明： 1、本底稿系根据《中国注册会计师审计准则问题解答第2号——函证》的要求，对执行函证程序过程中需要关注的舞弊风险迹象厘定。在进行了解时，应考虑上述表格中列示的项目，但考虑内容不限于这些内容。 2、在记录了解的内容时，如果涉及到多个项目，可以综合考虑并予以记录。 3、通过访谈、询问等程序获知上述信息的，应注明被调查人姓名、职位、相关的信息来源及相关工作底稿（若有）索引。 4、上述内容如果项目组的回答为“是”，应说明初步的审计应对措施计划，并在总体审计策略和具体审计计划中体现对所涉及的舞弊风险等重大错报风险评估结果的影响。

Sheet GT_Custom
A1: C1 | B1: Custom 1
A2: C2 | B2: Custom 2
A3: C3 | B3: Custom 3
A4: C4 | B4: Custom 4
A5: C5 | B5: Custom 5
A6: C6 | B6: Custom 6
A7: C7 | B7: Custom 7
A8: C8 | B8: Custom 8
