Workbook

Sheet 底稿目录
A1: 底稿开列时，可先在以下单元格填写有关内容，以便其他底稿引用有关数据：
A2: 被审计单位：
A3: 截止日：202X年12月31日
A4: 编制人： | D4: 序号 | E4: 内容 | F4: 索引号 | G4: 备注
A5: 编制日期： | D5: 1 | E5: 实质性程序表 | F5: K1A
A6: 复核人： | D6: 2 | E6: 审定表 | F6: K1-1
A7: 复核日期： | D7: 3 | E7: 附注披露信息(上市公司) | H7: 无需打印
A8: 关联方类别设置（以下内容请根据实际情况修改）： | D8: 4 | E8: 附注披露信息(国企) | H8: 无需打印
A9: 关联方（合并范围内） | D9: 5 | E9: 明细表 | F9: K1-2
A10: 关联方（合并范围外） | D10: 6 | E10: 坏账准备明细表 | F10: K1-3
A11: 非关联方 | D11: 7 | E11: 调整分录汇总 | F11: K1-4
A12: …… | D12: 8 | E12: 大额其他应付款情况分析表 | F12: K1-5
D13: 9 | E13: 函证结果汇总表 | F13: K0-1
D14: 10 | E14: 核实被函证单位信息 | F14: K0-2
D15: 11 | E15: 跟函函证过程控制 | F15: K0-3
D16: 12 | E16: 函证差异调节表 | F16: K0-4
D17: 13 | E17: 其他应收款替代程序检查表 | F17: K0-5
A18: 关于工作底稿与审计程序索引号对应的说明 | D18: 14 | E18: 邮件传真回函可靠性验证 | F18: K0-7
A19: 1.编制的审计工作底稿应与审计程序对应。审计项目组应根据被审计单位实际情况和风险评估情况在实质性程序表中裁剪、修改或增加审计程序，根据实际执行的审计程序完成相应审计工作底稿，编制的工作底稿中应按自然顺序依次编制索引号，并通过唯一的索引号将与实质性程序表中的程序对应关联（即将工作底稿的索引号填入实质性程序表中的底稿索引号列）。 | D19: 15 | E19: 函证程序舞弊风险评价表 | F19: K0-8
D20: 16 | E20: 信用减值损失会计政策检查 | F20: K1-6
D21: 17 | E21: 三阶段划分检查表 | F21: K1-7
D22: 18 | E22: 坏账准备测算 | F22: K1-8
A23: 2.获取的支持性证据应与审计底稿或程序对应。审计项目组在完成底稿时获取的支持性证据应根据底稿索引号编制下一级按自然顺序排序的索引号（如D1-2-1、D1-2-2、……），并在底稿中说明引用的支持性证据、关联索引号。 | D23: 19 | E23: 坏账准备转回（收回）、核销检查表 | F23: K1-9
D24: 20 | E24: 长期未收回款项检查表 | F24: K1-10
D25: 21 | E25: 关联方及交易检查表 | F25: K1-11
A26: 3.工作底稿索引号的编码规则：实质性程序索引号按循环从“D”到“N”,循环内账户以顺序号排列，模板中底稿索引号按账户顺序+自然数顺序（即模板中索引号按二级自然顺序排列，如D1-1、D1-2、D1-3、……D1-N）。 | D26: 22 | E26: 其他应收款检查表 | F26: K1-12

Sheet 实质性程序表 K1A
A1: 致同会计师事务所
A2: 其他应收款实质性程序
A3: =底稿目录!A2 -> 被审计单位： | C3: =底稿目录!A4 -> 编制人： | E3: =底稿目录!A5 -> 编制日期： | H3: 索引号： | I3: =底稿目录!F5 -> K1A
A4: =底稿目录!A3 -> 截止日：202X年12月31日 | C4: =底稿目录!A6 -> 复核人： | E4: =底稿目录!A7 -> 复核日期： | H4: 页次：
A5: 一、本账户涉及的科目
A6: 其他应收款、坏账准备
A7: 二、审计目标与认定的对应关系
A8: 审计目标 | G8: 财务报表的认定
A9: A. 资产负债表中记录的其他应收款、坏账准备是存在的，且已记录于恰当的账户 | G9: 存在
A10: B. 所有应记录的其他应收款、坏账准备均已记录，所有应当包括在财务报表中的相关披露均已包括 | G10: 完整性
A11: C. 记录的其他应收款、坏账准备由被审计单位拥有或控制 | G11: 权利和义务
A12: D. 其他应收款、坏账准备以恰当的金额包括在财务报表中，与之相关的计价或分摊调整已恰当记录，相关披露已得到恰当计量和描述 | G12: 准确性、计价和分摊
A13: E. 其他应收款、坏账准备已被恰当地汇总或分解且表述清楚，相关披露在按照企业会计准则的编制基础下是相关的、可理解的 | G13: 列报
A14: 三、计划实施的实质性程序
A15: 序号 | B15: 审计程序 | C15: 程序分类 | D15: 财务报表的认定 | I15: 底稿索引号
D16: 存在 | E16: 完整性 | F16: 权利和 义务 | G16: 准确性、计价和分摊 | H16: 列报 | J16: 根据被审计单位实际情况和风险评估情况裁剪、修改或增加审计程序
A17: 1 | B17: 获取或编制明细表、执行下列程序，并编制审定表： （1）复核加计正确，并与总账数和明细账合计数核对是否相符，期初余额与上期审定期末余额是否相符； （2）获取管理层编制的预付账款账龄分析表，检查账龄划分是否正确； （3）了解重大明细项目的其他应收款内容及性质，进行类别分析，重点关注是否存在资金被关联企业(或实际控制人)大量占用、变相拆借资金、隐形投资、误用会计科目、或有损失等重大异常交易； （4）考虑结合应收账款、其他应付款等明细余额，检查是否有同时挂账的项目，核算内容是否重复，分析有贷方余额的项目，查明原因，必要时作出适当调整； （5）检查非记账本位币其他应收款的折算汇率及折算是否正确；（如适用） （6）分析期末余期与期初余额各款项性质占比变动是否合理、账龄的结构是否合理； | C17: 常规★ | D17: √ | E17: √ | G17: √ | I17: K1-1 /K1-2 /K1-3
A18: 2 | B18: 在使用手工编制、自定义信息报告、系统生成的非固定格式报告等由被审计单位生成的信息时，测试有关信息准确性和完整性，并考虑针对编制和维护由被审计单位生成的信息的相关控制实施控制测试，以评价该信息是否能够为实现审计目的提供基础。 | C18: 常规★ | E18: √ | G18: √ | I18: T1 /K0-2 / | J18: 可参见《审计手册》4.2.6，由被审计单位生成的信息可能是由系统生成的、或手工编制的、或二者兼而有之的方式生成的。例如，由被审计单位生成的信息可能包括： • 不涉及自定义的、由系统生成的报告（如，固定格式报告）； • 可能通过人工自定义的、由系统生成的报告，例如，（计算机）查询信息或特别定制的报告； • 手工编制的信息，例如，汇总信息的电子表格或用以支持分配、计算以及调节的电子表格； • 其他系统生成或手工编制的信息，例如，由被审计单位编制的客户发票； • 通过影印、拍摄、扫描或其他方式转换成电子形式的文件记录。
A19: 3 | B19: 获取上期期末的其他应收款、坏账准备明细，复核加计正确，总账与明细账核对一致；识别重大的明细项目、查找异常项目并了解该明细项目的核算目的和用途；检查上期其他应收款在本期支付情况；函证期初余额以及其他必要追加的审计程序。（适用于首次承接） | C19: 备选 | D19: √ | E19: √ | F19: √ | G19: √ | J19: 由被审计单位生成的信息不包括： • 总分类账或明细分类账、试算平衡表、或经审计的财务报表； • 第三方（除了服务机构）的报表或报告，例如，原始银行对账单，或函证的回函； • 外部数据（例如，第三方发布的数据，如，定价来源）。
A20: 4 | B20: 分析主要债务人其他应收款期末余额，关注期末大额其他应收款商业合理性、真实性、期后收款情况；关注大额代收、代付性质款项，是否具有合理的交易目的等。 | C20: 常规★ | D20: √ | G20: √ | I20: K1-5
A21: 5 | B21: 实施函证程序： （1）以积极方式对其他应收款进行函证，设计询证函、发函前核实被函证单位信息； （2）注册会计师独立收发询证函； （3）编制函证结果汇总表，检查发函、回函物流信息和轨迹、比对回函印章和签字等以核实回函的真实性，检查回函是否相符，对不符事项查明原因确定是否存在错报； （4）如果未收到回函，应当考虑与被询证者联系，要求对方作出回应或再次寄发询证函，无法收到的回函实施替代程序； （5）如果管理层不允许寄发询证函的，询问管理层不允许寄发的原因，并就其原因的正当、合理性收集证据；考虑实施替代审计程序以获取相关、可靠的审计证据； （6）如果管理层不允许寄发询证函的原因不合理、或者认为回函不可靠，评价对评估的重大错报风险以及其他审计程序的性质、时间安排和范围的影响，并确定其对审计工作和审计意见的影响。 | C21: 常规★ | D21: √ | E21: √ | F21: √ | G21: √ | I21: K0
A22: 6 | B22: 了解并评价计提坏账准备计提政策、假设及计提方法，检查被审计单位制定的坏账准备政策的合理性。关注会计政策、会计估计合理性、一贯性，是否存在会计估计变更，关注其是否利用会计政策和会计估计及其变更操纵利润。 | C22: 常规★ | D22: √ | E22: √ | G22: √ | I22: K1-6
A23: 7 | B23: 检查其他应收款坏账准备计提是否正确： （1）了解其他应收款坏账准备计提会计政策，确定应收票据坏账准备是否以预期信用损失为基础计提，计提政策是否恰当，是否一贯执行，三阶段划分是否恰当；必要时，与同行业其他公司的会计政策进行对比，关注其是否利用会计政策和会计估计变更操纵利润； （2）重新计算应计提的坏账准备，与被审计单位已记录的坏账准备进行比较； （3）关注大额坏账准备转回是否合理。实际发生坏账损失的，检查转销依据是否符合有关规定，会计处理是否正确。已经确认并转销的坏账重新收回的，检查其会计处理是否正确。 | C23: 常规★ | E23: √ | G23: √ | I23: K1-7 /K1-8 /K1-9
A24: 8 | B24: 针对账龄较长的其他应收款，分析账龄较长的原因，是否存在纠纷或者对方缺乏付款能力等，考虑坏账准备计提是否充分；判断是否有长期挂账而推迟正常经营管理所需开支情况，并检查其原始凭证，确认会计处理是否正确，必要时进行函证。 | C24: 常规★ | D24: √ | G24: √ | I24: K1-10
A25: 9 | B25: 检查关联方款项： （1）了解交易的商业理由、交易事项的目的、价格和条件，考虑对关联方其他应收账款的合理性、合法性；结合费用审计考虑是否存在代关联方支付成本、费用；关注是否存在大股东或实际控制人及其关联方借款、资金占用； （2）检查对关联方其他应收账款的真实性相关的支持性文件、检查会计处理是否正确； （3）向关联方函证往来余额，必要时函证交易的条件和发生额（包括担保和其他重要信息）； （4）必要时，向与交易相关的人员和机构（如银行、律师）函证或与其讨论有关信息； （5）考虑是否存在未识别的关联方，关联交易和余额披露是否正确。 | C25: 常规★ | D25: √ | E25: √ | F25: √ | G25: √ | H25: √ | I25: K1-11 /K1-12 /K0
A26: 10 | B26: 检查与其他应收款有关的的记账凭证和相应的支持性证据以确定交易的真实性，是否按规定进行相应的会计处理和披露。 | C26: 常规★ | D26: √ | F26: √ | G26: √ | I26: K1-12
A27: 11 | B27: 结合其他收益等科目，对于在资产负债表日按照应收金额确认的政府补助，执行以下程序：查验正式发布的财政资金管理办法中的（定额）测算公式，或检查政府补助批文是否标明确切金额，分析政府补助金额是否存在重大不确定性；检查补助款批文中承诺的拨付期限，以及款项拨付对应的财政预算，分析政府补助在规定期限内的可收回性。 | C27: 备选 | D27: √ | F27: √ | G27: √ | I27: K10-5
A28: 12 | B28: 考虑是否存在超出被审计单位正常经营活动的重大、异常交易等，根据评估的舞弊风险等因素增加的审计程序。 | C28: IPO/上市/新三板/重组/舞弊应对
A29: 13 | B29: 检查其他应收款及坏账准备是否已按企业会计准则或其他适用的规定在财务报表中做出恰当列报和披露。 | C29: 常规★ | H29: √ | I29: A1-1/A1-15 /A1-16

Sheet 审定表K1-1
A1: 致同会计师事务所
A2: 其他应收款审定表
A3: =底稿目录!A2 -> 被审计单位： | E3: =底稿目录!A4 -> 编制人： | H3: =底稿目录!A5 -> 编制日期： | K3: 索引： | L3: =底稿目录!F6 -> K1-1
A4: =底稿目录!A3 -> 截止日：202X年12月31日 | E4: =底稿目录!A6 -> 复核人： | H4: =底稿目录!A7 -> 复核日期： | K4: 页次：
A5: 项目【不含应收利息、应收股利】 | B5: 期初数 | F5: 期末数 | J5: 本期与上期审定数比较 | L5: 原因分析
B6: 未审数 | C6: 账项调整 | D6: 重分类调整 | E6: 审定数 | F6: 未审数 | G6: 账项调整 | H6: 重分类调整 | I6: 审定数 | J6: 变动额 | K6: 变动率
A7: 一、其他应收款
A8: （一）其他应收款原值
A9: 单项计提坏账准备 | B9: =SUMIF('明细表K1-2'!$AF$12:$AF$32,"单项计提",'明细表K1-2'!$F$12:$F$32) -> 0 | C9: =SUMIF('明细表K1-2'!$AF$12:$AF$32,"单项计提",'明细表K1-2'!$G$12:$G$32) -> 0 | D9: =SUMIF('明细表K1-2'!$AF$12:$AF$32,"单项计提",'明细表K1-2'!$H$12:$H$32) -> 0 | E9: =B9+C9+D9 -> 0 | F9: =SUMIF('明细表K1-2'!$AF$12:$AF$32,"单项计提",'明细表K1-2'!$S$12:$S$32) -> 0 | G9: =SUMIF('明细表K1-2'!$AF$12:$AF$32,"单项计提",'明细表K1-2'!$V$12:$V$32) -> 0 | H9: =SUMIF('明细表K1-2'!$AF$12:$AF$32,"单项计提",'明细表K1-2'!$W$12:$W$32) -> 0 | I9: =F9+G9+H9 -> 0 | J9: =I9-E9 -> 0 | K9: =IF(AND(E9=0,I9=0),"",IF(AND(E9=0,I9>0),1,J9/E9))
A10: 按组合计提坏账准备 | B10: =SUM(B11:B13) -> 0 | C10: =SUM(C11:C13) -> 0 | D10: =SUM(D11:D13) -> 0 | E10: =SUM(E11:E13) -> 0 | F10: =SUM(F11:F13) -> 0 | G10: =SUM(G11:G13) -> 0 | H10: =SUM(H11:H13) -> 0 | I10: =SUM(I11:I13) -> 0 | J10: =I10-E10 -> 0 | K10: =IF(AND(E10=0,I10=0),"",IF(AND(E10=0,I10>0),1,J10/E10))
A11: 账龄组合 | B11: =SUMIF('明细表K1-2'!$AF$12:$AF$32,"账龄组合",'明细表K1-2'!$F$12:$F$32) -> 0 | C11: =SUMIF('明细表K1-2'!$AF$12:$AF$32,"账龄组合",'明细表K1-2'!$G$12:$G$32) -> 0 | D11: =SUMIF('明细表K1-2'!$AF$12:$AF$32,"账龄组合",'明细表K1-2'!$H$12:$H$32) -> 0 | E11: =B11+C11+D11 -> 0 | F11: =SUMIF('明细表K1-2'!$AF$12:$AF$32,"账龄组合",'明细表K1-2'!$S$12:$S$32) -> 0 | G11: =SUMIF('明细表K1-2'!$AF$12:$AF$32,"账龄组合",'明细表K1-2'!$V$12:$V$32) -> 0 | H11: =SUMIF('明细表K1-2'!$AF$12:$AF$32,"账龄组合",'明细表K1-2'!$W$12:$W$32) -> 0 | I11: =F11+G11+H11 -> 0 | J11: =I11-E11 -> 0 | K11: =IF(AND(E11=0,I11=0),"",IF(AND(E11=0,I11>0),1,J11/E11))
A12: 客户类型组合 | B12: =SUMIF('明细表K1-2'!$AF$12:$AF$32,"客户类型组合",'明细表K1-2'!$F$12:$F$32) -> 0 | C12: =SUMIF('明细表K1-2'!$AF$12:$AF$32,"客户类型组合",'明细表K1-2'!$G$12:$G$32) -> 0 | D12: =SUMIF('明细表K1-2'!$AF$12:$AF$32,"客户类型组合",'明细表K1-2'!$H$12:$H$32) -> 0 | E12: =B12+C12+D12 -> 0 | F12: =SUMIF('明细表K1-2'!$AF$12:$AF$32,"客户类型组合",'明细表K1-2'!$S$12:$S$32) -> 0 | G12: =SUMIF('明细表K1-2'!$AF$12:$AF$32,"客户类型组合",'明细表K1-2'!$V$12:$V$32) -> 0 | H12: =SUMIF('明细表K1-2'!$AF$12:$AF$32,"客户类型组合",'明细表K1-2'!$W$12:$W$32) -> 0 | I12: =F12+G12+H12 -> 0 | J12: =I12-E12 -> 0 | K12: =IF(AND(E12=0,I12=0),"",IF(AND(E12=0,I12>0),1,J12/E12))
A13: 其他组合 | B13: =SUMIF('明细表K1-2'!$AF$12:$AF$32,"其他组合",'明细表K1-2'!$F$12:$F$32) -> 0 | C13: =SUMIF('明细表K1-2'!$AF$12:$AF$32,"其他组合",'明细表K1-2'!$G$12:$G$32) -> 0 | D13: =SUMIF('明细表K1-2'!$AF$12:$AF$32,"其他组合",'明细表K1-2'!$H$12:$H$32) -> 0 | E13: =B13+C13+D13 -> 0 | F13: =SUMIF('明细表K1-2'!$AF$12:$AF$32,"其他组合",'明细表K1-2'!$S$12:$S$32) -> 0 | G13: =SUMIF('明细表K1-2'!$AF$12:$AF$32,"其他组合",'明细表K1-2'!$V$12:$V$32) -> 0 | H13: =SUMIF('明细表K1-2'!$AF$12:$AF$32,"其他组合",'明细表K1-2'!$W$12:$W$32) -> 0 | I13: =F13+G13+H13 -> 0 | J13: =I13-E13 -> 0 | K13: =IF(AND(E13=0,I13=0),"",IF(AND(E13=0,I13>0),1,J13/E13))
A14: 小计 | B14: =SUM(B9,B10) -> 0 | C14: =SUM(C9,C10) -> 0 | D14: =SUM(D9,D10) -> 0 | E14: =SUM(E9,E10) -> 0 | F14: =SUM(F9,F10) -> 0 | G14: =SUM(G9,G10) -> 0 | H14: =SUM(H9,H10) -> 0 | I14: =SUM(I9,I10) -> 0 | J14: =I14-E14 -> 0 | K14: =IF(AND(E14=0,I14=0),"",IF(AND(E14=0,I14>0),1,J14/E14))
A15: （二）其他应收款坏账准备
A16: =A9 -> 单项计提坏账准备 | E16: =B16+C16+D16 -> 0 | I16: =F16+G16+H16 -> 0 | J16: =I16-E16 -> 0 | K16: =IF(AND(E16=0,I16=0),"",IF(AND(E16=0,I16>0),1,J16/E16))
A17: =A10 -> 按组合计提坏账准备 | B17: =SUM(B18:B20) -> 0 | C17: =SUM(C18:C20) -> 0 | D17: =SUM(D18:D20) -> 0 | E17: =SUM(E18:E20) -> 0 | F17: =SUM(F18:F20) -> 0 | G17: =SUM(G18:G20) -> 0 | H17: =SUM(H18:H20) -> 0 | I17: =SUM(I18:I20) -> 0 | J17: =I17-E17 -> 0 | K17: =IF(AND(E17=0,I17=0),"",IF(AND(E17=0,I17>0),1,J17/E17))
A18: =A11 -> 账龄组合 | E18: =B18+C18+D18 -> 0 | I18: =F18+G18+H18 -> 0 | J18: =I18-E18 -> 0 | K18: =IF(AND(E18=0,I18=0),"",IF(AND(E18=0,I18>0),1,J18/E18))
A19: =A12 -> 客户类型组合 | E19: =B19+C19+D19 -> 0 | I19: =F19+G19+H19 -> 0 | J19: =I19-E19 -> 0 | K19: =IF(AND(E19=0,I19=0),"",IF(AND(E19=0,I19>0),1,J19/E19))
A20: =A13 -> 其他组合 | E20: =B20+C20+D20 -> 0 | I20: =F20+G20+H20 -> 0 | J20: =I20-E20 -> 0 | K20: =IF(AND(E20=0,I20=0),"",IF(AND(E20=0,I20>0),1,J20/E20))
A21: 小计 | B21: =SUM(B16,B17) -> 0 | C21: =SUM(C16,C17) -> 0 | D21: =SUM(D16,D17) -> 0 | E21: =SUM(E16,E17) -> 0 | F21: =SUM(F16,F17) -> 0 | G21: =SUM(G16,G17) -> 0 | H21: =SUM(H16,H17) -> 0 | I21: =SUM(I16,I17) -> 0 | J21: =I21-E21 -> 0 | K21: =IF(AND(E21=0,I21=0),"",IF(AND(E21=0,I21>0),1,J21/E21))
A22: （三）其他应收款净值
A23: =A9 -> 单项计提坏账准备 | B23: =B9-B16 -> 0 | C23: =C9-C16 -> 0 | D23: =D9-D16 -> 0 | E23: =E9-E16 -> 0 | F23: =F9-F16 -> 0 | G23: =G9-G16 -> 0 | H23: =H9-H16 -> 0 | I23: =I9-I16 -> 0 | J23: =I23-E23 -> 0 | K23: =IF(AND(E23=0,I23=0),"",IF(AND(E23=0,I23>0),1,J23/E23))
A24: =A10 -> 按组合计提坏账准备 | B24: =SUM(B25:B27) -> 0 | C24: =SUM(C25:C27) -> 0 | D24: =SUM(D25:D27) -> 0 | E24: =SUM(E25:E27) -> 0 | F24: =SUM(F25:F27) -> 0 | G24: =SUM(G25:G27) -> 0 | H24: =SUM(H25:H27) -> 0 | I24: =SUM(I25:I27) -> 0 | J24: =I24-E24 -> 0 | K24: =IF(AND(E24=0,I24=0),"",IF(AND(E24=0,I24>0),1,J24/E24))
A25: =A11 -> 账龄组合 | B25: =B11-B18 -> 0 | C25: =C11-C18 -> 0 | D25: =D11-D18 -> 0 | E25: =E11-E18 -> 0 | F25: =F11-F18 -> 0 | G25: =G11-G18 -> 0 | H25: =H11-H18 -> 0 | I25: =I11-I18 -> 0 | J25: =I25-E25 -> 0 | K25: =IF(AND(E25=0,I25=0),"",IF(AND(E25=0,I25>0),1,J25/E25))
A26: =A12 -> 客户类型组合 | B26: =B12-B19 -> 0 | C26: =C12-C19 -> 0 | D26: =D12-D19 -> 0 | E26: =E12-E19 -> 0 | F26: =F12-F19 -> 0 | G26: =G12-G19 -> 0 | H26: =H12-H19 -> 0 | I26: =I12-I19 -> 0 | J26: =I26-E26 -> 0 | K26: =IF(AND(E26=0,I26=0),"",IF(AND(E26=0,I26>0),1,J26/E26))
A27: =A13 -> 其他组合 | B27: =B13-B20 -> 0 | C27: =C13-C20 -> 0 | D27: =D13-D20 -> 0 | E27: =E13-E20 -> 0 | F27: =F13-F20 -> 0 | G27: =G13-G20 -> 0 | H27: =H13-H20 -> 0 | I27: =I13-I20 -> 0 | J27: =I27-E27 -> 0 | K27: =IF(AND(E27=0,I27=0),"",IF(AND(E27=0,I27>0),1,J27/E27))
A28: 合计 | B28: =SUM(B23,B24) -> 0 | C28: =SUM(C23,C24) -> 0 | D28: =SUM(D23,D24) -> 0 | E28: =SUM(E23,E24) -> 0 | F28: =SUM(F23,F24) -> 0 | G28: =SUM(G23,G24) -> 0 | H28: =SUM(H23,H24) -> 0 | I28: =SUM(I23,I24) -> 0 | J28: =I28-E28 -> 0 | K28: =IF(AND(E28=0,I28=0),"",IF(AND(E28=0,I28>0),1,J28/E28))
A29: 二、其他应收款账龄分布
A30: （一）账龄原值
A31: 一年以内 | E31: =B31+C31+D31 -> 0 | F31: ='明细表K1-2'!Y33 -> 0 | I31: =F31+G31+H31 -> 0 | J31: =I31-E31 -> 0 | K31: =IF(AND(E31=0,I31=0),"",IF(AND(E31=0,I31>0),1,J31/E31))
A32: 一到二年 | E32: =B32+C32+D32 -> 0 | F32: ='明细表K1-2'!Z33 -> 0 | I32: =F32+G32+H32 -> 0 | J32: =I32-E32 -> 0 | K32: =IF(AND(E32=0,I32=0),"",IF(AND(E32=0,I32>0),1,J32/E32))
A33: 二到三年 | E33: =B33+C33+D33 -> 0 | F33: ='明细表K1-2'!AA33 -> 0 | I33: =F33+G33+H33 -> 0 | J33: =I33-E33 -> 0 | K33: =IF(AND(E33=0,I33=0),"",IF(AND(E33=0,I33>0),1,J33/E33))
A34: 三到四年 | E34: =B34+C34+D34 -> 0 | F34: ='明细表K1-2'!AB33 -> 0 | I34: =F34+G34+H34 -> 0 | J34: =I34-E34 -> 0 | K34: =IF(AND(E34=0,I34=0),"",IF(AND(E34=0,I34>0),1,J34/E34))
A35: 四到五年 | E35: =B35+C35+D35 -> 0 | F35: ='明细表K1-2'!AC33 -> 0 | I35: =F35+G35+H35 -> 0 | J35: =I35-E35 -> 0 | K35: =IF(AND(E35=0,I35=0),"",IF(AND(E35=0,I35>0),1,J35/E35))
A36: 五年以上 | E36: =B36+C36+D36 -> 0 | F36: ='明细表K1-2'!AD33 -> 0 | I36: =F36+G36+H36 -> 0 | J36: =I36-E36 -> 0 | K36: =IF(AND(E36=0,I36=0),"",IF(AND(E36=0,I36>0),1,J36/E36))
A37: 小计 | B37: =SUM(B31:B36) -> 0 | C37: =SUM(C31:C36) -> 0 | D37: =SUM(D31:D36) -> 0 | E37: =SUM(E31:E36) -> 0 | F37: =SUM(F31:F36) -> 0 | G37: =SUM(G31:G36) -> 0 | H37: =SUM(H31:H36) -> 0 | I37: =SUM(I31:I36) -> 0 | J37: =I37-E37 -> 0 | K37: =IF(AND(E37=0,I37=0),"",IF(AND(E37=0,I37>0),1,J37/E37))
A38: （二）账龄坏账准备
A39: =A31 -> 一年以内 | E39: =B39+C39+D39 -> 0 | G39: =I39-F39 -> 0 | I39: ='坏账准备测算K1-8'!K21 -> 0 | J39: =I39-E39 -> 0 | K39: =IF(AND(E39=0,I39=0),"",IF(AND(E39=0,I39>0),1,J39/E39))
A40: =A32 -> 一到二年 | E40: =B40+C40+D40 -> 0 | G40: =I40-F40 -> 0 | I40: ='坏账准备测算K1-8'!K22 -> 0 | J40: =I40-E40 -> 0 | K40: =IF(AND(E40=0,I40=0),"",IF(AND(E40=0,I40>0),1,J40/E40))
...

Sheet 附注披露信息(上市公司）
A1: 致同会计师事务所
A2: 附注披露信息（上市公司）
A3: =底稿目录!A2 -> 被审计单位： | C3: =底稿目录!A4 -> 编制人： | E3: =底稿目录!A5 -> 编制日期：
A4: =底稿目录!A3 -> 截止日：202X年12月31日 | C4: =底稿目录!A6 -> 复核人： | E4: =底稿目录!A7 -> 复核日期：
A5: 其他应收款
A6: ① 按账龄披露
A7: 账 龄 | B7: 期末数 | C7: 上年年末数
A8: 1年以内 | B8: ='审定表K1-1'!I31 -> 0 | C8: ='审定表K1-1'!E31 -> 0
A9: 其中：0-X个月
A10: X-Y个月
A12: 1年以内小计： | B12: =SUM(B9:B11) -> 0 | C12: =SUM(C9:C11) -> 0
A13: 1至2年 | B13: ='审定表K1-1'!I32 -> 0 | C13: ='审定表K1-1'!E32 -> 0
A14: 2至3年 | B14: ='审定表K1-1'!I33 -> 0 | C14: ='审定表K1-1'!E33 -> 0
A15: 3至4年 | B15: ='审定表K1-1'!I34 -> 0 | C15: ='审定表K1-1'!E34 -> 0
A16: 4至5年 | B16: ='审定表K1-1'!I35 -> 0 | C16: ='审定表K1-1'!E35 -> 0
A17: 5年以上 | B17: ='审定表K1-1'!I36 -> 0 | C17: ='审定表K1-1'!E36 -> 0
A18: 小 计 | B18: =SUM(B12:B17) -> 0 | C18: =SUM(C12:C17) -> 0
A19: 减：坏账准备 | B19: ='审定表K1-1'!I45 -> 0 | C19: ='审定表K1-1'!E45 -> 0
A20: 合 计 | B20: =B18-B19 -> 0 | C20: =C18-C19 -> 0
A21: ② 按款项性质披露
A22: 项 目 | B22: 期末数 | E22: 上年年末数
B23: 账面余额 | C23: 坏账准备 | D23: 账面价值 | E23: 账面余额 | F23: 坏账准备 | G23: 账面价值
A24: 备用金 | B24: =SUMIFS('明细表K1-2'!X12:X32,'明细表K1-2'!E12:E32,$A$24) -> 0 | C24: =SUMIFS('明细表K1-2'!AE12:AE32,'明细表K1-2'!E12:E32,$A$24) -> 0 | D24: =B24-C24 -> 0 | E24: =SUMIFS('明细表K1-2'!I12:I32,'明细表K1-2'!E12:E32,$A$24) -> 0 | F24: =SUMIFS('明细表K1-2'!P12:P32,'明细表K1-2'!E12:E32,$A$24) -> 0 | G24: =E24-F24 -> 0
A25: 保证金、押金 | B25: =SUMIFS('明细表K1-2'!X12:X32,'明细表K1-2'!E12:E32,$A$25) -> 0 | C25: =SUMIFS('明细表K1-2'!AE12:AE32,'明细表K1-2'!E12:E32,$A$25) -> 0 | D25: =B25-C25 -> 0 | E25: =SUMIFS('明细表K1-2'!I12:I32,'明细表K1-2'!E12:E32,$A$25) -> 0 | F25: =SUMIFS('明细表K1-2'!P12:P32,'明细表K1-2'!E12:E32,$A$25) -> 0 | G25: =E25-F25 -> 0
D26: =B26-C26 -> 0 | G26: =E26-F26 -> 0
A27: 可无限量添加行 | D27: =B27-C27 -> 0 | G27: =E27-F27 -> 0
A28: 合 计 | B28: =SUM(B24:B27) -> 0 | C28: =SUM(C24:C27) -> 0 | D28: =SUM(D24:D27) -> 0 | E28: =SUM(E24:E27) -> 0 | F28: =SUM(F24:F27) -> 0 | G28: =SUM(G24:G27) -> 0
A29: ③ 坏账准备计提情况
A30: （15号文第十九条（四）5.采用一般预期信用损失模型计提坏账准备的应收款项，应分三阶段披露坏账准备计提情况，以及各阶段划分依据和坏账准备计提比例。）
A31: 期末，处于第一阶段的坏账准备：
A32: 类 别 | B32: 账面余额 | C32: 未来12个月内的预期信用损失率(%) | D32: 坏账准备 | E32: 账面价值 | F32: 理由
A33: 按单项计提坏账准备 | B33: =SUM(B34:B35) -> 0 | C33: =IFERROR(D33/B33,0) -> 0 | D33: =SUM(D34:D35) -> 0 | E33: =B33-D33 -> 0
A34: 其他应收款单位1 | C34: =IFERROR(D34/B34,0) -> 0 | E34: =B34-D34 -> 0
A35: 其他应收款单位2 | C35: =IFERROR(D35/B35,0) -> 0 | E35: =B35-D35 -> 0
A36: 按组合计提坏账准备【注意：与会计政策中披露的组合保持一致】 | B36: =SUM(B37:B38) -> 0 | C36: =IFERROR(D36/B36,0) -> 0 | D36: =SUM(D37:D38) -> 0 | E36: =B36-D36 -> 0
A37: 备用金 | B37: =B24 -> 0 | C37: =IFERROR(D37/B37,0) -> 0 | D37: =C24 -> 0 | E37: =B37-D37 -> 0
A38: 保证金、押金 | C38: =IFERROR(D38/B38,0) -> 0 | E38: =B38-D38 -> 0
A39: 合 计 | B39: =B36+B33 -> 0 | C39: =IFERROR(D39/B39,0) -> 0 | D39: =D36+D33 -> 0 | E39: =E36+E33 -> 0
A40: 期末，处于第二阶段的坏账准备：
A41: 类 别 | B41: 账面余额 | C41: 整个存续期预期信用损失率（%） | D41: 坏账准备 | E41: 账面价值 | F41: 理由
...

Sheet 附注披露信息（国企）
A1: 致同会计师事务所
A2: 附注披露信息（国企）
A3: =底稿目录!A2 -> 被审计单位： | B3: =底稿目录!A4 -> 编制人： | E3: =底稿目录!A5 -> 编制日期：
A4: =底稿目录!A3 -> 截止日：202X年12月31日 | B4: =底稿目录!A6 -> 复核人： | E4: =底稿目录!A7 -> 复核日期：
A5: 其他应收款
A6: 账 龄 | B6: 期末数 | C6: 期初数
A7: 1年以内（含1年） | B7: ='审定表K1-1'!I31 -> 0 | C7: ='审定表K1-1'!E31 -> 0
A8: 1至2年 | B8: ='审定表K1-1'!I32 -> 0 | C8: ='审定表K1-1'!E32 -> 0
A9: 2至3年 | B9: ='审定表K1-1'!I33 -> 0 | C9: ='审定表K1-1'!E33 -> 0
A10: 3至4年 | B10: ='审定表K1-1'!I34 -> 0 | C10: ='审定表K1-1'!E34 -> 0
A11: 4至5年 | B11: ='审定表K1-1'!I35 -> 0 | C11: ='审定表K1-1'!E35 -> 0
A12: 5年以上 | B12: ='审定表K1-1'!I36 -> 0 | C12: ='审定表K1-1'!E36 -> 0
A13: 小 计 | B13: =SUM(B7:B12) -> 0 | C13: =SUM(C7:C12) -> 0
A14: 减：坏账准备 | B14: ='审定表K1-1'!I45 -> 0 | C14: ='审定表K1-1'!E45 -> 0
A15: 合 计 | B15: =B13-B14 -> 0 | C15: =C13-C14 -> 0
A18: 按坏账准备计提方法分类披露其他应收款项
A19: 类 别 | B19: 期末余额
B20: 账面余额 | D20: 坏账准备 | F20: 账面价值
B21: 金额 | C21: 比例(%) | D21: 金额 | E21: 预期信用损失率(%)
A22: 单项计提坏账准备的其他应收款项 | C22: =IFERROR(B22/$B$22*100,0) -> 0 | E22: =IFERROR(D22/$B$18*100,0) -> 0 | F22: =B22-D22 -> 0
A23: 按信用风险特征组合计提坏账准备的其他应收款项 | C23: =IFERROR(B23/$B$22*100,0) -> 0 | E23: =IFERROR(D23/$B$18*100,0) -> 0 | F23: =B23-D23 -> 0
A24: …… | F24: =B24-D24 -> 0
F25: =B25-D25 -> 0
A26: 合 计 | B26: =B22+B23 -> 0 | C26: —— | E26: =IFERROR(D26/$B$18*100,0) -> 0 | F26: =B26-D26 -> 0
A27: 续：
A28: 类 别 | B28: 期初余额
B29: 账面余额 | D29: 坏账准备 | F29: 账面价值
B30: 金额 | C30: 比例(%) | D30: 金额 | E30: 预期信用损失率(%)
A31: 单项计提坏账准备的其他应收款项 | C31: =IFERROR(B31/$B$31*100,0) -> 0 | E31: =IFERROR(D31/$D$31*100,0) -> 0 | F31: =B31-D31 -> 0
A32: 按信用风险特征组合计提坏账准备的其他应收款项 | C32: =IFERROR(B32/$B$31*100,0) -> 0 | E32: =IFERROR(D32/$D$31*100,0) -> 0 | F32: =B32-D32 -> 0
A33: ……
A35: 合 计 | B35: =B31+B32 -> 0 | C35: —— | D35: =D31+D32 -> 0 | E35: =IFERROR(D35/$D$31*100,0) -> 0 | F35: =B35-D35 -> 0
A37: ① 单项计提坏账准备的其他应收款情况
A38: 债务人名称 | B38: 期末余额
B39: 账面余额 | C39: 坏账准备 | D39: 预期信用损失率(%) | E39: 计提理由
D40: =IFERROR(C40/$B$36*100,0) -> 0
D41: =IFERROR(C41/$B$36*100,0) -> 0
A42: 合计 | B42: =SUM(B40:B41) -> 0 | D42: =IFERROR(C42/$B$36*100,0) -> 0 | E42: ——
A44: ② 按信用风险特征组合计提坏账准备的其他应收款
A45: 账龄组合
...

Sheet 明细表K1-2
A1: 致同会计师事务所
A2: 其他应收款明细表
A3: =底稿目录!A2 -> 被审计单位： | I3: =底稿目录!A4 -> 编制人： | X3: =底稿目录!A5 -> 编制日期： | AI3: 索引号： | AJ3: =底稿目录!F9 -> K1-2
A4: =底稿目录!A3 -> 截止日：202X年12月31日 | I4: =底稿目录!A6 -> 复核人： | X4: =底稿目录!A7 -> 复核日期： | AI4: 页次：
A5: 一、审计目标:
A6: 1. 资产负债表中记录的其他应收款、坏账准备是存在的，且已记录于恰当的账户； | F6: 2.所有应记录的其他应收款、坏账准备均已记录，所有应当包括在财务报表中的相关披露均已包括； | M6: 3.其他应收款、坏账准备以恰当的金额包括在财务报表中，与之相关的计价或分摊调整已恰当记录，相关披露已得到恰当计量和描述。
A7: 二、审计过程：
A8: 1. 列示科目明细表，关注其他应收款贷方非收款减少和借方其他调整的情况。 | N8: 2. 与客户讨论并记录各主要明细项目的性质，并对波动较大的内容进行分析。根据相关审计情况，确定调整事项。
A9: 3. 对挂账时间超过三年以上本期又没有发生额或发生额很小的其他应收款，要求企业说明原因提供对方单位情况，根据情况进行调整。 | N9: 4. 关注关联方款项的变动情况，对异常情况要查明原因。
A10: 序号 | B10: 债务人名称 | C10: 公司代码 | D10: 关联方类型 | E10: 款项性质 | F10: 期初未审数 | G10: 期初账项调整 | H10: 期初重分类调整 | I10: 期初审定 | J10: 期初审定账龄 | P10: 期初坏账准备金额 | Q10: 借方发生 | R10: 贷方发生 | S10: 期末余额 | T10: 被审计单位重分类调整 | U10: 期末未审余额 | V10: 账项调整 | W10: 重分类调整 | X10: 其他应收款余额期末审定数 | Y10: 期末审定账龄 | AE10: 期末坏账准备金额 | AF10: 信用风险组合方式 | AG10: 组合名称 | AH10: 是否函证 | AI10: 期后收款 | AJ10: 备注
D11: 关联方类型 | E11: 款项性质 | J11: 1年以内 | K11: 1-2年 | L11: 2-3年 | M11: 3-4年 | N11: 4-5年 | O11: 5年以上 | S11: 期末余额 | U11: 期末余额 | Y11: 1年以内 | Z11: 1-2年 | AA11: 2-3年 | AB11: 3-4年 | AC11: 4-5年 | AD11: 5年以上
A12: 1 | I12: =F12+G12+H12 -> 0 | S12: =F12+Q12-R12 -> 0 | U12: =S12+T12 -> 0 | X12: =U12+V12+W12 -> 0
A13: 2 | I13: =F13+G13+H13 -> 0 | S13: =F13+Q13-R13 -> 0 | U13: =S13+T13 -> 0 | X13: =U13+V13+W13 -> 0
A14: 3 | I14: =F14+G14+H14 -> 0 | S14: =F14+Q14-R14 -> 0 | U14: =S14+T14 -> 0 | X14: =U14+V14+W14 -> 0
A15: 4 | I15: =F15+G15+H15 -> 0 | S15: =F15+Q15-R15 -> 0 | U15: =S15+T15 -> 0 | X15: =U15+V15+W15 -> 0
A16: 5 | I16: =F16+G16+H16 -> 0 | S16: =F16+Q16-R16 -> 0 | U16: =S16+T16 -> 0 | X16: =U16+V16+W16 -> 0
A17: 6 | I17: =F17+G17+H17 -> 0 | S17: =F17+Q17-R17 -> 0 | U17: =S17+T17 -> 0 | X17: =U17+V17+W17 -> 0
A18: 7 | I18: =F18+G18+H18 -> 0 | S18: =F18+Q18-R18 -> 0 | U18: =S18+T18 -> 0 | X18: =U18+V18+W18 -> 0
A19: 8 | I19: =F19+G19+H19 -> 0 | S19: =F19+Q19-R19 -> 0 | U19: =S19+T19 -> 0 | X19: =U19+V19+W19 -> 0
A20: 9 | I20: =F20+G20+H20 -> 0 | S20: =F20+Q20-R20 -> 0 | U20: =S20+T20 -> 0 | X20: =U20+V20+W20 -> 0
A21: 10 | I21: =F21+G21+H21 -> 0 | S21: =F21+Q21-R21 -> 0 | U21: =S21+T21 -> 0 | X21: =U21+V21+W21 -> 0
A22: 11 | I22: =F22+G22+H22 -> 0 | S22: =F22+Q22-R22 -> 0 | U22: =S22+T22 -> 0 | X22: =U22+V22+W22 -> 0
A23: 12 | I23: =F23+G23+H23 -> 0 | S23: =F23+Q23-R23 -> 0 | U23: =S23+T23 -> 0 | X23: =U23+V23+W23 -> 0
... A32: 21 | I32: =F32+G32+H32 -> 0 | S32: =F32+Q32-R32 -> 0 | U32: =S32+T32 -> 0 | X32: =U32+V32+W32 -> 0
A33: 合 计 | F33: =SUM(F12:F32) -> 0 | G33: =SUM(G12:G32) -> 0 | H33: =SUM(H12:H32) -> 0 | I33: =SUM(I12:I32) -> 0 | J33: =SUM(J12:J32) -> 0 | K33: =SUM(K12:K32) -> 0 | L33: =SUM(L12:L32) -> 0 | M33: =SUM(M12:M32) -> 0 | ... AE33: =SUM(AE12:AE32) -> 0
A34: 账龄占比 | I34: =IF((ROUND(I33-SUM(J33:O33),2)=0),"OK","账龄与审定不匹配") -> OK | J34: =IF(J33=0,"",J33/$I$33) | K34: =IF(K33=0,"",K33/$I$33) | L34: =IF(L33=0,"",L33/$I$33) | M34: =IF(M33=0,"",M33/$I$33) | N34: =IF(N33=0,"",N33/$I$33) | O34: =IF(O33=0,"",O33/$I$33) | X34: =IF((ROUND(X33-SUM(Y33:AD33),2)=0),"OK","账龄与审定不匹配") -> OK | Y34: =IF(Y33=0,"",Y33/$X$33) | Z34: =IF(Z33=0,"",Z33/$X$33) | AA34: =IF(AA33=0,"",AA33/$X$33) | AB34: =IF(AB33=0,"",AB33/$X$33) | AC34: =IF(AC33=0,"",AC33/$X$33) | AD34: =IF(AD33=0,"",AD33/$X$33)
A35: 账龄逻辑校验 | Z35: =IF(Z33<=J33,TRUE,FALSE) -> TRUE | AA35: =IF(AA33<=K33,TRUE,FALSE) -> TRUE | AB35: =IF(AB33<=L33,TRUE,FALSE) -> TRUE | AC35: =IF(AC33<=M33,TRUE,FALSE) -> TRUE | AD35: =IF(AD33<=(N33+O33),TRUE,FALSE) -> TRUE
A36: 三、审计说明：
A37: 1.明细账、总账、报表数核对一致。
A38: 2.针对大额异常的款项进行了期后收款的凭证检查，详见凭证检查表K1-
A39: 3.检查其他应收款、其他应付款各明细项目的性质，对于大额的代收、代付性质款项，检查相关合同、银行单据等支持性文件，必要时与客户取得沟通，向客户函证等，判断是否具有合理的交易目的。
A42: 四、审计结论：
A44: 提示
A45: 1.审计说明可以概述：（1）程序的测试情况、结果；（2）拟调整事项及其调整分录、未调整事项及其影响，审计范围受到限制情况及其影响。
A46: 2.审计结论可参考：A、未见异常。 B、除上述重大不符事项应当作为调整事项予以调整外，其余未见异常。 C、由于存在以下重大未调整事项（或审计范围受到限制无法获取充分、适当证据），不可确认。

Sheet 坏账准备明细表K1-3
A1: 致同会计师事务所
A2: 坏账准备明细表
A3: =底稿目录!A2 -> 被审计单位： | E3: =底稿目录!A4 -> 编制人： | I3: =底稿目录!A5 -> 编制日期： | L3: 索引号： | M3: =底稿目录!F10 -> K1-3
A4: =底稿目录!A3 -> 截止日：202X年12月31日 | E4: =底稿目录!A6 -> 复核人： | I4: =底稿目录!A7 -> 复核日期： | L4: 页 次：
A5: 一、审计目标:
A6: 1.资产负债表中记录的其他应收款坏账准备是存在的； | D6: 2.所有应当记录的其他应收款坏账准备均已记录； | H6: 3. 其他应收款坏账准备以恰当的金额包括在财务报表中，与之相关的计价调整已恰当记录。
A7: 二、审计过程：
A8: （一）坏账准备明细表
A9: 项目 | B9: 期初数 | E9: 本期增加 | G9: 本期减少 | J9: 期末数 | M9: 单独计提减值、转回或转销原因
B10: 期初未审数 | C10: 期初账项调整 | D10: 期初审定数 | E10: 计提 | F10: 其他增加 | G10: 转回 | H10: 核销 | I10: 其他减少 | J10: 期末未审数 | K10: 期末账项调整 | L10: 期末审定数额
A11: 按单项评估计提 | B11: =SUM(B12:B15) -> 0 | C11: =SUM(C12:C15) -> 0 | D11: =SUM(D12:D15) -> 0 | E11: =SUM(E12:E15) -> 0 | F11: =SUM(F12:F15) -> 0 | G11: =SUM(G12:G15) -> 0 | H11: =SUM(H12:H15) -> 0 | I11: =SUM(I12:I15) -> 0 | J11: =B11+SUM(E11:F11)-SUM(G11:I11) -> 0 | K11: =SUM(K12:K15) -> 0 | L11: =D11+SUM(G11:G11)-SUM(I11:K11) -> 0
A12: 其中： | D12: =B12+C12 -> 0 | J12: =B12+SUM(E12:F12)-SUM(G12:I12) -> 0 | L12: =J12+K12 -> 0
D13: =B13+C13 -> 0 | J13: =B13+SUM(E13:F13)-SUM(G13:I13) -> 0 | L13: =J13+K13 -> 0
D14: =B14+C14 -> 0 | J14: =B14+SUM(E14:F14)-SUM(G14:I14) -> 0 | L14: =J14+K14 -> 0
D15: =B15+C15 -> 0 | J15: =B15+SUM(E15:F15)-SUM(G15:I15) -> 0 | L15: =J15+K15 -> 0
A16: 按组合计提坏账准备 | B16: =SUM(B17:B21) -> 0 | C16: =SUM(C17:C21) -> 0 | D16: =SUM(D17:D21) -> 0 | E16: =SUM(E17:E21) -> 0 | F16: =SUM(F17:F21) -> 0 | G16: =SUM(G17:G21) -> 0 | H16: =SUM(H17:H21) -> 0 | I16: =SUM(I17:I21) -> 0 | ... L16: =SUM(L17:L21) -> 0
A17: 其中： | D17: =B17+C17 -> 0 | J17: =B17+SUM(E17:F17)-SUM(G17:I17) -> 0 | L17: =J17+K17 -> 0
D18: =B18+C18 -> 0 | J18: =B18+SUM(E18:F18)-SUM(G18:I18) -> 0 | L18: =J18+K18 -> 0
D19: =B19+C19 -> 0 | J19: =B19+SUM(E19:F19)-SUM(G19:I19) -> 0 | L19: =J19+K19 -> 0
D20: =B20+C20 -> 0 | J20: =B20+SUM(E20:F20)-SUM(G20:I20) -> 0 | L20: =J20+K20 -> 0
D21: =B21+C21 -> 0 | J21: =B21+SUM(E21:F21)-SUM(G21:I21) -> 0 | L21: =J21+K21 -> 0
A22: 合计 | B22: =B11+B16 -> 0 | C22: =C11+C16 -> 0 | D22: =D11+D16 -> 0 | E22: =E11+E16 -> 0 | F22: =F11+F16 -> 0 | G22: =G11+G16 -> 0 | H22: =H11+H16 -> 0 | I22: =I11+I16 -> 0 | ... L22: =L11+L16 -> 0 | M22: =SUM(M11:M21) -> 0
A23: （二）三阶段的转入转出
A24: 坏账准备 | B24: 第一阶段 | C24: 第二阶段 | D24: 第三阶段 | E24: 合计 | F24: 勾稽检查
B25: 未来12个月预期信用损失 | C25: 整个存续期预期信用损失(未发生信用减值) | D25: 整个存续期预期信用损失(已发生信用减值)
A26: 期初余额 | E26: =SUM(B26:D26) -> 0 | F26: =E26=D22 -> TRUE
A27: 期初余额在本期 | B27: -- | C27: -- | D27: -- | E27: --
A28: --转入第二阶段 | E28: =SUM(B28:D28) -> 0
A29: --转入第三阶段 | E29: =SUM(B29:D29) -> 0
A30: --转回第二阶段 | E30: =SUM(B30:D30) -> 0
A31: --转回第一阶段 | E31: =SUM(B31:D31) -> 0
A32: 本期计提 | E32: =SUM(B32:D32) -> 0 | F32: =E32=E22 -> TRUE
A33: 本期转回 | E33: =SUM(B33:D33) -> 0 | F33: =E33=G22 -> TRUE
A34: 本期核销 | E34: =SUM(B34:D34) -> 0 | F34: =E34=H22 -> TRUE
A35: 合并范围变化 | E35: =SUM(B35:D35) -> 0
A36: 其他变动 | E36: =SUM(B36:D36) -> 0
A37: 期末余额 | B37: =B26-B28-B29-B30+B31+B32-B33-B34+B35+B36 -> 0 | C37: =C26-C28-C29-C30+C31+C32-C33-C34+C35+C36 -> 0 | D37: =D26-D28-D29-D30+D31+D32-D33-D34+D35+D36 -> 0 | E37: =E26-E28-E29-E30+E31+E32-E33-E34+E35+E36 -> 0
A38: 三、审计说明： | H38: 四、审计结论：

Sheet 调整分录汇总K1-4
A1: 致同会计师事务所
A2: 其他应收款调整分录汇总表
A3: =底稿目录!A2 -> 被审计单位： | D3: =底稿目录!A4 -> 编制人： | F3: =底稿目录!A5 -> 编制日期： | I3: 索引号： | J3: =底稿目录!F11 -> K1-4
A4: =底稿目录!A3 -> 截止日：202X年12月31日 | D4: =底稿目录!A6 -> 复核人： | F4: =底稿目录!A7 -> 复核日期： | I4: 页次：
A5: 调整事项说明 | B5: 类别（报表调整/账项调整/其他） | C5: 报表项目 | D5: 科目名称 | E5: 附注项目 | F5: …… | G5: 借方调整金额 | H5: 贷方调整金额 | I5: 索引 | J5: 备注
A22: 【提示：本底稿适用于调整分录较多、较复杂的项目，且仅列示与本报表项目相关的审计调整。项目组可根据项目实际情况选择是否使用该底稿。】

Sheet 大额其他应收款情况分析表K1-5
A1: 致同会计师事务所
A2: 大额其他应收款情况分析表
A3: =底稿目录!A2 -> 被审计单位： | G3: =底稿目录!A4 -> 编制人： | J3: =底稿目录!A5 -> 编制日期： | L3: 索引号： | M3: =底稿目录!F12 -> K1-5
A4: =底稿目录!A3 -> 截止日：202X年12月31日 | G4: =底稿目录!A6 -> 复核人： | J4: =底稿目录!A7 -> 复核日期： | L4: 页 次：
A5: 一、审计目标
A6: 1.资产负债表中记录的其他应收款、坏账准备是存在的，且已记录于恰当的账户。
A7: 2.其他应收款、坏账准备以恰当的金额包括在财务报表中，与之相关的计价或分摊调整已恰当记录，相关披露已得到恰当计量和描述 。
A8: 二、审计过程
A9: 选择前10名大额其他应收款余额，通过函证、与高管及相关人员控制、投资的其他公司核对，检查相关支持性证据，确定其他应收款是否存在，是否存在未识别的关联方。
A10: （二）其他应收款前10名查验汇总表（不包含合并范围内关联方）
A11: 序号 | B11: 债务人名称 | C11: 期初余额 | D11: 本期借方 | E11: 本期贷方 | F11: 期末未审余额 | G11: 减：坏账准备 | H11: 账面价值 | I11: 发生时间及账龄 | J11: 经济业务说明 | K11: 关联方（√） | L11: 协议或合同索引 | M11: 期后收款金额
A12: 1 | F12: =C12+D12-E12 -> 0 | H12: =F12-G12 -> 0
A13: 2 | F13: =C13+D13-E13 -> 0 | H13: =F13-G13 -> 0
A14: 3 | F14: =C14+D14-E14 -> 0 | H14: =F14-G14 -> 0
A15: 4 | F15: =C15+D15-E15 -> 0 | H15: =F15-G15 -> 0
A16: 5 | F16: =C16+D16-E16 -> 0 | H16: =F16-G16 -> 0
A17: 6 | F17: =C17+D17-E17 -> 0 | H17: =F17-G17 -> 0
A18: 7 | F18: =C18+D18-E18 -> 0 | H18: =F18-G18 -> 0
A19: 8 | F19: =C19+D19-E19 -> 0 | H19: =F19-G19 -> 0
A20: 9 | F20: =C20+D20-E20 -> 0 | H20: =F20-G20 -> 0
A21: 10 | F21: =C21+D21-E21 -> 0 | H21: =F21-G21 -> 0
B22: 合计 | C22: =SUM(C12:C21) -> 0 | D22: =SUM(D12:D21) -> 0 | E22: =SUM(E12:E21) -> 0 | F22: =SUM(F12:F21) -> 0 | G22: =SUM(G12:G21) -> 0 | H22: =SUM(H12:H21) -> 0
A23: 三、审计说明：
A24: 1.针对期后收款的凭证检查，详见凭证检查表K1-
A26: 四、审计结论：

Sheet 信用减值损失会计政策检查K1-6
A1: 致同会计师事务所
A2: 信用减值损失会计政策检查
A3: =底稿目录!A2 -> 被审计单位： | D3: =底稿目录!A4 -> 编制人： | F3: =底稿目录!A5 -> 编制日期： | H3: 索引号： | I3: =底稿目录!F20 -> K1-6
A4: =底稿目录!A3 -> 截止日：202X年12月31日 | D4: =底稿目录!A6 -> 复核人： | F4: =底稿目录!A7 -> 复核日期： | H4: 页 次：
A5: 一、审计目标：
A6: 其他应收款、坏账准备以恰当的金额包括在财务报表中，与之相关的计价或分摊调整已恰当记录，相关披露已得到恰当计量和描述。
A7: 二、审计过程：
A8: 1.检查坏账准备计提的会计政策的合理性，并与前期进行对比，分析其是否前后一致。与同行业其他公司的会计政策进行对比，关注其是否利用会计政策和会计估计变更操纵利润。
A9: 2.根据执行程序的结果，包括回顾上期估计值与当期结果，考虑管理层在作出会计估计时的判断和决策时，是否表明存在管理层偏向的迹象。
A10: （一）具体减值政策说明
A11: 当单项其他应收款、长期应收款无法以合理成本评估预期信用损失的信息时，本公司依据信用风险特征将其他应收款、长期应收款划分为若干组合，在组合基础上计算预期信用损失：
A12: 确定组合的依据如下： | J12: 提示1：共同信用风险特征包括：金融工具类型、信用风险评级、担保物类型、
A13: 其他应收款组合1： | B13: 押金和保证金 | J13: 初始确认日期、剩余合同期限、债务人所处行业、债务人所处地理位置、
A14: 其他应收款组合2： | B14: 应收关联公司款项 | J14: 担保品相对于金融资产的价值等。
A15: 其他应收款组合3： | B15: 应收代垫款项
A16: 其他应收款组合4： | B16: 员工备用金
A17: 【以上组合划分方法仅为举例，实务中管理层应根据业务实际情况确定符合被审计单位经济业务特点的组合划分方式，或者均采用单项计提的方法；预期信用损失率的确定，可通过历史损失率和预期损失率确定，也可通过计算各年迁徙率并结合前瞻性信息等方式确定。】
A18: （二）被审计单位历史坏账损失情况
A19: 【应说明被审计单位其他应收款历史损失率的数据来源，以及项目组核实该等数据所执行的程序。需考虑货币的时间价值】
A22: （三）前瞻性信息的来源及其影响
A23: 【应说明被审计单位确定预期损失率的前瞻性信息来源（包括内部模型、第三方服务机构或利用外部专家工作等，以及项目组对前瞻性信息可靠性所执行的程序】
A26: （四）同行业公司的会计政策
A27: XX
A28: XX
A29: ……
A31: 三、审计说明：
A34: 四、审计结论：
A35: 被审计单位坏账准备的计提相关的会计政策和会计估计与企业会计准则的规定一致，反映了被审计单位经济业务的实际情况，与同行业公司相比不存在显著差异，且坏账准备政策得到一贯性地执行。
A36: 提示2：会计政策披露示例参考
A37: 中国中铁 | B37: 当单项其他应收款、长期应收款无法以合理成本评估预期信用损失的信息时，本集团依据信用风险特征将其他应收款、长期应收款划分为若干组合，在组合基础上计算预期信用损失，确定组合的依据如下： 其他应收款组合1 应收押金和保证金 其他应收款组合2 应收代垫款 其他应收款组合3 应收其他款项 长期应收款组合1 应收工程款、应收租赁款 长期应收款组合2 应收其他款项 对于长期应收工程款、应收租赁款，本集团参考历史信用损失经验，结合当前状况以及对未来经济状况的预测，通过违约风险敞口和整个存续期预期信用损失率，计算预期信用损失。除长期应收工程款、应收租赁款之外的划分为组合的其他应收款和长期应收款，通过违约风险敞口和未来12个月内或整个存续期预期信用损失率，计算预期信用损失。
A38: 海螺水泥 | B38: 对于单项测试未发生减值的其他应收款，本集团会将其包括在具有类似信用风险特征的其他应收款组合中再进行减值测试。 确认组合的依据： 组合1 除政府代垫款及银行委托理财产品以外的其他应收款 组合2 政府代垫款 组合3 银行委托理财产品
A39: 北辰实业 | B39: 当单项金融资产无法以合理成本评估预期信用损失的信息时，本集团依据信用风险特征将应收款项划分为若干组合，在组合基础上计算预期信用损失，确定组合的依据如下： 其他应收款组合1 应收押金、保证金及备用金 其他应收款组合2 应收关联公司款项 其他应收款组合3 应收少数股东款项 其他应收款组合4 应收代垫款项 其他应收款组合5 应收其他款项 对于划分为组合的其他应收款、长期应收款，本集团参考历史信用损失经验，结合当前状况以及对未来经济状况的预测，通过违约风险敞口和未来12个月内或整个存续期预期信用损失率，计算预期信用损失。
A40: 拉夏贝尔 | B40: 对于在资产负债表日具有较低信用风险的金融工具，本集团假设其信用风险自初始确认后并未显著增加，按照未来12个月内的预期信用损失计量损失准备。 当单项资产无法以合理成本评估预期信用损失的信息时，本集团依据信用风险特征将应收款项划分为若干组合，确定组合的依据如下： 其他应收款组合 — 押金和保证金 其他应收款组合 — 员工备用金及其他 其他应收款组合 — 应收子公司款项 其他应收款组合 — 应收股利款 其他应收款组合 — 应收定期存款利息 对于划分为组合的其他应收款，本集团参考历史信用损失经验，结合当前状况以及对未来经济状况的预测，通过违约风险敞口和未来12个月内或整个存续期预期信用损失率，计算预期信用损失。
A41: 上海医药 | B41: 当单项金融资产无法以合理成本评估预期信用损失的信息时，本集团依据信用风险特征将应收款项分为若干组合，在组合基础上计算预期信用损失，确定组合的依据如下： 组合一 账龄 组合二 关联方股利 组合三 利息及银行承兑汇票 组合四 保证金(含押金)组合及其他应收供应商款项 组合五 应收合并范围内公司款项 对于划分为组合的其他应收款与长期应收款，本集团参考历史信用损失经验，结合当前状况以及对未来经济状况的预测，通过违约风险敞口和未来12个月内或整个存续期预期信用损失率，计算预期信用损失。
A42: 上海电气 | B42: 对于存在客观证据表明存在减值，以及其他适用于单项评估的应收账款，单独进行减值测试，确认预期信用损失，计提单项减值准备。对于不存在减值客观证据的应收账款或当单项金融资产无法以合理成本评估预期信用损失的信息时，本集团依据信用风险特征将应收款项划分为若干组合，在组合基础上计算预期信用损失，确定组合的依据如下： 组合1 押金和保证金 组合2 员工备用金 组合3 其他 对于划分为组合的其他应收款、贷款及贴现、长期应收款、其他债权投资和买入返售金融资产，本集团参考历史信用损失经验，结合当前状况以及对未来经济状况的预测，通过违约风险敞口和未来12个月内或整个存续期预期信用损失率，计算预期信用损失。

Sheet 三阶段划分检查表K1-7
A1: 致同会计师事务所
A2: 其他应收款减值的三阶段划分检查表
A3: =底稿目录!A2 -> 被审计单位： | E3: =底稿目录!A4 -> 编制人： | G3: =底稿目录!A5 -> 编制日期： | I3: 索引号： | J3: =底稿目录!F21 -> K1-7
A4: =底稿目录!A3 -> 截止日：202X年12月31日 | E4: =底稿目录!A6 -> 复核人： | G4: =底稿目录!A7 -> 复核日期： | I4: 页 次：
A5: 一、审计目标：
A6: 其他应收款、坏账准备以恰当的金额包括在财务报表中，与之相关的计价或分摊调整已恰当记录，相关披露已得到恰当计量和描述。
A7: 二、审计过程：
A8: 1.对信用风险显著增加的评估 | K8: 其他应收款不适用简化方法，应按预期信用损失模型的一般方法按三阶段计提预期信用损失，即必须追踪信用风险的变化。
A9: 1.1 通过比较金融工具在初始确认时所确定的预计存续期内的违约概率和该工具在资产负债表日所确定的预计存续期内的违约概率，来判定金融工具信用风险是否显著增加。 | K9: 企业确定信用风险显著增加的时点应当早于实际发生减值的时点，这是“预期信用损失法”的应有之义。
A10: 1.2 如果合同付款逾期超过（含）30日，则通常可以推定金融资产的信用风险显著增加，除非企业以合理成本即可获得合理且有依据的信息，证明即使逾期超过30日，信用风险仍未显著增加。 | K10: 无论企业采用何种方式评估信用风险是否显著增加，通常情况下，如果逾期超过30日，则表明金融工具的信用风险已经显著增加
A11: 1.3 对于在资产负债表日具有较低信用风险的金融工具，企业可以不用与其初始确认时的信用风险进行比较，而直接做出该工具的信用风险自初始确认后未显著增加的假定（企业对这种简化处理有选择权）。 | K11: 发生违约（即进入第三阶段）的时间不应迟于金融资产逾期90日这一期限，除非企业具有合理及可支持的信息表明涵盖更长期间的违约标准更为恰当。
A12: 2.已发生信用减值的评估 | C12: 2.1 分析是否存在已发生信用减值的证据。 | K12: 如果交易对手方未按合同规定时间支付约定的款项，则表明该金融资产发生逾期。
A13: 2.2 如果一项金融工具逾期超过（含）90日，则企业应当推定该金融工具已发生违约，除非企业有合理且有依据的信息，表明以更长的逾期时间作为违约标准更为恰当。 | K13: 当对金融资产预期未来现金流量具有不利影响的一项或多项事件发生时，该金融资产成为已发生信用减值的金融资产。
A14: （一）信用风险是否显著增加
A15: 需要考虑的信息 | B15: 说明 | G15: 组合1： | H15: 组合2： | I15: 组合3： | J15: 组合X：
A16: 信用风险变化所导致的内部价格指标的显著变化 | B16: 例如，同一金融工具或具有相同条款及相同交易对于的类似金融工具，在最近期间发行时的信用利差相对于过去发行时的变化。 | K16: 根据金融工具的性质，企业可以单项金融工具或金融工具组合为基础评估信用风险是否显著增加。以金融工具组合为基础进行评估时，可基于共同信用风险特征对金融工具进行分类，例如逾期信息和信用风险评级。
A17: 金融工具的利率或其他条款将发生的显著变化 | B17: 若现有金融工具在报告日作为新金融工具源生或发行，该金融工具的利率或其他条款将发生的显著变化（如更严格的合同条款、增加抵押品或担保物或者更高的收益率等）。
A18: 类似金融工具的信用风险的外部市场指标的显著变化 | B18: 这些指标包括：1）信用利差；2）针对借款人的信用违约互换价格；3）金融资产的公允价值小于其摊余成本的时间长短和程度；4）与借款人相关的其他市场信息（如借款人的债务工具或权益工具的价格变动）。
A19: 外部信用评级、内部信用评级下调 | B19: 金融工具外部信用评级实际或预期的显著变化。 对借款人实际或预期的内部信用评级下调。 如果内部信用评级可与外部评级相对应或可通过违约调查予以证实，则更为可靠。
A20: 借款人业务、财务或外部经济状况的不利变化 | B20: 预期将导致借款人履行其偿债义务的能力发生显著变化的业务、财务或外部经济状况的不利变化。例如，实际或预期的利率上升，实际或预期的失业率显著上升。
A21: 借款人经营成果实际或预期的显著变化 | B21: 例如，借款人收入或毛利率下降、经营风险增加、营运资金短缺、资产质量下降、杠杆率上升、流动比率下降、管理出现问题、业务范围或组织结构变更（例如某些业务分部终止经营）。
A22: 借款人所处的监管、经济或技术环境的显著不利变化 | B22: 例如，技术变革导致对借款人产品的需求下降。
A23: 其他金融工具的信用风险的不利变化 | B23: 同一借款人发行的其他金融工具的信用风险显著增加。
A24: 担保或信用增级质量的显著变化 | B24: 作为债务抵押的担保物价值或第三方提供的担保或信用增级质量的显著变化。这些变化预期将降低借款人按合同规定期限还款的经济动机或者影响违约概率。例如，如果房价下降导致担保物价值下跌，则借款人可能会有更大动机拖欠抵押贷款。
A25: 借款人还款的经济动机的显著变化 | B25: 预期将降低借款人按合同约定期限还款的经济动机的显著变化。例如，母公司或其他关联公司能够提供的财务支持减少，或者信用增级质量的显著变化。关于信用增级的质量变化，企业应当考虑担保人的财务状况，次级权益预计能否吸收预期信用损失等。
A26: 借款合同的预期变更 | B26: 包括预计违反合同的行为可能导致的合同义务的免除或修订、给予免息期、利率跳升、要求追加抵押品或担保或者对金融工具的合同框架做出其他变更。
A27: 借款人预期表现和还款行为的显著变化 | B27: 例如，一组贷款资产中延期还款的数量或金额增加、接近授信额度或每月最低还款额的信用卡持有人的预期数量增加。
A28: 企业对金融工具信用管理方法的变化 | B28: 例如，企业信用风险管理实务预计将变得更为积极或者对该金融工具更加侧重，包括更密切地监控或更紧密地控制有关金融工具、对借款人实施特别干预。
A29: 逾期信息 | B29: 无论企业采用何种方式评估信用风险是否显著增加，如果合同付款逾期超过（含）30日，则通常可以推定金融资产的信用风险显著增加； 除非企业以合理成本即可获得合理且有依据的信息，证明即使逾期超过30日，信用风险仍未显著增加。例如，如果未能及时付款是由于管理上的疏忽而并非借款人本身的财务困难所致。再如，企业能够获得的历史统计数据表明，发生违约的风险显著增加与逾期超过30日之间不存在相关性。
A30: 分析结论
A32: （二）是否具有较低信用风险
A33: 组合：
A34: 序号 | B34: 条件（同时满足） | G34: 组合1： | H34: 组合2： | I34: 组合3： | J34: 组合X：
A35: 1 | B35: 金融工具的违约风险较低 | K35: 对于在资产负债表日具有较低信用风险的金融工具，企业可以不用与其初始确认时的信用风险进行比较，而直接做出该工具的信用风险自初始确认后未显著增加的假定。
A36: 2 | B36: 借款人在短期内履行其支付合同现金流量义务的能力很强 | K36: 如果一项金融工具具有“投资级”以上的外部信用评级，则该工具可能被视为具有较低信用风险。
A37: 3 | B37: 即使较长时期内经济形势和经营环境存在不利变化，也不一定会降低借款人履行其支付合同现金流量义务的能力 | K37: 金融工具不能仅因其担保物的价值较高而被视为具有较低的信用风险，也不能仅因为其与其他金融工具相比违约风险较低，
A38: 分析结论 | K38: 或者相对于企业所处的地区的信用风险水平而言风险相对较低而被视为具有较低的信用风险。
A40: （三）已发生信用减值的评估
A41: 组合：
A42: 序号 | B42: 可观察信息 | G42: 组合1： | H42: 组合2： | I42: 组合3： | J42: 组合X： | K42: 金融资产发生信用减值，有可能是多个事件的共同作用所致，未必是可单独识别的事件所致。
...

Sheet 坏账准备测算K1-8
A1: 致同会计师事务所
A2: 其他应收款坏账准备测算表
A3: =底稿目录!A2 -> 被审计单位： | C3: =底稿目录!A4 -> 编制人： | E3: =底稿目录!A5 -> 编制日期： | G3: 索引号： | H3: =底稿目录!F22 -> K1-8
A4: =底稿目录!A3 -> 截止日：202X年12月31日 | C4: =底稿目录!A6 -> 复核人： | E4: =底稿目录!A7 -> 复核日期： | G4: 页 次：
A5: 一、审计目标
A6: 其他应收款、坏账准备以恰当的金额包括在财务报表中，与之相关的计价或分摊调整已恰当记录，相关披露已得到恰当计量和描述
A7: 二、审计过程
A8: （一）单项计提坏账准备
A9: 债务人名称 | B9: 审定账面余额 | C9: 预期信用损失率 | D9: 期末应计提坏账准备 | E9: 期末坏账准备账面余额 | F9: 差异 | G9: 计提依据及文件 | H9: 索引号
B10: ① | C10: ② | D10: ③=①×② | E10: ④ | F10: ⑤=③-④
D11: =ROUND(B11*C11,2) -> 0 | F11: =B11-E11 -> 0
D12: =ROUND(B12*C12,2) -> 0 | F12: =B12-E12 -> 0
D13: =ROUND(B13*C13,2) -> 0 | F13: =B13-E13 -> 0
D14: =ROUND(B14*C14,2) -> 0 | F14: =B14-E14 -> 0
D15: =ROUND(B15*C15,2) -> 0 | F15: =B15-E15 -> 0
A16: 小计 | B16: =SUM(B11:B15) -> 0 | D16: =SUM(D11:D15) -> 0 | E16: =SUM(E11:E15) -> 0 | F16: =SUM(F11:F15) -> 0
A17: 核对差异 | B17: =B16-SUMIF('明细表K1-2'!$AF$12:$AF$32,"单项计提",'明细表K1-2'!$X$12:$X$32) -> 0 | D17: =D16-SUMIF('明细表K1-2'!$AF$12:$AF$32,"单项计提",'明细表K1-2'!$X$12:$X$32) -> 0
A18: （二）押金/保证金组合计提坏账准备 | H18: 【不适用的行项目请删除】
A19: 信用期 | B19: 审定账面余额 | C19: 预期信用损失率 | D19: 期末应计提坏账准备 | E19: 期末坏账准备账面余额 | F19: 差异 | G19: 计提依据及文件 | H19: 索引号
B20: ① | C20: ② | D20: ③=①×② | E20: ④ | F20: ⑤=③-④
A21: 合同期内 | D21: =ROUND(B21*C21,2) -> 0 | F21: =B21-E21 -> 0
A22: 逾期30天以内 | D22: =ROUND(B22*C22,2) -> 0 | F22: =B22-E22 -> 0
A23: 逾期30-90天 | D23: =ROUND(B23*C23,2) -> 0 | F23: =B23-E23 -> 0
A24: 逾期90天以上 | D24: =ROUND(B24*C24,2) -> 0 | F24: =B24-E24 -> 0
D25: =ROUND(B25*C25,2) -> 0 | F25: =B25-E25 -> 0
A26: 小计 | B26: =SUM(B21:B25) -> 0 | D26: =SUM(D21:D25) -> 0 | E26: =SUM(E21:E25) -> 0 | F26: =SUM(F21:F25) -> 0
A27: 核对差异 | B27: =B26-SUMIF('明细表K1-2'!$AF$12:$AF$32,"保证金组合",'明细表K1-2'!$X$12:$X$32) -> 0 | D27: =D26-SUMIF('明细表K1-2'!$AF$12:$AF$32,"保证金组合",'明细表K1-2'!$X$12:$X$32) -> 0
A28: （三）其他组合计提坏账准备 | H28: 【不适用的行项目请删除】
A29: 账龄【账龄以记账凭证日期起计算，逾期则考虑信用期】 | B29: 审定账面余额 | C29: 预期信用损失率 | D29: 期末应计提坏账准备 | E29: 期末坏账准备账面余额 | F29: 差异 | G29: 计提依据及文件 | H29: 索引号
A30: 组合1： | B30: ① | C30: ② | D30: ③=①×② | E30: ④ | F30: ⑤=③-④
A31: 1年以内/未逾期 | D31: =ROUND(B31*C31,2) -> 0 | F31: =B31-E31 -> 0
A32: 1年-2年/逾期30天以内 | D32: =ROUND(B32*C32,2) -> 0 | F32: =B32-E32 -> 0
A33: 2年-3年/逾期30-90天 | D33: =ROUND(B33*C33,2) -> 0 | F33: =B33-E33 -> 0
A34: 3年-4年/逾期90天-1年 | D34: =ROUND(B34*C34,2) -> 0 | F34: =B34-E34 -> 0
A35: 4年-5年/逾期1年-2年 | D35: =ROUND(B35*C35,2) -> 0 | F35: =B35-E35 -> 0
A36: 5年以上/逾期2年以上 | D36: =ROUND(B36*C36,2) -> 0 | F36: =B36-E36 -> 0
A37: 小计 | B37: =SUM(B31:B36) -> 0 | D37: =SUM(D31:D36) -> 0 | E37: =SUM(E31:E36) -> 0 | F37: =SUM(F31:F36) -> 0
A38: 组合2：
A39: 1年以内/未逾期 | D39: =ROUND(B39*C39,2) -> 0 | F39: =B39-E39 -> 0
A40: 1年-2年/逾期30天以内 | D40: =ROUND(B40*C40,2) -> 0 | F40: =B40-E40 -> 0
...

Sheet 坏账准备转回（收回）、核销检查表K1-9
A1: 致同会计师事务所
A2: 其他应收款－坏账准备转回、收回、核销检查表
A3: =底稿目录!A2 -> 被审计单位： | C3: =底稿目录!A4 -> 编制人： | E3: =底稿目录!A5 -> 编制日期： | G3: 索引号： | H3: =底稿目录!F23 -> K1-9
A4: =底稿目录!A3 -> 截止日：202X年12月31日 | C4: =底稿目录!A6 -> 复核人： | E4: =底稿目录!A7 -> 复核日期： | G4: 页 次：
A5: 一、审计目标
A6: 确定其他应收款坏账准备计提是否充分，应收账款转回、收回、转销是否恰当。
A7: 二、审计过程
A8: 1.取得被审计单位大额坏账准备及其他应收款核销清单； | E8: 2.了解大额坏账准备转回（收回）的原因、方式，判断其合理性；
A9: 3.对于实际发生坏账损失的，检查核销依据是否符合有关规定，会计处理是否正确； | E9: 4.已经确认并核销的坏账重新收回的，检查其会计处理是否正确。
A10: （一）本期重要的坏账准备转回检查
A11: 单位名称 | B11: 转回原因 | C11: 收回方式 | D11: 原确定坏账准备的依据 | E11: 收回或转回金额 | F11: 收回或转回前累计已计提坏账准备金额 | G11: 合理性分析 | H11: 索引号
A15: 合 计 | E15: =SUM(E12:E14) -> 0
A16: （二）本期重要的核销检查
A17: 单位名称 | B17: 其他应收款的性质 | C17: 核销金额 | D17: 核销原因 | E17: 履行的核销程序 | F17: 是否关联方往来 | G17: 合理性分析 | H17: 索引号
A21: 合 计 | C21: =SUM(C18:C20) -> 0
A22: 三、审计说明
A25: 四、审计结论

Sheet 长期未收回款项检查表K1-10
A1: 致同会计师事务所
A2: 长期未收回款项检查表
A3: =底稿目录!A2 -> 被审计单位： | E3: =底稿目录!A4 -> 编制人： | J3: =底稿目录!A5 -> 编制日期： | N3: 索引号： | O3: =底稿目录!F24 -> K1-10
A4: =底稿目录!A3 -> 截止日：202X年12月31日 | E4: =底稿目录!A6 -> 复核人： | J4: =底稿目录!A7 -> 复核日期： | N4: 页次：
A5: 一、审计目标
A6: 1.资产负债表中记录的其他应收款、坏账准备是存在的，且已记录于恰当的账户； | G6: 2.其他应收款、坏账准备以恰当的金额包括在财务报表中，与之相关的计价或分摊调整已恰当记录，相关披露已得到恰当计量和描述 。
A7: 二、审计过程
A8: 债务人名称 | B8: 期初余额 | C8: 本期借方发生额 | D8: 本期贷方发生额 | E8: 期末余额 | F8: 账龄 | G8: 经济业务说明 | H8: 未收回或未结转的原因 | I8: 是否诉讼 | J8: 是否无法收回 | K8: 处理计划 | L8: 计提坏账准备金额 | M8: 审定余额 | N8: 期后收款金额 | O8: 备注
E9: =B9+C9-D9 -> 0
A12: 合计 | B12: =SUM(B9:B11) -> 0 | C12: =SUM(C9:C11) -> 0 | D12: =SUM(D9:D11) -> 0 | E12: =SUM(E9:E11) -> 0 | F12: =SUM(F9:F11) -> 0 | M12: =SUM(M9:M11) -> 0 | N12: =SUM(N9:N11) -> 0
A13: 三、审计说明
A14: 1.针对期后收款的凭证检查，详见凭证检查表K1-
A17: 四、审计结论
A19: 提示：
A20: 1.针对报告期内账龄较长的其他应收款，判断是否有长期挂账而推迟正常经营管理所需开支（如不合理的备用金）或无需支付（如不合理的往来款挂账）的情况，并检查其原始凭证，确认会计处理是否正确，必要时进行函证（CSRC551-9）。
A21: 2.针对报告期内账龄较长的其他应收款，实施上条程序后未发现不合理的情况，应当进而分析账龄较长的原因，是否双方有纠纷或对方单位缺乏付款能力等，考虑坏账准备的计提是否充分。

Sheet 关联方及交易检查表K1-11
A1: 致同会计师事务所
A2: 其他应收款关联方及交易检查表
A3: =底稿目录!A2 -> 被审计单位： | D3: =底稿目录!A4 -> 编制人： | H3: =底稿目录!A5 -> 编制日期： | L3: 索引号： | M3: =底稿目录!F25 -> K1-11
A4: =底稿目录!A3 -> 截止日：202X年12月31日 | D4: =底稿目录!A6 -> 复核人： | H4: =底稿目录!A7 -> 复核日期： | L4: 页 次：
A5: 关注对关联方的其他应收款的真实性、合理性、合法性、会计处理是否正确，考虑是否存在未识别的关联方，检查关联交易和余额披露是否正确。
A6: 关联方名称 | B6: 关联关系 | C6: 期初余额 | D6: 借方发生额 | E6: 贷方发生额 | F6: 期末余额 | G6: 减：坏账准备 | H6: 账面价值 | I6: 发生时间及账龄 | J6: 发生原因（款项性质） | K6: 期后收款金额 | L6: 索引号 | M6: 备注
A7: 债务人（股东）1 | F7: =C7+D7-E7 -> 0 | H7: =F7-G7 -> 0
A8: 债务人（股东）2 | F8: =C8+D8-E8 -> 0 | H8: =F8-G8 -> 0
A9: …… | F9: =C9+D9-E9 -> 0 | H9: =F9-G9 -> 0
A10: 小计 | C10: =SUM(C7:C9) -> 0 | D10: =SUM(D7:D9) -> 0 | E10: =SUM(E7:E9) -> 0 | F10: =SUM(F7:F9) -> 0 | G10: =SUM(G7:G9) -> 0 | H10: =SUM(H7:H9) -> 0
A11: 1、审计说明：
A12: 1.针对期后收款的凭证检查，详见凭证检查表K1-
A14: 2、审计结论：
B16: 勿改、勿删
B17: 实际控制人
B18: 控股股东
B19: 控股股东、实际控制人的附属企业
B20: 持有5%以上股份的法人或其他组织
B21: 联营企业
B22: 合营企业
B23: 董高监等关键管理人员
B24: 其他关联方

Sheet 其他应收款检查表K1-12
A1: 致同会计师事务所
A2: 其他应收款检查表
A3: =底稿目录!A2 -> 被审计单位： | G3: =底稿目录!A4 -> 编制人： | L3: =底稿目录!A5 -> 编制日期： | P3: 索引号： | Q3: =底稿目录!F26 -> K1-12
A4: =底稿目录!A3 -> 截止日：202X年12月31日 | G4: =底稿目录!A6 -> 复核人： | L4: =底稿目录!A7 -> 复核日期： | P4: 页次：
A5: 一、审计目标：
A6: 1.资产负债表中记录的其他应收款是存在的，且已经记录在恰当的账户中； | G6: 2.记录的其他应收款由被审计单位拥有或控制；
A7: 3.其他应收款以恰当的金额包括在财务报表中，与之相关的计价或分摊调整已恰当记录，相关披露已得到恰当计量和描述。
A8: 二、样本选取标准与规模：
A9: 测试总体： | B9: 如借方发生额所有凭证共XX笔金额XX、贷方发生额所有凭证共XX笔金额XX | G9: 特定样本： | H9: XX金额以上（大额）、关联方/关联交易形成的款项、XX异常款项全部测试，共XX笔；
A10: 抽样总体： | B10: 测试总体扣除特定样本以外的样本，共XX笔、金额XX | G10: 确定的抽样样本量： | H10: 抽取XX笔（如果使用了样本计算器计算样本量，样本量计算过程见<XX>底稿）
A11: 抽样方法： | B11: 随机选样/系统选样/货币单元抽样/随意选样（非统计抽样适用） | G11: 抽样过程： | H11: 使用IDEA（XX抽样工具）选择XX数量、金额XX的样本进行测试，抽样工具中的样本选择过程和结果见<XX>底稿
A12: 三、测试：
A13: 测试内容说明：1.原始凭证是否齐全； 2.记账凭证与原始凭证是否相符；3.账务处理是否正确；4.是否记录于恰当的会计期间；5.……
A14: 1.本期发生额检查
A15: 记账凭证 | I15: 支持性文件 | J15: 核对内容 | O15: 索引号 | P15: 是否异常 | Q15: 备注说明
A16: 债务人名称 | B16: 日期 | C16: 凭证编号 | D16: 业务内容 | E16: 对方科目 | F16: 对方明细科目 | G16: 借方金额 | H16: 贷方金额 | J16: 1 | K16: 2 | L16: 3 | M16: 4 | N16: 5
A37: 合计 | G37: =SUM(G17:G36) -> 0 | H37: =SUM(H17:H36) -> 0
A38: 2.期后收款检查表
A39: 记账凭证 | H39: 支持性文件 | J39: 核对内容 | O39: 索引号 | P39: 是否异常 | Q39: 备注说明
A40: 债务人名称 | B40: 日期 | C40: 凭证编号 | D40: 业务内容 | E40: 对方科目 | F40: 对方明细科目 | G40: 贷方金额 | J40: 1 | K40: 2 | L40: 3 | M40: 4 | N40: 5
A58: 合计 | G58: =SUM(G41:G57) -> 0
A59: 四、审计说明：
A60: 1.本期发生额、期末余额检查比例： | D60: 方向 | E60: 账面金额 | F60: 检查金额 | G60: 检查比例 | H60: 如果检查比例较低应扩大检查样本量或说明原因
D61: 本期借方 | E61: ='明细表K1-2'!Q33 -> 0 | F61: =G37 -> 0 | G61: =ROUND(F61/E61,4) -> #DIV/0!
D62: 本期贷方 | E62: ='明细表K1-2'!R33 -> 0 | F62: =H37 -> 0 | G62: =ROUND(F62/E62,2) -> #DIV/0!
D63: 期末余额 | E63: ='明细表K1-2'!X33 -> 0 | F63: =G58 -> 0 | G63: =ROUND(F63/E63,2) -> #DIV/0!
A64: 2.……
A65: 五、审计结论：

Sheet GT_Custom
A1: C1 | B1: Custom 1
A2: C2 | B2: Custom 2
A3: C3 | B3: Custom 3
A4: C4 | B4: Custom 4
A5: C5 | B5: Custom 5
A6: C6 | B6: Custom 6
A7: C7 | B7: Custom 7
A8: C8 | B8: Custom 8
