Workbook
Name AS2DocOpenMode: "AS2DocumentEdit"

Sheet 底稿目录
A1: 底稿开列时，可先在以下单元格填写有关内容，以便其他底稿引用有关数据：
A2: 被审计单位：
A3: 截止日：202X年12月31日
A4: 编制人： | B4: 序号 | C4: 内容 | D4: 索引号 | E4: 备注
A5: 编制日期： | B5: 1 | C5: 实质性程序表 | D5: K6A
A6: 复核人： | B6: 2 | C6: 审定表 | D6: K6-1
A7: 复核日期： | B7: 3 | C7: 附注披露信息（上市公司） | F7: 无需打印
B8: 4 | C8: 附注披露信息(国企） | F8: 无需打印
B9: 5 | C9: 明细表 | D9: K6-2
A10: 关于工作底稿与审计程序索引号对应的说明 | B10: 6 | C10: 调整分录汇总表 | D10: K6-3
A11: 1.编制的审计工作底稿应与审计程序对应。审计项目组应根据被审计单位实际情况和风险评估情况在实质性程序表中裁剪、修改或增加审计程序，根据实际执行的审计程序完成相应审计工作底稿，编制的工作底稿中应按自然顺序依次编制索引号，并通过唯一的索引号将与实质性程序表中的程序对应关联（即将工作底稿的索引号填入实质性程序表中的底稿索引号列）。 | B11: 7 | C11: 初始确认检查表 | D11: K6-4
B12: 8 | C12: 减值准备测试表（后续计量） | D12: K6-5
B13: 9 | C13: 处置组减值测试表（后续计量） | D13: K6-6
B14: 10 | C14: 检查表（不再满足持有待售） | D14: K6-7
A15: 2.获取的支持性证据应与审计底稿或程序对应。审计项目组在完成底稿时获取的支持性证据应根据底稿索引号编制下一级按自然顺序排序的索引号（如D1-2-1、D1-2-2、……），并在底稿中说明引用的支持性证据、关联索引号。
A18: 3.工作底稿索引号的编码规则：实质性程序索引号按循环从“D”到“N”,循环内账户以顺序号排列，模板中底稿索引号按账户顺序+自然数顺序（即模板中索引号按二级自然顺序排列，如D1-1、D1-2、D1-3、……D1-N）。

Sheet 实质性程序表 K6A
A1: 致同会计师事务所
A2: 持有待售的资产和负债实质性程序
A3: =底稿目录!A2 -> 被审计单位： | C3: =底稿目录!A4 -> 编制人： | E3: =底稿目录!A5 -> 编制日期： | H3: 索引号： | I3: =底稿目录!D5 -> K6A
A4: =底稿目录!A3 -> 截止日：202X年12月31日 | C4: =底稿目录!A6 -> 复核人： | E4: =底稿目录!A7 -> 复核日期： | H4: 页次：
A5: 一、本账户涉及的科目
A6: 持有待售的资产、持有待售的负债
A7: 二、审计目标与认定的对应关系
A8: 审计目标 | G8: 财务报表的认定
A9: A. 资产负债表中记录的持有待售的资产和负债是存在的，且已记录于恰当的账户 | G9: 存在
A10: B. 所有应记录的持有待售的资产和负债均已记录，所有应当包括在财务报表中的相关披露均已包括 | G10: 完整性
A11: C. 记录的持有待售资产由被审计单位拥有或控制；记录的持有待售负债是被审计单位应当履行的偿还义务 | G11: 权利和义务
A12: D. 持有待售的资产和负债以恰当的金额包括在财务报表中，与之相关的计价或分摊调整已恰当记录，相关披露已得到恰当计量和描述 | G12: 准确性、计价和分摊
A13: E. 持有待售的资产和负债已被恰当地汇总或分解且表述清楚，相关披露在按照企业会计准则的编制基础下是相关的、可理解的 | G13: 列报
A14: 三、计划实施的实质性程序
A15: 序号 | B15: 审计程序 | C15: 程序分类 | D15: 财务报表的认定 | I15: 底稿索引号
D16: 存在 | E16: 完整性 | F16: 权利和 义务 | G16: 准确性、计价和分摊 | H16: 列报 | J16: 根据被审计单位实际情况和风险评估情况裁剪、修改或增加审计程序
A17: 1 | B17: 获取或编制明细表、执行下列程序，并编制审定表： （1）复核加计正确，并与总账数和明细账合计数核对是否相符，期初余额与上期审定期末余额是否相符； （2）根据终止经营项目判断是否满足持有待售条件，是否应纳入持有待售进行核算。 | C17: 常规★ | D17: √ | E17: √ | G17: √ | I17: K6-1 /K6-2
A18: 2 | B18: 在使用手工编制、自定义信息报告、系统生成的非固定格式报告等由被审计单位生成的信息时，测试有关信息准确性和完整性，并考虑针对编制和维护由被审计单位生成的信息的相关控制实施控制测试，以评价该信息是否能够为实现审计目的提供基础。 | C18: 常规★ | E18: √ | G18: √ | I18: T1 | J18: 可参见《审计手册》4.2.6，由被审计单位生成的信息可能是由系统生成的、或手工编制的、或二者兼而有之的方式生成的。例如，由被审计单位生成的信息可能包括： • 不涉及自定义的、由系统生成的报告（如，固定格式报告）； • 可能通过人工自定义的、由系统生成的报告，例如，（计算机）查询信息或特别定制的报告； • 手工编制的信息，例如，汇总信息的电子表格或用以支持分配、计算以及调节的电子表格； • 其他系统生成或手工编制的信息，例如，由被审计单位编制的客户发票； • 通过影印、拍摄、扫描或其他方式转换成电子形式的文件记录。
A19: 3 | B19: 获取上期期末的持有待售资产和负债明细，复核加计正确，总账与明细账核对一致；了解持有待售项目的情况；对重大持有待售项目检查期初余额形成的支持性证据，检查在本期出售等情况。（适用于首次承接） | C19: 备选 | D19: √ | E19: √ | G19: √ | J19: 由被审计单位生成的信息不包括： • 总分类账或明细分类账、试算平衡表、或经审计的财务报表； • 第三方（除了服务机构）的报表或报告，例如，原始银行对账单，或函证的回函； • 外部数据（例如，第三方发布的数据，如，定价来源）。
A20: 4 | B20: 关注会计政策、会计估计合理性、一贯性。关注其是否利用会计政策和会计估计及其变更操纵利润。 | C20: 常规★ | D20: √ | E20: √ | G20: √ | I20: K6-1 /K6-2
A21: 5 | B21: 对于终止经营满足持有待售条件，计入持有待售资产和负债的： （1）获取被审计单位就处置该非流动资产或处置组作出的决议、企业相关权力机构或监管部门的批准文件、与受让方签订的不可撤销的转让协议等文件，分析该非流动资产或处置组是否在当前状况下仅根据出售此类非流动资产或处置组的惯常条款即可立即出售，是否在一年内转让，确认该类非流动资产或处置组是否满足划分为持有待售的条件； （2）针对专为转售而取得的非流动资产或处置组，取得内部决议、审批文件、董事会会议纪要、转让协议等，分析取得日是否满足“预计出售将在一年内完成”的规定条件，且短期（通常为3个月）内很可能满足持有待售类别的其他划分条件； （3）检查划分为持有待售的非流动资产或处置组的计量是否适当，是否停止计提折旧/折耗/摊销，是否按照账面价值与公允价值减去出售费用后的净额孰低进行计量，公允价值确定是否合理，资产减值损失计量是否适当； （4）如果划分为持有待售的非流动资产或处置组相关交易未能在一年内完成，应了解交易未能完成是否由于企业自身原因导致，还是买方或其他方意外设定导致出售延期或者由其他罕见情况导致，判断其是否继续满足持有待售的条件； （5）如果划分为持有待售的非流动资产或处置组不再满足持有待售确认条件的，询问被审计单位管理层不再处置的原因，并获取相关支持性证据，检查是否停止将其划归为持有待售，计价是否正确。 | C21: 常规★ | D21: √ | F21: √ | G21: √ | I21: K6-4 /K6-5 /K6-6 /K6-7
A22: 6 | B22: 对于未在持有待售资产和负债列报的终止经营： （1）对于其中已被企业处置的组成部分，了解被审计单位终止经营的原因、内容、性质等，并取得相关的支持性文件； （2）确认满足终止经营的组成部分是否按照企业会计准则的规定进行了恰当列报和披露。 | C22: 备选 | D22: √ | F22: √ | G22: √ | H22: √
A23: 7 | B23: 考虑是否存在超出被审计单位正常经营活动的重大、异常交易等，根据评估的舞弊风险等因素增加的审计程序。 | C23: IPO/上市/新三板/重组/舞弊应对
A24: 8 | B24: 检查持有待售资产和负债、终止经营是否已按企业会计准则或其他适用的规定在财务报表中做出恰当列报和披露。 | C24: 常规★ | H24: √ | I24: A1-1/A1-15 /A1-16

Sheet 审定表 K6-1
A1: 致同会计师事务所
A2: 持有待售资产/负债审定表
A3: =底稿目录!A2 -> 被审计单位： | D3: =底稿目录!A4 -> 编制人： | H3: =底稿目录!A5 -> 编制日期： | K3: 索引： | L3: =底稿目录!D6 -> K6-1
A4: =底稿目录!A3 -> 截止日：202X年12月31日 | D4: =底稿目录!A6 -> 复核人： | H4: =底稿目录!A7 -> 复核日期： | K4: 页次：
A5: 项目 | B5: 期初数 | F5: 期末数 | J5: 本期审定数与上期 审定数的比较 | L5: 原因分析
B6: 未审数 | C6: 账项调整 | D6: 重分类调整 | E6: 审定数 | F6: 未审数 | G6: 账项调整 | H6: 重分类调整 | I6: 审定数 | J6: 变动额 | K6: 变动率
A7: 持有待售资产 | B7: ='明细表K6-2'!B16+'明细表K6-2'!B20 -> 0 | C7: ='明细表K6-2'!F16+'明细表K6-2'!F20 -> 0 | D7: ='明细表K6-2'!G16+'明细表K6-2'!G20 -> 0 | E7: ='明细表K6-2'!L16+'明细表K6-2'!L20 -> 0 | F7: ='明细表K6-2'!E16+'明细表K6-2'!E20 -> 0 | G7: ='明细表K6-2'!F16+'明细表K6-2'!F20+'明细表K6-2'!H16+'明细表K6-2'!H20-'明细表K6-2'!I16-'明细表K6-2'!I20 -> 0 | H7: ='明细表K6-2'!G16+'明细表K6-2'!G20+'明细表K6-2'!J16+'明细表K6-2'!J20-'明细表K6-2'!K16-'明细表K6-2'!K20 -> 0 | I7: ='明细表K6-2'!O16+'明细表K6-2'!O20 -> 0 | J7: =I7-E7 -> 0 | K7: =IF(AND(E7=0,I7=0),0,IF(AND(E7=0,I7>0),1,J7/E7)) -> 0
A8: 持有待售负债 | B8: ='明细表K6-2'!B24 -> 0 | C8: ='明细表K6-2'!F24 -> 0 | D8: ='明细表K6-2'!G24 -> 0 | E8: ='明细表K6-2'!L24 -> 0 | F8: ='明细表K6-2'!E24 -> 0 | G8: ='明细表K6-2'!F24+'明细表K6-2'!H24-'明细表K6-2'!I24 -> 0 | H8: ='明细表K6-2'!G24+'明细表K6-2'!J24-'明细表K6-2'!K24 -> 0 | I8: ='明细表K6-2'!O24 -> 0 | J8: =I8-E8 -> 0 | K8: =IF(AND(E8=0,I8=0),0,IF(AND(E8=0,I8>0),1,J8/E8)) -> 0
A9: 合计 | B9: =SUM(B7:B7) -> 0 | C9: =SUM(C7:C7) -> 0 | D9: =SUM(D7:D7) -> 0 | E9: =SUM(E7:E7) -> 0 | F9: =SUM(F7:F7) -> 0 | G9: =SUM(G7:G7) -> 0 | H9: =SUM(H7:H7) -> 0 | I9: =SUM(I7:I7) -> 0 | J9: =I9-E9 -> 0 | K9: =IF(AND(E9=0,I9=0),0,IF(AND(E9=0,I9>0),1,J9/E9)) -> 0
A10: TB数据：
A11: 差异： | B11: =B9-B10 -> 0 | C11: =C9-C10 -> 0 | D11: =D9-D10 -> 0 | E11: =E9-E10 -> 0 | F11: =F9-F10 -> 0 | G11: =G9-G10 -> 0 | H11: =H9-H10 -> 0 | I11: =I9-I10 -> 0
A12: 1.审计说明
A13: （1）持有待售资产/负债本期较上期增加（负数为减少）：
A14: 主要原因（比例超过30%的）：
A16: （2）情况说明。
A18: 2.审计结论

Sheet 附注披露信息（上市公司）
A1: 致同会计师事务所
A2: 附注披露信息（上市公司）
A3: =底稿目录!A2 -> 被审计单位： | C3: =底稿目录!A4 -> 编制人： | D3: =底稿目录!A5 -> 编制日期： | F3: 索引： | G3: =底稿目录!D7 -> 0
A4: =底稿目录!A3 -> 截止日：202X年12月31日 | C4: =底稿目录!A6 -> 复核人： | D4: =底稿目录!A7 -> 复核日期： | F4: 页次： | G4: 1
A5: 持有待售资产和负债
A6: 项 目 | B6: 期末数 | E6: 上年年末数
B7: 账面余额 | C7: 减值准备 | D7: 账面价值 | E7: 账面余额 | F7: 减值准备 | G7: 账面价值
A8: （一）持有待售非流动资产 | B8: =SUM(B9:B11) -> 0 | D8: =B8-C8 -> 0 | E8: ='明细表K6-2'!L12 -> 0 | G8: =E8-F8 -> 0
A9: ='明细表K6-2'!A12 -> 其中：固定资产 | B9: ='明细表K6-2'!O12 -> 0 | D9: =B9-C9 -> 0 | E9: ='明细表K6-2'!L13 -> 0 | G9: =E9-F9 -> 0
A10: ='明细表K6-2'!A13 -> 长期股权投资-联营企业 | B10: ='明细表K6-2'!O13 -> 0 | D10: =B10-C10 -> 0 | E10: ='明细表K6-2'!L14 -> 0 | G10: =E10-F10 -> 0
A11: ='明细表K6-2'!A14 -> 长期股权投资-合营企业 | B11: ='明细表K6-2'!O14 -> 0 | D11: =B11-C11 -> 0 | E11: ='明细表K6-2'!L15 -> 0 | G11: =E11-F11 -> 0
A12: （二）持有待售处置组中的资产 | B12: =SUM(B13:B15) -> 0 | D12: =B12-C12 -> 0 | E12: =SUM(E13:E15) -> 0 | G12: =E12-F12 -> 0
A13: ='明细表K6-2'!A18 -> 其中：子公司A | B13: ='明细表K6-2'!O18 -> 0 | D13: =B13-C13 -> 0 | E13: ='明细表K6-2'!L18 -> 0 | G13: =E13-F13 -> 0
A14: ='明细表K6-2'!A19 -> 分公司B | B14: ='明细表K6-2'!O19 -> 0 | D14: =B14-C14 -> 0 | E14: ='明细表K6-2'!L19 -> 0 | G14: =E14-F14 -> 0
A15: …… | D15: =B15-C15 -> 0 | G15: =E15-F15 -> 0
A16: 合 计 | B16: =B12+B8 -> 0 | C16: =C12+C8 -> 0 | D16: C=A+B=报表数 | E16: =E12+E8 -> 0 | F16: =F12+F8 -> 0
A17: 【提示：“持有待售资产”，反映资产负债表日划分为持有待售类别的非流动资产及划分为持有待售类别的处置组中的流动资产和非流动资产的期末账面价值。该项目应根据在资产类科目新设置的“持有待售资产”科目的期末余额，减去“持有待售资产减值准备”科目的期末余额后的金额填列。】
A18: 【根据《企业会计准则第37号——金融工具列报》第三条，本准则适用于所有企业各种类型的金融工具。因此，如果是包含金融资产的处置组，则可以整体适用《企业会计准则第42号——持有待售的非流动资产、处置组和终止经营》的分类和列报要求（计量仍适用金融工具准则）；如果是单项金融工具，应该按《企业会计准则第37号——金融工具列报》进行处理。】
A19: 项 目 | B19: 期末数 | C19: 上年年末数
A20: 持有待售负债：
A21: 持有待售的处置组中的负债 | B21: =SUM(B22:B23) -> 0 | C21: =SUM(C22:C23) -> 0
A22: ='明细表K6-2'!A22 -> 其中：子公司A | B22: ='明细表K6-2'!O22 -> 0 | C22: ='明细表K6-2'!L22 -> 0
A23: ='明细表K6-2'!A23 -> 分公司B | B23: ='明细表K6-2'!O23 -> 0 | C23: ='明细表K6-2'!L23 -> 0
A24: 合 计 | B24: =B20+B21 -> 0 | C24: =C20+C21 -> 0
A25: 【提示：“持有待售负债”，反映资产负债表日处置组中与划分为持有待售类别的资产直接相关的负债的期末账面价值。该项目应根据在负债类科目新设置的“持有待售负债”科目的期末余额填列。】
A26: 说明：（应当说明持有待售的非流动资产或处置组的出售原因、方式、分部及有关的综合收益累计金额。）
A27: 【披露示例如下：
A28: 2021年X月，本公司管理层因[描述出售原因]决定将其XX分部出售给XX公司。上述拟出售的XX分部作为[持有待售的处置组1]列报。
A29: 本公司将[持有待售的处置组1]的账面价值减计至公允价值减去出售费用后的净额，确认减值损失人民币XX元，同时对[持有待售的处置组1]中[固定资产][、][无形资产][及其他处置组中的资产]分别计提减值准备人民币XX元[、][人民币XX元][及人民币XX元]。
A30: 与[持有待售的处置组1]有关的其他综合收益累计金额为人民币XX元。】
A31: （1）持有待售资产减值准备
A32: 项 目 | B32: 上年年末数 | C32: 本期增加 | D32: 本期减少 | F32: 期末数
D33: 本期转回 | E33: 本期出售
A34: （一）持有待售非流动资产 | B34: =SUM(B35:B37) -> 0 | C34: =SUM(C35:C37) -> 0 | D34: =SUM(D35:D37) -> 0 | E34: =SUM(E35:E37) -> 0 | F34: =B34+C34-D34-E34 -> 0
A35: 其中：固定资产 | F35: =B35+C35-D35-E35 -> 0
A36: 无形资产 | F36: =B36+C36-D36-E36 -> 0
A37: …… | F37: =B37+C37-D37-E37 -> 0
A38: （二）持有待售处置组中的资产 | B38: =SUM(B39:B41) -> 0 | C38: =SUM(C39:C41) -> 0 | D38: =SUM(D39:D41) -> 0 | E38: =SUM(E39:E41) -> 0 | F38: =B38+C38-D38-E38 -> 0
A39: 其中：子公司A | F39: =B39+C39-D39-E39 -> 0
A40: 分公司B | F40: =B40+C40-D40-E40 -> 0
...

Sheet 附注披露信息(国企）
A1: 致同会计师事务所
A2: 附注披露信息(国企)
A3: =底稿目录!A2 -> 被审计单位： | B3: =底稿目录!A4 -> 编制人： | D3: =底稿目录!A5 -> 编制日期： | F3: 索引号： | G3: =底稿目录!D8 -> 0
A4: =底稿目录!A3 -> 截止日：202X年12月31日 | B4: =底稿目录!A6 -> 复核人： | D4: =底稿目录!A7 -> 复核日期： | F4: 页次：
A5: 【注：1.应披露划分为持有待售的非流动资产或处置组的出售原因和方式；
A6: 2.应披露持有待售的非流动资产或处置组的分部信息；
A7: 3.应披露持有待售的非流动资产或持有待售的处置组中的资产确认的减值损失及其转回金额；
A8: 4.应披露与持有待售的非流动资产或处置组有关的其他综合收益累计金额。】
A9: 项 目 | B9: 期末数 | E9: 期初数
B10: 账面余额 | C10: 减值准备 | D10: 账面价值 | E10: 账面余额 | F10: 减值准备 | G10: 账面价值
A11: （一）持有待售非流动资产 | B11: =SUM(B12:B14) -> 0 | D11: =B11-C11 -> 0 | E11: ='明细表K6-2'!L12 -> 0 | G11: =E11-F11 -> 0
A12: 其中：固定资产 | B12: ='明细表K6-2'!O12 -> 0 | D12: =B12-C12 -> 0 | E12: ='明细表K6-2'!L13 -> 0 | G12: =E12-F12 -> 0
A13: 无形资产 | B13: ='明细表K6-2'!O13 -> 0 | D13: =B13-C13 -> 0 | E13: ='明细表K6-2'!L14 -> 0 | G13: =E13-F13 -> 0
A14: …… | B14: ='明细表K6-2'!O14 -> 0 | D14: =B14-C14 -> 0 | E14: ='明细表K6-2'!L15 -> 0 | G14: =E14-F14 -> 0
A15: （二）持有待售处置组中的资产 | B15: =SUM(B16:B18) -> 0 | D15: =B15-C15 -> 0 | E15: =SUM(E16:E18) -> 0 | G15: =E15-F15 -> 0
A16: 其中：子公司A | B16: ='明细表K6-2'!O18 -> 0 | D16: =B16-C16 -> 0 | E16: ='明细表K6-2'!L18 -> 0 | G16: =E16-F16 -> 0
A17: 分公司B | B17: ='明细表K6-2'!O19 -> 0 | D17: =B17-C17 -> 0 | E17: ='明细表K6-2'!L19 -> 0 | G17: =E17-F17 -> 0
A18: …… | D18: =B18-C18 -> 0 | G18: =E18-F18 -> 0
A19: 合 计 | B19: =B11+B15 -> 0 | C19: =C11+C15 -> 0 | D19: A+B=报表数 | E19: =E11+E15 -> 0 | F19: =F11+F15 -> 0 | G19: =G11+G15 -> 0
A20: 【提示：“持有待售资产”，反映资产负债表日划分为持有待售类别的非流动资产及划分为持有待售类别的处置组中的流动资产和非流动资产的期末账面价值。该项目应根据在资产类科目新设置的“持有待售资产”科目的期末余额，减去“持有待售资产减值准备”科目的期末余额后的金额填列。】
A21: （1）持有待售资产减值准备
A22: 项 目 | B22: 期初数 | C22: 本期增加 | D22: 本期减少 | F22: 期末数
D23: 本期转回 | E23: 本期出售
A24: （一）持有待售非流动资产 | B24: =SUM(B25:B27) -> 0 | C24: =SUM(C25:C27) -> 0 | D24: =SUM(D25:D27) -> 0 | E24: =SUM(E25:E27) -> 0 | F24: =B24+C24-D24-E24 -> 0
A25: 其中：固定资产 | F25: =B25+C25-D25-E25 -> 0
A26: 无形资产 | F26: =B26+C26-D26-E26 -> 0
A27: …… | F27: =B27+C27-D27-E27 -> 0
A28: （二）持有待售处置组中的资产 | B28: =SUM(B29:B31) -> 0 | C28: =SUM(C29:C31) -> 0 | D28: =SUM(D29:D31) -> 0 | E28: =SUM(E29:E31) -> 0 | F28: =B28+C28-D28-E28 -> 0
A29: 其中：子公司A | F29: =B29+C29-D29-E29 -> 0
A30: 分公司B | F30: =B30+C30-D30-E30 -> 0
A31: …… | F31: =B31+C31-D31-E31 -> 0
A32: 合 计 | B32: =B24+B28 -> 0 | C32: =C24+C28 -> 0 | D32: =D24+D28 -> 0 | E32: =E24+E28 -> 0 | F32: =B32+C32-D32-E32 -> 0
A33: （2）持有待售非流动资产
A34: 项 目 | B34: 期末账面价值 | C34: 期末公允价值 | D34: 预计处置费用 | E34: 时间安排
A35: ='初始确认检查表K6-4'!A18 -> 其中：固定资产 | B35: ='初始确认检查表K6-4'!B18 -> 0 | C35: ='初始确认检查表K6-4'!I18 -> 0 | D35: ='初始确认检查表K6-4'!J18 -> 0 | E35: ='初始确认检查表K6-4'!L18 -> 0
A36: ='初始确认检查表K6-4'!A19 -> 长期股权投资-联营企业 | B36: ='初始确认检查表K6-4'!B19 -> 0 | C36: ='初始确认检查表K6-4'!I19 -> 0 | D36: ='初始确认检查表K6-4'!J19 -> 0 | E36: ='初始确认检查表K6-4'!L19 -> 0
A37: ='初始确认检查表K6-4'!A20 -> 长期股权投资-合营企业 | B37: ='初始确认检查表K6-4'!B20 -> 0 | C37: ='初始确认检查表K6-4'!I20 -> 0 | D37: ='初始确认检查表K6-4'!J20 -> 0 | E37: ='初始确认检查表K6-4'!L20 -> 0
A38: ='初始确认检查表K6-4'!A21 -> .. | B38: ='初始确认检查表K6-4'!B21 -> 0 | C38: ='初始确认检查表K6-4'!I21 -> 0 | D38: ='初始确认检查表K6-4'!J21 -> 0 | E38: ='初始确认检查表K6-4'!L21 -> 0
A39: 合 计 | B39: =SUM(B35:B38) -> 0 | C39: =SUM(C35:C38) -> 0 | D39: =SUM(D35:D38) -> 0
A40: 【提示：期末账面价值小于等于（期末公允价值-预计处置费用）】
...

Sheet 明细表K6-2
A1: 致同会计师事务所
A2: 持有待售资产和负债明细表
A3: =底稿目录!A2 -> 被审计单位： | D3: =底稿目录!A4 -> 编制人： | J3: =底稿目录!A5 -> 编制日期： | N3: 索引号： | O3: =底稿目录!D9 -> K6-2
A4: =底稿目录!A3 -> 截止日：202X年12月31日 | D4: =底稿目录!A6 -> 复核人： | J4: =底稿目录!A7 -> 复核日期： | N4: 页 次：
A5: 一、审计目标:
A6: 1.资产负债表中记录的持有待售的资产和负债是存在的，且已记录于恰当的账户； | G6: 2.所有应记录的持有待售的资产和负债均已记录，所有应当包括在财务报表中的相关披露均已包括；
A7: 3.持有待售的资产和负债以恰当的金额包括在财务报表中，与之相关的计价或分摊调整已恰当记录，相关披露已得到恰当计量和描述。
A8: 二、审计过程：
A9: 项目 | B9: 未审数 | F9: 期初调整 | H9: 账项调整 | J9: 重分类调整 | L9: 审定数
B10: 期初数 | C10: 本期增加 | D10: 本期减少 | E10: 期末数 | F10: 账项调整 | G10: 重分类调整 | H10: 本期增加 | I10: 本期减少 | J10: 本期增加 | K10: 本期减少 | L10: 期初数 | M10: 本期增加 | N10: 本期减少 | O10: 期末数
A11: 持有待售的非流动资产：
A12: 其中：固定资产 | E12: =B12+C12-D12 -> 0 | L12: =B12+F12+G12 -> 0 | M12: =C12+H12+J12 -> 0 | N12: =D12+I12+K12 -> 0 | O12: =L12+M12-N12 -> 0
A13: 长期股权投资-联营企业 | E13: =B13+C13-D13 -> 0 | L13: =B13+F13+G13 -> 0 | M13: =C13+H13+J13 -> 0 | N13: =D13+I13+K13 -> 0 | O13: =L13+M13-N13 -> 0
A14: 长期股权投资-合营企业 | E14: =B14+C14-D14 -> 0 | L14: =B14+F14+G14 -> 0 | M14: =C14+H14+J14 -> 0 | N14: =D14+I14+K14 -> 0 | O14: =L14+M14-N14 -> 0
A15: .. | E15: =B15+C15-D15 -> 0 | L15: =B15+F15+G15 -> 0 | M15: =C15+H15+J15 -> 0 | N15: =D15+I15+K15 -> 0 | O15: =L15+M15-N15 -> 0
A16: 小计 | B16: =SUM(B12:B15) -> 0 | C16: =SUM(C12:C15) -> 0 | D16: =SUM(D12:D15) -> 0 | E16: =SUM(E12:E15) -> 0 | F16: =SUM(F12:F15) -> 0 | G16: =SUM(G12:G15) -> 0 | H16: =SUM(H12:H15) -> 0 | I16: =SUM(I12:I15) -> 0 | ... O16: =SUM(O12:O15) -> 0
A17: 持有待售的处置组中的资产：
A18: 其中：子公司A | E18: =B18+C18-D18 -> 0 | L18: =B18+F18+G18 -> 0 | M18: =C18+H18+J18 -> 0 | N18: =D18+I18+K18 -> 0 | O18: =L18+M18-N18 -> 0
A19: 分公司B | E19: =B19+C19-D19 -> 0 | L19: =B19+F19+G19 -> 0 | M19: =C19+H19+J19 -> 0 | N19: =D19+I19+K19 -> 0 | O19: =L19+M19-N19 -> 0
A20: 资产合计 | B20: =SUM(B18:B19) -> 0 | C20: =SUM(C18:C19) -> 0 | D20: =SUM(D18:D19) -> 0 | E20: =SUM(E18:E19) -> 0 | F20: =SUM(F18:F19) -> 0 | G20: =SUM(G18:G19) -> 0 | H20: =SUM(H18:H19) -> 0 | I20: =SUM(I18:I19) -> 0 | ... O20: =SUM(O18:O19) -> 0
A21: 持有待售的处置组中的负债：
A22: 其中：子公司A | E22: =B22+C22-D22 -> 0 | L22: =B22+F22+G22 -> 0 | M22: =C22+H22+J22 -> 0 | N22: =D22+I22+K22 -> 0 | O22: =L22+M22-N22 -> 0
A23: 分公司B | E23: =B23+C23-D23 -> 0 | L23: =B23+F23+G23 -> 0 | M23: =C23+H23+J23 -> 0 | N23: =D23+I23+K23 -> 0 | O23: =L23+M23-N23 -> 0
A24: 负债合计 | B24: =SUM(B22:B23) -> 0 | C24: =SUM(C22:C23) -> 0 | D24: =SUM(D22:D23) -> 0 | E24: =SUM(E22:E23) -> 0 | F24: =SUM(F22:F23) -> 0 | G24: =SUM(G22:G23) -> 0 | H24: =SUM(H22:H23) -> 0 | I24: =SUM(I22:I23) -> 0 | ... O24: =SUM(O22:O23) -> 0
A25: 三、审计说明：
A27: 四、审计结论：
A31: 编制说明：
A32: 非流动资产或处置组划分为持有待售类别，应当同时满足下列条件：根据类似交易中出售此类资产或处置组的惯例，在当前状况下即可立即出售；出售极可能发生，即企业已经就一项出售计划作出决议且获得确定的购买承诺，预计出售将在一年内完成。有关规定要求企业相关权力机构或者监管部门批准后方可出售的，应当已经获得批准。
A33: 持有待售的资产包括单项资产和处置组。在特定情况下，处置组包括企业合并中取得的商誉等。
A34: 持有待售的非流动资产和持有待售的处置组 中的资产不计提折旧或进行摊销，按照账面价值与公允价值减去出售费用后的净额孰低进行计量，并列报为“划分为持有待售的资产”。持有待售的处置组中的负债，列报为“划分为持有待售的负债”。
A35: 某项非流动资产或处置组被划归为持有待售，但后来不再满足持有待售的非流动资产的确认条件，企业应当停止将其划归为持有待售，并按照下列两项金额中较低者计量：
A36: ① 划分为持有待售类别前的账面价值，按照假定不划分为持有待售类别情况下本应确认的折旧、摊销或减值等进行调整后的金额；
A37: ② 决定不再出售之日的可收回金额。

Sheet 调整分录汇总 K6-3
A1: 致同会计师事务所
A2: 持有待售资产和负债调整分录汇总表
A3: =底稿目录!A2 -> 被审计单位： | C3: =底稿目录!A4 -> 编制人： | E3: =底稿目录!A5 -> 编制日期： | I3: 索引号： | J3: =底稿目录!D10 -> K6-3
A4: =底稿目录!A3 -> 截止日：202X年12月31日 | C4: =底稿目录!A6 -> 复核人： | E4: =底稿目录!A7 -> 复核日期： | I4: 页次：
A5: 调整事项说明 | B5: 类别（报表调整/账项调整/其他） | C5: 报表项目 | D5: 科目名称 | E5: 附注项目 | F5: …… | G5: 借方调整金额 | H5: 贷方调整金额 | I5: 索引 | J5: 备注
A21: 提示：本底稿适用于调整分录较多、较复杂的项目，且仅列示与本报表项目相关的审计调整。项目组可根据项目实际情况选择是否使用该底稿。

Sheet 初始确认检查表K6-4
A1: 致同会计师事务所
A2: 持有待售资产和负债初始确认检查表
A3: =底稿目录!A2 -> 被审计单位： | G3: =底稿目录!A4 -> 编制人： | L3: =底稿目录!A5 -> 编制日期： | N3: 索引号： | O3: =底稿目录!D11 -> K6-4
A4: =底稿目录!A3 -> 截止日：202X年12月31日 | G4: =底稿目录!A6 -> 复核人： | L4: =底稿目录!A7 -> 复核日期： | N4: 页次：
A5: 一、审计目标:
A6: 1.资产负债表中记录的持有待售的资产和负债是存在的，且已记录于恰当的账户； | H6: 2.记录的持有待售资产由被审计单位拥有或控制；记录的持有待售负债是被审计单位应当履行的偿还义务；
A7: 3.持有待售的资产和负债以恰当的金额包括在财务报表中，与之相关的计价或分摊调整已恰当记录，相关披露已得到恰当计量和描述
A8: 二、审计过程：
A9: 1.获取处置该非流动资产或处置组作出的决议、与受让方签订的不可撤销的转让协议等文件，分析该非流动资产或处置组是否在当前状况下仅根据出售此类非流动资产或处置组的惯常条款即可立即出售，是否出售将在一年内完成，确认该类非流动资产或处置组是否满足划分为持有待售的条件。
A10: 2.检查划分为持有待售的非流动资产或处置组是否停止计提折旧/折耗/摊销，是否按照账面价值与公允价值减去出售费用后的净额孰低进行计量，公允价值确定是否合理。
A11: 3.根据处置资产类别不同，与计入的不同损益项目勾稽，核对并复核计入金额是否准确。
A12: 4.如果划分为持有待售的非流动资产或处置组不再满足持有待售确认条件的，询问被审计单位管理层不再处置的原因，并获取相关支持性证据，检查是否停止将其划归为持有待售，计价是否正确。
A13: 5.如果管理层聘请了专家来确定或者协助确定公允价值和出售费用，注册会计师也应该考虑利用专家工作。
A14: 6.结合关联方审计程序，关注与关联方签订的处置资产（或处置组）的协议的相关会计处理和披露是否符合企业会计准则要求。
A15: 项目 | B15: 账面价值 | C15: 公允价值 | J15: 出售费用（资产处置的直接归属费用） | K15: 公允价值减去出售费用后的净额 | L15: 预计出售时间（预计出售将在一年内完成） | M15: 根据类似交易中出售此类资产或处置组的惯例，在当前状况下即可立即出售 | N15: 被审计单位就出售计划作出决议（索引） | O15: 与受让方签订的不可撤销的具有法律约束力的购买协议 （索引）
C16: 销售协议价格 | D16: 依据 | E16: 资产活跃市场价格 | F16: 依据 | G16: 估计价格 | H16: 依据 | I16: 公允价值
A17: 持有待售的非流动资产：
A18: 其中：固定资产 | B18: ='明细表K6-2'!O12 -> 0 | I18: =IF(C18>0,C18,IF(E18>0,E18,G18)) -> 0 | K18: =IF(C18>0,C18,IF(E18>0,E18,G18))-J18 -> 0 | M18: 是
A19: 长期股权投资-联营企业 | B19: ='明细表K6-2'!O13 -> 0 | I19: =IF(C19>0,C19,IF(E19>0,E19,G19)) -> 0 | K19: =IF(C19>0,C19,IF(E19>0,E19,G19))-J19 -> 0 | M19: "请选择"
A20: 长期股权投资-合营企业 | B20: ='明细表K6-2'!O14 -> 0 | I20: =IF(C20>0,C20,IF(E20>0,E20,G20)) -> 0 | K20: =IF(C20>0,C20,IF(E20>0,E20,G20))-J20 -> 0 | M20: "请选择"
A21: .. | B21: ='明细表K6-2'!O15 -> 0 | I21: =IF(C21>0,C21,IF(E21>0,E21,G21)) -> 0 | K21: =IF(C21>0,C21,IF(E21>0,E21,G21))-J21 -> 0 | M21: "请选择"
A22: 小计 | B22: =SUM(B18:B21) -> 0 | C22: =SUM(C18:C21) -> 0 | D22: =SUM(D18:D21) -> 0 | E22: =SUM(E18:E21) -> 0 | F22: =SUM(F18:F21) -> 0 | G22: =SUM(G18:G21) -> 0 | H22: =SUM(H18:H21) -> 0 | I22: =SUM(I18:I21) -> 0 | ... K22: =SUM(K18:K21) -> 0
A23: 持有待售的处置组中的资产：
A24: 子公司A： | B24: =SUM(B25:B27) -> 0 | C24: =SUM(C25:C27) -> 0 | D24: =SUM(D25:D27) -> 0 | E24: =SUM(E25:E27) -> 0 | F24: =SUM(F25:F27) -> 0 | G24: =SUM(G25:G27) -> 0 | H24: =SUM(H25:H27) -> 0 | I24: =IF(C24>0,C24,IF(E24>0,E24,G24)) -> 0 | J24: =IF(D24>0,D24,IF(F24>0,F24,H24)) -> 0 | K24: =IF(C24>0,C24,IF(E24>0,E24,G24))-J24 -> 0 | M24: "请选择"
A25: 货币资金 | I25: =IF(C25>0,C25,IF(E25>0,E25,G25)) -> 0 | K25: =IF(C25>0,C25,IF(E25>0,E25,G25))-J25 -> 0 | M25: "请选择"
A26: 固定资产 | I26: =IF(C26>0,C26,IF(E26>0,E26,G26)) -> 0 | K26: =IF(C26>0,C26,IF(E26>0,E26,G26))-J26 -> 0 | M26: "请选择"
A27: .. | I27: =IF(C27>0,C27,IF(E27>0,E27,G27)) -> 0 | K27: =IF(C27>0,C27,IF(E27>0,E27,G27))-J27 -> 0 | M27: "请选择"
A28: 分公司B： | B28: =SUM(B29:B31) -> 0 | C28: =SUM(C29:C31) -> 0 | D28: =SUM(D29:D31) -> 0 | E28: =SUM(E29:E31) -> 0 | F28: =SUM(F29:F31) -> 0 | G28: =SUM(G29:G31) -> 0 | H28: =SUM(H29:H31) -> 0 | I28: =IF(C28>0,C28,IF(E28>0,E28,G28)) -> 0 | J28: =IF(D28>0,D28,IF(F28>0,F28,H28)) -> 0 | K28: =IF(C28>0,C28,IF(E28>0,E28,G28))-J28 -> 0 | M28: "请选择"
A29: 货币资金 | I29: =IF(C29>0,C29,IF(E29>0,E29,G29)) -> 0 | K29: =IF(C29>0,C29,IF(E29>0,E29,G29))-J29 -> 0 | M29: "请选择"
A30: 固定资产 | I30: =IF(C30>0,C30,IF(E30>0,E30,G30)) -> 0 | K30: =IF(C30>0,C30,IF(E30>0,E30,G30))-J30 -> 0 | M30: "请选择"
A31: .. | I31: =IF(C31>0,C31,IF(E31>0,E31,G31)) -> 0 | K31: =IF(C31>0,C31,IF(E31>0,E31,G31))-J31 -> 0 | M31: "请选择"
A32: 小计 | B32: =SUM(B25:B26,B29:B30) -> 0 | I32: =SUM(I25:I26,I29:I30) -> 0 | J32: =SUM(J25:J26,J29:J30) -> 0 | K32: =SUM(K24:K31) -> 0
A33: 资产合计 | B33: =B22+B32 -> 0 | I33: =I22+I32 -> 0 | J33: =J22+J32 -> 0 | K33: =K22+K32 -> 0
A34: 持有待售的处置组中的负债：
A35: 子公司A | B35: =SUM(B36:B38) -> 0 | C35: =SUM(C36:C38) -> 0 | D35: =SUM(D36:D38) -> 0 | E35: =SUM(E36:E38) -> 0 | F35: =SUM(F36:F38) -> 0 | G35: =SUM(G36:G38) -> 0 | H35: =SUM(H36:H38) -> 0 | I35: =SUM(I36:I38) -> 0 | ... K35: =SUM(K36:K38) -> 0 | M35: "请选择"
A36: 应付票据及应付账款 | I36: =IF(C36>0,C36,IF(E36>0,E36,G36)) -> 0 | K36: =IF(C36>0,C36,IF(E36>0,E36,G36))-J36 -> 0 | M36: "请选择"
A37: 长期应付款 | I37: =IF(C37>0,C37,IF(E37>0,E37,G37)) -> 0 | K37: =IF(C37>0,C37,IF(E37>0,E37,G37))-J37 -> 0 | M37: "请选择"
A38: .. | I38: =IF(C38>0,C38,IF(E38>0,E38,G38)) -> 0 | K38: =IF(C38>0,C38,IF(E38>0,E38,G38))-J38 -> 0 | M38: "请选择"
A39: 分公司B | B39: =SUM(B40:B42) -> 0 | C39: =SUM(C40:C42) -> 0 | D39: =SUM(D40:D42) -> 0 | E39: =SUM(E40:E42) -> 0 | F39: =SUM(F40:F42) -> 0 | G39: =SUM(G40:G42) -> 0 | H39: =SUM(H40:H42) -> 0 | I39: =SUM(I40:I42) -> 0 | ... K39: =SUM(K40:K42) -> 0 | M39: "请选择"
A40: 应付票据及应付账款 | I40: =IF(C40>0,C40,IF(E40>0,E40,G40)) -> 0 | K40: =IF(C40>0,C40,IF(E40>0,E40,G40))-J40 -> 0 | M40: "请选择"
...

Sheet 减值准备测试表（后续计量） K6-5
A1: 致同会计师事务所
A2: 减值准备测试表（后续计量）
A3: =底稿目录!A2 -> 被审计单位： | D3: =底稿目录!A4 -> 编制人： | F3: =底稿目录!A5 -> 编制日期： | I3: 索引号： | J3: =底稿目录!D12 -> K6-5
A4: =底稿目录!A3 -> 截止日：202X年12月31日 | D4: =底稿目录!A6 -> 复核人： | F4: =底稿目录!A7 -> 复核日期： | I4: 页 次：
A5: 一、审计目标:
A6: 持有待售的资产和负债以恰当的金额包括在财务报表中，与之相关的计价或分摊调整已恰当记录，相关披露已得到恰当计量和描述。
A7: 二、审计过程：
A8: 项目 | B8: 账面价值 | C8: 公允价值 | D8: 公允价值确定依据 | E8: 出售费用（资产处置的直接归属费用） | F8: 公允价值减去出售费用后的净额 | G8: 应计提减值准备 | H8: 账面期末减值准备 | I8: 应补提或转回的减值准备 | J8: 备注
A9: 持有待售的非流动资产：
A10: 其中：固定资产 | F10: =C10-E10 -> 0 | G10: =B10-F10 -> 0 | I10: =G10-H10 -> 0
A11: 长期股权投资-联营企业 | F11: =C11-E11 -> 0 | G11: =B11-F11 -> 0 | I11: =G11-H11 -> 0
A12: 长期股权投资-合营企业 | F12: =C12-E12 -> 0 | G12: =B12-F12 -> 0 | I12: =G12-H12 -> 0
A13: .. | F13: =C13-E13 -> 0 | G13: =B13-F13 -> 0 | I13: =G13-H13 -> 0
A14: 小计 | B14: =SUM(B10:B13) -> 0 | C14: =SUM(C10:C13) -> 0 | E14: =SUM(E10:E13) -> 0 | F14: =SUM(F10:F13) -> 0 | G14: =SUM(G10:G13) -> 0 | H14: =SUM(H10:H13) -> 0 | I14: =SUM(I10:I13) -> 0
A15: 三、审计说明：
A17: 四、审计结论：

Sheet 处置组减值测试表（后续计量） K6-6
A1: 致同会计师事务所
A2: 处置组减值测试表（后续计量）
A3: =底稿目录!A2 -> 被审计单位： | C3: =底稿目录!A4 -> 编制人： | E3: =底稿目录!A5 -> 编制日期： | I3: 索引号： | J3: =底稿目录!D13 -> K6-6
A4: =底稿目录!A3 -> 截止日：202X年12月31日 | C4: =底稿目录!A6 -> 复核人： | E4: =底稿目录!A7 -> 复核日期： | I4: 页 次：
A5: 一、审计目标:
A6: 持有待售的资产和负债以恰当的金额包括在财务报表中，与之相关的计价或分摊调整已恰当记录，相关披露已得到恰当计量和描述。
A7: 二、审计过程：
A8: （一）持有待售的处置组的减值测算
A9: 项目 | B9: 账面价值 | C9: 公允价值 | D9: 公允价值确定依据 | E9: 出售费用 | F9: 公允价值减去出售费用后的净额 | G9: 应计提减值准备 | H9: 账面期末减值准备 | I9: 应补提或转回的减值准备 | J9: 备注
A10: 持有待售的处置组：
A11: 子公司A | F11: =C11-E11 -> 0 | G11: =IF((B11-F11)<0,0,(B11-F11)) -> 0 | I11: =G11-H11 -> 0
A12: 分公司B | F12: =C12-E12 -> 0 | G12: =IF((B12-F12)<0,0,(B12-F12)) -> 0 | I12: =G12-H12 -> 0
F13: =C13-E13 -> 0 | G13: =IF((B13-F13)<0,0,(B13-F13)) -> 0 | I13: =G13-H13 -> 0
A14: .. | F14: =C14-E14 -> 0 | G14: =IF((B14-F14)<0,0,(B14-F14)) -> 0 | I14: =G14-H14 -> 0
A15: 小计 | B15: =SUM(B11:B14) -> 0 | C15: =SUM(C11:C14) -> 0 | D15: =SUM(D11:D14) -> 0 | E15: =SUM(E11:E14) -> 0 | F15: =SUM(F11:F14) -> 0 | G15: =SUM(G11:G14) -> 0 | H15: =SUM(H11:H14) -> 0 | I15: =SUM(I11:I14) -> 0
A16: （二）持有待售的处置组的减值损失的分摊---XX子公司
A17: 报表项目 | B17: 资产负债表日 未分摊减值前的账面价值 | C17: 处置组减值的分摊 | D17: 资产负债表日 分摊减值后的账面价值 | E17: 资产负债表日 未审账面价值 | F17: 应补提或转回的减值准备
A18: 1.持有待售资产：
A19: 资产类：
A20: 流动资产
A21: 货币资金 | D21: =B21-C21 -> 0 | F21: =D21-E21 -> 0
A22: 以公允价值计量且其变动计入当期损益的金融资产 | D22: =B22-C22 -> 0 | F22: =D22-E22 -> 0
A23: 应收票据及应收账款 | D23: =B23-C23 -> 0 | F23: =D23-E23 -> 0
A24: 预付账款 | D24: =B24-C24 -> 0 | F24: =D24-E24 -> 0
A25: 其他应收款 | D25: =B25-C25 -> 0 | F25: =D25-E25 -> 0
A26: 存货 | D26: =B26-C26 -> 0 | F26: =D26-E26 -> 0
A27: 一年内到期的非流动资产 | D27: =B27-C27 -> 0 | F27: =D27-E27 -> 0
A28: 其他流动资产 | D28: =B28-C28 -> 0 | F28: =D28-E28 -> 0
A29: 非流动资产
A30: 长期股权投资 | D30: =B30-C30 -> 0 | F30: =D30-E30 -> 0
A31: 投资性房地产 | D31: =B31-C31 -> 0 | F31: =D31-E31 -> 0
A32: 固定资产 | D32: =B32-C32 -> 0 | F32: =D32-E32 -> 0
A33: 无形资产 | D33: =B33-C33 -> 0 | F33: =D33-E33 -> 0
A34: 在建工程 | D34: =B34-C34 -> 0 | F34: =D34-E34 -> 0
A35: 开发支出 | D35: =B35-C35 -> 0 | F35: =D35-E35 -> 0
A36: 商誉 | D36: =B36-C36 -> 0 | F36: =D36-E36 -> 0
A37: … | D37: =B37-C37 -> 0 | F37: =D37-E37 -> 0
A38: 持有待售资产类合计 | B38: =SUM(B21:B37) -> 0 | C38: =SUM(C21:C37) -> 0 | D38: =SUM(D21:D37) -> 0 | E38: =SUM(E21:E37) -> 0 | F38: =D38-E38 -> 0
A39: 2.持有待售负债：
A40: 流动负债：
...

Sheet 检查表（不再满足持有待售）K6-7
A1: 致同会计师事务所
A2: 检查表（不再满足持有待售）
A3: =底稿目录!A2 -> 被审计单位： | D3: =底稿目录!A4 -> 编制人： | F3: =底稿目录!A5 -> 编制日期： | H3: 索引号： | I3: =底稿目录!D14 -> K6-7
A4: =底稿目录!A3 -> 截止日：202X年12月31日 | D4: =底稿目录!A6 -> 复核人： | F4: =底稿目录!A7 -> 复核日期： | H4: 页 次：
A5: 一、审计目标:
A6: 1.资产负债表中记录的持有待售的资产和负债是存在的，且已记录于恰当的账户；
A7: 2.所有应记录的持有待售的资产和负债均已记录，所有应当包括在财务报表中的相关披露均已包括；
A8: 3.持有待售的资产和负债以恰当的金额包括在财务报表中，与之相关的计价或分摊调整已恰当记录，相关披露已得到恰当计量和描述。
A9: 二、审计过程：
A10: 项目 | B10: 被划归为持有待售之前的账面价值 ① | C10: 假定在没有被划归为持有待售的情况下原应确认的折旧、摊销 ② | D10: 假定在没有被划归为持有待售的情况下原应确认的减值准备 ③ | E10: 净额 ④=①-②-③ | F10: 决定不再出售之日的可收回金额 | G10: 不再满足持有待售的原因 | H10: 被审计单位不再处置该非流动资产或处置组的决议（索引） | I10: 与受让方之间签订的不再处置的协议等（索引）
A11: 不再满足持有待售的非流动资产：
A12: 其中：固定资产 | E12: =B12-C12-D12 -> 0
A13: 长期股权投资-联营企业 | E13: =B13-C13-D13 -> 0
A14: 长期股权投资-合营企业 | E14: =B14-C14-D14 -> 0
A15: .. | E15: =B15-C15-D15 -> 0
A16: 小计 | B16: =SUM(B12:B15) -> 0 | C16: =SUM(C12:C15) -> 0 | D16: =SUM(D12:D15) -> 0 | E16: =SUM(E12:E15) -> 0 | F16: =SUM(F12:F15) -> 0
A17: 不再满足持有待售的处置组中的资产：
A18: 其中：子公司A
A19: 货币资金 | E19: =B19-C19-D19 -> 0
A20: …… | E20: =B20-C20-D20 -> 0
A21: 固定资产 | E21: =B21-C21-D21 -> 0
A22: …… | E22: =B22-C22-D22 -> 0
A23: 小计 | B23: =SUM(B19:B22) -> 0 | C23: =SUM(C19:C22) -> 0 | D23: =SUM(D19:D22) -> 0 | E23: =SUM(E19:E22) -> 0 | F23: =SUM(F19:F22) -> 0
A24: 分公司B
A25: 货币资金 | E25: =B25-C25-D25 -> 0
A26: …… | E26: =B26-C26-D26 -> 0
A27: 固定资产 | E27: =B27-C27-D27 -> 0
A28: …… | E28: =B28-C28-D28 -> 0
A29: 小计 | B29: =SUM(B25:B28) -> 0 | C29: =SUM(C25:C28) -> 0 | D29: =SUM(D25:D28) -> 0 | E29: =SUM(E25:E28) -> 0 | F29: =SUM(F25:F28) -> 0
A30: 小计 | B30: =B23+B29 -> 0 | C30: =C23+C29 -> 0 | D30: =D23+D29 -> 0 | E30: =E23+E29 -> 0 | F30: =F23+F29 -> 0
A31: 资产合计 | B31: =B16+B30 -> 0 | C31: =C16+C30 -> 0 | D31: =D16+D30 -> 0 | E31: =E16+E30 -> 0 | F31: =F16+F30 -> 0
A32: 不再满足持有待售的处置组中的负债： | D32: =IF($B$22=0,0,B32/$B$22) -> 0 | I32: =IF($F$22=0,0,F32/$F$22) -> 0
A33: 其中：子公司A
A34: 应付账款 | E34: =B34-C34-D34 -> 0
A35: 长期应付款 | E35: =B35-C35-D35 -> 0
A36: …… | E36: =B36-C36-D36 -> 0
A37: 小计 | B37: =SUM(B34:B36) -> 0 | C37: =SUM(C34:C36) -> 0 | D37: =SUM(D34:D36) -> 0 | E37: =SUM(E34:E36) -> 0 | F37: =SUM(F34:F36) -> 0
A38: 分公司B
A39: 应付账款 | E39: =B39-C39-D39 -> 0
A40: 长期应付款 | E40: =B40-C40-D40 -> 0
...
