Workbook

Sheet 底稿目录
A1: 底稿开列时，可先在以下单元格填写有关内容，以便其他底稿引用有关数据： | B1: 目录
A2: 被审计单位：
A3: 会计期间：202X年度 | B3: 序号 | C3: 内容 | D3: 索引号 | E3: 备注
A4: 编制人： | B4: 1 | C4: 实质性程序表 | D4: K8A
A5: 编制日期： | B5: 2 | C5: 审定表 | D5: K8-1
A6: 复核人： | B6: 3 | C6: 附注披露信息（上市公司） | F6: 无需打印
A7: 复核日期： | B7: 4 | C7: 附注披露信息（国企） | F7: 无需打印
B8: 5 | C8: 明细表 | D8: K8-2
A9: 关于工作底稿与审计程序索引号对应的说明 | B9: 6 | C9: 调整分录汇总 | D9: K8-3
A10: 1.编制的审计工作底稿应与审计程序对应。审计项目组应根据被审计单位实际情况和风险评估情况在实质性程序表中裁剪、修改或增加审计程序，根据实际执行的审计程序完成相应审计工作底稿，编制的工作底稿中应按自然顺序依次编制索引号，并通过唯一的索引号将与实质性程序表中的程序对应关联（即将工作底稿的索引号填入实质性程序表中的底稿索引号列）。 | B10: 7 | C10: 实质性分析 | D10: K8-4
B11: 9 | C11: 合同检查表 | D11: K8-5
B12: 8 | C12: 截止性测试(从记账凭证至原始凭证） | D12: K8-6
C13: 截止性测试（从原始凭证至记账凭证） | D13: K8-7
A14: 2.获取的支持性证据应与审计底稿或程序对应。审计项目组在完成底稿时获取的支持性证据应根据底稿索引号编制下一级按自然顺序排序的索引号（如D1-2-1、D1-2-2、……），并在底稿中说明引用的支持性证据、关联索引号。 | B14: 10 | C14: 销售费用检查表 | D14: K8-8
A17: 3.工作底稿索引号的编码规则：实质性程序索引号按循环从“D”到“N”,循环内账户以顺序号排列，模板中底稿索引号按账户顺序+自然数顺序（即模板中索引号按二级自然顺序排列，如D1-1、D1-2、D1-3、……D1-N）。

Sheet 实质性程序表K8A
A1: 致同会计师事务所
A2: 销售费用实质性程序
A3: =底稿目录!A2 -> 被审计单位： | C3: =底稿目录!A4 -> 编制人： | E3: =底稿目录!A5 -> 编制日期： | H3: 索引号： | I3: =底稿目录!D4 -> K8A
A4: =底稿目录!A3 -> 会计期间：202X年度 | C4: =底稿目录!A6 -> 复核人： | E4: =底稿目录!A7 -> 复核日期： | H4: 页次：
A5: 一、本账户涉及的科目
A6: 销售费用
A7: 二、审计目标与认定的对应关系
A8: 审计目标 | G8: 财务报表的认定
A9: A. 利润表中记录的销售费用已发生，且与被审计单位有关，已记录于恰当的账户 | G9: 发生
A10: B. 所有应当记录的销售费用均已记录，所有应当包括在财务报表中的相关披露均已包括 | G10: 完整性
A11: C. 与销售费用有关的金额及其他数据已恰当记录，相关披露已得到恰当计量和描述 | G11: 准确性
A12: D. 销售费用已记录于正确的会计期间 | G12: 截止
A13: E. 已被恰当地汇总或分解且表述清楚，相关披露在按照企业会计准则的编制基础下是相关的、可理解的 | G13: 列报
A14: 三、计划实施的实质性程序
A15: 序号 | B15: 审计程序 | C15: 程序分类 | D15: 审计程序 | I15: 底稿索引号
D16: 发生 | E16: 完整性 | F16: 准确性 | G16: 截止 | H16: 列报 | J16: 根据被审计单位实际情况和风险评估情况裁剪、修改或增加审计程序
A17: 1 | B17: 获取或编制明细表、执行下列程序，并编制审定表： (1)复核其加计数是否正确，并与报表、总账数和明细账合计数核对是否相符； (2)将销售费用中的工资、折旧等与相关的资产、负债科目核对，检查其勾稽关系的合理性。 | C17: 常规★ | D17: √ | E17: √ | F17: √ | I17: K8-1 /K8-2
A18: 2 | B18: 在使用手工编制、自定义信息报告、系统生成的非固定格式报告等由被审计单位生成的信息时，测试有关信息准确性和完整性，并考虑针对编制和维护由被审计单位生成的信息的相关控制实施控制测试，以评价该信息是否能够为实现审计目的提供基础。 | C18: 常规★ | E18: √ | F18: √ | I18: T1 | J18: 可参见《审计手册》4.2.6，由被审计单位生成的信息可能是由系统生成的、或手工编制的、或二者兼而有之的方式生成的。例如，由被审计单位生成的信息可能包括： • 不涉及自定义的、由系统生成的报告（如，固定格式报告）； • 可能通过人工自定义的、由系统生成的报告，例如，（计算机）查询信息或特别定制的报告； • 手工编制的信息，例如，汇总信息的电子表格或用以支持分配、计算以及调节的电子表格； • 其他系统生成或手工编制的信息，例如，由被审计单位编制的客户发票； • 通过影印、拍摄、扫描或其他方式转换成电子形式的文件记录。
A19: 3 | B19: 对上期发生额的审计：结合本期审计确定销售费用的上期金额的截止是否恰当。（适用于首次承接） | C19: 备选 | G19: √ | J19: 由被审计单位生成的信息不包括： • 总分类账或明细分类账、试算平衡表、或经审计的财务报表； • 第三方（除了服务机构）的报表或报告，例如，原始银行对账单，或函证的回函； • 外部数据（例如，第三方发布的数据，如，定价来源）。
A20: 4 | B20: 关注会计政策、会计估计合理性、一贯性。关注其是否利用会计政策和会计估计及其变更操纵利润。 | C20: 常规★ | D20: √ | E20: √ | F20: √ | I20: K8-1 /K8-2
A21: 5 | B21: 分析总体合理性： （1）分析本期销售费用明细占比情况、与上期发生额比较，分析异常波动原因；关注明细项中是否存在不符合往年常态的项目，不符合企业经营状况，存在异常变动的项目，检查相关支持性文件； （2）分析本期销售费用明细各月金额及其占比，分析异常波动原因； （3）计算分析本期销售费用及主要明细项目金额占主营业务收入的比率，并与上年度可比期间、同行业水平进行对比，判断变动的合理性； （4）将销售费用实际发生金额与预算金额进行比较。 | C21: 常规★ | D21: √ | E21: √ | F21: √ | I21: K8-4
A22: 6 | B22: 对具体费用项目与相关财务数据及非财务数据的匹配性进行分析测试，如公司收入与销售佣金、运输费用是否同步增长，或未同步增长的原因；销售模式的变更对佣金的影响；员工人数是否与公司业务规模相匹配等。对于重大异常情况，应考虑舞弊的可能。 | C22: IPO/上市/新三板/重组/舞弊应对 | D22: √ | E22: √ | F22: √
A23: 7 | B23: 对于广告费、宣传费、咨询费、房租等合同费用，获取合同、协议，查看具体约定条款，并根据具体约定条款测算费用，检查销售费用确认是否准确和完整。 | C23: 常规★ | D23: √ | E23: √ | F23: √ | G23: √ | I23: K8-5
A24: 8 | B24: 对于销售佣金：检查支出是否符合规定，审批手续是否健全，是否取得有效的原始凭证，根据具体情况进行量化匡算分析；如超过规定，应在计算应纳税所得额时调整； | C24: 备选 | D24: √ | E24: √ | F24: √ | G24: √
A25: 9 | B25: 检查关联方交易：了解关联交易事项的目的、价格和条件，检查交易的支持性文件，同时向关联方或其他注册会计师函证重大的交易（包括担保和其他重要信息），以确认交易的真实性；必要时，向与交易相关的人员和机构（如银行、律师）函证或与其讨论有关信息；考虑是否存在未识别的关联方，关联交易和余额披露是否正确。 | C25: 常规★ | D25: √ | E25: √ | F25: √ | G25: √ | H25: √
A26: 10 | B26: 检查是否存在关联方或其他利益相关方代被审计单位支付成本、费用或者采用无偿或不公允的交易价格向被审计单位提供经济资源： （1）取得控股股东、实际控制人及其控制企业的财务报表，对于财务报表相关费用项目变动较大的，以及该等关联方与被审计单位存在资金往来的，询问其原因，关注费用发生真实性以及资金真实意图和流向； （2）了解被审计单位是否向关联方租用办公场所或无偿使用，关注租金的合理性。与被审计单位相同或相近办公地址的关联方或其他利益相关方，重点核查其有无代为支付成本、费用的情形； （3）调查并访谈实际控制人关于其投资领域、投资回报以及民间借贷、借贷用途、接受各类监管检查等方面的情况； （4）分析计入费用的工资薪金，关注构成是否异常变化、各月之间波动有无异常，如果异常降低，关注是否存在其他方（如关联方）代付工资的情况； （4）取得被审计单位及其实际控制人、控股股东、董事、监事、高管等关联方对“关联方代为支付成本费用进行利益输送的情形”出具的承诺书；如报告期内实际控制人转让拟IPO企业股份或转让其他企业股权且金额较大的，需了解股权转让资金的用途； | C26: IPO/上市/新三板/重组/舞弊应对 | D26: √ | E26: √ | F26: √ | G26: √ | H26: √
A27: 11 | B27: 截止测试： （1）抽取资产负债表日前后若干张记账凭证，实施截止测试，存在异常迹象，应考虑是否有必要追加审计程序，对于重大跨期项目应作必要调整。 （2）从资产负债日后的银行对账单或付款凭证中若干项目进行测试，检查支持性文件；关注支持性文件的日期，检查费用是否记录于正确的会计期间，是否存在有未入账的负债。 | C27: 常规★ | G27: √ | I27: K8-6 /K8-7
A28: 12 | B28: 检查与销售费用有关的的记账凭证和相应的支持性证据以确定交易的真实性，是否按规定进行相应的会计处理和披露。 | C28: 常规★ | D28: √ | F28: √ | G28: √ | I28: K8-8
A29: 13 | B29: 考虑是否存在超出被审计单位正常经营活动的重大、异常交易等，根据评估的舞弊风险等因素增加的审计程序。 | C29: 舞弊应对/IPO/上市/新三板/重组
A30: 14 | B30: 检查销售费用是否已按企业会计准则或其他适用的规定在财务报表中做出恰当列报和披露。 | C30: 常规★ | H30: √ | I30: A1-1/A1-15 /A1-16

Sheet 审定表K8-1
A1: 致同会计师事务所
A2: 销售费用审定表（个别报表）
A3: =底稿目录!A2 -> 被审计单位： | D3: =底稿目录!A4 -> 编制人： | I3: =底稿目录!A5 -> 编制日期： | K3: 索引： | L3: =底稿目录!D5 -> K8-1
A4: =底稿目录!A3 -> 会计期间：202X年度 | D4: =底稿目录!A6 -> 复核人： | I4: =底稿目录!A7 -> 复核日期： | K4: 页次： | L4: 1
A5: 项目 | B5: 上期数 | F5: 本期数 | J5: 本期审定数与上期 审定数的比较 | L5: 原因分析
B6: 未审数 | C6: 账项调整 | D6: 重分类调整 | E6: 审定数 | F6: 未审数 | G6: 账项调整 | H6: 重分类调整 | I6: 审定数 | J6: 变动额 | K6: 变动率
A7: ='明细表K8-2'!A12 -> 专设销售机构的职工薪酬 | B7: =SUMIF('明细表K8-2'!$Z$12:$Z$24,$A7,'明细表K8-2'!$T$12:$T$24) -> 0 | C7: =SUMIF('明细表K8-2'!$Z$12:$Z$24,$A7,'明细表K8-2'!$U$12:$U$24) -> 0 | D7: =SUMIF('明细表K8-2'!$Z$12:$Z$24,$A7,'明细表K8-2'!$V$12:$V$24) -> 0 | E7: =B7+C7+D7 -> 0 | F7: =SUMIF('明细表K8-2'!$Z$12:$Z$24,$A7,'明细表K8-2'!$N$12:$N$24) -> 0 | G7: =SUMIF('明细表K8-2'!$Z$12:$Z$24,$A7,'明细表K8-2'!$O$12:$O$24) -> 0 | H7: =SUMIF('明细表K8-2'!$Z$12:$Z$24,$A7,'明细表K8-2'!$P$12:$P$24) -> 0 | I7: =F7+G7+H7 -> 0 | J7: =I7-E7 -> 0 | K7: =IF(AND(E7=0,I7=0),0,IF(AND(E7=0,I7>0),1,J7/E7)) -> 0
A8: ='明细表K8-2'!A13 -> 业务费 | B8: =SUMIF('明细表K8-2'!$Z$12:$Z$24,$A8,'明细表K8-2'!$T$12:$T$24) -> 0 | C8: =SUMIF('明细表K8-2'!$Z$12:$Z$24,$A8,'明细表K8-2'!$U$12:$U$24) -> 0 | D8: =SUMIF('明细表K8-2'!$Z$12:$Z$24,$A8,'明细表K8-2'!$V$12:$V$24) -> 0 | E8: =B8+C8+D8 -> 0 | F8: =SUMIF('明细表K8-2'!$Z$12:$Z$24,$A8,'明细表K8-2'!$N$12:$N$24) -> 0 | G8: =SUMIF('明细表K8-2'!$Z$12:$Z$24,$A8,'明细表K8-2'!$O$12:$O$24) -> 0 | H8: =SUMIF('明细表K8-2'!$Z$12:$Z$24,$A8,'明细表K8-2'!$P$12:$P$24) -> 0 | I8: =F8+G8+H8 -> 0 | J8: =I8-E8 -> 0 | K8: =IF(AND(E8=0,I8=0),0,IF(AND(E8=0,I8>0),1,J8/E8)) -> 0
A9: ='明细表K8-2'!A14 -> 折旧费 | B9: =SUMIF('明细表K8-2'!$Z$12:$Z$24,$A9,'明细表K8-2'!$T$12:$T$24) -> 0 | C9: =SUMIF('明细表K8-2'!$Z$12:$Z$24,$A9,'明细表K8-2'!$U$12:$U$24) -> 0 | D9: =SUMIF('明细表K8-2'!$Z$12:$Z$24,$A9,'明细表K8-2'!$V$12:$V$24) -> 0 | E9: =B9+C9+D9 -> 0 | F9: =SUMIF('明细表K8-2'!$Z$12:$Z$24,$A9,'明细表K8-2'!$N$12:$N$24) -> 0 | G9: =SUMIF('明细表K8-2'!$Z$12:$Z$24,$A9,'明细表K8-2'!$O$12:$O$24) -> 0 | H9: =SUMIF('明细表K8-2'!$Z$12:$Z$24,$A9,'明细表K8-2'!$P$12:$P$24) -> 0 | I9: =F9+G9+H9 -> 0 | J9: =I9-E9 -> 0 | K9: =IF(AND(E9=0,I9=0),0,IF(AND(E9=0,I9>0),1,J9/E9)) -> 0
A10: ='明细表K8-2'!A15 -> 保险费 | B10: =SUMIF('明细表K8-2'!$Z$12:$Z$24,$A10,'明细表K8-2'!$T$12:$T$24) -> 0 | C10: =SUMIF('明细表K8-2'!$Z$12:$Z$24,$A10,'明细表K8-2'!$U$12:$U$24) -> 0 | D10: =SUMIF('明细表K8-2'!$Z$12:$Z$24,$A10,'明细表K8-2'!$V$12:$V$24) -> 0 | E10: =B10+C10+D10 -> 0 | F10: =SUMIF('明细表K8-2'!$Z$12:$Z$24,$A10,'明细表K8-2'!$N$12:$N$24) -> 0 | G10: =SUMIF('明细表K8-2'!$Z$12:$Z$24,$A10,'明细表K8-2'!$O$12:$O$24) -> 0 | H10: =SUMIF('明细表K8-2'!$Z$12:$Z$24,$A10,'明细表K8-2'!$P$12:$P$24) -> 0 | I10: =F10+G10+H10 -> 0 | J10: =I10-E10 -> 0 | K10: =IF(AND(E10=0,I10=0),0,IF(AND(E10=0,I10>0),1,J10/E10)) -> 0
A11: ='明细表K8-2'!A16 -> 包装费 | B11: =SUMIF('明细表K8-2'!$Z$12:$Z$24,$A11,'明细表K8-2'!$T$12:$T$24) -> 0 | C11: =SUMIF('明细表K8-2'!$Z$12:$Z$24,$A11,'明细表K8-2'!$U$12:$U$24) -> 0 | D11: =SUMIF('明细表K8-2'!$Z$12:$Z$24,$A11,'明细表K8-2'!$V$12:$V$24) -> 0 | E11: =B11+C11+D11 -> 0 | F11: =SUMIF('明细表K8-2'!$Z$12:$Z$24,$A11,'明细表K8-2'!$N$12:$N$24) -> 0 | G11: =SUMIF('明细表K8-2'!$Z$12:$Z$24,$A11,'明细表K8-2'!$O$12:$O$24) -> 0 | H11: =SUMIF('明细表K8-2'!$Z$12:$Z$24,$A11,'明细表K8-2'!$P$12:$P$24) -> 0 | I11: =F11+G11+H11 -> 0 | J11: =I11-E11 -> 0 | K11: =IF(AND(E11=0,I11=0),0,IF(AND(E11=0,I11>0),1,J11/E11)) -> 0
A12: ='明细表K8-2'!A17 -> 展览费 | B12: =SUMIF('明细表K8-2'!$Z$12:$Z$24,$A12,'明细表K8-2'!$T$12:$T$24) -> 0 | C12: =SUMIF('明细表K8-2'!$Z$12:$Z$24,$A12,'明细表K8-2'!$U$12:$U$24) -> 0 | D12: =SUMIF('明细表K8-2'!$Z$12:$Z$24,$A12,'明细表K8-2'!$V$12:$V$24) -> 0 | E12: =B12+C12+D12 -> 0 | F12: =SUMIF('明细表K8-2'!$Z$12:$Z$24,$A12,'明细表K8-2'!$N$12:$N$24) -> 0 | G12: =SUMIF('明细表K8-2'!$Z$12:$Z$24,$A12,'明细表K8-2'!$O$12:$O$24) -> 0 | H12: =SUMIF('明细表K8-2'!$Z$12:$Z$24,$A12,'明细表K8-2'!$P$12:$P$24) -> 0 | I12: =F12+G12+H12 -> 0 | J12: =I12-E12 -> 0 | K12: =IF(AND(E12=0,I12=0),0,IF(AND(E12=0,I12>0),1,J12/E12)) -> 0
A13: ='明细表K8-2'!A18 -> 广告费 | B13: =SUMIF('明细表K8-2'!$Z$12:$Z$24,$A13,'明细表K8-2'!$T$12:$T$24) -> 0 | C13: =SUMIF('明细表K8-2'!$Z$12:$Z$24,$A13,'明细表K8-2'!$U$12:$U$24) -> 0 | D13: =SUMIF('明细表K8-2'!$Z$12:$Z$24,$A13,'明细表K8-2'!$V$12:$V$24) -> 0 | E13: =B13+C13+D13 -> 0 | F13: =SUMIF('明细表K8-2'!$Z$12:$Z$24,$A13,'明细表K8-2'!$N$12:$N$24) -> 0 | G13: =SUMIF('明细表K8-2'!$Z$12:$Z$24,$A13,'明细表K8-2'!$O$12:$O$24) -> 0 | H13: =SUMIF('明细表K8-2'!$Z$12:$Z$24,$A13,'明细表K8-2'!$P$12:$P$24) -> 0 | I13: =F13+G13+H13 -> 0 | J13: =I13-E13 -> 0 | K13: =IF(AND(E13=0,I13=0),0,IF(AND(E13=0,I13>0),1,J13/E13)) -> 0
A14: ='明细表K8-2'!A19 -> 商品维修费 | B14: =SUMIF('明细表K8-2'!$Z$12:$Z$24,$A14,'明细表K8-2'!$T$12:$T$24) -> 0 | C14: =SUMIF('明细表K8-2'!$Z$12:$Z$24,$A14,'明细表K8-2'!$U$12:$U$24) -> 0 | D14: =SUMIF('明细表K8-2'!$Z$12:$Z$24,$A14,'明细表K8-2'!$V$12:$V$24) -> 0 | E14: =B14+C14+D14 -> 0 | F14: =SUMIF('明细表K8-2'!$Z$12:$Z$24,$A14,'明细表K8-2'!$N$12:$N$24) -> 0 | G14: =SUMIF('明细表K8-2'!$Z$12:$Z$24,$A14,'明细表K8-2'!$O$12:$O$24) -> 0 | H14: =SUMIF('明细表K8-2'!$Z$12:$Z$24,$A14,'明细表K8-2'!$P$12:$P$24) -> 0 | I14: =F14+G14+H14 -> 0 | J14: =I14-E14 -> 0 | K14: =IF(AND(E14=0,I14=0),0,IF(AND(E14=0,I14>0),1,J14/E14)) -> 0
A15: ='明细表K8-2'!A20 -> 装卸费 | B15: =SUMIF('明细表K8-2'!$Z$12:$Z$24,$A15,'明细表K8-2'!$T$12:$T$24) -> 0 | C15: =SUMIF('明细表K8-2'!$Z$12:$Z$24,$A15,'明细表K8-2'!$U$12:$U$24) -> 0 | D15: =SUMIF('明细表K8-2'!$Z$12:$Z$24,$A15,'明细表K8-2'!$V$12:$V$24) -> 0 | E15: =B15+C15+D15 -> 0 | F15: =SUMIF('明细表K8-2'!$Z$12:$Z$24,$A15,'明细表K8-2'!$N$12:$N$24) -> 0 | G15: =SUMIF('明细表K8-2'!$Z$12:$Z$24,$A15,'明细表K8-2'!$O$12:$O$24) -> 0 | H15: =SUMIF('明细表K8-2'!$Z$12:$Z$24,$A15,'明细表K8-2'!$P$12:$P$24) -> 0 | I15: =F15+G15+H15 -> 0 | J15: =I15-E15 -> 0 | K15: =IF(AND(E15=0,I15=0),0,IF(AND(E15=0,I15>0),1,J15/E15)) -> 0
A16: ='明细表K8-2'!A21 -> …… | B16: =SUMIF('明细表K8-2'!$Z$12:$Z$24,$A16,'明细表K8-2'!$T$12:$T$24) -> 0 | C16: =SUMIF('明细表K8-2'!$Z$12:$Z$24,$A16,'明细表K8-2'!$U$12:$U$24) -> 0 | D16: =SUMIF('明细表K8-2'!$Z$12:$Z$24,$A16,'明细表K8-2'!$V$12:$V$24) -> 0 | E16: =B16+C16+D16 -> 0 | F16: =SUMIF('明细表K8-2'!$Z$12:$Z$24,$A16,'明细表K8-2'!$N$12:$N$24) -> 0 | G16: =SUMIF('明细表K8-2'!$Z$12:$Z$24,$A16,'明细表K8-2'!$O$12:$O$24) -> 0 | H16: =SUMIF('明细表K8-2'!$Z$12:$Z$24,$A16,'明细表K8-2'!$P$12:$P$24) -> 0 | I16: =F16+G16+H16 -> 0 | J16: =I16-E16 -> 0 | K16: =IF(AND(E16=0,I16=0),0,IF(AND(E16=0,I16>0),1,J16/E16)) -> 0
A17: 合计 | B17: =SUM(B7:B16) -> 0 | C17: =SUM(C7:C16) -> 0 | D17: =SUM(D7:D16) -> 0 | E17: =SUM(E7:E16) -> 0 | F17: =SUM(F7:F16) -> 0 | G17: =SUM(G7:G16) -> 0 | H17: =SUM(H7:H16) -> 0 | I17: =SUM(I7:I16) -> 0 | J17: =SUM(J7:J16) -> 0 | K17: =IF(AND(E17=0,I17=0),0,IF(AND(E17=0,I17>0),1,J17/E17)) -> 0
A18: TB数据：
A19: 差异： | B19: =B17-B18 -> 0 | C19: =C17-C18 -> 0 | D19: =D17-D18 -> 0 | E19: =E17-E18 -> 0 | F19: =F17-F18 -> 0 | G19: =G17-G18 -> 0 | H19: =H17-H18 -> 0 | I19: =I17-I18 -> 0
A20: 1.审计说明
A21: （1）销售费用本期较上期增加（负数为减少）：
A22: 主要原因（比例超过30%的）：
A24: （2）情况说明。
A26: 2.审计结论

Sheet 附注披露信息（上市公司）
A1: 致同会计师事务所
A2: 附注披露信息（上市公司）
A3: =底稿目录!A2 -> 被审计单位： | B3: =底稿目录!A4 -> 编制人： | C3: =底稿目录!A5 -> 编制日期： | D3: 索引： | E3: =底稿目录!D6 -> 0
A4: =底稿目录!A3 -> 会计期间：202X年度 | B4: =底稿目录!A6 -> 复核人： | C4: =底稿目录!A7 -> 复核日期： | D4: 页次：
A5: 销售费用(个别报表)
A6: 项 目 | B6: 本期发生额 | C6: 上期发生额
A7: ='审定表K8-1'!A7 -> 专设销售机构的职工薪酬 | B7: ='审定表K8-1'!I7 -> 0 | C7: ='审定表K8-1'!E7 -> 0
A8: ='审定表K8-1'!A8 -> 业务费 | B8: ='审定表K8-1'!I8 -> 0 | C8: ='审定表K8-1'!E8 -> 0
A9: ='审定表K8-1'!A9 -> 折旧费 | B9: ='审定表K8-1'!I9 -> 0 | C9: ='审定表K8-1'!E9 -> 0
A10: ='审定表K8-1'!A10 -> 保险费 | B10: ='审定表K8-1'!I10 -> 0 | C10: ='审定表K8-1'!E10 -> 0
A11: ='审定表K8-1'!A11 -> 包装费 | B11: ='审定表K8-1'!I11 -> 0 | C11: ='审定表K8-1'!E11 -> 0
A12: ='审定表K8-1'!A12 -> 展览费 | B12: ='审定表K8-1'!I12 -> 0 | C12: ='审定表K8-1'!E12 -> 0
A13: ='审定表K8-1'!A13 -> 广告费 | B13: ='审定表K8-1'!I13 -> 0 | C13: ='审定表K8-1'!E13 -> 0
A14: ='审定表K8-1'!A14 -> 商品维修费 | B14: ='审定表K8-1'!I14 -> 0 | C14: ='审定表K8-1'!E14 -> 0
A15: ='审定表K8-1'!A15 -> 装卸费 | B15: ='审定表K8-1'!I15 -> 0 | C15: ='审定表K8-1'!E15 -> 0
A16: ='审定表K8-1'!A16 -> …… | B16: ='审定表K8-1'!I16 -> 0 | C16: ='审定表K8-1'!E16 -> 0
A17: 合 计 | B17: =SUM(B7:B16) -> 0 | C17: =SUM(C7:C16) -> 0
A18: 销售费用(合并报表)
A19: 项 目 | B19: 本期发生额 | C19: 上期发生额
A30: 合 计 | B30: =SUM(B20:B29) -> 0 | C30: =SUM(C20:C29) -> 0

Sheet 附注披露信息（国企）
A1: 致同会计师事务所
A2: 附注披露信息(国企)
A3: =底稿目录!A2 -> 被审计单位： | B3: =底稿目录!A4 -> 编制人： | C3: =底稿目录!A5 -> 编制日期： | D3: 索引： | E3: =底稿目录!D7 -> 0
A4: =底稿目录!A3 -> 会计期间：202X年度 | B4: =底稿目录!A6 -> 复核人： | C4: =底稿目录!A7 -> 复核日期： | D4: 页次：
A5: 销售费用(个别报表)
A6: 项 目 | B6: 本期发生额 | C6: 上期发生额
A7: ='审定表K8-1'!A7 -> 专设销售机构的职工薪酬 | B7: ='审定表K8-1'!I7 -> 0 | C7: ='审定表K8-1'!E7 -> 0
A8: ='审定表K8-1'!A8 -> 业务费 | B8: ='审定表K8-1'!I8 -> 0 | C8: ='审定表K8-1'!E8 -> 0
A9: ='审定表K8-1'!A9 -> 折旧费 | B9: ='审定表K8-1'!I9 -> 0 | C9: ='审定表K8-1'!E9 -> 0
A10: ='审定表K8-1'!A10 -> 保险费 | B10: ='审定表K8-1'!I10 -> 0 | C10: ='审定表K8-1'!E10 -> 0
A11: ='审定表K8-1'!A11 -> 包装费 | B11: ='审定表K8-1'!I11 -> 0 | C11: ='审定表K8-1'!E11 -> 0
A12: ='审定表K8-1'!A12 -> 展览费 | B12: ='审定表K8-1'!I12 -> 0 | C12: ='审定表K8-1'!E12 -> 0
A13: ='审定表K8-1'!A13 -> 广告费 | B13: ='审定表K8-1'!I13 -> 0 | C13: ='审定表K8-1'!E13 -> 0
A14: ='审定表K8-1'!A14 -> 商品维修费 | B14: ='审定表K8-1'!I14 -> 0 | C14: ='审定表K8-1'!E14 -> 0
A15: ='审定表K8-1'!A15 -> 装卸费 | B15: ='审定表K8-1'!I15 -> 0 | C15: ='审定表K8-1'!E15 -> 0
A16: ='审定表K8-1'!A16 -> …… | B16: ='审定表K8-1'!I16 -> 0 | C16: ='审定表K8-1'!E16 -> 0
A17: 合 计 | B17: =SUM(B7:B16) -> 0 | C17: =SUM(C7:C16) -> 0
A18: 销售费用(合并报表)
A19: 项 目 | B19: 本期发生额 | C19: 上期发生额
A30: 合 计 | B30: =SUM(B20:B29) -> 0 | C30: =SUM(C20:C29) -> 0

Sheet 明细表K8-2
A1: 致同会计师事务所
A2: 销售费用明细表
A3: =底稿目录!A2 -> 被审计单位： | G3: =底稿目录!A4 -> 编制人： | Q3: =底稿目录!A5 -> 编制日期： | Z3: 索引号： | AA3: =底稿目录!D8 -> K8-2
A4: =底稿目录!A3 -> 会计期间：202X年度 | G4: =底稿目录!A6 -> 复核人： | Q4: =底稿目录!A7 -> 复核日期： | Z4: 页 次：
A5: 一、审计目标:
A6: 1.所有应当记录的销售费用均已记录，所有应当包括在财务报表中的相关披露均已包括; | I6: 2.与销售费用有关的金额及其他数据已恰当记录，相关披露已得到恰当计量和描述; | Q6: 3. 与销售费用有关的金额及其他数据已恰当记录，相关披露已得到恰当计量和描述
A7: 二、审计过程：
A8: 1.获取或编制各个月份期间费用主要构成情况，分析各月波动是否符合预期及与被审计单位的经营波动是否一致；
A9: 2.将相关明细项目发生额与资产负债表的相关科目的明细科目如应付职工薪酬、固定资产折旧、无形资产摊销、长期待摊费用摊销等核对；
A10: 3.检查销售费用各项费用的内容，防止应计入制造费用、销售费用、在建工程、营业外支出等科目的费用计入本科目。特别关注“其他”明细科目的内容；
A11: 项目 | B11: 1月 | C11: 2月 | D11: 3月 | E11: 4月 | F11: 5月 | G11: 6月 | H11: 7月 | I11: 8月 | J11: 9月 | K11: 10月 | L11: 11月 | M11: 12月 | N11: 本期未审合计 | O11: 账项调整 | P11: 重分类调整 | Q11: 本期审定金额 | R11: 各项目占比 | S11: 与相关科目勾稽（索引） | T11: 上期未审金额 | U11: 账项调整 | V11: 重分类调整 | W11: 上期审定金额 | X11: 上期各项目占比 | Y11: 各项目占比变动 | Z11: 个别报表下的重分类 | AA11: 合并报表下的重分类
A12: 专设销售机构的职工薪酬 | N12: =SUM(B12:M12) -> 0 | Q12: =N12+O12+P12 -> 0 | R12: =IF(Q12=0,0,Q12/$Q$25) -> 0 | S12: L1-XXX | W12: =T12+U12+V12 -> 0 | X12: =IF($W$25=0,0,W12/$W$25) -> 0 | Y12: =IFERROR((Q12-W12)/W12,0) -> 0 | Z12: 专设销售机构的职工薪酬 | AA12: 专设销售机构的职工薪酬
A13: 业务费 | N13: =SUM(B13:M13) -> 0 | Q13: =N13+O13+P13 -> 0 | R13: =IF(Q13=0,0,Q13/$Q$25) -> 0 | W13: =T13+U13+V13 -> 0 | X13: =IF($W$25=0,0,W13/$W$25) -> 0 | Y13: =IFERROR((Q13-W13)/W13,0) -> 0
A14: 折旧费 | N14: =SUM(B14:M14) -> 0 | Q14: =N14+O14+P14 -> 0 | R14: =IF(Q14=0,0,Q14/$Q$25) -> 0 | S14: J1-XXXX | W14: =T14+U14+V14 -> 0 | X14: =IF($W$25=0,0,W14/$W$25) -> 0 | Y14: =IFERROR((Q14-W14)/W14,0) -> 0
A15: 保险费 | N15: =SUM(B15:M15) -> 0 | Q15: =N15+O15+P15 -> 0 | R15: =IF(Q15=0,0,Q15/$Q$25) -> 0 | W15: =T15+U15+V15 -> 0 | X15: =IF($W$25=0,0,W15/$W$25) -> 0 | Y15: =IFERROR((Q15-W15)/W15,0) -> 0
A16: 包装费 | N16: =SUM(B16:M16) -> 0 | Q16: =N16+O16+P16 -> 0 | R16: =IF(Q16=0,0,Q16/$Q$25) -> 0 | W16: =T16+U16+V16 -> 0 | X16: =IF($W$25=0,0,W16/$W$25) -> 0 | Y16: =IFERROR((Q16-W16)/W16,0) -> 0
A17: 展览费 | N17: =SUM(B17:M17) -> 0 | Q17: =N17+O17+P17 -> 0 | R17: =IF(Q17=0,0,Q17/$Q$25) -> 0 | W17: =T17+U17+V17 -> 0 | X17: =IF($W$25=0,0,W17/$W$25) -> 0 | Y17: =IFERROR((Q17-W17)/W17,0) -> 0
A18: 广告费 | N18: =SUM(B18:M18) -> 0 | Q18: =N18+O18+P18 -> 0 | R18: =IF(Q18=0,0,Q18/$Q$25) -> 0 | W18: =T18+U18+V18 -> 0 | X18: =IF($W$25=0,0,W18/$W$25) -> 0 | Y18: =IFERROR((Q18-W18)/W18,0) -> 0
A19: 商品维修费 | N19: =SUM(B19:M19) -> 0 | Q19: =N19+O19+P19 -> 0 | R19: =IF(Q19=0,0,Q19/$Q$25) -> 0 | W19: =T19+U19+V19 -> 0 | X19: =IF($W$25=0,0,W19/$W$25) -> 0 | Y19: =IFERROR((Q19-W19)/W19,0) -> 0
A20: 装卸费 | N20: =SUM(B20:M20) -> 0 | Q20: =N20+O20+P20 -> 0 | R20: =IF(Q20=0,0,Q20/$Q$25) -> 0 | W20: =T20+U20+V20 -> 0 | X20: =IF($W$25=0,0,W20/$W$25) -> 0 | Y20: =IFERROR((Q20-W20)/W20,0) -> 0
A21: …… | N21: =SUM(B21:M21) -> 0 | Q21: =N21+O21+P21 -> 0 | R21: =IF(Q21=0,0,Q21/$Q$25) -> 0 | W21: =T21+U21+V21 -> 0 | X21: =IF($W$25=0,0,W21/$W$25) -> 0 | Y21: =IFERROR((Q21-W21)/W21,0) -> 0
N22: =SUM(B22:M22) -> 0 | Q22: =N22+O22+P22 -> 0 | R22: =IF(Q22=0,0,Q22/$Q$25) -> 0 | W22: =T22+U22+V22 -> 0 | X22: =IF($W$25=0,0,W22/$W$25) -> 0 | Y22: =IFERROR((Q22-W22)/W22,0) -> 0
N23: =SUM(B23:M23) -> 0 | Q23: =N23+O23+P23 -> 0 | R23: =IF(Q23=0,0,Q23/$Q$25) -> 0 | W23: =T23+U23+V23 -> 0 | X23: =IF($W$25=0,0,W23/$W$25) -> 0 | Y23: =IFERROR((Q23-W23)/W23,0) -> 0
N24: =SUM(B24:M24) -> 0 | Q24: =N24+O24+P24 -> 0 | R24: =IF(Q24=0,0,Q24/$Q$25) -> 0 | W24: =T24+U24+V24 -> 0 | X24: =IF($W$25=0,0,W24/$W$25) -> 0 | Y24: =IFERROR((Q24-W24)/W24,0) -> 0
A25: 合计 | B25: =SUM(B12:B24) -> 0 | C25: =SUM(C12:C24) -> 0 | D25: =SUM(D12:D24) -> 0 | E25: =SUM(E12:E24) -> 0 | F25: =SUM(F12:F24) -> 0 | G25: =SUM(G12:G24) -> 0 | H25: =SUM(H12:H24) -> 0 | I25: =SUM(I12:I24) -> 0 | ... Q25: =SUM(Q12:Q24) -> 0 | R25: =IF(Q25=0,0,Q25/$Q$25) -> 0 | T25: =SUM(T12:T24) -> 0 | U25: =SUM(U12:U24) -> 0 | V25: =SUM(V12:V24) -> 0 | W25: =SUM(W12:W24) -> 0 | X25: =SUM(X12:X24) -> 0
A26: 各月比例 | B26: =IF($N$25=0,0,B25/$N$25) -> 0 | C26: =IF($N$25=0,0,C25/$N$25) -> 0 | D26: =IF($N$25=0,0,D25/$N$25) -> 0 | E26: =IF($N$25=0,0,E25/$N$25) -> 0 | F26: =IF($N$25=0,0,F25/$N$25) -> 0 | G26: =IF($N$25=0,0,G25/$N$25) -> 0 | H26: =IF($N$25=0,0,H25/$N$25) -> 0 | I26: =IF($N$25=0,0,I25/$N$25) -> 0 | ... M26: =IF($N$25=0,0,M25/$N$25) -> 0
A27: 三、审计说明：
A28: 1.XX费用较上期增长XX%，本期大幅增加原因……
A29: 2.XX月XX费用发生额XX，占全年XX%，占比较大的原因……
A30: 3.XX费用测算如下：
A31: 项目 | B31: 计提依据 | C31: 计提比例 | D31: 应计提金额 | E31: 账面计提金额 | F31: 差异金额 | G31: 差异原因 | H31: 是否调整
A32: XX费用 | D32: =B32*C32 -> 0 | F32: =D32-E32 -> 0
A33: XX费用 | D33: =B33*C33 -> 0 | F33: =D33-E33 -> 0
A35: 四、审计结论：
A38: 提示：
A39: 1.本科目核算企业销售商品和材料、提供劳务的过程中发生的各种费用，包括保险费、包装费、展览费和广告费等以及为销售本企业商品而专设的销售机构(含销售网点、售后服务网点等)的职工薪酬、业务费、折旧费等经营费用；
A40: 2.为履行与客户的合同而发生的成本计入营业成本，例如产品的控制权转移给客户之前发生的运输费用、保险费等；
A41: 3.不符合固定资产资本化后续支出条件的固定资产日常修理费用，在发生时按照受益对象计入当期损益或计入相关资产的成本。与存货的生产和加工相关的固定资产日常修理费用按照存货成本确定原则进行处理，行政管理部门、企业专设的销售机构等发生的固定资产日常修理费用按照功能分类计入管理费用或销售费用。
A42: 4.关注：
A43: （1）关注是否存在关联方、潜在关联方代为承担成本、代垫费用的情形。
...

Sheet 调整分录汇总K8-3
A1: 致同会计师事务所
A2: 销售费用调整分录汇总表
A3: =底稿目录!A2 -> 被审计单位： | C3: =底稿目录!A4 -> 编制人： | F3: =底稿目录!A5 -> 编制日期： | I3: 索引号： | J3: =底稿目录!D9 -> K8-3
A4: =底稿目录!A3 -> 会计期间：202X年度 | C4: =底稿目录!A6 -> 复核人： | F4: =底稿目录!A7 -> 复核日期： | I4: 页次：
A5: 调整事项说明 | B5: 类别（报表调整/账项调整/其他） | C5: 报表项目 | D5: 科目名称 | E5: 附注项目 | F5: …… | G5: 借方调整金额 | H5: 贷方调整金额 | I5: 索引 | J5: 备注
A21: 提示：本底稿适用于调整分录较多、较复杂的项目，且仅列示与本报表项目相关的审计调整。项目组可根据项目实际情况选择是否使用该底稿。

Sheet 实质性分析K8-4
A1: 致同会计师事务所
A2: 实质性分析
A3: =底稿目录!A2 -> 被审计单位： | C3: =底稿目录!A4 -> 编制人： | F3: =底稿目录!A5 -> 编制日期： | I3: 索引号： | J3: =底稿目录!D10 -> K8-4
A4: =底稿目录!A3 -> 会计期间：202X年度 | C4: =底稿目录!A6 -> 复核人： | F4: =底稿目录!A7 -> 复核日期： | I4: 页 次：
A5: 一、审计目标:
A6: 1.所有应当记录的销售费用均已记录，所有应当包括在财务报表中的相关披露均已包括; 2.与销售费用有关的金额及其他数据已恰当记录，相关披露已得到恰当计量和描述; | Q6: 3. 与销售费用有关的金额及其他数据已恰当记录，相关披露已得到恰当计量和描述
A7: 3.与销售费用有关的金额及其他数据已恰当记录，相关披露已得到恰当计量和描述;
A8: 二、审计过程：
A9: （一）销售费用构成分析表
A10: 销售费用项目 | B10: 本期合计 | C10: 结构比 | D10: 占主营业务收入比率 | E10: 上年同期 | F10: 结构比 | G10: 占主营业务收入比率 | H10: 增长比例 | I10: 占主营业务收入比率变动 | J10: 变动分析
A11: ='明细表K8-2'!A12 -> 专设销售机构的职工薪酬 | B11: ='明细表K8-2'!Q12 -> 0 | C11: =IF(B11=0,0,B11/$B$21) -> 0 | D11: =IF(B11=0,0,B11/$B$22) -> 0 | E11: ='明细表K8-2'!W12 -> 0 | F11: =IF(E11=0,0,E11/$E$21) -> 0 | G11: =IF(E11=0,0,E11/$E$22) -> 0 | H11: =IF(AND(E11=0,B11>0),1,IF(AND(E11=0,B11=0),0,(B11-E11)/E11)) -> 0 | I11: =D11-G11 -> 0
A12: ='明细表K8-2'!A13 -> 业务费 | B12: ='明细表K8-2'!Q13 -> 0 | C12: =IF(B12=0,0,B12/$B$21) -> 0 | D12: =IF(B12=0,0,B12/$B$22) -> 0 | E12: ='明细表K8-2'!W13 -> 0 | F12: =IF(E12=0,0,E12/$E$21) -> 0 | G12: =IF(E12=0,0,E12/$E$22) -> 0 | H12: =IF(AND(E12=0,B12>0),1,IF(AND(E12=0,B12=0),0,(B12-E12)/E12)) -> 0 | I12: =D12-G12 -> 0
A13: ='明细表K8-2'!A14 -> 折旧费 | B13: ='明细表K8-2'!Q14 -> 0 | C13: =IF(B13=0,0,B13/$B$21) -> 0 | D13: =IF(B13=0,0,B13/$B$22) -> 0 | E13: ='明细表K8-2'!W14 -> 0 | F13: =IF(E13=0,0,E13/$E$21) -> 0 | G13: =IF(E13=0,0,E13/$E$22) -> 0 | H13: =IF(AND(E13=0,B13>0),1,IF(AND(E13=0,B13=0),0,(B13-E13)/E13)) -> 0 | I13: =D13-G13 -> 0
A14: ='明细表K8-2'!A15 -> 保险费 | B14: ='明细表K8-2'!Q15 -> 0 | C14: =IF(B14=0,0,B14/$B$21) -> 0 | D14: =IF(B14=0,0,B14/$B$22) -> 0 | E14: ='明细表K8-2'!W15 -> 0 | F14: =IF(E14=0,0,E14/$E$21) -> 0 | G14: =IF(E14=0,0,E14/$E$22) -> 0 | H14: =IF(AND(E14=0,B14>0),1,IF(AND(E14=0,B14=0),0,(B14-E14)/E14)) -> 0 | I14: =D14-G14 -> 0
A15: ='明细表K8-2'!A16 -> 包装费 | B15: ='明细表K8-2'!Q16 -> 0 | C15: =IF(B15=0,0,B15/$B$21) -> 0 | D15: =IF(B15=0,0,B15/$B$22) -> 0 | E15: ='明细表K8-2'!W16 -> 0 | F15: =IF(E15=0,0,E15/$E$21) -> 0 | G15: =IF(E15=0,0,E15/$E$22) -> 0 | H15: =IF(AND(E15=0,B15>0),1,IF(AND(E15=0,B15=0),0,(B15-E15)/E15)) -> 0 | I15: =D15-G15 -> 0
A16: ='明细表K8-2'!A17 -> 展览费 | B16: ='明细表K8-2'!Q17 -> 0 | C16: =IF(B16=0,0,B16/$B$21) -> 0 | D16: =IF(B16=0,0,B16/$B$22) -> 0 | E16: ='明细表K8-2'!W17 -> 0 | F16: =IF(E16=0,0,E16/$E$21) -> 0 | G16: =IF(E16=0,0,E16/$E$22) -> 0 | H16: =IF(AND(E16=0,B16>0),1,IF(AND(E16=0,B16=0),0,(B16-E16)/E16)) -> 0 | I16: =D16-G16 -> 0
A17: ='明细表K8-2'!A18 -> 广告费 | B17: ='明细表K8-2'!Q18 -> 0 | C17: =IF(B17=0,0,B17/$B$21) -> 0 | D17: =IF(B17=0,0,B17/$B$22) -> 0 | E17: ='明细表K8-2'!W18 -> 0 | F17: =IF(E17=0,0,E17/$E$21) -> 0 | G17: =IF(E17=0,0,E17/$E$22) -> 0 | H17: =IF(AND(E17=0,B17>0),1,IF(AND(E17=0,B17=0),0,(B17-E17)/E17)) -> 0 | I17: =D17-G17 -> 0
A18: ='明细表K8-2'!A19 -> 商品维修费 | B18: ='明细表K8-2'!Q19 -> 0 | C18: =IF(B18=0,0,B18/$B$21) -> 0 | D18: =IF(B18=0,0,B18/$B$22) -> 0 | E18: ='明细表K8-2'!W19 -> 0 | F18: =IF(E18=0,0,E18/$E$21) -> 0 | G18: =IF(E18=0,0,E18/$E$22) -> 0 | H18: =IF(AND(E18=0,B18>0),1,IF(AND(E18=0,B18=0),0,(B18-E18)/E18)) -> 0 | I18: =D18-G18 -> 0
A19: ='明细表K8-2'!A20 -> 装卸费 | B19: ='明细表K8-2'!Q20 -> 0 | C19: =IF(B19=0,0,B19/$B$21) -> 0 | D19: =IF(B19=0,0,B19/$B$22) -> 0 | E19: ='明细表K8-2'!W20 -> 0 | F19: =IF(E19=0,0,E19/$E$21) -> 0 | G19: =IF(E19=0,0,E19/$E$22) -> 0 | H19: =IF(AND(E19=0,B19>0),1,IF(AND(E19=0,B19=0),0,(B19-E19)/E19)) -> 0 | I19: =D19-G19 -> 0
A20: ='明细表K8-2'!A21 -> …… | B20: ='明细表K8-2'!Q21 -> 0 | C20: =IF(B20=0,0,B20/$B$21) -> 0 | D20: =IF(B20=0,0,B20/$B$22) -> 0 | E20: ='明细表K8-2'!W21 -> 0 | F20: =IF(E20=0,0,E20/$E$21) -> 0 | G20: =IF(E20=0,0,E20/$E$22) -> 0 | H20: =IF(AND(E20=0,B20>0),1,IF(AND(E20=0,B20=0),0,(B20-E20)/E20)) -> 0 | I20: =D20-G20 -> 0
A21: 合计 | B21: =SUM(B11:B20) -> 0 | C21: =IF(B21=0,0,B21/$B$21) -> 0 | D21: =IF(B21=0,0,B21/$B$22) -> 0 | E21: =SUM(E11:E20) -> 0 | F21: =IF(E21=0,0,E21/$E$21) -> 0 | G21: =IF(E21=0,0,E21/$E$22) -> 0 | H21: =IF(AND(E21=0,B21>0),1,IF(AND(E21=0,B21=0),0,(B21-E21)/E21)) -> 0 | I21: =D21-G21 -> 0
A22: 主营业务收入 | H22: =IF(AND(E22=0,B22>0),1,IF(AND(E22=0,B22=0),0,(B22-E22)/E22)) -> 0
A23: 销售费用占主营业务收入比率 | B23: =B21/B22 -> #DIV/0! | E23: =E21/E22 -> #DIV/0!
A24: （二）销售费用与预算及其他非财务数据对比分析表
A25: 项目 | B25: 本期发生额 | C25: 预算金额 | D25: …… | E25: 占比
A26: 销售费用 | B26: =B21 -> 0 | E26: =B26/C26 -> #DIV/0!
A27: （三）销售费用指标分析表（与同行业数据比较）
A28: 指标 | B28: 本期 | C28: 行业公司A | D28: 行业公司B | E28: 行业公司C | F28: 比较分析
A29: 销售费用占主营业务收入比率 | B29: =B23 -> #DIV/0!
A30: 三、审计说明：
A31: 1.费用各项目近两年比重变动较大的原因： | D31: 2.与上年同期数据相比，费用指标异常的原因：
A32: a. | D32: a.
A33: b. | D33: b.
A34: 3.与同行业数据相比，费用指标异常的原因： | D34: 4.与预算金额及其他非财务数据相比，费用指标异常的原因：
A35: a. | D35: a.
A36: b. | D36: b.
A38: 四、审计结论：

Sheet 合同检查表K8-5
A1: 致同会计师事务所
A2: 销售费用合同检查表-此表未改完
A3: =底稿目录!A2 -> 被审计单位： | H3: =底稿目录!A4 -> 编制人： | M3: =底稿目录!A5 -> 编制日期： | P3: 索引号： | Q3: =底稿目录!D11 -> K8-5
A4: =底稿目录!A3 -> 会计期间：202X年度 | H4: =底稿目录!A6 -> 复核人： | M4: =底稿目录!A7 -> 复核日期： | P4: 页 次：
A5: 一、审计目标:
A6: 1.所有应当记录的销售费用均已记录，所有应当包括在财务报表中的相关披露均已包括; 2.与销售费用有关的金额及其他数据已恰当记录，相关披露已得到恰当计量和描述;
A7: 3.与销售费用有关的金额及其他数据已恰当记录，相关披露已得到恰当计量和描述； 4. 销售费用已记录于正确的会计期间
A8: 二、审计过程：
B9: 摊销期初： | C9: 45658 | D9: 摊销期末： | E9: 46022
A10: 项目 | B10: 对方单位 | C10: 合同/协议内容 | D10: 合同/协议金额 | E10: 实际开票方 | F10: 支付条件 | G10: 支付时间 | H10: 合同/协议开始日期 | I10: 合同/协议结束日期 | J10: 合同总月份 | K10: 本期应计月份 | L10: 本期应计损益 | M10: 本期已计损益 | N10: 差异 | O10: 合同索引 | P10: 凭证检查索引 | Q10: 审计结论
A11: 律师费 | J11: =IF(OR($E$9="",H11="",$C$9="",I11=""),0,DATEDIF(H11, I11, "m")+1) -> 0 | K11: =IF(OR($E$9="",H11="",$C$9="",I11=""),0,IF(H11>$E$9,0,IF(H11=0,0,IF(AND(H11<$C$9,I11>$E$9),VALUE(DATEDIF($C$9,$E$9,"m")+1),IF(AND(H11<$C$9,I11<=$E$9),VALUE(DATEDIF($C$9,I11,"m")+1),IF(AND(H11>=$C$9,I11>$E$9),VALUE(DATEDIF(H11,$E$9,"m")+1),IF(AND(H11>=$C$9,I11<=$E$9),VALUE(DATEDIF(H11,I11,"m")+1),))))))) -> 0 | L11: =IF(K11=0,0,K11/J11*D11) -> 0 | N11: =L11-M11 -> 0
A12: 咨询费 | J12: =IF(OR($E$9="",H12="",$C$9="",I12=""),0,DATEDIF(H12, I12, "m")+1) -> 0 | K12: =IF(OR($E$9="",H12="",$C$9="",I12=""),0,IF(H12>$E$9,0,IF(H12=0,0,IF(AND(H12<$C$9,I12>$E$9),VALUE(DATEDIF($C$9,$E$9,"m")+1),IF(AND(H12<$C$9,I12<=$E$9),VALUE(DATEDIF($C$9,I12,"m")+1),IF(AND(H12>=$C$9,I12>$E$9),VALUE(DATEDIF(H12,$E$9,"m")+1),IF(AND(H12>=$C$9,I12<=$E$9),VALUE(DATEDIF(H12,I12,"m")+1),))))))) -> 0 | L12: =IF(K12=0,0,K12/J12*D12) -> 0 | N12: =L12-M12 -> 0
A13: 租赁费 | J13: =IF(OR($E$9="",H13="",$C$9="",I13=""),0,DATEDIF(H13, I13, "m")+1) -> 0 | K13: =IF(OR($E$9="",H13="",$C$9="",I13=""),0,IF(H13>$E$9,0,IF(H13=0,0,IF(AND(H13<$C$9,I13>$E$9),VALUE(DATEDIF($C$9,$E$9,"m")+1),IF(AND(H13<$C$9,I13<=$E$9),VALUE(DATEDIF($C$9,I13,"m")+1),IF(AND(H13>=$C$9,I13>$E$9),VALUE(DATEDIF(H13,$E$9,"m")+1),IF(AND(H13>=$C$9,I13<=$E$9),VALUE(DATEDIF(H13,I13,"m")+1),))))))) -> 0 | L13: =IF(K13=0,0,K13/J13*D13) -> 0 | N13: =L13-M13 -> 0
A14: 修理费 | J14: =IF(OR($E$9="",H14="",$C$9="",I14=""),0,DATEDIF(H14, I14, "m")+1) -> 0 | K14: =IF(OR($E$9="",H14="",$C$9="",I14=""),0,IF(H14>$E$9,0,IF(H14=0,0,IF(AND(H14<$C$9,I14>$E$9),VALUE(DATEDIF($C$9,$E$9,"m")+1),IF(AND(H14<$C$9,I14<=$E$9),VALUE(DATEDIF($C$9,I14,"m")+1),IF(AND(H14>=$C$9,I14>$E$9),VALUE(DATEDIF(H14,$E$9,"m")+1),IF(AND(H14>=$C$9,I14<=$E$9),VALUE(DATEDIF(H14,I14,"m")+1),))))))) -> 0 | L14: =IF(K14=0,0,K14/J14*D14) -> 0 | N14: =L14-M14 -> 0
A15: 保险费 | J15: =IF(OR($E$9="",H15="",$C$9="",I15=""),0,DATEDIF(H15, I15, "m")+1) -> 0 | K15: =IF(OR($E$9="",H15="",$C$9="",I15=""),0,IF(H15>$E$9,0,IF(H15=0,0,IF(AND(H15<$C$9,I15>$E$9),VALUE(DATEDIF($C$9,$E$9,"m")+1),IF(AND(H15<$C$9,I15<=$E$9),VALUE(DATEDIF($C$9,I15,"m")+1),IF(AND(H15>=$C$9,I15>$E$9),VALUE(DATEDIF(H15,$E$9,"m")+1),IF(AND(H15>=$C$9,I15<=$E$9),VALUE(DATEDIF(H15,I15,"m")+1),))))))) -> 0 | L15: =IF(K15=0,0,K15/J15*D15) -> 0 | N15: =L15-M15 -> 0
A16: 物业费 | J16: =IF(OR($E$9="",H16="",$C$9="",I16=""),0,DATEDIF(H16, I16, "m")+1) -> 0 | K16: =IF(OR($E$9="",H16="",$C$9="",I16=""),0,IF(H16>$E$9,0,IF(H16=0,0,IF(AND(H16<$C$9,I16>$E$9),VALUE(DATEDIF($C$9,$E$9,"m")+1),IF(AND(H16<$C$9,I16<=$E$9),VALUE(DATEDIF($C$9,I16,"m")+1),IF(AND(H16>=$C$9,I16>$E$9),VALUE(DATEDIF(H16,$E$9,"m")+1),IF(AND(H16>=$C$9,I16<=$E$9),VALUE(DATEDIF(H16,I16,"m")+1),))))))) -> 0 | L16: =IF(K16=0,0,K16/J16*D16) -> 0 | N16: =L16-M16 -> 0
A17: … | J17: =IF(OR($E$9="",H17="",$C$9="",I17=""),0,DATEDIF(H17, I17, "m")+1) -> 0 | K17: =IF(OR($E$9="",H17="",$C$9="",I17=""),0,IF(H17>$E$9,0,IF(H17=0,0,IF(AND(H17<$C$9,I17>$E$9),VALUE(DATEDIF($C$9,$E$9,"m")+1),IF(AND(H17<$C$9,I17<=$E$9),VALUE(DATEDIF($C$9,I17,"m")+1),IF(AND(H17>=$C$9,I17>$E$9),VALUE(DATEDIF(H17,$E$9,"m")+1),IF(AND(H17>=$C$9,I17<=$E$9),VALUE(DATEDIF(H17,I17,"m")+1),))))))) -> 0 | L17: =IF(K17=0,0,K17/J17*D17) -> 0 | N17: =L17-M17 -> 0
J18: =IF(OR($E$9="",H18="",$C$9="",I18=""),0,DATEDIF(H18, I18, "m")+1) -> 0 | K18: =IF(OR($E$9="",H18="",$C$9="",I18=""),0,IF(H18>$E$9,0,IF(H18=0,0,IF(AND(H18<$C$9,I18>$E$9),VALUE(DATEDIF($C$9,$E$9,"m")+1),IF(AND(H18<$C$9,I18<=$E$9),VALUE(DATEDIF($C$9,I18,"m")+1),IF(AND(H18>=$C$9,I18>$E$9),VALUE(DATEDIF(H18,$E$9,"m")+1),IF(AND(H18>=$C$9,I18<=$E$9),VALUE(DATEDIF(H18,I18,"m")+1),))))))) -> 0 | L18: =IF(K18=0,0,K18/J18*D18) -> 0 | N18: =L18-M18 -> 0
J19: =IF(OR($E$9="",H19="",$C$9="",I19=""),0,DATEDIF(H19, I19, "m")+1) -> 0 | K19: =IF(OR($E$9="",H19="",$C$9="",I19=""),0,IF(H19>$E$9,0,IF(H19=0,0,IF(AND(H19<$C$9,I19>$E$9),VALUE(DATEDIF($C$9,$E$9,"m")+1),IF(AND(H19<$C$9,I19<=$E$9),VALUE(DATEDIF($C$9,I19,"m")+1),IF(AND(H19>=$C$9,I19>$E$9),VALUE(DATEDIF(H19,$E$9,"m")+1),IF(AND(H19>=$C$9,I19<=$E$9),VALUE(DATEDIF(H19,I19,"m")+1),))))))) -> 0 | L19: =IF(K19=0,0,K19/J19*D19) -> 0 | N19: =L19-M19 -> 0
J20: =IF(OR($E$9="",H20="",$C$9="",I20=""),0,DATEDIF(H20, I20, "m")+1) -> 0 | K20: =IF(OR($E$9="",H20="",$C$9="",I20=""),0,IF(H20>$E$9,0,IF(H20=0,0,IF(AND(H20<$C$9,I20>$E$9),VALUE(DATEDIF($C$9,$E$9,"m")+1),IF(AND(H20<$C$9,I20<=$E$9),VALUE(DATEDIF($C$9,I20,"m")+1),IF(AND(H20>=$C$9,I20>$E$9),VALUE(DATEDIF(H20,$E$9,"m")+1),IF(AND(H20>=$C$9,I20<=$E$9),VALUE(DATEDIF(H20,I20,"m")+1),))))))) -> 0 | L20: =IF(K20=0,0,K20/J20*D20) -> 0 | N20: =L20-M20 -> 0
A21: 三、审计说明：
A22: 1.已对XXX进行检查….
A23: 2.XXX
A26: 四、审计结论：
A29: 检查广告费、宣传费合同、投放计划等条款，检查支出是否合理，说明核算的准确性和完整性，是否存在推迟确认广告费用的情形。

Sheet 截止性测试(从记账凭证至原始凭证）K8-6
A1: 致同会计师事务所
A2: 销售费用截止性测试(从记账凭证至原始凭证）
A3: =底稿目录!A2 -> 被审计单位： | C3: =底稿目录!A4 -> 编制人： | G3: =底稿目录!A5 -> 编制日期： | J3: 索引号： | K3: =底稿目录!D12 -> K8-6
A4: =底稿目录!A3 -> 会计期间：202X年度 | C4: =底稿目录!A6 -> 复核人： | G4: =底稿目录!A7 -> 复核日期： | J4: 页 次：
A5: 一、审计目标：
A6: 确认销售费用已记录于正确的会计期间。
A7: 二、样本选取标准与规模：
A8: 1.抽取资产负债表日前后（____）天的（____）张记账凭证，实施截止性测试，评价费用是否被记录于正确的会计期间；
A9: 2.对于首次承接的客户，执行前期期末的截止性测试。（适用于首次承接）
A10: 提示：如果存在跨期舞弊风险或者所检查样本中发现有跨期的，应扩大测试期间和样本，甚至可以考虑将截止测试期间延长至审计报告日。同时考虑是否存在内控缺陷。
A11: 三、测试：
A12: 序号 | B12: 记账凭证 | G12: 支出凭单 | J12: 是否跨期 | K12: 跨期金额
B13: 日期 | C13: 凭证编号 | D13: 业务内容 | E13: 对方科目 | F13: 金额 | G13: 凭单编号 | H13: 凭单日期 | I13: 金额
A14: 1
A15: 2
A16: 3
A17: 4
A18: 5
A19: 6
A20: 7
A21: 8
A22: 9
A23: 10
A24: ……
A25: ——————截止日期：202X年12月31日——————
A26: 1
A27: 2
A28: 3
A29: 4
A30: 5
A31: 6
A32: 7
A33: 8
A34: 9
A35: 10
A36: ……
A37: 四、审计说明：
A40: 五、审计结论

Sheet 截止性测试（从原始凭证至记账凭证）K8-7
A1: 致同会计师事务所
A2: 销售费用截止性测试（从原始凭证至记账凭证）
A3: =底稿目录!A2 -> 被审计单位： | E3: =底稿目录!A4 -> 编制人： | H3: =底稿目录!A5 -> 编制日期： | J3: 索引号： | K3: =底稿目录!D12 -> K8-6
A4: =底稿目录!A3 -> 会计期间：202X年度 | E4: =底稿目录!A6 -> 复核人： | H4: =底稿目录!A7 -> 复核日期： | J4: 页 次：
A5: 一、审计目标：
A6: 确认销售费用已记录于正确的会计期间。
A7: 二、样本选取标准与规模：
A8: 1.选取资产负债日后（____）天的的银行对账单或付款凭证、支出凭单（____）张，检查支持性文件，关注凭单的日期，检查费用是否记录于正确的会计期间，是否存在有未入帐的负债；
A9: 2.对于首次承接的客户，执行前期期末的截止性测试；（适用于首次承接）
A10: 提示：如果存在跨期舞弊风险或者所检查样本中发现有跨期的，应扩大测试期间和样本，甚至可以考虑将截止测试期间延长至审计报告日。同时考虑是否存在内控缺陷。
A11: 三、测试：
A12: 序号 | B12: 支出凭单 | E12: 记账凭证 | J12: 是否跨期 | K12: 跨期金额
B13: 凭单编号 | C13: 凭单日期 | D13: 金额 | E13: 日期 | F13: 凭证编号 | G13: 业务内容 | H13: 对方科目 | I13: 金额
A14: 1
A15: 2
A16: 3
A17: 4
A18: 5
A19: 6
A20: 7
A21: 8
A22: 9
A23: 10
A24: ……
A25: ——————截止日期：202X年12月31日——————
A26: 1
A27: 2
A28: 3
A29: 4
A30: 5
A31: 6
A32: 7
A33: 8
A34: 9
A35: 10
A36: ……
A37: 四、审计说明：
A40: 五、审计结论

Sheet 销售费用检查表K8-8
A1: 致同会计师事务所
A2: 销售费用检查表
A3: =底稿目录!A2 -> 被审计单位： | F3: =底稿目录!A4 -> 编制人： | I3: =底稿目录!A5 -> 编制日期： | P3: 索引号： | Q3: =底稿目录!D14 -> K8-8
A4: =底稿目录!A3 -> 会计期间：202X年度 | F4: =底稿目录!A6 -> 复核人： | I4: =底稿目录!A7 -> 复核日期： | P4: 页 次：
A5: 一、测试目标：
A6: 1.所有应当记录的销售费用均已记录，所有应当包括在财务报表中的相关披露均已包括;
A7: 2.与销售费用有关的金额及其他数据已恰当记录，相关披露已得到恰当计量和描述； 3. 销售费用已记录于正确的会计期间
A8: 二、样本选取标准与规模：
A9: 测试总体一般不包括：结转损益、职工薪酬/折旧计提、无形资产及长期费用摊销、各项税费计提等凭证。
A10: 测试总体： | B10: 如借方发生额所有凭证共XX笔金额XX、贷方发生额所有凭证共XX笔金额XX | G10: 特定样本： | H10: XX金额以上（大额）、关联方/关联交易形成的款项、XX异常款项全部测试，共XX笔；
A11: 抽样总体： | B11: 测试总体扣除特定样本以外的样本，共XX笔、金额XX | G11: 确定的抽样样本量： | H11: 抽取XX笔 | I11: （如果使用了样本计算器计算样本量，样本量计算过程见<XX>底稿）
A12: 抽样方法： | B12: 随机选样/系统选样/货币单元抽样/随意选样（非统计抽样适用） | G12: 抽样过程： | H12: 使用IDEA（XX抽样工具）选择XX数量、金额XX的样本进行测试，抽样工具中的样本选择过程和结果见<XX>底稿
A13: 三、测试：
A14: 测试内容说明：1.原始凭证是否齐全； 2.记账凭证与原始凭证是否相符；3.账务处理是否正确；4.是否记录于恰当的会计期间；5.……
A15: 费用明细项目 | B15: 记账凭证 | H15: 支持性文件 | J15: 核对内容 | O15: 索引号 | P15: 是否异常 | Q15: 备注说明
B16: 日期 | C16: 凭证编号 | D16: 业务内容 | E16: 对方科目 | F16: 对方明细科目 | G16: 借方金额 | J16: 1 | K16: 2 | L16: 3 | M16: 4 | N16: 5
H17: 付款审批单、费用报销单、支出凭单、银行回单、合同……
A34: 合计 | G34: =SUM(G17:G33) -> 0
A35: 本期发生额 | G35: ='明细表K8-2'!Q25 -> 0
A36: 检查比例 | G36: =G34/G35 -> #DIV/0!
A37: 四、审计说明：
A38: 1.如果检查比例较低应扩大检查样本量或说明原因
A40: 五、审计结论：
