Workbook

Sheet 底稿目录
A1: 底稿开列时，可先在以下单元格填写有关内容，以便其他底稿引用有关数据：
A2: 被审计单位： | B2: 目录
A3: 会计期间：202X年度
A4: 编制人： | B4: 序号 | C4: 内容 | D4: 索引号 | E4: 备注
A5: 编制日期： | B5: 1 | C5: 实质性程序表 | D5: K9A
A6: 复核人： | B6: 2 | C6: 审定表 | D6: K9-1
A7: 复核日期： | B7: 3 | C7: 附注披露信息（上市公司） | F7: 无需打印
B8: 4 | C8: 附注披露信息（国企） | F8: 无需打印
B9: 5 | C9: 明细表 | D9: K9-2
A10: 关于工作底稿与审计程序索引号对应的说明 | B10: 6 | C10: 调整分录汇总 | D10: K9-3
A11: 1.编制的审计工作底稿应与审计程序对应。审计项目组应根据被审计单位实际情况和风险评估情况在实质性程序表中裁剪、修改或增加审计程序，根据实际执行的审计程序完成相应审计工作底稿，编制的工作底稿中应按自然顺序依次编制索引号，并通过唯一的索引号将与实质性程序表中的程序对应关联（即将工作底稿的索引号填入实质性程序表中的底稿索引号列）。 | B11: 7 | C11: 实质性分析 | D11: K9-4
B12: 8 | C12: 合同检查表 | D12: K9-5
B13: 9 | C13: 截止性测试(从记账凭证至原始凭证） | D13: K9-6
B14: 10 | C14: 截止性测试（从原始凭证至记账凭证） | D14: K9-7
A15: 2.获取的支持性证据应与审计底稿或程序对应。审计项目组在完成底稿时获取的支持性证据应根据底稿索引号编制下一级按自然顺序排序的索引号（如D1-2-1、D1-2-2、……），并在底稿中说明引用的支持性证据、关联索引号。 | B15: 11 | C15: 管理费用检查表 | D15: K9-8
A18: 3.工作底稿索引号的编码规则：实质性程序索引号按循环从“D”到“N”,循环内账户以顺序号排列，模板中底稿索引号按账户顺序+自然数顺序（即模板中索引号按二级自然顺序排列，如D1-1、D1-2、D1-3、……D1-N）。

Sheet 实质性程序表K9A
A1: 致同会计师事务所
A2: 管理费用实质性程序
A3: =底稿目录!A2 -> 被审计单位： | C3: =底稿目录!A4 -> 编制人： | E3: =底稿目录!A5 -> 编制日期： | H3: 索引号： | I3: =底稿目录!D5 -> K9A
A4: =底稿目录!A3 -> 会计期间：202X年度 | C4: =底稿目录!A6 -> 复核人： | E4: =底稿目录!A7 -> 复核日期： | H4: 页次：
A5: 一、本账户涉及的科目
A6: 管理费用
A7: 二、审计目标与认定的对应关系
A8: 审计目标 | G8: 财务报表的认定
A9: A. 利润表中记录的管理费用已发生，且与被审计单位有关，已记录于恰当的账户 | G9: 发生
A10: B. 所有应当记录的管理费用均已记录，所有应当包括在财务报表中的相关披露均已包括 | G10: 完整性
A11: C. 与管理费用有关的金额及其他数据已恰当记录，相关披露已得到恰当计量和描述 | G11: 准确性
A12: D. 管理费用已记录于正确的会计期间 | G12: 截止
A13: E. 已被恰当地汇总或分解且表述清楚，相关披露在按照企业会计准则的编制基础下是相关的、可理解的 | G13: 列报
A14: 三、计划实施的实质性程序
A15: 序号 | B15: 审计程序 | C15: 程序分类 | D15: 审计程序 | I15: 底稿索引号
D16: 发生 | E16: 完整性 | F16: 准确性 | G16: 截止 | H16: 列报 | J16: 根据被审计单位实际情况和风险评估情况裁剪、修改或增加审计程序
A17: 1 | B17: 获取或编制明细表、执行下列程序，并编制审定表： (1)复核其加计数是否正确，并与报表、总账数和明细账合计数核对是否相符； (2)将管理费用中的工资、折旧等与相关的资产、负债科目核对，检查其勾稽关系的合理性。 | C17: 常规★ | D17: √ | E17: √ | F17: √ | I17: K9-1 /K9-2
A18: 2 | B18: 在使用手工编制、自定义信息报告、系统生成的非固定格式报告等由被审计单位生成的信息时，测试有关信息准确性和完整性，并考虑针对编制和维护由被审计单位生成的信息的相关控制实施控制测试，以评价该信息是否能够为实现审计目的提供基础。 | C18: 常规★ | E18: √ | F18: √ | I18: T1 | J18: 可参见《审计手册》4.2.6，由被审计单位生成的信息可能是由系统生成的、或手工编制的、或二者兼而有之的方式生成的。例如，由被审计单位生成的信息可能包括： • 不涉及自定义的、由系统生成的报告（如，固定格式报告）； • 可能通过人工自定义的、由系统生成的报告，例如，（计算机）查询信息或特别定制的报告； • 手工编制的信息，例如，汇总信息的电子表格或用以支持分配、计算以及调节的电子表格； • 其他系统生成或手工编制的信息，例如，由被审计单位编制的客户发票； • 通过影印、拍摄、扫描或其他方式转换成电子形式的文件记录。
A19: 3 | B19: 对上期发生额的审计：结合本期审计确定管理费用的上期金额的截止是否恰当。（适用于首次承接） | C19: 备选 | G19: √ | J19: 由被审计单位生成的信息不包括： • 总分类账或明细分类账、试算平衡表、或经审计的财务报表； • 第三方（除了服务机构）的报表或报告，例如，原始银行对账单，或函证的回函； • 外部数据（例如，第三方发布的数据，如，定价来源）。
A20: 4 | B20: 关注会计政策、会计估计合理性、一贯性。关注其是否利用会计政策和会计估计及其变更操纵利润。 | C20: 常规★ | D20: √ | E20: √ | F20: √ | I20: K9-1 /K9-2
A21: 5 | B21: 分析总体合理性： （1）分析本期管理费用明细占比情况、与上期发生额比较，分析异常波动原因；关注明细项中是否存在不符合往年常态的项目，不符合企业经营状况，存在异常变动的项目，检查相关支持性文件； （2）分析本期管理费用明细各月金额及其占比，分析异常波动原因； （3）计算分析管理销售费用及主要明细项目金额占主营业务收入的比率，并与上年度可比期间、同行业水平进行对比，判断变动的合理性； （4）将管理费用实际发生金额与预算金额进行比较。 | C21: 常规★ | D21: √ | E21: √ | F21: √ | I21: K9-4
A22: 6 | B22: 重新计算排污费、矿产资源补偿费、文化事业建设费等费用，确定其金额是否正确。 | C22: 备选 | F22: √ | I22: K9-2
A23: 7 | B23: 对于律师费、咨询费、房租、保险费等合同费用，获取合同、协议，查看具体约定条款，并根据具体约定条款测算费用，检查管理费用确认是否准确和完整。 | C23: 常规★ | D23: √ | E23: √ | F23: √ | G23: √ | I23: K9-5
A24: 8 | B24: 如发生诉讼相关费用，检查诉讼费用并结合或有事项、预计负债审计,检查涉及的相关重大诉讼事项是否已在附注中进行披露，并进一步关注诉讼状态，判断有无或有负债，或是否存在损失已发生而未入账的事项。 | C24: 备选 | E24: √
A25: 9 | B25: 检查关联方交易：了解关联交易事项的目的、价格和条件，检查交易的支持性文件，同时向关联方或其他注册会计师函证重大的交易（包括担保和其他重要信息），以确认交易的真实性；必要时，向与交易相关的人员和机构（如银行、律师）函证或与其讨论有关信息；考虑是否存在未识别的关联方，关联交易和余额披露是否正确。 | C25: 常规★ | D25: √ | E25: √ | F25: √ | G25: √ | H25: √
A26: 10 | B26: 检查是否存在关联方或其他利益相关方代被审计单位支付成本、费用或者采用无偿或不公允的交易价格向被审计单位提供经济资源： （1）取得控股股东、实际控制人及其控制企业的财务报表，对于财务报表相关费用项目变动较大的，以及该等关联方与被审计单位存在资金往来的，询问其原因，关注费用发生真实性以及资金真实意图和流向； （2）了解被审计单位是否向关联方租用办公场所或无偿使用，关注租金的合理性。与被审计单位相同或相近办公地址的关联方或其他利益相关方，重点核查其有无代为支付成本、费用的情形； （3）调查并访谈实际控制人关于其投资领域、投资回报以及民间借贷、借贷用途、接受各类监管检查等方面的情况； （4）分析计入费用的工资薪金，关注构成是否异常变化、各月之间波动有无异常，如果异常降低，关注是否存在其他方（如关联方）代付工资的情况； （4）取得被审计单位及其实际控制人、控股股东、董事、监事、高管等关联方对“关联方代为支付成本费用进行利益输送的情形”出具的承诺书；如报告期内实际控制人转让拟IPO企业股份或转让其他企业股权且金额较大的，需了解股权转让资金的用途； | C26: IPO/上市/新三板/重组/舞弊应对 | D26: √ | E26: √ | F26: √ | G26: √ | H26: √
A27: 11 | B27: 截止测试： （1）抽取资产负债表日前后若干张记账凭证，实施截止测试，存在异常迹象，应考虑是否有必要追加审计程序，对于重大跨期项目应作必要调整。 （2）从资产负债日后的银行对账单或付款凭证中若干项目进行测试，检查支持性文件；关注支持性文件的日期，检查费用是否记录于正确的会计期间，是否存在有未入账的负债。 | C27: 常规★ | G27: √ | I27: K9-6 /K9-7
A28: 12 | B28: 检查与管理费用有关的的记账凭证和相应的支持性证据以确定交易的真实性，是否按规定进行相应的会计处理和披露。 | C28: 常规★ | D28: √ | F28: √ | G28: √ | I28: K9-8
A29: 13 | B29: 考虑是否存在超出被审计单位正常经营活动的重大、异常交易等，根据评估的舞弊风险等因素增加的审计程序。 | C29: IPO/上市/新三板/重组/舞弊应对
A30: 14 | B30: 检查管理费用是否已按企业会计准则或其他适用的规定在财务报表中做出恰当列报和披露。 | C30: 常规★ | H30: √ | I30: A1-1/A1-15 /A1-16

Sheet 审定表K9-1
A1: 致同会计师事务所
A2: 管理费用审定表（个别报表）
A3: =底稿目录!A2 -> 被审计单位： | D3: =底稿目录!A4 -> 编制人： | H3: =底稿目录!A5 -> 编制日期： | K3: 索引： | L3: =底稿目录!D6 -> K9-1
A4: =底稿目录!A3 -> 会计期间：202X年度 | D4: =底稿目录!A6 -> 复核人： | H4: =底稿目录!A7 -> 复核日期： | K4: 页次：
A5: 项目 | B5: 上期数 | F5: 本期数 | J5: 本期审定数与上期 审定数的比较 | L5: 原因分析
B6: 未审数 | C6: 账项调整 | D6: 重分类调整 | E6: 审定数 | F6: 未审数 | G6: 账项调整 | H6: 重分类调整 | I6: 审定数 | J6: 变动额 | K6: 变动率
A7: ='明细表K9-2'!A11 -> 公司经费 | B7: =SUMIF('明细表K9-2'!$X$11:$X$28,$A7,'明细表K9-2'!$T$11:$T$28) -> 0 | C7: =SUMIF('明细表K9-2'!$X$11:$X$28,$A7,'明细表K9-2'!$U$11:$U$28) -> 0 | D7: =SUMIF('明细表K9-2'!$X$11:$X$28,$A7,'明细表K9-2'!$V$11:$V$28) -> 0 | E7: =B7+C7+D7 -> 0 | F7: =SUMIF('明细表K9-2'!$X$11:$X$28,$A7,'明细表K9-2'!$N$11:$N$28) -> 0 | G7: =SUMIF('明细表K9-2'!$X$11:$X$28,$A7,'明细表K9-2'!$O$11:$O$28) -> 0 | H7: =SUMIF('明细表K9-2'!$X$11:$X$28,$A7,'明细表K9-2'!$P$11:$P$28) -> 0 | I7: =F7+G7+H7 -> 0 | J7: =I7-E7 -> 0 | K7: =IF(AND(E7=0,I7=0),0,IF(AND(E7=0,I7>0),1,J7/E7)) -> 0
A8: ='明细表K9-2'!A12 -> 职工工资 | B8: =SUMIF('明细表K9-2'!$X$11:$X$28,$A8,'明细表K9-2'!$T$11:$T$28) -> 0 | C8: =SUMIF('明细表K9-2'!$X$11:$X$28,$A8,'明细表K9-2'!$U$11:$U$28) -> 0 | D8: =SUMIF('明细表K9-2'!$X$11:$X$28,$A8,'明细表K9-2'!$V$11:$V$28) -> 0 | E8: =B8+C8+D8 -> 0 | F8: =SUMIF('明细表K9-2'!$X$11:$X$28,$A8,'明细表K9-2'!$N$11:$N$28) -> 0 | G8: =SUMIF('明细表K9-2'!$X$11:$X$28,$A8,'明细表K9-2'!$O$11:$O$28) -> 0 | H8: =SUMIF('明细表K9-2'!$X$11:$X$28,$A8,'明细表K9-2'!$P$11:$P$28) -> 0 | I8: =F8+G8+H8 -> 0 | J8: =I8-E8 -> 0 | K8: =IF(AND(E8=0,I8=0),0,IF(AND(E8=0,I8>0),1,J8/E8)) -> 0
A9: ='明细表K9-2'!A13 -> 福利费 | B9: =SUMIF('明细表K9-2'!$X$11:$X$28,$A9,'明细表K9-2'!$T$11:$T$28) -> 0 | C9: =SUMIF('明细表K9-2'!$X$11:$X$28,$A9,'明细表K9-2'!$U$11:$U$28) -> 0 | D9: =SUMIF('明细表K9-2'!$X$11:$X$28,$A9,'明细表K9-2'!$V$11:$V$28) -> 0 | E9: =B9+C9+D9 -> 0 | F9: =SUMIF('明细表K9-2'!$X$11:$X$28,$A9,'明细表K9-2'!$N$11:$N$28) -> 0 | G9: =SUMIF('明细表K9-2'!$X$11:$X$28,$A9,'明细表K9-2'!$O$11:$O$28) -> 0 | H9: =SUMIF('明细表K9-2'!$X$11:$X$28,$A9,'明细表K9-2'!$P$11:$P$28) -> 0 | I9: =F9+G9+H9 -> 0 | J9: =I9-E9 -> 0 | K9: =IF(AND(E9=0,I9=0),0,IF(AND(E9=0,I9>0),1,J9/E9)) -> 0
A10: ='明细表K9-2'!A14 -> 物料消耗 | B10: =SUMIF('明细表K9-2'!$X$11:$X$28,$A10,'明细表K9-2'!$T$11:$T$28) -> 0 | C10: =SUMIF('明细表K9-2'!$X$11:$X$28,$A10,'明细表K9-2'!$U$11:$U$28) -> 0 | D10: =SUMIF('明细表K9-2'!$X$11:$X$28,$A10,'明细表K9-2'!$V$11:$V$28) -> 0 | E10: =B10+C10+D10 -> 0 | F10: =SUMIF('明细表K9-2'!$X$11:$X$28,$A10,'明细表K9-2'!$N$11:$N$28) -> 0 | G10: =SUMIF('明细表K9-2'!$X$11:$X$28,$A10,'明细表K9-2'!$O$11:$O$28) -> 0 | H10: =SUMIF('明细表K9-2'!$X$11:$X$28,$A10,'明细表K9-2'!$P$11:$P$28) -> 0 | I10: =F10+G10+H10 -> 0 | J10: =I10-E10 -> 0 | K10: =IF(AND(E10=0,I10=0),0,IF(AND(E10=0,I10>0),1,J10/E10)) -> 0
A11: ='明细表K9-2'!A15 -> 低值易耗品摊销 | B11: =SUMIF('明细表K9-2'!$X$11:$X$28,$A11,'明细表K9-2'!$T$11:$T$28) -> 0 | C11: =SUMIF('明细表K9-2'!$X$11:$X$28,$A11,'明细表K9-2'!$U$11:$U$28) -> 0 | D11: =SUMIF('明细表K9-2'!$X$11:$X$28,$A11,'明细表K9-2'!$V$11:$V$28) -> 0 | E11: =B11+C11+D11 -> 0 | F11: =SUMIF('明细表K9-2'!$X$11:$X$28,$A11,'明细表K9-2'!$N$11:$N$28) -> 0 | G11: =SUMIF('明细表K9-2'!$X$11:$X$28,$A11,'明细表K9-2'!$O$11:$O$28) -> 0 | H11: =SUMIF('明细表K9-2'!$X$11:$X$28,$A11,'明细表K9-2'!$P$11:$P$28) -> 0 | I11: =F11+G11+H11 -> 0 | J11: =I11-E11 -> 0 | K11: =IF(AND(E11=0,I11=0),0,IF(AND(E11=0,I11>0),1,J11/E11)) -> 0
A12: ='明细表K9-2'!A16 -> 办公费 | B12: =SUMIF('明细表K9-2'!$X$11:$X$28,$A12,'明细表K9-2'!$T$11:$T$28) -> 0 | C12: =SUMIF('明细表K9-2'!$X$11:$X$28,$A12,'明细表K9-2'!$U$11:$U$28) -> 0 | D12: =SUMIF('明细表K9-2'!$X$11:$X$28,$A12,'明细表K9-2'!$V$11:$V$28) -> 0 | E12: =B12+C12+D12 -> 0 | F12: =SUMIF('明细表K9-2'!$X$11:$X$28,$A12,'明细表K9-2'!$N$11:$N$28) -> 0 | G12: =SUMIF('明细表K9-2'!$X$11:$X$28,$A12,'明细表K9-2'!$O$11:$O$28) -> 0 | H12: =SUMIF('明细表K9-2'!$X$11:$X$28,$A12,'明细表K9-2'!$P$11:$P$28) -> 0 | I12: =F12+G12+H12 -> 0 | J12: =I12-E12 -> 0 | K12: =IF(AND(E12=0,I12=0),0,IF(AND(E12=0,I12>0),1,J12/E12)) -> 0
A13: ='明细表K9-2'!A17 -> 差旅费 | B13: =SUMIF('明细表K9-2'!$X$11:$X$28,$A13,'明细表K9-2'!$T$11:$T$28) -> 0 | C13: =SUMIF('明细表K9-2'!$X$11:$X$28,$A13,'明细表K9-2'!$U$11:$U$28) -> 0 | D13: =SUMIF('明细表K9-2'!$X$11:$X$28,$A13,'明细表K9-2'!$V$11:$V$28) -> 0 | E13: =B13+C13+D13 -> 0 | F13: =SUMIF('明细表K9-2'!$X$11:$X$28,$A13,'明细表K9-2'!$N$11:$N$28) -> 0 | G13: =SUMIF('明细表K9-2'!$X$11:$X$28,$A13,'明细表K9-2'!$O$11:$O$28) -> 0 | H13: =SUMIF('明细表K9-2'!$X$11:$X$28,$A13,'明细表K9-2'!$P$11:$P$28) -> 0 | I13: =F13+G13+H13 -> 0 | J13: =I13-E13 -> 0 | K13: =IF(AND(E13=0,I13=0),0,IF(AND(E13=0,I13>0),1,J13/E13)) -> 0
A14: ='明细表K9-2'!A18 -> 工会经费 | B14: =SUMIF('明细表K9-2'!$X$11:$X$28,$A14,'明细表K9-2'!$T$11:$T$28) -> 0 | C14: =SUMIF('明细表K9-2'!$X$11:$X$28,$A14,'明细表K9-2'!$U$11:$U$28) -> 0 | D14: =SUMIF('明细表K9-2'!$X$11:$X$28,$A14,'明细表K9-2'!$V$11:$V$28) -> 0 | E14: =B14+C14+D14 -> 0 | F14: =SUMIF('明细表K9-2'!$X$11:$X$28,$A14,'明细表K9-2'!$N$11:$N$28) -> 0 | G14: =SUMIF('明细表K9-2'!$X$11:$X$28,$A14,'明细表K9-2'!$O$11:$O$28) -> 0 | H14: =SUMIF('明细表K9-2'!$X$11:$X$28,$A14,'明细表K9-2'!$P$11:$P$28) -> 0 | I14: =F14+G14+H14 -> 0 | J14: =I14-E14 -> 0 | K14: =IF(AND(E14=0,I14=0),0,IF(AND(E14=0,I14>0),1,J14/E14)) -> 0
A15: ='明细表K9-2'!A19 -> 董事会费 | B15: =SUMIF('明细表K9-2'!$X$11:$X$28,$A15,'明细表K9-2'!$T$11:$T$28) -> 0 | C15: =SUMIF('明细表K9-2'!$X$11:$X$28,$A15,'明细表K9-2'!$U$11:$U$28) -> 0 | D15: =SUMIF('明细表K9-2'!$X$11:$X$28,$A15,'明细表K9-2'!$V$11:$V$28) -> 0 | E15: =B15+C15+D15 -> 0 | F15: =SUMIF('明细表K9-2'!$X$11:$X$28,$A15,'明细表K9-2'!$N$11:$N$28) -> 0 | G15: =SUMIF('明细表K9-2'!$X$11:$X$28,$A15,'明细表K9-2'!$O$11:$O$28) -> 0 | H15: =SUMIF('明细表K9-2'!$X$11:$X$28,$A15,'明细表K9-2'!$P$11:$P$28) -> 0 | I15: =F15+G15+H15 -> 0 | J15: =I15-E15 -> 0 | K15: =IF(AND(E15=0,I15=0),0,IF(AND(E15=0,I15>0),1,J15/E15)) -> 0
A16: ='明细表K9-2'!A20 -> 聘请中介机构费 | B16: =SUMIF('明细表K9-2'!$X$11:$X$28,$A16,'明细表K9-2'!$T$11:$T$28) -> 0 | C16: =SUMIF('明细表K9-2'!$X$11:$X$28,$A16,'明细表K9-2'!$U$11:$U$28) -> 0 | D16: =SUMIF('明细表K9-2'!$X$11:$X$28,$A16,'明细表K9-2'!$V$11:$V$28) -> 0 | E16: =B16+C16+D16 -> 0 | F16: =SUMIF('明细表K9-2'!$X$11:$X$28,$A16,'明细表K9-2'!$N$11:$N$28) -> 0 | G16: =SUMIF('明细表K9-2'!$X$11:$X$28,$A16,'明细表K9-2'!$O$11:$O$28) -> 0 | H16: =SUMIF('明细表K9-2'!$X$11:$X$28,$A16,'明细表K9-2'!$P$11:$P$28) -> 0 | I16: =F16+G16+H16 -> 0 | J16: =I16-E16 -> 0 | K16: =IF(AND(E16=0,I16=0),0,IF(AND(E16=0,I16>0),1,J16/E16)) -> 0
A17: ='明细表K9-2'!A21 -> 咨询费（含顾问费） | B17: =SUMIF('明细表K9-2'!$X$11:$X$28,$A17,'明细表K9-2'!$T$11:$T$28) -> 0 | C17: =SUMIF('明细表K9-2'!$X$11:$X$28,$A17,'明细表K9-2'!$U$11:$U$28) -> 0 | D17: =SUMIF('明细表K9-2'!$X$11:$X$28,$A17,'明细表K9-2'!$V$11:$V$28) -> 0 | E17: =B17+C17+D17 -> 0 | F17: =SUMIF('明细表K9-2'!$X$11:$X$28,$A17,'明细表K9-2'!$N$11:$N$28) -> 0 | G17: =SUMIF('明细表K9-2'!$X$11:$X$28,$A17,'明细表K9-2'!$O$11:$O$28) -> 0 | H17: =SUMIF('明细表K9-2'!$X$11:$X$28,$A17,'明细表K9-2'!$P$11:$P$28) -> 0 | I17: =F17+G17+H17 -> 0 | J17: =I17-E17 -> 0 | K17: =IF(AND(E17=0,I17=0),0,IF(AND(E17=0,I17>0),1,J17/E17)) -> 0
A18: ='明细表K9-2'!A22 -> 诉讼费 | B18: =SUMIF('明细表K9-2'!$X$11:$X$28,$A18,'明细表K9-2'!$T$11:$T$28) -> 0 | C18: =SUMIF('明细表K9-2'!$X$11:$X$28,$A18,'明细表K9-2'!$U$11:$U$28) -> 0 | D18: =SUMIF('明细表K9-2'!$X$11:$X$28,$A18,'明细表K9-2'!$V$11:$V$28) -> 0 | E18: =B18+C18+D18 -> 0 | F18: =SUMIF('明细表K9-2'!$X$11:$X$28,$A18,'明细表K9-2'!$N$11:$N$28) -> 0 | G18: =SUMIF('明细表K9-2'!$X$11:$X$28,$A18,'明细表K9-2'!$O$11:$O$28) -> 0 | H18: =SUMIF('明细表K9-2'!$X$11:$X$28,$A18,'明细表K9-2'!$P$11:$P$28) -> 0 | I18: =F18+G18+H18 -> 0 | J18: =I18-E18 -> 0 | K18: =IF(AND(E18=0,I18=0),0,IF(AND(E18=0,I18>0),1,J18/E18)) -> 0
... A24: ='明细表K9-2'!A28 -> …… | B24: =SUMIF('明细表K9-2'!$X$11:$X$28,$A24,'明细表K9-2'!$T$11:$T$28) -> 0 | C24: =SUMIF('明细表K9-2'!$X$11:$X$28,$A24,'明细表K9-2'!$U$11:$U$28) -> 0 | D24: =SUMIF('明细表K9-2'!$X$11:$X$28,$A24,'明细表K9-2'!$V$11:$V$28) -> 0 | E24: =B24+C24+D24 -> 0 | F24: =SUMIF('明细表K9-2'!$X$11:$X$28,$A24,'明细表K9-2'!$N$11:$N$28) -> 0 | G24: =SUMIF('明细表K9-2'!$X$11:$X$28,$A24,'明细表K9-2'!$O$11:$O$28) -> 0 | H24: =SUMIF('明细表K9-2'!$X$11:$X$28,$A24,'明细表K9-2'!$P$11:$P$28) -> 0 | I24: =F24+G24+H24 -> 0 | J24: =I24-E24 -> 0 | K24: =IF(AND(E24=0,I24=0),0,IF(AND(E24=0,I24>0),1,J24/E24)) -> 0
A25: 合计 | B25: =SUM(B7:B24) -> 0 | C25: =SUM(C7:C24) -> 0 | D25: =SUM(D7:D24) -> 0 | E25: =SUM(E7:E24) -> 0 | F25: =SUM(F7:F24) -> 0 | G25: =SUM(G7:G24) -> 0 | H25: =SUM(H7:H24) -> 0 | I25: =SUM(I7:I24) -> 0 | J25: =I25-E25 -> 0 | K25: =IF(AND(E25=0,I25=0),0,IF(AND(E25=0,I25>0),1,J25/E25)) -> 0
A26: TB数据：
A27: 差异： | B27: =B25-B26 -> 0 | C27: =C25-C26 -> 0 | D27: =D25-D26 -> 0 | E27: =E25-E26 -> 0 | F27: =F25-F26 -> 0 | G27: =G25-G26 -> 0 | H27: =H25-H26 -> 0 | I27: =I25-I26 -> 0
A28: 1.审计说明
A29: （1）管理费用本期较上期增加（负数为减少）：
A30: 主要原因（比例超过30%的）：
A31: （2）情况说明。
A32: 2.审计结论

Sheet 附注披露信息（上市公司）
A1: 致同会计师事务所
A2: 附注披露信息（上市公司）
A3: =底稿目录!A2 -> 被审计单位： | B3: =底稿目录!A4 -> 编制人： | C3: =底稿目录!A5 -> 编制日期： | D3: 索引：
A4: =底稿目录!A3 -> 会计期间：202X年度 | B4: =底稿目录!A6 -> 复核人： | C4: =底稿目录!A7 -> 复核日期： | D4: 页次： | E4: 1
A5: 管理费用（个别报表）
A6: 项 目 | B6: 本期发生额 | C6: 上期发生额
A7: ='审定表K9-1'!A7 -> 公司经费 | B7: ='审定表K9-1'!I7 -> 0 | C7: ='审定表K9-1'!E7 -> 0
A8: ='审定表K9-1'!A8 -> 职工工资 | B8: ='审定表K9-1'!I8 -> 0 | C8: ='审定表K9-1'!E8 -> 0
A9: ='审定表K9-1'!A9 -> 福利费 | B9: ='审定表K9-1'!I9 -> 0 | C9: ='审定表K9-1'!E9 -> 0
A10: ='审定表K9-1'!A10 -> 物料消耗 | B10: ='审定表K9-1'!I10 -> 0 | C10: ='审定表K9-1'!E10 -> 0
A11: ='审定表K9-1'!A11 -> 低值易耗品摊销 | B11: ='审定表K9-1'!I11 -> 0 | C11: ='审定表K9-1'!E11 -> 0
A12: ='审定表K9-1'!A12 -> 办公费 | B12: ='审定表K9-1'!I12 -> 0 | C12: ='审定表K9-1'!E12 -> 0
A13: ='审定表K9-1'!A13 -> 差旅费 | B13: ='审定表K9-1'!I13 -> 0 | C13: ='审定表K9-1'!E13 -> 0
A14: ='审定表K9-1'!A14 -> 工会经费 | B14: ='审定表K9-1'!I14 -> 0 | C14: ='审定表K9-1'!E14 -> 0
A15: ='审定表K9-1'!A15 -> 董事会费 | B15: ='审定表K9-1'!I15 -> 0 | C15: ='审定表K9-1'!E15 -> 0
A16: ='审定表K9-1'!A16 -> 聘请中介机构费 | B16: ='审定表K9-1'!I16 -> 0 | C16: ='审定表K9-1'!E16 -> 0
A17: ='审定表K9-1'!A17 -> 咨询费（含顾问费） | B17: ='审定表K9-1'!I17 -> 0 | C17: ='审定表K9-1'!E17 -> 0
A18: ='审定表K9-1'!A18 -> 诉讼费 | B18: ='审定表K9-1'!I18 -> 0 | C18: ='审定表K9-1'!E18 -> 0
... A24: ='审定表K9-1'!A24 -> …… | B24: ='审定表K9-1'!I24 -> 0 | C24: ='审定表K9-1'!E24 -> 0
A25: 合 计 | B25: =SUM(B7:B24) -> 0 | C25: =SUM(C7:C24) -> 0
A26: 管理费用（合并报表）
A27: 项 目 | B27: 本期发生额 | C27: 上期发生额
A42: 合 计 | B42: =SUM(B28:B41) -> 0 | C42: =SUM(C28:C41) -> 0

Sheet 附注披露信息（国企）
A1: 致同会计师事务所
A2: 附注披露信息(国企)
A3: =底稿目录!A2 -> 被审计单位： | B3: =底稿目录!A4 -> 编制人： | C3: =底稿目录!A5 -> 编制日期： | D3: 索引号：
A4: =底稿目录!A3 -> 会计期间：202X年度 | B4: =底稿目录!A6 -> 复核人： | C4: =底稿目录!A7 -> 复核日期： | D4: 页次:
A5: 管理费用（个别报表）
A6: 项 目 | B6: 本期发生额 | C6: 上期发生额
A7: ='审定表K9-1'!A7 -> 公司经费 | B7: ='审定表K9-1'!I7 -> 0 | C7: ='审定表K9-1'!E7 -> 0
A8: ='审定表K9-1'!A8 -> 职工工资 | B8: ='审定表K9-1'!I8 -> 0 | C8: ='审定表K9-1'!E8 -> 0
A9: ='审定表K9-1'!A9 -> 福利费 | B9: ='审定表K9-1'!I9 -> 0 | C9: ='审定表K9-1'!E9 -> 0
A10: ='审定表K9-1'!A10 -> 物料消耗 | B10: ='审定表K9-1'!I10 -> 0 | C10: ='审定表K9-1'!E10 -> 0
A11: ='审定表K9-1'!A11 -> 低值易耗品摊销 | B11: ='审定表K9-1'!I11 -> 0 | C11: ='审定表K9-1'!E11 -> 0
A12: ='审定表K9-1'!A12 -> 办公费 | B12: ='审定表K9-1'!I12 -> 0 | C12: ='审定表K9-1'!E12 -> 0
A13: ='审定表K9-1'!A13 -> 差旅费 | B13: ='审定表K9-1'!I13 -> 0 | C13: ='审定表K9-1'!E13 -> 0
A14: ='审定表K9-1'!A14 -> 工会经费 | B14: ='审定表K9-1'!I14 -> 0 | C14: ='审定表K9-1'!E14 -> 0
A15: ='审定表K9-1'!A15 -> 董事会费 | B15: ='审定表K9-1'!I15 -> 0 | C15: ='审定表K9-1'!E15 -> 0
A16: ='审定表K9-1'!A16 -> 聘请中介机构费 | B16: ='审定表K9-1'!I16 -> 0 | C16: ='审定表K9-1'!E16 -> 0
A17: ='审定表K9-1'!A17 -> 咨询费（含顾问费） | B17: ='审定表K9-1'!I17 -> 0 | C17: ='审定表K9-1'!E17 -> 0
A18: ='审定表K9-1'!A18 -> 诉讼费 | B18: ='审定表K9-1'!I18 -> 0 | C18: ='审定表K9-1'!E18 -> 0
... A24: ='审定表K9-1'!A24 -> …… | B24: ='审定表K9-1'!I24 -> 0 | C24: ='审定表K9-1'!E24 -> 0
A25: 合 计 | B25: =SUM(B7:B24) -> 0 | C25: =SUM(C7:C24) -> 0
A26: 管理费用（合并报表）
A27: 项 目 | B27: 本期发生额 | C27: 上期发生额
A42: 合 计 | B42: =SUM(B28:B41) -> 0 | C42: =SUM(C28:C41) -> 0

Sheet 明细表K9-2
A1: 致同会计师事务所
A2: 管理费用明细表
A3: =底稿目录!A2 -> 被审计单位： | G3: =底稿目录!A4 -> 编制人： | O3: =底稿目录!A5 -> 编制日期： | X3: 索引号： | Y3: =底稿目录!D9 -> K9-2
A4: =底稿目录!A3 -> 会计期间：202X年度 | G4: =底稿目录!A6 -> 复核人： | O4: =底稿目录!A7 -> 复核日期： | X4: 页次：
A5: 一、审计目标:
A6: 1.所有应当记录的管理费用均已记录，所有应当包括在财务报表中的相关披露均已包括; | H6: 2.与管理费用有关的金额及其他数据已恰当记录，相关披露已得到恰当计量和描述; | O6: 3. 与管理费用有关的金额及其他数据已恰当记录，相关披露已得到恰当计量和描述
A7: 二、审计过程：
A8: 1.获取或编制各个月份期间费用主要构成情况，分析各月波动是否符合预期及与被审计单位的经营波动是否一致； | J8: 2.检查管理费用各项费用的内容，防止应计入制造费用、销售费用、在建工程、营业外支出等科目的费用计入本科目。特别关注“其他”明细科目的内容；
A9: 3.将相关明细项目发生额与资产负债表的相关科目的明细科目如应付职工薪酬、折旧、无形资产摊销、长期待摊费用摊销等核对； | J9: 4.检查诉讼费用并结合或有事项审计,检查涉及的相关重大诉讼事项是否已在附注中进行披露，并进一步关注诉讼状态，判断有无或有负债，或是否存在损失已发生而未入账的事项。
A10: 项目 | B10: 1月 | C10: 2月 | D10: 3月 | E10: 4月 | F10: 5月 | G10: 6月 | H10: 7月 | I10: 8月 | J10: 9月 | K10: 10月 | L10: 11月 | M10: 12月 | N10: 本期未审合计 | O10: 账项调整 | P10: 重分类调整 | Q10: 本期审定金额 | R10: 各项目占比 | S10: 与相关科目勾稽 | T10: 上期未审金额 | U10: 账项调整 | V10: 重分类调整 | W10: 上期审定金额 | X10: 个别报表下的重分类 | Y10: 合并报表下的重分类
A11: 公司经费 | N11: =SUM(B11:M11) -> 0 | Q11: =N11+O11+P11 -> 0 | R11: =IF(Q11=0,0,Q11/$Q$29) -> 0 | S11: L1-XXX | W11: =T11+U11+V11 -> 0 | X11: 公司经费 | Y11: 公司经费
A12: 职工工资 | N12: =SUM(B12:M12) -> 0 | Q12: =N12+O12+P12 -> 0 | R12: =IF(Q12=0,0,Q12/$Q$29) -> 0 | W12: =T12+U12+V12 -> 0
A13: 福利费 | N13: =SUM(B13:M13) -> 0 | Q13: =N13+O13+P13 -> 0 | R13: =IF(Q13=0,0,Q13/$Q$29) -> 0 | S13: J1-XXXX | W13: =T13+U13+V13 -> 0
A14: 物料消耗 | N14: =SUM(B14:M14) -> 0 | Q14: =N14+O14+P14 -> 0 | R14: =IF(Q14=0,0,Q14/$Q$29) -> 0 | W14: =T14+U14+V14 -> 0
A15: 低值易耗品摊销 | N15: =SUM(B15:M15) -> 0 | Q15: =N15+O15+P15 -> 0 | R15: =IF(Q15=0,0,Q15/$Q$29) -> 0 | W15: =T15+U15+V15 -> 0
A16: 办公费 | N16: =SUM(B16:M16) -> 0 | Q16: =N16+O16+P16 -> 0 | R16: =IF(Q16=0,0,Q16/$Q$29) -> 0 | W16: =T16+U16+V16 -> 0
A17: 差旅费 | N17: =SUM(B17:M17) -> 0 | Q17: =N17+O17+P17 -> 0 | R17: =IF(Q17=0,0,Q17/$Q$29) -> 0 | W17: =T17+U17+V17 -> 0
A18: 工会经费 | N18: =SUM(B18:M18) -> 0 | Q18: =N18+O18+P18 -> 0 | R18: =IF(Q18=0,0,Q18/$Q$29) -> 0 | W18: =T18+U18+V18 -> 0
A19: 董事会费 | N19: =SUM(B19:M19) -> 0 | Q19: =N19+O19+P19 -> 0 | R19: =IF(Q19=0,0,Q19/$Q$29) -> 0 | W19: =T19+U19+V19 -> 0
A20: 聘请中介机构费 | N20: =SUM(B20:M20) -> 0 | Q20: =N20+O20+P20 -> 0 | R20: =IF(Q20=0,0,Q20/$Q$29) -> 0 | W20: =T20+U20+V20 -> 0
A21: 咨询费（含顾问费） | N21: =SUM(B21:M21) -> 0 | Q21: =N21+O21+P21 -> 0 | R21: =IF(Q21=0,0,Q21/$Q$29) -> 0 | W21: =T21+U21+V21 -> 0
A22: 诉讼费 | N22: =SUM(B22:M22) -> 0 | Q22: =N22+O22+P22 -> 0 | R22: =IF(Q22=0,0,Q22/$Q$29) -> 0 | W22: =T22+U22+V22 -> 0
A23: 业务招待费 | N23: =SUM(B23:M23) -> 0 | Q23: =N23+O23+P23 -> 0 | R23: =IF(Q23=0,0,Q23/$Q$29) -> 0 | W23: =T23+U23+V23 -> 0
A24: 技术转让费 | N24: =SUM(B24:M24) -> 0 | Q24: =N24+O24+P24 -> 0 | R24: =IF(Q24=0,0,Q24/$Q$29) -> 0 | W24: =T24+U24+V24 -> 0
A25: 矿产资源补偿费 | N25: =SUM(B25:M25) -> 0 | Q25: =N25+O25+P25 -> 0 | R25: =IF(Q25=0,0,Q25/$Q$29) -> 0 | W25: =T25+U25+V25 -> 0
... A28: …… | N28: =SUM(B28:M28) -> 0 | Q28: =N28+O28+P28 -> 0 | R28: =IF(Q28=0,0,Q28/$Q$29) -> 0 | W28: =T28+U28+V28 -> 0
A29: 合计 | B29: =SUM(B11:B28) -> 0 | C29: =SUM(C11:C28) -> 0 | D29: =SUM(D11:D28) -> 0 | E29: =SUM(E11:E28) -> 0 | F29: =SUM(F11:F28) -> 0 | G29: =SUM(G11:G28) -> 0 | H29: =SUM(H11:H28) -> 0 | I29: =SUM(I11:I28) -> 0 | ... R29: =SUM(R11:R28) -> 0 | T29: =SUM(T11:T28) -> 0 | U29: =SUM(U11:U28) -> 0 | V29: =SUM(V11:V28) -> 0 | W29: =SUM(W11:W28) -> 0
A30: 各月比例 | B30: =IF($N$29=0,0,B29/$N$29) -> 0 | C30: =IF($N$29=0,0,C29/$N$29) -> 0 | D30: =IF($N$29=0,0,D29/$N$29) -> 0 | E30: =IF($N$29=0,0,E29/$N$29) -> 0 | F30: =IF($N$29=0,0,F29/$N$29) -> 0 | G30: =IF($N$29=0,0,G29/$N$29) -> 0 | H30: =IF($N$29=0,0,H29/$N$29) -> 0 | I30: =IF($N$29=0,0,I29/$N$29) -> 0 | ... M30: =IF($N$29=0,0,M29/$N$29) -> 0
A31: 三、审计说明：
A32: 1.XX费用较上期增长XX%，本期大幅增加原因……
A33: 2.XX月XX费用发生额XX，占全年XX%，占比较大的原因……
A34: 3.XX费用测算如下：
A35: 项目 | B35: 计提依据 | C35: 计提比例 | D35: 应计提金额 | E35: 账面计提金额 | F35: 差异金额 | G35: 差异原因 | H35: 是否调整
A36: XX费用 | D36: =B36*C36 -> 0 | F36: =D36-E36 -> 0
A37: XX费用 | D37: =B37*C37 -> 0 | F37: =D37-E37 -> 0
A39: 四、审计结论：
A41: 提示：
A42: 1、本科目核算企业为组织和管理企业生产经营所发生的管理费用，包括企业在筹建期间内发生的开办费、董事会和行政管理部门在企业的经营管理中发生的或者应由企业统一负担的
A43: 公司经费(包括行政管理部门职工工资及福利费、物料消耗、低值易耗品摊销、办公费和差旅费等)、工会经费、董事会费(包括董事会成员津贴、会议费和差旅费等)、聘请中介机构费、咨询费(含顾问费)、诉讼费、业务招待费、技术转让费、矿产资源补偿费、研究费用、排污费等。
A44: 2.不符合固定资产资本化后续支出条件的固定资产日常修理费用，在发生时按照受益对象计入当期损益或计入相关资产的成本。
...

Sheet 调整分录汇总K9-3
A1: 致同会计师事务所
A2: 管理费用调整分录汇总表
A3: =底稿目录!A2 -> 被审计单位： | D3: =底稿目录!A4 -> 编制人： | F3: =底稿目录!A5 -> 编制日期： | I3: 索引号： | J3: =底稿目录!D10 -> K9-3
A4: =底稿目录!A3 -> 会计期间：202X年度 | D4: =底稿目录!A6 -> 复核人： | F4: =底稿目录!A7 -> 复核日期： | I4: 页次：
A5: 调整事项说明 | B5: 类别（报表调整/账项调整/其他） | C5: 报表项目 | D5: 科目名称 | E5: 附注项目 | F5: …… | G5: 借方调整金额 | H5: 贷方调整金额 | I5: 索引 | J5: 备注
A22: 提示：本底稿适用于调整分录较多、较复杂的项目，且仅列示与本报表项目相关的审计调整。项目组可根据项目实际情况选择是否使用该底稿。

Sheet 实质性分析K9-4
A1: 致同会计师事务所
A2: 实质性分析
A3: =底稿目录!A2 -> 被审计单位： | C3: =底稿目录!A4 -> 编制人： | F3: =底稿目录!A5 -> 编制日期： | I3: 索引号： | J3: =底稿目录!D11 -> K9-4
A4: =底稿目录!A3 -> 会计期间：202X年度 | C4: =底稿目录!A6 -> 复核人： | F4: =底稿目录!A7 -> 复核日期： | I4: 页次：
A5: 一、审计目标:
A6: 1.所有应当记录的管理费用均已记录，所有应当包括在财务报表中的相关披露均已包括;
A7: 2.与管理费用有关的金额及其他数据已恰当记录，相关披露已得到恰当计量和描述。
A8: 3.与管理费用有关的金额及其他数据已恰当记录，相关披露已得到恰当计量和描述;
A9: 二、审计过程：
A10: （一）管理费用构成分析表
A11: 项目 | B11: 本期合计 | C11: 结构比 | D11: 占主营业务收入比率 | E11: 上年同期 | F11: 结构比 | G11: 占主营业务收入比率 | H11: 增长比例 | I11: 占主营业务收入比率变动 | J11: 变动分析
A12: ='明细表K9-2'!A11 -> 公司经费 | B12: ='明细表K9-2'!Q11 -> 0 | C12: =IF(B12=0,0,B12/$B$30) -> 0 | D12: =IF(B12=0,0,B12/$B$31) -> 0 | E12: ='明细表K9-2'!W11 -> 0 | F12: =IF(E12=0,0,E12/$E$30) -> 0 | G12: =IF(E12=0,0,E12/$E$31) -> 0 | H12: =IF(AND(E12=0,B12>0),1,IF(AND(E12=0,B12=0),0,(B12-E12)/E12)) -> 0 | I12: =D12-G12 -> 0
A13: ='明细表K9-2'!A12 -> 职工工资 | B13: ='明细表K9-2'!Q12 -> 0 | C13: =IF(B13=0,0,B13/$B$30) -> 0 | D13: =IF(B13=0,0,B13/$B$31) -> 0 | E13: ='明细表K9-2'!W12 -> 0 | F13: =IF(E13=0,0,E13/$E$30) -> 0 | G13: =IF(E13=0,0,E13/$E$31) -> 0 | H13: =IF(AND(E13=0,B13>0),1,IF(AND(E13=0,B13=0),0,(B13-E13)/E13)) -> 0 | I13: =D13-G13 -> 0
A14: ='明细表K9-2'!A13 -> 福利费 | B14: ='明细表K9-2'!Q13 -> 0 | C14: =IF(B14=0,0,B14/$B$30) -> 0 | D14: =IF(B14=0,0,B14/$B$31) -> 0 | E14: ='明细表K9-2'!W13 -> 0 | F14: =IF(E14=0,0,E14/$E$30) -> 0 | G14: =IF(E14=0,0,E14/$E$31) -> 0 | H14: =IF(AND(E14=0,B14>0),1,IF(AND(E14=0,B14=0),0,(B14-E14)/E14)) -> 0 | I14: =D14-G14 -> 0
A15: ='明细表K9-2'!A14 -> 物料消耗 | B15: ='明细表K9-2'!Q14 -> 0 | C15: =IF(B15=0,0,B15/$B$30) -> 0 | D15: =IF(B15=0,0,B15/$B$31) -> 0 | E15: ='明细表K9-2'!W14 -> 0 | F15: =IF(E15=0,0,E15/$E$30) -> 0 | G15: =IF(E15=0,0,E15/$E$31) -> 0 | H15: =IF(AND(E15=0,B15>0),1,IF(AND(E15=0,B15=0),0,(B15-E15)/E15)) -> 0 | I15: =D15-G15 -> 0
A16: ='明细表K9-2'!A15 -> 低值易耗品摊销 | B16: ='明细表K9-2'!Q15 -> 0 | C16: =IF(B16=0,0,B16/$B$30) -> 0 | D16: =IF(B16=0,0,B16/$B$31) -> 0 | E16: ='明细表K9-2'!W15 -> 0 | F16: =IF(E16=0,0,E16/$E$30) -> 0 | G16: =IF(E16=0,0,E16/$E$31) -> 0 | H16: =IF(AND(E16=0,B16>0),1,IF(AND(E16=0,B16=0),0,(B16-E16)/E16)) -> 0 | I16: =D16-G16 -> 0
A17: ='明细表K9-2'!A16 -> 办公费 | B17: ='明细表K9-2'!Q16 -> 0 | C17: =IF(B17=0,0,B17/$B$30) -> 0 | D17: =IF(B17=0,0,B17/$B$31) -> 0 | E17: ='明细表K9-2'!W16 -> 0 | F17: =IF(E17=0,0,E17/$E$30) -> 0 | G17: =IF(E17=0,0,E17/$E$31) -> 0 | H17: =IF(AND(E17=0,B17>0),1,IF(AND(E17=0,B17=0),0,(B17-E17)/E17)) -> 0 | I17: =D17-G17 -> 0
A18: ='明细表K9-2'!A17 -> 差旅费 | B18: ='明细表K9-2'!Q17 -> 0 | C18: =IF(B18=0,0,B18/$B$30) -> 0 | D18: =IF(B18=0,0,B18/$B$31) -> 0 | E18: ='明细表K9-2'!W17 -> 0 | F18: =IF(E18=0,0,E18/$E$30) -> 0 | G18: =IF(E18=0,0,E18/$E$31) -> 0 | H18: =IF(AND(E18=0,B18>0),1,IF(AND(E18=0,B18=0),0,(B18-E18)/E18)) -> 0 | I18: =D18-G18 -> 0
A19: ='明细表K9-2'!A18 -> 工会经费 | B19: ='明细表K9-2'!Q18 -> 0 | C19: =IF(B19=0,0,B19/$B$30) -> 0 | D19: =IF(B19=0,0,B19/$B$31) -> 0 | E19: ='明细表K9-2'!W18 -> 0 | F19: =IF(E19=0,0,E19/$E$30) -> 0 | G19: =IF(E19=0,0,E19/$E$31) -> 0 | H19: =IF(AND(E19=0,B19>0),1,IF(AND(E19=0,B19=0),0,(B19-E19)/E19)) -> 0 | I19: =D19-G19 -> 0
A20: ='明细表K9-2'!A19 -> 董事会费 | B20: ='明细表K9-2'!Q19 -> 0 | C20: =IF(B20=0,0,B20/$B$30) -> 0 | D20: =IF(B20=0,0,B20/$B$31) -> 0 | E20: ='明细表K9-2'!W19 -> 0 | F20: =IF(E20=0,0,E20/$E$30) -> 0 | G20: =IF(E20=0,0,E20/$E$31) -> 0 | H20: =IF(AND(E20=0,B20>0),1,IF(AND(E20=0,B20=0),0,(B20-E20)/E20)) -> 0 | I20: =D20-G20 -> 0
A21: ='明细表K9-2'!A20 -> 聘请中介机构费 | B21: ='明细表K9-2'!Q20 -> 0 | C21: =IF(B21=0,0,B21/$B$30) -> 0 | D21: =IF(B21=0,0,B21/$B$31) -> 0 | E21: ='明细表K9-2'!W20 -> 0 | F21: =IF(E21=0,0,E21/$E$30) -> 0 | G21: =IF(E21=0,0,E21/$E$31) -> 0 | H21: =IF(AND(E21=0,B21>0),1,IF(AND(E21=0,B21=0),0,(B21-E21)/E21)) -> 0 | I21: =D21-G21 -> 0
A22: ='明细表K9-2'!A21 -> 咨询费（含顾问费） | B22: ='明细表K9-2'!Q21 -> 0 | C22: =IF(B22=0,0,B22/$B$30) -> 0 | D22: =IF(B22=0,0,B22/$B$31) -> 0 | E22: ='明细表K9-2'!W21 -> 0 | F22: =IF(E22=0,0,E22/$E$30) -> 0 | G22: =IF(E22=0,0,E22/$E$31) -> 0 | H22: =IF(AND(E22=0,B22>0),1,IF(AND(E22=0,B22=0),0,(B22-E22)/E22)) -> 0 | I22: =D22-G22 -> 0
A23: ='明细表K9-2'!A22 -> 诉讼费 | B23: ='明细表K9-2'!Q22 -> 0 | C23: =IF(B23=0,0,B23/$B$30) -> 0 | D23: =IF(B23=0,0,B23/$B$31) -> 0 | E23: ='明细表K9-2'!W22 -> 0 | F23: =IF(E23=0,0,E23/$E$30) -> 0 | G23: =IF(E23=0,0,E23/$E$31) -> 0 | H23: =IF(AND(E23=0,B23>0),1,IF(AND(E23=0,B23=0),0,(B23-E23)/E23)) -> 0 | I23: =D23-G23 -> 0
... A29: ='明细表K9-2'!A28 -> …… | B29: ='明细表K9-2'!Q28 -> 0 | C29: =IF(B29=0,0,B29/$B$30) -> 0 | D29: =IF(B29=0,0,B29/$B$31) -> 0 | E29: ='明细表K9-2'!W28 -> 0 | F29: =IF(E29=0,0,E29/$E$30) -> 0 | G29: =IF(E29=0,0,E29/$E$31) -> 0 | H29: =IF(AND(E29=0,B29>0),1,IF(AND(E29=0,B29=0),0,(B29-E29)/E29)) -> 0 | I29: =D29-G29 -> 0
A30: 合计 | B30: =SUM(B12:B29) -> 0 | C30: =IF(B30=0,0,B30/$B$30) -> 0 | D30: =IF(B30=0,0,B30/$B$31) -> 0 | E30: =SUM(E12:E29) -> 0 | F30: =IF(E30=0,0,E30/$E$30) -> 0 | G30: =IF(E30=0,0,E30/$E$31) -> 0 | H30: =IF(AND(E30=0,B30>0),1,IF(AND(E30=0,B30=0),0,(B30-E30)/E30)) -> 0 | I30: =D30-G30 -> 0
A31: 主营业务收入 | H31: =IF(AND(E31=0,B31>0),1,IF(AND(E31=0,B31=0),0,(B31-E31)/E31)) -> 0
A32: 管理费用占主营业务收入比率 | B32: =B30/B31 -> #DIV/0! | E32: =E30/E31 -> #DIV/0!
A33: （二）管理费用与预算及其他非财务数据对比分析表
A34: 项目 | B34: 本期发生额 | C34: 预算金额 | D34: …… | E34: 占比
A35: 管理费用 | B35: =B30 -> 0 | E35: =B35/C35 -> #DIV/0!
A36: （三）费用指标分析表（与同行业数据比较）
A37: 指标 | B37: 本期 | C37: 行业公司A | D37: 行业公司B | E37: 行业公司C | F37: 比较分析
A38: 管理费用占主营业务收入比率 | B38: =B32 -> #DIV/0!
A39: 三、审计说明：
A40: 1.费用各项目近两年比重变动较大的原因： | E40: 2.与上年同期数据相比，费用指标异常的原因：
A41: a. | E41: a.
A42: b. | E42: b.
A43: 3.与同行业数据相比，费用指标异常的原因： | E43: 4.与预算金额及其他非财务数据相比，费用指标异常的原因：
A44: a. | E44: a.
A45: b. | E45: b.
...

Sheet 合同检查表K9-5
A1: 致同会计师事务所
A2: 管理费用合同检查表
A3: =底稿目录!A2 -> 被审计单位： | H3: =底稿目录!A4 -> 编制人： | K3: =底稿目录!A5 -> 编制日期： | P3: 索引号： | Q3: =底稿目录!D12 -> K9-5
A4: =底稿目录!A3 -> 会计期间：202X年度 | H4: =底稿目录!A6 -> 复核人： | K4: =底稿目录!A7 -> 复核日期： | P4: 页次：
A5: 一、审计目标:
A6: 1.所有应当记录的管理费用均已记录，所有应当包括在财务报表中的相关披露均已包括; 2.与管理费用有关的金额及其他数据已恰当记录，相关披露已得到恰当计量和描述;
A7: 3.与管理费用有关的金额及其他数据已恰当记录，相关披露已得到恰当计量和描述； 4. 管理费用已记录于正确的会计期间
A8: 二、审计过程：
B9: 摊销期初： | C9: 45658 | D9: 摊销期末： | E9: 46022
A10: 项目 | B10: 对方单位 | C10: 合同/协议内容 | D10: 合同/协议金额 | E10: 实际开票方 | F10: 支付条件 | G10: 支付时间 | H10: 合同/协议开始日期 | I10: 合同/协议结束日期 | J10: 合同总月份 | K10: 本期应计月份 | L10: 本期应计损益 | M10: 本期已计损益 | N10: 差异 | O10: 合同索引 | P10: 凭证检查索引 | Q10: 审计结论
A11: 律师费 | J11: =IF(OR($E$9="",H11="",$C$9="",I11=""),0,DATEDIF(H11,I11,"m")+1) -> 0 | K11: =IF(OR($E$9="",H11="",$C$9="",I11=""),0,IF(H11>$E$9,0,IF(H11=0,0,IF(AND(H11<$C$9,I11>$E$9),VALUE(DATEDIF($C$9,$E$9,"m")+1),IF(AND(H11<$C$9,I11<=$E$9),VALUE(DATEDIF($C$9,I11,"m")+1),IF(AND(H11>=$C$9,I11>$E$9),VALUE(DATEDIF(H11,$E$9,"m")+1),IF(AND(H11>=$C$9,I11<=$E$9),VALUE(DATEDIF(H11,I11,"m")+1),))))))) -> 0 | L11: =IF(K11=0,0,K11/J11*D11) -> 0 | N11: =L11-M11 -> 0
A12: 咨询费 | J12: =IF(OR($E$9="",H12="",$C$9="",I12=""),0,DATEDIF(H12,I12,"m")+1) -> 0 | K12: =IF(OR($E$9="",H12="",$C$9="",I12=""),0,IF(H12>$E$9,0,IF(H12=0,0,IF(AND(H12<$C$9,I12>$E$9),VALUE(DATEDIF($C$9,$E$9,"m")+1),IF(AND(H12<$C$9,I12<=$E$9),VALUE(DATEDIF($C$9,I12,"m")+1),IF(AND(H12>=$C$9,I12>$E$9),VALUE(DATEDIF(H12,$E$9,"m")+1),IF(AND(H12>=$C$9,I12<=$E$9),VALUE(DATEDIF(H12,I12,"m")+1),))))))) -> 0 | L12: =IF(K12=0,0,K12/J12*D12) -> 0 | N12: =L12-M12 -> 0
A13: 租赁费 | J13: =IF(OR($E$9="",H13="",$C$9="",I13=""),0,DATEDIF(H13,I13,"m")+1) -> 0 | K13: =IF(OR($E$9="",H13="",$C$9="",I13=""),0,IF(H13>$E$9,0,IF(H13=0,0,IF(AND(H13<$C$9,I13>$E$9),VALUE(DATEDIF($C$9,$E$9,"m")+1),IF(AND(H13<$C$9,I13<=$E$9),VALUE(DATEDIF($C$9,I13,"m")+1),IF(AND(H13>=$C$9,I13>$E$9),VALUE(DATEDIF(H13,$E$9,"m")+1),IF(AND(H13>=$C$9,I13<=$E$9),VALUE(DATEDIF(H13,I13,"m")+1),))))))) -> 0 | L13: =IF(K13=0,0,K13/J13*D13) -> 0 | N13: =L13-M13 -> 0
A14: 修理费 | J14: =IF(OR($E$9="",H14="",$C$9="",I14=""),0,DATEDIF(H14,I14,"m")+1) -> 0 | K14: =IF(OR($E$9="",H14="",$C$9="",I14=""),0,IF(H14>$E$9,0,IF(H14=0,0,IF(AND(H14<$C$9,I14>$E$9),VALUE(DATEDIF($C$9,$E$9,"m")+1),IF(AND(H14<$C$9,I14<=$E$9),VALUE(DATEDIF($C$9,I14,"m")+1),IF(AND(H14>=$C$9,I14>$E$9),VALUE(DATEDIF(H14,$E$9,"m")+1),IF(AND(H14>=$C$9,I14<=$E$9),VALUE(DATEDIF(H14,I14,"m")+1),))))))) -> 0 | L14: =IF(K14=0,0,K14/J14*D14) -> 0 | N14: =L14-M14 -> 0
A15: 保险费 | J15: =IF(OR($E$9="",H15="",$C$9="",I15=""),0,DATEDIF(H15,I15,"m")+1) -> 0 | K15: =IF(OR($E$9="",H15="",$C$9="",I15=""),0,IF(H15>$E$9,0,IF(H15=0,0,IF(AND(H15<$C$9,I15>$E$9),VALUE(DATEDIF($C$9,$E$9,"m")+1),IF(AND(H15<$C$9,I15<=$E$9),VALUE(DATEDIF($C$9,I15,"m")+1),IF(AND(H15>=$C$9,I15>$E$9),VALUE(DATEDIF(H15,$E$9,"m")+1),IF(AND(H15>=$C$9,I15<=$E$9),VALUE(DATEDIF(H15,I15,"m")+1),))))))) -> 0 | L15: =IF(K15=0,0,K15/J15*D15) -> 0 | N15: =L15-M15 -> 0
A16: 物业费 | J16: =IF(OR($E$9="",H16="",$C$9="",I16=""),0,DATEDIF(H16,I16,"m")+1) -> 0 | K16: =IF(OR($E$9="",H16="",$C$9="",I16=""),0,IF(H16>$E$9,0,IF(H16=0,0,IF(AND(H16<$C$9,I16>$E$9),VALUE(DATEDIF($C$9,$E$9,"m")+1),IF(AND(H16<$C$9,I16<=$E$9),VALUE(DATEDIF($C$9,I16,"m")+1),IF(AND(H16>=$C$9,I16>$E$9),VALUE(DATEDIF(H16,$E$9,"m")+1),IF(AND(H16>=$C$9,I16<=$E$9),VALUE(DATEDIF(H16,I16,"m")+1),))))))) -> 0 | L16: =IF(K16=0,0,K16/J16*D16) -> 0 | N16: =L16-M16 -> 0
A17: … | J17: =IF(OR($E$9="",H17="",$C$9="",I17=""),0,DATEDIF(H17,I17,"m")+1) -> 0 | K17: =IF(OR($E$9="",H17="",$C$9="",I17=""),0,IF(H17>$E$9,0,IF(H17=0,0,IF(AND(H17<$C$9,I17>$E$9),VALUE(DATEDIF($C$9,$E$9,"m")+1),IF(AND(H17<$C$9,I17<=$E$9),VALUE(DATEDIF($C$9,I17,"m")+1),IF(AND(H17>=$C$9,I17>$E$9),VALUE(DATEDIF(H17,$E$9,"m")+1),IF(AND(H17>=$C$9,I17<=$E$9),VALUE(DATEDIF(H17,I17,"m")+1),))))))) -> 0 | L17: =IF(K17=0,0,K17/J17*D17) -> 0 | N17: =L17-M17 -> 0
J18: =IF(OR($E$9="",H18="",$C$9="",I18=""),0,DATEDIF(H18,I18,"m")+1) -> 0 | K18: =IF(OR($E$9="",H18="",$C$9="",I18=""),0,IF(H18>$E$9,0,IF(H18=0,0,IF(AND(H18<$C$9,I18>$E$9),VALUE(DATEDIF($C$9,$E$9,"m")+1),IF(AND(H18<$C$9,I18<=$E$9),VALUE(DATEDIF($C$9,I18,"m")+1),IF(AND(H18>=$C$9,I18>$E$9),VALUE(DATEDIF(H18,$E$9,"m")+1),IF(AND(H18>=$C$9,I18<=$E$9),VALUE(DATEDIF(H18,I18,"m")+1),))))))) -> 0 | L18: =IF(K18=0,0,K18/J18*D18) -> 0 | N18: =L18-M18 -> 0
J19: =IF(OR($E$9="",H19="",$C$9="",I19=""),0,DATEDIF(H19,I19,"m")+1) -> 0 | K19: =IF(OR($E$9="",H19="",$C$9="",I19=""),0,IF(H19>$E$9,0,IF(H19=0,0,IF(AND(H19<$C$9,I19>$E$9),VALUE(DATEDIF($C$9,$E$9,"m")+1),IF(AND(H19<$C$9,I19<=$E$9),VALUE(DATEDIF($C$9,I19,"m")+1),IF(AND(H19>=$C$9,I19>$E$9),VALUE(DATEDIF(H19,$E$9,"m")+1),IF(AND(H19>=$C$9,I19<=$E$9),VALUE(DATEDIF(H19,I19,"m")+1),))))))) -> 0 | L19: =IF(K19=0,0,K19/J19*D19) -> 0 | N19: =L19-M19 -> 0
J20: =IF(OR($E$9="",H20="",$C$9="",I20=""),0,DATEDIF(H20,I20,"m")+1) -> 0 | K20: =IF(OR($E$9="",H20="",$C$9="",I20=""),0,IF(H20>$E$9,0,IF(H20=0,0,IF(AND(H20<$C$9,I20>$E$9),VALUE(DATEDIF($C$9,$E$9,"m")+1),IF(AND(H20<$C$9,I20<=$E$9),VALUE(DATEDIF($C$9,I20,"m")+1),IF(AND(H20>=$C$9,I20>$E$9),VALUE(DATEDIF(H20,$E$9,"m")+1),IF(AND(H20>=$C$9,I20<=$E$9),VALUE(DATEDIF(H20,I20,"m")+1),))))))) -> 0 | L20: =IF(K20=0,0,K20/J20*D20) -> 0 | N20: =L20-M20 -> 0
A21: 三、审计说明：
A22: 1.已对XXX进行检查….
A23: 2.XXX
A25: 四、审计结论：

Sheet 截止性测试(从记账凭证至原始凭证）K9-6
A1: 致同会计师事务所
A2: 管理费用截止性测试(从记账凭证至原始凭证）
A3: =底稿目录!A2 -> 被审计单位： | E3: =底稿目录!A4 -> 编制人： | G3: =底稿目录!A5 -> 编制日期： | J3: 索引号： | K3: =底稿目录!D13 -> K9-6
A4: =底稿目录!A3 -> 会计期间：202X年度 | E4: =底稿目录!A6 -> 复核人： | G4: =底稿目录!A7 -> 复核日期： | J4: 页 次：
A5: 一、审计目标：
A6: 确认管理费用已记录于正确的会计期间。
A7: 二、样本选取标准与规模：
A8: 1.抽取资产负债表日前后（____）天的（____）张记账凭证，实施截止性测试，评价费用是否被记录于正确的会计期间；
A9: 2.对于首次承接的客户，执行前期期末的截止性测试。（适用于首次承接）
A10: 提示：如果存在跨期舞弊风险或者所检查样本中发现有跨期的，应扩大测试期间和样本，甚至可以考虑将截止测试期间延长至审计报告日。同时考虑是否存在内控缺陷。
A11: 三、测试：
A12: 序号 | B12: 记账凭证 | G12: 支出凭单 | J12: 是否跨期 | K12: 跨期金额
B13: 日期 | C13: 凭证编号 | D13: 业务内容 | E13: 对方科目 | F13: 金额 | G13: 凭单编号 | H13: 凭单日期 | I13: 金额
A14: 1
A15: 2
A16: 3
A17: 4
A18: 5
A19: 6
A20: 7
A21: 8
A22: 9
A23: 10
A24: ……
A25: ——————截止日期：202X年12月31日——————
A26: 1
A27: 2
A28: 3
A29: 4
A30: 5
A31: 6
A32: 7
A33: 8
A34: 9
A35: 10
A36: ……
A37: 四、审计说明：
A40: 五、审计结论

Sheet 截止性测试（从原始凭证至记账凭证）K9-7
A1: 致同会计师事务所
A2: 管理费用截止性测试（从原始凭证至记账凭证）
A3: =底稿目录!A2 -> 被审计单位： | E3: =底稿目录!A4 -> 编制人： | H3: =底稿目录!A5 -> 编制日期： | J3: 索引号： | K3: =底稿目录!D14 -> K9-7
A4: =底稿目录!A3 -> 会计期间：202X年度 | E4: =底稿目录!A6 -> 复核人： | H4: =底稿目录!A7 -> 复核日期： | J4: 页 次：
A5: 一、审计目标：
A6: 确认管理费用已记录于正确的会计期间。
A7: 二、样本选取标准与规模：
A8: 1.选取资产负债日后（____）天的的银行对账单或付款凭证、支出凭单（____）张，检查支持性文件，关注凭单的日期，检查费用是否记录于正确的会计期间，是否存在有未入帐的负债；
A9: 2.对于首次承接的客户，执行前期期末的截止性测试；（适用于首次承接）
A10: 提示：如果存在跨期舞弊风险或者所检查样本中发现有跨期的，应扩大测试期间和样本，甚至可以考虑将截止测试期间延长至审计报告日。同时考虑是否存在内控缺陷。
A11: 三、测试：
A12: 序号 | B12: 支出凭单 | E12: 记账凭证 | J12: 是否跨期 | K12: 跨期金额
B13: 凭单编号 | C13: 凭单日期 | D13: 金额 | E13: 日期 | F13: 凭证编号 | G13: 业务内容 | H13: 对方科目 | I13: 金额
A14: 1
A15: 2
A16: 3
A17: 4
A18: 5
A19: 6
A20: 7
A21: 8
A22: 9
A23: 10
A24: ……
A25: ——————截止日期：202X年12月31日——————
A26: 1
A27: 2
A28: 3
A29: 4
A30: 5
A31: 6
A32: 7
A33: 8
A34: 9
A35: 10
A36: ……
A37: 四、审计说明：
A40: 五、审计结论

Sheet 管理费用检查表K9-8
A1: 致同会计师事务所
A2: 管理费用检查表
A3: =底稿目录!A2 -> 被审计单位： | F3: =底稿目录!A4 -> 编制人： | I3: =底稿目录!A5 -> 编制日期： | P3: 索引号： | Q3: =底稿目录!D15 -> K9-8
A4: =底稿目录!A3 -> 会计期间：202X年度 | F4: =底稿目录!A6 -> 复核人： | I4: =底稿目录!A7 -> 复核日期： | P4: 页 次：
A5: 一、测试目标：
A6: 1.所有应当记录的管理费用均已记录，所有应当包括在财务报表中的相关披露均已包括;
A7: 2.与管理费用有关的金额及其他数据已恰当记录，相关披露已得到恰当计量和描述； 3. 管理费用已记录于正确的会计期间
A8: 二、样本选取标准与规模：
A9: 测试总体一般不包括：结转损益、职工薪酬/折旧计提、无形资产及长期费用摊销、各项税费计提等凭证。
A10: 测试总体： | B10: 如借方发生额所有凭证共XX笔金额XX、贷方发生额所有凭证共XX笔金额XX | G10: 特定样本： | H10: XX金额以上（大额）、关联方/关联交易形成的款项、XX异常款项全部测试，共XX笔；
A11: 抽样总体： | B11: 测试总体扣除特定样本以外的样本，共XX笔、金额XX | G11: 确定的抽样样本量： | H11: 抽取XX笔 | I11: （如果使用了样本计算器计算样本量，样本量计算过程见<XX>底稿）
A12: 抽样方法： | B12: 随机选样/系统选样/货币单元抽样/随意选样（非统计抽样适用） | G12: 抽样过程： | H12: 使用IDEA（XX抽样工具）选择XX数量、金额XX的样本进行测试，抽样工具中的样本选择过程和结果见<XX>底稿
A13: 三、测试：
A14: 测试内容说明：1.原始凭证是否齐全； 2.记账凭证与原始凭证是否相符；3.账务处理是否正确；4.是否记录于恰当的会计期间；5.……
A15: 费用明细项目 | B15: 记账凭证 | H15: 支持性文件 | J15: 核对内容 | O15: 索引号 | P15: 是否异常 | Q15: 备注说明
B16: 日期 | C16: 凭证编号 | D16: 业务内容 | E16: 对方科目 | F16: 对方明细科目 | G16: 借方金额 | J16: 1 | K16: 2 | L16: 3 | M16: 4 | N16: 5
H17: 付款审批单、费用报销单、支出凭单、银行回单、合同……
A31: 合计 | G31: =SUM(G17:G30) -> 0
A32: 本期发生额 | G32: ='明细表K9-2'!Q29 -> 0
A33: 检查比例 | G33: =G31/G32 -> #DIV/0!
A34: 四、审计说明：
A35: 1.如果检查比例较低应扩大检查样本量或说明原因
A37: 五、审计结论：
