Workbook

Sheet 底稿目录
A1: 底稿开列时，可先在以下单元格填写有关内容，以便其他底稿引用有关数据：
A2: 被审计单位名称：
A3: 截止日：202X年12月31日 | D3: 序号 | E3: 内容 | F3: 索引号
A4: 编制人： | D4: 1 | E4: 程序表 | F4: D1A
A5: 编制日期： | D5: 2 | E5: 审定表 | F5: D1-1
A6: 复核人： | D6: 3 | E6: 附注披露信息(上市公司) | G6: 无需打印
A7: 复核日期： | D7: 4 | E7: 附注披露信息(国企) | G7: 无需打印
D8: 5 | E8: 原值明细表（按类别） | F8: D1-2
A9: 关于工作底稿与审计程序索引号对应的说明 | D9: 6 | E9: 原值明细表（按客户） | F9: D1-3
A10: 1.编制的审计工作底稿应与审计程序对应。审计项目组应根据被审计单位实际情况和风险评估情况在实质性程序表中裁剪、修改或增加审计程序，根据实际执行的审计程序完成相应审计工作底稿，编制的工作底稿中应按自然顺序依次编制索引号，并通过唯一的索引号将与实质性程序表中的程序对应关联（即将工作底稿的索引号填入实质性程序表中的底稿索引号列）。 | D10: 7 | E10: 坏账准备明细表 | F10: D1-4
D11: 8 | E11: 调整分录汇总表 | F11: D1-5
D12: 9 | E12: 应收票据业务模式分析 | F12: D1-6
D13: 10 | E13: 应收票据备查簿核对 | F13: D1-7
A14: 2.获取的支持性证据应与审计底稿或程序对应。审计项目组在完成底稿时获取的支持性证据应根据底稿索引号编制下一级按自然顺序排序的索引号（如D1-2-1、D1-2-2、……），并在底稿中说明引用的支持性证据、关联索引号。 | D14: 11 | E14: 应收票据贴现、票据已背书未到期明细表 | F14: D1-8
D15: 12 | E15: 应收票据贴息检查表 | F15: D1-9
D16: 13 | E16: 应收票据监盘表 | F16: D1-10
A17: 3.工作底稿索引号的编码规则：实质性程序索引号按循环从“D”到“N”,循环内账户以顺序号排列，模板中底稿索引号按账户顺序+自然数顺序（即模板中索引号按二级自然顺序排列，如D1-1、D1-2、D1-3、……D1-N）。 | D17: 14 | E17: 关联方及交易检查表 | F17: D1-11
D18: 15 | E18: 应收票据质押检查表 | F18: D1-12
D19: 16 | E19: 函证结果汇总表 | F19: D0-1
D20: 17 | E20: 核实被函证单位信息 | F20: D0-2
D21: 18 | E21: 跟函函证过程控制 | F21: D0-3
D22: 19 | E22: 函证差异调节表 | F22: D0-4
D23: 20 | E23: 应收及销售替代程序检查表 | F23: D0-6
D24: 21 | E24: 邮件传真回函可靠性验证 | F24: D0-7
D25: 22 | E25: 函证程序舞弊风险评价表 | F25: D0-8
D26: 23 | E26: 应收票据检查表 | F26: D1-13
D27: 24 | E27: 坏账准备会计政策检查 | F27: D1-14
D28: 25 | E28: 坏账准备测试表 | F28: D1-15
D29: 26 | E29: 坏账准备转回、核销检查表 | F29: D1-16

Sheet 应收票据审计程序表D1A
A1: 致同会计师事务所
A2: 应收票据实质性程序表
A3: =底稿目录!A2 -> 被审计单位名称： | C3: =底稿目录!A4 -> 编制人： | F3: =底稿目录!A5 -> 编制日期： | H3: 索引号： | I3: D1A
A4: =底稿目录!A3 -> 截止日：202X年12月31日 | C4: =底稿目录!A6 -> 复核人： | F4: =底稿目录!A7 -> 复核日期： | H4: 页次：
A5: 一、本账户涉及的科目
A6: 应收票据
A7: 二、审计目标和财务报表的认定
A8: 审计目标 | G8: 财务报表的认定
A9: A. 资产负债表中记录的应收票据是存在的，且已经记录在恰当的账户中 | G9: 存在
A10: B. 所有应记录的应收票据均已记录，所有应当包括在财务报表中的相关披露均已包括 | G10: 完整性
A11: C. 记录的应收票据由被审计单位拥有或控制 | G11: 权利和义务
A12: D. 应收票据以恰当的金额包括在财务报表中，与之相关的计价或分摊调整已恰当记录，相关披露已得到恰当计量和描述 | G12: 准确性、计价和分摊
A13: E. 应收票据已被恰当地汇总或分解且表述清楚，相关披露在按照企业会计准则的编制基础下是相关的、可理解的 | G13: 列报
A14: 三、计划实施的实质性程序
A15: 序号 | B15: 审计程序 | C15: 程序分类 | D15: 财务报表的认定 | I15: 底稿索引
D16: 存在 | E16: 完整性 | F16: 权利和 义务 | G16: 准确性、计价和分摊 | H16: 列报 | J16: 根据被审计单位实际情况和风险评估情况裁剪、修改或增加审计程序
A17: 1 | B17: 获取或编制应收票据明细表，完成以下工作，并编制审定表： （1）复核加计是否正确，与总账、明细账合计数核对是否相符，期初余额与上期审定期末余额是否相符； （2）结合坏账准备明细表与报表核对是否相符； （3）检查已逾期应收票据是否结转至应收账款。 | C17: 常规★ | D17: √ | E17: √ | G17: √ | I17: D1-1 /D1-2 /D1-3 /D1-4
A18: 2 | B18: 在使用手工编制、自定义信息报告、系统生成的非固定格式报告等由被审计单位生成的信息时，测试有关信息准确性和完整性，并考虑针对编制和维护由被审计单位生成的信息的相关控制实施控制测试，以评价该信息是否能够为实现审计目的提供基础。 | C18: 常规★ | E18: √ | G18: √ | I18: T1 | J18: 可参见《审计手册》4.2.6，由被审计单位生成的信息可能是由系统生成的、或手工编制的、或二者兼而有之的方式生成的。例如，由被审计单位生成的信息可能包括： • 不涉及自定义的、由系统生成的报告（如，固定格式报告）； • 可能通过人工自定义的、由系统生成的报告，例如，（计算机）查询信息或特别定制的报告； • 手工编制的信息，例如，汇总信息的电子表格或用以支持分配、计算以及调节的电子表格； • 其他系统生成或手工编制的信息，例如，由被审计单位编制的客户发票； • 通过影印、拍摄、扫描或其他方式转换成电子形式的文件记录。
A19: 3 | B19: 取得应收票据期初余额明细表复核加计是否正确，与总账、明细账合计数是否相符；检查期初票据在本期承兑、背书等情况，必要时考虑函证期初余额以及其他必要追加的审计程序。（适用于首次承接） | C19: 备选 | D19: √ | E19: √ | F19: √ | G19: √ | J19: 由被审计单位生成的信息不包括： • 总分类账或明细分类账、试算平衡表、或经审计的财务报表； • 第三方（除了服务机构）的报表或报告，例如，原始银行对账单，或函证的回函； • 外部数据（例如，第三方发布的数据，如，定价来源）。
A20: 4 | B20: 了解并观察被审计单位被审计单位管理应收票据的业务模式，结合合同现金流量特征，判断应收票据分类是否正确。 | C20: 常规★ | H20: √ | I20: D1-6 | J20: 应收票据中的由被审计单位生成的信息例如：收票据备查簿等
A21: 5 | B21: 取得“应收票据备查簿”核对相关内容是否与账面记录一致，如果存在差异应追查原因，并取得支持性证据。 | C21: 常规★ | D21: √ | E21: √ | I21: D1-7
A22: 6 | B22: 对于贴现、背书的应收票据业务：编制已贴现或已背书未到期票据清单确定会计处理是否正确，复核贴现息计算是否正确，检查是否存在贴现保证金。 | C22: 常规★ | D22: √ | F22: √ | G22: √ | I22: D1-8 /D1-9
A23: 7 | B23: 监盘库存票据： （1）与“应收票据备查簿”的有关内容核对记录是否相符； （2）监盘应形成审计记录。对于电子票据应当在被审计单位人员协助下进入电子汇票系统核对票据并记录登录过程、取得系统截图；纸质票据应取得票据原件，并保留复印件。 （3）关注是否对背书转让或贴现的票据负有连带责任、是否存在已作质押或和银行退回的票据，了解具体情况并检查相应支持性证据。 | C23: 常规★ | D23: √ | E23: √ | F23: √ | G23: √ | I23: D1-10
A24: 8 | B24: 分析带息票据的利息是否合理，是否高于其他同类交易水平；复核利息计算是否正确；检查相关会计处理是否正确。 | C24: 备选 | G24: √
A25: 9 | B25: 检查应收票据关联方款项： （1）了解交易的商业理由、交易事项的目的、价格和条件，考虑对关联方应收票据的合理性、合法性； （2）检查对关联方应收票据的真实性相关的支持性文件、检查会计处理是否正确； （3）考虑向关联方或其他注册会计师函证重大的关联销售交易（包括担保和其他重要信息）； （4）必要时，向与交易相关的人员和机构（如银行、律师）函证或与其讨论有关信息。 （5）考虑是否存在未识别的关联方，关联余额披露是否正确。 | C25: 常规★ | D25: √ | E25: √ | F25: √ | G25: √ | H25: √ | I25: D1-11
A26: 10 | B26: 结合借款等债务审计，检查是否存在质押、担保等所有权受到限制的票据。 | C26: 常规★ | F26: √ | I26: D1-12
A27: 11 | B27: 实施函证程序： （1）以积极方式对应收票据进行函证，设计询证函、发函前核实被函证单位信息； （2）注册会计师独立收发询证函； （3）编制函证结果汇总表，检查发函、回函物流信息和轨迹、比对回函印章和签字等以核实回函的真实性，检查回函是否相符，对不符事项查明原因确定是否存在错报； （4）如果未收到回函，应当考虑与被询证者联系，要求对方作出回应或再次寄发询证函，无法收到的回函实施替代程序； （5）如果管理层不允许寄发询证函的，询问管理层不允许寄发的原因，并就其原因的正当、合理性收集证据；考虑实施替代审计程序以获取相关、可靠的审计证据； （6）如果管理层不允许寄发询证函的原因不合理、或者认为回函不可靠，评价对评估的重大错报风险以及其他审计程序的性质、时间安排和范围的影响，并确定其对审计工作和审计意见的影响。 | C27: 常规★ | D27: √ | E27: √ | F27: √ | G27: √ | I27: D0
A28: 12 | B28: 对于大额票据，取得相应销售合同或协议、销售发票和出库单等原始交易资料并进行核对，以证实是否存在真实交易。 | C28: 常规★ | D28: √ | G28: √ | I28: D1-13
A29: 13 | B29: 对于至审计时已兑现或已贴现的应收票据，检查收款凭证等，以确认其在资产负债表日的真实性。 | C29: 常规★ | D29: √ | I29: D1-13
A30: 14 | B30: 检查应收票据坏账准备计提是否正确： （1）了解应收票据坏账准备计提会计政策，确定应收票据坏账准备计提是否以预期信用损失为基础计提，计提政策是否恰当，是否一贯执行。 （2）重新计算应计提的坏账准备，与被审计单位已记录的坏账准备进行比较。 （3）关注大额坏账准备转回是否合理。实际发生坏账损失的，检查核销依据是否符合有关规定，会计处理是否正确。已经确认并核销的坏账重新收回的，检查其会计处理是否正确。 | C30: 常规★ | G30: √ | I30: /D1-14 /D1-15 /D1-16
A31: 15 | B31: 结合营业收入、应收账款等科目审计，核对是否存在未入账应收票据。 | C31: 备选 | E31: √
A32: 16 | B32: 对于票据使用频繁、存在交易异常的客户应收票据，应结合收入、应收账款等科目核对是否存在超出交易额的票据；检查票据流转信息上所有前后手之间以及与被审计单位之间是否存在关联关系，核实交易是否真实。 | C32: IPO/上市公司/新三板/舞弊应对 | D32: √
A33: 17 | B33: 针对评估的舞弊风险等因素增加的审计程序。 | C33: IPO/上市公司/新三板/舞弊应对
A34: 18 | B34: 检查应收票据是否已按企业会计准则或其他适用的规定在财务报表中做出恰当列报和披露。 | C34: 常规★ | H34: √ | I34: A 1-1/A1-15 /A1-16

Sheet 审定表D1-1
A1: 致同会计师事务所
A2: 应收票据审定表
A3: =底稿目录!A2 -> 被审计单位名称： | E3: =底稿目录!A4 -> 编制人： | H3: =底稿目录!A5 -> 编制日期： | K3: 索引号： | L3: D1-1
A4: =底稿目录!A3 -> 截止日：202X年12月31日 | E4: =底稿目录!A6 -> 复核人： | H4: =底稿目录!A7 -> 复核日期： | K4: 页次：
A5: 项目 | B5: 期初数 | F5: 期末数 | J5: 期末与期初审定数比较 | L5: 原因分析
B6: 未审数 | C6: 账项调整 | D6: 重分类调整 | E6: 审定数 | F6: 未审数 | G6: 账项调整 | H6: 重分类调整 | I6: 审定数 | J6: 变动额 | K6: 变动率
A7: 一、应收票据原值
A8: 银行承兑汇票 | B8: ='原值明细表（按类别）D1-2'!B14 -> 0 | C8: ='原值明细表（按类别）D1-2'!C14 -> 0 | D8: ='原值明细表（按类别）D1-2'!D14 -> 0 | E8: =B8+C8+D8 -> 0 | F8: ='原值明细表（按类别）D1-2'!H11 -> 0 | G8: ='原值明细表（按类别）D1-2'!I11 -> 0 | H8: ='原值明细表（按类别）D1-2'!J11 -> 0 | I8: =F8+G8+H8 -> 0 | J8: =I8-E8 -> 0 | K8: =IF(AND(E8=0,I8=0),"",IF(AND(E8=0,I8>0),1,J8/E8))
A9: 商业承兑汇票 | B9: ='原值明细表（按类别）D1-2'!B13 -> 0 | C9: ='原值明细表（按类别）D1-2'!C13 -> 0 | D9: ='原值明细表（按类别）D1-2'!D13 -> 0 | E9: =B9+C9+D9 -> 0 | F9: ='原值明细表（按类别）D1-2'!H13 -> 0 | G9: ='原值明细表（按类别）D1-2'!I13 -> 0 | H9: ='原值明细表（按类别）D1-2'!J13 -> 0 | I9: =F9+G9+H9 -> 0 | J9: =I9-E9 -> 0 | K9: =IF(AND(E9=0,I9=0),"",IF(AND(E9=0,I9>0),1,J9/E9))
A10: 小计 | B10: =SUM(B8:B9) -> 0 | C10: =SUM(C8:C9) -> 0 | D10: =SUM(D8:D9) -> 0 | E10: =SUM(E8:E9) -> 0 | F10: =SUM(F8:F9) -> 0 | G10: =SUM(G8:G9) -> 0 | H10: =SUM(H8:H9) -> 0 | I10: =SUM(I8:I9) -> 0 | J10: =I10-E10 -> 0 | K10: =IF(AND(E10=0,I10=0),"",IF(AND(E10=0,I10>0),1,J10/E10))
A11: 二、应收票据坏账准备
A12: 银行承兑汇票 | B12: ='坏账准备明细表D1-4'!B23 -> 0 | C12: ='坏账准备明细表D1-4'!C23 -> 0 | E12: =B12+C12+D12 -> 0 | F12: ='坏账准备明细表D1-4'!K23 -> 0 | G12: ='坏账准备明细表D1-4'!L23 -> 0 | I12: =F12+G12+H12 -> 0 | J12: =I12-E12 -> 0 | K12: =IF(AND(E12=0,I12=0),"",IF(AND(E12=0,I12>0),1,J12/E12))
A13: 商业承兑汇票 | B13: ='坏账准备明细表D1-4'!B24 -> 0 | C13: ='坏账准备明细表D1-4'!C24 -> 0 | E13: =B13+C13+D13 -> 0 | F13: ='坏账准备明细表D1-4'!K24 -> 0 | G13: ='坏账准备明细表D1-4'!L24 -> 0 | I13: =F13+G13+H13 -> 0 | J13: =I13-E13 -> 0 | K13: =IF(AND(E13=0,I13=0),"",IF(AND(E13=0,I13>0),1,J13/E13))
A14: 小计 | B14: =SUM(B12:B13) -> 0 | C14: =SUM(C12:C13) -> 0 | D14: =SUM(D12:D13) -> 0 | E14: =SUM(E12:E13) -> 0 | F14: =SUM(F12:F13) -> 0 | G14: =SUM(G12:G13) -> 0 | H14: =SUM(H12:H13) -> 0 | I14: =SUM(I12:I13) -> 0 | J14: =I14-E14 -> 0 | K14: =IF(AND(E14=0,I14=0),"",IF(AND(E14=0,I14>0),1,J14/E14))
A15: 三、应收票据净值
A16: 银行承兑汇票 | B16: =B8-B12 -> 0 | C16: =C8-C12 -> 0 | D16: =D8-D12 -> 0 | E16: =B16+C16+D16 -> 0 | F16: =F8-F12 -> 0 | G16: =G8-G12 -> 0 | H16: =H8-H12 -> 0 | I16: =F16+G16+H16 -> 0 | J16: =I16-E16 -> 0 | K16: =IF(AND(E16=0,I16=0),"",IF(AND(E16=0,I16>0),1,J16/E16))
A17: 商业承兑汇票 | B17: =B9-B13 -> 0 | C17: =C9-C13 -> 0 | D17: =D9-D13 -> 0 | E17: =B17+C17+D17 -> 0 | F17: =F9-F13 -> 0 | G17: =G9-G13 -> 0 | H17: =H9-H13 -> 0 | I17: =F17+G17+H17 -> 0 | J17: =I17-E17 -> 0 | K17: =IF(AND(E17=0,I17=0),"",IF(AND(E17=0,I17>0),1,J17/E17))
A18: 合计 | B18: =SUM(B16:B17) -> 0 | C18: =SUM(C16:C17) -> 0 | D18: =SUM(D16:D17) -> 0 | E18: =SUM(E16:E17) -> 0 | F18: =SUM(F16:F17) -> 0 | G18: =SUM(G16:G17) -> 0 | H18: =SUM(H16:H17) -> 0 | I18: =SUM(I16:I17) -> 0 | J18: =I18-E18 -> 0 | K18: =IF(AND(E18=0,I18=0),"",IF(AND(E18=0,I18>0),1,J18/E18))
A19: 试算平衡表数
A20: 差异数 | E20: =E18-E19 -> 0 | I20: =I18-I19 -> 0
A22: 1.审计说明
A23: （1）公司应收票据期末净值较期初净值增加（负数为减少）： | E23: =IF(AND(E18=0,I18=0),0,IF(AND(E18=0,I18>0),1,(I18-E18)/E18)) -> 0
A24: 主要原因（比例超过30%的）：
A27: （2）质押、贴现情况说明
A28: 2.审计结论

Sheet 附注披露信息（上市公司）
A1: 致同会计师事务所
A2: 附注披露信息（上市公司）
A3: =底稿目录!A2 -> 被审计单位名称： | C3: =底稿目录!A4 -> 编制人： | E3: =底稿目录!A5 -> 编制日期： | G3: 索引号：D1-1
A4: =底稿目录!A3 -> 截止日：202X年12月31日 | C4: =底稿目录!A6 -> 复核人： | E4: =底稿目录!A7 -> 复核日期： | G4: 页 次：1
A6: 应收票据
A7: 票据种类 | B7: 期末余额 | E7: 上年年末余额
B8: 期末余额 | C8: 坏账准备 | D8: 期末账面价值 | E8: 期初余额 | F8: 坏账准备 | G8: 期初账面价值
A9: 银行承兑汇票 | B9: ='审定表D1-1'!I8 -> 0 | C9: ='审定表D1-1'!I12 -> 0 | D9: =B9-C9 -> 0 | E9: ='审定表D1-1'!E8 -> 0 | F9: ='审定表D1-1'!E12 -> 0 | G9: =E9-F9 -> 0
A10: 商业承兑汇票 | B10: ='审定表D1-1'!I9 -> 0 | C10: ='审定表D1-1'!I13 -> 0 | D10: =B10-C10 -> 0 | E10: ='审定表D1-1'!E9 -> 0 | F10: ='审定表D1-1'!E13 -> 0 | G10: =E10-F10 -> 0
A11: 合计 | B11: =SUM(B9:B10) -> 0 | C11: =SUM(C9:C10) -> 0 | D11: =SUM(D9:D10) -> 0 | E11: =SUM(E9:E10) -> 0 | F11: =SUM(F9:F10) -> 0 | G11: =SUM(G9:G10) -> 0
A12: 说明：
A13: 【提示：企业因销售商品、提供服务等取得的、不属于《中华人民共和国票据法》规范票据的“云信”、“融信”等数字化应收账款债权凭证，不应当在“应收票据”项目中列示。企业管理“云信”、“融信”等的业务模式以收取合同现金流量为目标的，应当在“应收账款”项目中列示；既以收取合同现金流量为目标又以出售为目标的，应当在“应收款项融资”项目中列示。如果法律上认定供应链票据属于《商业汇票承兑、贴现与再贴现管理办法》（中国人民银行中国银行保险监督管理委员会令〔2022〕第4号）的范围、具备《票据法》规定的要件，则持有方应当自法律认定生效日（2023年1月1日）起将其作为“应收票据”进行会计处理（根据其业务模式列示为应收票据或应收款项融资），且无需对前期比较期间数据进行追溯调整。】
A14: （1）期末已质押的应收票据
A15: 种 类 | B15: 期末已质押金额
A16: 银行承兑票据
A17: 商业承兑票据
A18: 可无限量添加行
A19: 合 计 | B19: =SUM(B16:B18) -> 0
A20: （2）期末已背书或贴现但尚未到期的应收票据
A21: 种 类 | B21: 期末终止确认金额 | C21: 期末未终止确认金额
A22: 银行承兑票据
A23: 商业承兑票据
A24: 可无限量添加行
A25: 合 计 | B25: =SUM(B22:B24) -> 0 | C25: =SUM(C22:C24) -> 0
A26: 【上面各张表均可添加行项目】
A27: （如根据《企业会计准则第23号——金融资产转移》终止确认的应收票据，列示其终止确认的金额，及与终止确认相关的利得和损失）
A28: 【提示：证监会《2014 年上市公司年报会计监管报告》，对已背书或贴现且尚未到期的银行承兑汇票予以终止确认后，需在财务报表中补充披露终止确认的票据以及对票据被追索时可能存在的支付风险予以清晰说明。参考披露：
A29: 用于贴现的银行承兑汇票是由信用等级较高的银行承兑，信用风险和延期付款风险很小，并且票据相关的利率风险已转移给银行，可以判断票据所有权上的主要风险和报酬已经转移，故终止确认。
A30: 或：用于贴现的银行承兑汇票是由信用等级不高的银行承兑，贴现不影响追索权，票据相关的信用风险和延期付款风险仍没有转移，故未终止确认。】
A31: （3）期末因出票人未履约而其转应收账款的票据
A32: 种 类 | B32: 期末转应收账款金额
A33: 商业承兑票据
A36: 合 计 | B36: =SUM(B33:B35) -> 0
A37: （4）按坏账计提方法分类
A38: 类别 | B38: 期末余额
B39: 金 额 | C39: 比例(%) | D39: 坏账准备 | E39: 预期信用损失率(%) | F39: 账面价值
A40: 按单项计提坏账准备 | B40: =SUM(B41:B44) -> 0 | C40: =IFERROR(B40/$B$49,0) -> 0 | D40: =SUM(D41:D44) -> 0 | E40: =IFERROR(D40/B40,0) -> 0 | F40: =B40-D40 -> 0
A41: 其中： | C41: =IFERROR(B41/$B$49,0) -> 0 | E41: =IFERROR(D41/B41,0) -> 0 | F41: =B41-D41 -> 0
C42: =IFERROR(B42/$B$49,0) -> 0 | E42: =IFERROR(D42/B42,0) -> 0 | F42: =B42-D42 -> 0
C43: =IFERROR(B43/$B$49,0) -> 0 | E43: =IFERROR(D43/B43,0) -> 0 | F43: =B43-D43 -> 0
...

Sheet 附注披露信息（国企）
A1: 致同会计师事务所
A2: 附注披露信息（国有企业）
A3: =底稿目录!A2 -> 被审计单位名称： | C3: =底稿目录!A4 -> 编制人： | E3: =底稿目录!A5 -> 编制日期： | H3: 索引号：D1-1
A4: =底稿目录!A3 -> 截止日：202X年12月31日 | C4: =底稿目录!A6 -> 复核人： | E4: =底稿目录!A7 -> 复核日期： | H4: 页 次：1
A5: （1）应收票据分类
A6: 票据种类 | B6: 期末数 | E6: 期初数
B7: 期末余额 | C7: 坏账准备 | D7: 期末账面价值 | E7: 年初余额 | F7: 坏账准备 | G7: 年初账面价值
A8: 银行承兑汇票 | B8: ='审定表D1-1'!I8 -> 0 | C8: ='审定表D1-1'!I12 -> 0 | D8: =B8-C8 -> 0 | E8: ='审定表D1-1'!E8 -> 0 | F8: ='审定表D1-1'!E12 -> 0 | G8: =E8-F8 -> 0
A9: 商业承兑汇票 | B9: ='审定表D1-1'!I9 -> 0 | C9: ='审定表D1-1'!I13 -> 0 | D9: =B9-C9 -> 0 | E9: ='审定表D1-1'!E9 -> 0 | F9: ='审定表D1-1'!E13 -> 0 | G9: =E9-F9 -> 0
A10: 合计 | B10: =SUM(B8:B9) -> 0 | C10: =SUM(C8:C9) -> 0 | D10: =SUM(D8:D9) -> 0 | E10: =SUM(E8:E9) -> 0 | F10: =SUM(F8:F9) -> 0 | G10: =SUM(G8:G9) -> 0
A11: （2）坏账准备计提情况
A12: 按坏账准备计提方法分类披露应收票据
A13: 类 别 | B13: 期末数
B14: 账面余额 | D14: 坏账准备 | F14: 账面
B15: 金额 | C15: 比例(%) | D15: 金额 | E15: 预期信用损失率(%) | F15: 价值
A16: 按单项计提坏账准备 | C16: =IFERROR(B16/$B$15*100,0) -> 0 | E16: =IFERROR(D16/B16*100,0) -> 0 | F16: =B16-D16 -> 0
A17: 按组合计提坏账准备 | C17: =IFERROR(B17/$B$15*100,0) -> 0 | E17: =IFERROR(D17/B17*100,0) -> 0 | F17: =B17-D17 -> 0
A18: 合 计 | B18: =SUM(B16:B17) -> 0 | C18: =IFERROR(B18/$B$57*100,0) -> 0 | D18: =SUM(D16:D17) -> 0 | E18: =IFERROR(D18/B18*100,0) -> 0 | F18: =B18-D18 -> 0
A19: 按坏账准备计提方法分类披露应收票据（续）
A20: 类 别 | B20: 期初数
B21: 账面余额 | D21: 坏账准备 | F21: 账面
B22: 金额 | C22: 比例(%) | D22: 金额 | E22: 预期信用损失率(%) | F22: 价值
A23: 按单项计提坏账准备 | C23: =IFERROR(B23/$B$22*100,0) -> 0 | E23: =IFERROR(D23/B23*100,0) -> 0 | F23: =B23-D23 -> 0
A24: 按组合计提坏账准备 | C24: =IFERROR(B24/$B$22*100,0) -> 0 | E24: =IFERROR(D24/B24*100,0) -> 0 | F24: =B24-D24 -> 0
A25: 合 计 | B25: =B23+B24 -> 0 | C25: =IFERROR(B25/$B$22*100,0) -> 0 | D25: =SUM(D23:D24) -> 0 | E25: =IFERROR(D25/B25*100,0) -> 0 | F25: =B25-D25 -> 0
A26: 按单项计提坏账准备的应收票据：
A27: 名 称 | B27: 期末数
B28: 账面余额 | C28: 坏账准备 | D28: 预期信用损失率（%） | E28: 计提理由
D29: =IFERROR(C29/B29*100,0) -> 0
D30: =IFERROR(C30/B30*100,0) -> 0
D31: =IFERROR(C31/B31*100,0) -> 0
A32: 合 计 | B32: =SUM(B29:B31) -> 0 | C32: =SUM(C29:C31) -> 0 | D32: =IFERROR(C32/B32*100,0) -> 0
A33: 按组合计提坏账准备的应收票据：
A34: 名 称 | B34: 期末数
B35: 账面余额 | C35: 坏账准备 | D35: 预期信用损失率(%)
A36: 商业承兑汇票小计： | B36: =SUM(B37:B38) -> 0 | C36: =SUM(C37:C38) -> 0 | D36: =IFERROR(C36/B36*100,0) -> 0
A37: 出票人类型或账龄 | D37: =IFERROR(C37/B37*100,0) -> 0
A38: …… | D38: =IFERROR(C38/B38*100,0) -> 0
A39: 银行承兑汇票小计： | B39: =SUM(B40:B41) -> 0 | C39: =SUM(C40:C41) -> 0 | D39: =IFERROR(C39/B39*100,0) -> 0
A40: 出票人类型或账龄 | D40: =IFERROR(C40/B40*100,0) -> 0
...

Sheet 原值明细表（按类别）D1-2
A1: 致同会计师事务所
A2: 应收票据原值明细表(原值）
A3: =底稿目录!A2 -> 被审计单位名称： | D3: =底稿目录!A4 -> 编制人： | G3: =底稿目录!A5 -> 编制日期： | J3: 索引号： | K3: D1-2
A4: =底稿目录!A3 -> 截止日：202X年12月31日 | D4: =底稿目录!A6 -> 复核人： | G4: =底稿目录!A7 -> 复核日期： | J4: 页次：
A5: 一、审计目标：
A6: 应收票据以恰当的金额包括在财务报表中，与之相关的计价或分摊调整已恰当记录，相关披露已得到恰当计量和描述。
A7: 二、审计过程:
A8: 1.……
A10: 票据种类 | B10: 期初未审数 | C10: 账项调整 | D10: 重分类调整 | E10: 期初审定数 | F10: 本期增加 | G10: 本期减少 | H10: 期末未审数 | I10: 账项调整 | J10: 重分类调整 | K10: 期末审定数
A11: 银行承兑汇票 | E11: =B11+C11+D11 -> 0 | H11: =B11+F11-G11 -> 0 | K11: =H11+I11+J11 -> 0
A12: 财务公司承兑汇票 | E12: =B12+C12+D12 -> 0 | H12: =B12+F12-G12 -> 0 | K12: =H12+I12+J12 -> 0
A13: 商业承兑汇票 | E13: =B13+C13+D13 -> 0 | H13: =B13+F13-G13 -> 0 | K13: =H13+I13+J13 -> 0
A14: 合计 | B14: =SUM(B11:B13) -> 0 | C14: =SUM(C11:C13) -> 0 | D14: =SUM(D11:D13) -> 0 | E14: =SUM(E11:E13) -> 0 | F14: =SUM(F11:F13) -> 0 | G14: =SUM(G11:G13) -> 0 | H14: =SUM(H11:H13) -> 0 | I14: =SUM(I11:I13) -> 0 | ... K14: =SUM(K11:K13) -> 0
A15: 三、审计说明：
A19: 四、审计结论：

Sheet 原值明细表（按客户）D1-3
A1: 致同会计师事务所
A2: 应收票据原值明细表(按客户）
A3: =底稿目录!A2 -> 被审计单位名称： | F3: =底稿目录!A4 -> 编制人： | I3: =底稿目录!A5 -> 编制日期： | N3: 索引号： | O3: D1-3
A4: =底稿目录!A3 -> 截止日：202X年12月31日 | F4: =底稿目录!A6 -> 复核人： | I4: =底稿目录!A7 -> 复核日期： | N4: 页 次：
A5: 一、审计目标：
A6: 应收票据以恰当的金额包括在财务报表中，与之相关的计价或分摊调整已恰当记录，相关披露已得到恰当计量和描述。
A7: 二、审计过程:
A8: 1.……
A10: 客户名称 | B10: 公司代码 | C10: 关联关系 | D10: 期初未审数 | E10: 账项调整 | F10: 重分类调整 | G10: 期初审定数 | H10: 本期增加 | I10: 本期减少 | J10: 期末余额 | K10: 被审计单位重分类调整 | L10: 期末未审余额 | M10: 账项调整 | N10: 重分类调整 | O10: 期末审定数
G11: =D11+E11+F11 -> 0 | J11: =D11+H11-I11 -> 0 | L11: =J11+K11 -> 0 | O11: =L11+M11+N11 -> 0 | P11: 合并范围内关联方
G12: =D12+E12+F12 -> 0 | J12: =D12+H12-I12 -> 0 | L12: =J12+K12 -> 0 | O12: =L12+M12+N12 -> 0 | P12: 合并范围外关联方
G13: =D13+E13+F13 -> 0 | J13: =D13+H13-I13 -> 0 | L13: =J13+K13 -> 0 | O13: =L13+M13+N13 -> 0 | P13: 非关联方
G14: =D14+E14+F14 -> 0 | J14: =D14+H14-I14 -> 0 | L14: =J14+K14 -> 0 | O14: =L14+M14+N14 -> 0
G15: =D15+E15+F15 -> 0 | J15: =D15+H15-I15 -> 0 | L15: =J15+K15 -> 0 | O15: =L15+M15+N15 -> 0
G16: =D16+E16+F16 -> 0 | J16: =D16+H16-I16 -> 0 | L16: =J16+K16 -> 0 | O16: =L16+M16+N16 -> 0
G17: =D17+E17+F17 -> 0 | J17: =D17+H17-I17 -> 0 | L17: =J17+K17 -> 0 | O17: =L17+M17+N17 -> 0
G18: =D18+E18+F18 -> 0 | J18: =D18+H18-I18 -> 0 | L18: =J18+K18 -> 0 | O18: =L18+M18+N18 -> 0
G19: =D19+E19+F19 -> 0 | J19: =D19+H19-I19 -> 0 | L19: =J19+K19 -> 0 | O19: =L19+M19+N19 -> 0
G20: =D20+E20+F20 -> 0 | J20: =D20+H20-I20 -> 0 | L20: =J20+K20 -> 0 | O20: =L20+M20+N20 -> 0
A21: 合计 | D21: =SUM(D11:D20) -> 0 | E21: =SUM(E11:E20) -> 0 | F21: =SUM(F11:F20) -> 0 | G21: =SUM(G11:G20) -> 0 | H21: =SUM(H11:H20) -> 0 | I21: =SUM(I11:I20) -> 0 | J21: =SUM(J11:J20) -> 0 | L21: =SUM(L11:L20) -> 0 | M21: =SUM(M11:M20) -> 0 | N21: =SUM(N11:N20) -> 0 | O21: =SUM(O11:O20) -> 0
A22: 三、审计说明：
A26: 四、审计结论：

Sheet 坏账准备明细表D1-4
A1: 致同会计师事务所
A2: 应收票据坏账准备明细表
A3: =底稿目录!A2 -> 被审计单位名称： | E3: =底稿目录!A4 -> 编制人： | I3: =底稿目录!A5 -> 编制日期： | M3: 索引号： | N3: D1-4
A4: =底稿目录!A3 -> 截止日：202X年12月31日 | E4: =底稿目录!A6 -> 复核人： | I4: =底稿目录!A7 -> 复核日期： | M4: 页 次：
A5: 一、审计目标
A6: 应收票据以恰当的金额包括在财务报表中，与之相关的计价或分摊调整已恰当记录，相关披露已得到恰当计量和描述。
A7: 二、审计过程
A8: 1.……
A10: 项目 | B10: 期初余额 | F10: 本期增加 | H10: 本期减少 | K10: 期末余额
B11: 期初未审数 | C11: 账项调整 | D11: 重分类调整 | E11: 期初审定数 | F11: 计提 | G11: 其他增加 | H11: 转回 | I11: 核销 | J11: 其他减少 | K11: 期末未审数 | L11: 账项调整 | M11: 重分类调整 | N11: 期末审定数
A12: 按单项计提 | B12: =SUM(B13:B16) -> 0 | C12: =SUM(C13:C16) -> 0 | D12: =SUM(D13:D16) -> 0 | E12: =SUM(E13:E16) -> 0 | F12: =SUM(F13:F16) -> 0 | G12: =SUM(G13:G16) -> 0 | H12: =SUM(H13:H16) -> 0 | I12: =SUM(I13:I16) -> 0 | J12: =SUM(J13:J16) -> 0 | K12: =B12+SUM(F12:G12)-SUM(H12:J12) -> 0 | L12: =SUM(L13:L16) -> 0 | M12: =SUM(M13:M16) -> 0 | N12: =SUM(N13:N16) -> 0
A13: 其中： | E13: =B13+C13+D13 -> 0 | K13: =B13+SUM(F13:G13)-SUM(H13:J13) -> 0 | N13: =K13+L13+M13 -> 0
E14: =B14+C14+D14 -> 0 | K14: =B14+SUM(F14:G14)-SUM(H14:J14) -> 0 | N14: =K14+L14+M14 -> 0
E15: =B15+C15+D15 -> 0 | K15: =B15+SUM(F15:G15)-SUM(H15:J15) -> 0 | N15: =K15+L15+M15 -> 0
E16: =B16+C16+D16 -> 0 | K16: =B16+SUM(F16:G16)-SUM(H16:J16) -> 0 | N16: =K16+L16+M16 -> 0
A17: 按组合计提 | B17: =SUM(B18:B21) -> 0 | C17: =SUM(C18:C21) -> 0 | D17: =SUM(D18:D21) -> 0 | E17: =SUM(E18:E21) -> 0 | F17: =SUM(F18:F21) -> 0 | G17: =SUM(G18:G21) -> 0 | H17: =SUM(H18:H21) -> 0 | I17: =SUM(I18:I21) -> 0 | J17: =SUM(J18:J21) -> 0 | K17: =B17+SUM(F17:G17)-SUM(H17:J17) -> 0 | L17: =SUM(L18:L21) -> 0 | M17: =SUM(M18:M21) -> 0 | N17: =SUM(N18:N21) -> 0
A18: 其中： | E18: =B18+C18+D18 -> 0 | K18: =B18+SUM(F18:G18)-SUM(H18:J18) -> 0 | N18: =K18+L18+M18 -> 0
E19: =B19+C19+D19 -> 0 | K19: =B19+SUM(F19:G19)-SUM(H19:J19) -> 0 | N19: =K19+L19+M19 -> 0
E20: =B20+C20+D20 -> 0 | K20: =B20+SUM(F20:G20)-SUM(H20:J20) -> 0 | N20: =K20+L20+M20 -> 0
E21: =B21+C21+D21 -> 0 | K21: =B21+SUM(F21:G21)-SUM(H21:J21) -> 0 | N21: =K21+L21+M21 -> 0
A22: 合计 | B22: =B12+B17 -> 0 | C22: =C12+C17 -> 0 | D22: =D12+D17 -> 0 | E22: =E12+E17 -> 0 | F22: =F12+F17 -> 0 | G22: =G12+G17 -> 0 | H22: =H12+H17 -> 0 | I22: =I12+I17 -> 0 | ... N22: =N12+N17 -> 0
A23: 银行承兑汇票小计 | E23: =B23+C23+D23 -> 0 | K23: =B23+SUM(F23:G23)-SUM(H23:J23) -> 0 | N23: =K23+L23+M23 -> 0
A24: 商业承兑汇票小计 | E24: =B24+C24+D24 -> 0 | K24: =B24+SUM(F24:G24)-SUM(H24:J24) -> 0 | N24: =K24+L24+M24 -> 0
A25: 三、审计说明
A29: 四、审计结论

Sheet 调整分录汇总表D1-5
A1: 致同会计师事务所
A2: 应收票据调整分录汇总表
A3: =底稿目录!A2 -> 被审计单位名称： | D3: =底稿目录!A4 -> 编制人： | G3: =底稿目录!A5 -> 编制日期： | I3: 索引号： | J3: D1-5
A4: =底稿目录!A3 -> 截止日：202X年12月31日 | D4: =底稿目录!A6 -> 复核人： | G4: =底稿目录!A7 -> 复核日期： | I4: 页次：
A5: 调整事项说明 | B5: 类别（报表调整/账项调整/其他） | C5: 报表项目 | D5: 科目名称 | E5: 附注项目 | F5: …… | G5: 借方调整金额 | H5: 贷方调整金额 | I5: 索引 | J5: 备注
A21: 提示：本底稿适用于调整分录较多、较复杂的项目，且仅列示与本报表项目相关的审计调整。项目组可根据项目实际情况选择是否使用该底稿。

Sheet 应收票据业务模式分析D1-6
A1: 致同会计师事务所
A2: 应收票据业务模式分析
A3: =底稿目录!A2 -> 被审计单位名称： | B3: =底稿目录!A4 -> 编制人： | C3: =底稿目录!A5 -> 编制日期： | D3: 索引号： | E3: D1-6
A4: =底稿目录!A3 -> 截止日：202X年12月31日 | B4: =底稿目录!A6 -> 复核人： | C4: =底稿目录!A7 -> 复核日期： | D4: 页次：
A5: 一、审计目标：
A6: 资产负债表中记录的应收票据是存在的，且已经记录在恰当的账户中。
A7: 二、审计过程：
A8: 1.……
A10: （一）应收票据业务模式及依据
A11: 组合名称 | B11: 被审计单位管理应收票据业务模式 | C11: 具体依据 | D11: 索引号 | E11: 备注
A12: 信用等级高的银行承兑汇票 | B12: 以收取合同现金流量和出售金融资产为目标 | C12: 频繁贴现、背书
A13: 信用等级低的银行承兑汇票 | B13: 以收取合同现金流量为目标
A14: 商业承兑汇票 | B14: 以收取合同现金流量为目标
A15: （二）应收票据分类判断
A16: 了解并观察被审计单位贴现或背书的实际情况及未来预期 | B16: 信用等级高的银行承兑汇票 | C16: 信用等级低的银行承兑汇票 | D16: 商业承兑汇票 | E16: 备注
A17: 1.被审计单位是否涉及大额且频繁的应收票据背书或贴现且终止确认？ | B17: 是 | C17: 是 | D17: 是
A18: 2.被审计单位持有应收票据的目的是交易性的或基于应收票据的公允价值作出决策并对其进行管理？ | B18: 否 | C18: 是 | D18: 是
A19: 3.未来是否预期会进行大额且频繁的应收票据背书或贴现且可终止确认？ | B19: 否 | C19: 否 | D19: 否
A20: 4.未来是否预期持有应收票据的目的是交易性的或基于应收票据的公允价值作出决策并对其进行管理？ | B20: 否 | C20: 否 | D20: 否
A21: 确定业务模式 | B21: =IF(AND(B17="是",B18="否"),"属于以收取合同现金流量和出售金融资产为目标的业务模式",IF(AND(B17="是",B18="是"),"属于其他业务模式",IF(AND(B19="是",B20<>"是"),"属于以收取合同现金流量和出售金融资产为目标的业务模式",IF(B20="是","属于其他业务模式","属于以收取合同现金流量为目标的业务模式")))) -> 属于以收取合同现金流量和出售金融资产为目标的业务模式 | C21: =IF(AND(C17="是",C18="否"),"属于以收取合同现金流量和出售金融资产为目标的业务模式",IF(AND(C17="是",C18="是"),"属于其他业务模式",IF(AND(C19="是",C20<>"是"),"属于以收取合同现金流量和出售金融资产为目标的业务模式",IF(C20="是","属于其他业务模式","属于以收取合同现金流量为目标的业务模式")))) -> 属于其他业务模式 | D21: =IF(AND(D17="是",D18="否"),"属于以收取合同现金流量和出售金融资产为目标的业务模式",IF(AND(D17="是",D18="是"),"属于其他业务模式",IF(AND(D19="是",D20<>"是"),"属于以收取合同现金流量和出售金融资产为目标的业务模式",IF(D20="是","属于其他业务模式","属于以收取合同现金流量为目标的业务模式")))) -> 属于其他业务模式
A22: 确定报表项目 | B22: =IF(B21="属于以收取合同现金流量和出售金融资产为目标的业务模式","应列报为应收款项融资","") -> 应列报为应收款项融资 | C22: =IF(C21="属于以收取合同现金流量和出售金融资产为目标的业务模式","应列报为应收款项融资","") | D22: =IF(D21="属于以收取合同现金流量和出售金融资产为目标的业务模式","应列报为应收款项融资","")
A23: 三、审计说明：
A27: 四、审计结论：
A29: 提示1：就票据的贴现或背书而言，首先需要分析贴现或背书是否导致了终止确认。对于信用等级较低的银行承兑的汇票或由企业承兑的商业承兑汇票，贴现或背书时并不能终止确认，
A30: 因此并未导致会计上的“出售"，进而也不会改变企业管理应收票据的业务模式仍然是以收取合同现金流量为目标。其次，若企业的贴现或背书行为并不频繁，或者虽然频繁但金额不大，
A31: 则也可能不改变以收取合同现金流量为目标的业务模式。“如果企业经常贴现或背书信用等级较高的银行承兑的汇票，则其业务模式可能是既以收取合同现金流量为目标又以出售该金融
A32: 资产为目标，从而可能需要在“应收款项融资"项目列报。信用等级较高银行：如6家大型商业银行（中国银行、中国农业银行、中国建设银行、中国工商银行、中国邮政储蓄银行、交通银行）
A33: 和9家上市股份制商业银行（招商银行、浦发银行、中信银行、中国光大银行、华夏银行、中国民生银行、平安银行、兴业银行、浙商银行）。
A35: 提示2：还需确定管理应收票据的组合层次，例如应收票据整体作为组合来评估业务模式；区分银行承兑汇票和财务公司承兑汇票、商业承兑汇票两个组合分别评估业务模式；
A36: 划分为信用等级较高的银行承兑的汇票，信用等级不高的银行承兑的汇票和由企业承兑的商业承兑汇票、财务公司承兑汇票。
A38: 证监会《2013年上市公司年报会计监管报告》
A39: 对于承兑行信用等级不够高的银行承兑汇票、由企业承兑的商业承兑汇票以及应收账款，资产相关的主要风险为信用风险和延期付款风险。由于我国票据法对追索权进行了明确规定，银行也
A40: 大多在应收账款保理中保留追索权，因此这类金融资产在贴现、背书或保理后，其所有权相关的上述主要风险并没有转移给银行，相应企业在贴现、背书或保理此类金融资产时不应终止确认；
A41: 对于承兑行信用等级较高的银行承兑汇票，资产相关的主要风险是利率风险。通常情况下，由于利率风险已随票据的贴现及背书转移，相关票据可以在贴现、背书时予以终止确认。

Sheet 应收票据备查簿核对D1-7
A1: 致同会计师事务所 | Q1: 致同会计师事务所
A2: 应收票据备查簿核对表 | Q2: 应收票据备查簿核对表
A3: =底稿目录!A2 -> 被审计单位名称： | E3: =底稿目录!A4 -> 编制人： | I3: =底稿目录!A5 -> 编制日期： | O3: 索引号： | P3: D1-7 | Q3: =底稿目录!A2 -> 被审计单位名称： | V3: =底稿目录!A4 -> 编制人： | Z3: =底稿目录!A5 -> 编制日期： | AC3: 索引号： | AD3: D1-7
A4: =底稿目录!A3 -> 截止日：202X年12月31日 | E4: =底稿目录!A6 -> 复核人： | I4: =底稿目录!A7 -> 复核日期： | O4: 页 次： | Q4: =底稿目录!A3 -> 截止日：202X年12月31日 | V4: =底稿目录!A6 -> 复核人： | Z4: =底稿目录!A7 -> 复核日期： | AC4: 页 次：
A5: 一、审计目标：
A6: 1.所有应记录的应收票据均已记录，所有应当包括在财务报表中的相关披露均已包括；2.应收票据以恰当的金额包括在财务报表中，与之相关的计价或分摊调整已恰当记录，相关披露已得到恰当计量和描述 。
A7: 二、审计过程
A8: 1.……
A10: 截止日期 | B10: 45657
A11: 备查簿信息【实务中企业的备查簿中的表述各有不同，模板仅供参考】 | Q11: 审计核对
A12: 票据类型 | B12: 票据号 | C12: 收到票据日期 | D12: 票据前手名称 | E12: 出票日期 | F12: 出票人名称 | G12: 承兑人名称 | H12: 票据金额 | I12: 票据到期日 | J12: 票据流转日期 | K12: 票据状态 | L12: 被背书人名称 | M12: 贴现银行 | N12: 贴现息 | O12: 是否质押 | P12: 审计日已贴现、背书 | Q12: 年初余额 | R12: 本期收到 | S12: 本期背书 | T12: 本期到期承兑 | U12: 本期贴现 | V12: 年末持有票据余额 | W12: 期末未到期背书或贴现金额 | X12: 期末未到期背书或贴现是否终止确认 | Y12: 承兑单位信用评级 | Z12: 审定应收款项融资 | AA12: 审定应收票据 | AB12: 被审计单位与前手或后手的关联关系 | AC12: 是否逾期 | AD12: 逾期转入应收账款金额
A13: 银行承兑汇票 | Q13: =IF(YEAR(C13)=YEAR($B$10)-1,H13,0) -> 0 | R13: =H13-Q13 -> 0 | S13: =IF(K13="背书",H13,0) -> 0 | T13: =IF(K13="到期承兑",H13,0) -> 0 | U13: =IF(K13="贴现",H13,0) -> 0 | V13: =Q13+R13-S13-T13-U13 -> 0 | W13: =IF(I13<$B$10,0,IF(J13<I13,S13+U13,0)) -> 0 | AE13: 背书
A14: 银行承兑汇票 | Q14: =IF(YEAR(C14)=YEAR($B$10)-1,H14,0) -> 0 | R14: =H14-Q14 -> 0 | S14: =IF(K14="背书",H14,0) -> 0 | T14: =IF(K14="到期承兑",H14,0) -> 0 | U14: =IF(K14="贴现",H14,0) -> 0 | V14: =Q14+R14-S14-T14-U14 -> 0 | W14: =IF(I14<$B$10,0,IF(J14<I14,S14+U14,0)) -> 0 | AE14: 贴现
A15: 银行承兑汇票 | Q15: =IF(YEAR(C15)=YEAR($B$10)-1,H15,0) -> 0 | R15: =H15-Q15 -> 0 | S15: =IF(K15="背书",H15,0) -> 0 | T15: =IF(K15="到期承兑",H15,0) -> 0 | U15: =IF(K15="贴现",H15,0) -> 0 | V15: =Q15+R15-S15-T15-U15 -> 0 | W15: =IF(I15<$B$10,0,IF(J15<I15,S15+U15,0)) -> 0 | AE15: 到期承兑
A16: 银行承兑汇票 | Q16: =IF(YEAR(C16)=YEAR($B$10)-1,H16,0) -> 0 | R16: =H16-Q16 -> 0 | S16: =IF(K16="背书",H16,0) -> 0 | T16: =IF(K16="到期承兑",H16,0) -> 0 | U16: =IF(K16="贴现",H16,0) -> 0 | V16: =Q16+R16-S16-T16-U16 -> 0 | W16: =IF(I16<$B$10,0,IF(J16<I16,S16+U16,0)) -> 0 | AE16: 未到期
Q17: =IF(YEAR(C17)=YEAR($B$10)-1,H17,0) -> 0 | R17: =H17-Q17 -> 0 | S17: =IF(K17="背书",H17,0) -> 0 | T17: =IF(K17="到期承兑",H17,0) -> 0 | U17: =IF(K17="贴现",H17,0) -> 0 | V17: =Q17+R17-S17-T17-U17 -> 0 | W17: =IF(I17<$B$10,0,IF(J17<I17,S17+U17,0)) -> 0
A18: 银行承兑汇票小计 | Q18: =SUM(Q13:Q17) -> 0 | R18: =SUM(R13:R17) -> 0 | S18: =SUM(S13:S17) -> 0 | T18: =SUM(T13:T17) -> 0 | U18: =SUM(U13:U17) -> 0 | V18: =SUM(V13:V17) -> 0 | W18: =SUM(W13:W17) -> 0
A19: 商业承兑汇票 | Q19: =IF(YEAR(C19)=YEAR($B$10)-1,H19,0) -> 0 | R19: =H19-Q19 -> 0 | S19: =IF(K19="背书",H19,0) -> 0 | T19: =IF(K19="到期承兑",H19,0) -> 0 | U19: =IF(K19="贴现",H19,0) -> 0 | V19: =Q19+R19-S19-T19-U19 -> 0 | W19: =IF(I19<$B$10,0,IF(J19<I19,S19+U19,0)) -> 0 | AE19: 是
A20: 商业承兑汇票 | Q20: =IF(YEAR(C20)=YEAR($B$10)-1,H20,0) -> 0 | R20: =H20-Q20 -> 0 | S20: =IF(K20="背书",H20,0) -> 0 | T20: =IF(K20="到期承兑",H20,0) -> 0 | U20: =IF(K20="贴现",H20,0) -> 0 | V20: =Q20+R20-S20-T20-U20 -> 0 | W20: =IF(I20<$B$10,0,IF(J20<I20,S20+U20,0)) -> 0 | AE20: 否
A21: 商业承兑汇票 | Q21: =IF(YEAR(C21)=YEAR($B$10)-1,H21,0) -> 0 | R21: =H21-Q21 -> 0 | S21: =IF(K21="背书",H21,0) -> 0 | T21: =IF(K21="到期承兑",H21,0) -> 0 | U21: =IF(K21="贴现",H21,0) -> 0 | V21: =Q21+R21-S21-T21-U21 -> 0 | W21: =IF(I21<$B$10,0,IF(J21<I21,S21+U21,0)) -> 0 | AE21: 不适用
A22: 商业承兑汇票 | Q22: =IF(YEAR(C22)=YEAR($B$10)-1,H22,0) -> 0 | R22: =H22-Q22 -> 0 | S22: =IF(K22="背书",H22,0) -> 0 | T22: =IF(K22="到期承兑",H22,0) -> 0 | U22: =IF(K22="贴现",H22,0) -> 0 | V22: =Q22+R22-S22-T22-U22 -> 0 | W22: =IF(I22<$B$10,0,IF(J22<I22,S22+U22,0)) -> 0
Q23: =IF(YEAR(A23)=YEAR($B$10)-1,H23,0) -> 0 | R23: =H23-Q23 -> 0 | S23: =IF(K23="背书",H23,0) -> 0 | T23: =IF(K23="到期承兑",H23,0) -> 0 | U23: =IF(K23="贴现",H23,0) -> 0 | V23: =Q23+R23-S23-T23-U23 -> 0 | W23: =IF(I23<$B$10,0,IF(J23<I23,S23+U23,0)) -> 0
A24: 商业承兑汇票小计 | Q24: =SUM(Q19:Q23) -> 0 | R24: =SUM(R19:R23) -> 0 | S24: =SUM(S19:S23) -> 0 | T24: =SUM(T19:T23) -> 0 | U24: =SUM(U19:U23) -> 0 | V24: =SUM(V19:V23) -> 0 | W24: =SUM(W19:W23) -> 0
A25: 合计 | N25: =SUM(N13:N24) -> 0 | Q25: =Q24+Q18 -> 0 | R25: =R24+R18 -> 0 | S25: =S24+S18 -> 0 | T25: =T24+T18 -> 0 | U25: =U24+U18 -> 0 | V25: =V24+V18 -> 0 | W25: =W24+W18 -> 0
A26: 三、审计说明
A27: 1.将被审计单位提供的票据备查簿与明细账核对结果如下： | G27: 2.贴现、票据已背书未到期明细：
A28: 项目 | B28: 期初余额 | C28: 本期增加额 | D28: 本期减少额 | E28: 期末余额 | G28: 分类 | H28: 终止确认 | I28: 不终止确认
A29: 备查簿 | B29: =Q25 -> 0 | C29: =R25 -> 0 | D29: =S25+T25+U25 -> 0 | E29: =B29+C29-D29 -> 0 | G29: 已背书未到期银行承兑汇票 | H29: =SUMIFS($W$13:$W$24,$X$13:$X$24,"是",$K$13:$K$24,"背书",$A$13:$A$24,"银行承兑汇票") -> 0 | I29: =SUMIFS($W$13:$W$24,$X$13:$X$24,"否",$K$13:$K$24,"背书",$A$13:$A$24,"银行承兑汇票") -> 0
A30: 明细账 | B30: ='原值明细表（按类别）D1-2'!B14 -> 0 | C30: ='原值明细表（按类别）D1-2'!F14 -> 0 | D30: ='原值明细表（按类别）D1-2'!G14 -> 0 | E30: =B30+C30-D30 -> 0 | G30: 已背书未到期商业承兑汇票 | H30: =SUMIFS($W$13:$W$24,$X$13:$X$24,"是",$K$13:$K$24,"背书",$A$13:$A$24,"商业承兑汇票") -> 0 | I30: =SUMIFS($W$13:$W$24,$X$13:$X$24,"否",$K$13:$K$24,"背书",$A$13:$A$24,"商业承兑汇票") -> 0
A31: 核对差异 | B31: =B29-B30 -> 0 | C31: =C29-C30 -> 0 | D31: =D29-D30 -> 0 | E31: =E29-E30 -> 0 | G31: 已贴现未到期银行承兑汇票 | H31: =SUMIFS($W$13:$W$24,$X$13:$X$24,"是",$K$13:$K$24,"贴现",$A$13:$A$24,"银行承兑汇票") -> 0 | I31: =SUMIFS($W$13:$W$24,$X$13:$X$24,"否",$K$13:$K$24,"贴现",$A$13:$A$24,"银行承兑汇票") -> 0
G32: 已贴现未到期商业承兑汇票 | H32: =SUMIFS($W$13:$W$24,$X$13:$X$24,"是",$K$13:$K$24,"贴现",$A$13:$A$24,"商业承兑汇票") -> 0 | I32: =SUMIFS($W$13:$W$24,$X$13:$X$24,"否",$K$13:$K$24,"贴现",$A$13:$A$24,"商业承兑汇票") -> 0
G33: 合计 | H33: =SUM(H29:H32) -> 0 | I33: =SUM(I29:I32) -> 0
G34: 勾稽 | H34: =W25-H33-I33 -> 0
A35: 四、审计结论
A37: 提示1：企业因销售商品、提供服务等取得的、不属于《中华人民共和国票据法》规范票据的“云信”、“融信”等数字化应收账款债权凭证，不应当在“应收票据”项目中列示。企业管理“云信”、“融信”等的业务模式以收取合同现金流量为目标的，应当在“应收账款”项目
A38: 中列示；既以收取合同现金流量为目标又以出售为目标的，应当在“应收款项融资”项目中列示。如果法律上认定供应链票据属于《商业汇票承兑、贴现与再贴现管理办法》（中国人民银行中国银行保险监督管理委员会令〔2022〕第4号）的范围、具备《票据法》规定的要件，
A39: 则持有方应当自法律认定生效日（2023年1月1日）起将其作为“应收票据”进行会计处理（根据其业务模式列示为应收票据或应收款项融资），且无需对前期比较期间数据进行追溯调整。
A40: 提示2：根据我国票据法对追索权的规定，在背书转让合同未明确约定无追索权的情况下，该类金融资产所有权相关的主要风险并没有转移，背书公司不应终止确认相关资产。——《证监会《2017年上市公司年报会计监管报告》

Sheet 应收票据贴现、票据已背书未到期明细表D1-8
A1: 致同会计师事务所
A2: 应收票据贴现、票据已背书未到期明细表
A3: =底稿目录!A2 -> 被审计单位名称： | E3: =底稿目录!A4 -> 编制人： | I3: =底稿目录!A5 -> 编制日期： | O3: 索引号： | P3: =底稿目录!F14 -> D1-8
A4: =底稿目录!A3 -> 截止日：202X年12月31日 | E4: =底稿目录!A6 -> 复核人： | I4: =底稿目录!A7 -> 复核日期： | O4: 页 次：
A5: 一、审计目标：
A6: 1.所有应记录的应收票据均已记录，所有应当包括在财务报表中的相关披露均已包括；
A7: 2.应收票据以恰当的金额包括在财务报表中，与之相关的计价或分摊调整已恰当记录，相关披露已得到恰当计量和描述 。
A8: 二、审计过程
A9: 1.……
A11: （一）已贴现尚未到期票据检查：
A12: 票据种类 | B12: 收到日期 | C12: 出票人全称 | D12: 票据号 | E12: 汇票金额 | F12: 已计利息 | G12: 出票日期 | H12: 到期日 | I12: 承兑银行 | J12: 承兑单位信用等级 | K12: 贴现银行 | L12: 贴现金额 | M12: 贴现息 | N12: 是否终止确认 | O12: 会计处理是否正确 | P12: 索引号
A22: 合计 | E22: =SUM(E14:E21) -> 0 | F22: =SUM(F14:F21) -> 0 | L22: =SUM(L14:L21) -> 0 | M22: =SUM(M14:M21) -> 0
A23: （二）已背书尚未到期票据检查：
A24: 票据种类 | B24: 收到日期 | C24: 出票人全称 | D24: 票据号 | E24: 汇票金额 | F24: 前手 | G24: 出票日期 | H24: 到期日 | I24: 承兑银行 | J24: 承兑单位信用等级 | K24: 背书转让单位 | L24: 背书转让日期 | M24: 说明 | N24: 是否终止确认 | O24: 会计处理是否正确 | P24: 索引号
A34: 合计 | E34: =SUM(E26:E33) -> 0
A35: 三、审计说明
A38: 四、审计结论

Sheet 应收票据贴息检查表D1-9
A1: 致同会计师事务所
A2: 应收票据贴息检查表
A3: =底稿目录!A2 -> 被审计单位名称： | D3: =底稿目录!A4 -> 编制人： | H3: =底稿目录!A5 -> 编制日期： | L3: 索引号： | M3: =底稿目录!F15 -> D1-9
A4: =底稿目录!A3 -> 截止日：202X年12月31日 | D4: =底稿目录!A6 -> 复核人： | H4: =底稿目录!A7 -> 复核日期： | L4: 页 次：
A5: 一、审计目标：
A6: 应收票据以恰当的金额包括在财务报表中，与之相关的计价或分摊调整已恰当记录，相关披露已得到恰当计量和描述 。
A7: 二、审计过程：
A8: 1.……
A10: 票据类型 | B10: 票面金额 | C10: 票面利率 | D10: 出票日期 | E10: 票据到期日 | F10: 到期日票据价值 | G10: 贴现日期 | H10: 贴息天数 | I10: 贴现率 | J10: 应计贴现利息 | K10: 账面贴现利息 | L10: 差异 | M10: 备注
H11: =E11-G11 -> 0 | J11: =I11/365*H11*B11 -> 0 | L11: =J11-K11 -> 0
H12: =E12-G12 -> 0 | J12: =I12/365*H12*B12 -> 0 | L12: =J12-K12 -> 0
H13: =E13-G13 -> 0 | J13: =I13/365*H13*B13 -> 0 | L13: =J13-K13 -> 0
H14: =E14-G14 -> 0 | J14: =I14/365*H14*B14 -> 0 | L14: =J14-K14 -> 0
H15: =E15-G15 -> 0 | J15: =I15/365*H15*B15 -> 0 | L15: =J15-K15 -> 0
H16: =E16-G16 -> 0 | J16: =I16/365*H16*B16 -> 0 | L16: =J16-K16 -> 0
H17: =E17-G17 -> 0 | J17: =I17/365*H17*B17 -> 0 | L17: =J17-K17 -> 0
A18: 合计 | B18: =SUM(B11:B17) -> 0 | J18: =SUM(J11:J17) -> 0 | K18: =SUM(K11:K17) -> 0 | L18: =SUM(L11:L17) -> 0
A19: 三、审计说明：
A23: 四、审计结论：

Sheet 应收票据监盘D1-10
A1: 致同会计师事务所
A2: 应收票据监盘表
A3: =底稿目录!A2 -> 被审计单位名称： | F3: =底稿目录!A4 -> 编制人： | J3: =底稿目录!A5 -> 编制日期： | N3: 索引号： | O3: =底稿目录!F16 -> D1-10
A4: =底稿目录!A3 -> 截止日：202X年12月31日 | F4: =底稿目录!A6 -> 复核人： | J4: =底稿目录!A7 -> 复核日期： | N4: 页次：
A5: 一、审计目标：
A6: 1.资产负债表中记录的应收票据是存在的，且已经记录在恰当的账户中。2.所有应记录的应收票据均已记录，所有应当包括在财务报表中的相关披露均已包括。
A7: 3.应收票据以恰当的金额包括在财务报表中，与之相关的计价或分摊调整已恰当记录，相关披露已得到恰当计量和描述
A8: 二、审计过程
A9: 1.……
A11: 监盘票据情况
A12: 监盘日结存 | M12: 是否存在差异 | N12: 差异原因 | O12: 索引号
A13: 票据类型 | B13: 票据号 | C13: 收到票据日期 | D13: 票据前手名称 | E13: 出票日期 | F13: 出票人名称 | G13: 承兑人名称 | H13: 票据金额 | I13: 票据到期日 | J13: 被背书人名称 | K13: 付款人名称 | L13: 是否质押
A21: 合计 | H21: =SUM(H14:H20) -> 0
A22: 盘点人： | F22: 监盘人： | M22: 监盘日期：
A23: 资产负债表日后票据倒轧表 | I23: 资产负债表日前票据倒轧表
A24: 监盘日金额 ① | B24: 资产负债表日至监盘日贷方发生额 ② | C24: 资产负债表至监盘日借方发生额 ③ | D24: 倒推至资产负债表日金额 ④=①+②-③ | E24: 资产负债表日账面金额 ⑤ | F24: 差异额 ⑥=④-⑤ | G24: 备注 | I24: 监盘日金额 ① | J24: 资产负债表日至监盘日贷方发生额 ② | K24: 资产负债表至监盘日借方发生额 ③ | L24: 倒推至资产负债表日金额 ④=①+③-② | M24: 资产负债表日账面金额 ⑤ | N24: 差异额 ⑥=④-⑤ | O24: 备注
A25: =H21 -> 0 | D25: =A25+B25-C25 -> 0 | F25: =D25-E25 -> 0 | I25: =H24 -> 0 | L25: =I25+K25-J25 -> 0 | N25: =L25-M25 -> 0
A26: 三、审计说明
A27: 1.审计人员于 年 月 日对公司的应收票据进行了监盘，监盘时将公司存放于 中的票据全部进行清点/核对电子汇票系统持有的电子票据。
A28: 如果核对电子汇票系统中的电子票据，应记录登录系统的过程、截图保存票据系统网页等检查过程。
A29: 2.我们均已查见票据原件，并与应收票据备查簿 年至 年 月 日相应的记录进行了逐一核对，核对项目包括：票据种类、出票日期、票据
A30: 号、出票人、前手、……，记录均核对一致（底稿见索引号 ），未发现已背书未到期的票据。监盘中发现……。
A31: 3.……
A32: 四、审计结论
A35: 提示：监盘日前已背书未到期的票据不应包含在应收票据监盘表中

Sheet 关联方关系及交易检查表D1-11
A1: 致同会计师事务所
A2: 应收票据关联方关系及交易检查表
A3: =底稿目录!A2 -> 被审计单位名称： | E3: =底稿目录!A4 -> 编制人： | I3: =底稿目录!A5 -> 编制日期： | L3: 索引号： | M3: =底稿目录!F17 -> D1-11
A4: =底稿目录!A3 -> 截止日：202X年12月31日 | E4: =底稿目录!A6 -> 复核人： | I4: =底稿目录!A7 -> 复核日期： | L4: 页次：
A5: 一、审计目标
A6: 资产负债表中记录的应收票据是存在的，且已经记录在恰当的账户中
A7: 二、审计过程
A8: 1.……
A10: 关联方名称 | B10: 关联关系 | C10: 期初余额 | D10: 借方发生 | E10: 贷方发生 | F10: 期末余额 | G10: 减：坏账准备 | H10: 账面价值 | I10: 发生时间及账龄 | J10: 发生原因（款项性质） | K10: 期后已兑现或已贴现 | L10: 索引号 | M10: 备注
A11: 债务人（股东）1 | F11: =C11+D11-E11 -> 0 | H11: =F11-G11 -> 0
A12: 债务人（股东）2 | F12: =C12+D12-E12 -> 0 | H12: =F12-G12 -> 0
A13: …… | F13: =C13+D13-E13 -> 0 | H13: =F13-G13 -> 0
A14: 合计 | C14: =SUM(C11:C13) -> 0 | D14: =SUM(D11:D13) -> 0 | E14: =SUM(E11:E13) -> 0 | F14: =SUM(F11:F13) -> 0 | G14: =SUM(G11:G13) -> 0 | H14: =SUM(H11:H13) -> 0 | K14: =SUM(K11:K13) -> 0
A15: 三、审计说明：
A19: 四、审计结论：
B24: 勿删、勿改
B25: 实际控制人
B26: 控股股东
B27: 控股股东、实际控制人的附属企业
B28: 持有5%以上股份的法人或其他组织
B29: 联营企业
B30: 合营企业
B31: 董高监等关键管理人员
B32: 其他关联方

Sheet 应收票据质押检查表D1-12
A1: 致同会计师事务所
A2: 应收票据质押情况检查表
A3: =底稿目录!A2 -> 被审计单位名称： | F3: =底稿目录!A4 -> 编制人： | J3: =底稿目录!A5 -> 编制日期： | O3: 索引号： | P3: =底稿目录!F18 -> D1-12
A4: =底稿目录!A3 -> 截止日：202X年12月31日 | F4: =底稿目录!A6 -> 复核人： | J4: =底稿目录!A7 -> 复核日期： | O4: 页 次：
A5: 一、审计目标：
A6: 记录的应收票据由被审计单位拥有或控制
A7: 二、审计过程：
A8: 1.……
A11: 票据类型 | B11: 票据号码 | C11: 收到票据日期 | D11: 票据前手名称 | E11: 出票日期 | F11: 出票人名称 | G11: 承兑人名称 | H11: 票据金额 | I11: 票据到期日 | J11: 质押金额 | K11: 质权人 | L11: 质押原因 | M11: 质押条件 | N11: 质押期限 | O11: 质押协议 | P11: 索引号
A18: 合计 | H18: =SUM(H12:H17) -> 0 | J18: =SUM(J12:J17) -> 0
A19: 三、审计说明：
A23: 四、审计结论：

Sheet 应收票据检查表D1-13
A1: 致同会计师事务所
A2: 应收票据检查表
A3: =底稿目录!A2 -> 被审计单位名称： | F3: =底稿目录!A4 -> 编制人： | I3: =底稿目录!A5 -> 编制日期： | P3: 索引号： | Q3: =底稿目录!F26 -> D1-13
A4: =底稿目录!A3 -> 截止日：202X年12月31日 | F4: =底稿目录!A6 -> 复核人： | I4: =底稿目录!A7 -> 复核日期： | P4: 页 次：
A5: 一、审计目标
A6: 1.资产负债表中记录的应收票据是存在的，且已经记录在恰当的账户中。2.应收票据以恰当的金额包括在财务报表中，与之相关的计价或分摊调整已恰当记录，相关披露已得到恰当计量和描述
A7: 二、样本选取标准与规模：
A8: 测试总体： | B8: 如应收票据借方发生额所有凭证共XX笔金额XX、贷方发生额所有凭证共XX笔金额XX | H8: 特定样本： | I8: XX金额以上（大额）、关联方/关联交易形成的款项、XX异常款项全部测试，共XX笔；
A9: 抽样总体： | B9: 测试总体扣除特定样本以外的样本，共XX笔、金额XX | H9: 确定的抽样样本量： | I9: 抽取XX笔（如果使用了样本计算器计算样本量，样本量计算过程见<XX>底稿）
A10: 抽样方法： | B10: 随机选样/系统选样/货币单元抽样/随意选样（非统计抽样适用） | H10: 抽样过程： | I10: 使用IDEA（XX抽样工具）选择XX数量、金额XX的样本进行测试，抽样工具中的样本选择过程和结果见<XX>底稿
A11: 三、测试：
A12: 测试内容说明：1.原始凭证是否齐全； 2.记账凭证与原始凭证是否相符；3.账务处理是否正确；4.是否记录于恰当的会计期间；5.……
A13: （1）本期增减变动检查
A14: 明细项目 | B14: 记账凭证 | I14: 支持性文件 | J14: 核对内容 | O14: 索引号 | P14: 是否异常 | Q14: 备注说明
B15: 日期 | C15: 凭证编号 | D15: 业务内容 | E15: 对方科目 | F15: 对方明细科目 | G15: 借方金额 | H15: 贷方金额 | J15: 1 | K15: 2 | L15: 3 | M15: 4 | N15: 5
A32: 合计 | G32: =SUM(G16:G31) -> 0 | H32: =SUM(H16:H31) -> 0
A34: （2）期后贴现\背书\调整等检查
A35: 明细项目 | B35: 记账凭证 | H35: 支持性文件 | J35: 核对内容 | O35: 索引号 | P35: 是否异常 | Q35: 备注说明
B36: 日期 | C36: 凭证编号 | D36: 业务内容 | E36: 对方科目 | F36: 对方明细科目 | G36: 贷方金额 | J36: 1 | K36: 2 | L36: 3 | M36: 4 | N36: 5
A45: 合计 | G45: =SUM(G37:G44) -> 0
A46: 三、审计说明
A47: 1.本期发生额、期末余额检查比例： | D47: 方向 | E47: 账面金额 | F47: 检查金额 | G47: 检查比例 | H47: 如果检查比例较低应扩大检查样本量或说明原因
D48: 本期借方 | E48: ='原值明细表（按类别）D1-2'!F14 -> 0 | F48: =G32 -> 0 | G48: =ROUND(F48/E48,4) -> #DIV/0!
D49: 本期贷方 | E49: ='原值明细表（按类别）D1-2'!G14 -> 0 | F49: =H32 -> 0 | G49: =ROUND(F49/E49,2) -> #DIV/0!
D50: 期末余额 | E50: ='原值明细表（按类别）D1-2'!K14 -> 0 | F50: =G45 -> 0 | G50: =ROUND(F50/E50,2) -> #DIV/0!
A51: 2.……
A53: 四、审计结论

Sheet 应收票据坏账准备会计政策检查D1-14
A1: 致同会计师事务所
A2: 应收票据坏账准备会计政策检查
A3: =底稿目录!A2 -> 被审计单位名称： | D3: =底稿目录!A4 -> 编制人： | F3: =底稿目录!A5 -> 编制日期： | H3: 索引号： | I3: =底稿目录!F27 -> D1-14
A4: =底稿目录!A3 -> 截止日：202X年12月31日 | D4: =底稿目录!A6 -> 复核人： | F4: =底稿目录!A7 -> 复核日期： | H4: 页次：
A5: 一、审计目标：
A6: 应收票据以恰当的金额包括在财务报表中，与之相关的计价或分摊调整已恰当记录，相关披露已得到恰当计量和描述。
A7: 二、审计过程：
A8: 1.……
A11: （一）应收票据坏账准备计提政策
A15: 【应说明被审计单位预期信用损失计量、组合划分依据等】
A16: （二）被审计单位历史坏账损失情况
A21: 【应说明被审计单位应收票据历史损失率的数据来源，以及项目组核实该等数据所执行的程序。需考虑货币的时间价值】
A22: （三）前瞻性信息的来源及其影响
A26: 【应说明被审计单位确定预期损失率的前瞻性信息来源（包括内部模型、第三方服务机构或利用外部专家工作等，以及项目组对前瞻
A27: 性信息可靠性所执行的程序】
A28: （四）同行业公司的坏账准备会计政策
... A37: 提示：上市公司会计政策披露示例参考
A38: 中国中铁 | B38: 对于应收票据及应收账款和合同资产，无论是否存在重大融资成分，本集团均按照整个存续期的预期信用损失计量损失准备。 本集团依据信用风险特征将应收票据及应收账款和合同资产划分为若干组合，在组合基础上计算预期信用损失，确定组合的依据如下： 应收票据组合1 商业承兑汇票 应收票据组合2 银行承兑汇票 对于划分为组合的应收票据和合同资产，本集团参考历史信用损失经验，结合当前状况以及对未来经济状况的预测，通过违约风险敞口和整个存续期预期信用损失率，计算预期信用损失。 组合 — 商业承兑汇票：整个存续期预期信用损失率 0.25% 组合 — 银行承兑汇票：本集团按照整个存续期预期信用损失计量银行承兑汇票坏账准备。本集团认为所持有的银行承兑汇票不存在重大的信用风险，不会因银行或其他出票人违约而产生重大损失。
A39: 南方航空 | B39: 对于应收账款和租赁应收款，本集团始终按照相当于整个存续期内预期信用损失的金额计量其损失准备。本集团基于历史信用损失经验、使用准备矩阵计算上述金融资产的预期信用损失，相关历史经验根据资产负债表日债务人的特定因素、以及对当前状况和未来经济状况预测的评估进行调整。
A40: 长城汽车 | B40: 本集团对由新收入准则规范的交易形成的未包含重大融资成分或不考虑不超过一年的合同中的融资成分的合同资产与应收账款按照相当于整个存续期内预期信用损失的金额计量损失准备。 本集团对应收账款、其他分类为按摊余成本计量的金融资产和分类为以公允价值计量且其变动计入其他综合收益的债务工具在组合基础上采用减值矩阵确定相关金融工具的信用损失。本集团以共同风险特征为依据，将金融工具分为不同组别。本集团采用的共同信用风险特征包括：金融工具类型、信用风险评级、担保物类型、初始确认日期、剩余合同期限、债务人所处行业、债务人所处地理位置、担保品相对于金融资产的价值等。
A41: 金隅集团 | B41: 对于不含重大融资成分的应收款项以及合同资产，本集团运用简化计量方法，按照相当于整个存续期内的预期信用损失金额计量损失准备。 对于租赁应收款、包含重大融资成分的应收款项以及合同资产，本集团选择运用简化计量方法，按照相当于整个存续期内的预期信用损失金额计量损失准备。 除某些金融资产基于单项为基础评估逾期信用损失之外，本集团还以账龄组合为基础评估以摊余成本计量金融资产的预期信用损失。 本集团在评估预期信用损失时，考虑所有合理且有依据的信息，包括前瞻性信息。

Sheet 应收票据坏账准备测试表D1-15
A1: 致同会计师事务所
A2: 应收票据坏账准备测算表
A3: =底稿目录!A2 -> 被审计单位名称： | C3: =底稿目录!A4 -> 编制人： | E3: =底稿目录!A5 -> 编制日期： | G3: 索引号： | H3: =底稿目录!F28 -> D1-15
A4: =底稿目录!A3 -> 截止日：202X年12月31日 | C4: =底稿目录!A6 -> 复核人： | E4: =底稿目录!A7 -> 复核日期： | G4: 页次：
A5: 一、审计目标
A6: 应收票据以恰当的金额包括在财务报表中，与之相关的计价或分摊调整已恰当记录，相关披露已得到恰当计量和描述
A7: 二、审计过程
A8: 1.重新计算应计提的坏账准备，与被审计单位已记录的坏账准备进行比较。
A11: （一）单项计提坏账准备
A12: 债务人名称 | B12: 审定应收票据账面余额 | C12: 预期信用损失率 | D12: 期末应计提坏账准备 | E12: 期末坏账准备账面余额 | F12: 差异 | G12: 坏账准备计提依据及文件 | H12: 索引号
B13: ① | C13: ② | D13: ③=①×② | E13: ④=①-③ | F13: ⑤=③-④
D14: =B14*C14 -> 0 | E14: =B14-D14 -> 0 | F14: =D14-E14 -> 0
D15: =B15*C15 -> 0 | E15: =B15-D15 -> 0 | F15: =D15-E15 -> 0
D16: =B16*C16 -> 0 | E16: =B16-D16 -> 0 | F16: =D16-E16 -> 0
D17: =B17*C17 -> 0 | E17: =B17-D17 -> 0 | F17: =D17-E17 -> 0
A18: 小计 | B18: =SUM(B14:B17) -> 0 | D18: =SUM(D14:D17) -> 0 | E18: =SUM(E14:E17) -> 0 | F18: =SUM(F14:F17) -> 0
A19: （二）分组合计提坏账准备
A20: 组合名称 | B20: 审定应收票据账面余额 | C20: 预期信用损失率 | D20: 期末应计提坏账准备 | E20: 期末坏账准备账面余额 | F20: 差异 | G20: 坏账准备计提依据及文件 | H20: 索引号
B21: ① | C21: ② | D21: ③=①×② | E21: ④=①-③ | F21: ⑤=③-④
A22: 信用风险等级高的银行承兑汇票 | D22: =B22*C22 -> 0 | E22: =B22-D22 -> 0 | F22: =D22-E22 -> 0
A23: 信用风险等级低的银行承兑汇票 | D23: =B23*C23 -> 0 | E23: =B23-D23 -> 0 | F23: =D23-E23 -> 0
A24: 商业承兑汇票 | D24: =B24*C24 -> 0 | E24: =B24-D24 -> 0 | F24: =D24-E24 -> 0
A25: 小计 | B25: =SUM(B22:B24) -> 0 | D25: =SUM(D22:D24) -> 0 | E25: =SUM(E22:E24) -> 0 | F25: =SUM(F22:F24) -> 0 | H25: =SUM(H22:H24) -> 0
A26: 三、审计说明
A30: 四、审计结论：
A32: 提示1:对于在收入确认时对应收账款进行初始确认，后又将该应收账款转为商业承兑汇票结算的，按照账龄连续计算的原则对应收票据计提坏账准备。（《首发审核财务与会计知识问答》）
A33: 提示2：预期信用损失计量测试可参考预期信用损失计算示例

Sheet 坏账准备转回、核销检查表D1-16
A1: 致同会计师事务所
A2: 应收票据大额坏账准备转回、核销检查表
A3: =底稿目录!A2 -> 被审计单位名称： | C3: =底稿目录!A4 -> 编制人： | E3: =底稿目录!A5 -> 编制日期： | G3: 索引号： | H3: =底稿目录!F29 -> D1-16
A4: =底稿目录!A3 -> 截止日：202X年12月31日 | C4: =底稿目录!A6 -> 复核人： | E4: =底稿目录!A7 -> 复核日期： | G4: 页 次：
A5: 一、审计目标
A6: 应收票据以恰当的金额包括在财务报表中，与之相关的计价或分摊调整已恰当记录，相关披露已得到恰当计量和描述
A7: 二、审计过程
A8: 1.……
A10: （一）本期重要的坏账准备转回检查
A11: 单位名称 | B11: 转回原因 | C11: 收回方式 | D11: 原确定坏账准备的依据 | E11: 收回或转回金额 | F11: 收回或转回前累计已计提坏账准备金额 | G11: 合理性分析 | H11: 索引号
A15: 合计 | E15: =SUM(E12:E14) -> 0 | F15: =SUM(F12:F14) -> 0
A16: （二）本期重要的核销应收票据检查
A17: 单位名称 | B17: 应收票据的性质 | C17: 核销金额 | D17: 核销原因 | E17: 履行的核销程序 | F17: 是否由关联交易产生 | G17: 合理性分析 | H17: 索引号
A21: 合计 | C21: =SUM(C18:C20) -> 0
A22: 三、审计说明
A26: 四、审计结论

Sheet 应收票据业务模式分析提示
A1: 应收票据业务模式分析
A2: 关于应收票据业务模式：
A3: 1.业务模式决定企业所管理金融资产现金流量的来源是收取合同现金流量、出售金融资产还是两者兼有。
A4: 2.业务模式是一项事实而非仅仅是认定，也不是一项选择，不依赖于管理层对单项工具的意图。
A5: 3.业务模式应当在反映如何对多组金融资产一起进行管理以实现特定业务目标的层次上确定。
A6: 4.出售本身并不能决定业务模式。 5.但频繁且重大的出售（贴现或背书）说明业务模式不是以收取合同现金流量为目标。
A8: 在了解被审计单位管理金融资产业务模式时，考虑：
A9: 1.了解并观察被审计单位如何管理其金融资产以产生现金流量
A10: 1.1 了解被审计单位关键管理人员决定的对金融资产进行管理的特定业务目标；
A11: 1.2 考虑被审计单位评价和向关键管理人员报告金融资产业绩的方式、影响金融资产业绩的风险及其管理方式以及相关业务管理人员获得报酬的方式（例如报酬是基于所管理资产的公允价值还是所收取的合同现金流量）等。
A12: 2. 了解被审计单位确定业务模式的层次。若被审计单位将应收票据划分为不同的组合从而确定多个业务模式，分析划分组合的依据是否明确，各组合是否可明确区分。
A13: 3. 对于以收取合同现金流量为目标的业务模式：
... A22: 5.2 了解被审计单位是否基于应收票据的公允价值作出决策并对其进行管理。
