Workbook

Sheet 底稿目录
A1: 底稿开列时，可先在以下单元格填写有关内容，以便其他底稿引用有关数据：
A2: 被审计单位名称： | D2: 序号 | E2: 内容 | F2: 索引号
A3: 截止日：202X年12月31日 | D3: 1 | E3: 程序表 | F3: D5A
A4: 编制人： | D4: 2 | E4: 审定表 | F4: D5-1
A5: 编制日期： | D5: 3 | E5: 附注披露信息（上市公司） | G5: 无需打印
A6: 复核人： | D6: 4 | E6: 附注披露信息（国企） | G6: 无需打印
A7: 复核日期： | D7: 5 | E7: 明细表 | F7: D5-2
D8: 6 | E8: 调整分录汇总表 | F8: D5-3
A9: 关于工作底稿与审计程序索引号对应的说明 | D9: 7 | E9: 公允价值测算表 | F9: D5-4
A10: 1.编制的审计工作底稿应与审计程序对应。审计项目组应根据被审计单位实际情况和风险评估情况在实质性程序表中裁剪、修改或增加审计程序，根据实际执行的审计程序完成相应审计工作底稿，编制的工作底稿中应按自然顺序依次编制索引号，并通过唯一的索引号将与实质性程序表中的程序对应关联（即将工作底稿的索引号填入实质性程序表中的底稿索引号列）。
A14: 2.获取的支持性证据应与审计底稿或程序对应。审计项目组在完成底稿时获取的支持性证据应根据底稿索引号编制下一级按自然顺序排序的索引号（如D1-2-1、D1-2-2、……），并在底稿中说明引用的支持性证据、关联索引号。
A17: 3.工作底稿索引号的编码规则：实质性程序索引号按循环从“D”到“N”,循环内账户以顺序号排列，模板中底稿索引号按账户顺序+自然数顺序（即模板中索引号按二级自然顺序排列，如D1-1、D1-2、D1-3、……D1-N）。

Sheet 应收款项融资审计程序表D5A
A1: 致同会计师事务所
A2: 应收款项融资实质性程序表
A3: =底稿目录!A2 -> 被审计单位名称： | C3: =底稿目录!A4 -> 编制人： | E3: =底稿目录!A5 -> 编制日期： | H3: 索引号： | I3: D5A
A4: =底稿目录!A3 -> 截止日：202X年12月31日 | C4: =底稿目录!A6 -> 复核人： | E4: =底稿目录!A7 -> 复核日期： | H4: 页次：
A5: 一、本账户涉及的科目
A6: 应收款项融资
A7: 二、审计目标与认定的对应关系
A8: 审计目标 | G8: 财务报表的认定
A9: A.资产负债表中记录的应收款项融资是存在的，且已经记录在恰当的账户中 | G9: 存在
A10: B.所有应记录的应收款项融资均已记录，所有应当包括在财务报表中的相关披露均已包括 | G10: 完整性
A11: C.记录的应收款项融资由被审计单位拥有或控制 | G11: 权利和义务
A12: D.应收款项融资以恰当的金额包括在财务报表中，与之相关的计价或分摊调整已恰当记录，相关披露已得到恰当计量和描述 | G12: 准确性、计价和分摊
A13: E.应收款项融资已被恰当地汇总或分解且表述清楚，相关披露在按照企业会计准则的编制基础下是相关的、可理解的 | G13: 列报
A14: 三、计划实施的实质性程序
A15: 序号 | B15: 审计程序 | C15: 程序分类 | D15: 财务报表的认定 | I15: 底稿索引号
D16: 存在 | E16: 完整性 | F16: 权利和 义务 | G16: 准确性、计价和分摊 | H16: 列报 | J16: 根据被审计单位实际情况和风险评估情况裁剪、修改或增加审计程序
A17: 1 | B17: 获取或编制应收款项融资明细表，复核加计是否正确，与总账、明细账合计数核对是否相符，并编制审定表。 | C17: 常规★ | D17: √ | E17: √ | G17: √ | I17: D5-1 /D5-2
A18: 2 | B18: 对期初余额的审计，取得应收款项融资期初余额明细表复核加计是否正确，与总账、明细账合计数是否相符，检查期初金额在本期出售或收回情况，必要时，函证期初余额以及其他必要追加的审计程序。（适用于首次承接） | C18: 备选 | D18: √ | E18: √ | F18: √ | G18: √
A19: 3 | B19: 了解并观察被审计单位被审计单位管理应收款项融资的业务模式，结合合同现金流量特征，判断应收款项融资分类是否正确。 | C19: 常规★ | D19: √ | H19: √ | I19: D1-6 /D2-13
A20: 4 | B20: 结合应收票据、应收账款科目审计，对应收款项融资执行函证、监盘等程序。 | C20: 常规★ | D20: √ | E20: √ | F20: √ | G20: √ | I20: D0 /D1-7 /D1-10
A21: 5 | B21: 重新计算应收款项融资公允价值计量是否正确 | C21: 常规★ | G21: √ | I21: D5-4
A22: 6 | B22: 根据评估的舞弊风险等因素增加的审计程序。 | C22: IPO/上市/新三板/重组/舞弊应对
A23: 7 | B23: 检查应收款项融资是否已按企业会计准则或其他适用的规定在财务报表中做出恰当列报和披露。 | C23: 常规★ | H23: √ | I23: A1-1/A1-15 /A1-16

Sheet 审定表D5
A1: 致同会计师事务所
A2: 应收款项融资审定表
A3: =底稿目录!A2 -> 被审计单位名称： | E3: =底稿目录!A4 -> 编制人： | H3: =底稿目录!A5 -> 编制日期： | J3: 索引号： | K3: D5-1
A4: =底稿目录!A3 -> 截止日：202X年12月31日 | E4: =底稿目录!A6 -> 复核人： | H4: =底稿目录!A7 -> 复核日期： | J4: 页次：
A5: 项目 | B5: 期初数 | F5: 期末数 | J5: 期末与期初审定数比较
B6: 未审数 | C6: 账项调整 | D6: 重分类调整 | E6: 审定数 | F6: 未审数 | G6: 账项调整 | H6: 重分类调整 | I6: 审定数 | J6: 变动额 | K6: 变动率
A7: 应收票据 | B7: =SUMIF('应收款项融资明细表D5-2'!$B$12:$B$16,A7,'应收款项融资明细表D5-2'!C12:C16) -> 0 | C7: =SUMIF('应收款项融资明细表D5-2'!$B$12:$B$16,A7,'应收款项融资明细表D5-2'!D12:D16) -> 0 | D7: =SUMIF('应收款项融资明细表D5-2'!$B$12:$B$16,A7,'应收款项融资明细表D5-2'!E12:E16) -> 0 | E7: =B7+C7+D7 -> 0 | F7: =SUMIF('应收款项融资明细表D5-2'!$B$12:$B$16,A7,'应收款项融资明细表D5-2'!J12:J16) -> 0 | G7: =SUMIF('应收款项融资明细表D5-2'!$B$12:$B$16,A7,'应收款项融资明细表D5-2'!M12:M16) -> 0 | H7: =SUMIF('应收款项融资明细表D5-2'!$B$12:$B$16,A7,'应收款项融资明细表D5-2'!N12:N16) -> 0 | I7: =F7+G7+H7 -> 0 | J7: =I7-E7 -> 0 | K7: =IF(AND(E7=0,I7=0),"",IF(AND(E7=0,I7>0),1,J7/E7))
A8: 应收账款 | B8: =SUMIF('应收款项融资明细表D5-2'!$B$12:$B$16,A8,'应收款项融资明细表D5-2'!C12:C16) -> 0 | C8: =SUMIF('应收款项融资明细表D5-2'!$B$12:$B$16,A8,'应收款项融资明细表D5-2'!D12:D16) -> 0 | D8: =SUMIF('应收款项融资明细表D5-2'!$B$12:$B$16,A8,'应收款项融资明细表D5-2'!E12:E16) -> 0 | E8: =B8+C8+D8 -> 0 | F8: =SUMIF('应收款项融资明细表D5-2'!$B$12:$B$16,A8,'应收款项融资明细表D5-2'!J12:J16) -> 0 | G8: =SUMIF('应收款项融资明细表D5-2'!$B$12:$B$16,A8,'应收款项融资明细表D5-2'!M12:M16) -> 0 | H8: =SUMIF('应收款项融资明细表D5-2'!$B$12:$B$16,A8,'应收款项融资明细表D5-2'!N12:N16) -> 0 | I8: =F8+G8+H8 -> 0 | J8: =I8-E8 -> 0 | K8: =IF(AND(E8=0,I8=0),"",IF(AND(E8=0,I8>0),1,J8/E8))
A9: 小计 | B9: =SUM(B7:B8) -> 0 | C9: =SUM(C7:C8) -> 0 | D9: =SUM(D7:D8) -> 0 | E9: =B9+C9+D9 -> 0 | F9: =SUM(F7:F8) -> 0 | G9: =SUM(G7:G8) -> 0 | H9: =SUM(H7:H8) -> 0 | I9: =F9+G9+H9 -> 0 | J9: =I9-E9 -> 0 | K9: =IF(AND(E9=0,I9=0),"",IF(AND(E9=0,I9>0),1,J9/E9))
A10: 减：其他综合收益-公允价值变动 | E10: =B10+C10+D10 -> 0 | I10: =F10+G10+H10 -> 0 | J10: =I10-E10 -> 0 | K10: =IF(AND(E10=0,I10=0),"",IF(AND(E10=0,I10>0),1,J10/E10))
A11: 应收款项融资公允价值合计 | B11: =B7+B8-B10 -> 0 | C11: =C7+C8-C10 -> 0 | D11: =D7+D8-D10 -> 0 | E11: =E7+E8-E10 -> 0 | F11: =F7+F8-F10 -> 0 | G11: =G7+G8-G10 -> 0 | H11: =H7+H8-H10 -> 0 | I11: =I7+I8-I10 -> 0 | J11: =I11-E11 -> 0 | K11: =IF(AND(E11=0,I11=0),"",IF(AND(E11=0,I11>0),1,J11/E11))
A12: 试算平衡表数
A13: 差异数 | E13: =E11-E12 -> 0 | I13: =I11-I12 -> 0
A14: 1.审计说明 | F14: 2.审计结论
A15: （1）应收款项融资本期较上期增加（负数为减少）：
A16: 主要原因（比例超过30%的）：

Sheet 附注披露信息（上市公司）
A1: 致同会计师事务所
A2: 附注披露信息（上市公司）
A3: =底稿目录!A2 -> 被审计单位名称： | C3: =底稿目录!A4 -> 编制人： | E3: =底稿目录!A5 -> 编制日期： | G3: 索引号：
A4: =底稿目录!A3 -> 截止日：202X年12月31日 | C4: =底稿目录!A6 -> 复核人： | E4: =底稿目录!A7 -> 复核日期： | G4: 页次：
A5: 附注披露信息
A6: 【提示：“应收款项融资”项目，反映资产负债表日以公允价值计量且其变动计入其他综合收益的应收票据和应收账款等。 就票据的贴现或背书而言，首先需要分析贴现或背书是否导致了终止确认。对于信用等级较低的银行承兑的汇票或由企业承兑的商业承兑汇票，贴现或背书时并不能终止确认，因此并未导致会计上的“出售”，进而也不会改变企业管理应收票据的业务模式仍然是以收取合同现金流量为目标。其次，若企业的贴现或背书行为并不频繁，或者虽然频繁但金额不大，则也可能不改变以收取合同现金流量为目标的业务模式。 如果企业经常贴现或背书信用等级较高的银行承兑的汇票，则其业务模式可能是既以收取合同现金流量为目标又以出售该金融资产为目标，从而可能需要在“应收款项融资”项目列报。】
A7: 【应收款项融资的披露应当参考应收账款和应收票据的相关披露内容。】
A8: 项 目 | B8: 期末余额 | C8: 上年年末余额
A9: 应收票据 | B9: =审定表D5!I7 -> 0 | C9: =审定表D5!E7 -> 0
A10: 应收账款 | B10: =审定表D5!I8 -> 0 | C10: =审定表D5!E8 -> 0
A11: 小 计 | B11: =审定表D5!I9 -> 0 | C11: =审定表D5!E9 -> 0
A12: 减：其他综合收益-公允价值变动 | B12: =审定表D5!I10 -> 0 | C12: =审定表D5!E10 -> 0
A13: 期末公允价值 | B13: =B11-B12 -> 0 | C13: =C11-C12 -> 0
A14: 【应收票据票面金额或应收账款余额-公允价值变动=期末公允价值】
A15: 说明：应收款项融资本期增减变动及公允价值变动情况。
A16: 本公司所属部分子公司视其日常资金管理的需要将一部分银行承兑汇票进行贴现和背书，故将该子公司的银行承兑汇票分类为以公允价值计量且其变动计入其他综合收益的金融资产。
A17: 本公司无单项计提减值准备的银行承兑汇票。于2021年12月31日，本公司认为所持有的银行承兑汇票不存在重大信用风险，不会因银行违约而产生重大损失。
A18: 或
A19: （1）本期计提、收回或转回的减值准备情况
B20: 减值准备金额
A21: 上年年末余额 | B21: =审定表D5!#REF! -> #REF!
A22: 本期计提
A23: 本期收回或转回
A24: 本期核销
A25: [本期转销]
A26: [其他]
A27: 期末余额 | B27: =B21+B22-B23-B24-B25-B26 -> #REF!
A28: 【提示：若涉及应收账款，本期计提、收回或转回的减值准备情况参考应收账款（2）（3）进行披露。】
A29: （2）期末本公司已质押的应收票据
A30: 种 类 | B30: 期末已质押金额
A31: 银行承兑票据
A32: 商业承兑票据
A33: 合 计 | B33: =SUM(B31:B32) -> 0
A34: （3）期末本公司已背书或贴现但尚未到期的应收票据
A35: 种 类 | B35: 期末终止确认金额 | C35: 期末未终止确认金额
A36: 银行承兑票据
A37: 商业承兑票据
A38: 合 计 | B38: =SUM(B36:B37) -> 0 | C38: =SUM(C36:C37) -> 0
A39: 【上面各张表均可添加行项目】
A40: （如根据《企业会计准则第23号——金融资产转移》终止确认的应收票据，列示其终止确认的金额，及与终止确认相关的利得和损失）
...

Sheet 附注披露信息（国企）
A1: 致同会计师事务所
A2: 附注披露信息（国企）
A3: =底稿目录!A2 -> 被审计单位名称： | C3: =底稿目录!A4 -> 编制人： | E3: =底稿目录!A5 -> 编制日期： | F3: 索引号：
A4: =底稿目录!A3 -> 截止日：202X年12月31日 | C4: =底稿目录!A6 -> 复核人： | E4: =底稿目录!A7 -> 复核日期： | F4: 页次：
A5: 附注披露信息
A6: （1）应收款项融资分项目列示
A7: 项 目 | B7: 期末余额 | C7: 期初余额
A8: 应收票据
A9: 应收账款
A10: 合 计 | B10: =SUM(B8:B9) -> 0 | C10: =SUM(C8:C9) -> 0
A11: 【提示：1、应收账款，本期计提、收回或转回的减值准备情况参考附注八、5、（3）进行披露；本期实际核销的应收款项融资情况参考附注八、5、（4）进行披露。
A12: 2、应收票据，期末质押、背书或贴现且在资产负债表日尚未到期、出票人未履约、坏账准备计提情况参考附注八、4、（2）（3）（4）（5）（6）进行披露】

Sheet 应收款项融资明细表D5-2
A1: 致同会计师事务所
A2: 应收款项融资明细表
A3: =底稿目录!A2 -> 被审计单位名称： | F3: =底稿目录!A4 -> 编制人： | J3: =底稿目录!A5 -> 编制日期： | P3: 索引号： | Q3: D5-2
A4: =底稿目录!A3 -> 截止日：202X年12月31日 | F4: =底稿目录!A6 -> 复核人： | J4: =底稿目录!A7 -> 复核日期： | P4: 页次：
A5: 一、审计目标
A6: 所有应记录的应收款项融资均已记录，所有应当包括在财务报表中的相关披露均已包括
A7: 二、审计过程
A8: 1.……
A10: 类别 | B10: 明细项目 | C10: 期初数 | H10: 本期变动 | J10: 期末数 | Q10: 备注
C11: 未审数 | D11: 账项调整 | E11: 重分类调整 | F11: 审定数 | G11: 其他综合收益-应收款项融资减值准备余额 | H11: 本期增加 | I11: 本期减少 | J11: 期末余额 | K11: 被审计单位重分类调整 | L11: 期末未审余额 | M11: 账项调整 | N11: 重分类调整 | O11: 审定数 | P11: 其他综合收益-应收款项融资减值准备余额
F12: =C12+E12+D12 -> 0 | J12: =C12+H12-I12 -> 0 | L12: =J12+K12 -> 0 | O12: =J12+N12+M12 -> 0
F13: =C13+E13+D13 -> 0 | J13: =C13+H13-I13 -> 0 | L13: =J13+K13 -> 0 | O13: =J13+N13+M13 -> 0
F14: =C14+E14+D14 -> 0 | J14: =C14+H14-I14 -> 0 | L14: =J14+K14 -> 0 | O14: =J14+N14+M14 -> 0
F15: =C15+E15+D15 -> 0 | J15: =C15+H15-I15 -> 0 | L15: =J15+K15 -> 0 | O15: =J15+N15+M15 -> 0
F16: =C16+E16+D16 -> 0 | J16: =C16+H16-I16 -> 0 | L16: =J16+K16 -> 0 | O16: =J16+N16+M16 -> 0
A17: 合计 | C17: =SUM(C12:C16) -> 0 | D17: =SUM(D12:D16) -> 0 | E17: =SUM(E12:E16) -> 0 | F17: =SUM(F12:F16) -> 0 | G17: =SUM(G12:G16) -> 0 | H17: =SUM(H12:H16) -> 0 | I17: =SUM(I12:I16) -> 0 | J17: =SUM(J12:J16) -> 0 | ... P17: =SUM(P12:P16) -> 0
A18: 三、审计说明
A22: 四、审计结论
A24: 提示：应收款项融资分类为以公允价值计量且其变动计入其他综合收益的金融资产，产生的预期信用损失应列报在其他综合收益-信用减值准备，不影响应收款项融资报表项目数据。

Sheet 调整分录汇总表D5-3
A1: 致同会计师事务所
A2: 应收款项融资调整分录汇总表
A3: =底稿目录!A2 -> 被审计单位名称： | D3: =底稿目录!A4 -> 编制人： | F3: =底稿目录!A5 -> 编制日期： | I3: 索引号： | J3: D5-3
A4: =底稿目录!A3 -> 截止日：202X年12月31日 | D4: =底稿目录!A6 -> 复核人： | F4: =底稿目录!A7 -> 复核日期： | I4: 页次：
A5: 调整事项说明 | B5: 类别（报表调整/账项调整/其他） | C5: 报表项目 | D5: 科目名称 | E5: 附注项目 | F5: …… | G5: 借方调整金额 | H5: 贷方调整金额 | I5: 索引 | J5: 备注
A21: 1.审计说明
A25: 2.审计结论
A27: 提示：本底稿适用于调整分录较多、较复杂的项目，且仅列示与本报表项目相关的审计调整。项目组可根据项目实际情况选择是否使用该底稿。

Sheet 应收款项融资公允价值测算表D5-4
A1: 致同会计师事务所
A2: 应收款项融资公允价值测算表
A3: =底稿目录!A2 -> 被审计单位名称： | E3: =底稿目录!A4 -> 编制人： | I3: =底稿目录!A5 -> 编制日期： | L3: 索引号： | M3: D5-4
A4: =底稿目录!A3 -> 截止日：202X年12月31日 | E4: =底稿目录!A6 -> 复核人： | I4: =底稿目录!A7 -> 复核日期： | L4: 页次：
A5: 一、审计目标
A6: 应收款项融资以恰当的金额包括在财务报表中，与之相关的计价或分摊调整已恰当记录，相关披露已得到恰当计量和描述
A7: 二、审计过程
A8: 1.……
A10: 类别 | B10: 明细项目 | C10: 期末余额 | H10: 市场贴现利率 | I10: 贴现利息/ 保理费用 | J10: 贴现金额/ 保理金额 | K10: 应收款项融资期末公允价值 | L10: 公允价值层次 | M10: 备注
C11: 票据号 | D11: 票面金额 | E11: 计量日 | F11: 到期日 | G11: 剩余日期（天）
A12: 应收票据 | B12: 应收银行承兑汇票 | D12: 13000000 | E12: 44561 | F12: 44742 | G12: =F12-E12 -> 181 | H12: 0.0404 | I12: =D12*H12*G12/365 -> 260441.64 | J12: =D12-I12 -> 12739558 | K12: =J12 -> 12739558 | L12: 第二层次
K13: =J13 -> 0
K14: =J14 -> 0
K15: =J15 -> 0
K16: =J16 -> 0
A17: 合计 | D17: =SUM(D12:D16) -> 13000000 | I17: =SUM(I12:I16) -> 260441.64 | J17: =SUM(J12:J16) -> 12739558 | K17: =SUM(K12:K16) -> 12739558
A18: 三、审计说明：
A22: 四、审计结论：
A24: 提示1：票据背书金额是结算负债的金额，因此不是公允价值（公允价值是脱手价）。公允价值，是指市场参与者在计量日发生的有序交易中，出售一项资产所能收到或者转移一项负债所需支付的价格。
A25: 提示2：若贴现利率属于可观察输入值，则公允价值属于第二层次；若贴现利率不属于可观察输入值（例如单独协商），则公允价值属于第三层次；
A26: 另外，若考虑重要性后直接以票面金额作为公允价值的替代，则属于第三层次。
