Workbook
Name _.dbf: #REF!
Name _00510: #REF!
Name _1、: #REF!
Name _1、受本循环影响的相关交易和账户余额: #REF!
Name _13: #REF!
Name _1w6_: #REF!
Name _1固定资产数据库_筛选打印: #REF!
Name _2、主要业务活动: #REF!
Name _2、注册会计师通常应在本循环中了解与上述业务活动相关的内部控制_如果计划在其他业务循环中对上述: #REF!
Name _2其他资产_开办费除外_明细表: #REF!
Name _3余额表_一级_.dbf: #REF!
Name _YE1: #REF!
Name _YS1: #REF!
Name _YS2: '[1]YS02-02'!#REF!
Name a: #REF!
Name a1c1: #REF!,#REF!
Name aa: #REF!
Name aaa: #REF!
Name agmmt: #REF!
Name agmt: #REF!
Name agmt1: #REF!
Name al: #REF!
Name avg_days: [2]Sheet3!$A$2
Name a暗暗: [3]企业表一!$F$20
Name b: #REF!
Name BD: #REF!
Name beg_day: #REF!
Name beg_day1: #REF!
Name CarryKnown: #REF!
Name CarryKnownTable: #REF!
Name CarryLikely: #REF!
Name CarryLikelyTable: #REF!
Name Carryover_Effect_of_Prior_Year: #REF!
Name CarryoverTitle: #REF!
Name CC_Instruction: #REF!
Name CE_CarryKnownProtection: #REF!
Name CE_CarryKnownTable: #REF!
Name CE_CarryLikely1Protection: #REF!
Name CE_CarryLikely1Table: #REF!
Name CE_CarryLikely2Protection: #REF!
Name CE_CarryLikely2Table: #REF!
Name CE_CarryTaxable: #REF!
Name CE_Desc: #REF!
Name CE_Income: #REF!
Name CE_KeepFormat: #REF!
Name CE_KnownChange: #REF!
Name CE_KnownFormulaProtection: #REF!
Name CE_KnownImpact: #REF!
Name CE_Likely1Change: #REF!
Name CE_Likely1FormulaProtection: #REF!
Name CE_Likely1Impact: #REF!
Name CE_Likely2Change: #REF!
Name CE_Likely2FormulaProtection: #REF!
Name CE_Likely2Impact: #REF!
Name CE_SheetCorrect: #REF!
Name CE_StatementImpact: #REF!
Name CE_TotalProtection: #REF!
Name CE_WholeSheet: #REF!
Name CE_XF1: #REF!
Name CE_XF1Rng1: #REF!

Sheet 底稿目录
A1: 底稿开列时，可先在以下单元格填写有关内容，以便其他底稿引用有关数据：
A2: 被审计单位：
A3: 截止日：202X年12月31日 | D3: 序号 | E3: 内容 | F3: 索引号
A4: 编制人： | D4: 1 | E4: 合同负债实质性程序表 | F4: D7A
A5: 编制日期： | D5: 2 | E5: 审定表 | F5: D7-1
A6: 复核人： | D6: 3 | E6: 附注披露信息(上市公司) | G6: 无需打印
A7: 复核日期： | D7: 4 | E7: 附注披露信息(国企) | G7: 无需打印
D8: 5 | E8: 明细表 | F8: D7-2
A9: 关于工作底稿与审计程序索引号对应的说明 | D9: 6 | E9: 调整分录汇总表 | F9: D7-3
A10: 1.编制的审计工作底稿应与审计程序对应。审计项目组应根据被审计单位实际情况和风险评估情况在实质性程序表中裁剪、修改或增加审计程序，根据实际执行的审计程序完成相应审计工作底稿，编制的工作底稿中应按自然顺序依次编制索引号，并通过唯一的索引号将与实质性程序表中的程序对应关联（即将工作底稿的索引号填入实质性程序表中的底稿索引号列）。 | D10: 7 | E10: 合同负债分析表 | F10: D7-4
D11: 8 | E11: 函证结果汇总表 | F11: D0-1
D12: 9 | E12: 核实被函证单位信息 | F12: D0-2
D13: 10 | E13: 跟函函证过程控制 | F13: D0-3
A14: 2.获取的支持性证据应与审计底稿或程序对应。审计项目组在完成底稿时获取的支持性证据应根据底稿索引号编制下一级按自然顺序排序的索引号（如D1-2-1、D1-2-2、……），并在底稿中说明引用的支持性证据、关联索引号。 | D14: 11 | E14: 函证差异调节表 | F14: D0-4
D15: 12 | E15: 合同负债及销售替代程序检查表 | F15: D0-5
D16: 13 | E16: 邮件传真回函可靠性验证 | F16: D0-7
A17: 3.工作底稿索引号的编码规则：实质性程序索引号按循环从“D”到“N”,循环内账户以顺序号排列，模板中底稿索引号按账户顺序+自然数顺序（即模板中索引号按二级自然顺序排列，如D1-1、D1-2、D1-3、……D1-N）。 | D17: 14 | E17: 函证程序舞弊风险评价表 | F17: D0-8
D18: 16 | E18: 账龄1年以上合同负债检查表 | F18: D7-5
D19: 17 | E19: 关联方关系及交易检查表 | F19: D7-6
D20: 18 | E20: 合同负债检查表 | F20: D7-7

Sheet 合同负债实质性程序表 D7A
A1: 致同会计师事务所
A2: 合同负债的实质性程序
A3: =底稿目录!A2 -> 被审计单位： | C3: =底稿目录!A4 -> 编制人： | E3: =底稿目录!A5 -> 编制日期： | H3: 索引号： | I3: D7A
A4: =底稿目录!A3 -> 截止日：202X年12月31日 | C4: =底稿目录!A6 -> 复核人： | E4: =底稿目录!A7 -> 复核日期： | H4: 页次：
A5: 一、本循环涉及的财务报表项目
A6: 合同负债
A7: 二、审计目标与认定的对应关系
A8: 审计目标 | G8: 财务报表的认定
A9: A.资产负债表中记录的合同负债是存在的，且已经记录在恰当的账户中 | G9: 存在
A10: B.所有应当记录的货币合同负债均已记录，所有应当包括在财务报表中的相关披露均已包括 | G10: 完整性
A11: C.记录的合同负债是被审计单位应当履行的现时义务 | G11: 权利和义务
A12: D.合同负债以恰当的金额包括在财务报表中，与之相关的计价或分摊调整已恰当记录，相关披露已得到恰当计量和描述 | G12: 准确性、计价和分摊
A13: E.合同负债已被恰当地汇总或分解且表述清楚，相关披露在按照企业会计准则的编制基础下是相关的、可理解的 | G13: 列报
A14: 三、计划实施的实质性程序
A15: 序号 | B15: 审计程序 | C15: 程序分类 | D15: 财务报表的认定 | I15: 底稿索引号
D16: 存在 | E16: 完整性 | F16: 权利和义务 | G16: 准确性、计价和分摊 | H16: 列报 | J16: 根据被审计单位实际情况和风险评估情况裁剪、修改或增加审计程序
A17: 1 | B17: 获取或编制合同负债明细表，完成以下工作，并编制审定表： （1）复核加计是否正确，与总账、明细账合计数核对是否相符，期初余额与上期审定期末余额是否相符； （2）以非记账本位币结算的合同负债，检查其采用的折算汇率及折算是否正确； （3）检查是否存在借方余额，必要时进行重分类调整； （4）结合应收账款等往来款项目的明细余额，检查是否存在多方挂账的项目，必要时做出调整。 （5）与合同资产明细余额核对，检查是否存在同一合同未净额列报的情况。 | C17: 常规★ | D17: √ | E17: √ | G17: √ | I17: D7-1 /D7-2
A18: 2 | B18: 在使用手工编制、自定义信息报告、系统生成的非固定格式报告等由被审计单位生成的信息时，测试有关信息准确性和完整性，并考虑针对编制和维护由被审计单位生成的信息的相关控制实施控制测试，以评价该信息是否能够为实现审计目的提供基础。 | C18: 常规★ | E18: √ | G18: √ | I18: T1 /D0-2 | J18: 可参见《审计手册》4.2.6，由被审计单位生成的信息可能是由系统生成的、或手工编制的、或二者兼而有之的方式生成的。例如，由被审计单位生成的信息可能包括： • 不涉及自定义的、由系统生成的报告（如，固定格式报告）； • 可能通过人工自定义的、由系统生成的报告，例如，（计算机）查询信息或特别定制的报告； • 手工编制的信息，例如，汇总信息的电子表格或用以支持分配、计算以及调节的电子表格； • 其他系统生成或手工编制的信息，例如，由被审计单位编制的客户发票； • 通过影印、拍摄、扫描或其他方式转换成电子形式的文件记录。
A19: 3 | B19: 对期初余额的审计，取得合同负债期初余额明细表复核加计是否正确，与总账、明细账合计数是否相符，检查上期合同负债在本期结转情况，函证期初余额以及其他必要追加的审计程序。（适用于首次承接） | C19: 备选 | D19: √ | E19: √ | F19: √ | G19: √ | J19: 由被审计单位生成的信息不包括： • 总分类账或明细分类账、试算平衡表、或经审计的财务报表； • 第三方（除了服务机构）的报表或报告，例如，原始银行对账单，或函证的回函； • 外部数据（例如，第三方发布的数据，如，定价来源）。
A20: 4 | B20: 实施分析性程序： （1）分析借贷方发生额，与对应科目比较是否存在异常； （1）比较主要客户合同负债余额变动情况，分析合理性； | C20: 常规★ | D20: √ | G20: √ | I20: D7-4 | J20: 合同负债由被审计单位生成的信息例如：合同负债项目台账等被审计单位提供信息
A21: 5 | B21: 实施函证程序： （1）以积极方式对合同负债进行函证，设计询证函、发函前核实被函证单位信息； （2）注册会计师独立收发询证函； （3）编制函证结果汇总表，检查发函、回函物流信息和轨迹、比对回函印章和签字等以核实回函的真实性，检查回函是否相符，对不符事项查明原因确定是否存在错报； （4）如果未收到回函，应当考虑与被询证者联系，要求对方作出回应或再次寄发询证函，无法收到的回函实施替代程序； （5）如果管理层不允许寄发询证函的，询问管理层不允许寄发的原因，并就其原因的正当、合理性收集证据；考虑实施替代审计程序以获取相关、可靠的审计证据； （6）如果管理层不允许寄发询证函的原因不合理、或者认为回函不可靠，评价对评估的重大错报风险以及其他审计程序的性质、时间安排和范围的影响，并确定其对审计工作和审计意见的影响。 | C21: 常规★ | D21: √ | E21: √ | F21: √ | G21: √ | I21: D0
A22: 6 | B22: 检查合同负债长期挂账的原因，并作出记录，必要时提请被审计单位予以调整。 | C22: 常规★ | D22: √ | G22: √ | I22: D7-7
A23: 7 | B23: 检查合同负债关联方款项： （1）了解交易的商业理由、交易事项的目的、价格和条件，确定关联交易价格是否远高于或低于非关联方交易价格，考虑对关联方合同负债的合理性、合法性； （2）检查对关联方合同负债的真实性相关的支持性文件、检查会计处理是否正确； （3）考虑向关联方或其他注册会计师函证重大的关联销售交易和余额（包括担保和其他重要信息）； （4）必要时，向与交易相关的人员和机构（如银行、律师）函证或与其讨论有关信息； （5）考虑是否存在未识别的关联方，关联余额披露是否正确。 | C23: 常规★ | D23: √ | E23: √ | F23: √ | G23: √ | I23: D7-6
A24: 8 | B24: 检查与合同负债有关的的记账凭证和相应的销货合同、仓库发货记录、货运单据和收款凭证，检查已实现销售的商品是否及时转销合同负债，确定合同负债期末余额的正确性和合理性。 | C24: 常规★ | D24: √ | G24: √ | I24: D7-5
A25: 9 | B25: 结合收入、应收账款底稿考虑对重大、新增、异常等合同负债客户执行背景调查、实地走访等延伸程序。 | C25: IPO/上市公司/新三板/舞弊应对 | D25: √ | E25: √ | F25: √ | G25: √ | I25: D4-28 /D4-29 /D4-30 /D4-31 /D4-32
A26: 10 | B26: 针对评估的舞弊风险等因素增加的审计程序。 | C26: IPO/上市公司/新三板/舞弊应对
A27: 11 | B27: 检查合同负债是否已按企业会计准则或其他适用的规定在财务报表中做出恰当列报和披露。 | C27: 常规★ | H27: √ | I27: A1-1/A1-15 /A1-16

Sheet 合同负债实质性程序表 D8A（原）
A1: 致同会计师事务所
A2: 合同负债的实质性程序
A3: 客户名称： | C3: =[21]底稿目录!A4 -> 编制人： | G3: =[21]底稿目录!A5 -> 编制日期： | I3: 索引号：D8A
A4: =[21]底稿目录!A3 -> 截止日：2024年12月31日 | C4: =[21]底稿目录!A6 -> 复核人： | G4: =[21]底稿目录!A7 -> 复核日期： | I4: 页次：
A5: 一、本循环涉及的财务报表项目
A6: 合同负债
A7: 二、重大错报风险需从实质性程序获取的保证程度
A8: 根据风险评估和内控测试的结果按下列顺序作出判断： | C8: 财务报表的认定 | H8: 信赖/不信赖/不适用 | I8: 索引号
C9: 存在 | D9: 完整性 | E9: 权利和义务 | F9: 计价和分摊 | G9: 列报和披露
A10: A.资产负债表中记录的合同负债是存在的。 | C10: √ | I10: B22-2,B22-3
A11: B.所有应当记录的货币合同负债均已记录。 | D11: √ | I11: C2
A12: C.记录的合同负债是被审计单位应当履行的现时义务。 | E12: √ | I12: ——
A13: D.合同负债以恰当的金额包括在财务报表中，与之相关的计价调整已恰当记录。 | F13: √
A14: E.合同负债已按照企业会计准则的规定在财务报表中作出恰当列报和披露。 | G14: √
A15: 三、计划实施的实质性程序 | J15: 软件专用
A16: 序号 | B16: 审计程序 | C16: 程序分类 | E16: 审计目标 | H16: 执行情况说明 （含底稿索引） | J16: 风险 | K16: 开机启动项 | L16: 问题
A17: 一 | B17: 编制审定表 | C17: 常规★ | E17: B | H17: D8 | J17: 收入 Revenues-1
A18: 二 | B18: 获取或编制合同负债（包括其他非流动负债中列示的合同负债）明细表。 | C18: 常规★ | D18: 应收票据、应收账款,合同资产,其他非流动资产,合同负债,其他非流动负债,主营业务收入,其他流动负债,预计负债 | E18: C | H18: D8-2 | J18: 收入 Revenues-1
A19: 1 | B19: 复核加计正确 | C19: 常规★ | J19: 收入 Revenues-1
A20: 2 | B20: 将总金额与总账、明细账合计数核对相符 | C20: 常规★ | D20: 应收票据、应收账款,合同资产,其他非流动资产,合同负债,其他非流动负债,主营业务收入 | J20: 收入 Revenues-1
A21: 三 | B21: 在使用被审计单位生成的信息（IPE）时，应当评价该信息对实现审计目的是否足够可靠，包括根据具体情况在必要时实施下列程序： | E21: B | H21: T1
A22: 1 | B22: 获取有关信息准确性和完整性的审计证据。
A23: 2 | B23: 评价信息对实现审计目的是否足够准确和详细。
A24: 四 | B24: 测试上期合同负债期末余额。（适用于首次实施） 测试上期合同负债（包括其他非流动负债中列示的合同负债）期末余额。（适用于实施新收入准则后的首次承接） | C24: 备选 | E24: D | J24: 收入 Revenues-10 | K24: 首次承接
A25: 1 | B25: 向被审计单位人员询问前期期末关于收入截止的相关处理。 | C25: 备选 | D25: 应收票据、应收账款,合同资产,其他非流动资产,合同负债,其他非流动负债,主营业务收入 | J25: 收入 Revenues-10 | K25: 首次承接
A26: 2 | B26: 复核资产负债表日前后一段合理期间里的销售分录，调查任何异常分录。 | C26: 备选 | D26: 应收票据、应收账款,合同资产,其他非流动资产,合同负债,其他非流动负债,主营业务收入 | J26: 收入 Revenues-10 | K26: 首次承接
A27: 3 | B27: 复核资产负债表日前后一段合理期间里销售退回或销售折扣的记录。 | C27: 备选 | D27: 应收票据、应收账款,合同资产,其他非流动资产,合同负债,其他非流动负债,主营业务收入 | J27: 收入 Revenues-10 | K27: 首次承接
A28: 4 | B28: 调查接近前期期末发生的大额或异常的销售交易。 | C28: 备选 | D28: 应收票据、应收账款,合同资产,其他非流动资产,合同负债,其他非流动负债,主营业务收入 | J28: 收入 Revenues-10 | K28: 首次承接
A29: 五 | B29: 重大会计政策、会计估计合理性检查 | C29: 常规★ | D29: 应收账款,合同资产,主营业务收入 | E29: ABCD | H29: D8-2 | J29: 收入 Revenues-12,收入 Revenues-20
A30: 1 | B30: 针对附有销售退回条款的销售、客户额外购买选择权（奖励积分、常旅客计划等）、向客户预收销售款项（预售卡打折）、无需退回的初始费（如俱乐部的入会费等）等情况，检查收入确认政策，确定预计负债、合同负债的会计处理是否正确。 | C30: 常规★ | D30: 主营业务收入,预计负债、合同负债 | J30: 收入 Revenues-12 | L30: 收入4-1
A31: 六 | B31: 使用积极式函证方式对合同负债进行函证 | C31: 常规★ | D31: 应收账款,主营业务收入,合同负债 | E31: AC | H31: D8-6、D8-7、D8-8 | J31: 收入 Revenues-10,收入 Revenues-11,收入 Revenues-12,收入 Revenues-13
A32: 1 | B32: 样本的选择： 对总体中特定项目（金额重大、性质特殊）全部进行函证，对于剩余项目，如果总体重要，则选用抽样方法，如果总体不重要的，仅执行分析程序。 Select %S items using an appropriate selection method. | C32: 常规 | D32: 应收账款,主营业务收入,合同负债 | J32: 收入 Revenues-10
A33: (1) | B33: 抽样方法：使用IDEA选择%样本，并记录选样标准Use IDEA to select %S items. | C33: 常规 | D33: 应收账款,主营业务收入,合同负债 | J33: 收入 Revenues-10
A34: (2) | B34: 记录函证抽样的依据及比例。
A35: 2 | B35: 设计询证函（可以采用事务所的模板，或根据需要在模板基础上修改），考虑制作询证函防伪标识，并在发函前核实被函证单位信息（函证科目、客户名称、通讯地址、联系人、联系电话、邮政编码、函证人等），对于函证地址与注册地址、办公地址等不一致，不同客户或供应商的函证地址相近、电话号段相邻，函证联系人并非被询证单位员工等情况，需核查并记录原因。 | C35: 常规 | D35: 应收账款,主营业务收入,合同负债 | J35: 收入 Revenues-10
A36: 3 | B36: 对函证过程实施控制：验证被函证对象信息；询证函须由注册会计师独立收发，跟函时观察实地场所以及函证核对过程，确认处理函证的人员身份和权限，防范询证函被拦截、篡改或发生串通舞弊；在底稿中记录控制过程；保存发函回执及收函的相关证据。 | C36: 常规★ | D36: 应收账款,主营业务收入,合同负债 | H36: D8-6 | J36: 收入 Revenues-10
A37: （1） | B37: 核实快递物流信息、比对回函印章和签字，确认回函联系人及回函地址的真实性。 | C37: 常规★ | D37: 应收账款,主营业务收入,合同负债
A38: （2） | B38: 分析核实未回函、回函不符及回函率较低的原因，必要时实施再次发函、现场走访等程序，获取账面记录与外部证据矛盾的审计证据。 | C38: 常规★ | D38: 应收账款,主营业务收入,合同负债
A39: （3） | B39: 回函情况较好时，应结合风险评估情况及各类风险迹象，考虑串通舞弊、伪造交易的可能性等。 | C39: 常规★ | D39: 应收账款,主营业务收入,合同负债
A40: 4 | B40: 如果被询证者以传真、电子邮件等方式回函，审计项目组应当直接接收，并要求被询证者在审计报告日之前寄回询证函原件。如果审计项目组在审计报告日之前未收到询证函原件，应当实施以下程序： | C40: 常规 | D40: 应收账款,主营业务收入,合同负债 | J40: 收入 Revenues-10
...

Sheet 审定表D7-1
A1: 致同会计师事务所
A2: 合同负债审定表
A3: =底稿目录!A2 -> 被审计单位： | E3: =底稿目录!A4 -> 编制人： | H3: =底稿目录!A5 -> 编制日期： | K3: 索引号： | L3: =底稿目录!F5 -> D7-1
A4: =底稿目录!A3 -> 截止日：202X年12月31日 | E4: =底稿目录!A6 -> 复核人： | H4: =底稿目录!A7 -> 复核日期： | K4: 页次：
A5: 一、按照性质分类
A6: 项目 | B6: 期初数 | F6: 期末数 | J6: 本期与上期比较 | L6: 原因分析
B7: 未审数 | C7: 账项调整 | D7: 重分类调整 | E7: 审定数 | F7: 未审数 | G7: 账项调整 | H7: 重分类调整 | I7: 审定数 | J7: 变动额 | K7: 变动率
A8: 预收货款 | E8: =B8+C8+D8 -> 0 | I8: =F8+G8+H8 -> 0 | J8: =I8-E8 -> 0 | K8: =IF(AND(E8=0,I8=0),"",IF(AND(E8=0,I8>0),1,J8/E8))
A9: 开发项目预收款 | E9: =B9+C9+D9 -> 0 | I9: =F9+G9+H9 -> 0 | J9: =I9-E9 -> 0 | K9: =IF(AND(E9=0,I9=0),"",IF(AND(E9=0,I9>0),1,J9/E9))
A10: 预收工程款 | E10: =B10+C10+D10 -> 0 | I10: =F10+G10+H10 -> 0 | J10: =I10-E10 -> 0 | K10: =IF(AND(E10=0,I10=0),"",IF(AND(E10=0,I10>0),1,J10/E10))
E11: =B11+C11+D11 -> 0 | I11: =F11+G11+H11 -> 0 | J11: =I11-E11 -> 0 | K11: =IF(AND(E11=0,I11=0),"",IF(AND(E11=0,I11>0),1,J11/E11))
E12: =B12+C12+D12 -> 0 | I12: =F12+G12+H12 -> 0 | J12: =I12-E12 -> 0 | K12: =IF(AND(E12=0,I12=0),"",IF(AND(E12=0,I12>0),1,J12/E12))
A13: 其他 | E13: =B13+C13+D13 -> 0 | I13: =F13+G13+H13 -> 0 | J13: =I13-E13 -> 0 | K13: =IF(AND(E13=0,I13=0),"",IF(AND(E13=0,I13>0),1,J13/E13))
A14: 小计 | B14: =SUM(B8:B13) -> 0 | C14: =SUM(C8:C13) -> 0 | D14: =SUM(D7:D13) -> 0 | E14: =SUM(E8:E13) -> 0 | F14: =SUM(F8:F13) -> 0 | G14: =SUM(G8:G13) -> 0 | H14: =SUM(H8:H13) -> 0 | I14: =SUM(I8:I13) -> 0 | J14: =I14-E14 -> 0 | K14: =IF(AND(E14=0,I14=0),"",IF(AND(E14=0,I14>0),1,J14/E14))
A15: 减：计入其他非流动负债的合同负债 | E15: =B15+C15+D15 -> 0 | I15: =F15+G15+H15 -> 0 | J15: =I15-E15 -> 0 | K15: =IF(AND(E15=0,I15=0),"",IF(AND(E15=0,I15>0),1,J15/E15))
A16: 合同负债合计 | B16: =B14-B15 -> 0 | C16: =C14-C15 -> 0 | D16: =D14-D15 -> 0 | E16: =E14-E15 -> 0 | F16: =F14-F15 -> 0 | G16: =G14-G15 -> 0 | H16: =H14-H15 -> 0 | I16: =I14-I15 -> 0 | J16: =I16-E16 -> 0 | K16: =IF(AND(E16=0,I16=0),"",IF(AND(E16=0,I16>0),1,J16/E16))
A17: 二、按照账龄分类
A18: 项目 | B18: 期初数 | F18: 期末数 | J18: 本期与上期比较 | L18: 原因分析
B19: 未审数 | C19: 账项调整 | D19: 重分类调整 | E19: 审定数 | F19: 未审数 | G19: 账项调整 | H19: 重分类调整 | I19: 审定数 | J19: 变动额 | K19: 变动率
A20: 1年以内（含1年） | E20: =B20+C20+D20 -> 0 | I20: =F20+G20+H20 -> 0 | J20: =I20-E20 -> 0 | K20: =IF(AND(E20=0,I20=0),"",IF(AND(E20=0,I20>0),1,J20/E20))
A21: 1至2年（含2年） | E21: =B21+C21+D21 -> 0 | I21: =F21+G21+H21 -> 0 | J21: =I21-E21 -> 0 | K21: =IF(AND(E21=0,I21=0),"",IF(AND(E21=0,I21>0),1,J21/E21))
A22: 2至3年（含3年） | E22: =B22+C22+D22 -> 0 | I22: =F22+G22+H22 -> 0 | J22: =I22-E22 -> 0 | K22: =IF(AND(E22=0,I22=0),"",IF(AND(E22=0,I22>0),1,J22/E22))
A23: 3年以上 | E23: =B23+C23+D23 -> 0 | I23: =F23+G23+H23 -> 0 | J23: =I23-E23 -> 0 | K23: =IF(AND(E23=0,I23=0),"",IF(AND(E23=0,I23>0),1,J23/E23))
A24: 合计 | B24: =SUM(B20:B23) -> 0 | C24: =SUM(C20:C23) -> 0 | D24: =SUM(D20:D23) -> 0 | E24: =SUM(E20:E23) -> 0 | F24: =SUM(F20:F23) -> 0 | G24: =SUM(G20:G23) -> 0 | H24: =SUM(H20:H23) -> 0 | I24: =SUM(I20:I23) -> 0 | J24: =SUM(J20:J23) -> 0 | K24: =IF(AND(E24=0,I24=0),"",IF(AND(E24=0,I24>0),1,J24/E24))
A25: 试算平衡表数
A26: 差异数 | E26: =E24-E25 -> 0 | I26: =I24-I25 -> 0
A27: 1.审计说明 | I27: 2.审计结论
A28: （1）合同负债本期较上期增加（负数为减少）： | E28: =IF(AND(E14=0,I14=0),0,IF(AND(E14=0,I14>0),1,(I14-E14)/E14)) -> 0
A29: 主要原因（比例超过30%的）：
A32: （2）情况说明

Sheet 附注披露信息(上市公司)
A1: 致同会计师事务所
A2: 合同负债附注披露信息（上市公司）
A3: =底稿目录!A2 -> 被审计单位： | C3: =底稿目录!A4 -> 编制人： | D3: =底稿目录!A5 -> 编制日期： | E3: 索引号：D7-1
A4: =底稿目录!A3 -> 截止日：202X年12月31日 | C4: =底稿目录!A6 -> 复核人： | D4: =底稿目录!A7 -> 复核日期： | E4: 页次：
A5: 预收款项
A6: 合同负债附注
A7: 项 目 | B7: 期末余额 | C7: 上年年末余额
A8: =[22]审定表D7!A8 -> #REF! | B8: ='审定表D7-1'!I8 -> 0 | C8: ='审定表D7-1'!E8 -> 0
A9: ='审定表D7-1'!A9 -> 开发项目预收款 | B9: ='审定表D7-1'!I9 -> 0 | C9: ='审定表D7-1'!E9 -> 0
A10: ='审定表D7-1'!A10 -> 预收工程款 | B10: ='审定表D7-1'!I10 -> 0 | C10: ='审定表D7-1'!E10 -> 0
A11: ='审定表D7-1'!A11 -> 0 | B11: ='审定表D7-1'!I11 -> 0 | C11: ='审定表D7-1'!E11 -> 0
A12: ='审定表D7-1'!A12 -> 0 | B12: ='审定表D7-1'!I12 -> 0 | C12: ='审定表D7-1'!E12 -> 0
A13: ='审定表D7-1'!A13 -> 其他 | B13: ='审定表D7-1'!I13 -> 0 | C13: ='审定表D7-1'!E13 -> 0
A14: 减：计入其他非流动负债的合同负债
A15: 合 计 | B15: =SUM(B8:B13)-B14 -> 0 | C15: =SUM(C8:C13)-C14 -> 0
A16: 【提示：同一合同下的合同资产和合同负债应当以净额在资产负债表列示。净额为借方余额的，应当根据其流动性在“合同资产”或“其他非流动资产”项目中列示，其中预计自资产负债表日起一年内变现的，应当在“合同资产”项目列示，不应在“一年内到期的非流动资产”项目列示；净额为贷方余额的，应当根据其流动性在“合同负债”或“其他非流动负债”项目中列示，其中预计自资产负债表日起一年内到期的，应当在“合同负债”项目列示，不应在“一年内到期的非流动负债”项目列示。】
A17: （1）账龄超过1年的重要合同负债
A18: 项 目 | B18: 期末余额 | C18: 未偿还或未结转的原因
A23: 合 计 | B23: =SUM(B19:B22) -> 0
A24: （2）本期合同负债账面价值的重大变动
A25: 项 目 | B25: 变动金额 | C25: 变动原因
A30: 合 计 | B30: =SUM(B26:B29) -> 0
A31: 披露以下信息：
A32: 1、在本期确认的包括在合同负债期初账面价值中的收入；以及前期已经履行（或部分履行）的履约义务在本期确认的收入（例如，交易价格的变动）。
A33: 2、履行履约义务的时间与通常的付款时间之间的关系，以及此类因素对合同负债（如果对合同资产产生影响在合同负债科目下说明）账面价值的影响的定量或定性信息。
A34: 3、合同负债的账面价值在本期内发生的重大变动的情形包括：
A35: ①企业合并导致的变动；
A36: ②对收入进行累积追加调整导致的相关合同资产和合同负债的变动，此类调整可能源于估计履约进度的变化、估计交易价格的变化（包括对于可变对价是否受到限制的评估发生变化）或者合同变更；
A37: ③履行履约义务（即从合同负债转为收入）的时间安排发生变化。

Sheet 附注披露信息(国企)
A1: 致同会计师事务所
A2: 合同负债附注披露信息（国企）
A3: =底稿目录!A2 -> 被审计单位： | B3: =底稿目录!A4 -> 编制人： | C3: =底稿目录!A5 -> 编制日期： | D3: 索引号：D8-1
A4: =底稿目录!A3 -> 截止日：202X年12月31日 | B4: =底稿目录!A6 -> 复核人： | C4: =底稿目录!A7 -> 复核日期： | D4: 页次：
A5: 合同负债附注披露信息：
A6: 项 目 | B6: 期末余额 | C6: 期初余额
A7: ='审定表D7-1'!A8 -> 预收货款 | B7: ='审定表D7-1'!I8 -> 0 | C7: ='审定表D7-1'!E8 -> 0
A8: ='审定表D7-1'!A9 -> 开发项目预收款 | B8: ='审定表D7-1'!I9 -> 0 | C8: ='审定表D7-1'!E9 -> 0
A9: ='审定表D7-1'!A10 -> 预收工程款 | B9: ='审定表D7-1'!I10 -> 0 | C9: ='审定表D7-1'!E10 -> 0
A10: ='审定表D7-1'!A11 -> 0 | B10: ='审定表D7-1'!I11 -> 0 | C10: ='审定表D7-1'!E11 -> 0
A11: ='审定表D7-1'!A12 -> 0 | B11: ='审定表D7-1'!I12 -> 0 | C11: ='审定表D7-1'!E12 -> 0
A12: ='审定表D7-1'!A13 -> 其他 | B12: ='审定表D7-1'!I13 -> 0 | C12: ='审定表D7-1'!E13 -> 0
A13: 合 计 | B13: =SUM(B7:B12) -> 0 | C13: =SUM(C7:C12) -> 0
A14: 说明：
A15: 1、在本期确认的包括在合同负债期初账面价值中的收入；以及前期已经履行（或部分履行）的履约义务在本期确认的收入（例如，交易价格的变动）。
A16: 2、履行履约义务的时间与通常的付款时间之间的关系，以及此类因素对合同负债（如果对合同资产产生影响在合同负债科目下说明）账面价值的影响的定量或定性信息。
A17: 3、合同负债的账面价值在本期内发生的重大变动的情形包括：
A18: ①企业合并导致的变动；
A19: ②对收入进行累积追加调整导致的相关合同资产和合同负债的变动，此类调整可能源于估计履约进度的变化、估计交易价格的变化（包括对于可变对价是否受到限制的评估发生变化）或者合同变更；
A20: （1）本期合同负债账面价值的重大变动
A21: 项 目 | B21: 变动金额 | C21: 变动原因
A25: 合 计 | B25: =SUM(B22:B24) -> 0

Sheet 明细表D7-2
A1: 致同会计师事务所
A2: 合同负债明细表
A3: =底稿目录!A2 -> 被审计单位： | K3: =底稿目录!A4 -> 编制人： | S3: =底稿目录!A5 -> 编制日期： | Z3: 索引号： | AA3: =底稿目录!F8 -> D7-2
A4: =底稿目录!A3 -> 截止日：202X年12月31日 | K4: =底稿目录!A6 -> 复核人： | S4: =底稿目录!A7 -> 复核日期： | Z4: 页次：
A5: 一、审计目标:
A6: 合同负债以恰当的金额包括在财务报表中，与之相关的计价或分摊调整已恰当记录，相关披露已得到恰当计量和描述。
A7: 二、审计过程：
A8: 合同名称/项目名称 | B8: 单位名称 | C8: 公司代码 | D8: 关联关系 | E8: 类型 | F8: 期初未审数 | G8: 账项调整 | H8: 重分类调整 | I8: 期初审定数 | J8: 审定账龄 | N8: 借方发生 | O8: 贷方发生 | P8: 期末未审数 | Q8: 被审计单位重分类调整 | R8: 期末未审余额 | S8: 账项调整 | T8: 重分类调整 | U8: 期末审定数 | V8: 审定账龄 | Z8: 是否发函 | AA8: 期后结转
J9: 1年以下 | K9: 1～2年 | L9: ２～3年 | M9: 3年以上 | R9: 期末余额 | V9: 1年以下 | W9: 1～2年 | X9: ２～3年 | Y9: 3年以上
I10: =F10+G10+H10 -> 0 | P10: =F10-N10+O10 -> 0 | R10: =P10+Q10 -> 0 | U10: =R10+S10+T10 -> 0
I11: =F11+G11+H11 -> 0 | P11: =F11-N11+O11 -> 0 | R11: =P11+Q11 -> 0 | U11: =R11+S11+T11 -> 0
I12: =F12+G12+H12 -> 0 | P12: =F12-N12+O12 -> 0 | R12: =P12+Q12 -> 0 | U12: =R12+S12+T12 -> 0
I13: =F13+G13+H13 -> 0 | P13: =F13-N13+O13 -> 0 | R13: =P13+Q13 -> 0 | U13: =R13+S13+T13 -> 0
I14: =F14+G14+H14 -> 0 | P14: =F14-N14+O14 -> 0 | R14: =P14+Q14 -> 0 | U14: =R14+S14+T14 -> 0
I15: =F15+G15+H15 -> 0 | P15: =F15-N15+O15 -> 0 | R15: =P15+Q15 -> 0 | U15: =R15+S15+T15 -> 0
I16: =F16+G16+H16 -> 0 | P16: =F16-N16+O16 -> 0 | R16: =P16+Q16 -> 0 | U16: =R16+S16+T16 -> 0
I17: =F17+G17+H17 -> 0 | P17: =F17-N17+O17 -> 0 | R17: =P17+Q17 -> 0 | U17: =R17+S17+T17 -> 0
I18: =F18+G18+H18 -> 0 | P18: =F18-N18+O18 -> 0 | R18: =P18+Q18 -> 0 | U18: =R18+S18+T18 -> 0
I19: =F19+G19+H19 -> 0 | P19: =F19-N19+O19 -> 0 | R19: =P19+Q19 -> 0 | U19: =R19+S19+T19 -> 0
I20: =F20+G20+H20 -> 0 | P20: =F20-N20+O20 -> 0 | R20: =P20+Q20 -> 0 | U20: =R20+S20+T20 -> 0
I21: =F21+G21+H21 -> 0 | P21: =F21-N21+O21 -> 0 | R21: =P21+Q21 -> 0 | U21: =R21+S21+T21 -> 0
I22: =F22+G22+H22 -> 0 | P22: =F22-N22+O22 -> 0 | R22: =P22+Q22 -> 0 | U22: =R22+S22+T22 -> 0
A23: 合 计 | I23: =SUM(I10:I22) -> 0 | J23: =SUM(J10:J22) -> 0 | K23: =SUM(K10:K22) -> 0 | L23: =SUM(L10:L22) -> 0 | M23: =SUM(M10:M22) -> 0 | N23: =SUM(N10:N22) -> 0 | O23: =SUM(O10:O22) -> 0 | P23: =SUM(P10:P22) -> 0 | ... Y23: =SUM(Y10:Y22) -> 0 | AA23: =SUM(AA10:AA22) -> 0
A24: 账龄占比 | I24: =IF((I23-SUM(J23:M23)=0),"OK","账龄与审定不匹配") -> OK | U24: =IF((U23-SUM(V23:Y23)=0),"OK","账龄与审定不匹配") -> OK | W24: =IF(W23<=J23,TRUE,FALSE) -> TRUE | X24: =IF(X23<=K23,TRUE,FALSE) -> TRUE | Y24: =IF(Y23<=(L23+M23),TRUE,FALSE) -> TRUE
A25: 三、审计说明：
A29: 四、审计结论：
A31: 提示：
A32: 合同负债，是指企业已收或应收客户对价而应向客户转让商品或提供服务的义务。
A33: 合同资产和合同负债应当在资产负债表中单独列示。同一合同下的合同资产和合同负债应当以净额列示，不同合同下的合同资产和合同负债不能互相抵销。
A34: 企业在向客户转让商品之前，客户已经支付了合同对价或企业已经取得了无条件收取合同对价权利的，企业应当在客户实际支付款项与到期应支付款项孰早时点，按照该已收或应收的金额，
A35: 借记“银行存款”“应收账款”“应收票据”等科日，贷记“合同负债”。
A36: 企业因转让商品收到的预收款适用本准则进行会计处理时，不再使用“预收账款”科目及“递延收益”科目。

Sheet 调整分录汇总表D7-3
A1: 致同会计师事务所
A2: 合同负债调整分录汇总表
A3: =底稿目录!A2 -> 被审计单位： | D3: =底稿目录!A4 -> 编制人： | G3: =底稿目录!A5 -> 编制日期： | I3: 索引号： | J3: =底稿目录!F9 -> D7-3
A4: =底稿目录!A3 -> 截止日：202X年12月31日 | D4: =底稿目录!A6 -> 复核人： | G4: =底稿目录!A7 -> 复核日期： | I4: 页次：
A5: 调整事项说明 | B5: 类别（报表调整/账项调整/其他） | C5: 报表项目 | D5: 科目名称 | E5: 附注项目 | F5: …… | G5: 借方调整金额 | H5: 贷方调整金额 | I5: 索引 | J5: 备注
A21: 提示：本底稿适用于调整分录较多、较复杂的项目，且仅列示与本报表项目相关的审计调整。项目组可根据项目实际情况选择是否使用该底稿。

Sheet 合同负债分析表D7-4
A1: 致同会计师事务所
A2: 合同负债分析表
A3: =底稿目录!A2 -> 被审计单位： | C3: =底稿目录!A4 -> 编制人： | E3: =底稿目录!A5 -> 编制日期： | F3: 索引号： | G3: =底稿目录!F10 -> D7-4
A4: =底稿目录!A3 -> 截止日：202X年12月31日 | C4: =底稿目录!A6 -> 复核人： | E4: =底稿目录!A7 -> 复核日期： | F4: 页次：
A5: 一、审计目标
A6: 1.资产负债表中记录的合同负债是存在的，且已经记录在恰当的账户中。2.所有应当记录的货币合同负债均已记录，所有应当包括在财务报表中的相关披露均已包括。
A7: 3.合同负债以恰当的金额包括在财务报表中，与之相关的计价或分摊调整已恰当记录，相关披露已得到恰当计量和描述。
A8: 二、审计过程
A9: （一）合同负债借方发生额分析
A10: 项目 | B10: 金额 | C10: 数据来源 | D10: 备注
A11: 本期借方发生额合计
A12: 对方科目：
A13: 营业收入
A14: 增值税
A15: ……
A16: 差异 | B16: =B11-B13-B14-B15 -> 0
A17: 差异合理性分析
A18: （三）合同负债贷方发生额分析
B19: 金额 | C19: 数据来源 | D19: 与对方科目核对 | E19: 说明
A20: 本期贷方发生额合计 | C20: 合同负债总账 | D20: N/A | E20: N/A
A21: 其中：银行存款收款 | E21: 与银行存款借方发生额核对
A22: 应收票据 | E22: 与应收票据借方发生额核对
A23: ……
A24: 差异合理性分析
A25: （四）期末合同负债主要债权人余额分析
A26: 债权人名称 | B26: 期末账面余额 | C26: 期初账面余额 | D26: 变动金额 | E26: 变动比例 | F26: 账龄 | G26: 期后结转
A27: 债权人1 | D27: =B27-C27 -> 0 | E27: =D27/C27 -> #DIV/0!
A28: 债权人2 | D28: =B28-C28 -> 0 | E28: =D28/C28 -> #DIV/0!
A29: 债权人3 | D29: =B29-C29 -> 0 | E29: =D29/C29 -> #DIV/0!
A30: 债权人4 | D30: =B30-C30 -> 0 | E30: =D30/C30 -> #DIV/0!
A31: 债权人5 | D31: =B31-C31 -> 0 | E31: =D31/C31 -> #DIV/0!
A32: 债权人6 | D32: =B32-C32 -> 0 | E32: =D32/C32 -> #DIV/0!
A33: 债权人7 | D33: =B33-C33 -> 0 | E33: =D33/C33 -> #DIV/0!
A34: 债权人8 | D34: =B34-C34 -> 0 | E34: =D34/C34 -> #DIV/0!
A35: 债权人9 | D35: =B35-C35 -> 0 | E35: =D35/C35 -> #DIV/0!
A36: 债权人10 | D36: =B36-C36 -> 0 | E36: =D36/C36 -> #DIV/0!
A37: 小计 | B37: =SUM(B27:B36) -> 0 | C37: =SUM(C27:C36) -> 0 | D37: =SUM(D27:D36) -> 0 | E37: =D37/C37 -> #DIV/0!
A38: 三、审计说明
A42: 四、审计结论

Sheet 账龄1年以上合同负债检查表D7-5
A1: 致同会计师事务所
A2: 账龄1年以上的合同负债检查表
A3: =底稿目录!A2 -> 被审计单位： | C3: =底稿目录!A4 -> 编制人： | E3: =底稿目录!A5 -> 编制日期： | G3: 索引号： | H3: =底稿目录!F18 -> D7-5
A4: =底稿目录!A3 -> 截止日：202X年12月31日 | C4: =底稿目录!A6 -> 复核人： | E4: =底稿目录!A7 -> 复核日期： | G4: 页次：
A5: 一、审计目标
A6: 资产负债表中记录的合同负债是存在的，且已经记录在恰当的账户中。
A7: 二、审计过程
A8: 1.……
A10: 客户名称 | B10: 期末余额 | C10: 账龄 | D10: 经济业务说明 | E10: 未结转或未偿还的原因 | F10: 至审计日结转或偿还金额 | G10: 处理计划 | H10: 备注
B14: =SUM(B11:B13) -> 0 | F14: =SUM(F11:F13) -> 0
A15: 三、审计说明
A19: 四、审计结论

Sheet 关联方关系及交易检查表D7-6
A1: 致同会计师事务所
A2: 关联方关系及交易检查表
A3: =底稿目录!A2 -> 被审计单位： | D3: =底稿目录!A4 -> 编制人： | F3: =底稿目录!A5 -> 编制日期： | J3: 索引号： | K3: =底稿目录!F19 -> D7-6
A4: =底稿目录!A3 -> 截止日：202X年12月31日 | D4: =底稿目录!A6 -> 复核人： | F4: =底稿目录!A7 -> 复核日期： | J4: 页次：
A5: 一、审计目标
A6: 1.资产负债表中记录的合同负债是存在的，且已经记录在恰当的账户中；2.记录的合同负债由被审计单位拥有或控制；3.记录的合同负债是被审计单位应当履行的现时义务；
A7: 4.负债以恰当的金额包括在财务报表中，与之相关的计价或分摊调整已恰当记录，相关披露已得到恰当计量和描述
A8: 二、审计过程
A9: 1.……
A11: 关联方名称 | B11: 关联关系 | C11: 期初余额 | D11: 借方发生 | E11: 贷方发生 | F11: 期末余额 | G11: 发生时间及账龄 | H11: 未结转或未偿还的原因 | I11: 至审计日结转或偿还金额 | J11: 处理计划 | K11: 备注
F12: =C12+D12-E12 -> 0
F13: =C13+D13-E13 -> 0
F14: =C14+D14-E14 -> 0
C15: =SUM(C12:C14) -> 0 | D15: =SUM(D12:D14) -> 0 | E15: =SUM(E12:E14) -> 0 | F15: =SUM(F12:F14) -> 0 | I15: =SUM(I12:I14) -> 0
A16: 三、审计说明：
A20: 四、审计结论：
B23: 勿改、勿删
B24: 实际控制人
B25: 控股股东
B26: 控股股东、实际控制人的附属企业
B27: 持有5%以上股份的法人或其他组织
B28: 联营企业
B29: 合营企业
B30: 董高监等关键管理人员
B31: 其他关联方

Sheet 合同负债检查表D7-7
A1: 致同会计师事务所
A2: 合同负债检查表
A3: =底稿目录!A2 -> 被审计单位： | F3: =底稿目录!A4 -> 编制人： | H3: =底稿目录!A5 -> 编制日期： | P3: 索引号： | Q3: =底稿目录!F20 -> D7-7
A4: =底稿目录!A3 -> 截止日：202X年12月31日 | F4: =底稿目录!A6 -> 复核人： | H4: =底稿目录!A7 -> 复核日期： | P4: 页次：
A5: 一、审计目标：
A6: 1.资产负债表中记录的合同负债是存在的，且已经记录在恰当的账户中；2.记录的合同负债由被审计单位拥有或控制；
A7: 3.合同负债以恰当的金额包括在财务报表中，与之相关的计价或分摊调整已恰当记录，相关披露已得到恰当计量和描述
A8: 二、审计过程：
A9: 1.样本选取及标准
A10: 测试总体： | B10: 如合同负债借方发生额所有凭证共XX笔金额XX、贷方发生额所有凭证共XX笔金额XX | G10: 特定样本： | H10: XX金额以上（大额）、关联方/关联交易形成的款项、XX异常款项全部测试，共XX笔；
A11: 抽样总体： | B11: 测试总体扣除特定样本以外的样本，共XX笔、金额XX | G11: 确定的抽样样本量： | H11: 抽取XX笔（如果使用了样本计算器计算样本量，样本量计算过程见<XX>底稿）
A12: 抽样方法： | B12: 随机选样/系统选样/货币单元抽样/随意选样（非统计抽样适用） | G12: 抽样过程： | H12: 使用IDEA（XX抽样工具）选择XX数量、金额XX的样本进行测试，抽样工具中的样本选择过程和结果见<XX>底稿
A13: 2.测试
A14: 测试内容说明：1.原始凭证是否齐全； 2.记账凭证与原始凭证是否相符；3.账务处理是否正确；4.是否记录于恰当的会计期间；5.……
A15: （1）本期增减变动检查
A16: 客户名称 | B16: 记账凭证 | I16: 支持性文件 | J16: 核对内容 | O16: 索引号 | P16: 是否异常 | Q16: 备注说明
B17: 日期 | C17: 凭证编号 | D17: 业务内容 | E17: 对方科目 | F17: 对方明细科目 | G17: 借方金额 | H17: 贷方金额 | J17: 1 | K17: 2 | L17: 3 | M17: 4 | N17: 5
A31: 合计 | G31: =SUM(G18:G30) -> 0 | H31: =SUM(H18:H30) -> 0
A32: （2）期后结转检查
A33: 客户名称 | B33: 记账凭证 | H33: 支持性文件 | J33: 核对内容 | O33: 索引号 | P33: 是否异常 | Q33: 备注说明
B34: 日期 | C34: 凭证编号 | D34: 业务内容 | E34: 对方科目 | F34: 对方明细科目 | G34: 借方金额 | J34: 1 | K34: 2 | L34: 3 | M34: 4 | N34: 5
A40: 合计 | G40: =SUM(G35:G39) -> 0
A41: 四、审计说明：
A42: 1.本期发生额、期末余额检查比例： | D42: 方向 | E42: 账面金额 | F42: 检查金额 | G42: 检查比例 | H42: 如果检查比例较低应扩大检查样本量或说明原因
D43: 本期借方 | E43: ='明细表D7-2'!N23 -> 0 | F43: =G31 -> 0 | G43: =ROUND(F43/E43,4) -> #DIV/0!
D44: 本期贷方 | E44: ='明细表D7-2'!O23 -> 0 | F44: =H31 -> 0 | G44: =ROUND(F44/E44,2) -> #DIV/0!
D45: 期末余额 | E45: ='明细表D7-2'!U23 -> 0 | F45: =G40 -> 0 | G45: =ROUND(F45/E45,2) -> #DIV/0!
A46: 2.……
A47: 五、审计结论：

Sheet GT_Custom
A1: C1 | B1: Custom 1
A2: C2 | B2: Custom 2
A3: C3 | B3: Custom 3
A4: C4 | B4: Custom 4
A5: C5 | B5: Custom 5
A6: C6 | B6: Custom 6
A7: C7 | B7: Custom 7
A8: C8 | B8: Custom 8
