Workbook
Name bs: {#N/A,#N/A,FALSE,"BBPREP"}
Name bs: {#N/A,#N/A,FALSE,"BBPREP"}
Name bs: {#N/A,#N/A,FALSE,"BBPREP"}
Name bs_1: {#N/A,#N/A,FALSE,"BBPREP"}
Name bs_1: {#N/A,#N/A,FALSE,"BBPREP"}

Sheet 底稿目录
A1: 底稿开列时，可先在以下单元格填写有关内容，以便其他底稿引用有关数据： | D1: 序号 | E1: 内容 | F1: 索引号
A2: 被审计单位： | D2: 1 | E2: 存货总体分析表 | F2: F2-18
A3: 截止日：202X年12月31日 | D3: =D2+1 -> 2 | E3: 存货产销量变动分析表 | F3: F2-19
A4: 编制人： | D4: =D3+1 -> 3 | E4: 产成品单位成本年度比较表 | F4: F2-20
A5: 编制日期：
A6: 复核人：
A7: 复核日期：

Sheet GT_Custom
A1: C1 | B1: Custom 1
A2: C2 | B2: Custom 2
A3: C3 | B3: Custom 3
A4: C4 | B4: Custom 4
A5: C5 | B5: Custom 5
A6: C6 | B6: Custom 6
A7: C7 | B7: Custom 7
A8: C8 | B8: Custom 8

Sheet 存货总体分析表F2-18
A1: 致同会计师事务所
A2: 存货总体分析表
A3: =底稿目录!A2 -> 被审计单位： | C3: =底稿目录!A4 -> 编制人： | E3: =底稿目录!A5 -> 编制日期： | H3: 索引号： | I3: =底稿目录!F2 -> F2-18
A4: =底稿目录!A3 -> 截止日：202X年12月31日 | C4: =底稿目录!A6 -> 复核人： | E4: =底稿目录!A7 -> 复核日期： | H4: 页 次：
A5: 一、审计目标：
A6: 1.资产负债表中记录的存货是存在的，且已经记录在恰当的账户中
A7: 2.存货以恰当的金额包括在财务报表中，与之相关的计价或分摊调整已恰当记录，相关披露已得到恰当计量和描述
A8: 二、审计过程：
A9: A、存货构成分析
A10: 存货项目 | C10: 20X5/12/31 | E10: 20X4/12/31 | G10: 20X3/12/31 | I10: 是否异常
C11: 金额 | D11: 结构比 | E11: 金额 | F11: 结构比 | G11: 金额 | H11: 结构比
A12: ='[1]明细汇总表F2-2'!A17 -> 原材料 | D12: =IF($C$25=0,0,C12/$C$25) -> 0 | F12: =IF($E$25=0,0,E12/$E$25) -> 0 | H12: =IF($G$25=0,0,G12/$G$25) -> 0
A13: ='[1]明细汇总表F2-2'!A18 -> 材料采购/在途物资 | D13: =IF($C$25=0,0,C13/$C$25) -> 0 | F13: =IF($E$25=0,0,E13/$E$25) -> 0 | H13: =IF($G$25=0,0,#REF!/$G$25) -> 0
A14: ='[1]明细汇总表F2-2'!A19 -> 周转材料/低值易耗品/包装物 | D14: =IF($C$25=0,0,C14/$C$25) -> 0 | F14: =IF($E$25=0,0,E14/$E$25) -> 0 | H14: =IF($G$25=0,0,G29/$G$25) -> 0
A15: ='[1]明细汇总表F2-2'!A20 -> 在产品 | D15: =IF($C$25=0,0,C15/$C$25) -> 0 | F15: =IF($E$25=0,0,E15/$E$25) -> 0 | H15: =IF($G$25=0,0,G30/$G$25) -> 0
A16: ='[1]明细汇总表F2-2'!A21 -> 自制半成品 | D16: =IF($C$25=0,0,C16/$C$25) -> 0 | F16: =IF($E$25=0,0,E16/$E$25) -> 0 | H16: =IF($G$25=0,0,G32/$G$25) -> 0
A17: ='[1]明细汇总表F2-2'!A22 -> 委托加工物资 | D17: =IF($C$25=0,0,C17/$C$25) -> 0 | F17: =IF($E$25=0,0,E17/$E$25) -> 0 | H17: =IF($G$25=0,0,#REF!/$G$25) -> 0
A18: ='[1]明细汇总表F2-2'!A23 -> 库存商品 | D18: =IF($C$25=0,0,C18/$C$25) -> 0 | F18: =IF($E$25=0,0,E18/$E$25) -> 0 | H18: =IF($G$25=0,0,#REF!/$G$25) -> 0
A19: ='[1]明细汇总表F2-2'!A24 -> 发出商品 | D19: =IF($C$25=0,0,C19/$C$25) -> 0 | F19: =IF($E$25=0,0,E19/$E$25) -> 0 | H19: =IF($G$25=0,0,#REF!/$G$25) -> 0
A20: ='[1]明细汇总表F2-2'!A25 -> 开发产品 | D20: =IF($C$25=0,0,C20/$C$25) -> 0 | F20: =IF($E$25=0,0,E20/$E$25) -> 0 | H20: =IF($G$25=0,0,#REF!/$G$25) -> 0
A21: ='[1]明细汇总表F2-2'!A26 -> 开发成本 | D21: =IF($C$25=0,0,C21/$C$25) -> 0 | F21: =IF($E$25=0,0,E21/$E$25) -> 0 | H21: =IF($G$25=0,0,#REF!/$G$25) -> 0
A22: ='[1]明细汇总表F2-2'!A27 -> 合同履约成本 | D22: =IF($C$25=0,0,C22/$C$25) -> 0 | F22: =IF($E$25=0,0,E22/$E$25) -> 0 | H22: =IF($G$25=0,0,#REF!/$G$25) -> 0
A23: ='[1]明细汇总表F2-2'!A28 -> 消耗性生物资产 | D23: =IF($C$25=0,0,C23/$C$25) -> 0 | F23: =IF($E$25=0,0,E23/$E$25) -> 0 | H23: =IF($G$25=0,0,#REF!/$G$25) -> 0
A24: ='[1]明细汇总表F2-2'!A29 -> 数据资源 | D24: =IF($C$25=0,0,C24/$C$25) -> 0 | F24: =IF($E$25=0,0,E24/$E$25) -> 0 | H24: =IF($G$25=0,0,#REF!/$G$25) -> 0
A25: 合计 | C25: =SUM(C12:C23) -> 0 | D25: =SUM(D12:D23) -> 0 | E25: =SUM(E12:E23) -> 0 | F25: =SUM(F12:F23) -> 0 | G25: =SUM(G12:G23) -> 0 | H25: =SUM(H12:H23) -> 0 | I25: ——
A26: 审计说明：
A27: 异常原因
A29: B、存货指标分析（三期数据对比）
A30: 指标 | C30: 20X5年 | E30: 20X4年 | G30: 20X3年 | I30: 是否异常
C31: 指标值 | D31: 变动率 | E31: 指标值 | F31: 变动率 | G31: 指标值 | H31: 变动率
A32: 存货周转率（销售成本÷平均存货） | D32: =IF(E32=0,0,(C32-E32)/E32) -> 0 | F32: =IF(G32=0,0,(E32-G32)/G32) -> 0 | H32: ——
A33: 存货平均天数（365天÷存货周转率） | D33: =IF(E33=0,0,(C33-E33)/E33) -> 0 | F33: =IF(G33=0,0,(E33-G33)/G33) -> 0 | H33: ——
A34: 存货跌价准备占存货余额比例 （存货跌价准备÷存货余额） | D34: =IF(E34=0,0,(C34-E34)/E34) -> 0 | F34: =IF(G34=0,0,(E34-G34)/G34) -> 0 | H34: ——
A35: 存货占流动资产比例 （平均存货÷平均流动资产） | D35: =IF(E35=0,0,(C35-E35)/E35) -> 0 | F35: =IF(G35=0,0,(E35-G35)/G35) -> 0 | H35: ——
A36: 废率（核销存货/平均存货余额） | D36: =IF(E36=0,0,(C36-E36)/E36) -> 0 | F36: =IF(G36=0,0,(E36-G36)/G36) -> 0 | H36: ——
A37: 审计说明：
A38: 异常原因
A40: C、存货指标分析（与同行业数据对比）
A41: 指标 | C41: 20X5年 | E41: 行业平均 | F41: 行业公司A | G41: 行业公司B | H41: 行业公司C | I41: 是否异常
C42: 指标值 | D42: 偏离
...

Sheet 存货产销量变动分析表F2-19
A1: 致同会计师事务所
A2: 存货产销量变动分析表
A3: =底稿目录!A2 -> 被审计单位： | E3: =底稿目录!A4 -> 编制人： | K3: =底稿目录!A5 -> 编制日期： | O3: 索引号： | P3: =底稿目录!F3 -> F2-19
A4: =底稿目录!A3 -> 截止日：202X年12月31日 | E4: =底稿目录!A6 -> 复核人： | K4: =底稿目录!A7 -> 复核日期： | O4: 页 次：
A5: 一、审计目标：
A6: 1.资产负债表中记录的存货是存在的，且已经记录在恰当的账户中
A7: 2.存货以恰当的金额包括在财务报表中，与之相关的计价或分摊调整已恰当记录，相关披露已得到恰当计量和描述
A8: 二、审计过程：
A9: 1.获取主要库存商品各月产量及原材料消耗量，测算报告期主要产品各月产耗比，与以前年度、可比公司、行业经验值进行比较，分析变动趋势及合理性；
A10: 2.结合存货监盘和对仓库实物账的核对，分析原材料实际投入量是否与财务账面记录一致。
A11: 库存商品各月产量统计
A12: 项目 | B12: 1月 | C12: 2月 | D12: 3月 | E12: 4月 | F12: 5月 | G12: 6月 | H12: 7月 | I12: 8月 | J12: 9月 | K12: 10月 | L12: 11月 | M12: 12月 | N12: 合计 | O12: 上年度 | P12: 变动率
N13: =SUM(B13:M13) -> 0 | P13: =IF(AND(O13=0,N13-O13=0),0,IF(AND(O13=0,N13-O13>0),1,(N13-O13)/O13)) -> 0
N14: =SUM(B14:M14) -> 0 | P14: =IF(AND(O14=0,N14-O14=0),0,IF(AND(O14=0,N14-O14>0),1,(N14-O14)/O14)) -> 0
N15: =SUM(B15:M15) -> 0 | P15: =IF(AND(O15=0,N15-O15=0),0,IF(AND(O15=0,N15-O15>0),1,(N15-O15)/O15)) -> 0
N16: =SUM(B16:M16) -> 0 | P16: =IF(AND(O16=0,N16-O16=0),0,IF(AND(O16=0,N16-O16>0),1,(N16-O16)/O16)) -> 0
N17: =SUM(B17:M17) -> 0 | P17: =IF(AND(O17=0,N17-O17=0),0,IF(AND(O17=0,N17-O17>0),1,(N17-O17)/O17)) -> 0
N18: =SUM(B18:M18) -> 0 | P18: =IF(AND(O18=0,N18-O18=0),0,IF(AND(O18=0,N18-O18>0),1,(N18-O18)/O18)) -> 0
A19: 合计 | B19: =SUM(B13:B18) -> 0 | C19: =SUM(C13:C18) -> 0 | D19: =SUM(D13:D18) -> 0 | E19: =SUM(E13:E18) -> 0 | F19: =SUM(F13:F18) -> 0 | G19: =SUM(G13:G18) -> 0 | H19: =SUM(H13:H18) -> 0 | I19: =SUM(I13:I18) -> 0 | ... M19: =SUM(M13:M18) -> 0 | N19: =SUM(B19:M19) -> 0 | O19: =SUM(C19:N19) -> 0 | P19: =IF(AND(O19=0,N19-O19=0),0,IF(AND(O19=0,N19-O19>0),1,(N19-O19)/O19)) -> 0
A20: 库存商品各月销售数量统计
A21: 项目 | B21: 1月 | C21: 2月 | D21: 3月 | E21: 4月 | F21: 5月 | G21: 6月 | H21: 7月 | I21: 8月 | J21: 9月 | K21: 10月 | L21: 11月 | M21: 12月 | N21: 合计 | O21: 上年度 | P21: 变动率
A22: =A13 -> 0 | N22: =SUM(B22:M22) -> 0 | P22: =IF(AND(O22=0,N22-O22=0),0,IF(AND(O22=0,N22-O22>0),1,(N22-O22)/O22)) -> 0
A23: =A14 -> 0 | N23: =SUM(B23:M23) -> 0 | P23: =IF(AND(O23=0,N23-O23=0),0,IF(AND(O23=0,N23-O23>0),1,(N23-O23)/O23)) -> 0
A24: =A15 -> 0 | N24: =SUM(B24:M24) -> 0 | P24: =IF(AND(O24=0,N24-O24=0),0,IF(AND(O24=0,N24-O24>0),1,(N24-O24)/O24)) -> 0
A25: =A16 -> 0 | N25: =SUM(B25:M25) -> 0 | P25: =IF(AND(O25=0,N25-O25=0),0,IF(AND(O25=0,N25-O25>0),1,(N25-O25)/O25)) -> 0
A26: =A17 -> 0 | N26: =SUM(B26:M26) -> 0 | P26: =IF(AND(O26=0,N26-O26=0),0,IF(AND(O26=0,N26-O26>0),1,(N26-O26)/O26)) -> 0
A27: =A18 -> 0 | N27: =SUM(B27:M27) -> 0 | P27: =IF(AND(O27=0,N27-O27=0),0,IF(AND(O27=0,N27-O27>0),1,(N27-O27)/O27)) -> 0
A28: 合计 | B28: =SUM(B22:B27) -> 0 | C28: =SUM(C22:C27) -> 0 | D28: =SUM(D22:D27) -> 0 | E28: =SUM(E22:E27) -> 0 | F28: =SUM(F22:F27) -> 0 | G28: =SUM(G22:G27) -> 0 | H28: =SUM(H22:H27) -> 0 | I28: =SUM(I22:I27) -> 0 | ... M28: =SUM(M22:M27) -> 0 | N28: =SUM(B28:M28) -> 0 | O28: =SUM(C28:N28) -> 0 | P28: =IF(AND(O28=0,N28-O28=0),0,IF(AND(O28=0,N28-O28>0),1,(N28-O28)/O28)) -> 0
A29: 库存商品各月销售量与产量占比分析
A30: 项目 | B30: 1月 | C30: 2月 | D30: 3月 | E30: 4月 | F30: 5月 | G30: 6月 | H30: 7月 | I30: 8月 | J30: 9月 | K30: 10月 | L30: 11月 | M30: 12月 | N30: 合计 | O30: 上年度 | P30: 变动率
A31: =A13 -> 0 | B31: =IF(B13=0,0,B22/B13) -> 0 | C31: =IF(C13=0,0,C22/C13) -> 0 | D31: =IF(D13=0,0,D22/D13) -> 0 | E31: =IF(E13=0,0,E22/E13) -> 0 | F31: =IF(F13=0,0,F22/F13) -> 0 | G31: =IF(G13=0,0,G22/G13) -> 0 | H31: =IF(H13=0,0,H22/H13) -> 0 | I31: =IF(I13=0,0,I22/I13) -> 0 | ... O31: =IF(O13=0,0,O22/O13) -> 0 | P31: =IF(AND(O31=0,N31-O31=0),0,IF(AND(O31=0,N31-O31>0),1,(N31-O31)/O31)) -> 0
A32: =A14 -> 0 | B32: =IF(B14=0,0,B23/B14) -> 0 | C32: =IF(C14=0,0,C23/C14) -> 0 | D32: =IF(D14=0,0,D23/D14) -> 0 | E32: =IF(E14=0,0,E23/E14) -> 0 | F32: =IF(F14=0,0,F23/F14) -> 0 | G32: =IF(G14=0,0,G23/G14) -> 0 | H32: =IF(H14=0,0,H23/H14) -> 0 | I32: =IF(I14=0,0,I23/I14) -> 0 | ... O32: =IF(O14=0,0,O23/O14) -> 0 | P32: =IF(AND(O32=0,N32-O32=0),0,IF(AND(O32=0,N32-O32>0),1,(N32-O32)/O32)) -> 0
A33: =A15 -> 0 | B33: =IF(B15=0,0,B24/B15) -> 0 | C33: =IF(C15=0,0,C24/C15) -> 0 | D33: =IF(D15=0,0,D24/D15) -> 0 | E33: =IF(E15=0,0,E24/E15) -> 0 | F33: =IF(F15=0,0,F24/F15) -> 0 | G33: =IF(G15=0,0,G24/G15) -> 0 | H33: =IF(H15=0,0,H24/H15) -> 0 | I33: =IF(I15=0,0,I24/I15) -> 0 | ... O33: =IF(O15=0,0,O24/O15) -> 0 | P33: =IF(AND(O33=0,N33-O33=0),0,IF(AND(O33=0,N33-O33>0),1,(N33-O33)/O33)) -> 0
A34: =A16 -> 0 | B34: =IF(B16=0,0,B25/B16) -> 0 | C34: =IF(C16=0,0,C25/C16) -> 0 | D34: =IF(D16=0,0,D25/D16) -> 0 | E34: =IF(E16=0,0,E25/E16) -> 0 | F34: =IF(F16=0,0,F25/F16) -> 0 | G34: =IF(G16=0,0,G25/G16) -> 0 | H34: =IF(H16=0,0,H25/H16) -> 0 | I34: =IF(I16=0,0,I25/I16) -> 0 | ... O34: =IF(O16=0,0,O25/O16) -> 0 | P34: =IF(AND(O34=0,N34-O34=0),0,IF(AND(O34=0,N34-O34>0),1,(N34-O34)/O34)) -> 0
A35: =A17 -> 0 | B35: =IF(B17=0,0,B26/B17) -> 0 | C35: =IF(C17=0,0,C26/C17) -> 0 | D35: =IF(D17=0,0,D26/D17) -> 0 | E35: =IF(E17=0,0,E26/E17) -> 0 | F35: =IF(F17=0,0,F26/F17) -> 0 | G35: =IF(G17=0,0,G26/G17) -> 0 | H35: =IF(H17=0,0,H26/H17) -> 0 | I35: =IF(I17=0,0,I26/I17) -> 0 | ... O35: =IF(O17=0,0,O26/O17) -> 0 | P35: =IF(AND(O35=0,N35-O35=0),0,IF(AND(O35=0,N35-O35>0),1,(N35-O35)/O35)) -> 0
A36: =A18 -> 0 | B36: =IF(B18=0,0,B27/B18) -> 0 | C36: =IF(C18=0,0,C27/C18) -> 0 | D36: =IF(D18=0,0,D27/D18) -> 0 | E36: =IF(E18=0,0,E27/E18) -> 0 | F36: =IF(F18=0,0,F27/F18) -> 0 | G36: =IF(G18=0,0,G27/G18) -> 0 | H36: =IF(H18=0,0,H27/H18) -> 0 | I36: =IF(I18=0,0,I27/I18) -> 0 | ... O36: =IF(O18=0,0,O27/O18) -> 0 | P36: =IF(AND(O36=0,N36-O36=0),0,IF(AND(O36=0,N36-O36>0),1,(N36-O36)/O36)) -> 0
A37: 合计 | B37: =IF(B19=0,0,B28/B19) -> 0 | C37: =IF(C19=0,0,C28/C19) -> 0 | D37: =IF(D19=0,0,D28/D19) -> 0 | E37: =IF(E19=0,0,E28/E19) -> 0 | F37: =IF(F19=0,0,F28/F19) -> 0 | G37: =IF(G19=0,0,G28/G19) -> 0 | H37: =IF(H19=0,0,H28/H19) -> 0 | I37: =IF(I19=0,0,I28/I19) -> 0 | ... O37: =IF(O19=0,0,O28/O19) -> 0 | P37: =IF(AND(O37=0,N37-O37=0),0,IF(AND(O37=0,N37-O37>0),1,(N37-O37)/O37)) -> 0
A38: 原材料各月采购统计
A39: 项目 | B39: 1月 | C39: 2月 | D39: 3月 | E39: 4月 | F39: 5月 | G39: 6月 | H39: 7月 | I39: 8月 | J39: 9月 | K39: 10月 | L39: 11月 | M39: 12月 | N39: 合计 | O39: 上年度 | P39: 变动率
A40: =A13 -> 0 | N40: =SUM(B40:M40) -> 0 | P40: =IF(AND(O40=0,N40-O40=0),0,IF(AND(O40=0,N40-O40>0),1,(N40-O40)/O40)) -> 0
...

Sheet 产品年度成本比较分析F2-20
A1: 致同会计师事务所
A2: 产成品单位成本年度比较分析表
A3: =底稿目录!A2 -> 被审计单位： | F3: =底稿目录!A4 -> 编制人： | L3: =底稿目录!A5 -> 编制日期： | Q3: 索引号： | R3: =底稿目录!F4 -> F2-20
A4: =底稿目录!A3 -> 截止日：202X年12月31日 | F4: =底稿目录!A6 -> 复核人： | L4: =底稿目录!A7 -> 复核日期： | Q4: 页次：
A5: 产成品名称 | B5: 本年单位成本 | G5: 上年单位成本 | L5: 波动比例 | Q5: 是否存在异常波动 | R5: 进一步审验底稿索引
B6: 直接材料 | C6: 直接人工 | D6: 制造费用 | F6: 合计 | G6: 直接材料 | H6: 直接人工 | I6: 制造费用 | K6: 合计 | L6: 直接材料 | M6: 直接人工 | N6: 制造费用 | P6: 合计
F7: =SUM(B7:E7) -> 0 | K7: =SUM(G7:J7) -> 0 | L7: =IF(G7=0,0,(B7-G7)/G7) -> 0 | M7: =IF(H7=0,0,(C7-H7)/H7) -> 0 | N7: =IF(I7=0,0,(D7-I7)/I7) -> 0 | O7: =IF(J7=0,0,(E7-J7)/J7) -> 0 | P7: =IF(K7=0,0,(F7-K7)/K7) -> 0 | S7: 对波动异常的产品应进一步执行舞弊应对程序中原材料采购价格分析<F2-61>、产品生产成本及单耗分析<F2-64>
F8: =SUM(B8:E8) -> 0 | K8: =SUM(G8:J8) -> 0 | L8: =IF(G8=0,0,(B8-G8)/G8) -> 0 | M8: =IF(H8=0,0,(C8-H8)/H8) -> 0 | N8: =IF(I8=0,0,(D8-I8)/I8) -> 0 | O8: =IF(J8=0,0,(E8-J8)/J8) -> 0 | P8: =IF(K8=0,0,(F8-K8)/K8) -> 0
F9: =SUM(B9:E9) -> 0 | K9: =SUM(G9:J9) -> 0 | L9: =IF(G9=0,0,(B9-G9)/G9) -> 0 | M9: =IF(H9=0,0,(C9-H9)/H9) -> 0 | N9: =IF(I9=0,0,(D9-I9)/I9) -> 0 | O9: =IF(J9=0,0,(E9-J9)/J9) -> 0 | P9: =IF(K9=0,0,(F9-K9)/K9) -> 0
F10: =SUM(B10:E10) -> 0 | K10: =SUM(G10:J10) -> 0 | L10: =IF(G10=0,0,(B10-G10)/G10) -> 0 | M10: =IF(H10=0,0,(C10-H10)/H10) -> 0 | N10: =IF(I10=0,0,(D10-I10)/I10) -> 0 | O10: =IF(J10=0,0,(E10-J10)/J10) -> 0 | P10: =IF(K10=0,0,(F10-K10)/K10) -> 0
F11: =SUM(B11:E11) -> 0 | K11: =SUM(G11:J11) -> 0 | L11: =IF(G11=0,0,(B11-G11)/G11) -> 0 | M11: =IF(H11=0,0,(C11-H11)/H11) -> 0 | N11: =IF(I11=0,0,(D11-I11)/I11) -> 0 | O11: =IF(J11=0,0,(E11-J11)/J11) -> 0 | P11: =IF(K11=0,0,(F11-K11)/K11) -> 0
F12: =SUM(B12:E12) -> 0 | K12: =SUM(G12:J12) -> 0 | L12: =IF(G12=0,0,(B12-G12)/G12) -> 0 | M12: =IF(H12=0,0,(C12-H12)/H12) -> 0 | N12: =IF(I12=0,0,(D12-I12)/I12) -> 0 | O12: =IF(J12=0,0,(E12-J12)/J12) -> 0 | P12: =IF(K12=0,0,(F12-K12)/K12) -> 0
F13: =SUM(B13:E13) -> 0 | K13: =SUM(G13:J13) -> 0 | L13: =IF(G13=0,0,(B13-G13)/G13) -> 0 | M13: =IF(H13=0,0,(C13-H13)/H13) -> 0 | N13: =IF(I13=0,0,(D13-I13)/I13) -> 0 | O13: =IF(J13=0,0,(E13-J13)/J13) -> 0 | P13: =IF(K13=0,0,(F13-K13)/K13) -> 0
F14: =SUM(B14:E14) -> 0 | K14: =SUM(G14:J14) -> 0 | L14: =IF(G14=0,0,(B14-G14)/G14) -> 0 | M14: =IF(H14=0,0,(C14-H14)/H14) -> 0 | N14: =IF(I14=0,0,(D14-I14)/I14) -> 0 | O14: =IF(J14=0,0,(E14-J14)/J14) -> 0 | P14: =IF(K14=0,0,(F14-K14)/K14) -> 0
F15: =SUM(B15:E15) -> 0 | K15: =SUM(G15:J15) -> 0 | L15: =IF(G15=0,0,(B15-G15)/G15) -> 0 | M15: =IF(H15=0,0,(C15-H15)/H15) -> 0 | N15: =IF(I15=0,0,(D15-I15)/I15) -> 0 | O15: =IF(J15=0,0,(E15-J15)/J15) -> 0 | P15: =IF(K15=0,0,(F15-K15)/K15) -> 0
F16: =SUM(B16:E16) -> 0 | K16: =SUM(G16:J16) -> 0 | L16: =IF(G16=0,0,(B16-G16)/G16) -> 0 | M16: =IF(H16=0,0,(C16-H16)/H16) -> 0 | N16: =IF(I16=0,0,(D16-I16)/I16) -> 0 | O16: =IF(J16=0,0,(E16-J16)/J16) -> 0 | P16: =IF(K16=0,0,(F16-K16)/K16) -> 0
A18: 审计说明：
A19: 1.XX产品单位成本异常波动原因： 对XX产品进一步进行生产成本及单耗分析见<F2-64>
A20: 2.原材料采购价格进一步分析见<F2-61>
A22: 审计结论：
