Workbook

Sheet 底稿目录
A1: 底稿开列时，可先在以下单元格填写有关内容，以便其他底稿引用有关数据： | D1: 序号 | E1: 内容 | F1: 索引号
A2: 被审计单位： | D2: 1 | E2: 存货监盘程序表 | F2: F2-21A
A3: 截止日：202X年12月31日 | D3: 2 | E3: 存货盘点计划问卷 | F3: F2-21
A4: 编制人： | D4: 3 | E4: 存货监盘计划 | F4: F2-22
A5: 编制日期： | D5: 4 | E5: 存货监盘小结 | F5: F2-23
A6: 复核人： | D6: 5 | E6: 存货账面余额与仓储台账（ERP业务数据)核对记录 | F6: F2-24
A7: 复核日期： | D7: 6 | E7: 存货抽盘结果汇总表 | F7: F2-25
D8: 7 | E8: 存货盘点倒轧表 | F8: F2-26

Sheet GT_Custom
A1: C1 | B1: Custom 1
A2: C2 | B2: Custom 2
A3: C3 | B3: Custom 3
A4: C4 | B4: Custom 4
A5: C5 | B5: Custom 5
A6: C6 | B6: Custom 6
A7: C7 | B7: Custom 7
A8: C8 | B8: Custom 8

Sheet 存货监盘程序表F2-21A
A1: 致同会计师事务所
A2: 存货监盘程序表
A3: =底稿目录!A2 -> 被审计单位： | C3: =底稿目录!A4 -> 编制人： | D3: =底稿目录!A5 -> 编制日期： | E3: 索引号： | F3: =底稿目录!F2 -> F2-21A
A4: =底稿目录!A3 -> 截止日：202X年12月31日 | C4: =底稿目录!A6 -> 复核人： | D4: =底稿目录!A7 -> 复核日期： | E4: 页 次：
A5: 序号 | B5: 审计程序 | D5: 程序分类 | E5: 底稿索引号 | G5: 根据被审计单位实际情况和风险评估情况裁剪、修改或增加审计程序
A6: （一） | B6: 了解存货形态、取得存货存放地点清单等，确定是否实地监盘存货，并考虑： （1）存货存放地点、所有地点同时进行、在期末或接近期末执行监盘； （2）以不可预见的时间和方式进行，对特殊形态的存货是否利用专家工作。 | D6: 常规★
A7: （二） | B7: 评价被审计单位存货盘点内部控制、程序和指令，完成盘点计划调查问卷 | D7: 常规★ | E7: F2-21
A8: 1 | B8: 根据被审计单位的存货盘存制度和相关内部控制的有效性，与管理层讨论评价盘点时间是否合理： （1）盘点日是否与资产负债表一致，如果盘点日和资产负债表日不一致，评价对内部控制的信赖能否将盘点日的结论延伸至资产负债表日； （2）所有重要存货均列入盘点范围（包括在异地存放的重要存货）、不同地点存货是否同时盘点； | D8: 常规★
A9: 2 | B9: 获取被审计单位加盖公司印鉴的完整仓库清单或存货存放地点清单（包括期末库存量为零的仓库、租赁的仓库，以及第三方代被审计单位保管存货的仓库等）及按存放地点分类的存货明细表，结合询问、与前期仓库变动情况、存货出入库单中的仓库、支付的仓储租金、固定资产中仓库建筑物分析是否存在遗漏的仓库、遗漏存货存放地点。 | D9: 常规★
A10: 3 | B10: 获取被审计单位存货盘点计划及其他用以记录和控制存货盘点结果的指令和程序，与管理层讨论： （1）在盘点过程中是否存在无法停止移动的存货，所采取的控制程序和对存货收发截止影响的考虑； （2）盘点的计量工具和计量方法，对于盘点有困难的特殊存货，盘点方法的可行性和科学性，是否有专家参与盘点； （3）出入库单等与存货相关的单据是否连续编号，如何控制存货的完整性和截止性等。 | D10: 常规★
A11: 4 | B11: 与管理层讨论以前年度存货存在的问题以及目前存货的状况。 | D11: 常规★
A12: 5 | B12: 评价被审计单位的盘点计划是否恰当、是否存在缺陷。 | D12: 常规★
A13: （三） | B13: 编制存货监盘计划 | D13: 常规★ | E13: F2-22
A14: 1 | B14: 在获取完整的存货存放地点清单的基础上，根据不同地点所存放存货的重要性以及对各个地点与存货相关的重大错报风险的评估结果，选择适当的地点进行监盘，并记录选择这些地点的原因。在连续审计中，可考虑在不同期间的审计中变更所选择实施监盘的地点。 | D14: 常规★
A15: 2 | B15: 取得被审计单位永续盘存纪录（盘点表），选择对总体中特定项目（金额重大、性质特殊）全部进行抽盘，剩余部分可采用抽样的方式选择抽盘样本。 | D15: 常规★
A16: 3 | B16: 根据了解的被审计单位存货的形态及特点，制定存货监盘计划（考虑前期存货监盘对本期监盘的影响、前期监盘遇到的重大问题及存货监盘的改善建议、风险评估结果、特别风险、同时进行、具有不可预见性和针对性），并将计划传达给参与监盘的项目组成员，以明确监盘时间、监盘范围、监盘方式、抽盘范围、参与人员及分工等事项。 | D16: 常规★
A17: 4 | B17: 判断内部审计部门在盘点中的参与程度，考虑内部审计人员已执行或拟执行的特定工作的性质和范围、重大错报风险、专业胜任能力、客观性，以及是否利用内部审计的工作。 | D17: 备选
A18: 5 | B18: 如果管理层不允许在同一时间对所有存放地点的存货实施监盘，关注可能存在管理层操纵转移不同地点的存货以虚增或虚减存货的舞弊风险。 | D18: IPO/上市/新三板/重组/舞弊应对
A19: （四） | B19: 观察管理层制定的盘点程序的执行情况，并检查存货并检查存货的状况，是否存在过时、毁损或陈旧的存货； | D19: 常规★ | E19: F2-
A20: 1 | B20: 在被审计单位盘点存货前，观察盘点现场： （1）确定应纳入盘点范围的存货是否已经适当整理和排列，是否存在已经销售但仍存放在公司仓库或未确认收入已由客户代管的存货； （2）存货是否附有盘点标识/标签/编号，是否存在重复、是否有未纳入盘点范围的存货以及未纳入的原因； （3）存货是否已经停止流动，如未停止流动，如何对在不同存放地点之间的流动以及出入库情况进行控制。 （4）是否已经恰当区分所有毁损、陈旧、过时及残次的存货； （5）是否对计量用具（地秤、秤量器和其他计量器）进行校验； （6）是否对存货盘点表单的领用实施充分的控制，并通过连续编号确保没有遗漏或重复。 | D20: 常规★ | G20: 根据被审计单位实际情况裁剪程序
A21: 2 | B21: 在被审计单位盘点人员盘点过程中，进行观察： （1）被审计单位的实际盘点是否按照计划进行，盘点过程是否有独立于存货实物管理责任人员以外的人员参与； （2）盘点人员是否是否准确记录了存货实际的数量和状况； （3）是否使用复盘法（对相同的存货执行两次清点）进行盘点，如不是，如何确保所有存货盘点准确； （4）对于特殊类型的存货（如堆积型存货、液体、气体、生物资产等），用于估计数量的方法是否恰当； （5）关注存货发送和验收场所，确定这里的存货是否应包括在盘点范围内； （6）盘点人员是否记录了毁损、陈旧、残次和周转缓慢及可能毁损、陈旧、残次和周转缓慢的存货； （7）已填用、作废及未使用的盘点表单、标识/标签的号码是否完整记录； （8）是否特别关注在产品完工进度、金额重大存货、数量重大存货、可能报废/损毁/陈旧/残次存货、第三方存货、抵质押、所有权证据（如货运单价、商标）等； （9）盘点中发现的问题否是否得到适当的跟进与解决，对盘点结果的改动是否经过适当的授权审批 | D21: 常规★ | G21: 根据被审计单位实际情况裁剪程序
A22: 3 | B22: 已恰当识别所有权不属于被审计单位的存货（如寄售商品），并单独标识和存放，以确保这些存货没有被纳入盘点范围。 | D22: 常规★
A23: 4 | B23: 观察有关存货移动的控制程序是否得到执行，核实在不同地点间转移的库存产品未遗漏和重复。 | D23: 常规★
A24: 5 | B24: 盘点结束后，与适当人员巡回检查仓库，以确定所有的存货已被盘点、未被重复盘点；确定已发放的表单是否均已收回，取得签章的盘点控制文件（如：盘点清单、盘点汇总表、标签控制清单）及盘盈、盘亏处理意见等报告和管理部门的审批文件，并账面核对相符。 | D24: 常规★ | G24: 根据被审计单位实际情况裁剪程序
A25: （五） | B25: 根据监盘计划，执行抽盘，核对盘点结果并编制监盘小结 | D25: 常规★ | E25: F2-23
A26: 1 | B26: 抽查核对被审计单位存货明细账与仓库台账（仓储系统）的盘点日存货结存余额是否一致，不一致的查明原因。 | D26: 常规★ | E26: F2-24
A27: 2 | B27: 结合被审计单位实际盘点是否与计划存货监盘工作时的估计基本一致，如果存在较大差异，考虑修改抽盘范围。 （1）从存货盘点记录中选取项目追查至存货实物，以测试盘点记录的准确性； （2）从存货实物中选取项目追查至存货盘点记录，以测试存货盘点的完整性。 | D27: 常规★ | E27: F2-25
A28: 3 | B28: 对以包装箱等封存的存货，考虑要求打开箱子或挪开成堆的箱子。 | D28: 常规★
A29: 4 | B29: 对计量特殊、质量特征特殊等特殊类型的存货，考虑实施追加的审计程序或利用专家的工作。 | D29: 备选
A30: 5 | B30: 将抽盘结果与被审计单位盘点记录、资产负债表日账面记录核对，当抽盘中发现错报时应查明原因，考虑扩大抽盘范围以及是否应调整错报。 | D30: 常规★ | E30: F2-25
A31: 6 | B31: 如存货盘点日不是资产负债表日，检查盘点日与资产负债表日之间存货的变动是否已作正确的记录，并将抽盘结果进行存货倒轧，结合存货截止测试考虑存货在盘点日和财务报表日的截止是否正确。 | D31: 备选 | E31: F2-26
A32: 7 | B32: 核对存货监盘记录与存货明细账记录 （1）从明细账中选取具有代表性的样本，将明细账上的存货数量与经确认盘点报告的数量核对； （2）从经确认的盘点报告中抽取有代表性的样本，将盘点报告的数量与存货明细账核对。 | D32: 常规★ | E32: F2-25
A33: 8 | B33: 完成存货监盘程序表要求的各项工作，复核监盘结果汇总记录，编制存货监盘报告（监盘小结） | D33: 常规★ | E33: F2-23
A34: （六） | B34: 其他考虑
A35: 1 | B35: 如无法直接参与客户存货盘点的，则应在审计外勤日对被审计单位的存货内部控制的有效性进行评估，并对重要存货项目进行实地盘点，同时在测试有关存货项目资产负债表日至盘点日之间所有增减变动的会计记录的基础上进行存货倒轧。 | D35: 备选
A36: 2 | B36: 如果由第三方保管或控制的存货对财务报表是重要的，考虑现场盘点第三方保管或控制的存货 | D36: 备选
A37: 3 | B37: 如果认为被审计单位的盘点方式及其结果无效，提请被审计单位重新盘点。 | D37: 备选

Sheet 盘点计划问卷F2-21
A1: 致同会计师事务所
A2: 存货盘点计划问卷
A3: =底稿目录!A2 -> 被审计单位： | D3: =底稿目录!A4 -> 编制人： | F3: =底稿目录!A5 -> 编制日期： | H3: 索引号： | I3: =底稿目录!F3 -> F2-21
A4: =底稿目录!A3 -> 截止日：202X年12月31日 | D4: =底稿目录!A6 -> 复核人： | F4: =底稿目录!A7 -> 复核日期： | H4: 页次：
A5: 本调查问卷旨在帮助注册会计师了解和评价被审计单位存货盘点计划。如果被审计单位有盘点的书面说明,本调查问卷也可作为有益的补充。需要说明的是,注册会计师在审计实务中,应当根据被审计单位所处行业的特点、内部控制和会计核算制度等具体情况,对本调查问卷进行修改。存货盘点需审计人员现场亲自监盘，如果因特殊情况需要视频盘点的，应详细说明视频盘点的原因和合理性，并详细记录监盘过程、项目地理位置和坐标信息，核实视频中盘点人员身份，确保视频监盘程序的有效性。 | K5: 提示1：如果被审计单位的存货存放在多个地点，注册会计师可以要求被审计单位提供一份完整的存货存放地点清单（包括期末库存量为零的仓库、租赁的仓库，以及第三方代被审计单位保管存货的仓库等），并考虑其完整性。根据具体情况下的风险评估结果，注册会计师可以考虑执行以下一项或多项审计程序： （1）询问被审计单位除管理层和财务部门以外的其他人员，如营销人员、仓库人员等，以了解有关存货存放地点的情况; （2）比较被审计单位不同时期的存货存放地点清单，关注仓库变动情况，以确定是否存在因仓库变动而未将存货纳入盘点范围的情况发生； （3）检查被审计单位存货的出、入库单，关注是否存在被审计单位尚未告知注册会计师的仓库（如期末库存量为零的仓库）； （4）检查费用支出明细账和租赁合同，关注被审计单位是否租赁仓库并支付租金，如果有，该仓库是否已包括在被审计单位提供的仓库清单中； （5）检查被审计单位“固定资产——房屋建筑物”明细清单，了解被审计单位可用于存放存货的房屋建筑物。
A6: 1.存货盘点的范围、盘点的场所以及盘点时间是如何确定的?填列以下表格。
A7: 地点 | B7: 存货类型 | C7: 占存货总额的大致比例 | D7: 盘点时间
A11: 2．盘点人员是如何组织分工的？是否具有胜任能力？填列以下表格。 | K11: 提示2：如果对存货数量存在舞弊风险，盘点时应考虑： （1）在不预先通知的情况下对特定存放地点的存货实施监盘，或在同一天对所有存放地点实施存货监盘； （2）要求被审计单位在报告期末或临近期末的时点实施存货盘点，如：更严格地检查包装箱中的货物、货物堆放方式（如堆为中空）或标记方式、液态物质（如香水、特殊的化学物质）的质量特征（如纯度、品级或浓度）或利用专家的工作； （3）按照存货的等级或类别、存放地点或其他分类标准，将本期存货数量与前期进行比较，或将盘点数量与永续盘存记录进行比较，如按标签号进行检索以测试存货的标签控制，或按照项目的顺序编号进行整理以检查是否存在漏记或重复编号。
A12: 人员 | B12: 地点 | C12: 职责 | D12: 胜任能力 | E12: 电话
A16: 3.盘点过程是否有专家参加?是否对专家参与盘点作出了适当的安排?
A18: 4.盘点前是否召开会议并布置任务?
A20: 5.在盘点过程中,存货是怎样整理和排列的?
A22: 6.是否存在代销存货等所有权不属于被审计单位的存货?如有,情况如何?
A24: 7.有哪些毁损、陈旧、过时、残次的存货?它们是如何区分和存放的?
A26: 8.半成品、原材料和产成品如何分开?
A28: 9.对于成堆堆放或分散在仓库中的存货,是否设置了专门的盘点程序或数量转换计算的方法?
A30: 10.分散在不同地方的相同存货项目如何汇总(这对于与后续盘点汇总保持一致很重要)?
A32: 11.存货盘点采用什么计量工具和计量方法?
A34: 12.在产品的完工程度如何确认?原材料、直接人工、制造费用等如何在产成品和在产品之间分配?
A36: 13.是否有存放在外单位的存货?如何进行盘点?
A38: 14.放在距离较远的地方的存货如何盘点?
... A58: 22.2盘点计划是否存在缺陷?如是,应建议被审计单位调整。

Sheet 监盘计划F2-22
B3: 存货监盘计划

Sheet 监盘小结F2-23
B3: 存货监盘小结

Sheet 存货账面余额与仓储台账（ERP业务数据)核对记录F2-24
A1: 致同会计师事务所
A2: 存货账面余额与仓储台账（ERP业务数据)核对记录
A3: =底稿目录!A2 -> 被审计单位： | D3: =底稿目录!A4 -> 编制人： | F3: =底稿目录!A5 -> 编制日期： | H3: 索引号： | I3: =底稿目录!F6 -> F2-24
A4: =底稿目录!A3 -> 截止日：202X年12月31日 | D4: =底稿目录!A6 -> 复核人： | F4: =底稿目录!A7 -> 复核日期： | H4: 页 次：
A5: 一、资产负债表日存货账面余额与仓储台账（ERP业务数据)核对记录
A6: 提示1：结合存货常规程序：抽查核对存货收发存明细账是否与仓储台账（ERP业务数据）、卡片记录相符（双向核对）一致
A7: 提示2：如果数据量大可结合IT审计完成核对
A14: 二、盘点日存货账面余额与仓储台账（ERP业务数据)核对记录
A15: 提示1：只适用于监盘（抽盘）日不是资产负债表日的情况
A16: 提示2：如果数据量大可结合IT审计完成核对
A25: 三、审计说明：
A29: 四、审计结论：

Sheet 抽盘结果汇总表F2-25
A1: 致同会计师事务所
A2: 存货抽盘结果汇总表 | N2: 本表将抽盘结果录入并检查盘点差异，现场盘点时记录数量的纸质抽盘表作为本表的附件
A3: =底稿目录!A2 -> 被审计单位： | D3: =底稿目录!A4 -> 编制人： | H3: =底稿目录!A5 -> 编制日期： | L3: 索引号： | M3: =底稿目录!F7 -> F2-25
A4: =底稿目录!A3 -> 截止日：202X年12月31日 | D4: =底稿目录!A6 -> 复核人： | H4: =底稿目录!A7 -> 复核日期： | L4: 页 次：
A5: 一、审计目标:
A6: 1. 资产负债表中记录的存货是存在的，且已经记录在恰当的账户中
A7: 2. 所有应记录的存货均已记录，所有应当包括在财务报表中的相关披露均已包括
A8: 3. 记录的存货由被审计单位拥有或控制
A9: 4. 存货以恰当的金额包括在财务报表中，与之相关的计价或分摊调整已恰当记录，相关披露已得到恰当计量和描述
A10: 二、审计过程:
A11: 仓库名称：_____________________ | F11: 盘点时间：__________________
A12: 监盘人员：（审计人员签字） | F12: 盘点人员：（被审计单位仓库盘点人和财务监盘人签字）
A13: （一）从存货盘点记录中选取项目追查至存货实物
A14: 存货编码 | B14: 存货名称/类别 | C14: 规格 | D14: 单位 | E14: 单价 | F14: 盘点前财务账面记录 | H14: 企业盘点记录数量 | I14: 抽盘数量 | J14: 抽盘与账面差异（+盈-亏） | K14: 抽盘与企业盘点差异 | L14: 企业盘点与账面差异 | M14: 品质状况（正常/残次/毁损/滞销等）
F15: 数量 | G15: 金额
J16: =I16-F16 -> 0 | K16: =I16-H16 -> 0 | L16: =H16-F16 -> 0
J17: =I17-F17 -> 0 | K17: =I17-H17 -> 0 | L17: =H17-F17 -> 0
J18: =I18-F18 -> 0 | K18: =I18-H18 -> 0 | L18: =H18-F18 -> 0
J19: =I19-F19 -> 0 | K19: =I19-H19 -> 0 | L19: =H19-F19 -> 0
J20: =I20-F20 -> 0 | K20: =I20-H20 -> 0 | L20: =H20-F20 -> 0
J21: =I21-F21 -> 0 | K21: =I21-H21 -> 0 | L21: =H21-F21 -> 0
J22: =I22-F22 -> 0 | K22: =I22-H22 -> 0 | L22: =H22-F22 -> 0
J23: =I23-F23 -> 0 | K23: =I23-H23 -> 0 | L23: =H23-F23 -> 0
J24: =I24-F24 -> 0 | K24: =I24-H24 -> 0 | L24: =H24-F24 -> 0
J25: =I25-F25 -> 0 | K25: =I25-H25 -> 0 | L25: =H25-F25 -> 0
J26: =I26-F26 -> 0 | K26: =I26-H26 -> 0 | L26: =H26-F26 -> 0
A27: 合计 | G27: =SUM(G16:G26) -> 0
A28: （二）从存货实物中选取项目追查至存货盘点记录
A29: 存货编码 | B29: 存货名称/类别 | C29: 规格 | D29: 单位 | E29: 单价 | F29: 盘点前财务账面记录 | H29: 企业盘点记录数量 | I29: 抽盘数量 | J29: 抽盘与账面差异（+盈-亏） | K29: 抽盘与企业盘点差异 | L29: 企业盘点与账面差异 | M29: 品质状况（正常/残次/毁损/滞销等）
F30: 数量 | G30: 金额
J31: =I31-F31 -> 0 | K31: =I31-H31 -> 0 | L31: =H31-F31 -> 0
J32: =I32-F32 -> 0 | K32: =I32-H32 -> 0 | L32: =H32-F32 -> 0
J33: =I33-F33 -> 0 | K33: =I33-H33 -> 0 | L33: =H33-F33 -> 0
J34: =I34-F34 -> 0 | K34: =I34-H34 -> 0 | L34: =H34-F34 -> 0
J35: =I35-F35 -> 0 | K35: =I35-H35 -> 0 | L35: =H35-F35 -> 0
J36: =I36-F36 -> 0 | K36: =I36-H36 -> 0 | L36: =H36-F36 -> 0
J37: =I37-F37 -> 0 | K37: =I37-H37 -> 0 | L37: =H37-F37 -> 0
J38: =I38-F38 -> 0 | K38: =I38-H38 -> 0 | L38: =H38-F38 -> 0
J39: =I39-F39 -> 0 | K39: =I39-H39 -> 0 | L39: =H39-F39 -> 0
J40: =I40-F40 -> 0 | K40: =I40-H40 -> 0 | L40: =H40-F40 -> 0
...

Sheet 盘点倒轧表F2-26
A1: 致同会计师事务所
A2: 存货盘点倒轧表
A3: =底稿目录!A2 -> 被审计单位： | D3: =底稿目录!A4 -> 编制人： | I3: =底稿目录!A5 -> 编制日期： | N3: 索引号： | O3: =底稿目录!F8 -> F2-26
A4: =底稿目录!A3 -> 截止日：202X年12月31日 | D4: =底稿目录!A6 -> 复核人： | I4: =底稿目录!A7 -> 复核日期： | N4: 页次：
A5: （一）资产负债表日后盘点倒轧表
A6: 说明：针对有关入库或发出的调整，核对出入库单据是否与明细账记录一致。
A7: 存货类别 | B7: 存货编码 | C7: 品名及规格 | D7: 单位 | E7: 单价 | F7: 仓库 | G7: 监盘日实存数量 | H7: 加：资产负债表日至监盘日发出数量（经核对调节后） | I7: 减：资产负债表日至监盘日入库数量（经核对调节后） | J7: 资产负债表日实存数量 | K7: 资产负债表日账面数量 | L7: 数量差异 | M7: 金额差异 | N7: 差异原因 | O7: 是否调整
J8: =G8+H8-I8 -> 0 | L8: =J8-K8 -> 0 | M8: =L8*E8 -> 0
J9: =J2+H9-I9 -> 0 | L9: =J9-K9 -> 0 | M9: =L9*E9 -> 0
J10: =G10+H10-I10 -> 0 | L10: =J10-K10 -> 0 | M10: =L10*E10 -> 0
J11: =G11+H11-I11 -> 0 | L11: =J11-K11 -> 0 | M11: =L11*E11 -> 0
J12: =G12+H12-I12 -> 0 | L12: =J12-K12 -> 0 | M12: =L12*E12 -> 0
J13: =G13+H13-I13 -> 0 | L13: =J13-K13 -> 0 | M13: =L13*E13 -> 0
J14: =G14+H14-I14 -> 0 | L14: =J14-K14 -> 0 | M14: =L14*E14 -> 0
A15: （二）资产负债表日前盘点倒轧表
A16: 存货类别 | B16: 存货编码 | C16: 品名及规格 | D16: 单位 | E16: 单价 | F16: 仓库 | G16: 监盘日实存数量 | H16: 加：监盘日至资产负债表日入库数量 | I16: 减：监盘日至资产负债表日发出数量 | J16: 资产负债表日实存数量 | K16: 资产负债表日账面数量 | L16: 数量差异 | M16: 金额差异 | N16: 差异原因 | O16: 是否调整
J17: =G17+H17-I17 -> 0 | L17: =J17-K17 -> 0 | M17: =L17*E17 -> 0
J18: =G18+H18-I18 -> 0 | L18: =J18-K18 -> 0 | M18: =L18*E18 -> 0
J19: =G19+H19-I19 -> 0 | L19: =J19-K19 -> 0 | M19: =L19*E19 -> 0
J20: =G20+H20-I20 -> 0 | L20: =J20-K20 -> 0 | M20: =L20*E20 -> 0
J21: =G21+H21-I21 -> 0 | L21: =J21-K21 -> 0 | M21: =L21*E21 -> 0
J22: =G22+H22-I22 -> 0 | L22: =J22-K22 -> 0 | M22: =L22*E22 -> 0
J23: =G23+H23-I23 -> 0 | L23: =J23-K23 -> 0 | M23: =L23*E23 -> 0
A24: 审计说明：
A28: 审计结论：
