Workbook

Sheet 底稿目录
A1: 底稿开列时，可先在以下单元格填写有关内容，以便其他底稿引用有关数据：
A2: 被审计单位： | D2: 序号 | E2: 内容 | F2: 索引号
A3: 截止日：202X年12月31日 | D3: 1 | E3: 计价方法测试表-平均 | F3: F2-38
A4: 编制人： | D4: 2 | E4: 计价方法测试表-先进先出 | F4: F2-39
A5: 编制日期： | D5: 3 | E5: 计价方法测试表-标准成本差异 | F5: F2-40
A6: 复核人： | D6: 4 | E6: 生产成本明细表 | F6: F2-41
A7: 复核日期： | D7: 5 | E7: 直接人工分析表 | F7: F2-42
D8: 6 | E8: 制造费用明细表 | F8: F2-43
D9: 7 | E9: 生产成本分配 | F9: F2-44

Sheet GT_Custom
A1: C1 | B1: Custom 1
A2: C2 | B2: Custom 2
A3: C3 | B3: Custom 3
A4: C4 | B4: Custom 4
A5: C5 | B5: Custom 5
A6: C6 | B6: Custom 6
A7: C7 | B7: Custom 7
A8: C8 | B8: Custom 8

Sheet 存货计价测试程序G2-8-删除
A1: 致同会计师事务所
A2: 存货计价测试程序
A3: =底稿目录!A2 -> 被审计单位： | C3: =底稿目录!A4 -> 编制人： | G3: =底稿目录!A5 -> 编制日期： | K3: 索引号： | L3: G2-8
A4: 会计期间：201X年度 | C4: =底稿目录!A6 -> 复核人： | G4: =底稿目录!A7 -> 复核日期： | K4: 页 次：
A5: 序号 | B5: 审计程序 | D5: 程序分类 | E5: 对应账户 | F5: 对应的认定/风险 | K5: 执行情况说明 （含底稿索引）
B6: 执行存货计价测试：Perform inventory price testing: | D6: 常规 | E6: 存货 | F6: 计价/准确性（毛值） VG 存货计价不准确 Inventory prices not valid | K6: G2-8-1、G2-8-2、G2-8-3 | M6: 删除 | N6: 英文程序是否删除？
A7: 1 | B7: 确定存货计价方法是否恰当，并与上期方法一致。考虑以下几点： Determine whether the method of inventory costing is appropriate and consistent with prior periods. Consider:前期减值项目的账面价值。 Carrying value of items written down in prior periods；运费、相关税费、折扣、返利和其他此类折让。 Freight, commodity taxes, discounts, rebates, and other such allowances | D7: 常规 | E7: 存货 | F7: 计价/准确性（毛值） VG 存货计价不准确 Inventory prices not valid | M7: 删除
A8: 2 | B8: 将现有文件（存货明细表）与对应的上期期末的对应文件相匹配，以完成或确认如下事项： Match the current file with the corresponding file at the end of the prior period to complete or identify the following: | D8: 常规 | E8: 存货 | F8: 计价/准确性（毛值） VG 存货计价不准确 Inventory prices not valid | M8: 删除
A9: 2.1 | B9: 价格出现重大变化的项目 Items with significant changes in price | D9: 常规 | E9: 存货 | F9: 计价/准确性（毛值） VG 存货计价不准确 Inventory prices not valid | M9: 删除
A10: 2.2 | B10: 新项目 New items | D10: 常规 | E10: 存货 | F10: 计价/准确性（毛值） VG 存货计价不准确 Inventory prices not valid | M10: 删除
A11: 2.3 | B11: 本期未发生变动或变动很少（文件未标注最后销售日期，与上期数量相同）Items with little or no activity (same quantity as prior period if files don't have last sale date) | D11: 常规 | E11: 存货 | F11: 计价/准确性（毛值） VG 存货计价不准确 Inventory prices not valid | M11: 删除
A12: 2.4 | B12: 数量为零或负数，或者价格为零或负数的项目 Items with zero or negative quantities and/or prices | D12: 常规 | E12: 存货 | F12: 计价/准确性（毛值） VG 存货计价不准确 Inventory prices not valid | M12: 删除
A13: 3 | B13: 除上述特殊项目外，从剩余的总体中，使用样本计算器设计一个抽样。 From the remaining population, design a sample using the Sample Size Calculator. | D13: 常规 | E13: 存货 | F13: 计价/准确性（毛值） VG 存货计价不准确 Inventory prices not valid | M13: 删除
A14: 3.1 | B14: 使用样本计算器计算样本。 Design a sample using the Sample Size Calculator. | D14: 常规 | E14: 存货 | F14: 计价/准确性（毛值） VG 存货计价不准确 Inventory prices not valid | M14: 删除
A15: 3.2 | B15: 采用适当选样方法选取%S的项目。 Select %S items using an appropriate selection method. | D15: 常规 | E15: 存货 | F15: 计价/准确性（毛值） VG 存货计价不准确 Inventory prices not valid | M15: 删除
A16: 3.3 | B16: 对选中项目进行计价测试。 Test the pricing for the items selected. | D16: 常规 | E16: 存货 | F16: 计价/准确性（毛值） VG 存货计价不准确 Inventory prices not valid | M16: 删除
A17: 3.4 | B17: 向适当的人员报告未解决的差异。 Report unresolved differences to appropriate personnel. | D17: 常规 | E17: 存货 | F17: 计价/准确性（毛值） VG 存货计价不准确 Inventory prices not valid | M17: 删除
A18: 3.5 | B18: 使用样本评价工具，将错报推断到总体。 Project the errors to the population using Sample Evaluation. | D18: 常规 | E18: 存货 | F18: 计价/准确性（毛值） VG 存货计价不准确 Inventory prices not valid | M18: 删除
... A21: 3.8 | B21: 如有推断误差，记录在未更正错报汇总表中。Record the projected error, if any, on the Summary of Unrecorded Misstatements. | D21: 常规 | E21: 存货 | F21: 计价/准确性（毛值） VG 存货计价不准确 Inventory prices not valid | M21: 删除
A22: 4 | B22: 对原材料、自制半成品、库存商品计价测试，还需： | D22: 常规 | E22: 存货 | F22: 计价/准确性（毛值） VG 存货计价不准确 Inventory prices not valid,标准成本应用不合理 Standard costs not applied properly,外币计量不恰当 Foreign currency measurements not proper | M22: 删除 | N22: 移至主程序中
A23: 4.1 | B23: 在以实际成本计价时，应以样本的单位成本与原材料、自制半成品、库存商品明细账核对；原材料、外购库存商品还需核对购货发票（如与期末存货数量相同的最后几张），核实单位成本，并确认存货成本中不包含增值税。 | D23: 常规 | E23: 存货 | F23: 计价/准确性（毛值） VG 存货计价不准确 Inventory prices not valid | M23: 与存货底稿一致
A24: 4.2 | B24: 在以计划成本计价时，应以样本的单位成本与原材料明细账、自制半成品明细账、库存商品明细账、材料成本差异明细账、商品成本差异明细账及购货发票核对；还应检查“材料成本差异”、“商品成本差异”账项发生额、转销额是否计算正确。 | D24: 常规 | E24: 存货 | F24: 计价/准确性（毛值） VG 标准成本应用不合理 Standard costs not applied properly | M24: 与存货底稿一致
A25: 4.3 | B25: 测试进口原材料、进口库存商品的外币折算及相应的关税的会计处理。 | D25: 备选 | E25: 存货 | F25: 计价/准确性（毛值） VG 外币计量不恰当 Foreign currency measurements not proper | M25: 与存货底稿一致
A26: 4.4 | B26: 检查发出材料、自制半成品、库存商品的计价方法（如先进先出法，加权平均法等）是否正确，是否前后期一致，并抽取主要原材料、自制半成品、库存商品进行计价测试，验证被审计单位原材料、自制半成品、库存商品发出汇总表的正确性。 | D26: 常规 | E26: 存货 | F26: 计价/准确性（毛值） VG 存货计价不准确 Inventory prices not valid | M26: 与存货底稿一致
A27: 4.5 | B27: 抽查自制半成品、库存商品入库单，核对自制半成品、库存商品的品种、数量与入账记录是否一致；并检查入库自制半成品、库存商品的实际成本是否与“生产成本”科目的结转额相符。 | D27: 常规 | E27: 存货 | F27: 计价/准确性（毛值） VG 存货计价不准确 Inventory prices not valid | N27: 增加至主程序中
A28: 4.6 | B28: 抽查自制半成品的发出凭证，核对转出自制半成品的品种、数量和实际成本与“生产成本”是否相符。 | D28: 常规 | E28: 存货 | F28: 计价/准确性（毛值） VG 存货计价不准确 Inventory prices not valid | M28: 重复
A29: 4.7 | B29: 抽查库存商品的发出凭证，核对发出库存商品的品种、数量和实际成本与“主营业务成本”是否相符。 | D29: 常规 | E29: 存货 | F29: 计价/准确性（毛值） VG 存货计价不准确 Inventory prices not valid | N29: 增加至主程序中
A30: 5 | B30: 对材料采购或在途物资计价测试，还需： | D30: 常规 | E30: 存货 | F30: 计价/准确性（毛值） VG 存货计价不准确 Inventory prices not valid | N30: 材料采购或在途物资检查移至主程序中
A31: 5.1 | B31: 检查期末物资采购或在途物资，核对有关凭证，查看是否存在不属于本科目核算的其他物资采购。 | D31: 常规 | E31: 存货 | F31: 计价/准确性（毛值） VG 存货计价不准确 Inventory prices not valid
A32: 5.2 | B32: 查阅资产负债表日前后（______）天物资采购或在途物资增减变动的有关账簿记录和收料报告单等资料，检查有无跨期现象，如有，则应作出记录，必要时作调整。 | D32: 常规 | E32: 存货 | F32: 计价/准确性（毛值） VG 存货计价不准确 Inventory prices not valid
A33: 5.3 | B33: 如采用计划成本核算，审核物资采购账项有关材料成本差异发生额的计算处理是否正确。 | D33: 常规 | E33: 存货 | F33: 计价/准确性（毛值） VG 存货计价不准确 Inventory prices not valid
A34: 5.4 | B34: 检查月末转入原材料等科目的会计处理是否正确。 | D34: 常规 | E34: 存货 | F34: 计价/准确性（毛值） VG 存货计价不准确 Inventory prices not valid
A35: 6 | B35: 委托加工物资测试： | D35: 备选 | E35: 存货 | F35: 计价/准确性（毛值） VG 存货计价不准确 Inventory prices not valid | M35: 无此底稿，移至主程序中
A36: 6.1 | B36: 选取重要委托加工业务合同（也可参照9.3选取样本并评估样本误差），抽查有关发料凭证、加工费、运费结算凭证，关注所有权归属，核对其计费、计价是否正确，会计处理是否及时、正确； | D36: 备选 | E36: 存货 | F36: 计价/准确性（毛值） VG 存货计价不准确 Inventory prices not valid
A37: 6.2 | B37: 抽查加工完成物资的验收入库手续是否齐全，会计处理是否正确； | D37: 备选 | E37: 存货 | F37: 计价/准确性（毛值） VG 存货计价不准确 Inventory prices not valid
A38: 6.3 | B38: 检查委外加工自制半成品转入自制半成品的账务处理是否正确； | D38: 备选 | E38: 存货 | F38: 计价/准确性（毛值） VG 存货计价不准确 Inventory prices not valid
A39: 6.4 | B39: 函证核实委外加工自制半成品，必要时现场查看或利用其他注册会计师的工作。 | D39: 备选 | E39: 存货 | F39: 计价/准确性（毛值） VG 存货计价不准确 Inventory prices not valid
A40: 7 | B40: 根据需要，抽取主要周转材料（低值易耗品、包装物）进行计价测试： | D40: 常规 | E40: 存货 | F40: 计价/准确性（毛值） VG 存货计价不准确 Inventory prices not valid
A41: 7.1 | B41: 检查周转材料的入库和领用的手续是否齐全，会计处理是否正确； | D41: 常规 | E41: 存货 | F41: 计价/准确性（毛值） VG 存货计价不准确 Inventory prices not valid
A42: 7.2 | B42: 检查周转材料摊销方法是否正确，前后期是否一致，验证发出周转材料汇总表的正确性； | D42: 常规 | E42: 存货 | F42: 计价/准确性（毛值） VG 存货计价不准确 Inventory prices not valid
...

Sheet 计价方法测试表-平均F2-38
A1: 致同会计师事务所
A2: 存货计价方法测试表（月末一次加权平均法适用）
A3: =底稿目录!A2 -> 被审计单位： | E3: =底稿目录!A4 -> 编制人： | I3: =底稿目录!A5 -> 编制日期： | M3: 索引号： | N3: =底稿目录!F3 -> F2-38
A4: =底稿目录!A3 -> 截止日：202X年12月31日 | E4: =底稿目录!A6 -> 复核人： | I4: =底稿目录!A7 -> 复核日期： | M4: 页 次：
A5: 一、测试目标：
A6: 存货以恰当的金额包括在财务报表中，与之相关的计价或分摊调整已恰当记录，相关披露已得到恰当计量和描述
A7: 二、样本选取标准与规模：
A9: 三、测试：
A10: （一）计价方法说明： | D10: 月末一次加权平均法
A11: （二）测试项目1： | C11: 品名：
A12: 月份 | B12: 本期生产（或购入） | E12: 本期销售（或发出） | H12: 期末结存 | K12: 应结转 | N12: 差异
B13: 数量 | C13: 单价 | D13: 金额 | E13: 数量 | F13: 单价 | G13: 金额 | H13: 数量 | I13: 单价 | J13: 金额 | K13: 单价 | L13: 金额 | M13: 结余 | N13: M=K-F
A14: 年初数 | B14: A | C14: B | D14: C | E14: D | F14: E | G14: F | I14: =IF(ISERROR(J14/H14),0,J14/H14) -> 0 | K14: J | L14: K | M14: =J14 -> 0 | N14: M
A15: 1月 | C15: =IF(ISERROR(D15/B15),0,D15/B15) -> 0 | F15: =IF(ISERROR(G15/E15),0,G15/E15) -> 0 | H15: =H14+B15-E15 -> 0 | I15: =IF(ISERROR(J15/H15),0,J15/H15) -> 0 | J15: =J14+D15-G15 -> 0 | K15: =IF(ISERROR((M14+D15)/(H14+B15)),0,(M14+D15)/(H14+B15)) -> 0 | L15: =K15*E15 -> 0 | M15: =M14+D15-L15 -> 0 | N15: =L15-G15 -> 0
A16: 2月 | C16: =IF(ISERROR(D16/B16),0,D16/B16) -> 0 | F16: =IF(ISERROR(G16/E16),0,G16/E16) -> 0 | H16: =H15+B16-E16 -> 0 | I16: =IF(ISERROR(J16/H16),0,J16/H16) -> 0 | J16: =J15+D16-G16 -> 0 | K16: =IF(ISERROR((M15+D16)/(H15+B16)),0,(M15+D16)/(H15+B16)) -> 0 | L16: =K16*E16 -> 0 | M16: =M15+D16-L16 -> 0 | N16: =L16-G16 -> 0
A17: 3月 | C17: =IF(ISERROR(D17/B17),0,D17/B17) -> 0 | F17: =IF(ISERROR(G17/E17),0,G17/E17) -> 0 | H17: =H16+B17-E17 -> 0 | I17: =IF(ISERROR(J17/H17),0,J17/H17) -> 0 | J17: =J16+D17-G17 -> 0 | K17: =IF(ISERROR((M16+D17)/(H16+B17)),0,(M16+D17)/(H16+B17)) -> 0 | L17: =K17*E17 -> 0 | M17: =M16+D17-L17 -> 0 | N17: =L17-G17 -> 0
A18: 4月 | C18: =IF(ISERROR(D18/B18),0,D18/B18) -> 0 | F18: =IF(ISERROR(G18/E18),0,G18/E18) -> 0 | H18: =H17+B18-E18 -> 0 | I18: =IF(ISERROR(J18/H18),0,J18/H18) -> 0 | J18: =J17+D18-G18 -> 0 | K18: =IF(ISERROR((M17+D18)/(H17+B18)),0,(M17+D18)/(H17+B18)) -> 0 | L18: =K18*E18 -> 0 | M18: =M17+D18-L18 -> 0 | N18: =L18-G18 -> 0
A19: 5月 | C19: =IF(ISERROR(D19/B19),0,D19/B19) -> 0 | F19: =IF(ISERROR(G19/E19),0,G19/E19) -> 0 | H19: =H18+B19-E19 -> 0 | I19: =IF(ISERROR(J19/H19),0,J19/H19) -> 0 | J19: =J18+D19-G19 -> 0 | K19: =IF(ISERROR((M18+D19)/(H18+B19)),0,(M18+D19)/(H18+B19)) -> 0 | L19: =K19*E19 -> 0 | M19: =M18+D19-L19 -> 0 | N19: =L19-G19 -> 0
A20: 6月 | C20: =IF(ISERROR(D20/B20),0,D20/B20) -> 0 | F20: =IF(ISERROR(G20/E20),0,G20/E20) -> 0 | H20: =H19+B20-E20 -> 0 | I20: =IF(ISERROR(J20/H20),0,J20/H20) -> 0 | J20: =J19+D20-G20 -> 0 | K20: =IF(ISERROR((M19+D20)/(H19+B20)),0,(M19+D20)/(H19+B20)) -> 0 | L20: =K20*E20 -> 0 | M20: =M19+D20-L20 -> 0 | N20: =L20-G20 -> 0
A21: 7月 | C21: =IF(ISERROR(D21/B21),0,D21/B21) -> 0 | F21: =IF(ISERROR(G21/E21),0,G21/E21) -> 0 | H21: =H20+B21-E21 -> 0 | I21: =IF(ISERROR(J21/H21),0,J21/H21) -> 0 | J21: =J20+D21-G21 -> 0 | K21: =IF(ISERROR((M20+D21)/(H20+B21)),0,(M20+D21)/(H20+B21)) -> 0 | L21: =K21*E21 -> 0 | M21: =M20+D21-L21 -> 0 | N21: =L21-G21 -> 0
A22: 8月 | C22: =IF(ISERROR(D22/B22),0,D22/B22) -> 0 | F22: =IF(ISERROR(G22/E22),0,G22/E22) -> 0 | H22: =H21+B22-E22 -> 0 | I22: =IF(ISERROR(J22/H22),0,J22/H22) -> 0 | J22: =J21+D22-G22 -> 0 | K22: =IF(ISERROR((M21+D22)/(H21+B22)),0,(M21+D22)/(H21+B22)) -> 0 | L22: =K22*E22 -> 0 | M22: =M21+D22-L22 -> 0 | N22: =L22-G22 -> 0
A23: 9月 | C23: =IF(ISERROR(D23/B23),0,D23/B23) -> 0 | F23: =IF(ISERROR(G23/E23),0,G23/E23) -> 0 | H23: =H22+B23-E23 -> 0 | I23: =IF(ISERROR(J23/H23),0,J23/H23) -> 0 | J23: =J22+D23-G23 -> 0 | K23: =IF(ISERROR((M22+D23)/(H22+B23)),0,(M22+D23)/(H22+B23)) -> 0 | L23: =K23*E23 -> 0 | M23: =M22+D23-L23 -> 0 | N23: =L23-G23 -> 0
A24: 10月 | C24: =IF(ISERROR(D24/B24),0,D24/B24) -> 0 | F24: =IF(ISERROR(G24/E24),0,G24/E24) -> 0 | H24: =H23+B24-E24 -> 0 | I24: =IF(ISERROR(J24/H24),0,J24/H24) -> 0 | J24: =J23+D24-G24 -> 0 | K24: =IF(ISERROR((M23+D24)/(H23+B24)),0,(M23+D24)/(H23+B24)) -> 0 | L24: =K24*E24 -> 0 | M24: =M23+D24-L24 -> 0 | N24: =L24-G24 -> 0
A25: 11月 | C25: =IF(ISERROR(D25/B25),0,D25/B25) -> 0 | F25: =IF(ISERROR(G25/E25),0,G25/E25) -> 0 | H25: =H24+B25-E25 -> 0 | I25: =IF(ISERROR(J25/H25),0,J25/H25) -> 0 | J25: =J24+D25-G25 -> 0 | K25: =IF(ISERROR((M24+D25)/(H24+B25)),0,(M24+D25)/(H24+B25)) -> 0 | L25: =K25*E25 -> 0 | M25: =M24+D25-L25 -> 0 | N25: =L25-G25 -> 0
A26: 12月 | C26: =IF(ISERROR(D26/B26),0,D26/B26) -> 0 | F26: =IF(ISERROR(G26/E26),0,G26/E26) -> 0 | H26: =H25+B26-E26 -> 0 | I26: =IF(ISERROR(J26/H26),0,J26/H26) -> 0 | J26: =J25+D26-G26 -> 0 | K26: =IF(ISERROR((M25+D26)/(H25+B26)),0,(M25+D26)/(H25+B26)) -> 0 | L26: =K26*E26 -> 0 | M26: =M25+D26-L26 -> 0 | N26: =L26-G26 -> 0
A27: 合计 | B27: =SUM(B14:B26) -> 0 | C27: =IF(ISERROR(D27/B27),0,D27/B27) -> 0 | D27: =SUM(D14:D26) -> 0 | E27: =SUM(E14:E26) -> 0 | F27: =IF(ISERROR(G27/E27),0,G27/E27) -> 0 | G27: =SUM(G24:G26) -> 0 | H27: =H26 -> 0 | I27: =IF(ISERROR(J27/H27),0,J27/H27) -> 0 | J27: =J26 -> 0 | L27: =SUM(L15:L26) -> 0 | M27: =M26 -> 0 | N27: =SUM(N15:N26) -> 0
A28: （二）测试项目2： | C28: 品名：
A29: 月份 | B29: 本期生产（或购入） | E29: 本期销售（或发出） | H29: 期末结存 | K29: 应结转 | N29: 差异
B30: 数量 | C30: 单价 | D30: 金额 | E30: 数量 | F30: 单价 | G30: 金额 | H30: 数量 | I30: 单价 | J30: 金额 | K30: 单价 | L30: 金额 | M30: 结余 | N30: M=K-F
A31: 年初数 | B31: A | C31: B | D31: C | E31: D | F31: E | G31: F | I31: =IF(ISERROR(J31/H31),0,J31/H31) -> 0 | K31: J | L31: K | M31: =J31 -> 0 | N31: M
A32: 1月 | C32: =IF(ISERROR(D32/B32),0,D32/B32) -> 0 | F32: =IF(ISERROR(G32/E32),0,G32/E32) -> 0 | H32: =H31+B32-E32 -> 0 | I32: =IF(ISERROR(J32/H32),0,J32/H32) -> 0 | J32: =J31+D32-G32 -> 0 | K32: =IF(ISERROR((M31+D32)/(H31+B32)),0,(M31+D32)/(H31+B32)) -> 0 | L32: =K32*E32 -> 0 | M32: =M31+D32-L32 -> 0 | N32: =L32-G32 -> 0
A33: 2月 | C33: =IF(ISERROR(D33/B33),0,D33/B33) -> 0 | F33: =IF(ISERROR(G33/E33),0,G33/E33) -> 0 | H33: =H32+B33-E33 -> 0 | I33: =IF(ISERROR(J33/H33),0,J33/H33) -> 0 | J33: =J32+D33-G33 -> 0 | K33: =IF(ISERROR((M32+D33)/(H32+B33)),0,(M32+D33)/(H32+B33)) -> 0 | L33: =K33*E33 -> 0 | M33: =M32+D33-L33 -> 0 | N33: =L33-G33 -> 0
A34: 3月 | C34: =IF(ISERROR(D34/B34),0,D34/B34) -> 0 | F34: =IF(ISERROR(G34/E34),0,G34/E34) -> 0 | H34: =H33+B34-E34 -> 0 | I34: =IF(ISERROR(J34/H34),0,J34/H34) -> 0 | J34: =J33+D34-G34 -> 0 | K34: =IF(ISERROR((M33+D34)/(H33+B34)),0,(M33+D34)/(H33+B34)) -> 0 | L34: =K34*E34 -> 0 | M34: =M33+D34-L34 -> 0 | N34: =L34-G34 -> 0
A35: 4月 | C35: =IF(ISERROR(D35/B35),0,D35/B35) -> 0 | F35: =IF(ISERROR(G35/E35),0,G35/E35) -> 0 | H35: =H34+B35-E35 -> 0 | I35: =IF(ISERROR(J35/H35),0,J35/H35) -> 0 | J35: =J34+D35-G35 -> 0 | K35: =IF(ISERROR((M34+D35)/(H34+B35)),0,(M34+D35)/(H34+B35)) -> 0 | L35: =K35*E35 -> 0 | M35: =M34+D35-L35 -> 0 | N35: =L35-G35 -> 0
A36: 5月 | C36: =IF(ISERROR(D36/B36),0,D36/B36) -> 0 | F36: =IF(ISERROR(G36/E36),0,G36/E36) -> 0 | H36: =H35+B36-E36 -> 0 | I36: =IF(ISERROR(J36/H36),0,J36/H36) -> 0 | J36: =J35+D36-G36 -> 0 | K36: =IF(ISERROR((M35+D36)/(H35+B36)),0,(M35+D36)/(H35+B36)) -> 0 | L36: =K36*E36 -> 0 | M36: =M35+D36-L36 -> 0 | N36: =L36-G36 -> 0
A37: 6月 | C37: =IF(ISERROR(D37/B37),0,D37/B37) -> 0 | F37: =IF(ISERROR(G37/E37),0,G37/E37) -> 0 | H37: =H36+B37-E37 -> 0 | I37: =IF(ISERROR(J37/H37),0,J37/H37) -> 0 | J37: =J36+D37-G37 -> 0 | K37: =IF(ISERROR((M36+D37)/(H36+B37)),0,(M36+D37)/(H36+B37)) -> 0 | L37: =K37*E37 -> 0 | M37: =M36+D37-L37 -> 0 | N37: =L37-G37 -> 0
A38: 7月 | C38: =IF(ISERROR(D38/B38),0,D38/B38) -> 0 | F38: =IF(ISERROR(G38/E38),0,G38/E38) -> 0 | H38: =H37+B38-E38 -> 0 | I38: =IF(ISERROR(J38/H38),0,J38/H38) -> 0 | J38: =J37+D38-G38 -> 0 | K38: =IF(ISERROR((M37+D38)/(H37+B38)),0,(M37+D38)/(H37+B38)) -> 0 | L38: =K38*E38 -> 0 | M38: =M37+D38-L38 -> 0 | N38: =L38-G38 -> 0
A39: 8月 | C39: =IF(ISERROR(D39/B39),0,D39/B39) -> 0 | F39: =IF(ISERROR(G39/E39),0,G39/E39) -> 0 | H39: =H38+B39-E39 -> 0 | I39: =IF(ISERROR(J39/H39),0,J39/H39) -> 0 | J39: =J38+D39-G39 -> 0 | K39: =IF(ISERROR((M38+D39)/(H38+B39)),0,(M38+D39)/(H38+B39)) -> 0 | L39: =K39*E39 -> 0 | M39: =M38+D39-L39 -> 0 | N39: =L39-G39 -> 0
A40: 9月 | C40: =IF(ISERROR(D40/B40),0,D40/B40) -> 0 | F40: =IF(ISERROR(G40/E40),0,G40/E40) -> 0 | H40: =H39+B40-E40 -> 0 | I40: =IF(ISERROR(J40/H40),0,J40/H40) -> 0 | J40: =J39+D40-G40 -> 0 | K40: =IF(ISERROR((M39+D40)/(H39+B40)),0,(M39+D40)/(H39+B40)) -> 0 | L40: =K40*E40 -> 0 | M40: =M39+D40-L40 -> 0 | N40: =L40-G40 -> 0
A41: 10月 | C41: =IF(ISERROR(D41/B41),0,D41/B41) -> 0 | F41: =IF(ISERROR(G41/E41),0,G41/E41) -> 0 | H41: =H40+B41-E41 -> 0 | I41: =IF(ISERROR(J41/H41),0,J41/H41) -> 0 | J41: =J40+D41-G41 -> 0 | K41: =IF(ISERROR((M40+D41)/(H40+B41)),0,(M40+D41)/(H40+B41)) -> 0 | L41: =K41*E41 -> 0 | M41: =M40+D41-L41 -> 0 | N41: =L41-G41 -> 0
...

Sheet 计价方法测试表-先进先出F2-39
A1: 致同会计师事务所
A2: 存货计价方法测试表（先进先出法/移动加权平均法适用）
A3: =底稿目录!A2 -> 被审计单位： | F3: =底稿目录!A4 -> 编制人： | J3: =底稿目录!A5 -> 编制日期： | M3: 索引号： | N3: F2-39
A4: =底稿目录!A3 -> 截止日：202X年12月31日 | F4: =底稿目录!A6 -> 复核人： | J4: =底稿目录!A7 -> 复核日期： | M4: 页 次：
A5: 一、测试目标：
A6: 存货以恰当的金额包括在财务报表中，与之相关的计价或分摊调整已恰当记录，相关披露已得到恰当计量和描述
A7: 二、样本选取标准与规模：
A9: 三、测试：
A10: （一）计价方法说明： | D10: 先进先出法/移动加权平均法
A11: （二）测试项目1： | C11: 品名：
A12: 日期 | B12: 本期生产（或购入） | E12: 本期销售（或发出） | H12: 期末结存 | K12: 应结转 | N12: 差异
B13: 数量 | C13: 单价 | D13: 金额 | E13: 数量 | F13: 单价 | G13: 金额 | H13: 数量 | I13: 单价 | J13: 金额 | K13: 单价 | L13: 金额 | M13: 结余 | N13: M=K-F
A14: 年初数 | B14: A | C14: B | D14: C | E14: D | F14: E | G14: F | I14: =IF(ISERROR(J14/H14),0,J14/H14) -> 0 | K14: J | L14: K | M14: =J14 -> 0 | N14: M
A28: 合计 | B28: =SUM(B14:B27) -> 0 | C28: =IF(ISERROR(D28/B28),0,D28/B28) -> 0 | D28: =SUM(D14:D27) -> 0 | E28: =SUM(E14:E27) -> 0 | F28: =IF(ISERROR(G28/E28),0,G28/E28) -> 0 | G28: =SUM(G24:G27) -> 0 | H28: =H27 -> 0 | I28: =IF(ISERROR(J28/H28),0,J28/H28) -> 0 | J28: =J27 -> 0 | L28: =SUM(L16:L27) -> 0 | M28: =M27 -> 0 | N28: =SUM(N16:N27) -> 0
A29: （二）测试项目2： | C29: 品名：
A30: 日期 | B30: 本期生产（或购入） | E30: 本期销售（或发出） | H30: 期末结存 | K30: 应结转 | N30: 差异
B31: 数量 | C31: 单价 | D31: 金额 | E31: 数量 | F31: 单价 | G31: 金额 | H31: 数量 | I31: 单价 | J31: 金额 | K31: 单价 | L31: 金额 | M31: 结余 | N31: M=K-F
A32: 年初数 | B32: A | C32: B | D32: C | E32: D | F32: E | G32: F | I32: =IF(ISERROR(J32/H32),0,J32/H32) -> 0 | K32: J | L32: K | M32: =J32 -> 0 | N32: M
A46: 合计 | B46: =SUM(B32:B45) -> 0 | C46: =IF(ISERROR(D46/B46),0,D46/B46) -> 0 | D46: =SUM(D32:D45) -> 0 | E46: =SUM(E32:E45) -> 0 | F46: =IF(ISERROR(G46/E46),0,G46/E46) -> 0 | G46: =SUM(G42:G45) -> 0 | H46: =H45 -> 0 | I46: =IF(ISERROR(J46/H46),0,J46/H46) -> 0 | J46: =J45 -> 0 | L46: =SUM(L34:L45) -> 0 | M46: =M45 -> 0 | N46: =SUM(N34:N45) -> 0
A47: （二）测试项目3： | C47: 品名：
A48: 日期 | B48: 本期生产（或购入） | E48: 本期销售（或发出） | H48: 期末结存 | K48: 应结转 | N48: 差异
B49: 数量 | C49: 单价 | D49: 金额 | E49: 数量 | F49: 单价 | G49: 金额 | H49: 数量 | I49: 单价 | J49: 金额 | K49: 单价 | L49: 金额 | M49: 结余 | N49: M=K-F
A50: 年初数 | B50: A | C50: B | D50: C | E50: D | F50: E | G50: F | I50: =IF(ISERROR(J50/H50),0,J50/H50) -> 0 | K50: J | L50: K | M50: =J50 -> 0 | N50: M
A64: 合计 | B64: =SUM(B50:B63) -> 0 | C64: =IF(ISERROR(D64/B64),0,D64/B64) -> 0 | D64: =SUM(D50:D63) -> 0 | E64: =SUM(E50:E63) -> 0 | F64: =IF(ISERROR(G64/E64),0,G64/E64) -> 0 | G64: =SUM(G60:G63) -> 0 | H64: =H63 -> 0 | I64: =IF(ISERROR(J64/H64),0,J64/H64) -> 0 | J64: =J63 -> 0 | L64: =SUM(L52:L63) -> 0 | M64: =M63 -> 0 | N64: =SUM(N52:N63) -> 0
A65: 四、审计说明：
A68: 五、审计结论：
A71: 提示：
A72: 企业应当采用先进先出法、加权平均法或者个别计价法确定发出存货的实际成本。
A73: 对于性质和用途相似的存货，应当采用相同的成本计算方法确定发出存货的成本。
A74: 对于不能替代使用的存货、为特定项目专门购入或制造的存货以及提供劳务的成本，通常采用个别计价法确定发出存货的成本。
A75: 对于已售存货，应当将其成本结转为当期损益，相应的存货跌价准备也应当予以结转。

Sheet 计价方法测试表-标准成本差异F2-40
A1: 致同会计师事务所
A2: 标准成本差异测试表
A3: =底稿目录!A2 -> 被审计单位： | G3: =底稿目录!A4 -> 编制人： | J3: =底稿目录!A5 -> 编制日期： | N3: 索引号： | O3: =底稿目录!F5 -> F2-40
A4: =底稿目录!A3 -> 截止日：202X年12月31日 | G4: =底稿目录!A6 -> 复核人： | J4: =底稿目录!A7 -> 复核日期： | N4: 页 次：
A5: 一、测试目标：
A6: 存货以恰当的金额包括在财务报表中，与之相关的计价或分摊调整已恰当记录，相关披露已得到恰当计量和描述
A7: 二、样本选取标准与规模：
A9: 三、测试：
A10: 测试项目1： | D10: 品名：
A11: 月份 | B11: 本期生产（或购入） | F11: 本期销售（或发出）应结转 | I11: 期末应结存 | L11: 期末实际结存 | O11: 差异
B12: 数量 | C12: 标准单价 | D12: 标准成本 | E12: 标准成本差异 | F12: 数量 | G12: 标准成本 | H12: 标准成本差异 | I12: 数量 | J12: 标准成本 | K12: 标准成本差异 | L12: 数量 | M12: 标准成本 | N12: 标准成本差异
A13: 年初数 | D13: =B13*C13 -> 0 | I13: =B13 -> 0 | J13: =D13 -> 0 | K13: =E13 -> 0 | O13: =N13-K13 -> 0
A14: 1月 | D14: =B14*C14 -> 0 | G14: =F14*C14 -> 0 | H14: =(IF(ISERROR((K13+E14)/(I13+B14)),0,(K13+E14)/(I13+B14)))*G14 -> 0 | I14: =I13+B14-F14 -> 0 | J14: =J13+D14-G14 -> 0 | K14: =K13+E14-H14 -> 0 | O14: =N14-K14 -> 0
A15: 2月 | D15: =B15*C15 -> 0 | G15: =F15*C15 -> 0 | H15: =(IF(ISERROR((K14+E15)/(I14+B15)),0,(K14+E15)/(I14+B15)))*G15 -> 0 | I15: =I14+B15-F15 -> 0 | J15: =J14+D15-G15 -> 0 | K15: =K14+E15-H15 -> 0 | O15: =N15-K15 -> 0
A16: 3月 | D16: =B16*C16 -> 0 | G16: =F16*C16 -> 0 | H16: =(IF(ISERROR((K15+E16)/(I15+B16)),0,(K15+E16)/(I15+B16)))*G16 -> 0 | I16: =I15+B16-F16 -> 0 | J16: =J15+D16-G16 -> 0 | K16: =K15+E16-H16 -> 0 | O16: =N16-K16 -> 0
A17: 4月 | D17: =B17*C17 -> 0 | G17: =F17*C17 -> 0 | H17: =(IF(ISERROR((K16+E17)/(I16+B17)),0,(K16+E17)/(I16+B17)))*G17 -> 0 | I17: =I16+B17-F17 -> 0 | J17: =J16+D17-G17 -> 0 | K17: =K16+E17-H17 -> 0 | O17: =N17-K17 -> 0
A18: 5月 | D18: =B18*C18 -> 0 | G18: =F18*C18 -> 0 | H18: =(IF(ISERROR((K17+E18)/(I17+B18)),0,(K17+E18)/(I17+B18)))*G18 -> 0 | I18: =I17+B18-F18 -> 0 | J18: =J17+D18-G18 -> 0 | K18: =K17+E18-H18 -> 0 | O18: =N18-K18 -> 0
A19: 6月 | D19: =B19*C19 -> 0 | G19: =F19*C19 -> 0 | H19: =(IF(ISERROR((K18+E19)/(I18+B19)),0,(K18+E19)/(I18+B19)))*G19 -> 0 | I19: =I18+B19-F19 -> 0 | J19: =J18+D19-G19 -> 0 | K19: =K18+E19-H19 -> 0 | O19: =N19-K19 -> 0
A20: 7月 | D20: =B20*C20 -> 0 | G20: =F20*C20 -> 0 | H20: =(IF(ISERROR((K19+E20)/(I19+B20)),0,(K19+E20)/(I19+B20)))*G20 -> 0 | I20: =I19+B20-F20 -> 0 | J20: =J19+D20-G20 -> 0 | K20: =K19+E20-H20 -> 0 | O20: =N20-K20 -> 0
A21: 8月 | D21: =B21*C21 -> 0 | G21: =F21*C21 -> 0 | H21: =(IF(ISERROR((K20+E21)/(I20+B21)),0,(K20+E21)/(I20+B21)))*G21 -> 0 | I21: =I20+B21-F21 -> 0 | J21: =J20+D21-G21 -> 0 | K21: =K20+E21-H21 -> 0 | O21: =N21-K21 -> 0
A22: 9月 | D22: =B22*C22 -> 0 | G22: =F22*C22 -> 0 | H22: =(IF(ISERROR((K21+E22)/(I21+B22)),0,(K21+E22)/(I21+B22)))*G22 -> 0 | I22: =I21+B22-F22 -> 0 | J22: =J21+D22-G22 -> 0 | K22: =K21+E22-H22 -> 0 | O22: =N22-K22 -> 0
A23: 10月 | D23: =B23*C23 -> 0 | G23: =F23*C23 -> 0 | H23: =(IF(ISERROR((K22+E23)/(I22+B23)),0,(K22+E23)/(I22+B23)))*G23 -> 0 | I23: =I22+B23-F23 -> 0 | J23: =J22+D23-G23 -> 0 | K23: =K22+E23-H23 -> 0 | O23: =N23-K23 -> 0
A24: 11月 | D24: =B24*C24 -> 0 | G24: =F24*C24 -> 0 | H24: =(IF(ISERROR((K23+E24)/(I23+B24)),0,(K23+E24)/(I23+B24)))*G24 -> 0 | I24: =I23+B24-F24 -> 0 | J24: =J23+D24-G24 -> 0 | K24: =K23+E24-H24 -> 0 | O24: =N24-K24 -> 0
A25: 12月 | D25: =B25*C25 -> 0 | G25: =F25*C25 -> 0 | H25: =(IF(ISERROR((K24+E25)/(I24+B25)),0,(K24+E25)/(I24+B25)))*G25 -> 0 | I25: =I24+B25-F25 -> 0 | J25: =J24+D25-G25 -> 0 | K25: =K24+E25-H25 -> 0 | O25: =N25-K25 -> 0
A26: 测试项目2： | D26: 品名：
A27: 月份 | B27: 本期生产（或购入） | F27: 本期销售（或发出）应结转 | I27: 期末应结存 | L27: 期末实际结存 | O27: 差异
B28: 数量 | C28: 标准单价 | D28: 标准成本 | E28: 标准成本差异 | F28: 数量 | G28: 标准成本 | H28: 标准成本差异 | I28: 数量 | J28: 标准成本 | K28: 标准成本差异 | L28: 数量 | M28: 标准成本 | N28: 标准成本差异
A29: 年初数 | D29: =B29*C29 -> 0 | I29: =B29 -> 0 | J29: =D29 -> 0 | K29: =E29 -> 0 | O29: =N29-K29 -> 0
A30: 1月 | D30: =B30*C30 -> 0 | G30: =F30*C30 -> 0 | H30: =(IF(ISERROR((K29+E30)/(I29+B30)),0,(K29+E30)/(I29+B30)))*G30 -> 0 | I30: =I29+B30-F30 -> 0 | J30: =J29+D30-G30 -> 0 | K30: =K29+E30-H30 -> 0 | O30: =N30-K30 -> 0
A31: 2月 | D31: =B31*C31 -> 0 | G31: =F31*C31 -> 0 | H31: =(IF(ISERROR((K30+E31)/(I30+B31)),0,(K30+E31)/(I30+B31)))*G31 -> 0 | I31: =I30+B31-F31 -> 0 | J31: =J30+D31-G31 -> 0 | K31: =K30+E31-H31 -> 0 | O31: =N31-K31 -> 0
A32: 3月 | D32: =B32*C32 -> 0 | G32: =F32*C32 -> 0 | H32: =(IF(ISERROR((K31+E32)/(I31+B32)),0,(K31+E32)/(I31+B32)))*G32 -> 0 | I32: =I31+B32-F32 -> 0 | J32: =J31+D32-G32 -> 0 | K32: =K31+E32-H32 -> 0 | O32: =N32-K32 -> 0
A33: 4月 | D33: =B33*C33 -> 0 | G33: =F33*C33 -> 0 | H33: =(IF(ISERROR((K32+E33)/(I32+B33)),0,(K32+E33)/(I32+B33)))*G33 -> 0 | I33: =I32+B33-F33 -> 0 | J33: =J32+D33-G33 -> 0 | K33: =K32+E33-H33 -> 0 | O33: =N33-K33 -> 0
A34: 5月 | D34: =B34*C34 -> 0 | G34: =F34*C34 -> 0 | H34: =(IF(ISERROR((K33+E34)/(I33+B34)),0,(K33+E34)/(I33+B34)))*G34 -> 0 | I34: =I33+B34-F34 -> 0 | J34: =J33+D34-G34 -> 0 | K34: =K33+E34-H34 -> 0 | O34: =N34-K34 -> 0
A35: 6月 | D35: =B35*C35 -> 0 | G35: =F35*C35 -> 0 | H35: =(IF(ISERROR((K34+E35)/(I34+B35)),0,(K34+E35)/(I34+B35)))*G35 -> 0 | I35: =I34+B35-F35 -> 0 | J35: =J34+D35-G35 -> 0 | K35: =K34+E35-H35 -> 0 | O35: =N35-K35 -> 0
A36: 7月 | D36: =B36*C36 -> 0 | G36: =F36*C36 -> 0 | H36: =(IF(ISERROR((K35+E36)/(I35+B36)),0,(K35+E36)/(I35+B36)))*G36 -> 0 | I36: =I35+B36-F36 -> 0 | J36: =J35+D36-G36 -> 0 | K36: =K35+E36-H36 -> 0 | O36: =N36-K36 -> 0
A37: 8月 | D37: =B37*C37 -> 0 | G37: =F37*C37 -> 0 | H37: =(IF(ISERROR((K36+E37)/(I36+B37)),0,(K36+E37)/(I36+B37)))*G37 -> 0 | I37: =I36+B37-F37 -> 0 | J37: =J36+D37-G37 -> 0 | K37: =K36+E37-H37 -> 0 | O37: =N37-K37 -> 0
A38: 9月 | D38: =B38*C38 -> 0 | G38: =F38*C38 -> 0 | H38: =(IF(ISERROR((K37+E38)/(I37+B38)),0,(K37+E38)/(I37+B38)))*G38 -> 0 | I38: =I37+B38-F38 -> 0 | J38: =J37+D38-G38 -> 0 | K38: =K37+E38-H38 -> 0 | O38: =N38-K38 -> 0
A39: 10月 | D39: =B39*C39 -> 0 | G39: =F39*C39 -> 0 | H39: =(IF(ISERROR((K38+E39)/(I38+B39)),0,(K38+E39)/(I38+B39)))*G39 -> 0 | I39: =I38+B39-F39 -> 0 | J39: =J38+D39-G39 -> 0 | K39: =K38+E39-H39 -> 0 | O39: =N39-K39 -> 0
A40: 11月 | D40: =B40*C40 -> 0 | G40: =F40*C40 -> 0 | H40: =(IF(ISERROR((K39+E40)/(I39+B40)),0,(K39+E40)/(I39+B40)))*G40 -> 0 | I40: =I39+B40-F40 -> 0 | J40: =J39+D40-G40 -> 0 | K40: =K39+E40-H40 -> 0 | O40: =N40-K40 -> 0
A41: 12月 | D41: =B41*C41 -> 0 | G41: =F41*C41 -> 0 | H41: =(IF(ISERROR((K40+E41)/(I40+B41)),0,(K40+E41)/(I40+B41)))*G41 -> 0 | I41: =I40+B41-F41 -> 0 | J41: =J40+D41-G41 -> 0 | K41: =K40+E41-H41 -> 0 | O41: =N41-K41 -> 0
...

Sheet 生产成本明细表F2-41
A1: 致同会计师事务所
A2: 生产成本明细表
A3: =底稿目录!A2 -> 被审计单位： | G3: =底稿目录!A4 -> 编制人： | K3: =底稿目录!A5 -> 编制日期： | P3: 索引号： | Q3: =底稿目录!F6 -> F2-41
A4: =底稿目录!A3 -> 截止日：202X年12月31日 | G4: =底稿目录!A6 -> 复核人： | K4: =底稿目录!A7 -> 复核日期： | P4: 页 次：
A5: 月份 项目 | B5: 1月 | C5: 2月 | D5: 3月 | E5: 4月 | F5: 5月 | G5: 6月 | H5: 7月 | I5: 8月 | J5: 9月 | K5: 10月 | L5: 11月 | M5: 12月 | N5: 合计 | O5: 上年度 | P5: 变动率 | Q5: 变动原因
A6: 期初余额 | N6: =SUM(B6:M6) -> 0
A7: 本期增加：
A8: 原材料 | N8: =SUM(B8:M8) -> 0 | P8: =(N8-O8)/O8 -> #DIV/0!
A9: 燃料动力 | N9: =SUM(B9:M9) -> 0 | P9: =(N9-O9)/O9 -> #DIV/0!
A10: 人工费用 | N10: =SUM(B10:M10) -> 0 | P10: =(N10-O10)/O10 -> #DIV/0!
A11: 制造费用 | N11: =SUM(B11:M11) -> 0 | P11: =(N11-O11)/O11 -> #DIV/0!
A12: 其他 | N12: =SUM(B12:M12) -> 0 | P12: =(N12-O12)/O12 -> #DIV/0!
A13: 增加合计 | B13: =SUM(B8:B12) -> 0 | C13: =SUM(C8:C12) -> 0 | D13: =SUM(D8:D12) -> 0 | E13: =SUM(E8:E12) -> 0 | F13: =SUM(F8:F12) -> 0 | G13: =SUM(G8:G12) -> 0 | H13: =SUM(H8:H12) -> 0 | I13: =SUM(I8:I12) -> 0 | ... M13: =SUM(M8:M12) -> 0 | N13: =SUM(B13:M13) -> 0 | P13: =(N13-O13)/O13 -> #DIV/0!
A14: 本期结转产成品 | N14: =SUM(B14:M14) -> 0 | P14: =(N14-O14)/O14 -> #DIV/0!
A15: 本期结转半成本
A16: 月末余额 | B16: =B6+B13-B14-B15 -> 0 | C16: =C6+C13-C14-C15 -> 0 | D16: =D6+D13-D14-D15 -> 0 | E16: =E6+E13-E14-E15 -> 0 | F16: =F6+F13-F14-F15 -> 0 | G16: =G6+G13-G14-G15 -> 0 | H16: =H6+H13-H14-H15 -> 0 | I16: =I6+I13-I14-I15 -> 0 | ... N16: =N6+N13-N14-N15 -> 0 | P16: =(N16-O16)/O16 -> #DIV/0!
A17: 三、审计说明：
A21: 四、审计结论：
A24: 提示：
A25: 1.关注存货成本是否包含了应费用化的项目（如停工损失等非正常消耗的直接材料、直接人工和制造费用，完工后的仓储费用，与销售相关的运输费，超范围、超期的借款费用资本化，不能归属于使存货达到目前场所和状态的其他支出）
A26: 2.将直接材料与材料耗用汇总表、直接工资总额与工资分配表、制造费用总额与制造费用明细表及相关账项明细表核对一致，并作交叉索引
A27: 3.检查生产成本在完工产品与在产品间分配是否正确（包括评价被审计单位确定在产品完工程度的方法是否合理），分配标准和计算方法是否有重大变化，是否合理和适当。

Sheet 产品年度成本比较G2-8-4-移至分析类
A1: 致同会计师事务所
A2: 产成品单位成本年度比较表
A3: =底稿目录!A2 -> 被审计单位： | F3: =底稿目录!A4 -> 编制人： | L3: =底稿目录!A5 -> 编制日期： | Q3: 索引号： | R3: G2-8-4
A4: =底稿目录!A3 -> 截止日：202X年12月31日 | F4: =底稿目录!A6 -> 复核人： | L4: =底稿目录!A7 -> 复核日期： | Q4: 页次：
A5: 产成品名称 | B5: 本年单位成本 | G5: 上年单位成本 | L5: 波动比例 | Q5: 是否存在异常波动 | R5: 进一步审验底稿索引
B6: 直接材料 | C6: 直接人工 | D6: 制造费用 | F6: 合计 | G6: 直接材料 | H6: 直接人工 | I6: 制造费用 | K6: 合计 | L6: 直接材料 | M6: 直接人工 | N6: 制造费用 | P6: 合计
A7: 啊啊啊啊 | B7: 1 | C7: 2 | D7: 3 | E7: 4 | F7: =SUM(B7:E7) -> 10 | G7: 4 | H7: 5 | I7: 6 | J7: 8 | K7: =SUM(G7:J7) -> 23 | L7: =IF(G7=0,0,(B7-G7)/G7) -> -0.75 | M7: =IF(H7=0,0,(C7-H7)/H7) -> -0.6 | N7: =IF(I7=0,0,(D7-I7)/I7) -> -0.5 | O7: =IF(J7=0,0,(E7-J7)/J7) -> -0.5 | P7: =IF(K7=0,0,(F7-K7)/K7) -> -0.56521739 | Q7: 是 | R7: 123
F8: =SUM(B8:E8) -> 0 | K8: =SUM(G8:J8) -> 0 | L8: =IF(G8=0,0,(B8-G8)/G8) -> 0 | M8: =IF(H8=0,0,(C8-H8)/H8) -> 0 | N8: =IF(I8=0,0,(D8-I8)/I8) -> 0 | O8: =IF(J8=0,0,(E8-J8)/J8) -> 0 | P8: =IF(K8=0,0,(F8-K8)/K8) -> 0
F9: =SUM(B9:E9) -> 0 | K9: =SUM(G9:J9) -> 0 | L9: =IF(G9=0,0,(B9-G9)/G9) -> 0 | M9: =IF(H9=0,0,(C9-H9)/H9) -> 0 | N9: =IF(I9=0,0,(D9-I9)/I9) -> 0 | O9: =IF(J9=0,0,(E9-J9)/J9) -> 0 | P9: =IF(K9=0,0,(F9-K9)/K9) -> 0
F10: =SUM(B10:E10) -> 0 | K10: =SUM(G10:J10) -> 0 | L10: =IF(G10=0,0,(B10-G10)/G10) -> 0 | M10: =IF(H10=0,0,(C10-H10)/H10) -> 0 | N10: =IF(I10=0,0,(D10-I10)/I10) -> 0 | O10: =IF(J10=0,0,(E10-J10)/J10) -> 0 | P10: =IF(K10=0,0,(F10-K10)/K10) -> 0
F11: =SUM(B11:E11) -> 0 | K11: =SUM(G11:J11) -> 0 | L11: =IF(G11=0,0,(B11-G11)/G11) -> 0 | M11: =IF(H11=0,0,(C11-H11)/H11) -> 0 | N11: =IF(I11=0,0,(D11-I11)/I11) -> 0 | O11: =IF(J11=0,0,(E11-J11)/J11) -> 0 | P11: =IF(K11=0,0,(F11-K11)/K11) -> 0
F12: =SUM(B12:E12) -> 0 | K12: =SUM(G12:J12) -> 0 | L12: =IF(G12=0,0,(B12-G12)/G12) -> 0 | M12: =IF(H12=0,0,(C12-H12)/H12) -> 0 | N12: =IF(I12=0,0,(D12-I12)/I12) -> 0 | O12: =IF(J12=0,0,(E12-J12)/J12) -> 0 | P12: =IF(K12=0,0,(F12-K12)/K12) -> 0
F13: =SUM(B13:E13) -> 0 | K13: =SUM(G13:J13) -> 0 | L13: =IF(G13=0,0,(B13-G13)/G13) -> 0 | M13: =IF(H13=0,0,(C13-H13)/H13) -> 0 | N13: =IF(I13=0,0,(D13-I13)/I13) -> 0 | O13: =IF(J13=0,0,(E13-J13)/J13) -> 0 | P13: =IF(K13=0,0,(F13-K13)/K13) -> 0
F14: =SUM(B14:E14) -> 0 | K14: =SUM(G14:J14) -> 0 | L14: =IF(G14=0,0,(B14-G14)/G14) -> 0 | M14: =IF(H14=0,0,(C14-H14)/H14) -> 0 | N14: =IF(I14=0,0,(D14-I14)/I14) -> 0 | O14: =IF(J14=0,0,(E14-J14)/J14) -> 0 | P14: =IF(K14=0,0,(F14-K14)/K14) -> 0
F15: =SUM(B15:E15) -> 0 | K15: =SUM(G15:J15) -> 0 | L15: =IF(G15=0,0,(B15-G15)/G15) -> 0 | M15: =IF(H15=0,0,(C15-H15)/H15) -> 0 | N15: =IF(I15=0,0,(D15-I15)/I15) -> 0 | O15: =IF(J15=0,0,(E15-J15)/J15) -> 0 | P15: =IF(K15=0,0,(F15-K15)/K15) -> 0
F16: =SUM(B16:E16) -> 0 | K16: =SUM(G16:J16) -> 0 | L16: =IF(G16=0,0,(B16-G16)/G16) -> 0 | M16: =IF(H16=0,0,(C16-H16)/H16) -> 0 | N16: =IF(I16=0,0,(D16-I16)/I16) -> 0 | O16: =IF(J16=0,0,(E16-J16)/J16) -> 0 | P16: =IF(K16=0,0,(F16-K16)/K16) -> 0
F17: =SUM(B17:E17) -> 0 | K17: =SUM(G17:J17) -> 0 | L17: =IF(G17=0,0,(B17-G17)/G17) -> 0 | M17: =IF(H17=0,0,(C17-H17)/H17) -> 0 | N17: =IF(I17=0,0,(D17-I17)/I17) -> 0 | O17: =IF(J17=0,0,(E17-J17)/J17) -> 0 | P17: =IF(K17=0,0,(F17-K17)/K17) -> 0
F18: =SUM(B18:E18) -> 0 | K18: =SUM(G18:J18) -> 0 | L18: =IF(G18=0,0,(B18-G18)/G18) -> 0 | M18: =IF(H18=0,0,(C18-H18)/H18) -> 0 | N18: =IF(I18=0,0,(D18-I18)/I18) -> 0 | O18: =IF(J18=0,0,(E18-J18)/J18) -> 0 | P18: =IF(K18=0,0,(F18-K18)/K18) -> 0
F19: =SUM(B19:E19) -> 0 | K19: =SUM(G19:J19) -> 0 | L19: =IF(G19=0,0,(B19-G19)/G19) -> 0 | M19: =IF(H19=0,0,(C19-H19)/H19) -> 0 | N19: =IF(I19=0,0,(D19-I19)/I19) -> 0 | O19: =IF(J19=0,0,(E19-J19)/J19) -> 0 | P19: =IF(K19=0,0,(F19-K19)/K19) -> 0
F20: =SUM(B20:E20) -> 0 | K20: =SUM(G20:J20) -> 0 | L20: =IF(G20=0,0,(B20-G20)/G20) -> 0 | M20: =IF(H20=0,0,(C20-H20)/H20) -> 0 | N20: =IF(I20=0,0,(D20-I20)/I20) -> 0 | O20: =IF(J20=0,0,(E20-J20)/J20) -> 0 | P20: =IF(K20=0,0,(F20-K20)/K20) -> 0
A22: 审计说明：
A26: 审计结论：

Sheet 直接人工分析表F2-42
A1: 致同会计师事务所
A2: 直接人工分析表
A3: =底稿目录!A2 -> 被审计单位： | F3: =底稿目录!A4 -> 编制人： | K3: =底稿目录!A5 -> 编制日期： | O3: 索引号： | P3: =底稿目录!F7 -> F2-42
A4: =底稿目录!A3 -> 截止日：202X年12月31日 | F4: =底稿目录!A6 -> 复核人： | K4: =底稿目录!A7 -> 复核日期： | O4: 页 次：
A5: 一、审计目标：
A6: 存货以恰当的金额包括在财务报表中，与之相关的计价或分摊调整已恰当记录，相关披露已得到恰当计量和描述
A7: 二、审计过程：
A8: 分析计入在产品和产成品中的直接人工成本、产量或工时和单位人工成本，关注否异常变化、各月之间波动及与上年度比较有无异常
A9: 各月发生的直接人工
A10: 产品 | B10: 1月 | C10: 2月 | D10: 3月 | E10: 4月 | F10: 5月 | G10: 6月 | H10: 7月 | I10: 8月 | J10: 9月 | K10: 10月 | L10: 11月 | M10: 12月 | N10: 合计 | O10: 上年度 | P10: 变动率
N11: =SUM(B11:M11) -> 0 | P11: =IF(AND(O11=0,N11-O11=0),0,IF(AND(O11=0,N11-O11>0),1,(N11-O11)/O11)) -> 0
N12: =SUM(B12:M12) -> 0 | P12: =IF(AND(O12=0,N12-O12=0),0,IF(AND(O12=0,N12-O12>0),1,(N12-O12)/O12)) -> 0
N13: =SUM(B13:M13) -> 0 | P13: =IF(AND(O13=0,N13-O13=0),0,IF(AND(O13=0,N13-O13>0),1,(N13-O13)/O13)) -> 0
N14: =SUM(B14:M14) -> 0 | P14: =IF(AND(O14=0,N14-O14=0),0,IF(AND(O14=0,N14-O14>0),1,(N14-O14)/O14)) -> 0
N15: =SUM(B15:M15) -> 0 | P15: =IF(AND(O15=0,N15-O15=0),0,IF(AND(O15=0,N15-O15>0),1,(N15-O15)/O15)) -> 0
N16: =SUM(B16:M16) -> 0 | P16: =IF(AND(O16=0,N16-O16=0),0,IF(AND(O16=0,N16-O16>0),1,(N16-O16)/O16)) -> 0
N17: =SUM(B17:M17) -> 0 | P17: =IF(AND(O17=0,N17-O17=0),0,IF(AND(O17=0,N17-O17>0),1,(N17-O17)/O17)) -> 0
N18: =SUM(B18:M18) -> 0 | P18: =IF(AND(O18=0,N18-O18=0),0,IF(AND(O18=0,N18-O18>0),1,(N18-O18)/O18)) -> 0
N19: =SUM(B19:M19) -> 0 | P19: =IF(AND(O19=0,N19-O19=0),0,IF(AND(O19=0,N19-O19>0),1,(N19-O19)/O19)) -> 0
A20: 各月产量/工时
A21: 产品 | B21: 1月 | C21: 2月 | D21: 3月 | E21: 4月 | F21: 5月 | G21: 6月 | H21: 7月 | I21: 8月 | J21: 9月 | K21: 10月 | L21: 11月 | M21: 12月 | N21: 合计 | O21: 上年度 | P21: 变动率
N22: =SUM(B22:M22) -> 0 | P22: =IF(AND(O22=0,N22-O22=0),0,IF(AND(O22=0,N22-O22>0),1,(N22-O22)/O22)) -> 0
N23: =SUM(B23:M23) -> 0 | P23: =IF(AND(O23=0,N23-O23=0),0,IF(AND(O23=0,N23-O23>0),1,(N23-O23)/O23)) -> 0
N24: =SUM(B24:M24) -> 0 | P24: =IF(AND(O24=0,N24-O24=0),0,IF(AND(O24=0,N24-O24>0),1,(N24-O24)/O24)) -> 0
N25: =SUM(B25:M25) -> 0 | P25: =IF(AND(O25=0,N25-O25=0),0,IF(AND(O25=0,N25-O25>0),1,(N25-O25)/O25)) -> 0
N26: =SUM(B26:M26) -> 0 | P26: =IF(AND(O26=0,N26-O26=0),0,IF(AND(O26=0,N26-O26>0),1,(N26-O26)/O26)) -> 0
N27: =SUM(B27:M27) -> 0 | P27: =IF(AND(O27=0,N27-O27=0),0,IF(AND(O27=0,N27-O27>0),1,(N27-O27)/O27)) -> 0
N28: =SUM(B28:M28) -> 0 | P28: =IF(AND(O28=0,N28-O28=0),0,IF(AND(O28=0,N28-O28>0),1,(N28-O28)/O28)) -> 0
N29: =SUM(B29:M29) -> 0 | P29: =IF(AND(O29=0,N29-O29=0),0,IF(AND(O29=0,N29-O29>0),1,(N29-O29)/O29)) -> 0
N30: =SUM(B30:M30) -> 0 | P30: =IF(AND(O30=0,N30-O30=0),0,IF(AND(O30=0,N30-O30>0),1,(N30-O30)/O30)) -> 0
A31: 单位人工成本（各月发生的直接人工/生产产量或工时）
A32: 产品 | B32: 1月 | C32: 2月 | D32: 3月 | E32: 4月 | F32: 5月 | G32: 6月 | H32: 7月 | I32: 8月 | J32: 9月 | K32: 10月 | L32: 11月 | M32: 12月 | N32: 平均值 | O32: 上年度 | P32: 变动率
B33: =IF(B22=0,0,B11/B22) -> 0 | C33: =IF(C22=0,0,C11/C22) -> 0 | D33: =IF(D22=0,0,D11/D22) -> 0 | E33: =IF(E22=0,0,E11/E22) -> 0 | F33: =IF(F22=0,0,F11/F22) -> 0 | G33: =IF(G22=0,0,G11/G22) -> 0 | H33: =IF(H22=0,0,H11/H22) -> 0 | I33: =IF(I22=0,0,I11/I22) -> 0 | ... N33: =IF(N22=0,0,N11/N22) -> 0 | O33: 2 | P33: =IF(AND(O33=0,N33-O33=0),0,IF(AND(O33=0,N33-O33>0),1,(N33-O33)/O33)) -> -1 | Q33: 对变动异常的产品应进一步执行舞弊应对程序中的产品生产成本及单耗分析
B34: =IF(B23=0,0,B12/B23) -> 0 | C34: =IF(C23=0,0,C12/C23) -> 0 | D34: =IF(D23=0,0,D12/D23) -> 0 | E34: =IF(E23=0,0,E12/E23) -> 0 | F34: =IF(F23=0,0,F12/F23) -> 0 | G34: =IF(G23=0,0,G12/G23) -> 0 | H34: =IF(H23=0,0,H12/H23) -> 0 | I34: =IF(I23=0,0,I12/I23) -> 0 | ... N34: =IF(N23=0,0,N12/N23) -> 0 | P34: =IF(AND(O34=0,N34-O34=0),0,IF(AND(O34=0,N34-O34>0),1,(N34-O34)/O34)) -> 0
B35: =IF(B24=0,0,B13/B24) -> 0 | C35: =IF(C24=0,0,C13/C24) -> 0 | D35: =IF(D24=0,0,D13/D24) -> 0 | E35: =IF(E24=0,0,E13/E24) -> 0 | F35: =IF(F24=0,0,F13/F24) -> 0 | G35: =IF(G24=0,0,G13/G24) -> 0 | H35: =IF(H24=0,0,H13/H24) -> 0 | I35: =IF(I24=0,0,I13/I24) -> 0 | ... N35: =IF(N24=0,0,N13/N24) -> 0 | P35: =IF(AND(O35=0,N35-O35=0),0,IF(AND(O35=0,N35-O35>0),1,(N35-O35)/O35)) -> 0
B36: =IF(B25=0,0,B14/B25) -> 0 | C36: =IF(C25=0,0,C14/C25) -> 0 | D36: =IF(D25=0,0,D14/D25) -> 0 | E36: =IF(E25=0,0,E14/E25) -> 0 | F36: =IF(F25=0,0,F14/F25) -> 0 | G36: =IF(G25=0,0,G14/G25) -> 0 | H36: =IF(H25=0,0,H14/H25) -> 0 | I36: =IF(I25=0,0,I14/I25) -> 0 | ... N36: =IF(N25=0,0,N14/N25) -> 0 | P36: =IF(AND(O36=0,N36-O36=0),0,IF(AND(O36=0,N36-O36>0),1,(N36-O36)/O36)) -> 0
B37: =IF(B26=0,0,B15/B26) -> 0 | C37: =IF(C26=0,0,C15/C26) -> 0 | D37: =IF(D26=0,0,D15/D26) -> 0 | E37: =IF(E26=0,0,E15/E26) -> 0 | F37: =IF(F26=0,0,F15/F26) -> 0 | G37: =IF(G26=0,0,G15/G26) -> 0 | H37: =IF(H26=0,0,H15/H26) -> 0 | I37: =IF(I26=0,0,I15/I26) -> 0 | ... N37: =IF(N26=0,0,N15/N26) -> 0 | P37: =IF(AND(O37=0,N37-O37=0),0,IF(AND(O37=0,N37-O37>0),1,(N37-O37)/O37)) -> 0
B38: =IF(B27=0,0,B16/B27) -> 0 | C38: =IF(C27=0,0,C16/C27) -> 0 | D38: =IF(D27=0,0,D16/D27) -> 0 | E38: =IF(E27=0,0,E16/E27) -> 0 | F38: =IF(F27=0,0,F16/F27) -> 0 | G38: =IF(G27=0,0,G16/G27) -> 0 | H38: =IF(H27=0,0,H16/H27) -> 0 | I38: =IF(I27=0,0,I16/I27) -> 0 | ... N38: =IF(N27=0,0,N16/N27) -> 0 | P38: =IF(AND(O38=0,N38-O38=0),0,IF(AND(O38=0,N38-O38>0),1,(N38-O38)/O38)) -> 0
B39: =IF(B28=0,0,B17/B28) -> 0 | C39: =IF(C28=0,0,C17/C28) -> 0 | D39: =IF(D28=0,0,D17/D28) -> 0 | E39: =IF(E28=0,0,E17/E28) -> 0 | F39: =IF(F28=0,0,F17/F28) -> 0 | G39: =IF(G28=0,0,G17/G28) -> 0 | H39: =IF(H28=0,0,H17/H28) -> 0 | I39: =IF(I28=0,0,I17/I28) -> 0 | ... N39: =IF(N28=0,0,N17/N28) -> 0 | P39: =IF(AND(O39=0,N39-O39=0),0,IF(AND(O39=0,N39-O39>0),1,(N39-O39)/O39)) -> 0
B40: =IF(B29=0,0,B18/B29) -> 0 | C40: =IF(C29=0,0,C18/C29) -> 0 | D40: =IF(D29=0,0,D18/D29) -> 0 | E40: =IF(E29=0,0,E18/E29) -> 0 | F40: =IF(F29=0,0,F18/F29) -> 0 | G40: =IF(G29=0,0,G18/G29) -> 0 | H40: =IF(H29=0,0,H18/H29) -> 0 | I40: =IF(I29=0,0,I18/I29) -> 0 | ... N40: =IF(N29=0,0,N18/N29) -> 0 | P40: =IF(AND(O40=0,N40-O40=0),0,IF(AND(O40=0,N40-O40>0),1,(N40-O40)/O40)) -> 0
...

Sheet 制造费用明细表F2-43
A1: 致同会计师事务所
A2: 制造费用明细表
A3: =底稿目录!A2 -> 被审计单位： | F3: =底稿目录!A4 -> 编制人： | K3: =底稿目录!A5 -> 编制日期： | O3: 索引号： | P3: F2-43
A4: =底稿目录!A3 -> 截止日：202X年12月31日 | F4: =底稿目录!A6 -> 复核人： | K4: =底稿目录!A7 -> 复核日期： | O4: 页 次：
A5: 一、审计目标：
A6: 1.资产负债表中记录的存货是存在的，且已经记录在恰当的账户中
A7: 2.所有应记录的存货均已记录，所有应当包括在财务报表中的相关披露均已包括
A8: 3.存货以恰当的金额包括在财务报表中，与之相关的计价或分摊调整已恰当记录，相关披露已得到恰当计量和描述
A9: 二、审计过程：
A10: 取得本期各月及前期制造费用明细情况，将资产折旧与折旧分配表、资产摊销与各项资产摊销分配表等核对一致，关注制造费用分配方法是否合理、适当，本期各月与上期金额是否存在异常变动
A11: 月份 项目 | B11: 1月 | C11: 2月 | D11: 3月 | E11: 4月 | F11: 5月 | G11: 6月 | H11: 7月 | I11: 8月 | J11: 9月 | K11: 10月 | L11: 11月 | M11: 12月 | N11: 合计 | O11: 上年度 | P11: 变动率
A12: 工资 | N12: =SUM(B12:M12) -> 0 | P12: =(N12-O12)/O12 -> #DIV/0!
A13: 福利费 | N13: =SUM(B13:M13) -> 0 | P13: =(N13-O13)/O13 -> #DIV/0!
A14: 修理费 | N14: =SUM(B14:M14) -> 0 | P14: =(N14-O14)/O14 -> #DIV/0!
A15: 办公费 | N15: =SUM(B15:M15) -> 0 | P15: =(N15-O15)/O15 -> #DIV/0!
A16: 差旅费 | N16: =SUM(B16:M16) -> 0 | P16: =(N16-O16)/O16 -> #DIV/0!
A17: 运费 | N17: =SUM(B17:M17) -> 0 | P17: =(N17-O17)/O17 -> #DIV/0!
A18: 折旧费 | N18: =SUM(B18:M18) -> 0 | P18: =(N18-O18)/O18 -> #DIV/0!
A19: 劳动保护费 | N19: =SUM(B19:M19) -> 0 | P19: =(N19-O19)/O19 -> #DIV/0!
A20: 机物料消耗 | N20: =SUM(B20:M20) -> 0 | P20: =(N20-O20)/O20 -> #DIV/0!
A21: 低值易耗品摊销 | N21: =SUM(B21:M21) -> 0 | P21: =(N21-O21)/O21 -> #DIV/0!
A22: 水电费 | N22: =SUM(B22:M22) -> 0 | P22: =(N22-O22)/O22 -> #DIV/0!
A23: 租赁费 | N23: =SUM(B23:M23) -> 0 | P23: =(N23-O23)/O23 -> #DIV/0!
A24: 其他 | N24: =SUM(B24:M24) -> 0 | P24: =(N24-O24)/O24 -> #DIV/0!
A25: 合计 | B25: =SUM(B12:B24) -> 0 | C25: =SUM(C12:C24) -> 0 | D25: =SUM(D12:D24) -> 0 | E25: =SUM(E12:E24) -> 0 | F25: =SUM(F12:F24) -> 0 | G25: =SUM(G12:G24) -> 0 | H25: =SUM(H12:H24) -> 0 | I25: =SUM(I12:I24) -> 0 | ... M25: =SUM(M12:M24) -> 0 | N25: =SUM(B25:M25) -> 0 | O25: =SUM(O12:O24) -> 0 | P25: =(N25-O25)/O25 -> #DIV/0!
A26: 三、审计说明：
A29: 四、审计结论：
A32: 提示：
A33: 1.复核制造费用明细汇总表的正确性，将制造费用明细表中的材料发生额与材料耗用汇总表、工资发生额与工资分配表、折旧发生额与折旧分配表、资产摊销发生额与各项资产摊销分配表及相关账项明细表核对一致，并作交叉索引。
A34: 2.获取制造费用的分配标准和计算方法，评价有关分配标准和计算方法是否合理和适当，以确认在产品中所含直接人工和制造费用是合理的。必要时重新计算。
A35: 3.关注计入生产成本的制造费用是否已扣除非正常消耗的制造费用，如非正常的低生产量、闲置设备等产生的费用。
A36: 4.关注存货成本是否包含了应费用化的项目（如停工损失等非正常消耗的直接材料、直接人工和制造费用，完工后的仓储费用，与销售相关的运输费，超范围、超期的借款费用资本化，不能归属于使存货达到目前场所和状态的其他支出）

Sheet 生产成本分配F2-44
A1: 致同会计师事务所
A2: 抽查×月×车间生产成本分配表
A3: =底稿目录!A2 -> 被审计单位： | E3: =底稿目录!A4 -> 编制人： | I3: =底稿目录!A5 -> 编制日期： | M3: 索引号： | N3: =底稿目录!F9 -> F2-44
A4: =底稿目录!A3 -> 截止日：202X年12月31日 | E4: =底稿目录!A6 -> 复核人： | I4: =底稿目录!A7 -> 复核日期： | M4: 页 次：
A5: ×月×车间生产成本发生额： | C5: 直接材料：
C6: 直接人工：
C7: 制造费用：
C8: 其他
C9: 合计： | D9: =SUM(D5:D8) -> 0
A10: 产成品名称 | B10: 产量 | C10: 入库产品成本单价 | D10: 分配标准（产量、工时、定额成本等） | E10: 直接材料分配率 | F10: 直接材料分配额 | G10: 直接人工分配率 | H10: 直接人工分配额 | I10: 制造费用分配率 | J10: 制造费用分配额 | K10: 其他分配率 | L10: 其他分配额 | M10: 应计单位成本 | N10: 核对
E11: =IF($D$23=0,0,$D$5/$D$23) -> 0 | F11: =E11*D11 -> 0 | G11: =IF($D$23=0,0,$D$6/$D$23) -> 0 | H11: =G11*D11 -> 0 | I11: =IF($D$23=0,0,$D$7/$D$23) -> 0 | J11: =I11*D11 -> 0 | K11: =IF($D$23=0,0,$D$8/$D$23) -> 0 | L11: =K11*D11 -> 0 | M11: =IF(B11=0,0,SUM(F11,H11,J11,L11)/B11) -> 0 | N11: =IF(M11=C11,"OK",M11-C11) -> OK
E12: =IF($D$23=0,0,$D$5/$D$23) -> 0 | F12: =E12*D12 -> 0 | G12: =IF($D$23=0,0,$D$6/$D$23) -> 0 | H12: =G12*D12 -> 0 | I12: =IF($D$23=0,0,$D$7/$D$23) -> 0 | J12: =I12*D12 -> 0 | K12: =IF($D$23=0,0,$D$8/$D$23) -> 0 | L12: =K12*D12 -> 0 | M12: =IF(B12=0,0,SUM(F12,H12,J12,L12)/B12) -> 0 | N12: =IF(M12=C12,"OK",M12-C12) -> OK
E13: =IF($D$23=0,0,$D$5/$D$23) -> 0 | F13: =E13*D13 -> 0 | G13: =IF($D$23=0,0,$D$6/$D$23) -> 0 | H13: =G13*D13 -> 0 | I13: =IF($D$23=0,0,$D$7/$D$23) -> 0 | J13: =I13*D13 -> 0 | K13: =IF($D$23=0,0,$D$8/$D$23) -> 0 | L13: =K13*D13 -> 0 | M13: =IF(B13=0,0,SUM(F13,H13,J13,L13)/B13) -> 0 | N13: =IF(M13=C13,"OK",M13-C13) -> OK
E14: =IF($D$23=0,0,$D$5/$D$23) -> 0 | F14: =E14*D14 -> 0 | G14: =IF($D$23=0,0,$D$6/$D$23) -> 0 | H14: =G14*D14 -> 0 | I14: =IF($D$23=0,0,$D$7/$D$23) -> 0 | J14: =I14*D14 -> 0 | K14: =IF($D$23=0,0,$D$8/$D$23) -> 0 | L14: =K14*D14 -> 0 | M14: =IF(B14=0,0,SUM(F14,H14,J14,L14)/B14) -> 0 | N14: =IF(M14=C14,"OK",M14-C14) -> OK
E15: =IF($D$23=0,0,$D$5/$D$23) -> 0 | F15: =E15*D15 -> 0 | G15: =IF($D$23=0,0,$D$6/$D$23) -> 0 | H15: =G15*D15 -> 0 | I15: =IF($D$23=0,0,$D$7/$D$23) -> 0 | J15: =I15*D15 -> 0 | K15: =IF($D$23=0,0,$D$8/$D$23) -> 0 | L15: =K15*D15 -> 0 | M15: =IF(B15=0,0,SUM(F15,H15,J15,L15)/B15) -> 0 | N15: =IF(M15=C15,"OK",M15-C15) -> OK
E16: =IF($D$23=0,0,$D$5/$D$23) -> 0 | F16: =E16*D16 -> 0 | G16: =IF($D$23=0,0,$D$6/$D$23) -> 0 | H16: =G16*D16 -> 0 | I16: =IF($D$23=0,0,$D$7/$D$23) -> 0 | J16: =I16*D16 -> 0 | K16: =IF($D$23=0,0,$D$8/$D$23) -> 0 | L16: =K16*D16 -> 0 | M16: =IF(B16=0,0,SUM(F16,H16,J16,L16)/B16) -> 0 | N16: =IF(M16=C16,"OK",M16-C16) -> OK
E17: =IF($D$23=0,0,$D$5/$D$23) -> 0 | F17: =E17*D17 -> 0 | G17: =IF($D$23=0,0,$D$6/$D$23) -> 0 | H17: =G17*D17 -> 0 | I17: =IF($D$23=0,0,$D$7/$D$23) -> 0 | J17: =I17*D17 -> 0 | K17: =IF($D$23=0,0,$D$8/$D$23) -> 0 | L17: =K17*D17 -> 0 | M17: =IF(B17=0,0,SUM(F17,H17,J17,L17)/B17) -> 0 | N17: =IF(M17=C17,"OK",M17-C17) -> OK
E18: =IF($D$23=0,0,$D$5/$D$23) -> 0 | F18: =E18*D18 -> 0 | G18: =IF($D$23=0,0,$D$6/$D$23) -> 0 | H18: =G18*D18 -> 0 | I18: =IF($D$23=0,0,$D$7/$D$23) -> 0 | J18: =I18*D18 -> 0 | K18: =IF($D$23=0,0,$D$8/$D$23) -> 0 | L18: =K18*D18 -> 0 | M18: =IF(B18=0,0,SUM(F18,H18,J18,L18)/B18) -> 0 | N18: =IF(M18=C18,"OK",M18-C18) -> OK
E19: =IF($D$23=0,0,$D$5/$D$23) -> 0 | F19: =E19*D19 -> 0 | G19: =IF($D$23=0,0,$D$6/$D$23) -> 0 | H19: =G19*D19 -> 0 | I19: =IF($D$23=0,0,$D$7/$D$23) -> 0 | J19: =I19*D19 -> 0 | K19: =IF($D$23=0,0,$D$8/$D$23) -> 0 | L19: =K19*D19 -> 0 | M19: =IF(B19=0,0,SUM(F19,H19,J19,L19)/B19) -> 0 | N19: =IF(M19=C19,"OK",M19-C19) -> OK
E20: =IF($D$23=0,0,$D$5/$D$23) -> 0 | F20: =E20*D20 -> 0 | G20: =IF($D$23=0,0,$D$6/$D$23) -> 0 | H20: =G20*D20 -> 0 | I20: =IF($D$23=0,0,$D$7/$D$23) -> 0 | J20: =I20*D20 -> 0 | K20: =IF($D$23=0,0,$D$8/$D$23) -> 0 | L20: =K20*D20 -> 0 | M20: =IF(B20=0,0,SUM(F20,H20,J20,L20)/B20) -> 0 | N20: =IF(M20=C20,"OK",M20-C20) -> OK
E21: =IF($D$23=0,0,$D$5/$D$23) -> 0 | F21: =E21*D21 -> 0 | G21: =IF($D$23=0,0,$D$6/$D$23) -> 0 | H21: =G21*D21 -> 0 | I21: =IF($D$23=0,0,$D$7/$D$23) -> 0 | J21: =I21*D21 -> 0 | K21: =IF($D$23=0,0,$D$8/$D$23) -> 0 | L21: =K21*D21 -> 0 | M21: =IF(B21=0,0,SUM(F21,H21,J21,L21)/B21) -> 0 | N21: =IF(M21=C21,"OK",M21-C21) -> OK
E22: =IF($D$23=0,0,$D$5/$D$23) -> 0 | F22: =E22*D22 -> 0 | G22: =IF($D$23=0,0,$D$6/$D$23) -> 0 | H22: =G22*D22 -> 0 | I22: =IF($D$23=0,0,$D$7/$D$23) -> 0 | J22: =I22*D22 -> 0 | K22: =IF($D$23=0,0,$D$8/$D$23) -> 0 | L22: =K22*D22 -> 0 | M22: =IF(B22=0,0,SUM(F22,H22,J22,L22)/B22) -> 0 | N22: =IF(M22=C22,"OK",M22-C22) -> OK
A23: 合计 | B23: =SUM(B11:B22) -> 0 | C23: =IF(COUNTA(C11:C22)=0,0,SUM(C11:C22)/COUNTA(C11:C22)) -> 0 | D23: =SUM(D11:D22) -> 0 | E23: =IF($D$23=0,0,$D$5/$D$23) -> 0 | F23: =SUM(F11:F22) -> 0 | G23: =IF($D$23=0,0,$D$6/$D$23) -> 0 | H23: =SUM(H11:H22) -> 0 | I23: =IF($D$23=0,0,$D$7/$D$23) -> 0 | J23: =SUM(J11:J22) -> 0 | K23: =IF($D$23=0,0,$D$8/$D$23) -> 0 | L23: =SUM(L11:L22) -> 0 | M23: ——
A24: 1、审计说明：
A27: 2、审计结论：

Sheet 产品月度成本比较G2-8-5（删除 在舞弊应对单耗分析中）
A1: 致同会计师事务所
A2: 完工产成品月度成本构成比较表
A3: =底稿目录!A2 -> 被审计单位： | H3: =底稿目录!A4 -> 编制人： | O3: =底稿目录!A5 -> 编制日期： | S3: 索引号： | T3: G2-8-5
A4: =底稿目录!A3 -> 截止日：202X年12月31日 | H4: =底稿目录!A6 -> 复核人： | O4: =底稿目录!A7 -> 复核日期： | S4: 页次：
A5: 品名1：
A6: 月份 | B6: 产量 | C6: 直接材料 | F6: 直接人工 | I6: 制造费用 | L6: …… | O6: …… | R6: 合计
C7: 金额 | D7: 单位成本 | E7: 波动比例(与平均成本比较) | F7: 金额 | G7: 单位成本 | H7: 波动比例(与平均成本比较) | I7: 金额 | J7: 单位成本 | K7: 波动比例(与平均成本比较) | L7: 金额 | M7: 单位成本 | N7: 波动比例(与平均成本比较) | O7: 金额 | P7: 单位成本 | Q7: 波动比例(与平均成本比较) | R7: 金额 | S7: 单位成本 | T7: 波动比例(与平均成本比较)
A8: 1 | D8: =IF($B8=0,0,$C8/$B8) -> 0 | E8: =IF($D$20=0,0,($D8-$D$20)/$D$20) -> 0 | G8: =IF($B8=0,0,$F8/$B8) -> 0 | H8: =IF($G$20=0,0,($G8-$G$20)/$G$20) -> 0 | J8: =IF($B8=0,0,$I8/$B8) -> 0 | K8: =IF($J$20=0,0,($J8-$J$20)/$J$20) -> 0 | M8: =IF($B8=0,0,$L8/$B8) -> 0 | N8: =IF($M$20=0,0,($M8-$M$20)/$M$20) -> 0 | P8: =IF($B8=0,0,$O8/$B8) -> 0 | Q8: =IF($P$20=0,0,($P8-$P$20)/$P$20) -> 0 | R8: =SUM(C8,F8,I8,L8,O8) -> 0 | S8: =IF($B8=0,0,$R8/$B8) -> 0 | T8: =IF($S$20=0,0,($S8-$S$20)/$S$20) -> 0
A9: 2 | D9: =IF($B9=0,0,$C9/$B9) -> 0 | E9: =IF($D$20=0,0,($D9-$D$20)/$D$20) -> 0 | G9: =IF($B9=0,0,$F9/$B9) -> 0 | H9: =IF($G$20=0,0,($G9-$G$20)/$G$20) -> 0 | J9: =IF($B9=0,0,$I9/$B9) -> 0 | K9: =IF($J$20=0,0,($J9-$J$20)/$J$20) -> 0 | M9: =IF($B9=0,0,$L9/$B9) -> 0 | N9: =IF($M$20=0,0,($M9-$M$20)/$M$20) -> 0 | P9: =IF($B9=0,0,$O9/$B9) -> 0 | Q9: =IF($P$20=0,0,($P9-$P$20)/$P$20) -> 0 | R9: =SUM(C9,F9,I9,L9,O9) -> 0 | S9: =IF($B9=0,0,$R9/$B9) -> 0 | T9: =IF($S$20=0,0,($S9-$S$20)/$S$20) -> 0
A10: 3 | D10: =IF($B10=0,0,$C10/$B10) -> 0 | E10: =IF($D$20=0,0,($D10-$D$20)/$D$20) -> 0 | G10: =IF($B10=0,0,$F10/$B10) -> 0 | H10: =IF($G$20=0,0,($G10-$G$20)/$G$20) -> 0 | J10: =IF($B10=0,0,$I10/$B10) -> 0 | K10: =IF($J$20=0,0,($J10-$J$20)/$J$20) -> 0 | M10: =IF($B10=0,0,$L10/$B10) -> 0 | N10: =IF($M$20=0,0,($M10-$M$20)/$M$20) -> 0 | P10: =IF($B10=0,0,$O10/$B10) -> 0 | Q10: =IF($P$20=0,0,($P10-$P$20)/$P$20) -> 0 | R10: =SUM(C10,F10,I10,L10,O10) -> 0 | S10: =IF($B10=0,0,$R10/$B10) -> 0 | T10: =IF($S$20=0,0,($S10-$S$20)/$S$20) -> 0
A11: 4 | D11: =IF($B11=0,0,$C11/$B11) -> 0 | E11: =IF($D$20=0,0,($D11-$D$20)/$D$20) -> 0 | G11: =IF($B11=0,0,$F11/$B11) -> 0 | H11: =IF($G$20=0,0,($G11-$G$20)/$G$20) -> 0 | J11: =IF($B11=0,0,$I11/$B11) -> 0 | K11: =IF($J$20=0,0,($J11-$J$20)/$J$20) -> 0 | M11: =IF($B11=0,0,$L11/$B11) -> 0 | N11: =IF($M$20=0,0,($M11-$M$20)/$M$20) -> 0 | P11: =IF($B11=0,0,$O11/$B11) -> 0 | Q11: =IF($P$20=0,0,($P11-$P$20)/$P$20) -> 0 | R11: =SUM(C11,F11,I11,L11,O11) -> 0 | S11: =IF($B11=0,0,$R11/$B11) -> 0 | T11: =IF($S$20=0,0,($S11-$S$20)/$S$20) -> 0
A12: 5 | D12: =IF($B12=0,0,$C12/$B12) -> 0 | E12: =IF($D$20=0,0,($D12-$D$20)/$D$20) -> 0 | G12: =IF($B12=0,0,$F12/$B12) -> 0 | H12: =IF($G$20=0,0,($G12-$G$20)/$G$20) -> 0 | J12: =IF($B12=0,0,$I12/$B12) -> 0 | K12: =IF($J$20=0,0,($J12-$J$20)/$J$20) -> 0 | M12: =IF($B12=0,0,$L12/$B12) -> 0 | N12: =IF($M$20=0,0,($M12-$M$20)/$M$20) -> 0 | P12: =IF($B12=0,0,$O12/$B12) -> 0 | Q12: =IF($P$20=0,0,($P12-$P$20)/$P$20) -> 0 | R12: =SUM(C12,F12,I12,L12,O12) -> 0 | S12: =IF($B12=0,0,$R12/$B12) -> 0 | T12: =IF($S$20=0,0,($S12-$S$20)/$S$20) -> 0
A13: 6 | D13: =IF($B13=0,0,$C13/$B13) -> 0 | E13: =IF($D$20=0,0,($D13-$D$20)/$D$20) -> 0 | G13: =IF($B13=0,0,$F13/$B13) -> 0 | H13: =IF($G$20=0,0,($G13-$G$20)/$G$20) -> 0 | J13: =IF($B13=0,0,$I13/$B13) -> 0 | K13: =IF($J$20=0,0,($J13-$J$20)/$J$20) -> 0 | M13: =IF($B13=0,0,$L13/$B13) -> 0 | N13: =IF($M$20=0,0,($M13-$M$20)/$M$20) -> 0 | P13: =IF($B13=0,0,$O13/$B13) -> 0 | Q13: =IF($P$20=0,0,($P13-$P$20)/$P$20) -> 0 | R13: =SUM(C13,F13,I13,L13,O13) -> 0 | S13: =IF($B13=0,0,$R13/$B13) -> 0 | T13: =IF($S$20=0,0,($S13-$S$20)/$S$20) -> 0
A14: 7 | D14: =IF($B14=0,0,$C14/$B14) -> 0 | E14: =IF($D$20=0,0,($D14-$D$20)/$D$20) -> 0 | G14: =IF($B14=0,0,$F14/$B14) -> 0 | H14: =IF($G$20=0,0,($G14-$G$20)/$G$20) -> 0 | J14: =IF($B14=0,0,$I14/$B14) -> 0 | K14: =IF($J$20=0,0,($J14-$J$20)/$J$20) -> 0 | M14: =IF($B14=0,0,$L14/$B14) -> 0 | N14: =IF($M$20=0,0,($M14-$M$20)/$M$20) -> 0 | P14: =IF($B14=0,0,$O14/$B14) -> 0 | Q14: =IF($P$20=0,0,($P14-$P$20)/$P$20) -> 0 | R14: =SUM(C14,F14,I14,L14,O14) -> 0 | S14: =IF($B14=0,0,$R14/$B14) -> 0 | T14: =IF($S$20=0,0,($S14-$S$20)/$S$20) -> 0
A15: 8 | D15: =IF($B15=0,0,$C15/$B15) -> 0 | E15: =IF($D$20=0,0,($D15-$D$20)/$D$20) -> 0 | G15: =IF($B15=0,0,$F15/$B15) -> 0 | H15: =IF($G$20=0,0,($G15-$G$20)/$G$20) -> 0 | J15: =IF($B15=0,0,$I15/$B15) -> 0 | K15: =IF($J$20=0,0,($J15-$J$20)/$J$20) -> 0 | M15: =IF($B15=0,0,$L15/$B15) -> 0 | N15: =IF($M$20=0,0,($M15-$M$20)/$M$20) -> 0 | P15: =IF($B15=0,0,$O15/$B15) -> 0 | Q15: =IF($P$20=0,0,($P15-$P$20)/$P$20) -> 0 | R15: =SUM(C15,F15,I15,L15,O15) -> 0 | S15: =IF($B15=0,0,$R15/$B15) -> 0 | T15: =IF($S$20=0,0,($S15-$S$20)/$S$20) -> 0
A16: 9 | D16: =IF($B16=0,0,$C16/$B16) -> 0 | E16: =IF($D$20=0,0,($D16-$D$20)/$D$20) -> 0 | G16: =IF($B16=0,0,$F16/$B16) -> 0 | H16: =IF($G$20=0,0,($G16-$G$20)/$G$20) -> 0 | J16: =IF($B16=0,0,$I16/$B16) -> 0 | K16: =IF($J$20=0,0,($J16-$J$20)/$J$20) -> 0 | M16: =IF($B16=0,0,$L16/$B16) -> 0 | N16: =IF($M$20=0,0,($M16-$M$20)/$M$20) -> 0 | P16: =IF($B16=0,0,$O16/$B16) -> 0 | Q16: =IF($P$20=0,0,($P16-$P$20)/$P$20) -> 0 | R16: =SUM(C16,F16,I16,L16,O16) -> 0 | S16: =IF($B16=0,0,$R16/$B16) -> 0 | T16: =IF($S$20=0,0,($S16-$S$20)/$S$20) -> 0
A17: 10 | D17: =IF($B17=0,0,$C17/$B17) -> 0 | E17: =IF($D$20=0,0,($D17-$D$20)/$D$20) -> 0 | G17: =IF($B17=0,0,$F17/$B17) -> 0 | H17: =IF($G$20=0,0,($G17-$G$20)/$G$20) -> 0 | J17: =IF($B17=0,0,$I17/$B17) -> 0 | K17: =IF($J$20=0,0,($J17-$J$20)/$J$20) -> 0 | M17: =IF($B17=0,0,$L17/$B17) -> 0 | N17: =IF($M$20=0,0,($M17-$M$20)/$M$20) -> 0 | P17: =IF($B17=0,0,$O17/$B17) -> 0 | Q17: =IF($P$20=0,0,($P17-$P$20)/$P$20) -> 0 | R17: =SUM(C17,F17,I17,L17,O17) -> 0 | S17: =IF($B17=0,0,$R17/$B17) -> 0 | T17: =IF($S$20=0,0,($S17-$S$20)/$S$20) -> 0
A18: 11 | D18: =IF($B18=0,0,$C18/$B18) -> 0 | E18: =IF($D$20=0,0,($D18-$D$20)/$D$20) -> 0 | G18: =IF($B18=0,0,$F18/$B18) -> 0 | H18: =IF($G$20=0,0,($G18-$G$20)/$G$20) -> 0 | J18: =IF($B18=0,0,$I18/$B18) -> 0 | K18: =IF($J$20=0,0,($J18-$J$20)/$J$20) -> 0 | M18: =IF($B18=0,0,$L18/$B18) -> 0 | N18: =IF($M$20=0,0,($M18-$M$20)/$M$20) -> 0 | P18: =IF($B18=0,0,$O18/$B18) -> 0 | Q18: =IF($P$20=0,0,($P18-$P$20)/$P$20) -> 0 | R18: =SUM(C18,F18,I18,L18,O18) -> 0 | S18: =IF($B18=0,0,$R18/$B18) -> 0 | T18: =IF($S$20=0,0,($S18-$S$20)/$S$20) -> 0
A19: 12 | D19: =IF($B19=0,0,$C19/$B19) -> 0 | E19: =IF($D$20=0,0,($D19-$D$20)/$D$20) -> 0 | G19: =IF($B19=0,0,$F19/$B19) -> 0 | H19: =IF($G$20=0,0,($G19-$G$20)/$G$20) -> 0 | J19: =IF($B19=0,0,$I19/$B19) -> 0 | K19: =IF($J$20=0,0,($J19-$J$20)/$J$20) -> 0 | M19: =IF($B19=0,0,$L19/$B19) -> 0 | N19: =IF($M$20=0,0,($M19-$M$20)/$M$20) -> 0 | P19: =IF($B19=0,0,$O19/$B19) -> 0 | Q19: =IF($P$20=0,0,($P19-$P$20)/$P$20) -> 0 | R19: =SUM(C19,F19,I19,L19,O19) -> 0 | S19: =IF($B19=0,0,$R19/$B19) -> 0 | T19: =IF($S$20=0,0,($S19-$S$20)/$S$20) -> 0
A20: 合计 | B20: =SUM(B8:B19) -> 0 | C20: =SUM(C8:C19) -> 0 | D20: =IF($B20=0,0,$C20/$B20) -> 0 | E20: —— | F20: =SUM(F8:F19) -> 0 | G20: =IF($B20=0,0,$F20/$B20) -> 0 | H20: —— | I20: =SUM(I8:I19) -> 0 | J20: =IF($B20=0,0,$I20/$B20) -> 0 | K20: —— | L20: =SUM(L8:L19) -> 0 | M20: =IF($B20=0,0,$L20/$B20) -> 0 | N20: —— | O20: =SUM(O8:O19) -> 0 | P20: =IF($B20=0,0,$O20/$B20) -> 0 | Q20: —— | R20: =SUM(R8:R19) -> 0 | S20: =IF($B20=0,0,$R20/$B20) -> 0 | T20: ——
A21: 品名2：
A22: 月份 | B22: 产量 | C22: 直接材料 | F22: 直接人工 | I22: 制造费用 | L22: …… | O22: …… | R22: 合计
C23: 金额 | D23: 单位成本 | E23: 波动比例(与平均成本比较) | F23: 金额 | G23: 单位成本 | H23: 波动比例(与平均成本比较) | I23: 金额 | J23: 单位成本 | K23: 波动比例(与平均成本比较) | L23: 金额 | M23: 单位成本 | N23: 波动比例(与平均成本比较) | O23: 金额 | P23: 单位成本 | Q23: 波动比例(与平均成本比较) | R23: 金额 | S23: 单位成本 | T23: 波动比例(与平均成本比较)
A24: 1 | D24: =IF($B24=0,0,$C24/$B24) -> 0 | E24: =IF($D$20=0,0,($D24-$D$20)/$D$20) -> 0 | G24: =IF($B24=0,0,$F24/$B24) -> 0 | H24: =IF($G$20=0,0,($G24-$G$20)/$G$20) -> 0 | J24: =IF($B24=0,0,$I24/$B24) -> 0 | K24: =IF($J$20=0,0,($J24-$J$20)/$J$20) -> 0 | M24: =IF($B24=0,0,$L24/$B24) -> 0 | N24: =IF($M$20=0,0,($M24-$M$20)/$M$20) -> 0 | P24: =IF($B24=0,0,$O24/$B24) -> 0 | Q24: =IF($P$20=0,0,($P24-$P$20)/$P$20) -> 0 | R24: =SUM(C24,F24,I24,L24,O24) -> 0 | S24: =IF($B24=0,0,$R24/$B24) -> 0 | T24: =IF($S$20=0,0,($S24-$S$20)/$S$20) -> 0
A25: 2 | D25: =IF($B25=0,0,$C25/$B25) -> 0 | E25: =IF($D$20=0,0,($D25-$D$20)/$D$20) -> 0 | G25: =IF($B25=0,0,$F25/$B25) -> 0 | H25: =IF($G$20=0,0,($G25-$G$20)/$G$20) -> 0 | J25: =IF($B25=0,0,$I25/$B25) -> 0 | K25: =IF($J$20=0,0,($J25-$J$20)/$J$20) -> 0 | M25: =IF($B25=0,0,$L25/$B25) -> 0 | N25: =IF($M$20=0,0,($M25-$M$20)/$M$20) -> 0 | P25: =IF($B25=0,0,$O25/$B25) -> 0 | Q25: =IF($P$20=0,0,($P25-$P$20)/$P$20) -> 0 | R25: =SUM(C25,F25,I25,L25,O25) -> 0 | S25: =IF($B25=0,0,$R25/$B25) -> 0 | T25: =IF($S$20=0,0,($S25-$S$20)/$S$20) -> 0
A26: 3 | D26: =IF($B26=0,0,$C26/$B26) -> 0 | E26: =IF($D$20=0,0,($D26-$D$20)/$D$20) -> 0 | G26: =IF($B26=0,0,$F26/$B26) -> 0 | H26: =IF($G$20=0,0,($G26-$G$20)/$G$20) -> 0 | J26: =IF($B26=0,0,$I26/$B26) -> 0 | K26: =IF($J$20=0,0,($J26-$J$20)/$J$20) -> 0 | M26: =IF($B26=0,0,$L26/$B26) -> 0 | N26: =IF($M$20=0,0,($M26-$M$20)/$M$20) -> 0 | P26: =IF($B26=0,0,$O26/$B26) -> 0 | Q26: =IF($P$20=0,0,($P26-$P$20)/$P$20) -> 0 | R26: =SUM(C26,F26,I26,L26,O26) -> 0 | S26: =IF($B26=0,0,$R26/$B26) -> 0 | T26: =IF($S$20=0,0,($S26-$S$20)/$S$20) -> 0
A27: 4 | D27: =IF($B27=0,0,$C27/$B27) -> 0 | E27: =IF($D$20=0,0,($D27-$D$20)/$D$20) -> 0 | G27: =IF($B27=0,0,$F27/$B27) -> 0 | H27: =IF($G$20=0,0,($G27-$G$20)/$G$20) -> 0 | J27: =IF($B27=0,0,$I27/$B27) -> 0 | K27: =IF($J$20=0,0,($J27-$J$20)/$J$20) -> 0 | M27: =IF($B27=0,0,$L27/$B27) -> 0 | N27: =IF($M$20=0,0,($M27-$M$20)/$M$20) -> 0 | P27: =IF($B27=0,0,$O27/$B27) -> 0 | Q27: =IF($P$20=0,0,($P27-$P$20)/$P$20) -> 0 | R27: =SUM(C27,F27,I27,L27,O27) -> 0 | S27: =IF($B27=0,0,$R27/$B27) -> 0 | T27: =IF($S$20=0,0,($S27-$S$20)/$S$20) -> 0
A28: 5 | D28: =IF($B28=0,0,$C28/$B28) -> 0 | E28: =IF($D$20=0,0,($D28-$D$20)/$D$20) -> 0 | G28: =IF($B28=0,0,$F28/$B28) -> 0 | H28: =IF($G$20=0,0,($G28-$G$20)/$G$20) -> 0 | J28: =IF($B28=0,0,$I28/$B28) -> 0 | K28: =IF($J$20=0,0,($J28-$J$20)/$J$20) -> 0 | M28: =IF($B28=0,0,$L28/$B28) -> 0 | N28: =IF($M$20=0,0,($M28-$M$20)/$M$20) -> 0 | P28: =IF($B28=0,0,$O28/$B28) -> 0 | Q28: =IF($P$20=0,0,($P28-$P$20)/$P$20) -> 0 | R28: =SUM(C28,F28,I28,L28,O28) -> 0 | S28: =IF($B28=0,0,$R28/$B28) -> 0 | T28: =IF($S$20=0,0,($S28-$S$20)/$S$20) -> 0
A29: 6 | D29: =IF($B29=0,0,$C29/$B29) -> 0 | E29: =IF($D$20=0,0,($D29-$D$20)/$D$20) -> 0 | G29: =IF($B29=0,0,$F29/$B29) -> 0 | H29: =IF($G$20=0,0,($G29-$G$20)/$G$20) -> 0 | J29: =IF($B29=0,0,$I29/$B29) -> 0 | K29: =IF($J$20=0,0,($J29-$J$20)/$J$20) -> 0 | M29: =IF($B29=0,0,$L29/$B29) -> 0 | N29: =IF($M$20=0,0,($M29-$M$20)/$M$20) -> 0 | P29: =IF($B29=0,0,$O29/$B29) -> 0 | Q29: =IF($P$20=0,0,($P29-$P$20)/$P$20) -> 0 | R29: =SUM(C29,F29,I29,L29,O29) -> 0 | S29: =IF($B29=0,0,$R29/$B29) -> 0 | T29: =IF($S$20=0,0,($S29-$S$20)/$S$20) -> 0
A30: 7 | D30: =IF($B30=0,0,$C30/$B30) -> 0 | E30: =IF($D$20=0,0,($D30-$D$20)/$D$20) -> 0 | G30: =IF($B30=0,0,$F30/$B30) -> 0 | H30: =IF($G$20=0,0,($G30-$G$20)/$G$20) -> 0 | J30: =IF($B30=0,0,$I30/$B30) -> 0 | K30: =IF($J$20=0,0,($J30-$J$20)/$J$20) -> 0 | M30: =IF($B30=0,0,$L30/$B30) -> 0 | N30: =IF($M$20=0,0,($M30-$M$20)/$M$20) -> 0 | P30: =IF($B30=0,0,$O30/$B30) -> 0 | Q30: =IF($P$20=0,0,($P30-$P$20)/$P$20) -> 0 | R30: =SUM(C30,F30,I30,L30,O30) -> 0 | S30: =IF($B30=0,0,$R30/$B30) -> 0 | T30: =IF($S$20=0,0,($S30-$S$20)/$S$20) -> 0
A31: 8 | D31: =IF($B31=0,0,$C31/$B31) -> 0 | E31: =IF($D$20=0,0,($D31-$D$20)/$D$20) -> 0 | G31: =IF($B31=0,0,$F31/$B31) -> 0 | H31: =IF($G$20=0,0,($G31-$G$20)/$G$20) -> 0 | J31: =IF($B31=0,0,$I31/$B31) -> 0 | K31: =IF($J$20=0,0,($J31-$J$20)/$J$20) -> 0 | M31: =IF($B31=0,0,$L31/$B31) -> 0 | N31: =IF($M$20=0,0,($M31-$M$20)/$M$20) -> 0 | P31: =IF($B31=0,0,$O31/$B31) -> 0 | Q31: =IF($P$20=0,0,($P31-$P$20)/$P$20) -> 0 | R31: =SUM(C31,F31,I31,L31,O31) -> 0 | S31: =IF($B31=0,0,$R31/$B31) -> 0 | T31: =IF($S$20=0,0,($S31-$S$20)/$S$20) -> 0
A32: 9 | D32: =IF($B32=0,0,$C32/$B32) -> 0 | E32: =IF($D$20=0,0,($D32-$D$20)/$D$20) -> 0 | G32: =IF($B32=0,0,$F32/$B32) -> 0 | H32: =IF($G$20=0,0,($G32-$G$20)/$G$20) -> 0 | J32: =IF($B32=0,0,$I32/$B32) -> 0 | K32: =IF($J$20=0,0,($J32-$J$20)/$J$20) -> 0 | M32: =IF($B32=0,0,$L32/$B32) -> 0 | N32: =IF($M$20=0,0,($M32-$M$20)/$M$20) -> 0 | P32: =IF($B32=0,0,$O32/$B32) -> 0 | Q32: =IF($P$20=0,0,($P32-$P$20)/$P$20) -> 0 | R32: =SUM(C32,F32,I32,L32,O32) -> 0 | S32: =IF($B32=0,0,$R32/$B32) -> 0 | T32: =IF($S$20=0,0,($S32-$S$20)/$S$20) -> 0
A33: 10 | D33: =IF($B33=0,0,$C33/$B33) -> 0 | E33: =IF($D$20=0,0,($D33-$D$20)/$D$20) -> 0 | G33: =IF($B33=0,0,$F33/$B33) -> 0 | H33: =IF($G$20=0,0,($G33-$G$20)/$G$20) -> 0 | J33: =IF($B33=0,0,$I33/$B33) -> 0 | K33: =IF($J$20=0,0,($J33-$J$20)/$J$20) -> 0 | M33: =IF($B33=0,0,$L33/$B33) -> 0 | N33: =IF($M$20=0,0,($M33-$M$20)/$M$20) -> 0 | P33: =IF($B33=0,0,$O33/$B33) -> 0 | Q33: =IF($P$20=0,0,($P33-$P$20)/$P$20) -> 0 | R33: =SUM(C33,F33,I33,L33,O33) -> 0 | S33: =IF($B33=0,0,$R33/$B33) -> 0 | T33: =IF($S$20=0,0,($S33-$S$20)/$S$20) -> 0
A34: 11 | D34: =IF($B34=0,0,$C34/$B34) -> 0 | E34: =IF($D$20=0,0,($D34-$D$20)/$D$20) -> 0 | G34: =IF($B34=0,0,$F34/$B34) -> 0 | H34: =IF($G$20=0,0,($G34-$G$20)/$G$20) -> 0 | J34: =IF($B34=0,0,$I34/$B34) -> 0 | K34: =IF($J$20=0,0,($J34-$J$20)/$J$20) -> 0 | M34: =IF($B34=0,0,$L34/$B34) -> 0 | N34: =IF($M$20=0,0,($M34-$M$20)/$M$20) -> 0 | P34: =IF($B34=0,0,$O34/$B34) -> 0 | Q34: =IF($P$20=0,0,($P34-$P$20)/$P$20) -> 0 | R34: =SUM(C34,F34,I34,L34,O34) -> 0 | S34: =IF($B34=0,0,$R34/$B34) -> 0 | T34: =IF($S$20=0,0,($S34-$S$20)/$S$20) -> 0
A35: 12 | D35: =IF($B35=0,0,$C35/$B35) -> 0 | E35: =IF($D$20=0,0,($D35-$D$20)/$D$20) -> 0 | G35: =IF($B35=0,0,$F35/$B35) -> 0 | H35: =IF($G$20=0,0,($G35-$G$20)/$G$20) -> 0 | J35: =IF($B35=0,0,$I35/$B35) -> 0 | K35: =IF($J$20=0,0,($J35-$J$20)/$J$20) -> 0 | M35: =IF($B35=0,0,$L35/$B35) -> 0 | N35: =IF($M$20=0,0,($M35-$M$20)/$M$20) -> 0 | P35: =IF($B35=0,0,$O35/$B35) -> 0 | Q35: =IF($P$20=0,0,($P35-$P$20)/$P$20) -> 0 | R35: =SUM(C35,F35,I35,L35,O35) -> 0 | S35: =IF($B35=0,0,$R35/$B35) -> 0 | T35: =IF($S$20=0,0,($S35-$S$20)/$S$20) -> 0
A36: 合计 | B36: =SUM(B24:B35) -> 0 | C36: =SUM(C24:C35) -> 0 | D36: =IF($B36=0,0,$C36/$B36) -> 0 | E36: —— | F36: =SUM(F24:F35) -> 0 | G36: =IF($B36=0,0,$F36/$B36) -> 0 | H36: —— | I36: =SUM(I24:I35) -> 0 | J36: =IF($B36=0,0,$I36/$B36) -> 0 | K36: —— | L36: =SUM(L24:L35) -> 0 | M36: =IF($B36=0,0,$L36/$B36) -> 0 | N36: —— | O36: =SUM(O24:O35) -> 0 | P36: =IF($B36=0,0,$O36/$B36) -> 0 | Q36: —— | R36: =SUM(R24:R35) -> 0 | S36: =IF($B36=0,0,$R36/$B36) -> 0 | T36: =IF($S$20=0,0,($S36-$S$20)/$S$20) -> 0
A37: 1、审计说明：
A40: 2、审计结论：

Sheet 产品同行业成本比较G2-8-7-移至舞弊应对单耗分析中
A1: 致同会计师事务所
A2: 同行业产成品单位成本占比比较表
A3: =底稿目录!A2 -> 被审计单位： | F3: =底稿目录!A4 -> 编制人： | L3: =底稿目录!A5 -> 编制日期： | O3: 索引号： | P3: G2-8-7
A4: =底稿目录!A3 -> 截止日：202X年12月31日 | F4: =底稿目录!A6 -> 复核人： | L4: =底稿目录!A7 -> 复核日期： | O4: 页次：
A5: 产成品名称 | B5: 本公司单位成本 | G5: 同行业单位成本 | L5: 占比差异 | O5: 是否存在异常波动 | P5: 进一步审验底稿索引
B6: 直接材料 | C6: 直接人工 | D6: 制造费用 | F6: 合计 | G6: 直接材料 | H6: 直接人工 | I6: 制造费用 | K6: 合计 | L6: 直接材料 | M6: 直接人工 | N6: 制造费用
F7: =SUM(B7:E7) -> 0 | K7: =SUM(G7:J7) -> 0 | L7: =(B7/$F$7)-(G7/$K$7) -> #DIV/0! | M7: =(C7/$F$7)-(H7/$K$7) -> #DIV/0! | N7: =(D7/$F$7)-(I7/$K$7) -> #DIV/0!
F8: =SUM(B8:E8) -> 0 | K8: =SUM(G8:J8) -> 0 | L8: =(B8/$F$7)-(G8/$K$7) -> #DIV/0! | M8: =(C8/$F$7)-(H8/$K$7) -> #DIV/0! | N8: =(D8/$F$7)-(I8/$K$7) -> #DIV/0!
F9: =SUM(B9:E9) -> 0 | K9: =SUM(G9:J9) -> 0 | L9: =(B9/$F$7)-(G9/$K$7) -> #DIV/0! | M9: =(C9/$F$7)-(H9/$K$7) -> #DIV/0! | N9: =(D9/$F$7)-(I9/$K$7) -> #DIV/0!
F10: =SUM(B10:E10) -> 0 | K10: =SUM(G10:J10) -> 0 | L10: =(B10/$F$7)-(G10/$K$7) -> #DIV/0! | M10: =(C10/$F$7)-(H10/$K$7) -> #DIV/0! | N10: =(D10/$F$7)-(I10/$K$7) -> #DIV/0!
F11: =SUM(B11:E11) -> 0 | K11: =SUM(G11:J11) -> 0 | L11: =(B11/$F$7)-(G11/$K$7) -> #DIV/0! | M11: =(C11/$F$7)-(H11/$K$7) -> #DIV/0! | N11: =(D11/$F$7)-(I11/$K$7) -> #DIV/0!
F12: =SUM(B12:E12) -> 0 | K12: =SUM(G12:J12) -> 0 | L12: =(B12/$F$7)-(G12/$K$7) -> #DIV/0! | M12: =(C12/$F$7)-(H12/$K$7) -> #DIV/0! | N12: =(D12/$F$7)-(I12/$K$7) -> #DIV/0!
F13: =SUM(B13:E13) -> 0 | K13: =SUM(G13:J13) -> 0 | L13: =(B13/$F$7)-(G13/$K$7) -> #DIV/0! | M13: =(C13/$F$7)-(H13/$K$7) -> #DIV/0! | N13: =(D13/$F$7)-(I13/$K$7) -> #DIV/0!
F14: =SUM(B14:E14) -> 0 | K14: =SUM(G14:J14) -> 0 | L14: =(B14/$F$7)-(G14/$K$7) -> #DIV/0! | M14: =(C14/$F$7)-(H14/$K$7) -> #DIV/0! | N14: =(D14/$F$7)-(I14/$K$7) -> #DIV/0!
