Workbook

Sheet 底稿目录
A1: 底稿开列时，可先在以下单元格填写有关内容，以便其他底稿引用有关数据：
A2: 被审计单位： | D2: 序号 | E2: 内容 | F2: 索引号
A3: 截止日：202X年12月31日 | D3: 1 | E3: 存货实质性程序 | F3: F2-61A
A4: 编制人： | D4: 2 | E4: 原材料采购价格分析表 | F4: F2-61
A5: 编制日期： | D5: 3 | E5: 原材料单价分析表 | F5: F2-62
A6: 复核人： | D6: 4 | E6: 存货产量与产能、能耗分析表 | F6: F2-63
A7: 复核日期： | D7: 5 | E7: 主要产品生产成本及单耗分析表 | F7: F2-64
D8: 6 | E8: 函证结果汇总表 | F8: F0-1
A9: 关于工作底稿与审计程序索引号对应的说明 | D9: 7 | E9: 核实被函证单位信息 | F9: F0-2
A10: 1.编制的审计工作底稿应与审计程序对应。审计项目组应根据被审计单位实际情况和风险评估情况在实质性程序表中裁剪、修改或增加审计程序，根据实际执行的审计程序完成相应审计工作底稿，编制的工作底稿中应按自然顺序依次编制索引号，并通过唯一的索引号将与实质性程序表中的程序对应关联（即将工作底稿的索引号填入实质性程序表中的底稿索引号列）。 | D10: 8 | E10: 跟函函证过程控制 | F10: F0-3
D11: 9 | E11: 函证差异调节表 | F11: F0-4
D12: 10 | E12: 预付及采购替代程序检查表 | F12: F0-5
D13: 11 | E13: 应付及采购替代程序检查表 | F13: F0-6
A14: 2.获取的支持性证据应与审计底稿或程序对应。审计项目组在完成底稿时获取的支持性证据应根据底稿索引号编制下一级按自然顺序排序的索引号（如D1-2-1、D1-2-2、……），并在底稿中说明引用的支持性证据、关联索引号。 | D14: 12 | E14: 邮件传真回函可靠性验证 | F14: F0-7
D15: 13 | E15: 函证程序舞弊风险评价表 | F15: F0-8
D16: 14 | E16: 关联方采购定价公允性核查（询价函） | F16: F2-65
A17: 3.工作底稿索引号的编码规则：实质性程序索引号按循环从“D”到“N”,循环内账户以顺序号排列，模板中底稿索引号按账户顺序+自然数顺序（即模板中索引号按二级自然顺序排列，如D1-1、D1-2、D1-3、……D1-N）。 | D17: 15 | E17: 关联方采购定价公允性核查（市场价） | F17: F2-66
D18: 16 | E18: 识别未披露的关联方 | F18: F2-67
D19: 17 | E19: 重要供应商结构分析 | F19: F2-68
D20: 18 | E20: 供应商核查清单 | F20: F2-69
D21: 19 | E21: 供应商信息核查表 | F21: F2-70
D22: 20 | E22: 供应商访谈记录汇总表 | F22: F2-71
D23: 21 | E23: 供应商访谈记录 | F23: F2-72

Sheet 程序表F2-61A
A1: 致同会计师事务所
A2: 存货实质性程序
A3: =底稿目录!A2 -> 被审计单位： | D3: =底稿目录!A4 -> 编制人： | F3: =底稿目录!A5 -> 编制日期： | I3: 索引号： | J3: =底稿目录!F3 -> F2-61A
A4: =底稿目录!A3 -> 截止日：202X年12月31日 | D4: =底稿目录!A6 -> 复核人： | F4: =底稿目录!A7 -> 复核日期： | I4: 页 次：
A5: 一、本账户涉及的科目
A6: 存货及跌价准备
A7: 二、审计目标与认定的对应关系
A8: 审计目标 | H8: 财务报表的认定
A9: A. 资产负债表中记录的存货是存在的，且已经记录在恰当的账户中 | H9: 存在
A10: B. 所有应记录的存货均已记录，所有应当包括在财务报表中的相关披露均已包括 | H10: 完整性
A11: C. 记录的存货由被审计单位拥有或控制 | H11: 权利和义务
A12: D. 存货以恰当的金额包括在财务报表中，与之相关的计价或分摊调整已恰当记录，相关披露已得到恰当计量和描述 | H12: 准确性、计价和分摊
A13: E. 存货已被恰当地汇总或分解且表述清楚，相关披露在按照企业会计准则的编制基础下是相关的、可理解的 | H13: 列报
A14: 三、计划实施的实质性程序
A15: 序号 | B15: 与Leap对应 | C15: 审计程序 | D15: 程序分类 | E15: 财务报表的认定 | J15: 底稿索引号
E16: 存在 | F16: 完整性 | G16: 权利和 义务 | H16: 准确性、计价和分摊 | I16: 列报 | K16: 根据被审计单位实际情况和风险评估情况裁剪、修改或增加审计程序
A17: 1 | B17: 应对措施-实质性/非实质性分析程序 | C17: 原材料采购价格分析： （1）分析本期各月及前期主要原材料采购金额、数量、采购单价，关注采购单价异常波动、与市场价格偏离情况； （2）分析同一供应商采购不同物料的单价、同一原材料在不同供应商采购单价、同一类原材料不同规格采购单价波动分析，关注原材料采购入库价格是否异常。 | D17: IPO/上市/新三板/重组/舞弊应对 | E17: √ | H17: √ | J17: F2-61 /F2-62
A18: 2 | B18: 应对措施-实质性/非实质性分析程序 | C18: 财务指标与非财务指标结合分析，分析存货产量与产能（产能利用率）、货库存量与库存能力、水电等能源价格和单位产品能源消耗，关注异常情况。 | D18: IPO/上市/新三板/重组/舞弊应对 | E18: √ | H18: √ | J18: F2-63
A19: 3 | B19: 应对措施-实质性/非实质性分析程序 | C19: 主要产品成本及单耗分析： （1）分析本期及上期各月主要产品的生产成本（主要原材料、直接人工、制造费用）发生额，占比是否异常； （2）分析本期及上期各月主要产品生产成本结转、产量、产成品单位成本是否异常； （3）分析本期及上期各月主要产品产成品入库对应的主要原材料、直接人工、制造费用耗用，单位成本是否异常，与同行业公司对比是否异常； （4）分析本期及上期各月主要产品产成品入库对应的主要材料单位耗用是否异常； | D19: IPO/上市/新三板/重组/舞弊应对 | E19: √ | H19: √ | J19: F2-64
A20: 4 | B20: 应对措施-实质性/非实质性分析程序 | C20: 结合存货监盘和对仓库实物账的核对，分析原材料实际投入量是否与财务账面记录一致。 | D20: IPO/上市/新三板/重组/舞弊应对 | E20: √ | H20: √
A21: 5 | B21: 应对措施-检查 | C21: 结合销售循环审计，分析客户、供应商名单以及应收、应付等往来明细，检查是否针对同一对方单位或存在关联关系的对方单位同时存在销售、采购的情况，是否有合理的商业理由，关注是否存在第三方配合舞弊的情形。 | D21: IPO/上市/新三板/重组/舞弊应对 | E21: √ | G21: √ | H21: √
A22: 6 | B22: 应对措施-函证 | C22: 结合预付账款、应付账账款，选择主要、异常供应商，对采购额、合同条款、是否存在关联方关系及是否存在补充协议等实施函证程序。 | D22: IPO/上市/新三板/重组/舞弊应对 | E22: √ | F22: √ | G22: √ | H22: √ | J22: F0
A23: 7 | B23: 常规程序（选择“存在关联交易”） | C23: 对重大、异常关联交易，采用向可比公司询价或者查询采购产品可比市场价格的方式，核查向关联方采购价格的公允性。 | D23: IPO/上市/新三板/重组/舞弊应对 | H23: √ | J23: F2-65 /F2-66
A24: 8 | B24: 常规程序（选择“存在关联交易”） | C24: 考虑大额或异常的交易是否表明存在一个先前没有披露的关联方： （1）查询供应商工商、银行、税务信息资料，关注其地址、董事/监事/关键管理人员、联系方式等信息，并与其相关发票信息、网站信息进行核对，识别供应商是否存在与被审计单位存在疑似关联关系的信息； （2）选取重要供应商，获取关联方关系确认函； （3）取得实际控制人、董高监及其密切家庭人员的对外投资清单，与重要客户的股东和关键经办人员进行比对，关注与发行人实际控制人、董事、监事、高级管理人员关系密切的家庭成员与发行人的供应商是否存在关联方关系； （4）取得保荐机构及其关联方、PE投资机构及其关联方、PE投资机构的股东或实际控制人控制或投资的其他企业清单，将这些利益相关方清单和重要供应商及其法人、股东和关键经办人员名单进行比对，关注其是否与发行人发生大额交易； （5）获取发行人主要股东、董事、监事、关键管理人员及上述利益相关方的确认函，确认除其本人在被审计单位领取薪酬或分得股利外，其本人及其关系密切的家庭成员未与被审计单位有任何形式的交易。 | D24: IPO/上市/新三板/重组/舞弊应对 | E24: √ | F24: √ | I24: √ | J24: F2-67 /F2-70 /F2-
A25: 9 | B25: 应对措施-检查（选择“执行延申检查”） | C25: 分析主要供应商交易及变化情况，对主要供应商进行检查： （1）比较分析主要供应商的采购数量、采购金额、信用期、支付方式的变动以及原因，关注新增和异常供应商交易的合理性及持续性； （2）关注与主要供应商否存在关联关系、向供应商采购业务是否与经营范围匹配、采购金额是否与供应商规模匹配等。 （3）分析主要和异常供应商的采购物资种类、采购金额、采购单价、与平均单价的差异等； | D25: IPO/上市/新三板/重组/舞弊应对 | E25: √ | F25: √ | G25: √ | H25: √ | I25: √ | J25: F2-68 /F2-62
A26: 10 | B26: 应对措施-检查（选择“执行延申检查”） | C26: 如果识别出被审计单位采购真实性存在重大异常情况，且通过常规审计程序无法获取充分、适当的审计证据时，考虑实施“延伸检查”程序，可以实施的“延伸检查”程序包括不限于： （1）利用企业信息查询工具查询公司注册资本、地址、成立时间、经营范围、法定代表人、股东、最终控制人等，了解公司经营范围，判断客户所购产品是否具有合理用途、是否存在关联关系、向供应商采购金额是否与供应商规模匹配等。 （2）现场走访供应商的办公场所、经营场所，访谈客户关键经办人员，或电话访谈关键经办人员。核实被访谈对象对象身份的真实性和适当性，根据实际情况设计访谈计划和访谈提纲，观察对方生产经营情况、供应商产成品中是否有被审计单位采购的产品，判断其与被审计单位之间的交易规模是否和其生产经营规模匹配； （3）了解相关供应商向被审计单位进行销售的商业理由、销售产品的来源、供应商与被审计单位是否存在除购销交易以外的资金往来等。 （4）当注意到可能存在关联方（例如被审计单位控股股东、实际控制人、关键管理人员）或者第三方供应商配合被审计单位虚构采购的迹象时，考虑获取并检查相关关联方或者供应商的银行账户资金流水、关注是否存在与被审计单位相关供应商、客户或关联方的异常资金往来。 | D26: IPO/上市/新三板/重组/舞弊应对 | E26: √ | F26: √ | G26: √ | H26: √ | J26: F2-69 /F2-70 /F2-71 /F2-72 /D4-32
A27: 11 | C27: 根据评估的舞弊风险等因素增加的审计程序。 | D27: IPO/上市/新三板/重组/舞弊应对
A29: 提示：注册会计师在判断是否需要实施“延伸检查”程序及如何实施时，应当根据审计准则的规定，并考虑有经验的专业人士在该场景下通常会作出的合理职业判断。《中国注册会计师审计准则第 1131 号——审计工作底稿》对“有经验的专业人士”进行了定义。此外，实施“延伸检查”程序的可行性和效果受诸多因素影响，注册会计师设计的具体“延伸检查”程序的性质、时间安排和范围，应当针对被审计单位的具体况，与评估的舞弊风险相称，并体现重要性原则。例如，被审计单位所处行业的下游产业链较长，如果对下游产业链的某个或某几个环节实施“延伸检查”程序获取的审计证据，可以应对与收入确认相关的舞弊风险，则“延伸检查”程序无需覆盖所有环节。再者，相对于常规年度财务报表审计而言，在首次公开发行股票并上市审计（IPO 审计）中，由于存在监管要求和相关方的配合，注册会计师实施“延伸检查”程序通常相对可行。

Sheet 原材料采购价格分析表F2-61
A1: 致同会计师事务所
A2: 原材料采购价格分析表（报告期逐月采购金额、数量、单价比较）
A3: =底稿目录!A2 -> 被审计单位： | E3: =底稿目录!A4 -> 编制人： | J3: =底稿目录!A5 -> 编制日期： | O3: 索引号： | P3: =底稿目录!F4 -> F2-61
A4: =底稿目录!A3 -> 截止日：202X年12月31日 | E4: =底稿目录!A6 -> 复核人： | J4: =底稿目录!A7 -> 复核日期： | O4: 页 次：
A5: 入库金额（单位：元）
A6: 主要原材料/月份 | B6: 1月 | C6: 2月 | D6: 3月 | E6: 4月 | F6: 5月 | G6: 6月 | H6: 7月 | I6: 8月 | J6: 9月 | K6: 10月 | L6: 11月 | M6: 12月 | N6: 上期末 | O6: 本期合计金额 | P6: 上期合计金额
O7: =SUM(B7:M7) -> 0
O8: =SUM(B8:M8) -> 0
O9: =SUM(B9:M9) -> 0
O10: =SUM(B10:M10) -> 0
O11: =SUM(B11:M11) -> 0
A12: 小计 | B12: =SUM(B7:B11) -> 0 | C12: =SUM(C7:C11) -> 0 | D12: =SUM(D7:D11) -> 0 | E12: =SUM(E7:E11) -> 0 | F12: =SUM(F7:F11) -> 0 | G12: =SUM(G7:G11) -> 0 | H12: =SUM(H7:H11) -> 0 | I12: =SUM(I7:I11) -> 0 | ... P12: =SUM(P7:P11) -> 0
A13: 入库数量（单位：_______）
A14: 主要原材料/月份 | B14: 1月 | C14: 2月 | D14: 3月 | E14: 4月 | F14: 5月 | G14: 6月 | H14: 7月 | I14: 8月 | J14: 9月 | K14: 10月 | L14: 11月 | M14: 12月 | N14: 上期末 | O14: 本期合计数量 | P14: 上期合计数量
A15: =A7 -> 0 | O15: =SUM(B15:M15) -> 0
A16: =A8 -> 0 | O16: =SUM(B16:M16) -> 0
A17: =A9 -> 0 | O17: =SUM(B17:M17) -> 0
A18: =A10 -> 0 | O18: =SUM(B18:M18) -> 0
A19: =A11 -> 0 | O19: =SUM(B19:M19) -> 0
A20: 小计 | B20: =SUM(B15:B19) -> 0 | C20: =SUM(C15:C19) -> 0 | D20: =SUM(D15:D19) -> 0 | E20: =SUM(E15:E19) -> 0 | F20: =SUM(F15:F19) -> 0 | G20: =SUM(G15:G19) -> 0 | H20: =SUM(H15:H19) -> 0 | I20: =SUM(I15:I19) -> 0 | ... P20: =SUM(P15:P19) -> 0
A21: 入库单价（单位：元）
A22: 主要原材料/月份 | B22: 1月 | C22: 2月 | D22: 3月 | E22: 4月 | F22: 5月 | G22: 6月 | H22: 7月 | I22: 8月 | J22: 9月 | K22: 10月 | L22: 11月 | M22: 12月 | N22: 上期末 | O22: 本期平均单价 | P22: 上期平均单价
A23: =A7 -> 0 | B23: =IF(B15=0,0,B7/B15) -> 0 | C23: =IF(C15=0,0,C7/C15) -> 0 | D23: =IF(D15=0,0,D7/D15) -> 0 | E23: =IF(E15=0,0,E7/E15) -> 0 | F23: =IF(F15=0,0,F7/F15) -> 0 | G23: =IF(G15=0,0,G7/G15) -> 0 | H23: =IF(H15=0,0,H7/H15) -> 0 | I23: =IF(I15=0,0,I7/I15) -> 0 | ... P23: =IF(P15=0,0,P7/P15) -> 0
A24: =A8 -> 0 | B24: =IF(B16=0,0,B8/B16) -> 0 | C24: =IF(C16=0,0,C8/C16) -> 0 | D24: =IF(D16=0,0,D8/D16) -> 0 | E24: =IF(E16=0,0,E8/E16) -> 0 | F24: =IF(F16=0,0,F8/F16) -> 0 | G24: =IF(G16=0,0,G8/G16) -> 0 | H24: =IF(H16=0,0,H8/H16) -> 0 | I24: =IF(I16=0,0,I8/I16) -> 0 | ... P24: =IF(P16=0,0,P8/P16) -> 0
A25: =A9 -> 0 | B25: =IF(B17=0,0,B9/B17) -> 0 | C25: =IF(C17=0,0,C9/C17) -> 0 | D25: =IF(D17=0,0,D9/D17) -> 0 | E25: =IF(E17=0,0,E9/E17) -> 0 | F25: =IF(F17=0,0,F9/F17) -> 0 | G25: =IF(G17=0,0,G9/G17) -> 0 | H25: =IF(H17=0,0,H9/H17) -> 0 | I25: =IF(I17=0,0,I9/I17) -> 0 | ... P25: =IF(P17=0,0,P9/P17) -> 0
A26: =A10 -> 0 | B26: =IF(B18=0,0,B10/B18) -> 0 | C26: =IF(C18=0,0,C10/C18) -> 0 | D26: =IF(D18=0,0,D10/D18) -> 0 | E26: =IF(E18=0,0,E10/E18) -> 0 | F26: =IF(F18=0,0,F10/F18) -> 0 | G26: =IF(G18=0,0,G10/G18) -> 0 | H26: =IF(H18=0,0,H10/H18) -> 0 | I26: =IF(I18=0,0,I10/I18) -> 0 | ... P26: =IF(P18=0,0,P10/P18) -> 0
A27: =A11 -> 0 | B27: =IF(B19=0,0,B11/B19) -> 0 | C27: =IF(C19=0,0,C11/C19) -> 0 | D27: =IF(D19=0,0,D11/D19) -> 0 | E27: =IF(E19=0,0,E11/E19) -> 0 | F27: =IF(F19=0,0,F11/F19) -> 0 | G27: =IF(G19=0,0,G11/G19) -> 0 | H27: =IF(H19=0,0,H11/H19) -> 0 | I27: =IF(I19=0,0,I11/I19) -> 0 | ... P27: =IF(P19=0,0,P11/P19) -> 0
A28: 市场单价（单位：元）
A29: 主要原材料/月份 | B29: 1月 | C29: 2月 | D29: 3月 | E29: 4月 | F29: 5月 | G29: 6月 | H29: 7月 | I29: 8月 | J29: 9月 | K29: 10月 | L29: 11月 | M29: 12月 | N29: 上期末 | O29: 本期平均单价 | P29: 上期平均单价
O30: =AVERAGE(B30:M30) -> #DIV/0!
O31: =AVERAGE(B31:M31) -> #DIV/0!
O32: =AVERAGE(B32:M32) -> #DIV/0!
O33: =AVERAGE(B33:M33) -> #DIV/0!
O34: =AVERAGE(B34:M34) -> #DIV/0!
A35: 小计 | B35: =SUM(B30:B34) -> 0 | C35: =SUM(C30:C34) -> 0 | D35: =SUM(D30:D34) -> 0 | E35: =SUM(E30:E34) -> 0 | F35: =SUM(F30:F34) -> 0 | G35: =SUM(G30:G34) -> 0 | H35: =SUM(H30:H34) -> 0 | I35: =SUM(I30:I34) -> 0 | ... N35: =SUM(N30:N34) -> 0 | O35: =AVERAGE(B35:M35) -> 0
A36: 1、审计说明：
A37: 1.原材料——***月采购单价变动较大的原因：
A38: 2.原材料——***月采购单价与市场价格差异较大原因：
A40: 2、审计结论：
A42: 提示：
...

Sheet 原材料单价分析F2-62
A1: 致同会计师事务所
A2: 原材料单价分析表
A3: =底稿目录!A2 -> 被审计单位： | D3: =底稿目录!A4 -> 编制人： | G3: =底稿目录!A5 -> 编制日期： | I3: 索引号： | J3: =底稿目录!F5 -> F2-62
A4: =底稿目录!A3 -> 截止日：202X年12月31日 | D4: =底稿目录!A6 -> 复核人： | G4: =底稿目录!A7 -> 复核日期： | I4: 页 次：
A5: 一、同一供应商，采购不同物料单价分析
A6: XX供应商 | B6: A物料 | E6: B物料 | H6: ……
A7: 月份 | B7: 入库金额 | C7: 入库主数量 | D7: 单价 | E7: 入库金额 | F7: 入库主数量 | G7: 单价 | H7: 入库金额 | I7: 入库主数量 | J7: 单价
A8: 1月 | D8: =B8/C8 -> #DIV/0! | G8: =E8/F8 -> #DIV/0! | J8: =H8/I8 -> #DIV/0!
A9: 2月 | D9: =B9/C9 -> #DIV/0! | G9: =E9/F9 -> #DIV/0! | J9: =H9/I9 -> #DIV/0!
A10: 3月 | D10: =B10/C10 -> #DIV/0! | G10: =E10/F10 -> #DIV/0! | J10: =H10/I10 -> #DIV/0!
A11: 4月 | D11: =B11/C11 -> #DIV/0! | G11: =E11/F11 -> #DIV/0! | J11: =H11/I11 -> #DIV/0!
A12: 5月 | D12: =B12/C12 -> #DIV/0! | G12: =E12/F12 -> #DIV/0! | J12: =H12/I12 -> #DIV/0!
A13: 6月 | D13: =B13/C13 -> #DIV/0! | G13: =E13/F13 -> #DIV/0! | J13: =H13/I13 -> #DIV/0!
A14: 7月 | D14: =B14/C14 -> #DIV/0! | G14: =E14/F14 -> #DIV/0! | J14: =H14/I14 -> #DIV/0!
A15: 8月 | D15: =B15/C15 -> #DIV/0! | G15: =E15/F15 -> #DIV/0! | J15: =H15/I15 -> #DIV/0!
A16: 9月 | D16: =B16/C16 -> #DIV/0! | G16: =E16/F16 -> #DIV/0! | J16: =H16/I16 -> #DIV/0!
A17: 10月 | D17: =B17/C17 -> #DIV/0! | G17: =E17/F17 -> #DIV/0! | J17: =H17/I17 -> #DIV/0!
A18: 11月 | D18: =B18/C18 -> #DIV/0! | G18: =E18/F18 -> #DIV/0! | J18: =H18/I18 -> #DIV/0!
A19: 12月 | D19: =B19/C19 -> #DIV/0! | G19: =E19/F19 -> #DIV/0! | J19: =H19/I19 -> #DIV/0!
A20: 总计 | B20: =SUM(B8:B19) -> 0 | C20: =SUM(C8:C19) -> 0 | D20: =IFERROR(B20/C20,0) -> 0 | E20: =SUM(E8:E19) -> 0 | F20: =SUM(F8:F19) -> 0 | G20: =IFERROR(E20/F20,0) -> 0 | H20: =SUM(H8:H19) -> 0 | I20: =SUM(I8:I19) -> 0 | J20: =IFERROR(H20/I20,0) -> 0
A22: 二、同一原材料，在不同供应商处各月采购单价分析
A23: XX原材料 | B23: 供应商1 | E23: 供应商2 | H23: ……
A24: 月份 | B24: 入库金额 | C24: 入库数量 | D24: 单价 | E24: 入库金额 | F24: 入库数量 | G24: 单价 | H24: 入库金额 | I24: 入库数量 | J24: 单价
A25: 1月 | D25: =B25/C25 -> #DIV/0! | G25: =E25/F25 -> #DIV/0! | J25: =H25/I25 -> #DIV/0!
A26: 2月 | D26: =B26/C26 -> #DIV/0! | G26: =E26/F26 -> #DIV/0! | J26: =H26/I26 -> #DIV/0!
A27: 3月 | D27: =B27/C27 -> #DIV/0! | G27: =E27/F27 -> #DIV/0! | J27: =H27/I27 -> #DIV/0!
A28: 4月 | D28: =B28/C28 -> #DIV/0! | G28: =E28/F28 -> #DIV/0! | J28: =H28/I28 -> #DIV/0!
A29: 5月 | D29: =B29/C29 -> #DIV/0! | G29: =E29/F29 -> #DIV/0! | J29: =H29/I29 -> #DIV/0!
A30: 6月 | D30: =B30/C30 -> #DIV/0! | G30: =E30/F30 -> #DIV/0! | J30: =H30/I30 -> #DIV/0!
A31: 7月 | D31: =B31/C31 -> #DIV/0! | G31: =E31/F31 -> #DIV/0! | J31: =H31/I31 -> #DIV/0!
A32: 8月 | D32: =B32/C32 -> #DIV/0! | G32: =E32/F32 -> #DIV/0! | J32: =H32/I32 -> #DIV/0!
A33: 9月 | D33: =B33/C33 -> #DIV/0! | G33: =E33/F33 -> #DIV/0! | J33: =H33/I33 -> #DIV/0!
A34: 10月 | D34: =B34/C34 -> #DIV/0! | G34: =E34/F34 -> #DIV/0! | J34: =H34/I34 -> #DIV/0!
A35: 11月 | D35: =B35/C35 -> #DIV/0! | G35: =E35/F35 -> #DIV/0! | J35: =H35/I35 -> #DIV/0!
A36: 12月 | D36: =B36/C36 -> #DIV/0! | G36: =E36/F36 -> #DIV/0! | J36: =H36/I36 -> #DIV/0!
A37: 合计 | B37: =SUM(B25:B36) -> 0 | C37: =SUM(C25:C36) -> 0 | D37: =IFERROR(B37/C37,0) -> 0 | E37: =SUM(E25:E36) -> 0 | F37: =SUM(F25:F36) -> 0 | G37: =IFERROR(E37/F37,0) -> 0 | H37: =SUM(H25:H36) -> 0 | I37: =SUM(I25:I36) -> 0 | J37: =IFERROR(H37/I37,0) -> 0
A39: 三、同一类原材料，不同规格材料采购单价分析
A40: 规格 | B40: 20XX年度 | E40: 20XX年度 | H40: 20XX年度
B41: 数量 | C41: 金额 | D41: 采购单价 | E41: 数量 | F41: 金额 | G41: 采购单价 | H41: 数量 | I41: 金额 | J41: 采购单价
D42: =C42/B42 -> #DIV/0! | G42: =F42/E42 -> #DIV/0! | J42: =I42/H42 -> #DIV/0!
...

Sheet 存货产量与产能、能耗分析表F2-63
A1: 致同会计师事务所
A2: 存货产量与产能、能耗分析表
A3: =底稿目录!A2 -> 被审计单位： | D3: =底稿目录!A4 -> 编制人： | G3: =底稿目录!A5 -> 编制日期： | I3: 索引号： | J3: =底稿目录!F6 -> F2-63
A4: =底稿目录!A3 -> 截止日：202X年12月31日 | D4: =底稿目录!A6 -> 复核人： | G4: =底稿目录!A7 -> 复核日期： | I4: 页 次：
A5: 一、实际产量与产能比较分析
A6: 存货名称 | B6: 本年产量 | C6: 全年产能 | D6: 产能利用率 | E6: 备注
D7: =IF(C7=0,0,B7/C7) -> 0
D8: =IF(C8=0,0,B8/C8) -> 0
D9: =IF(C9=0,0,B9/C9) -> 0
D10: =IF(C10=0,0,B10/C10) -> 0
D11: =IF(C11=0,0,B11/C11) -> 0
A12: 二、期末库存与库存容量比较
A13: 仓库名称 | B13: 存货名称 | C13: 实际库存量 | D13: 库存容量 | E13: 容量利用率 | F13: 已有订单数量 | G13: 已有订单金额 | H13: 期后销售数量 | I13: 期后销售金额
A17: XX仓库小计 | C17: =SUM(C14:C16) -> 0 | E17: =IF(D17=0,0,C17/D17) -> 0 | F17: =SUM(F14:F16) -> 0 | G17: =SUM(G14:G16) -> 0 | H17: =SUM(H14:H16) -> 0 | I17: =SUM(I14:I16) -> 0
A21: XX仓库小计 | C21: =SUM(C18:C20) -> 0 | E21: =IF(D21=0,0,C21/D21) -> 0 | F21: =SUM(F18:F20) -> 0 | G21: =SUM(G18:G20) -> 0 | H21: =SUM(H18:H20) -> 0 | I21: =SUM(I18:I20) -> 0
A22: 三、实际产量与能耗比较分析
A23: 采购项目 | B23: 本期 | E23: 上期
B24: 采购数量 | C24: 采购金额 | D24: 单价 | E24: 采购数量 | F24: 采购金额 | G24: 单价
A25: 水 | D25: =C25/B25 -> #DIV/0! | G25: =F25/E25 -> #DIV/0!
A26: 电 | D26: =C26/B26 -> #DIV/0! | G26: =F26/E26 -> #DIV/0!
A27: 燃气 | D27: =C27/B27 -> #DIV/0! | G27: =F27/E27 -> #DIV/0!
A28: 蒸汽 | D28: =C28/B28 -> #DIV/0! | G28: =F28/E28 -> #DIV/0!
A29: …… | D29: =C29/B29 -> #DIV/0! | G29: =F29/E29 -> #DIV/0!
A30: 合计 | C30: =SUM(C25:C29) -> 0 | F30: =SUM(F25:F29) -> 0
A32: 产品 | B32: 本年产量 | C32: 耗用能耗 | F32: 单位能耗 | G32: 上年单位能耗 | H32: 变动 | I32: 变动率
C33: 水 | D33: 电 | E33: 燃气
A34: =A7 -> 0 | B34: =B7 -> 0 | F34: =B34/(C34+D34+E34) -> #DIV/0! | H34: =F34-G34 -> #DIV/0! | I34: =IF(G34=0,0,H34/G34) -> 0
A35: =A8 -> 0 | B35: =B8 -> 0 | F35: =B35/(C35+D35+E35) -> #DIV/0! | H35: =F35-G35 -> #DIV/0! | I35: =IF(G35=0,0,H35/G35) -> 0
A36: =A9 -> 0 | B36: =B9 -> 0 | F36: =B36/(C36+D36+E36) -> #DIV/0! | H36: =F36-G36 -> #DIV/0! | I36: =IF(G36=0,0,H36/G36) -> 0
A37: =A10 -> 0 | B37: =B10 -> 0 | F37: =B37/(C37+D37+E37) -> #DIV/0! | H37: =F37-G37 -> #DIV/0! | I37: =IF(G37=0,0,H37/G37) -> 0
A38: =A11 -> 0 | B38: =B11 -> 0 | F38: =B38/(C38+D38+E38) -> #DIV/0! | H38: =F38-G38 -> #DIV/0! | I38: =IF(G38=0,0,H38/G38) -> 0
A40: 四、审计说明：
A41: 1.实际产量与产能异常的原因，与同行业产能利用率差异的原因：
A42: 2.期末实际库存与库存容量比较异常的原因：
A43: 2.能耗异常原因：
A44: 五、审计结论：
A46: 提示：
A47: 1.底稿中仅列示了实际产量与产能比较、期末库存与库存容量比较的参考格式，请结合公司实际情况和审计程序要求设计和编制相关底稿。
A48: 2.识别与存货成本密切相关的联动成本因素（如关键原材料、水电费等），根据标准单耗指标，以及工资表、水费单、电费单、运费单等测算发行人真实的产量和销量，并倒推采购量，将其实际采购量情况、存货收发存情况与投入产出结合比较，以分析本期存货产、销、存的合理性，分析说明有无重大异常。

Sheet 主要产品生产成本及单耗分析表F2-64
A1: 致同会计师事务所
A2: 主要产品生产成本及单耗分析表
A3: =底稿目录!A2 -> 被审计单位： | E3: =底稿目录!A4 -> 编制人： | I3: =底稿目录!A5 -> 编制日期： | N3: 索引号： | O3: =底稿目录!F7 -> F2-64
A4: =底稿目录!A3 -> 截止日：202X年12月31日 | E4: =底稿目录!A6 -> 复核人： | I4: =底稿目录!A7 -> 复核日期： | N4: 页次：
A5: 产品名称： | B5: XX产品
A6: 一、生产成本本期及上期各月发生额分析
A7: 年度 | B7: 月份 | C7: 金额 | J7: 结构比
C8: 主要原材料1 | D8: 主要原材料2 | E8: 主要原材料3 | F8: 其他材料 | G8: 直接人工 | H8: 制造费用 | I8: 小计 | J8: 主要原材料1 | K8: 主要原材料2 | L8: 主要原材料3 | M8: 其他材料 | N8: 直接人工 | O8: 制造费用
A9: 20X5年 | B9: 1月 | I9: =SUM(C9:H9) -> 0 | J9: =IF(C9=0,0,C9/$I9) -> 0 | K9: =IF(D9=0,0,D9/$I9) -> 0 | L9: =IF(E9=0,0,E9/$I9) -> 0 | M9: =IF(F9=0,0,F9/$I9) -> 0 | N9: =IF(G9=0,0,G9/$I9) -> 0 | O9: =IF(H9=0,0,H9/$I9) -> 0
B10: 2月 | I10: =SUM(C10:H10) -> 0 | J10: =IF(C10=0,0,C10/$I10) -> 0 | K10: =IF(D10=0,0,D10/$I10) -> 0 | L10: =IF(E10=0,0,E10/$I10) -> 0 | M10: =IF(F10=0,0,F10/$I10) -> 0 | N10: =IF(G10=0,0,G10/$I10) -> 0 | O10: =IF(H10=0,0,H10/$I10) -> 0
B11: 3月 | I11: =SUM(C11:H11) -> 0 | J11: =IF(C11=0,0,C11/$I11) -> 0 | K11: =IF(D11=0,0,D11/$I11) -> 0 | L11: =IF(E11=0,0,E11/$I11) -> 0 | M11: =IF(F11=0,0,F11/$I11) -> 0 | N11: =IF(G11=0,0,G11/$I11) -> 0 | O11: =IF(H11=0,0,H11/$I11) -> 0
B12: 4月 | I12: =SUM(C12:H12) -> 0 | J12: =IF(C12=0,0,C12/$I12) -> 0 | K12: =IF(D12=0,0,D12/$I12) -> 0 | L12: =IF(E12=0,0,E12/$I12) -> 0 | M12: =IF(F12=0,0,F12/$I12) -> 0 | N12: =IF(G12=0,0,G12/$I12) -> 0 | O12: =IF(H12=0,0,H12/$I12) -> 0
B13: 5月 | I13: =SUM(C13:H13) -> 0 | J13: =IF(C13=0,0,C13/$I13) -> 0 | K13: =IF(D13=0,0,D13/$I13) -> 0 | L13: =IF(E13=0,0,E13/$I13) -> 0 | M13: =IF(F13=0,0,F13/$I13) -> 0 | N13: =IF(G13=0,0,G13/$I13) -> 0 | O13: =IF(H13=0,0,H13/$I13) -> 0
B14: 6月 | I14: =SUM(C14:H14) -> 0 | J14: =IF(C14=0,0,C14/$I14) -> 0 | K14: =IF(D14=0,0,D14/$I14) -> 0 | L14: =IF(E14=0,0,E14/$I14) -> 0 | M14: =IF(F14=0,0,F14/$I14) -> 0 | N14: =IF(G14=0,0,G14/$I14) -> 0 | O14: =IF(H14=0,0,H14/$I14) -> 0
B15: 7月 | I15: =SUM(C15:H15) -> 0 | J15: =IF(C15=0,0,C15/$I15) -> 0 | K15: =IF(D15=0,0,D15/$I15) -> 0 | L15: =IF(E15=0,0,E15/$I15) -> 0 | M15: =IF(F15=0,0,F15/$I15) -> 0 | N15: =IF(G15=0,0,G15/$I15) -> 0 | O15: =IF(H15=0,0,H15/$I15) -> 0
B16: 8月 | I16: =SUM(C16:H16) -> 0 | J16: =IF(C16=0,0,C16/$I16) -> 0 | K16: =IF(D16=0,0,D16/$I16) -> 0 | L16: =IF(E16=0,0,E16/$I16) -> 0 | M16: =IF(F16=0,0,F16/$I16) -> 0 | N16: =IF(G16=0,0,G16/$I16) -> 0 | O16: =IF(H16=0,0,H16/$I16) -> 0
B17: 9月 | I17: =SUM(C17:H17) -> 0 | J17: =IF(C17=0,0,C17/$I17) -> 0 | K17: =IF(D17=0,0,D17/$I17) -> 0 | L17: =IF(E17=0,0,E17/$I17) -> 0 | M17: =IF(F17=0,0,F17/$I17) -> 0 | N17: =IF(G17=0,0,G17/$I17) -> 0 | O17: =IF(H17=0,0,H17/$I17) -> 0
B18: 10月 | I18: =SUM(C18:H18) -> 0 | J18: =IF(C18=0,0,C18/$I18) -> 0 | K18: =IF(D18=0,0,D18/$I18) -> 0 | L18: =IF(E18=0,0,E18/$I18) -> 0 | M18: =IF(F18=0,0,F18/$I18) -> 0 | N18: =IF(G18=0,0,G18/$I18) -> 0 | O18: =IF(H18=0,0,H18/$I18) -> 0
B19: 11月 | I19: =SUM(C19:H19) -> 0 | J19: =IF(C19=0,0,C19/$I19) -> 0 | K19: =IF(D19=0,0,D19/$I19) -> 0 | L19: =IF(E19=0,0,E19/$I19) -> 0 | M19: =IF(F19=0,0,F19/$I19) -> 0 | N19: =IF(G19=0,0,G19/$I19) -> 0 | O19: =IF(H19=0,0,H19/$I19) -> 0
B20: 12月 | I20: =SUM(C20:H20) -> 0 | J20: =IF(C20=0,0,C20/$I20) -> 0 | K20: =IF(D20=0,0,D20/$I20) -> 0 | L20: =IF(E20=0,0,E20/$I20) -> 0 | M20: =IF(F20=0,0,F20/$I20) -> 0 | N20: =IF(G20=0,0,G20/$I20) -> 0 | O20: =IF(H20=0,0,H20/$I20) -> 0
B21: 合计 | C21: =SUM(C9:C20) -> 0 | D21: =SUM(D9:D20) -> 0 | E21: =SUM(E9:E20) -> 0 | F21: =SUM(F9:F20) -> 0 | G21: =SUM(G9:G20) -> 0 | H21: =SUM(H9:H20) -> 0 | I21: =SUM(I9:I20) -> 0 | J21: =IF(C21=0,0,C21/$I21) -> 0 | K21: =IF(D21=0,0,D21/$I21) -> 0 | L21: =IF(E21=0,0,E21/$I21) -> 0 | M21: =IF(F21=0,0,F21/$I21) -> 0 | N21: =IF(G21=0,0,G21/$I21) -> 0 | O21: =IF(H21=0,0,H21/$I21) -> 0
A22: 20X4年 | B22: 1月 | I22: =SUM(C22:H22) -> 0 | J22: =IF(C22=0,0,C22/$I22) -> 0 | K22: =IF(D22=0,0,D22/$I22) -> 0 | L22: =IF(E22=0,0,E22/$I22) -> 0 | M22: =IF(F22=0,0,F22/$I22) -> 0 | N22: =IF(G22=0,0,G22/$I22) -> 0 | O22: =IF(H22=0,0,H22/$I22) -> 0
B23: 2月 | I23: =SUM(C23:H23) -> 0 | J23: =IF(C23=0,0,C23/$I23) -> 0 | K23: =IF(D23=0,0,D23/$I23) -> 0 | L23: =IF(E23=0,0,E23/$I23) -> 0 | M23: =IF(F23=0,0,F23/$I23) -> 0 | N23: =IF(G23=0,0,G23/$I23) -> 0 | O23: =IF(H23=0,0,H23/$I23) -> 0
B24: 3月 | I24: =SUM(C24:H24) -> 0 | J24: =IF(C24=0,0,C24/$I24) -> 0 | K24: =IF(D24=0,0,D24/$I24) -> 0 | L24: =IF(E24=0,0,E24/$I24) -> 0 | M24: =IF(F24=0,0,F24/$I24) -> 0 | N24: =IF(G24=0,0,G24/$I24) -> 0 | O24: =IF(H24=0,0,H24/$I24) -> 0
B25: 4月 | I25: =SUM(C25:H25) -> 0 | J25: =IF(C25=0,0,C25/$I25) -> 0 | K25: =IF(D25=0,0,D25/$I25) -> 0 | L25: =IF(E25=0,0,E25/$I25) -> 0 | M25: =IF(F25=0,0,F25/$I25) -> 0 | N25: =IF(G25=0,0,G25/$I25) -> 0 | O25: =IF(H25=0,0,H25/$I25) -> 0
B26: 5月 | I26: =SUM(C26:H26) -> 0 | J26: =IF(C26=0,0,C26/$I26) -> 0 | K26: =IF(D26=0,0,D26/$I26) -> 0 | L26: =IF(E26=0,0,E26/$I26) -> 0 | M26: =IF(F26=0,0,F26/$I26) -> 0 | N26: =IF(G26=0,0,G26/$I26) -> 0 | O26: =IF(H26=0,0,H26/$I26) -> 0
B27: 6月 | I27: =SUM(C27:H27) -> 0 | J27: =IF(C27=0,0,C27/$I27) -> 0 | K27: =IF(D27=0,0,D27/$I27) -> 0 | L27: =IF(E27=0,0,E27/$I27) -> 0 | M27: =IF(F27=0,0,F27/$I27) -> 0 | N27: =IF(G27=0,0,G27/$I27) -> 0 | O27: =IF(H27=0,0,H27/$I27) -> 0
B28: 7月 | I28: =SUM(C28:H28) -> 0 | J28: =IF(C28=0,0,C28/$I28) -> 0 | K28: =IF(D28=0,0,D28/$I28) -> 0 | L28: =IF(E28=0,0,E28/$I28) -> 0 | M28: =IF(F28=0,0,F28/$I28) -> 0 | N28: =IF(G28=0,0,G28/$I28) -> 0 | O28: =IF(H28=0,0,H28/$I28) -> 0
B29: 8月 | I29: =SUM(C29:H29) -> 0 | J29: =IF(C29=0,0,C29/$I29) -> 0 | K29: =IF(D29=0,0,D29/$I29) -> 0 | L29: =IF(E29=0,0,E29/$I29) -> 0 | M29: =IF(F29=0,0,F29/$I29) -> 0 | N29: =IF(G29=0,0,G29/$I29) -> 0 | O29: =IF(H29=0,0,H29/$I29) -> 0
B30: 9月 | I30: =SUM(C30:H30) -> 0 | J30: =IF(C30=0,0,C30/$I30) -> 0 | K30: =IF(D30=0,0,D30/$I30) -> 0 | L30: =IF(E30=0,0,E30/$I30) -> 0 | M30: =IF(F30=0,0,F30/$I30) -> 0 | N30: =IF(G30=0,0,G30/$I30) -> 0 | O30: =IF(H30=0,0,H30/$I30) -> 0
B31: 10月 | I31: =SUM(C31:H31) -> 0 | J31: =IF(C31=0,0,C31/$I31) -> 0 | K31: =IF(D31=0,0,D31/$I31) -> 0 | L31: =IF(E31=0,0,E31/$I31) -> 0 | M31: =IF(F31=0,0,F31/$I31) -> 0 | N31: =IF(G31=0,0,G31/$I31) -> 0 | O31: =IF(H31=0,0,H31/$I31) -> 0
B32: 11月 | I32: =SUM(C32:H32) -> 0 | J32: =IF(C32=0,0,C32/$I32) -> 0 | K32: =IF(D32=0,0,D32/$I32) -> 0 | L32: =IF(E32=0,0,E32/$I32) -> 0 | M32: =IF(F32=0,0,F32/$I32) -> 0 | N32: =IF(G32=0,0,G32/$I32) -> 0 | O32: =IF(H32=0,0,H32/$I32) -> 0
B33: 12月 | I33: =SUM(C33:H33) -> 0 | J33: =IF(C33=0,0,C33/$I33) -> 0 | K33: =IF(D33=0,0,D33/$I33) -> 0 | L33: =IF(E33=0,0,E33/$I33) -> 0 | M33: =IF(F33=0,0,F33/$I33) -> 0 | N33: =IF(G33=0,0,G33/$I33) -> 0 | O33: =IF(H33=0,0,H33/$I33) -> 0
B34: 合计 | C34: =SUM(C22:C33) -> 0 | D34: =SUM(D22:D33) -> 0 | E34: =SUM(E22:E33) -> 0 | F34: =SUM(F22:F33) -> 0 | G34: =SUM(G22:G33) -> 0 | H34: =SUM(H22:H33) -> 0 | I34: =SUM(I22:I33) -> 0 | J34: =IF(C34=0,0,C34/$I34) -> 0 | K34: =IF(D34=0,0,D34/$I34) -> 0 | L34: =IF(E34=0,0,E34/$I34) -> 0 | M34: =IF(F34=0,0,F34/$I34) -> 0 | N34: =IF(G34=0,0,G34/$I34) -> 0 | O34: =IF(H34=0,0,H34/$I34) -> 0
A35: 审计说明：
A38: 二、生产成本本期及上期各月结转、产量、产成品单位成本分析
A39: 年度 | B39: 月份 | C39: 生产成本 | H39: 产成品入库
C40: 期初余额 | D40: 本期投入 | E40: 转入产成品 | F40: 转入其他 | G40: 期末余额-在产品 | H40: 产量 | I40: 单位成本
A41: 20X5年 | B41: 1月 | G41: =C41+D41-E41-F41 -> 0 | I41: =IF(E41=0,0,E41/$H41) -> 0
B42: 2月 | G42: =C42+D42-E42-F42 -> 0 | I42: =IF(E42=0,0,E42/$H42) -> 0
...

Sheet 关联方采购定价公允性核查（询价函）F2-65
A1: 致同会计师事务所
A2: 关联方采购定价公允性核查（询价函）
A3: =底稿目录!A2 -> 被审计单位： | C3: =底稿目录!A4 -> 编制人： | E3: =底稿目录!A5 -> 编制日期： | G3: 索引号： | H3: =底稿目录!F16 -> F2-65
A4: =底稿目录!A3 -> 截止日：202X年12月31日 | C4: =底稿目录!A6 -> 复核人： | E4: =底稿目录!A7 -> 复核日期： | G4: 页 次：
A5: 一、审计目标：
A6: 存货以恰当的金额包括在财务报表中，与之相关的计价或分摊调整已恰当记录，相关披露已得到恰当计量和描述
A7: 二、审计过程：
A8: 1.向可比公司寄发询证函，获取公司相同或相似产品销售价格；
A9: 2.将公司的采购单价与可比公司的销售价格进行比较，分析关联方采购价格的公允性；
A10: 关联方：XXXX 产品A
A11: 月份 | B11: 产品规格 | C11: 采购价格 | D11: 可比采购价格 | H11: 采购价格是否合理
D12: 单位1 | E12: 单位2 | F12: 单位3 | G12: 单位4
A13: 1月
A14: 2月
A15: 3月
A16: 4月
A17: 5月
A18: 6月
A19: 7月
A20: 8月
A21: 9月
A22: 10月
A23: 11月
A24: 12月
A25: 关联方：XXXX 产品B
A26: 月份 | B26: 产品规格 | C26: 采购价格 | D26: 可比采购价格 | H26: 采购价格是否合理
D27: 单位1 | E27: 单位2 | F27: 单位3 | G27: 单位4
A28: 1月
A29: 2月
A30: 3月
A31: 4月
A32: 5月
A33: 6月
A34: 7月
A35: 8月
A36: 9月
A37: 10月
A38: 11月
A39: 12月
... A46: 该底稿也适用于非关联方之间采购交易的价格公允性测试。

Sheet 关联方采购定价公允性核查（市场价）F2-66
A1: 致同会计师事务所
A2: 关联方采购定价公允性核查（市场价）
A3: =底稿目录!A2 -> 被审计单位： | B3: =底稿目录!A4 -> 编制人： | D3: =底稿目录!A5 -> 编制日期： | E3: 索引号： | F3: =底稿目录!F17 -> F2-66
A4: =底稿目录!A3 -> 截止日：202X年12月31日 | B4: =底稿目录!A6 -> 复核人： | D4: =底稿目录!A7 -> 复核日期： | E4: 页 次：
A5: 一、审计目标：
A6: 存货以恰当的金额包括在财务报表中，与之相关的计价或分摊调整已恰当记录，相关披露已得到恰当计量和描述
A7: 二、审计过程：
A8: 1.获取关联采购产品可比市场价格。
A9: 2.将公司的采购价格与可比市场价格进行比较，分析关联方采购价格的公允性。
A10: 关联方：XXXX 产品A
A11: 月份 | B11: 采购均价 | C11: 市场价格（挂牌价）均价 | E11: 采购价格是否处于市场价区间
C12: 月初 | D12: 月末
A13: 1月
A14: 2月
A15: 3月
A16: 4月
A17: 5月
A18: 6月
A19: 7月
A20: 8月
A21: 9月
A22: 10月
A23: 11月
A24: 12月
A25: 关联方：XXXX 产品B
A26: 月份 | B26: 采购均价 | C26: 市场价格（挂牌价）均价 | E26: 采购价格是否处于市场价区间
C27: 月初 | D27: 月末
A28: 1月
A29: 2月
A30: 3月
A31: 4月
A32: 5月
A33: 6月
A34: 7月
A35: 8月
A36: 9月
A37: 10月
A38: 11月
A39: 12月
... A46: 该底稿也适用于非关联方之间采购交易的价格公允性测试。

Sheet 识别未披露的关联方F2-67
A1: 致同会计师事务所
A2: 识别未披露的关联方
A3: =底稿目录!A2 -> 被审计单位： | I3: =底稿目录!A4 -> 编制人： | N3: =底稿目录!A5 -> 编制日期： | Q3: 索引号： | R3: =底稿目录!F18 -> F2-67
A4: =底稿目录!A3 -> 截止日：202X年12月31日 | I4: =底稿目录!A6 -> 复核人： | N4: =底稿目录!A7 -> 复核日期： | Q4: 页 次：
A5: 一、审计目标：
A6: 主要或异常供应商（包括施工单位）是否与被审计单位存在关联方关系。
A7: 二、审计过程：
A8: 1.选择大额、异常的客户或交易。
A9: 2.查询供应商工商、银行、税务信息资料，关注其地址、董事/监事/关键管理人员、联系方式等信息，并与其相关发票信息、网站信息进行核对，识别供应商是否存在与被审计单位存在疑似关联关系的信息；
A10: 3.选取重要供应商，获取关联方关系确认函。
A11: 4.取得实际控制人、董高监及其密切家庭人员的对外投资清单，与重要客户的股东和关键经办人员进行比对，关注与发行人实际控制人、董事、监事、高级管理人员关系密切的家庭成员与发行人的供应商是否存在关联方关系。
A12: 5.取得保荐机构及其关联方、PE投资机构及其关联方、PE投资机构的股东或实际控制人控制或投资的其他企业清单，将这些利益相关方清单和重要供应商及其法人、股东和关键经办人员名单进行比对，关注其是否与发行人发生大额交易。
A13: 6.获取发行人主要股东、董事、监事、关键管理人员及上述利益相关方的确认函，确认除其本人在被审计单位领取薪酬或分得股利外，其本人及其关系密切的家庭成员未与被审计单位有任何形式的交易。
A14: 序号 | B14: 姓名 | C14: 个人供应商 | D14: 供应商法人 | E14: 合同签订人 | F14: 高管亲属 | G14: 财务部门 | H14: 管理部门 | I14: 技术部门 | J14: 生产部门 | K14: 营销部门 | L14: … | M14: 总计 | N14: 供应商与公司员工或高管或/和亲属重名（Y/N） | O14: 公司股东/高管/亲属/员工 | P14: 202X年度采购额 | Q14: 说明 | R14: 索引号
A15: 1 | B15: 陈XX | D15: 1 | J15: 1 | M15: =SUM(C15:L15) -> 2 | N15: Y | O15: 公司员工 | P15: 942.91
A16: 2 | B16: 李YY | C16: 1 | G16: 1 | M16: =SUM(C16:L16) -> 2 | N16: Y | O16: 公司股东 | P16: 557.16
A17: 3
A18: 4
A19: 5
A20: 6
A21: 7
A22: 8
A23: 9
A24: 10
A27: 三、审计说明：
A28: 1.公司的主要股东、高管、股东及高管的家属、公司员工名单见< >，主要概况：
A29: XX公司：高管亲属338；之财务部门65；之管理部门323；之技术部门686；之生产部门1344；之营销部门1165；
A30: 2.供应商的法人及关键管理人员名单见< >，主要概况：
A31: 个人供应商70；供应商法人1697；供应商合同签订人39。
A32: 3.对比后，有54个姓名存在重复，涉及127人，其中供应商60个；涉及2013年采购额约2.1亿元；
A33: 抽取采购额大于500万的个人供应商约11个，涉及27人；涉及2013年采购额约为1.43亿，占2013年总采购额的比例约为67.58%。
A34: 4.获取27人的身份证复印件；对身份证信息的身份证号码、家庭地址，做交叉对比。
A35: 核对未发现身份证号码、登记地址有和公司员工重复的现象。
A36: 四、审计结论：
A37: 未识别出重要供应商与公司存在关联方关系。
A41: 提示：
... A45: 3.获取公司的征信报告（人民银行系统），通过征信信息显示的公司高管任职或投资的公司，识别是否存在未披露的关联方以及关联交易。

Sheet 重要供应商结构分析F2-68
A1: 致同会计师事务所
A2: 重要供应商结构分析
A3: =底稿目录!A2 -> 被审计单位： | E3: =底稿目录!A4 -> 编制人： | J3: =底稿目录!A4 -> 编制人： | Q3: 索引号： | R3: =底稿目录!F19 -> F2-68
A4: =底稿目录!A3 -> 截止日：202X年12月31日 | E4: =底稿目录!A6 -> 复核人： | J4: =底稿目录!A6 -> 复核人： | Q4: 页 次：
A5: 本年（期）总采购金额 | C5: 0 | D5: 本年（期）总采购量 | G5: 0
A6: 序号 | B6: 本年（期）大额供应商名称 | C6: 采购金额 | D6: 占比 | E6: 采购数量 | F6: 占比 | G6: 上期排名 | H6: 合作年限 | I6: 采购产品名称 | J6: 合同主要条款 | O6: 合同执行情况 | P6: 是否关联方 | Q6: 采购金额是否与公司规模匹配 | R6: 采购产品是否属于供应商主营业务
J7: 采购金额 | K7: 信用期 | L7: 交货方式 | M7: 支付方式 | N7: 其他
A8: 1 | D8: =IF(ISERROR(C8/$C$5),0,C8/$C$5) -> 0 | F8: =IF(ISERROR(E8/$G$5),0,E8/$G$5) -> 0 | S8: 关联关系、供应商规模、供应商经营范围核查见<F2-70>
A9: 2 | D9: =IF(ISERROR(C9/$C$5),0,C9/$C$5) -> 0 | F9: =IF(ISERROR(E9/$G$5),0,E9/$G$5) -> 0
A10: 3 | D10: =IF(ISERROR(C10/$C$5),0,C10/$C$5) -> 0 | F10: =IF(ISERROR(E10/$G$5),0,E10/$G$5) -> 0
A11: 4 | D11: =IF(ISERROR(C11/$C$5),0,C11/$C$5) -> 0 | F11: =IF(ISERROR(E11/$G$5),0,E11/$G$5) -> 0
A12: 5 | D12: =IF(ISERROR(C12/$C$5),0,C12/$C$5) -> 0 | F12: =IF(ISERROR(E12/$G$5),0,E12/$G$5) -> 0
A13: 6 | D13: =IF(ISERROR(C13/$C$5),0,C13/$C$5) -> 0 | F13: =IF(ISERROR(E13/$G$5),0,E13/$G$5) -> 0
A14: 7 | D14: =IF(ISERROR(C14/$C$5),0,C14/$C$5) -> 0 | F14: =IF(ISERROR(E14/$G$5),0,E14/$G$5) -> 0
A15: 8 | D15: =IF(ISERROR(C15/$C$5),0,C15/$C$5) -> 0 | F15: =IF(ISERROR(E15/$G$5),0,E15/$G$5) -> 0
A16: 9 | D16: =IF(ISERROR(C16/$C$5),0,C16/$C$5) -> 0 | F16: =IF(ISERROR(E16/$G$5),0,E16/$G$5) -> 0
A17: 10 | D17: =IF(ISERROR(C17/$C$5),0,C17/$C$5) -> 0 | F17: =IF(ISERROR(E17/$G$5),0,E17/$G$5) -> 0
D18: =IF(ISERROR(C18/$C$5),0,C18/$C$5) -> 0 | F18: =IF(ISERROR(E18/$G$5),0,E18/$G$5) -> 0
D19: =IF(ISERROR(C19/$C$5),0,C19/$C$5) -> 0 | F19: =IF(ISERROR(E19/$G$5),0,E19/$G$5) -> 0
B20: 合 计 | C20: =SUM(C8:C19) -> 0 | D20: =SUM(D8:D17) -> 0 | E20: =SUM(E8:E19) -> 0 | F20: =SUM(F8:F17) -> 0 | J20: =SUM(J8:J19) -> 0 | Q20: 是 | R20: 是
A21: 上年（期）总采购金额 | D21: 上年（期）总采购量 | G21: 0
A22: 序号 | B22: 上年（期）大额供应商名称 | C22: 采购金额 | D22: 占比 | E22: 采购数量 | F22: 占比 | G22: 上期排名 | H22: 合作年限 | I22: 采购产品名称 | J22: 合同主要条款 | O22: 合同执行情况 | P22: 是否关联方 | Q22: 采购金额是否与公司规模匹配 | R22: 采购产品是否属于供应商主营业务
J23: 采购金额 | K23: 信用期 | L23: 交货方式 | M23: 支付方式 | N23: 其他
A24: 1 | D24: =IF(ISERROR(C24/$C$21),0,C24/$C$21) -> 0 | F24: =IF(ISERROR(E24/$G$21),0,E24/$G$21) -> 0
A25: 2 | D25: =IF(ISERROR(C25/$C$21),0,C25/$C$21) -> 0 | F25: =IF(ISERROR(E25/$G$21),0,E25/$G$21) -> 0
A26: 3 | D26: =IF(ISERROR(C26/$C$21),0,C26/$C$21) -> 0 | F26: =IF(ISERROR(E26/$G$21),0,E26/$G$21) -> 0
A27: 4 | D27: =IF(ISERROR(C27/$C$21),0,C27/$C$21) -> 0 | F27: =IF(ISERROR(E27/$G$21),0,E27/$G$21) -> 0
A28: 5 | D28: =IF(ISERROR(C28/$C$21),0,C28/$C$21) -> 0 | F28: =IF(ISERROR(E28/$G$21),0,E28/$G$21) -> 0
A29: 6 | D29: =IF(ISERROR(C29/$C$21),0,C29/$C$21) -> 0 | F29: =IF(ISERROR(E29/$G$21),0,E29/$G$21) -> 0
A30: 7 | D30: =IF(ISERROR(C30/$C$21),0,C30/$C$21) -> 0 | F30: =IF(ISERROR(E30/$G$21),0,E30/$G$21) -> 0
A31: 8 | D31: =IF(ISERROR(C31/$C$21),0,C31/$C$21) -> 0 | F31: =IF(ISERROR(E31/$G$21),0,E31/$G$21) -> 0
A32: 9 | D32: =IF(ISERROR(C32/$C$21),0,C32/$C$21) -> 0 | F32: =IF(ISERROR(E32/$G$21),0,E32/$G$21) -> 0
A33: 10 | D33: =IF(ISERROR(C33/$C$21),0,C33/$C$21) -> 0 | F33: =IF(ISERROR(E33/$G$21),0,E33/$G$21) -> 0
D34: =IF(ISERROR(C34/$C$21),0,C34/$C$21) -> 0 | F34: =IF(ISERROR(E34/$G$21),0,E34/$G$21) -> 0
D35: =IF(ISERROR(C35/$C$21),0,C35/$C$21) -> 0 | F35: =IF(ISERROR(E35/$G$21),0,E35/$G$21) -> 0
B36: 合 计 | C36: =SUM(C24:C35) -> 0 | D36: =SUM(D24:D33) -> 0 | E36: =SUM(E24:E35) -> 0 | F36: =SUM(F24:F33) -> 0 | J36: =SUM(J24:J35) -> 0
A37: 1、审计说明：
A38: 1.本年向前十名供应商的采购额较去年增加/减少%，主要是因为…………
A39: 2.关联关系、供应商规模、供应商经营范围核查见<F2-70>
A40: 2、审计结论：

Sheet 供应商核查清单F2-69
A1: 致同会计师事务所
A2: 供应商核查清单
A3: =[5]底稿目录!A2 -> 被审计单位：ABC公司 | F3: =[5]底稿目录!A4 -> 编制人：张XX | J3: =[5]底稿目录!A5 -> 编制日期：2024-4-1 | M3: 索引号： | N3: =底稿目录!F20 -> F2-69
A4: =[5]底稿目录!A3 -> 截止日：202X年12月31日 | F4: =[5]底稿目录!A6 -> 复核人：李XX | J4: =[5]底稿目录!A7 -> 复核日期：2024-5-1 | M4: 页 次：
A5: 一、审计目标：
A6: 1. 资产负债表中记录的存货是存在的，且已经记录在恰当的账户中；2. 所有应记录的存货均已记录，所有应当包括在财务报表中的相关披露均已包括
A7: 3. 记录的存货由被审计单位拥有或控制；4. 存货以恰当的金额包括在财务报表中，与之相关的计价或分摊调整已恰当记录，相关披露已得到恰当计量和描述
A8: 二、审计过程：
A9: 1.对比历年主要供应商清单，找出报告期新增的主要供应商、原有主要供应商交易额大幅减少或合作关系取消的情况，重点关注变化原因。
A10: 2.通过互联网搜索供应商的基本信息，初步了解供应商的经营范围、规模、判断所购货物是否与供应商的实际生产经营情况一致。
A11: 3.查询供应商工商、银行、税务资料，关注其注册资本、地址、成立时间、经营范围、法定代表人等信息，查看是否有重复的银行账号、地址等，并调查异常情况；并与其相关发票信息、网站信息进行核对。
A12: 4.现场走访供应商的办公场所、经营场所，访谈供应商关键经办人员。
A13: 三、拟定的核查方式如下表：
A14: 供应商名称 | B14: 选取原因 | C14: 交易额 | D14: 占总交易比重 | E14: 应付款项 | G14: 预付款项 | I14: 核查方式（√） | N14: 底稿索引号
E15: 期末余额 | F15: 占期末余额比重 | G15: 期末余额 | H15: 占期末余额比重 | I15: 工商资料查询 | J15: 互联网信息查询 | K15: 视频、电话访谈 | L15: 函证 | M15: 实地走访
A16: 供应商1 | B16: 新增主要供应商
A17: 供应商2 | B17: 第一大供应商
A18: 供应商3
A19: 供应商4
A20: 供应商5
A21: 供应商6
A22: 供应商7
A23: 供应商8
A24: 供应商9
A25: 供应商10
A26: ……
A27: 四、审计说明：
A30: 五、审计结论：
A34: 提示1：样本选取
... A49: 3.核查支持性证据的真实性，包括核查合同、货物交付凭据（如入库单、验收单、发票）、付款等资料及相关信息的一致性；重点关注相关签字及印章是否前后一致，以及供应商资质和注册资本的大小与其业务量的匹配性。

Sheet 供应商信息核查表F2-70
A1: 致同会计师事务所
A2: 供应商信息核查表
A3: =底稿目录!A2 -> 被审计单位： | E3: =底稿目录!A4 -> 编制人： | H3: =底稿目录!A5 -> 编制日期： | L3: 索引号： | M3: =底稿目录!F21 -> F2-70
A4: =底稿目录!A3 -> 截止日：202X年12月31日 | E4: =底稿目录!A6 -> 复核人： | H4: =底稿目录!A7 -> 复核日期： | L4: 页 次：
A5: 一、审计目标：
A6: 资产负债表中记录的存货是存在的，且已经记录在恰当的账户中
A7: 二、审计过程
A8: 1.查询供应商工商、银行、税务资料，关注其注册资本、地址、成立时间、经营范围、法定代表人等信息，并与其相关发票信息、网站信息进行核对。
A9: 2.通过互联网搜索供应商的基本信息，初步了解供应商的经营范围、规模、判断与公司采购金额和产品是否匹配。
A10: 3..……
A11: 检查项目 | C11: 供应商1 | D11: 供应商2 | E11: 供应商3 | F11: 供应商4 | G11: 供应商5 | H11: 供应商6 | I11: 供应商7 | J11: 供应商8 | K11: 供应商9 | L11: 供应商10 | M11: ……
A12: 统一社会信用代码
A13: 注册地址
A14: 办公地址
A15: 网站地址
A16: 网站IP地址
A17: 企业邮箱
A18: 成立时间
A19: 注册资本/实缴资本 | N19: 关注向供应商的采购金额是否与其经营规模、注册资本相符
A20: 经营范围 | N20: 关注被审计单位采购产品是否与供应商经营范围相匹配
A21: 人员规模/缴纳社保人数 | N21: 关注向供应商的采购金额是否与其人员规模相符
A22: 法定代表人
A23: 股东名称及 持股比例 | B23: 股东1及持股比例
B24: 股东2及持股比例
B25: 股东3及持股比例
B26: 股东4及持股比例
B27: 股东5及持股比例
B28: ……
A29: 关键管理人员 | B29: 董事长
B30: 总经理
B31: ……
A32: 关键经办人员
A35: 实际控制人
A36: 是否为关联方
A37: 是否同时为客户（含同一实际控制人）
A38: 经营状态
A39: 是否列入失信人
A40: 信息来源
A41: 三、审计说明：
A43: 四、审计结论：
...

Sheet 供应商访谈记录汇总表F2-71
A1: 致同会计师事务所
A2: 供应商访谈记录汇总表
A3: =底稿目录!A2 -> 被审计单位： | C3: =底稿目录!A4 -> 编制人： | E3: =底稿目录!A5 -> 编制日期： | G3: 索引号： | H3: =底稿目录!F22 -> F2-71
A4: =底稿目录!A3 -> 截止日：202X年12月31日 | C4: =底稿目录!A6 -> 复核人： | E4: =底稿目录!A7 -> 复核日期： | G4: 页 次：
A5: 项目 | B5: 供应商1 | C5: 供应商2 | D5: 供应商3 | E5: 供应商4 | F5: 供应商5 | G5: 供应商6 | H5: ……
A6: 访谈时间
A7: 访谈原因 | B7: 发行人第X大供应商/本期新增供应商/采购价格异常供应商/……
A8: 访谈方式 | B8: 实地走访/视频访谈/电话访谈/……
A9: 被访谈公司注册地址
A10: 实地走访公司地址
A11: 接受访谈人员及身份 | B11: 身份信息、职务信息、具体负责的工作等
A12: 参与访谈的审计人员
A13: 参与访谈的其他人员
A14: 访谈人员行程信息 | B14: 车票、机票、住宿发票复印件或照片，住宿酒店照片
A15: 是否现场函证
A16: 访谈关注要点
A17: 合同执行核对情况
A18: 交易金额核对是否一致
A19: 往来余额核对是否一致
A20: ……
A21: 访谈结论
A22: 访谈记录索引
A23: 提示1：走访的范围：主要客户和供应商（如前十名客户或供应商）；新增的主要客户；存在疑虑的重要客户及供应商；主要基建工程建造商
A24: 提示2：访谈需核对和注意事项
A25: 1.走访地址与注册地址是否一致？不一致的原因是否合理？公司基本情况是否与工商信息查询信息一致？走访的公司地址是否与百度地图等查询走访地址一致？
A26: 2.交易内容是否与走访公司实际业务范围一致？
... A34: 10.保留访谈对象身份证复印件、名片/工牌复印件、与访谈对象合影（厂区门口、仓库、车间等地）、走访公司工作现场照片

Sheet 供应商访谈记录F2-72
A1: 致同会计师事务所
A2: 供应商访谈记录
A3: =底稿目录!A2 -> 被审计单位： | C3: =底稿目录!A4 -> 编制人： | E3: =底稿目录!A5 -> 编制日期： | G3: 索引号： | H3: =底稿目录!F23 -> F2-72
A4: =底稿目录!A3 -> 截止日：202X年12月31日 | C4: =底稿目录!A6 -> 复核人： | E4: =底稿目录!A7 -> 复核日期： | G4: 页 次：
A5: 访谈对象：
A6: 访谈时间及地点：
A7: 参与人员：
A8: 访谈内容： | B8: 根据被审计单位实际情况、关注的供应商主要风险情况修改访谈内容
A9: 一、接受访谈人介绍，包括姓名、任职的公司、职务、具体负责的工作等
A12: 二、供应商基本情况（包括但不限于公司股东、管理层人员、主要业务及主要产品、所处行业、业务规模、人员规模、生产能力、经营场所面积等）
A15: 三、供应商与被审计单位何时开始开展的业务？通过什么渠道开始开展业务的？
A18: 四、供应商与被审计单位签订XXX合同，合同主要条款……，是否出现过纠纷？若存在纠纷，是如何解决的？
A21: 五、供应商202X年向被审计单位销售的货物有哪些？金额有多少？占供应商每年销售金额的比例是多少？交易价格如何确定？交货方式是什么？结算方式是什么？还有多少货款未支付？
A24: 六、供应商主要产品年销售量和销售金额是多少？主要客户有哪些？XX产品平均销售价格多少？
A27: 七、供应商向被审计单位销售的货物是否全部为供应商所生产？若不是，则自产、外购数量各是多少？外购厂家主要是哪些单位？
A30: 八、供应商除了上述与被审计单位业务以外，是否还存在其他的资金往来？
A33: 九、供应商（及其实际控制人）与被审计单位及其实际控制人XXX、董事XXX、监事XXX、高级管理人员XXX以及被审计单位的主要客户XXX等是否存在关联关系（包括持股、任职、亲属关系等）？是否存在业务和资金往来？
A37: 十、被审计单位支付XX元大额预付款原因？供应商收到预付款资金用途是什么？供货计划是什么？
A40: 十一、……
A43: 附：1.供应商盖章确认的工商登记证明文件、……
... A47: 参与访谈的各方人员签字：
A48: 接受访谈人员： | C48: 审计人员： | E48: 其他人员：
A51: 日期：
A52: 如果识别出供应商存在第三方配合实施财务舞弊的风险，则应要求供应商就其向注册会计师提供的资料、信息以及作出的陈述的
A53: 真实性和完整性进行承诺，并加盖供应商公章。（所有被访谈的供应商可参照执行要求提供承诺并在访谈记录加盖公章）
A54: “本公司向XX会计师事务所提供的信息和资料真实、完整，如存在虚假信息 或重大遗漏，本公司愿意承担一切法律责任”。
G56: XXX公司（盖章）
A59: 提示：
A60: 根据《中国注册会计师审计准则问题解答第18号——识别和应对第三方配合实施财务舞弊》，如果已经识别出走访对象存在可能配合被审计单位实施财务舞弊的迹象，
A61: 1.注册会计师需要更有针对性地计划实地走访工作以及设计访谈提纲，安排职业敏感性更强的项目组成员实施实地走访，在访谈前需要注意对访谈信息保密，并考虑在进行实地走访时实施以下程序：
A62: （1）选择多名或不同层级的人员访谈相同或类似问题，进行相互印证。
A63: （2）核实被询问人员是否与被审计单位存在特殊关系，如是否为被审计单位的前员工，或被审计单位的关联方。
A64: （3）对于被审计单位的供应商，关注其产成品中是否有被审计单位采购的产品。
A65: 2.针对识别出的第三方配合实施财务舞弊的风险，可以考虑采用跟函方式进行函证，观察函证处理过程，评估回函可靠性。

Sheet 访谈记录与核对示例
A1: 致同会计师事务所（特殊普通合伙）
A2: 访谈记录与核对
A3: =底稿目录!A2 -> 被审计单位： | E3: =底稿目录!A4 -> 编制人： | G3: =底稿目录!A5 -> 编制日期： | I3: 索引：
A4: =底稿目录!A3 -> 截止日：202X年12月31日 | E4: =底稿目录!A6 -> 复核人： | G4: =底稿目录!A7 -> 复核日期： | I4: 页次：
A5: 走访公司名称：
A6: 一、走访的公司基本信息 | H6: 〔随需填写〕
A7: 【XYZ公司的基本情况，包括：XYZ公司法定代表人、注册地、注册资本、成立时间，股权关系等；公司营业执照复印件或照片、公司章程等】
A8: 工商信息查询结果、天眼查等查询结果：
A10: 百度地图等查询走访地址的结果：
A12: 二、交易基本信息 | H12: 〔随需填写〕
A13: 【XYZ公司与发行人的业务关系，发生业务的起始时间、交易金额、交易量、交易量是否异常，若异常应在访谈结论中明确交易量异常变动的原因，XYZ公司原行业状况、与发行人的交易占XYZ公司的总交易比重（公司基本情况需通过获取XYZ公司工商资料，并与发行人记录情况、增值税发票、XYZ公司网站信息等核对】
A14: 如： | B14: 与发行人合作从2006年至今已超过了5年，XYZ公司主要从发行人采购AAA材料，最近三年一期（2010年、2011年、2012年）的交易量和交易金额，占总交易额比重分别为 ；三年的交易量、交易金额稳步上升，交易比重保持平稳，未见异常变动。发行人的销售员经常到访XYZ公司维护客户关系，两家公司的合作关系良好，均有继续合作发展的意愿。
B15: 检查了XYZ公司的营业执照、组织机构代码证、税务登记证、章程等工商资料（若为特许经营行业，应检查相应证照）并取得复印件，与发行人记录情况、增值税发票、XYZ公司网站的相关信息等核对一致。【若为新增、异常客户/供应商或关联方客户/供应商，考虑获取XYZ公司的工商登记资料、纳税资料、银行账户流水等资料，并了解公司的实际控制人、关键经办人员等相关情况进行核对分析，包括核对XYZ公司的经营业绩、银行账户往来是否与其声称的经营状况和营运能力、现金流量相关等】
B16: XYZ公司不是ABC的关联方
B17: XYZ公司今年对AAA材料的采购目标为3亿（含税），其中约有20%采购自发行人
B18: XYZ公司的业务区域主要集中在山西陕西地区
B19: XYZ公司所在行业具有季节性，春、夏、秋为旺季，冬为淡季；因此原材料采购呈现类似特征。
B20: ……
A21: 三、与发行人的主要合同条款核对 | H21: 〔随需填写〕
A22: 【询问及取得合同样本：核对XYZ公司与发行人的合同条款（交易模式、交易规模、付款方式、付款期限、运输条款、运输保险受益人、销售佣金比例、质保金比例、信用期等）】
A23: 如： | B23: 项目 | C23: 询问所得信息 | G23: 来自发行人合同条款
B24: 交易模式 | C24: 包销 | G24: 与合同条款一致
B25: 交易标的 | C25: AAA材料 | G25: 与合同条款一致
B26: 交易规模 | C26: 500-600吨（含税金额约5000-6000万） | D26: 500-600吨（含税金额约5000-6000万） | G26: 与合同条款一致
B27: 付款方式 | C27: 银行承兑汇票或银行转账 | G27: 与合同条款一致
B28: 预付款项及质保金
B29: 付款期限 | C29: 收货验收后，3个月内（较同行业稍优惠，行业平均约为2.5月，75天） | G29: 与合同条款一致
B30: 订货到发货时间 | C30: 1个月以内，基本在1周之内发货（一般每月发一次订单） | G30: 合同条款为1个月之内
B31: 佣金返利 | C31: 5-6%，每季度按5%结算一次，全年若超过6000万采购量，按全年5.5%结算差额部分，若超过7000万，按全年6%结算差额部分；每年4月份进行全年佣金返利。 | G31: 与合同条款一致
B32: 佣金水平 | C32: 略高于同行业的返利水平，行业平均为4.8-5.5% | G32: 与合同条款一致
B33: 运输方式及费用承担 | C33: 实际承运单位：。物流公司汽运运输，运输时间3-5天，运费由发行人负责；运费中含保险费，保险受益人为发行人 | G33: 与合同条款一致
B34: 交付方式 | C34: XYZ收到材料，验收合格后，在发行人的验收单和物流公司的运单上签字确认后，交付完毕 | G34: 与合同条款一致
B35: 质量保证 | C35: 收货验收后质保1个月 | G35: 与合同条款一致
B36: 验收或检验 | C36: 出具验收报告/验收单 | G36: 与凭证检查情况一致
B37: 退货、换货情况 | C37: 合作5年来，仅在3年前发生过一次质保期内的质量问题，换货解决，价值约为20万 | G37: 与从发行人处获取的信息一致
B38: 是否涉及委托加工
B39: 是否存在实物返利
B40: 现金交易情况
B41: 第三方收款/付款
B42: 代收款、代付款情况
...
