Workbook

Sheet 底稿目录
A1: 底稿开列时，可先在以下单元格填写有关内容，以便其他底稿引用有关数据：
A2: 被审计单位： | B2: 目录
A3: 会计期间：202X年度
A4: 编制人： | B4: 序号 | C4: 内容 | D4: 索引号 | E4: 备注
A5: 编制日期： | B5: 1 | C5: 实质性程序表 | D5: L8A
A6: 复核人： | B6: 2 | C6: 审定表 | D6: L8-1
A7: 复核日期： | B7: 4 | C7: 附注披露信息（上市公司） | F7: 无需打印
B8: 3 | C8: 附注披露信息（国企） | F8: 无需打印
A9: 关于工作底稿与审计程序索引号对应的说明 | B9: 5 | C9: 明细表 | D9: L8-2
A10: 1.编制的审计工作底稿应与审计程序对应。审计项目组应根据被审计单位实际情况和风险评估情况在实质性程序表中裁剪、修改或增加审计程序，根据实际执行的审计程序完成相应审计工作底稿，编制的工作底稿中应按自然顺序依次编制索引号，并通过唯一的索引号将与实质性程序表中的程序对应关联（即将工作底稿的索引号填入实质性程序表中的底稿索引号列）。 | B10: 6 | C10: 调整分录汇总 | D10: L8-3
B11: 8 | C11: 非金融机构利息支出测算表 | D11: L8-4
B12: 7 | C12: 截止性测试 | D12: L8-5
B13: 9 | C13: 财务费用检查表 | D13: L8-6
A14: 2.获取的支持性证据应与审计底稿或程序对应。审计项目组在完成底稿时获取的支持性证据应根据底稿索引号编制下一级按自然顺序排序的索引号（如D1-2-1、D1-2-2、……），并在底稿中说明引用的支持性证据、关联索引号。
A17: 3.工作底稿索引号的编码规则：实质性程序索引号按循环从“D”到“N”,循环内账户以顺序号排列，模板中底稿索引号按账户顺序+自然数顺序（即模板中索引号按二级自然顺序排列，如D1-1、D1-2、D1-3、……D1-N）。

Sheet 实质性程序表L8A
A1: 致同会计师事务所
A2: 财务费用实质性程序
A3: =底稿目录!A2 -> 被审计单位： | C3: =底稿目录!A4 -> 编制人： | E3: =底稿目录!A5 -> 编制日期： | H3: 索引号： | I3: =底稿目录!D5 -> L8A
A4: =底稿目录!A3 -> 会计期间：202X年度 | C4: =底稿目录!A6 -> 复核人： | E4: =底稿目录!A7 -> 复核日期： | H4: 页次：
A5: 一、本账户涉及的科目
A6: 财务费用
A7: 二、审计目标与认定的对应关系
A8: 审计目标 | G8: 财务报表的认定
A9: A. 利润表中记录的财务费用已发生，且与被审计单位有关，已记录于恰当的账户 | G9: 发生
A10: B. 所有应当记录的财务费用均已记录，所有应当包括在财务报表中的相关披露均已包括 | G10: 完整性
A11: C. 与财务费用有关的金额及其他数据已恰当记录，相关披露已得到恰当计量和描述 | G11: 准确性
A12: D. 财务费用已记录于正确的会计期间 | G12: 截止
A13: E. 已被恰当地汇总或分解且表述清楚，相关披露在按照企业会计准则的编制基础下是相关的、可理解的 | G13: 列报
A14: 三、计划实施的实质性程序
A15: 序号 | B15: 审计程序 | C15: 程序分类 | D15: 审计程序 | I15: 底稿索引号
D16: 发生 | E16: 完整性 | F16: 准确性 | G16: 截止 | H16: 列报 | J16: 根据被审计单位实际情况和风险评估情况裁剪、修改或增加审计程序
A17: 1 | B17: 获取或编制明细表、执行下列程序，并编制审定表：复核加计正确；将总金额与总账、明细账合计数核对相符；将本期财务费用明细表与上期审定数据进行比较，分析两期波动的原因及合理性。 | C17: 常规★ | D17: √ | E17: √ | F17: √ | I17: L8-1 /L8-2
A18: 2 | B18: 在使用手工编制、自定义信息报告、系统生成的非固定格式报告等由被审计单位生成的信息时，测试有关信息准确性和完整性，并考虑针对编制和维护由被审计单位生成的信息的相关控制实施控制测试，以评价该信息是否能够为实现审计目的提供基础。 | C18: 常规★ | E18: √ | F18: √ | I18: T1 / | J18: 可参见《审计手册》4.2.6，由被审计单位生成的信息可能是由系统生成的、或手工编制的、或二者兼而有之的方式生成的。例如，由被审计单位生成的信息可能包括： • 不涉及自定义的、由系统生成的报告（如，固定格式报告）； • 可能通过人工自定义的、由系统生成的报告，例如，（计算机）查询信息或特别定制的报告； • 手工编制的信息，例如，汇总信息的电子表格或用以支持分配、计算以及调节的电子表格； • 其他系统生成或手工编制的信息，例如，由被审计单位编制的客户发票； • 通过影印、拍摄、扫描或其他方式转换成电子形式的文件记录。
A19: 3 | B19: 对上期发生额的审计：结合本期审计确定财务费用的上期金额的截止是否恰当。（适用于首次承接） | C19: 备选 | G19: √ | J19: 由被审计单位生成的信息不包括： • 总分类账或明细分类账、试算平衡表、或经审计的财务报表； • 第三方（除了服务机构）的报表或报告，例如，原始银行对账单，或函证的回函； • 外部数据（例如，第三方发布的数据，如，定价来源）。
A20: 4 | B20: 关注会计政策、会计估计合理性、一贯性。关注其是否利用会计政策和会计估计及其变更操纵利润。 | C20: 常规★ | D20: √ | E20: √ | F20: √ | I20: L8-1 /L8-2
A21: 5 | B21: 结合货币资金审计，根据银行存款平均余额和存款平均利率复核利息收入； | C21: 常规★ | D21: √ | E21: √ | F21: √
A22: 6 | B22: 根据借款平均余额、平均借款利率测算当期利息费用，与账面记录进行比较，检查其准确性和完整性。 | C22: 常规★ | D22: √ | E22: √ | F22: √
A23: 7 | B23: 对金融机构借款、应付债券等利息费用，结合相关科目审计，复核金额是否一致、是否合理。 | C23: 常规★ | D23: √ | E23: √ | F23: √
A24: 8 | B24: 对非金融机构利息，根据借款金额、期限和利率测算利息费用金额计算是否正确，将利率同以前年度及同期市场平均利率进行比较分析是否合理。 | C24: 备选 | D24: √ | E24: √ | F24: √
A25: 9 | B25: 检查关联方交易：了解关联交易事项的目的、价格和条件，检查交易的支持性文件，同时向关联方或其他注册会计师函证重大的交易（包括担保和其他重要信息），以确认交易的真实性；必要时，向与交易相关的人员和机构（如银行、律师）函证或与其讨论有关信息；考虑是否存在未识别的关联方，关联交易和余额披露是否正确。 | C25: 常规★ | D25: √ | E25: √ | F25: √ | G25: √ | H25: √
A26: 10 | B26: 检查是否存在关联方或其他利益相关方代被审计单位承担资金成本、采用无偿或不公允的交易价格向被审计单位提供资金： （1）取得控股股东、实际控制人及其控制企业的财务报表，对于财务报表相关费用项目变动较大的，以及该等关联方与被审计单位存在资金往来的，询问其原因，关注费用发生真实性以及资金真实意图和流向； （3）调查并访谈实际控制人关于其投资领域、投资回报以及民间借贷、借贷用途、接受各类监管检查等方面的情况； （4）取得被审计单位及其实际控制人、控股股东、董事、监事、高管等关联方对“关联方代为支付成本费用进行利益输送的情形”出具的承诺书；如报告期内实际控制人转让拟IPO企业股份或转让其他企业股权且金额较大的，需了解股权转让资金的用途； | C26: IPO/上市/新三板/重组/舞弊应对 | D26: √ | E26: √ | F26: √ | G26: √ | H26: √
A27: 11 | B27: 截止测试：抽取资产负债表日前后若干张记账凭证，实施截止测试，存在异常迹象，应考虑是否有必要追加审计程序，对于重大跨期项目应作必要调整。 | C27: 常规★ | G27: √ | I27: L8-4 /L8-5
A28: 12 | B28: 检查与财务费用有关的的记账凭证和相应的支持性证据以确定交易的真实性，是否按规定进行相应的会计处理和披露。 | C28: 常规★ | D28: √ | F28: √ | I28: L8-7
A29: 13 | B29: 考虑是否存在超出被审计单位正常经营活动的重大、异常交易等，根据评估的舞弊风险等因素增加的审计程序。 | C29: IPO/上市/新三板/重组/舞弊应对
A30: 14 | B30: 检查财务费用是否已按企业会计准则或其他适用的规定在财务报表中做出恰当列报和披露。 | C30: 常规★ | H30: √ | I30: A1-1/A1-15 /A1-16

Sheet 审定表L8-1
A1: 致同会计师事务所
A2: 财务费用审定表
A3: =底稿目录!A2 -> 被审计单位： | E3: =底稿目录!A4 -> 编制人： | H3: =底稿目录!A5 -> 编制日期： | K3: 索引： | L3: =底稿目录!D6 -> L8-1
A4: =底稿目录!A3 -> 会计期间：202X年度 | E4: =底稿目录!A6 -> 复核人： | H4: =底稿目录!A7 -> 复核日期： | K4: 页次：
A5: 项目 | B5: 上期数 | F5: 本期数 | J5: 本期审定数与上期 审定数的比较 | L5: 原因分析
B6: 未审数 | C6: 账项调整 | D6: 重分类调整 | E6: 审定数 | F6: 未审数 | G6: 账项调整 | H6: 重分类调整 | I6: 审定数 | J6: 变动额 | K6: 变动率
A7: 利息费用总额 | B7: =SUMIF('明细表L8-2'!$A$9:$A$21,'审定表L8-1'!$A7,'明细表L8-2'!T$9:T$21) -> 0 | C7: =SUMIF('明细表L8-2'!$A$9:$A$21,'审定表L8-1'!$A7,'明细表L8-2'!U$9:U$21) -> 0 | D7: =SUMIF('明细表L8-2'!$A$9:$A$21,'审定表L8-1'!$A7,'明细表L8-2'!V$9:V$21) -> 0 | E7: =SUM(B7:D7) -> 0 | F7: =SUMIF('明细表L8-2'!$A$9:$A$21,'审定表L8-1'!$A7,'明细表L8-2'!N$9:N$21) -> 0 | G7: =SUMIF('明细表L8-2'!$A$9:$A$21,'审定表L8-1'!$A7,'明细表L8-2'!O$9:O$21) -> 0 | H7: =SUMIF('明细表L8-2'!$A$9:$A$21,'审定表L8-1'!$A7,'明细表L8-2'!P$9:P$21) -> 0 | I7: =SUM(F7:H7) -> 0 | J7: =I7-E7 -> 0 | K7: =IF(AND(E7=0,I7=0),0,IF(AND(E7=0,I7>0),1,J7/E7)) -> 0
A8: 减：利息资本化 | B8: =SUMIF('明细表L8-2'!$A$9:$A$21,'审定表L8-1'!$A8,'明细表L8-2'!T$9:T$21) -> 0 | C8: =SUMIF('明细表L8-2'!$A$9:$A$21,'审定表L8-1'!$A8,'明细表L8-2'!U$9:U$21) -> 0 | D8: =SUMIF('明细表L8-2'!$A$9:$A$21,'审定表L8-1'!$A8,'明细表L8-2'!V$9:V$21) -> 0 | E8: =SUM(B8:D8) -> 0 | F8: =SUMIF('明细表L8-2'!$A$9:$A$21,'审定表L8-1'!$A8,'明细表L8-2'!N$9:N$21) -> 0 | G8: =SUMIF('明细表L8-2'!$A$9:$A$21,'审定表L8-1'!$A8,'明细表L8-2'!O$9:O$21) -> 0 | H8: =SUMIF('明细表L8-2'!$A$9:$A$21,'审定表L8-1'!$A8,'明细表L8-2'!P$9:P$21) -> 0 | I8: =SUM(F8:H8) -> 0 | J8: =I8-E8 -> 0 | K8: =IF(AND(E8=0,I8=0),0,IF(AND(E8=0,I8>0),1,J8/E8)) -> 0
A9: 减：利息收入 | B9: =SUMIF('明细表L8-2'!$A$9:$A$21,'审定表L8-1'!$A9,'明细表L8-2'!T$9:T$21) -> 0 | C9: =SUMIF('明细表L8-2'!$A$9:$A$21,'审定表L8-1'!$A9,'明细表L8-2'!U$9:U$21) -> 0 | D9: =SUMIF('明细表L8-2'!$A$9:$A$21,'审定表L8-1'!$A9,'明细表L8-2'!V$9:V$21) -> 0 | E9: =SUM(B9:D9) -> 0 | F9: =SUMIF('明细表L8-2'!$A$9:$A$21,'审定表L8-1'!$A9,'明细表L8-2'!N$9:N$21) -> 0 | G9: =SUMIF('明细表L8-2'!$A$9:$A$21,'审定表L8-1'!$A9,'明细表L8-2'!O$9:O$21) -> 0 | H9: =SUMIF('明细表L8-2'!$A$9:$A$21,'审定表L8-1'!$A9,'明细表L8-2'!P$9:P$21) -> 0 | I9: =SUM(F9:H9) -> 0 | J9: =I9-E9 -> 0 | K9: =IF(AND(E9=0,I9=0),0,IF(AND(E9=0,I9>0),1,J9/E9)) -> 0
A10: 未确认融资费用 | B10: =SUMIF('明细表L8-2'!$A$9:$A$21,'审定表L8-1'!$A10,'明细表L8-2'!T$9:T$21) -> 0 | C10: =SUMIF('明细表L8-2'!$A$9:$A$21,'审定表L8-1'!$A10,'明细表L8-2'!U$9:U$21) -> 0 | D10: =SUMIF('明细表L8-2'!$A$9:$A$21,'审定表L8-1'!$A10,'明细表L8-2'!V$9:V$21) -> 0 | E10: =SUM(B10:D10) -> 0 | F10: =SUMIF('明细表L8-2'!$A$9:$A$21,'审定表L8-1'!$A10,'明细表L8-2'!N$9:N$21) -> 0 | G10: =SUMIF('明细表L8-2'!$A$9:$A$21,'审定表L8-1'!$A10,'明细表L8-2'!O$9:O$21) -> 0 | H10: =SUMIF('明细表L8-2'!$A$9:$A$21,'审定表L8-1'!$A10,'明细表L8-2'!P$9:P$21) -> 0 | I10: =SUM(F10:H10) -> 0 | J10: =I10-E10 -> 0 | K10: =IF(AND(E10=0,I10=0),0,IF(AND(E10=0,I10>0),1,J10/E10)) -> 0
A11: 减：未实现融资收益 | B11: =SUMIF('明细表L8-2'!$A$9:$A$21,'审定表L8-1'!$A11,'明细表L8-2'!T$9:T$21) -> 0 | C11: =SUMIF('明细表L8-2'!$A$9:$A$21,'审定表L8-1'!$A11,'明细表L8-2'!U$9:U$21) -> 0 | D11: =SUMIF('明细表L8-2'!$A$9:$A$21,'审定表L8-1'!$A11,'明细表L8-2'!V$9:V$21) -> 0 | E11: =SUM(B11:D11) -> 0 | F11: =SUMIF('明细表L8-2'!$A$9:$A$21,'审定表L8-1'!$A11,'明细表L8-2'!N$9:N$21) -> 0 | G11: =SUMIF('明细表L8-2'!$A$9:$A$21,'审定表L8-1'!$A11,'明细表L8-2'!O$9:O$21) -> 0 | H11: =SUMIF('明细表L8-2'!$A$9:$A$21,'审定表L8-1'!$A11,'明细表L8-2'!P$9:P$21) -> 0 | I11: =SUM(F11:H11) -> 0 | J11: =I11-E11 -> 0 | K11: =IF(AND(E11=0,I11=0),0,IF(AND(E11=0,I11>0),1,J11/E11)) -> 0
A12: 承兑汇票贴息 | B12: =SUMIF('明细表L8-2'!$A$9:$A$21,'审定表L8-1'!$A12,'明细表L8-2'!T$9:T$21) -> 0 | C12: =SUMIF('明细表L8-2'!$A$9:$A$21,'审定表L8-1'!$A12,'明细表L8-2'!U$9:U$21) -> 0 | D12: =SUMIF('明细表L8-2'!$A$9:$A$21,'审定表L8-1'!$A12,'明细表L8-2'!V$9:V$21) -> 0 | E12: =SUM(B12:D12) -> 0 | F12: =SUMIF('明细表L8-2'!$A$9:$A$21,'审定表L8-1'!$A12,'明细表L8-2'!N$9:N$21) -> 0 | G12: =SUMIF('明细表L8-2'!$A$9:$A$21,'审定表L8-1'!$A12,'明细表L8-2'!O$9:O$21) -> 0 | H12: =SUMIF('明细表L8-2'!$A$9:$A$21,'审定表L8-1'!$A12,'明细表L8-2'!P$9:P$21) -> 0 | I12: =SUM(F12:H12) -> 0 | J12: =I12-E12 -> 0 | K12: =IF(AND(E12=0,I12=0),0,IF(AND(E12=0,I12>0),1,J12/E12)) -> 0
A13: 汇兑损失 | B13: =SUMIF('明细表L8-2'!$A$9:$A$21,'审定表L8-1'!$A13,'明细表L8-2'!T$9:T$21) -> 0 | C13: =SUMIF('明细表L8-2'!$A$9:$A$21,'审定表L8-1'!$A13,'明细表L8-2'!U$9:U$21) -> 0 | D13: =SUMIF('明细表L8-2'!$A$9:$A$21,'审定表L8-1'!$A13,'明细表L8-2'!V$9:V$21) -> 0 | E13: =SUM(B13:D13) -> 0 | F13: =SUMIF('明细表L8-2'!$A$9:$A$21,'审定表L8-1'!$A13,'明细表L8-2'!N$9:N$21) -> 0 | G13: =SUMIF('明细表L8-2'!$A$9:$A$21,'审定表L8-1'!$A13,'明细表L8-2'!O$9:O$21) -> 0 | H13: =SUMIF('明细表L8-2'!$A$9:$A$21,'审定表L8-1'!$A13,'明细表L8-2'!P$9:P$21) -> 0 | I13: =SUM(F13:H13) -> 0 | J13: =I13-E13 -> 0 | K13: =IF(AND(E13=0,I13=0),0,IF(AND(E13=0,I13>0),1,J13/E13)) -> 0
A14: 减：汇兑收益 | B14: =SUMIF('明细表L8-2'!$A$9:$A$21,'审定表L8-1'!$A14,'明细表L8-2'!T$9:T$21) -> 0 | C14: =SUMIF('明细表L8-2'!$A$9:$A$21,'审定表L8-1'!$A14,'明细表L8-2'!U$9:U$21) -> 0 | D14: =SUMIF('明细表L8-2'!$A$9:$A$21,'审定表L8-1'!$A14,'明细表L8-2'!V$9:V$21) -> 0 | E14: =SUM(B14:D14) -> 0 | F14: =SUMIF('明细表L8-2'!$A$9:$A$21,'审定表L8-1'!$A14,'明细表L8-2'!N$9:N$21) -> 0 | G14: =SUMIF('明细表L8-2'!$A$9:$A$21,'审定表L8-1'!$A14,'明细表L8-2'!O$9:O$21) -> 0 | H14: =SUMIF('明细表L8-2'!$A$9:$A$21,'审定表L8-1'!$A14,'明细表L8-2'!P$9:P$21) -> 0 | I14: =SUM(F14:H14) -> 0 | J14: =I14-E14 -> 0 | K14: =IF(AND(E14=0,I14=0),0,IF(AND(E14=0,I14>0),1,J14/E14)) -> 0
A15: 减：汇兑损益资本化 | B15: =SUMIF('明细表L8-2'!$A$9:$A$21,'审定表L8-1'!$A15,'明细表L8-2'!T$9:T$21) -> 0 | C15: =SUMIF('明细表L8-2'!$A$9:$A$21,'审定表L8-1'!$A15,'明细表L8-2'!U$9:U$21) -> 0 | D15: =SUMIF('明细表L8-2'!$A$9:$A$21,'审定表L8-1'!$A15,'明细表L8-2'!V$9:V$21) -> 0 | E15: =SUM(B15:D15) -> 0 | F15: =SUMIF('明细表L8-2'!$A$9:$A$21,'审定表L8-1'!$A15,'明细表L8-2'!N$9:N$21) -> 0 | G15: =SUMIF('明细表L8-2'!$A$9:$A$21,'审定表L8-1'!$A15,'明细表L8-2'!O$9:O$21) -> 0 | H15: =SUMIF('明细表L8-2'!$A$9:$A$21,'审定表L8-1'!$A15,'明细表L8-2'!P$9:P$21) -> 0 | I15: =SUM(F15:H15) -> 0 | J15: =I15-E15 -> 0 | K15: =IF(AND(E15=0,I15=0),0,IF(AND(E15=0,I15>0),1,J15/E15)) -> 0
A16: 手续费及其他 | B16: =SUMIF('明细表L8-2'!$A$9:$A$21,'审定表L8-1'!$A16,'明细表L8-2'!T$9:T$21) -> 0 | C16: =SUMIF('明细表L8-2'!$A$9:$A$21,'审定表L8-1'!$A16,'明细表L8-2'!U$9:U$21) -> 0 | D16: =SUMIF('明细表L8-2'!$A$9:$A$21,'审定表L8-1'!$A16,'明细表L8-2'!V$9:V$21) -> 0 | E16: =SUM(B16:D16) -> 0 | F16: =SUMIF('明细表L8-2'!$A$9:$A$21,'审定表L8-1'!$A16,'明细表L8-2'!N$9:N$21) -> 0 | G16: =SUMIF('明细表L8-2'!$A$9:$A$21,'审定表L8-1'!$A16,'明细表L8-2'!O$9:O$21) -> 0 | H16: =SUMIF('明细表L8-2'!$A$9:$A$21,'审定表L8-1'!$A16,'明细表L8-2'!P$9:P$21) -> 0 | I16: =SUM(F16:H16) -> 0 | J16: =I16-E16 -> 0 | K16: =IF(AND(E16=0,I16=0),0,IF(AND(E16=0,I16>0),1,J16/E16)) -> 0
B17: =SUMIF('明细表L8-2'!$A$9:$A$21,'审定表L8-1'!$A17,'明细表L8-2'!T$9:T$21) -> 0 | C17: =SUMIF('明细表L8-2'!$A$9:$A$21,'审定表L8-1'!$A17,'明细表L8-2'!U$9:U$21) -> 0 | D17: =SUMIF('明细表L8-2'!$A$9:$A$21,'审定表L8-1'!$A17,'明细表L8-2'!V$9:V$21) -> 0 | E17: =SUM(B17:D17) -> 0 | F17: =SUMIF('明细表L8-2'!$A$9:$A$21,'审定表L8-1'!$A17,'明细表L8-2'!N$9:N$21) -> 0 | G17: =SUMIF('明细表L8-2'!$A$9:$A$21,'审定表L8-1'!$A17,'明细表L8-2'!O$9:O$21) -> 0 | H17: =SUMIF('明细表L8-2'!$A$9:$A$21,'审定表L8-1'!$A17,'明细表L8-2'!P$9:P$21) -> 0 | I17: =SUM(F17:H17) -> 0 | J17: =I17-E17 -> 0 | K17: =IF(AND(E17=0,I17=0),0,IF(AND(E17=0,I17>0),1,J17/E17)) -> 0
A18: 合计 | B18: =B7-B8-B9+B10-B11+B12+B13-B14-B15+B16 -> 0 | C18: =C7-C8-C9+C10-C11+C12+C13-C14-C15+C16 -> 0 | D18: =D7-D8-D9+D10-D11+D12+D13-D14-D15+D16 -> 0 | E18: =SUM(B18:D18) -> 0 | F18: =F7-F8-F9+F10-F11+F12+F13-F14-F15+F16 -> 0 | G18: =G7-G8-G9+G10-G11+G12+G13-G14-G15+G16 -> 0 | H18: =H7-H8-H9+H10-H11+H12+H13-H14-H15+H16 -> 0 | I18: =SUM(F18:H18) -> 0 | J18: =I18-E18 -> 0 | K18: =IF(AND(E18=0,I18=0),0,IF(AND(E18=0,I18>0),1,J18/E18)) -> 0
A19: TB数据：
A20: 差异： | B20: =B18-B19 -> 0 | C20: =C18-C19 -> 0 | D20: =D18-D19 -> 0 | E20: =E18-E19 -> 0 | F20: =F18-F19 -> 0 | G20: =G18-G19 -> 0 | H20: =H18-H19 -> 0 | I20: =I18-I19 -> 0
A21: 1.审计说明 | E21: .
A22: （1）财务费用本期较上期增加（负数为减少）：
A23: 主要原因（比例超过30%的）：
A25: （2）情况说明。
A27: 2.审计结论

Sheet 附注披露信息（上市公司）
A1: 致同会计师事务所
A2: 附注披露信息（上市公司）
A3: =底稿目录!A2 -> 被审计单位： | B3: =底稿目录!A4 -> 编制人： | C3: =底稿目录!A5 -> 编制日期： | D3: 索引： | E3: =底稿目录!D7 -> 0
A4: =底稿目录!A3 -> 会计期间：202X年度 | B4: =底稿目录!A6 -> 复核人： | C4: =底稿目录!A7 -> 复核日期： | D4: 页次： | E4: 1
A5: 财务费用（（按费用性质列示）（注：以下不存在的项目可以删除）
A6: 项 目 | B6: 本期发生额 | C6: 上期发生额
A7: ='明细表L8-2'!A9 -> 利息费用总额 | B7: ='明细表L8-2'!Q9 -> 0 | C7: ='明细表L8-2'!W9 -> 0
A8: ='明细表L8-2'!A10 -> 减：利息资本化 | B8: ='明细表L8-2'!Q10 -> 0 | C8: ='明细表L8-2'!W10 -> 0
A9: ='明细表L8-2'!A11 -> 利息费用 | B9: ='明细表L8-2'!Q11 -> 0 | C9: ='明细表L8-2'!W11 -> 0
A10: ='明细表L8-2'!A12 -> 减：利息收入 | B10: ='明细表L8-2'!Q12 -> 0 | C10: ='明细表L8-2'!W12 -> 0
A11: ='明细表L8-2'!A13 -> 利息净支出 | B11: ='明细表L8-2'!Q13 -> 0 | C11: ='明细表L8-2'!W13 -> 0
A12: ='明细表L8-2'!A16 -> 承兑汇票贴息 | B12: ='明细表L8-2'!Q16 -> 0 | C12: ='明细表L8-2'!W16 -> 0
A13: ='明细表L8-2'!A17 -> 汇兑损失 | B13: ='明细表L8-2'!Q17 -> 0 | C13: ='明细表L8-2'!W17 -> 0
A14: ='明细表L8-2'!A18 -> 减：汇兑收益 | B14: ='明细表L8-2'!Q18 -> 0 | C14: ='明细表L8-2'!W18 -> 0
A15: ='明细表L8-2'!A19 -> 减：汇兑损益资本化 | B15: ='明细表L8-2'!Q19 -> 0 | C15: ='明细表L8-2'!W19 -> 0
A16: ='明细表L8-2'!A20 -> 汇兑净损失 | B16: ='明细表L8-2'!Q20 -> 0 | C16: ='明细表L8-2'!W20 -> 0
A17: ='明细表L8-2'!A21 -> 手续费及其他 | B17: ='明细表L8-2'!Q21 -> 0 | C17: ='明细表L8-2'!W21 -> 0
A18: 合 计 | B18: ='明细表L8-2'!Q22 -> 0 | C18: ='明细表L8-2'!W22 -> 0
A19: 说明：
A20: 利息资本化金额已计入存货和在建工程。本期用于计算确定借款费用资本化金额的资本化率为XX%（上期：XX%）

Sheet 附注披露信息（国企）
A1: 致同会计师事务所
A2: 附注披露信息(国有企业)
A3: =底稿目录!A2 -> 被审计单位： | B3: =底稿目录!A4 -> 编制人： | C3: =底稿目录!A5 -> 编制日期： | D3: 索引： | E3: =底稿目录!D8 -> 0
A4: =底稿目录!A3 -> 会计期间：202X年度 | B4: =底稿目录!A6 -> 复核人： | C4: =底稿目录!A7 -> 复核日期： | D4: 页次： | E4: 1
A5: 财务费用
A6: 项 目 | B6: 本期发生额 | C6: 上期发生额
A7: ='明细表L8-2'!A9 -> 利息费用总额 | B7: ='明细表L8-2'!Q9 -> 0 | C7: ='明细表L8-2'!W9 -> 0
A8: ='明细表L8-2'!A10 -> 减：利息资本化 | B8: ='明细表L8-2'!Q10 -> 0 | C8: ='明细表L8-2'!W10 -> 0
A9: ='明细表L8-2'!A11 -> 利息费用 | B9: ='明细表L8-2'!Q11 -> 0 | C9: ='明细表L8-2'!W11 -> 0
A10: ='明细表L8-2'!A12 -> 减：利息收入 | B10: ='明细表L8-2'!Q12 -> 0 | C10: ='明细表L8-2'!W12 -> 0
A11: ='明细表L8-2'!A13 -> 利息净支出 | B11: ='明细表L8-2'!Q13 -> 0 | C11: ='明细表L8-2'!W13 -> 0
A12: ='明细表L8-2'!A16 -> 承兑汇票贴息 | B12: ='明细表L8-2'!Q16 -> 0 | C12: ='明细表L8-2'!W16 -> 0
A13: ='明细表L8-2'!A17 -> 汇兑损失 | B13: ='明细表L8-2'!Q17 -> 0 | C13: ='明细表L8-2'!W17 -> 0
A14: ='明细表L8-2'!A18 -> 减：汇兑收益 | B14: ='明细表L8-2'!Q18 -> 0 | C14: ='明细表L8-2'!W18 -> 0
A15: ='明细表L8-2'!A19 -> 减：汇兑损益资本化 | B15: ='明细表L8-2'!Q19 -> 0 | C15: ='明细表L8-2'!W19 -> 0
A16: ='明细表L8-2'!A20 -> 汇兑净损失 | B16: ='明细表L8-2'!Q20 -> 0 | C16: ='明细表L8-2'!W20 -> 0
A17: ='明细表L8-2'!A21 -> 手续费及其他 | B17: ='明细表L8-2'!Q21 -> 0 | C17: ='明细表L8-2'!W21 -> 0
A18: 合 计 | B18: ='明细表L8-2'!Q22 -> 0 | C18: ='明细表L8-2'!W22 -> 0

Sheet 明细表L8-2
A1: 致同会计师事务所
A2: 财务费用明细表
A3: =底稿目录!A2 -> 被审计单位： | I3: =底稿目录!A4 -> 编制人： | R3: =底稿目录!A5 -> 编制日期： | V3: 索引号： | W3: =底稿目录!D9 -> L8-2
A4: =底稿目录!A3 -> 会计期间：202X年度 | I4: =底稿目录!A6 -> 复核人： | R4: =底稿目录!A7 -> 复核日期： | V4: 页次：
A5: 一、审计目标:
A6: 1.所有应当记录的财务费用均已记录，所有应当包括在财务报表中的相关披露均已包括; | H6: 2.与财务费用有关的金额及其他数据已恰当记录，相关披露已得到恰当计量和描述; | O6: 3. 与财务费用有关的金额及其他数据已恰当记录，相关披露已得到恰当计量和描述
A7: 二、审计过程：
A8: 项目 | B8: 1月 | C8: 2月 | D8: 3月 | E8: 4月 | F8: 5月 | G8: 6月 | H8: 7月 | I8: 8月 | J8: 9月 | K8: 10月 | L8: 11月 | M8: 12月 | N8: 本期未审合计 | O8: 账项调整 | P8: 重分类调整 | Q8: 本期审定金额 | R8: 各项目占比 | S8: 与相关科目勾稽 | T8: 上期未审金额 | U8: 账项调整 | V8: 重分类调整 | W8: 上期审定金额
A9: 利息费用总额 | N9: =SUM(B9:M9) -> 0 | Q9: =N9+O9+P9 -> 0 | R9: =IF(Q9=0,0,Q9/$Q$22) -> 0 | W9: =T9+U9+V9 -> 0
A10: 减：利息资本化 | N10: =SUM(B10:M10) -> 0 | Q10: =N10+O10+P10 -> 0 | R10: =IF(Q10=0,0,Q10/$Q$22) -> 0 | W10: =T10+U10+V10 -> 0
A11: 利息费用 | B11: =B9-B10 -> 0 | C11: =C9-C10 -> 0 | D11: =D9-D10 -> 0 | E11: =E9-E10 -> 0 | F11: =F9-F10 -> 0 | G11: =G9-G10 -> 0 | H11: =H9-H10 -> 0 | I11: =I9-I10 -> 0 | ... M11: =M9-M10 -> 0 | N11: =SUM(B11:M11) -> 0 | O11: =O9-O10 -> 0 | P11: =P9-P10 -> 0 | Q11: =N11+O11+P11 -> 0 | R11: =IF(Q11=0,0,Q11/$Q$22) -> 0 | W11: =T11+U11+V11 -> 0
A12: 减：利息收入 | N12: =SUM(B12:M12) -> 0 | Q12: =N12+O12+P12 -> 0 | R12: =IF(Q12=0,0,Q12/$Q$22) -> 0 | W12: =T12+U12+V12 -> 0
A13: 利息净支出 | B13: =B11-B12 -> 0 | C13: =C11-C12 -> 0 | D13: =D11-D12 -> 0 | E13: =E11-E12 -> 0 | F13: =F11-F12 -> 0 | G13: =G11-G12 -> 0 | H13: =H11-H12 -> 0 | I13: =I11-I12 -> 0 | ... M13: =M11-M12 -> 0 | N13: =SUM(B13:M13) -> 0 | O13: =O11-O12 -> 0 | P13: =P11-P12 -> 0 | Q13: =N13+O13+P13 -> 0 | R13: =IF(Q13=0,0,Q13/$Q$22) -> 0 | W13: =T13+U13+V13 -> 0
A14: 未确认融资费用 | N14: =SUM(B14:M14) -> 0 | Q14: =N14+O14+P14 -> 0 | R14: =IF(Q14=0,0,Q14/$Q$22) -> 0 | W14: =T14+U14+V14 -> 0
A15: 减：未实现融资收益 | N15: =SUM(B15:M15) -> 0 | Q15: =N15+O15+P15 -> 0 | R15: =IF(Q15=0,0,Q15/$Q$22) -> 0 | W15: =T15+U15+V15 -> 0
A16: 承兑汇票贴息 | N16: =SUM(B16:M16) -> 0 | Q16: =N16+O16+P16 -> 0 | R16: =IF(Q16=0,0,Q16/$Q$22) -> 0 | W16: =T16+U16+V16 -> 0
A17: 汇兑损失 | N17: =SUM(B17:M17) -> 0 | Q17: =N17+O17+P17 -> 0 | R17: =IF(Q17=0,0,Q17/$Q$22) -> 0 | W17: =T17+U17+V17 -> 0
A18: 减：汇兑收益 | N18: =SUM(B18:M18) -> 0 | Q18: =N18+O18+P18 -> 0 | R18: =IF(Q18=0,0,Q18/$Q$22) -> 0 | W18: =T18+U18+V18 -> 0
A19: 减：汇兑损益资本化 | N19: =SUM(B19:M19) -> 0 | Q19: =N19+O19+P19 -> 0 | R19: =IF(Q19=0,0,Q19/$Q$22) -> 0 | W19: =T19+U19+V19 -> 0
A20: 汇兑净损失 | B20: =B17-B18-B19 -> 0 | C20: =C17-C18-C19 -> 0 | D20: =D17-D18-D19 -> 0 | E20: =E17-E18-E19 -> 0 | F20: =F17-F18-F19 -> 0 | G20: =G17-G18-G19 -> 0 | H20: =H17-H18-H19 -> 0 | I20: =I17-I18-I19 -> 0 | ... M20: =M17-M18-M19 -> 0 | N20: =SUM(B20:M20) -> 0 | O20: =O17-O18-O19 -> 0 | P20: =P17-P18-P19 -> 0 | Q20: =N20+O20+P20 -> 0 | R20: =IF(Q20=0,0,Q20/$Q$22) -> 0 | T20: =T17-T18-T19 -> 0 | U20: =U17-U18-U19 -> 0 | V20: =V17-V18-V19 -> 0 | W20: =T20+U20+V20 -> 0
A21: 手续费及其他 | N21: =SUM(B21:M21) -> 0 | Q21: =N21+O21+P21 -> 0 | R21: =IF(Q21=0,0,Q21/$Q$22) -> 0 | W21: =T21+U21+V21 -> 0
A22: 合计 | B22: =B13+B14-B15+B16+B20+B21 -> 0 | C22: =C13+C14-C15+C16+C20+C21 -> 0 | D22: =D13+D14-D15+D16+D20+D21 -> 0 | E22: =E13+E14-E15+E16+E20+E21 -> 0 | F22: =F13+F14-F15+F16+F20+F21 -> 0 | G22: =G13+G14-G15+G16+G20+G21 -> 0 | H22: =H13+H14-H15+H16+H20+H21 -> 0 | I22: =I13+I14-I15+I16+I20+I21 -> 0 | ... Q22: =Q13+Q14-Q15+Q16+Q20+Q21 -> 0 | R22: =IF(Q22=0,0,Q22/$Q$22) -> 0 | T22: =T13+T14-T15+T16+T20+T21 -> 0 | U22: =U13+U14-U15+U16+U20+U21 -> 0 | V22: =V13+V14-V15+V16+V20+V21 -> 0 | W22: =T22+U22+V22 -> 0
A23: 各月比例 | B23: =IF($N$22=0,0,B22/$N$22) -> 0 | C23: =IF($N$22=0,0,C22/$N$22) -> 0 | D23: =IF($N$22=0,0,D22/$N$22) -> 0 | E23: =IF($N$22=0,0,E22/$N$22) -> 0 | F23: =IF($N$22=0,0,F22/$N$22) -> 0 | G23: =IF($N$22=0,0,G22/$N$22) -> 0 | H23: =IF($N$22=0,0,H22/$N$22) -> 0 | I23: =IF($N$22=0,0,I22/$N$22) -> 0 | ... N23: =IF($N$22=0,0,N22/$N$22) -> 0 | R23: =IF(Q23=0,0,Q23/$Q$48) -> 0
A24: 三、审计说明： | K24: 8.将利息费用合计与各债务科目计提利息费用的金额进行勾稽核对
A25: 1.明细账、总账、报表数核对一致；与试算平衡表核对一致； | K25: 利息费用总额 | M25: =Q9 -> 0
A26: 2.根据借款平均余额XX与同期市场平均利率为XX测算利息费用，与账面记录进行比较，结果： | K26: 短期借款-利息费用
A27: 3.根据银行存款平均余额XX和同期市场平均存款利率测算利息收入，与账面利息收入进行核对，详见银行存款底稿XXX； | K27: 长期借款-利息费用
A28: 4.对于涉及借款费用资本化的，详见在建工程底稿XXX； | K28: 应付债券-利息费用
A29: 5.对于涉及贴现费用的，详见应收票据底稿XXX； | K29: 其他应付款-利息费用
A30: 6.对于金融机构的利息费用的测算，详见短期借款、长期借款、应付债券底稿XXX； | K30: ……
A31: 7.对于涉及汇兑损益的，结合各涉及外币核算科目的审计，确定汇兑损益/收益的总体合理性。 | K31: 合计 | M31: =SUM(M26:M30) -> 0
K32: 校验 | M32: =M25-M31 -> 0
A34: 四、审计结论：
A36: 提示：
A37: 1、本科目核算企业为筹集生产经营所需资金等而发生的筹资费用，包括利息费用(减利息收入)、汇兑损益以及相关的手续费等。
A38: 2、利息费用不包括企业在销售商品时给予客户的现金折扣（按可变对价的相关规定冲减当期收入）；
A39: 3、外币预收账款和预付账款均不满足货币性项目的定义，属于以历史成本计量的外币非货币性项目，企业在资产负债表日应当采用交易发生日的即期汇率折算，不产生汇兑损益。
A40: 4、为购建或生产满足资本化条件的资产发生的应予资本化的借款费用，在“在建工程”、“制造费用”等科目核算。
A41: 5、符合资本化条件的资产，是指需要经过相当长时间的购建或者生产活动才能达到预定可使用或者可销售状态的固定资产、投资性房地产和存货等资产。
A42: 购入即可使用的资产，或者购入后需要安装但所需安装时间较短的资产，或者需要建造或生产但建造或生产时间较短的资产，均不属于符合资本化条件的资产，例如企业取得的采矿权等。
...

Sheet 调整分录汇总L8-3
A1: 致同会计师事务所
A2: 财务费用调整分录汇总表
A3: =底稿目录!A2 -> 被审计单位： | C3: =底稿目录!A4 -> 编制人： | F3: =底稿目录!A5 -> 编制日期： | I3: 索引号： | J3: =底稿目录!D10 -> L8-3
A4: =底稿目录!A3 -> 会计期间：202X年度 | C4: =底稿目录!A6 -> 复核人： | F4: =底稿目录!A7 -> 复核日期： | I4: 页次：
A5: 调整事项说明 | B5: 类别（报表调整/账项调整/其他） | C5: 报表项目 | D5: 科目名称 | E5: 附注项目 | F5: …… | G5: 借方调整金额 | H5: 贷方调整金额 | I5: 索引 | J5: 备注
A21: 提示：本底稿适用于调整分录较多、较复杂的项目，且仅列示与本报表项目相关的审计调整。项目组可根据项目实际情况选择是否使用该底稿。

Sheet 非金融机构利息支出测算表L8-4
A1: 致同会计师事务所
A2: 非金融机构借款利息支出测算表
A3: =底稿目录!A2 -> 被审计单位： | D3: =底稿目录!A4 -> 编制人： | F3: =底稿目录!A5 -> 编制日期： | I3: 索引号： | J3: =底稿目录!D11 -> L8-4
A4: =底稿目录!A3 -> 会计期间：202X年度 | D4: =底稿目录!A6 -> 复核人： | F4: =底稿目录!A7 -> 复核日期： | I4: 页次：
A5: 一、审计目标:
A6: 1.利润表中记录的财务费用已发生，且与被审计单位有关，已记录于恰当的账户；
A7: 2.所有应当记录的财务费用均已记录，所有应当包括在财务报表中的相关披露均已包括；
A8: 3.与财务费用有关的金额及其他数据已恰当记录，相关披露已得到恰当计量和描述。
A9: 二、审计过程：
A10: 核算科目 | B10: 贷款单位 | C10: 实际借款日期 | D10: 实际还款日期 | E10: 年利率 | F10: 借款本金 | G10: 计息天数 | H10: 应计利息 | I10: 借款合同索引 | J10: 备 注
G11: =IF(C11=0,0,IF((D11-C11)=365,D11-C11,D11-C11+1)) -> 0 | H11: =E11*F11/365*G11 -> 0
G12: =IF(C12=0,0,IF((D12-C12)=365,D12-C12,D12-C12+1)) -> 0 | H12: =E12*F12/365*G12 -> 0
G13: =IF(C13=0,0,IF((D13-C13)=365,D13-C13,D13-C13+1)) -> 0 | H13: =E13*F13/365*G13 -> 0
G14: =IF(C14=0,0,IF((D14-C14)=365,D14-C14,D14-C14+1)) -> 0 | H14: =E14*F14/365*G14 -> 0
G15: =IF(C15=0,0,IF((D15-C15)=365,D15-C15,D15-C15+1)) -> 0 | H15: =E15*F15/365*G15 -> 0
A16: 合计 | F16: =SUM(F11:F15) -> 0 | G16: =SUM(G11:G15) -> 0 | H16: =SUM(H11:H15) -> 0
A17: 全年 账面利息支出金额 | B17: 利息计入财务费用
B18: 利息计入在建工程
B19: 利息计入开发成本
B20: 利息计入___________
A21: 合计 | D21: =D17+D18+D19+D20 -> 0
A22: 差异 | D22: =H16-D21 -> 0
A23: 三、审计说明：
A24: 1.将利率同以前年度及市场平均利率相比较……
A25: 2…….
A26: 四、审计结论：

Sheet 截止性测试L8-5
A1: 致同会计师事务所
A2: 财务费用截止性测试(从记账凭证至原始凭证）
A3: =底稿目录!A2 -> 被审计单位： | E3: =底稿目录!A4 -> 编制人： | G3: =底稿目录!A5 -> 编制日期： | J3: 索引号： | K3: =底稿目录!D12 -> L8-5
A4: =底稿目录!A3 -> 会计期间：202X年度 | E4: =底稿目录!A6 -> 复核人： | G4: =底稿目录!A7 -> 复核日期： | J4: 页 次：
A5: 一、审计目标：
A6: 确认财务费用已记录于正确的会计期间。
A7: 二、样本选取标准与规模：
A8: 1.抽取资产负债表日前后（____）天的（____）张记账凭证，实施截止性测试，评价费用是否被记录于正确的会计期间；
A9: 2.对于首次承接的客户，执行前期期末的截止性测试。（适用于首次承接）
A10: 提示：如果存在跨期舞弊风险或者所检查样本中发现有跨期的，应扩大测试期间和样本，甚至可以考虑将截止测试期间延长至审计报告日。同时考虑是否存在内控缺陷。
A11: 三、测试：
A12: 序号 | B12: 记账凭证 | G12: 支出凭单 | J12: 是否跨期 | K12: 跨期金额
B13: 日期 | C13: 凭证编号 | D13: 业务内容 | E13: 对方科目 | F13: 金额 | G13: 凭单编号 | H13: 凭单日期 | I13: 金额
A14: 1
A15: 2
A16: 3
A17: 4
A18: 5
A19: 6
A20: ……
A21: ——————截止日期：202X年12月31日——————
A22: 1
A23: 2
A24: 3
A25: 4
A26: 5
A27: 6
A28: ……
A29: 四、审计说明：
A32: 五、审计结论

Sheet 财务费用检查表L8-6
A1: 致同会计师事务所
A2: 财务费用检查表
A3: =底稿目录!A2 -> 被审计单位： | F3: =底稿目录!A4 -> 编制人： | I3: =底稿目录!A5 -> 编制日期： | P3: 索引号： | Q3: =底稿目录!D13 -> L8-6
A4: =底稿目录!A3 -> 会计期间：202X年度 | F4: =底稿目录!A6 -> 复核人： | I4: =底稿目录!A7 -> 复核日期： | P4: 页 次：
A5: 一、测试目标：
A6: 1.所有应当记录的财务费用均已记录，所有应当包括在财务报表中的相关披露均已包括;
A7: 2.与财务费用有关的金额及其他数据已恰当记录，相关披露已得到恰当计量和描述； 4. 财务费用已记录于正确的会计期间
A8: 二、测试： | C8: 测试原因：大额（）关联方（）大额交易频繁（）异常（）其他（）
A9: 测试内容说明：1.原始凭证是否齐全； 2.记账凭证与原始凭证是否相符；3.账务处理是否正确；4.是否记录于恰当的会计期间；5.……
A10: 费用明细项目 | B10: 记账凭证 | H10: 支持性文件 | J10: 核对内容 | O10: 索引号 | P10: 是否异常 | Q10: 备注说明
B11: 日期 | C11: 凭证编号 | D11: 业务内容 | E11: 对方科目 | F11: 对方明细科目 | G11: 借方金额 | J11: 1 | K11: 2 | L11: 3 | M11: 4 | N11: 5
A22: 合计 | G22: =SUM(G12:G21) -> 0
A23: 本期发生额 | G23: ='明细表L8-2'!Q22 -> 0
A24: 检查比例 | G24: =G22/G23 -> #DIV/0!
A25: 三、审计说明：
A28: 四、审计结论：
