Workbook

Sheet 底稿目录
A1: 底稿开列时，可先在以下单元格填写有关内容，以便其他底稿引用有关数据：
A2: 被审计单位： | D2: 序号 | E2: 内容 | F2: 索引号
A3: 会计期间：202X年度 | D3: 1 | E3: 营业收入审计程序表 | F3: D4A
A4: 编制人： | D4: 2 | E4: 营业收入审定表 | F4: D4-1
A5: 编制日期： | D5: 3 | E5: 附注披露信息（上市公司） | G5: 无需打印
A6: 复核人： | D6: 4 | E6: 附注披露信息（国企） | G6: 无需打印
A7: 复核日期： | D7: 5 | E7: 主营业务收入月度明细表 | F7: D4-2
D8: 6 | E8: 其他业务收入明细表 | F8: D4-3
A9: 关于工作底稿与审计程序索引号对应的说明 | D9: 7 | E9: 调整分录汇总表 | F9: D4-4
A10: 1.编制的审计工作底稿应与审计程序对应。审计项目组应根据被审计单位实际情况和风险评估情况在实质性程序表中裁剪、修改或增加审计程序，根据实际执行的审计程序完成相应审计工作底稿，编制的工作底稿中应按自然顺序依次编制索引号，并通过唯一的索引号将与实质性程序表中的程序对应关联（即将工作底稿的索引号填入实质性程序表中的底稿索引号列）。
A14: 2.获取的支持性证据应与审计底稿或程序对应。审计项目组在完成底稿时获取的支持性证据应根据底稿索引号编制下一级按自然顺序排序的索引号（如D1-2-1、D1-2-2、……），并在底稿中说明引用的支持性证据、关联索引号。
A17: 3.工作底稿索引号的编码规则：实质性程序索引号按循环从“D”到“N”,循环内账户以顺序号排列，模板中底稿索引号按账户顺序+自然数顺序（即模板中索引号按二级自然顺序排列，如D1-1、D1-2、D1-3、……D1-N）。

Sheet 营业收入审计程序表D4A
A1: 致同会计师事务所
A2: 营业收入实质性程序表
A3: =底稿目录!A2 -> 被审计单位： | D3: =底稿目录!A4 -> 编制人： | F3: =底稿目录!A5 -> 编制日期： | I3: 索引号： | J3: D4A
A4: =底稿目录!A3 -> 会计期间：202X年度 | D4: =底稿目录!A6 -> 复核人： | F4: =底稿目录!A7 -> 复核日期： | I4: 页 次：
A5: 一、本账户涉及的科目
A6: 主营业务收入、其他业务收入
A7: 二、审计目标与财务报表认定
A8: 审计目标 | H8: 财务报表的认定
A9: A.利润表中记录的营业收入已发生，且与被审计单位有关，已记录于恰当的账户 | H9: 发生
A10: B.所有应当记录的营业收入均已记录，所有应当包括在财务报表中的相关披露均已包括 | H10: 完整性
A11: C.与营业收入有关的金额及其他数据已恰当记录，相关披露已得到恰当计量和描述 | H11: 准确性
A12: D.与营业收入有关的交易和事项已记录于正确的会计期间 | H12: 截止性
A13: E.营业收入已被恰当地汇总或分解且表述清楚，相关披露在按照企业会计准则的编制基础下是相关的、可理解的 | H13: 列报
A14: 三、计划实施的实质性程序
A15: 序号 | B15: 对应Leap程序 | C15: 审计程序 | D15: 程序分类 | E15: 财务报表认定 | J15: 底稿索引号
E16: 发生 | F16: 完整性 | G16: 准确性 | H16: 截止性 | I16: 列报 | K16: 根据被审计单位实际情况和风险评估情况裁剪、修改或增加审计程序
A17: 1 | B17: 常规程序 | C17: 获取或编制主营业务收入、其他业务收入明细表编制审定表，并完成以下工作： （1）复核加计正确，将总金额与总账、明细账合计数核对相符； （2）检查以非记账本位币结算的营业收入的折算汇率及折算是否正确。 | D17: 常规★ | E17: √ | F17: √ | G17: √ | J17: D4-1 /D4-2 /D4-3
A18: 2 | B18: 常规程序 | C18: 如果被审计单位存在销售业务系统，核对财务账面记录的营业收入数据与销售系统（ERP业务数据）记录是否相符（双向核对）。 | D18: 备选 | E18: √ | F18: √ | G18: √ | J18: D4-13
A19: 3 | B19: IPE程序 | C19: 在使用手工编制、自定义信息报告、系统生成的非固定格式报告等由被审计单位生成的信息时，测试有关信息准确性和完整性，并考虑针对编制和维护由被审计单位生成的信息的相关控制实施控制测试，以评价该信息是否能够为实现审计目的提供基础。 | D19: 常规★ | F19: √ | G19: √ | J19: T1 | K19: 可参见《审计手册》4.2.6，由被审计单位生成的信息可能是由系统生成的、或手工编制的、或二者兼而有之的方式生成的。例如，由被审计单位生成的信息可能包括： • 不涉及自定义的、由系统生成的报告（如，固定格式报告）； • 可能通过人工自定义的、由系统生成的报告，例如，（计算机）查询信息或特别定制的报告； • 手工编制的信息，例如，汇总信息的电子表格或用以支持分配、计算以及调节的电子表格； • 其他系统生成或手工编制的信息，例如，由被审计单位编制的客户发票； • 通过影印、拍摄、扫描或其他方式转换成电子形式的文件记录。
A20: 4 | B20: 期初余额 | C20: 对上期发生额的审计：（适用于首次承接）： （1）向被审计单位人员询问前期期末关于收入截止的相关处理； （2）复核资产负债表日前后一段合理期间里的销售分录，调查任何异常分录。 （3）复核资产负债表日前后一段合理期间里销售退回或销售折扣的记录。 （4）调查接近前期期末发生的大额或异常的销售交易。 （5）必要时执行函证程序。 | D20: 备选 | E20: √ | F20: √ | G20: √ | H20: √ | K20: 由被审计单位生成的信息不包括： • 总分类账或明细分类账、试算平衡表、或经审计的财务报表； • 第三方（除了服务机构）的报表或报告，例如，原始银行对账单，或函证的回函； • 外部数据（例如，第三方发布的数据，如，定价来源）。
A21: 5 | B21: 常规程序/应对措施-会计估计 | C21: 了解被审计单位收入类型，充分了解公司经销售模式，针对不同业务或模式，检查收入确认政策的合理性及与前期的一致性。关注周期性、偶然性的收入是否符合既定的收入确认原则、方法。必要时，与同行业其他公司的会计政策进行对比。 | D21: 常规★ | E21: √ | G21: √ | J21: D4-5 | K21: 营业收入中由被审计单位生成的信息例如：在使用被审计单位提供的发票清单、销售价格表、运输清单等被审计单位提供信息
A22: 6 | B22: 应对措施-实质性/非实质性分析程序 | C22: 实施分析程序： （1）计算本期重要的比率指标：赊销率、应收账款周转率、末月销售情况/当期销售（金额或销量）、重要客户的销售额/销售额等，与可比期间数据、预算数或同行业其他企业数据进行比较； （2）结合收入来源和销售模式，按照产品类别、业务模式、销售区域（如境内、海外）等将本期的主营业务收入与上期的主营业务收入进行比较，分析销售收入结构和价格变动是否异常，是否符合行业和市场同期的变化情况； （3）分月或分季度比较本期主营业务收入波动情况，分析其变动趋势是否正常，是否符合被审计单位季节性、周期性的经营规律，查明异常现象和重大波动的原因； (4）计算本期重要产品的各月毛利率，与上期毛利率进行比较，分析变动原因，关注是否存在显著异常，必要时应与同行业比较； （5）就不同业务模式比较分析主要客户的销售数量、销售金额及占比的变动以及原因，关注是否存在异常。 （6）比较主要客户主要产品销售单价与销售平均价格（或指导价）、同类产品市场价格差异，分析价格合理性，判断有无以低价或高价结算的方法，相互之间有无转移利润的现象。 （7）比较关联方客户销售价格与非关联方销售价格的差异，分析关联方销售价格合理性，判断有无以低价或高价结算的方法，相互之间有无转移利润的现象。 (8)获取产品销售价格目录，与上期末相关文件进行对比分析，选取定价有较大或异常变化的产品进行测试，检查售价变动是否符合定价政策，价格变动是否合理。 | D22: 常规★ | E22: √ | F22: √ | G22: √ | J22: D4-6 /D4-7 /D4-8 /D4-9 /D4-10 /D4-11
A23: 7 | B23: 常规程序(选择“存在重大合同”) | C23: 选取重要合同进行检查： （1）了解与重要合同相关的交易，包括商业理由（或缺乏商业理由）和经济实质； （2）检查重要合同并记录关键条款和条件，判断合同条款的合理性，考虑是否可能存在抽屉协议等； （3）检查重要合同价格，确定是否符合销售及信用管理政策，并测试交易价格的确定是否正确。考虑代第三方收取的款项、预期将退还给客户的款项，以及可变对价（如现金折扣、数量折扣、价格折让等）、合同中存在的重大融资成分、非现金对价、应付客户对价等因素的影响。 （4）判断履约义务识别、交易价格的确定、交易价格分摊、收入控制权转移时点或期间等是否恰当。 （5）判断是否涉及特定交易，例如：附有质量保证条款的销售、附有销售退回条款的销售、主要责任人和代理人、售后回购交易、分期收款销售、寄售商品、以旧换新、授予知识产权，客户未行使的权利等； （6）确定合同是否表明存在以前未识别或未披露的关联方或重大关联方交易、超过被审计单位正常经营过程的交易以及与审计有关的其他问题； （7）确定交易是否按合同条款履行。 | D23: 常规★ | E23: √ | G23: √ | J23: D4-12
A24: 8 | B24: 应对措施-检查 | C24: 采用恰当的抽样方法，选择样本检查时点法收入确认依据（出库单、验收单、物流运输单、发票等）是否充分，记账是否正确；检查时段法的履约进度确认方法是否恰当，前后期是否一致，检查履约进度确认收入依据（监理报告、履约进度审核报告、竣工验收报告、结算资料等）是否充分，记账是否正确。 | D24: 常规★ | E24: √ | G24: √ | H24: √ | J24: D4-14
A25: 9 | B25: 应对措施-检查 | C25: 针对重要出口业务收入： （1）将销售记录与合同、报关单、装箱单、提单、发票、结汇单、物流运输单等出口销售单据进行核对； （2）使用电子口岸卡登陆电子口岸的信息系统，查询交易记录。 （3）必要时，向海关函证出口交易信息。 | D25: 备选 | E25: √ | G25: √ | H25: √ | J25: D4-14 /D4-16
A26: 10 | B26: 应对措施-检查 | C26: 针对电商、游戏等互联网行业等，应充分了解其具体的运营模式、盈利模式、不同参与主体间的责任分担等情况，结合IT审计检查收入数据、结算数据的真实性、完整性、准确性。 | D26: 备选 | E26: √ | G26: √
A27: 11 | B27: 应对措施-检查 | C27: 针对大额现金交易： （1）分析现金收付合理性，是否与行业特征和实际生产经营情况一致。 （2）获取公司报告期内存在现金销售的原因分析，分析被审计单位关于现金交易的相关说明是否合理。与对公司关键人员访谈、生产销售流程观察等程序获取的信息核对。 （3）逐月统计最近三年内现金销售收款金额，核查现金收款异常波动的原因，根据被审计单位情况分层统计分析，并对最近一年现金销售收入进行概要分析； （4）选择大额或异常现金交易，进行测试，核对付款方和付款金额与合同、订单、出库单是否一致，款项是否确实由客户支付。记录主要信息，必要的留存复印件；未见异常的项目，按照随机抽样的原则抽取一定比例，进行测试。必要时，实施函证程序。 | D27: 备选 | E27: √ | G27: √ | H27: √
A28: 12 | B28: 应对措施-检查 | C28: 销售的截止测试： （1）获取资产负债表日前后若干笔会计记录，与发货单证等信息核对，确定收入是否记入了恰当的期间。 （2）获取资产负债表日前后若干张发货单，与会计记录信息核对，确定是否存在收入跨期。 （3）复核资产负债表日前后的销售和发货水平，与正常水平相比是否存在异常，并考虑是否追加截止性测试。 （4）浏览期后一定时间的总账和明细账，以发现是否存在销售收 入冲回或大额销售退回的情况，对期后的大宗或异常的销售退货、冲回进行检查，以确定是否提前确认收入。 （5）结合存货监盘，对于尚未发运的销售（如开出账单但保管商品），查核支持性文件，与客户适当人员讨论，检查是否满足收入确认条件及会计处理的正确性。 | D28: 常规★ | H28: √ | J28: D4-17 /D4-18
A29: 13 | B29: 应对措施-检查 | C29: 销售折扣与折让： (1)获取或编制销售折扣与折让明细表，复核加计正确，并与明细账合计数核对相符； (2)取得被审计单位有关折扣与折让的具体规定和其他文件资料，并抽查较大的折扣发生额的授权批准情况，与实际执行情况进行核对； (3)检查折扣与折让是否及时足额提交对方，有无虚设中介、转移收入、私设账外“小金库”等情况； (4)检查折扣与折让的会计处理是否正确。 | D29: 常规★ | G29: √ | J29: D4-19
A30: 14 | B30: 应对措施-检查 | C30: 存在销货退回的，分析被审计单位对于退货率的估计是否合理，应付退货款、应收退货成本的会计处理是否正确；检查手续是否符合规定，结合原始销售凭证检查其会计处理是否正确；结合存货项目审计关注其真实性。 | D30: 常规★ | E30: √ | G30: √ | H30: √ | J30: D4-20
A31: 15 | B31: 常规程序(选择“存在关联交易”) | C31: 检查关联交易： (1)了解交易的商业理由、交易事项的目的、价格和条件，考虑对关联方销售的合理性、合法性； (2）检查证实交易的支持性文件（例如合同、发票、运输单据等），检查价格公允性，合同条款是否与非关联方一致； （考虑向关联方或其他注册会计师函证重大的关联采购交易和余额（包括担保和其他重要信息）； （4）必要时，向与交易相关的人员和机构（如银行、律师）函证或与其讨论有关信息； （5）考虑是否存在未识别的关联方，关联交易和余额披露是否正确。 | D31: 常规★ | E31: √ | F31: √ | G31: √ | I31: √ | J31: D4-21
A32: 16 | C32: 根据评估的舞弊风险等因素增加的审计程序。 | D32: IPO/上市/新三板/重组/舞弊应对 | J32: D4-22A
A33: 17 | C33: 检查营业收入是否已按企业会计准则或其他适用的规定在财务报表中做出恰当列报和披露。 | D33: 常规★ | I33: √ | J33: A 1-1/A1-15 /A1-16
C34: 针对其他业务收入，考虑执行以下程序：
A35: 18 | B35: 常规程序/应对措施-会计估计 | C35: 了解其他业务收入的业务内容，判断其分类为其他业务收入是否恰当。获取并了解被审计单位其他业务收入确认相关的会计政策，并与上年相比较是否存在重大差异变化。 | D35: 常规★ | E35: √ | J35: D4-3 /D4-5
A36: 19 | B36: 应对措施-实质性/非实质性分析程序 | C36: 计算本期其他业务收入与其他业务成本的比率和毛利率,并与上期该比率比较，检查是否有重大波动，如有，应查明原因。 | D36: 常规★ | E36: √ | F36: √ | G36: √ | J36: D4-33
A37: 20 | B37: 应对措施-检查 | C37: 获取其他业务收入合同，检查合同主要条款，考虑商业实质和合理性；重新计算出租、咨询等服务合同收入金额是否正确。 | D37: 常规★ | E37: √ | F37: √ | G37: √ | H37: √ | J37: D4-34
A38: 21 | B38: 应对措施-检查 | C38: 对于大额其他业务收入，检查支持性文件，分析交易实质，确定是否符合收入确认条件、会计处理是否正确。 | D38: 常规★ | E38: √ | G38: √ | H38: √ | J38: D4-35
A39: 22 | B39: 应对措施-检查 | C39: 抽取资产负债表日前后若干天、一定金额以上的其他业务收入记账凭证与发货单等信息核对，确定其他业务收入是否记入了恰当的期间；抽取资产负债表日前后若干天、一定金额以上的发货单等与记账凭证核对，确定其他业务收入是否记入了恰当的期间； | D39: 常规★ | H39: √ | J39: D4-36

Sheet 主营业务收入审计程序表D4A（修订前）
A1: 致同会计师事务所
A2: 主营业务收入实质性程序表
A3: 客户名称： | D3: 编制人： | G3: 编制日期： | J3: 索引号：D4A
A4: 会计期间：2024年度 | D4: 复核人： | G4: 复核日期： | J4: 页 次：
A5: 一、本账户涉及的科目
A6: 主营业务收入
A7: 二、重大错报风险需从实质性程序获取的保证程度 | K7: 按照统一格式修改
A8: 审计目标与认定对应关系 | D8: 财务报表的认定 | I8: 信赖/不信赖/不适用 | J8: 索引号
D9: 发生 | E9: 完整性 | F9: 准确性 | G9: 分类 | H9: 列报与披露
A10: A. 利润表中记录的主营业务收入已发生，且与被审计单位有关。 | D10: √
A11: B. 所有应当记录的主营业务收入均已记录。 | E11: √
A12: C. 与主营业务收入有关的金额及其他数据已恰当记录于正确的会计期间。 | F12: √
A13: D. 主营业务收入已记录于恰当的账户。 | G13: √
A14: E. 主营业务收入已按照企业会计准则的规定在财务报表中作出恰当的列报和披露。 | H14: √
A15: 三、计划实施的实质性程序
A16: 序号 | B16: 对应Leap程序 | C16: 审计程序 | D16: 程序分类 | E16: 审计目标 | I16: 执行情况说明 （含底稿索引）
A17: （一） | B17: 常规程序 | C17: 编制审定表 | D17: 常规★ | E17: B | I17: D4 | L17: 编制审定表，将主营业务收入、其他业务收入与报表数核对相符。
A18: 1 | B18: =B17 -> 常规程序 | C18: 结合其他业务收入科目，将主营业务收入与报表数核对相符 | D18: 常规★ | E18: E | H18: √ | I18: D5-1
A19: （二） | B19: 常规程序 | C19: 获取或编制主营业务收入明细表。 | D19: 常规★ | E19: B | I19: D4-2 | K19: 整合成一条 | L19: 获取或编制主营业务收入明细表，并完成以下工作：复核加计正确；将总金额与总账、明细账合计数核对相符；检查以非记账本位币结算的主营业务收入的折算汇率及折算是否正确。
A20: 1 | B20: =B17 -> 常规程序 | C20: 复核加计正确。 | D20: 常规★ | E20: B
A21: 2 | B21: =B17 -> 常规程序 | C21: 将总金额与总账、明细账合计数核对相符。 | D21: 常规★ | E21: B
A22: 3 | B22: =B17 -> 常规程序 | C22: 检查以非记账本位币结算的主营业务收入的折算汇率及折算是否正确。 | D22: 常规 | E22: C
A23: （三） | B23: IPE程序 | C23: 在使用被审计单位生成的信息（IPE）时，应当评价该信息对实现审计目的是否足够可靠，包括根据具体情况在必要时实施下列程序： | D23: 常规★ | E23: BC | I23: T1 | K23: 修改 | L23: IPE写的不具体，建议要么写具体或者作为审计提示，要么就删除，仅在T1中做
A24: 1 | B24: IPE程序 | C24: 获取有关信息准确性和完整性的审计证据。
A25: 2 | B25: IPE程序 | C25: 评价信息对实现审计目的是否足够准确和详细。
A26: （四） | B26: 期初余额 | C26: 测试上期主营业务收入发生额。（适用于首次承接） | D26: 备选 | E26: A | I26: S3 | K26: 整合 | L26: 对上期发生额的审计（适用于首次承接）： （1）向被审计单位人员询问前期期末关于收入截止的相关处理； （2）复核资产负债表日前后一段合理期间里的销售分录，调查任何异常分录。 （3）复核资产负债表日前后一段合理期间里销售退回或销售折扣的记录。 （4）调查接近前期期末发生的大额或异常的销售交易。 （5）必要时，对上期收入函证。
A27: 1 | B27: 期初余额 | C27: 向被审计单位人员询问前期期末关于收入截止的相关处理。 | D27: 备选 | E27: A
A28: 2 | B28: 期初余额 | C28: 复核资产负债表日前后一段合理期间里的销售分录，调查任何异常分录。 | D28: 备选 | E28: A
A29: 3 | B29: 期初余额 | C29: 复核资产负债表日前后一段合理期间里销售退回或销售折扣的记录。 | D29: 备选 | E29: A
A30: 4 | B30: 期初余额 | C30: 调查接近前期期末发生的大额或异常的销售交易。 | D30: 备选 | E30: A
A31: （五） | B31: 应对措施-实质性/非实质性分析程序 | C31: 对主营业务收入实施分析程序： | D31: 常规★ | E31: A
A32: 1 | B32: 应对措施-实质性/非实质性分析程序 | C32: 结合被审计单位业务特点和其主要客户基本经营信息，分析其客户购买力、结构变化和销售波动情况，是否存在客户异常采购的情况；与其客户信息披露核对。 | D32: 常规★ | E32: A | K32: 舞弊 | L32: 实施分析性程序： (1)结合收入来源和销售模式，按照产品类别、业务模式、销售区域（如境内、海外）等将本期的主营业务收入与上期的主营业务收入进行比较，分析销售收入结构和价格变动是否异常，是否符合行业和市场同期的变化情况；； (2)计算本期重要产品的毛利率，与上期和同行业进行比较，分析变动原因，关注是否存在显著异常。 (3)分月或分季度比较本期各类主营业务收入、毛利率等波动情况，分析其变动趋势是否正常，是否符合被审计单位季节性、周期性的经营规律，查明异常现象和重大波动的原因 （4）计算本期重要的比率指标：赊销率、应收账款周转率、末月销售情况/当期销售（金额或销量）、重要客户的销售额/销售额等，与可比期间数据、预算数或同行业其他企业数据进行比较。 （5）就不同业务模式比较分析主要客户的销售数量、销售金额及占比的变动以及原因，关注是否存在异常。 （6）比较主要客户主要产品销售单价与销售平均价格（或指导价）、同类产品市场价格差异，分析价格合理性，判断有无以低价或高价结算的方法，相互之间有无转移利润的现象。 （7）比较关联方客户销售价格与非关联方销售价格的差异，分析关联方销售价格合理性，判断有无以低价或高价结算的方法，相互之间有无转移利润的现象。 (8)获取产品销售价格目录，与上期末相关文件进行对比分析，选取定价有较大或异常变化的产品进行测试，检查售价变动是否符合定价政策，价格变动是否合理。 | M32: 第一段话来源于审计准则应用指南《分析性程序》
A33: 2 | B33: 应对措施-实质性/非实质性分析程序 | C33: 结合收入来源和销售模式，按照业务模式或销售区域（如境内、海外）对报告期内年度及各月产品销售结构和毛利的变化进行分析，并和同行业比较。 | D33: 常规★ | E33: A | K33: 这三句有重复，应整合，标红字是否需要保留？
A34: （1） | B34: 应对措施-实质性/非实质性分析程序 | C34: 按产品类别（按产品应用场景）分析被审计单位收入构成及变化（包括具体产品名称、单价、销售数量、报告期各年销售金额和占比情况）情况是否符合行业和市场同期的变化情况；是否存在放宽信用政策增加销售收入的情形。 | D34: 常规★ | E34: A
A35: （2） | B35: 应对措施-实质性/非实质性分析程序 | C35: 分析被审计单位产品或服务价格、销量及变动趋势与市场上相同或相近产品或服务的信息及其走势相比是否存在显著异常。 | D35: 常规★ | E35: A
A36: （3） | B36: 应对措施-实质性/非实质性分析程序 | C36: 计算本期重要产品的毛利率，与上期和同行业进行比较，关注其走势相比是否存在显著异常。 | D36: 常规★ | E36: A | K36: 保留
A37: 3 | B37: 应对措施-实质性/非实质性分析程序 | C37: 就不同业务模式分别分析大额前十名销售客户的名单，和前期相比是否发生变化，分析重要客户的销售数量、销售金额额、销售单价及产品毛利率。 | D37: 常规★ | E37: A | K37: 保留
A38: 4 | B38: 应对措施-实质性/非实质性分析程序 | C38: 计算本期重要的比率指标，例如：赊销率、应收账款周转率、末月销售情况/当期销售（金额或销量）、重要客户的销售额/销售额等。针对IPO/上市公司/新三板和高风险客户，还需要分析产能利用率、水电能耗、投入增长率、劳动生产率、产销率、经营性现金流量等指标。 | D38: 常规★ | E38: A | K38: 保留
A39: 5 | B39: 应对措施-实质性/非实质性分析程序 | C39: 了解期末在手订单情况，分析销售与采购是否配比，以及重要客户大量采购的原因、最终销售情况、终端客户同经销商地域的匹配性。 | D39: 常规★ | E39: C | K39: 移到IPO等特殊考虑
A40: 6 | B40: 应对措施-实质性/非实质性分析程序 | C40: 获取产品销售价格目录，与上期末相关文件进行对比分析，选取定价有较大或异常变化的产品进行测试，检查售价变动是否符合定价政策，价格变动是否合理。 | D40: 常规★ | E40: C | K40: 保留
...

Sheet 营业收入审定表D4-1
A1: 致同会计师事务所
A2: 营业收入审定表
A3: =底稿目录!A2 -> 被审计单位： | C3: =底稿目录!A4 -> 编制人： | F3: =底稿目录!A5 -> 编制日期： | H3: 索引号： | I3: D4-1
A4: =底稿目录!A3 -> 会计期间：202X年度 | C4: =底稿目录!A6 -> 复核人： | F4: =底稿目录!A7 -> 复核日期： | H4: 页次：
A5: 项目 | B5: 本期数 | F5: 上期数
B6: 未审数 | C6: 账项调整 | D6: 重分类调整 | E6: 审定数 | F6: 未审数 | G6: 账项调整 | H6: 重分类调整 | I6: 审定数
A7: 主营业务收入：
E8: =SUM(B8:D8) -> 0 | I8: =SUM(F8:H8) -> 0
E9: =SUM(B9:D9) -> 0 | I9: =SUM(F9:H9) -> 0
E10: =SUM(B10:D10) -> 0 | I10: =SUM(F10:H10) -> 0
E11: =SUM(B11:D11) -> 0 | I11: =SUM(F11:H11) -> 0
A12: 小计 | B12: =SUM(B8:B11) -> 0 | C12: =SUM(C8:C11) -> 0 | D12: =SUM(D8:D11) -> 0 | E12: =B12+C12+D12 -> 0 | F12: =SUM(F8:F11) -> 0 | G12: =SUM(G8:G11) -> 0 | H12: =SUM(H8:H11) -> 0 | I12: =SUM(I8:I11) -> 0
A13: 其他业务收入：
E14: =SUM(B14:D14) -> 0 | I14: =SUM(F14:H14) -> 0
E15: =SUM(B15:D15) -> 0 | I15: =SUM(F15:H15) -> 0
E16: =SUM(B16:D16) -> 0 | I16: =SUM(F16:H16) -> 0
E17: =SUM(B17:D17) -> 0 | I17: =SUM(F17:H17) -> 0
A18: 小计 | B18: =SUM(B14:B17) -> 0 | C18: =SUM(C14:C17) -> 0 | D18: =SUM(D14:D17) -> 0 | E18: =SUM(E14:E17) -> 0 | F18: =SUM(F14:F17) -> 0 | G18: =SUM(G14:G17) -> 0 | H18: =SUM(H14:H17) -> 0 | I18: =SUM(I14:I17) -> 0
A19: 合计 | B19: =B18+B12 -> 0 | C19: =C18+C12 -> 0 | D19: =D18+D12 -> 0 | E19: =E18+E12 -> 0 | F19: =F18+F12 -> 0 | G19: =G18+G12 -> 0 | H19: =H18+H12 -> 0 | I19: =I18+I12 -> 0
A20: 试算平衡表数
A21: 差异数 | E21: =E19-E20 -> 0 | I21: =I19-I20 -> 0
A22: 1.审计说明 | E22: 2.审计结论
A23: （1）营业收入本期较上期增加（负数为减少）：
A24: 主要原因（比例超过30%的）：
A26: （2）公司前五名客户营业收入总额为 元，占公司全部主营业务收入的比例为 %。
A28: （3）实际执行的审计程序和完成的底稿概述
A29: 实施的实质性程序概述 | C29: 执行结果 | E29: 底稿索引号
A36: 注：根据2024年沪深北交易所修订的《上市规则》：公司最近一个会计年度经审计的利润总额、净利润或者扣除非经常性损益后的净利润孰低者为负值的，公司应当在年度报告或者更正公告中披露
A37: 营业收入扣除情况及扣除后的营业收入金额；负责审计的会计师事务所应当就公司营业收入扣除事项是否符合本条规定及扣除后的营业收入金额出具专项核查意见。项目需完成营业收入扣除情况核查底稿<S20>
A39: 提示1：根据2024年沪深北交易所修订的《上市规则》：公司最近一个会计年度经审计的利润总额、净利润或者扣除非经常性损益后的净利润孰低者为负值的，公司应当在年度报告或者更正公告中披露
A40: 营业收入扣除情况及扣除后的营业收入金额；负责审计的会计师事务所应当就公司营业收入扣除事项是否符合本条规定及扣除后的营业收入金额出具专项核查意见。项目需完成营业收入扣除情况核查底稿<S20>
A41: 提示2：针对最近一个会计年度经审计营业收入低于 3亿元（沪深主板）/1亿元（科创板、创业板）但利润总额、净利润及扣除非经常性损益后的净利润均为正值的公司，会计师事务所应当对其非经常
A42: 性损益披露的真实性、准确性、完整性出具专项核查意见。
A74: 出租固定资产
A75: 出租无形资产
A76: 出租包装物和商品
A77: 销售材料
A78: 用材料进行非货币性交换
A79: 用材料进行债务重组
A80: 投资性房地产租金收入

Sheet 附注披露信息（上市公司）
A1: 致同会计师事务所
A2: 附注披露信息（上市公司）
A3: 客户名称： | C3: 编制人： | E3: 编制日期： | I3: 索引号：
A4: 会计期间：201x年度 | C4: 复核人： | E4: 复核日期： | I4: 页 次：1
A6: 营业收入附注汇总
A7: （1）营业收入和营业成本
A8: 项 目 | B8: 本期发生额 | D8: 上期发生额
B9: 收入 | C9: 成本 | D9: 收入 | E9: 成本
A10: 主营业务
A11: 其他业务
A12: 合 计 | B12: =SUM(B10:B11) -> 0 | C12: =SUM(C10:C11) -> 0 | D12: =SUM(D10:D11) -> 0 | E12: =SUM(E10:E11) -> 0
A13: 说明：
A14: [披露本公司前期已经履行 (或部分履行) 的履约义务在本期调整的收入。例如：
A15: 本公司在2023年确认的、源自前期已经履行 (或部分履行) 的履约义务的收入金额为人民币XX元，主要是由于与XX客户签订的XX合同的估计完工进度发生了变化。]
A16: 【提示：
A17: 1.处置投资性房地产（无论采用公允价值模式计量还是成本模式计量）的收入，在“其他业务收入”列示，相应结转成本至“其他业务成本”；
A18: 2.单项的投资性房地产的处置，无论是直接出售还是先划分为持有待售资产再出售，处置损益均计入“其他业务收入/成本”，不计入“资产处置损益”
A19: 3.在停工停产期间继续计提固定资产折旧和无形资产摊销，并根据用途计入相关资产的成本或当期损益。例如，企业因需求不足而停产或因事故而停工检修等，相关生产设备应当继续计提折旧，并计入营业成本。】
A20: （2）营业收入、营业成本按行业（或产品类型）划分
A21: 主要产品类型（或行业） | B21: 本期发生额 | D21: 上期发生额
B22: 收入 | C22: 成本 | D22: 收入 | E22: 成本
A23: 主营业务：
A24: 消费品
A25: 汽车
A26: 能源
A27: ......
A29: 小 计 | B29: =SUM(B24:B28)-B24-B25-B26 -> 0 | C29: =SUM(C24:C28)-C24-C25-C26 -> 0 | D29: =SUM(D24:D28)-D24-D25-D26 -> 0 | E29: =SUM(E24:E28)-E24-E25-E26 -> 0
A30: 其他业务：
A31: 销售材料
A32: 租赁收入
A33: 小 计 | B33: =SUM(B31:B32) -> 0 | C33: =SUM(C31:C32) -> 0 | D33: =SUM(D31:D32) -> 0 | E33: =SUM(E31:E32) -> 0
A34: 合 计 | B34: =B29+B33 -> 0 | C34: =C29+C33 -> 0 | D34: =D29+D33 -> 0 | E34: =E29+E33 -> 0
A35: （3）营业收入、营业成本按地区划分（不适用的，删除）
A36: 主要经营地区 | B36: 本期发生额 | D36: 上期发生额
B37: 主营业务收入 | C37: 主营业务成本 | D37: 主营业务收入 | E37: 主营业务成本
A38: 东北
A39: 华北
A40: 西北
A41: ......
A43: 小 计 | B43: =B40+B39+B38 -> 0 | C43: =C40+C39+C38 -> 0 | D43: =D40+D39+D38 -> 0 | E43: =E40+E39+E38 -> 0
...

Sheet 附注披露信息（国企）
A1: 致同会计师事务所
A2: 附注披露信息（国有企业）
A3: 客户名称： | C3: 编制人： | E3: 编制日期： | I3: 索引号：
A4: 会计期间：201x年度 | C4: 复核人： | E4: 复核日期： | I4: 页 次：1
A5: 营业收入、营业成本附注
A6: （1）营业收入、营业成本
A7: 项 目 | B7: 本期发生额 | D7: 上期发生额
B8: 收入 | C8: 成本 | D8: 收入 | E8: 成本
A9: 主营业务
A10: 其他业务
A11: 合 计 | B11: =SUM(B9:B10) -> 0 | C11: =SUM(C9:C10) -> 0 | D11: =SUM(D9:D10) -> 0 | E11: =SUM(E9:E10) -> 0
A12: 【提示：
A13: 1.处置投资性房地产（无论采用公允价值模式计量还是成本模式计量）的收入，在“其他业务收入”列示，相应结转成本至“其他业务成本”；
A14: 2.单项的投资性房地产的处置，无论是直接出售还是先划分为持有待售资产再出售，处置损益均计入“其他业务收入/成本”，不计入“资产处置损益”
A15: 3.在停工停产期间继续计提固定资产折旧和无形资产摊销，并根据用途计入相关资产的成本或当期损益。例如，企业因需求不足而停产或因事故而停工检修等，相关生产设备应当继续计提折旧，并计入营业成本。
A16: （2）按行业（或产品类型）划分
A17: 主要产品类型（或行业） | B17: 本期发生额 | D17: 上期发生额
B18: 收入 | C18: 成本 | D18: 收入 | E18: 成本
A19: 主营业务：
A20: 消费品
A21: 汽车
A22: 能源
A23: 小 计 | B23: =B20+B21+B22 -> 0 | C23: =C20+C21+C22 -> 0 | D23: =D20+D21+D22 -> 0 | E23: =E20+E21+E22 -> 0
A24: 其他业务：
A25: 销售材料
A26: 租赁收入
A27: 小 计 | B27: =B25+B26 -> 0 | C27: =C25+C26 -> 0 | D27: =D25+D26 -> 0 | E27: =E25+E26 -> 0
A28: 合 计 | B28: =B23+B27 -> 0 | C28: =C23+C27 -> 0 | D28: =D23+D27 -> 0 | E28: =E23+E27 -> 0
A29: （3）营业收入、营业成本按地区划分（不适用的，删除）
A30: 主要经营地区 | B30: 本期发生额 | D30: 上期发生额
B31: 收入 | C31: 成本 | D31: 收入 | E31: 成本
A32: 东北
A33: 华北
A34: 西北
A36: 小 计 | B36: =B32+B33+B34 -> 0 | C36: =C32+C33+C34 -> 0 | D36: =D32+D33+D34 -> 0 | E36: =E32+E33+E34 -> 0
A37: （4）营业收入分解信息
B38: 本期发生额
B39: 消费品 | D39: 汽车 | F39: 能源 | H39: 其他
B40: 收入 | C40: 成本 | D40: 收入 | E40: 成本 | F40: 收入 | G40: 成本 | H40: 收入 | I40: 成本
A41: 主营业务 | B41: =SUM(B42:B44) -> 0 | C41: =SUM(C42:C44) -> 0 | F41: =SUM(F42:F44) -> 0 | I41: =SUM(I42:I44) -> 0
...

Sheet 主营业务收入明细表D4-2
A1: 致同会计师事务所
A2: 主营业务收入明细表
A3: =底稿目录!A2 -> 被审计单位： | I3: =底稿目录!A4 -> 编制人： | O3: =底稿目录!A5 -> 编制日期： | U3: 索引号： | V3: D4-2
A4: =底稿目录!A3 -> 会计期间：202X年度 | I4: =底稿目录!A6 -> 复核人： | O4: =底稿目录!A7 -> 复核日期： | U4: 页次：
A5: 一、审计目标
A6: 与主营业务收入有关的金额及其他数据已恰当记录，相关披露已得到恰当计量和描述。
A7: 二、审计过程
A8: 1.……
A11: 项目 | B11: 1月 | C11: 2月 | D11: 3月 | E11: 4月 | F11: 5月 | G11: 6月 | H11: 7月 | I11: 8月 | J11: 9月 | K11: 10月 | L11: 11月 | M11: 12月 | N11: 本期未审数合计 | O11: 本期审计调整 | P11: 本期审定数 | Q11: 上期未审数 | R11: 上期审计调整 | S11: 上期审定数 | T11: 未审变动比例 | U11: 审定变动比例 | V11: 备注
N12: =SUM(B12:M12) -> 0 | P12: =N12+O12 -> 0 | S12: =Q12+R12 -> 0 | T12: =IF(AND(Q12=0,N12=0),0,IF(AND(Q12=0,N12>0),1,(N12-Q12)/Q12)) -> 0 | U12: =IF(AND(S12=0,P12=0),0,IF(AND(S12=0,P12>0),1,(P12-S12)/S12)) -> 0
N13: =SUM(B13:M13) -> 0 | P13: =N13+O13 -> 0 | S13: =Q13+R13 -> 0 | T13: =IF(AND(Q13=0,N13=0),0,IF(AND(Q13=0,N13>0),1,(N13-Q13)/Q13)) -> 0 | U13: =IF(AND(S13=0,P13=0),0,IF(AND(S13=0,P13>0),1,(P13-S13)/S13)) -> 0
N14: =SUM(B14:M14) -> 0 | P14: =N14+O14 -> 0 | S14: =Q14+R14 -> 0 | T14: =IF(AND(Q14=0,N14=0),0,IF(AND(Q14=0,N14>0),1,(N14-Q14)/Q14)) -> 0 | U14: =IF(AND(S14=0,P14=0),0,IF(AND(S14=0,P14>0),1,(P14-S14)/S14)) -> 0
N15: =SUM(B15:M15) -> 0 | P15: =N15+O15 -> 0 | S15: =Q15+R15 -> 0 | T15: =IF(AND(Q15=0,N15=0),0,IF(AND(Q15=0,N15>0),1,(N15-Q15)/Q15)) -> 0 | U15: =IF(AND(S15=0,P15=0),0,IF(AND(S15=0,P15>0),1,(P15-S15)/S15)) -> 0
N16: =SUM(B16:M16) -> 0 | P16: =N16+O16 -> 0 | S16: =Q16+R16 -> 0 | T16: =IF(AND(Q16=0,N16=0),0,IF(AND(Q16=0,N16>0),1,(N16-Q16)/Q16)) -> 0 | U16: =IF(AND(S16=0,P16=0),0,IF(AND(S16=0,P16>0),1,(P16-S16)/S16)) -> 0
N17: =SUM(B17:M17) -> 0 | P17: =N17+O17 -> 0 | S17: =Q17+R17 -> 0 | T17: =IF(AND(Q17=0,N17=0),0,IF(AND(Q17=0,N17>0),1,(N17-Q17)/Q17)) -> 0 | U17: =IF(AND(S17=0,P17=0),0,IF(AND(S17=0,P17>0),1,(P17-S17)/S17)) -> 0
N18: =SUM(B18:M18) -> 0 | P18: =N18+O18 -> 0 | S18: =Q18+R18 -> 0 | T18: =IF(AND(Q18=0,N18=0),0,IF(AND(Q18=0,N18>0),1,(N18-Q18)/Q18)) -> 0 | U18: =IF(AND(S18=0,P18=0),0,IF(AND(S18=0,P18>0),1,(P18-S18)/S18)) -> 0
N19: =SUM(B19:M19) -> 0 | P19: =N19+O19 -> 0 | S19: =Q19+R19 -> 0 | T19: =IF(AND(Q19=0,N19=0),0,IF(AND(Q19=0,N19>0),1,(N19-Q19)/Q19)) -> 0 | U19: =IF(AND(S19=0,P19=0),0,IF(AND(S19=0,P19>0),1,(P19-S19)/S19)) -> 0
N20: =SUM(B20:M20) -> 0 | P20: =N20+O20 -> 0 | S20: =Q20+R20 -> 0 | T20: =IF(AND(Q20=0,N20=0),0,IF(AND(Q20=0,N20>0),1,(N20-Q20)/Q20)) -> 0 | U20: =IF(AND(S20=0,P20=0),0,IF(AND(S20=0,P20>0),1,(P20-S20)/S20)) -> 0
N21: =SUM(B21:M21) -> 0 | P21: =N21+O21 -> 0 | S21: =Q21+R21 -> 0 | T21: =IF(AND(Q21=0,N21=0),0,IF(AND(Q21=0,N21>0),1,(N21-Q21)/Q21)) -> 0 | U21: =IF(AND(S21=0,P21=0),0,IF(AND(S21=0,P21>0),1,(P21-S21)/S21)) -> 0
N22: =SUM(B22:M22) -> 0 | P22: =N22+O22 -> 0 | S22: =Q22+R22 -> 0 | T22: =IF(AND(Q22=0,N22=0),0,IF(AND(Q22=0,N22>0),1,(N22-Q22)/Q22)) -> 0 | U22: =IF(AND(S22=0,P22=0),0,IF(AND(S22=0,P22>0),1,(P22-S22)/S22)) -> 0
N23: =SUM(B23:M23) -> 0 | P23: =N23+O23 -> 0 | S23: =Q23+R23 -> 0 | T23: =IF(AND(Q23=0,N23=0),0,IF(AND(Q23=0,N23>0),1,(N23-Q23)/Q23)) -> 0 | U23: =IF(AND(S23=0,P23=0),0,IF(AND(S23=0,P23>0),1,(P23-S23)/S23)) -> 0
A24: 合计 | B24: =SUM(B12:B23) -> 0 | C24: =SUM(C12:C23) -> 0 | D24: =SUM(D12:D23) -> 0 | E24: =SUM(E12:E23) -> 0 | F24: =SUM(F12:F23) -> 0 | G24: =SUM(G12:G23) -> 0 | H24: =SUM(H12:H23) -> 0 | I24: =SUM(I12:I23) -> 0 | ... S24: =SUM(S12:S23) -> 0 | T24: =IF(AND(Q24=0,N24=0),0,IF(AND(Q24=0,N24>0),1,(N24-Q24)/Q24)) -> 0 | U24: =IF(AND(S24=0,P24=0),0,IF(AND(S24=0,P24>0),1,(P24-S24)/S24)) -> 0
A25: 各月比例 | B25: =IF($N$24=0,0,B24/$N$24) -> 0 | C25: =IF($N$24=0,0,C24/$N$24) -> 0 | D25: =IF($N$24=0,0,D24/$N$24) -> 0 | E25: =IF($N$24=0,0,E24/$N$24) -> 0 | F25: =IF($N$24=0,0,F24/$N$24) -> 0 | G25: =IF($N$24=0,0,G24/$N$24) -> 0 | H25: =IF($N$24=0,0,H24/$N$24) -> 0 | I25: =IF($N$24=0,0,I24/$N$24) -> 0 | ... N25: =IF($N$24=0,0,N24/$N$24) -> 0
A26: 三、审计说明
A27: 1.XX公司收入主要集中在第二季度和第四季度，主要原因是……，经查询同行业数据< >，收入季节变化符合行业周期季节变化，季节性因素对公司各季度收入的影响合理。
A30: 四、审计结论
A32: 提示1：根据项目需要，按照区域、品种等进行分类汇总。

Sheet 其他业务收入明细表D4-3
A1: 致同会计师事务所
A2: 其他业务收入明细表
A3: =底稿目录!A2 -> 被审计单位： | E3: =底稿目录!A4 -> 编制人： | I3: =底稿目录!A5 -> 编制日期： | M3: 索引号： | N3: D4-3
A4: =底稿目录!A3 -> 会计期间：202X年度 | E4: =底稿目录!A6 -> 复核人： | I4: =底稿目录!A7 -> 复核日期： | M4: 页次：
A5: 一、审计目标：
A6: 与其他业务收入有关的金额及其他数据已恰当记录，相关披露已得到恰当计量和描述。
A7: 二、审计过程:
A8: 1.……
A11: 项目 | B11: 本期数 | G11: 上期数 | L11: 本期数比上期增加（减少） | N11: 备注
B12: 本期未审数 | C12: 账项调整 | D12: 重分类调整 | E12: 本期审定数 | F12: 结构比 | G12: 上期未审数 | H12: 账项调整 | I12: 重分类调整 | J12: 上期审定额 | K12: 结构比 | L12: 变动额 | M12: 变动率
A13: 出租固定资产 | E13: =B13+C13+D13 -> 0 | F13: =IF(E13=0,0,E13/$E$20) -> 0 | J13: =G13+H13+I13 -> 0 | K13: =IF(J13=0,0,J13/$J$20) -> 0 | L13: =E13-J13 -> 0 | M13: =IF(AND(J13=0,L13=0),0,IF(AND(J13=0,L13>0),1,L13/J13)) -> 0
A14: 出租无形资产 | E14: =B14+C14+D14 -> 0 | F14: =IF(E14=0,0,E14/$E$20) -> 0 | J14: =G14+H14+I14 -> 0 | K14: =IF(J14=0,0,J14/$J$20) -> 0 | L14: =E14-J14 -> 0 | M14: =IF(AND(J14=0,L14=0),0,IF(AND(J14=0,L14>0),1,L14/J14)) -> 0
A15: 出租包装物和商品 | E15: =B15+C15+D15 -> 0 | F15: =IF(E15=0,0,E15/$E$20) -> 0 | J15: =G15+H15+I15 -> 0 | K15: =IF(J15=0,0,J15/$J$20) -> 0 | L15: =E15-J15 -> 0 | M15: =IF(AND(J15=0,L15=0),0,IF(AND(J15=0,L15>0),1,L15/J15)) -> 0
A16: 销售材料 | E16: =B16+C16+D16 -> 0 | F16: =IF(E16=0,0,E16/$E$20) -> 0 | J16: =G16+H16+I16 -> 0 | K16: =IF(J16=0,0,J16/$J$20) -> 0 | L16: =E16-J16 -> 0 | M16: =IF(AND(J16=0,L16=0),0,IF(AND(J16=0,L16>0),1,L16/J16)) -> 0
A17: 用材料进行非货币性交换 | E17: =B17+C17+D17 -> 0 | F17: =IF(E17=0,0,E17/$E$20) -> 0 | J17: =G17+H17+I17 -> 0 | K17: =IF(J17=0,0,J17/$J$20) -> 0 | L17: =E17-J17 -> 0 | M17: =IF(AND(J17=0,L17=0),0,IF(AND(J17=0,L17>0),1,L17/J17)) -> 0
A18: 投资性房地产租金收入 | E18: =B18+C18+D18 -> 0 | F18: =IF(E18=0,0,E18/$E$20) -> 0 | J18: =G18+H18+I18 -> 0 | K18: =IF(J18=0,0,J18/$J$20) -> 0 | L18: =E18-J18 -> 0 | M18: =IF(AND(J18=0,L18=0),0,IF(AND(J18=0,L18>0),1,L18/J18)) -> 0
A19: …… | E19: =B19+C19+D19 -> 0 | F19: =IF(E19=0,0,E19/$E$20) -> 0 | J19: =G19+H19+I19 -> 0 | K19: =IF(J19=0,0,J19/$J$20) -> 0 | L19: =E19-J19 -> 0 | M19: =IF(AND(J19=0,L19=0),0,IF(AND(J19=0,L19>0),1,L19/J19)) -> 0
A20: 合计 | B20: =SUM(B13:B19) -> 0 | C20: =SUM(C13:C19) -> 0 | D20: =SUM(D13:D19) -> 0 | E20: =SUM(E13:E19) -> 0 | F20: =IF(E20=0,0,E20/$E$20) -> 0 | G20: =SUM(G13:G19) -> 0 | H20: =SUM(H13:H19) -> 0 | I20: =SUM(I13:I19) -> 0 | J20: =SUM(J13:J19) -> 0 | K20: =IF(J20=0,0,J20/$J$20) -> 0 | L20: =E20-J20 -> 0 | M20: =IF(AND(J20=0,L20=0),0,IF(AND(J20=0,L20>0),1,L20/J20)) -> 0
A21: 三、审计说明：
A25: 四、审计结论：
A29: 提示：
A30: 本科目核算企业确认的除主营业务活动以外的其他经营活动实现的收入，包括出租固定资产、出租无形资产、出租包装物和商品、销售材料、用材料进行非货币性交换（非货币性资产交换具有商业实质且公允价值能够可靠计量）或债务重组等实现的收入。
A31: 企业（保险）经营受托管理业务收取的管理费收入，也通过本科目核算。

Sheet 营业收入调整分录汇总D4-4
A1: 致同会计师事务所
A2: 营业收入调整分录汇总表
A3: =底稿目录!A2 -> 被审计单位： | D3: =底稿目录!A4 -> 编制人： | G3: =底稿目录!A5 -> 编制日期： | I3: 索引号： | J3: D4-4
A4: =底稿目录!A3 -> 会计期间：202X年度 | D4: =底稿目录!A6 -> 复核人： | G4: =底稿目录!A7 -> 复核日期： | I4: 页次：
A5: 调整事项说明 | B5: 类别（报表调整/账项调整/其他） | C5: 报表项目 | D5: 科目名称 | E5: 附注项目 | F5: …… | G5: 借方调整金额 | H5: 贷方调整金额 | I5: 索引 | J5: 备注
A21: 提示：本底稿适用于调整分录较多、较复杂的项目，且仅列示与本报表项目相关的审计调整。项目组可根据项目实际情况选择是否使用该底稿。

Sheet GT_Custom
A1: C1 | B1: Custom 1
A2: C2 | B2: Custom 2
A3: C3 | B3: Custom 3
A4: C4 | B4: Custom 4
A5: C5 | B5: Custom 5
A6: C6 | B6: Custom 6
A7: C7 | B7: Custom 7
A8: C8 | B8: Custom 8
