Workbook

Sheet 底稿目录
A1: 1.底稿开列时，可先在以下单元格填写有关内容，以便其他底稿引用有关数据：
A2: 被审计单位名称： | D2: 序号 | E2: 内容 | F2: 索引号
A3: 会计期间：202X年度 | D3: 1 | E3: 重要指标分析 | F3: D4-6
A4: 编制人： | D4: 2 | E4: 毛利率分析表 | F4: D4-7
A5: 编制日期： | D5: 3 | E5: 重要产品毛利分析 | F5: D4-8
A6: 复核人： | D6: 4 | E6: 重要客户结构分析 | F6: D4-9
A7: 复核日期： | D7: 5 | E7: 重要客户销售价格分析 | F7: D4-10
D8: 6 | E8: 产品销售价格分析 | F8: D4-11
A9: 关于工作底稿与审计程序索引号对应的说明
A10: 1.编制的审计工作底稿应与审计程序对应。审计项目组应根据被审计单位实际情况和风险评估情况在实质性程序表中裁剪、修改或增加审计程序，根据实际执行的审计程序完成相应审计工作底稿，编制的工作底稿中应按自然顺序依次编制索引号，并通过唯一的索引号将与实质性程序表中的程序对应关联（即将工作底稿的索引号填入实质性程序表中的底稿索引号列）。
A14: 2.获取的支持性证据应与审计底稿或程序对应。审计项目组在完成底稿时获取的支持性证据应根据底稿索引号编制下一级按自然顺序排序的索引号（如D1-2-1、D1-2-2、……），并在底稿中说明引用的支持性证据、关联索引号。
A17: 3.工作底稿索引号的编码规则：实质性程序索引号按循环从“D”到“N”,循环内账户以顺序号排列，模板中底稿索引号按账户顺序+自然数顺序（即模板中索引号按二级自然顺序排列，如D1-1、D1-2、D1-3、……D1-N）。

Sheet 重要指标分析D4-6
A1: 致同会计师事务所
A2: 重要指标分析表
A3: =底稿目录!A2 -> 被审计单位名称： | B3: =底稿目录!A4 -> 编制人： | E3: =底稿目录!A5 -> 编制日期： | G3: 索引号： | H3: =底稿目录!F3 -> D4-6
A4: =底稿目录!A3 -> 会计期间：202X年度 | B4: =底稿目录!A6 -> 复核人： | E4: =底稿目录!A7 -> 复核日期： | G4: 页次：
A5: 一、审计目标
A6: 1.利润表中记录的营业收入已发生，且与被审计单位有关；2.所有应当记录的营业收入均已记录；
A7: 3.与营业收入有关的金额及其他数据已恰当记录，相关披露已得到恰当计量和描述。
A8: 二、审计过程
A9: 1.……
A11: 指标名称 | B11: 本期 | C11: 上期 | D11: 差异1 | E11: 变化原因及合理性分析1 | F11: 同行业公司平均值 | G11: 差异2 | H11: 变化原因及合理性分析2
B12: ① | C12: ② | D12: ③=(①-②)/② | E12: ④ | F12: ⑤ | G12: ⑥=（①-⑤）/⑤ | H12: ⑦
A13: 应收账款/总资产 | D13: =IF(C13=0,0,(B13-C13)/C13) -> 0 | G13: =IF(F13=0,0,(B13-F13)/F13) -> 0
A14: 应收账款周转天数=应收账款平均余额/(销售收入/365) | D14: =IF(C14=0,0,(B14-C14)/C14) -> 0 | G14: =IF(F14=0,0,(B14-F14)/F14) -> 0
A15: 应收账款周转次数=销售收入/应收账款平均余额 | D15: =IF(C15=0,0,(B15-C15)/C15) -> 0 | G15: =IF(F15=0,0,(B15-F15)/F15) -> 0
A16: (末月/最后一个季度）销售情况/当期销售（金额或销量） | D16: =IF(C16=0,0,(B16-C16)/C16) -> 0 | G16: =IF(F16=0,0,(B16-F16)/F16) -> 0
A17: 销售折扣/销售额 | D17: =IF(C17=0,0,(B17-C17)/C17) -> 0 | G17: =IF(F17=0,0,(B17-F17)/F17) -> 0
A18: 销售折让/销售额 | D18: =IF(C18=0,0,(B18-C18)/C18) -> 0 | G18: =IF(F18=0,0,(B18-F18)/F18) -> 0
A19: 销货退回/销售额 | D19: =IF(C19=0,0,(B19-C19)/C19) -> 0 | G19: =IF(F19=0,0,(B19-F19)/F19) -> 0
A20: 坏账准备余额/应收账款余额 | D20: =IF(C20=0,0,(B20-C20)/C20) -> 0 | G20: =IF(F20=0,0,(B20-F20)/F20) -> 0
A21: 人均创收=销售收入/员工总数 | D21: =IF(C21=0,0,(B21-C21)/C21) -> 0 | G21: =IF(F21=0,0,(B21-F21)/F21) -> 0
A22: 销售净利率=净利润/销售收入 | D22: =IF(C22=0,0,(B22-C22)/C22) -> 0 | G22: =IF(F22=0,0,(B22-F22)/F22) -> 0
A23: 人均创利=净利润/员工总数 | D23: =IF(C23=0,0,(B23-C23)/C23) -> 0 | G23: =IF(F23=0,0,(B23-F23)/F23) -> 0
A24: 当期销售金额/主要原材料采购金额 | D24: =IF(C24=0,0,(B24-C24)/C24) -> 0 | G24: =IF(F24=0,0,(B24-F24)/F24) -> 0
A25: 三、审计说明
A28: 四、审计结论

Sheet 毛利率分析表D4-7
A1: 致同会计师事务所
A2: 主营业务收入毛利率分析表
A3: =底稿目录!A2 -> 被审计单位名称： | I3: =底稿目录!A4 -> 编制人： | Q3: =底稿目录!A5 -> 编制日期： | V3: 索引号： | W3: =底稿目录!F4 -> D4-7
A4: =底稿目录!A3 -> 会计期间：202X年度 | I4: =底稿目录!A6 -> 复核人： | Q4: =底稿目录!A7 -> 复核日期： | V4: 页次：
A5: 一、审计目标：
A6: 利润表中记录的营业收入已发生，且与被审计单位有关。
A7: 二、审计过程
A8: 1.了解公司各月毛利、收入的构成及变化情况是否符合行业和市场同期的变化情况。了解公司的产品或服务价格、销量及变动趋势，了解市场上具有代表性企业的价格信息和趋势、行业协会发布的统计数据，并进行比较，确定是否存在显著异常
A10: （一）月度毛利分析
A11: 月份 | B11: 1月 | C11: 2月 | D11: 3月 | E11: 4月 | F11: 5月 | G11: 6月 | H11: 7月 | I11: 8月 | J11: 9月 | K11: 10月 | L11: 11月 | M11: 12月 | N11: 合计 | O11: 上期 | P11: 变动比例
A12: 主营业务收入 | N12: =SUM(B12:M12) -> 0 | P12: =(N12-O12)/N12 -> #DIV/0!
A13: 主营业务成本 | N13: =SUM(B13:M13) -> 0 | P13: =(N13-O13)/N13 -> #DIV/0!
A14: 毛利 | B14: =B12-B13 -> 0 | C14: =C12-C13 -> 0 | D14: =D12-D13 -> 0 | E14: =E12-E13 -> 0 | F14: =F12-F13 -> 0 | G14: =G12-G13 -> 0 | H14: =H12-H13 -> 0 | I14: =I12-I13 -> 0 | ... O14: =O12-O13 -> 0 | P14: =(N14-O14)/N14 -> #DIV/0!
A15: 毛利率 | B15: =B14/B12 -> #DIV/0! | C15: =C14/C12 -> #DIV/0! | D15: =D14/D12 -> #DIV/0! | E15: =E14/E12 -> #DIV/0! | F15: =F14/F12 -> #DIV/0! | G15: =G14/G12 -> #DIV/0! | H15: =H14/H12 -> #DIV/0! | I15: =I14/I12 -> #DIV/0! | ... O15: =O14/O12 -> #DIV/0!
A17: （二）按产品毛利分析
A18: 产品名称 | B18: 本期 | J18: 上期 | R18: 变动比例 | W18: 备注
B19: 数量 | C19: 平均单价 | D19: 主营业务收入 | E19: 结构比 | F19: 单位成本 | G19: 主营业务成本 | H19: 毛利 | I19: 毛利率 | J19: 数量 | K19: 平均单价 | L19: 主营业务收入 | M19: 结构比 | N19: 单位成本 | O19: 主营业务成本 | P19: 毛利 | Q19: 毛利率 | R19: 平均单价 | S19: 单位成本 | T19: 主营业务收入 | U19: 主营业务成本 | V19: 毛利率
C20: =D20/B20 -> #DIV/0! | E20: =D20/$D$26 -> #DIV/0! | F20: =G20/B20 -> #DIV/0! | H20: =D20-G20 -> 0 | I20: =IF(D20=0,0,H20/D20) -> 0 | K20: =L20/J20 -> #DIV/0! | M20: =L20/$L$26 -> #DIV/0! | N20: =O20/J20 -> #DIV/0! | P20: =L20-O20 -> 0 | Q20: =IF(L20=0,0,P20/L20) -> 0 | R20: =(K20-C20)/K20 -> #DIV/0! | S20: =(F20-N20)/N20 -> #DIV/0! | T20: =(L20-D20)/L20 -> #DIV/0! | U20: =(O20-G20)/O20 -> #DIV/0! | V20: =Q20-I20 -> 0
C21: =D21/B21 -> #DIV/0! | E21: =D21/$D$26 -> #DIV/0! | F21: =G21/B21 -> #DIV/0! | H21: =D21-G21 -> 0 | I21: =IF(D21=0,0,H21/D21) -> 0 | K21: =L21/J21 -> #DIV/0! | M21: =L21/$L$26 -> #DIV/0! | N21: =O21/J21 -> #DIV/0! | P21: =L21-O21 -> 0 | Q21: =IF(L21=0,0,P21/L21) -> 0 | R21: =(K21-C21)/K21 -> #DIV/0! | S21: =(F21-N21)/N21 -> #DIV/0! | T21: =(L21-D21)/L21 -> #DIV/0! | U21: =(O21-G21)/O21 -> #DIV/0! | V21: =Q21-I21 -> 0
C22: =D22/B22 -> #DIV/0! | E22: =D22/$D$26 -> #DIV/0! | F22: =G22/B22 -> #DIV/0! | H22: =D22-G22 -> 0 | I22: =IF(D22=0,0,H22/D22) -> 0 | K22: =L22/J22 -> #DIV/0! | M22: =L22/$L$26 -> #DIV/0! | N22: =O22/J22 -> #DIV/0! | P22: =L22-O22 -> 0 | Q22: =IF(L22=0,0,P22/L22) -> 0 | R22: =(K22-C22)/K22 -> #DIV/0! | S22: =(F22-N22)/N22 -> #DIV/0! | T22: =(L22-D22)/L22 -> #DIV/0! | U22: =(O22-G22)/O22 -> #DIV/0! | V22: =Q22-I22 -> 0
C23: =D23/B23 -> #DIV/0! | E23: =D23/$D$26 -> #DIV/0! | F23: =G23/B23 -> #DIV/0! | H23: =D23-G23 -> 0 | I23: =IF(D23=0,0,H23/D23) -> 0 | K23: =L23/J23 -> #DIV/0! | M23: =L23/$L$26 -> #DIV/0! | N23: =O23/J23 -> #DIV/0! | P23: =L23-O23 -> 0 | Q23: =IF(L23=0,0,P23/L23) -> 0 | R23: =(K23-C23)/K23 -> #DIV/0! | S23: =(F23-N23)/N23 -> #DIV/0! | T23: =(L23-D23)/L23 -> #DIV/0! | U23: =(O23-G23)/O23 -> #DIV/0! | V23: =Q23-I23 -> 0
C24: =D24/B24 -> #DIV/0! | E24: =D24/$D$26 -> #DIV/0! | F24: =G24/B24 -> #DIV/0! | H24: =D24-G24 -> 0 | I24: =IF(D24=0,0,H24/D24) -> 0 | K24: =L24/J24 -> #DIV/0! | M24: =L24/$L$26 -> #DIV/0! | N24: =O24/J24 -> #DIV/0! | P24: =L24-O24 -> 0 | Q24: =IF(L24=0,0,P24/L24) -> 0 | R24: =(K24-C24)/K24 -> #DIV/0! | S24: =(F24-N24)/N24 -> #DIV/0! | T24: =(L24-D24)/L24 -> #DIV/0! | U24: =(O24-G24)/O24 -> #DIV/0! | V24: =Q24-I24 -> 0
C25: =D25/B25 -> #DIV/0! | E25: =D25/$D$26 -> #DIV/0! | F25: =G25/B25 -> #DIV/0! | H25: =D25-G25 -> 0 | I25: =IF(D25=0,0,H25/D25) -> 0 | K25: =L25/J25 -> #DIV/0! | M25: =L25/$L$26 -> #DIV/0! | N25: =O25/J25 -> #DIV/0! | P25: =L25-O25 -> 0 | Q25: =IF(L25=0,0,P25/L25) -> 0 | R25: =(K25-C25)/K25 -> #DIV/0! | S25: =(F25-N25)/N25 -> #DIV/0! | T25: =(L25-D25)/L25 -> #DIV/0! | U25: =(O25-G25)/O25 -> #DIV/0! | V25: =Q25-I25 -> 0
A26: 合计 | B26: =SUM(B20:B25) -> 0 | C26: =D26/B26 -> #DIV/0! | D26: =SUM(D20:D25) -> 0 | E26: =D26/$D$26 -> #DIV/0! | F26: =G26/B26 -> #DIV/0! | G26: =SUM(G20:G25) -> 0 | H26: =SUM(H20:H25) -> 0 | I26: =IF(D26=0,0,H26/D26) -> 0 | J26: =SUM(J20:J25) -> 0 | K26: =L26/J26 -> #DIV/0! | L26: =SUM(L20:L25) -> 0 | M26: =L26/$L$26 -> #DIV/0! | N26: =O26/J26 -> #DIV/0! | O26: =SUM(O20:O25) -> 0 | P26: =SUM(P20:P25) -> 0 | Q26: =IF(L26=0,0,P26/L26) -> 0 | R26: =(K26-C26)/K26 -> #DIV/0! | S26: =(F26-N26)/N26 -> #DIV/0! | T26: =(L26-D26)/L26 -> #DIV/0! | U26: =(O26-G26)/O26 -> #DIV/0! | V26: =Q26-I26 -> 0
A27: 三、审计说明
A28: 1.毛利率变动异常原因：
A29: 2.XX产品单价变动异常，采用审计抽样方法检查该类型产品单价变动的合理性，判断销售给关联方或关系密切的重要客户的产品价格是否合理，有无以低价或高价结算的方法，相互之间有无转移利润的现象，见<产品销售价格分析D4-1>。
A30: 四、审计结论
A32: 提示：除分析主要产品和服务之外，还需要考虑被审计单位是否有联产品和副产品产出；如有，应同时分析联产品和副产品的毛利变化情况，并结合营业成本的审计，判断联产品和副产品的成本分摊是否正确。

Sheet 重要产品毛利分析D4-8
A1: 致同会计师事务所
A2: 重要产品/服务毛利率分析表
A3: =底稿目录!A2 -> 被审计单位名称： | H3: =底稿目录!A4 -> 编制人： | N3: =底稿目录!A5 -> 编制日期： | W3: 索引号： | X3: =底稿目录!F5 -> D4-8
A4: =底稿目录!A3 -> 会计期间：202X年度 | H4: =底稿目录!A6 -> 复核人： | N4: =底稿目录!A7 -> 复核日期： | W4: 页次：
A5: 一、审计目标
A6: 1.利润表中记录的营业收入已发生，且与被审计单位有关；2.所有应当记录的营业收入均已记录；
A7: 3.与营业收入有关的金额及其他数据已恰当记录，相关披露已得到恰当计量和描述。
A8: 二、审计过程
A9: 1.……
A12: 产品A：
A13: 月份 | B13: 本期数 | J13: 上期数 | R13: 本期比上期增减变动分析 | X13: 备注
B14: 营业收入 | E14: 营业成本 | H14: 毛利 | I14: 毛利率 | J14: 营业收入 | M14: 营业成本 | P14: 毛利 | Q14: 毛利率 | R14: 平均单价 | S14: 单位成本 | T14: 主营业务收入 | U14: 主营业务成本 | V14: 毛利 | W14: 毛利率
B15: 销量 | C15: 平均单价 | D15: 金额 | E15: 销量 | F15: 平均单位成本 | G15: 金额 | J15: 销量 | K15: 平均单价 | L15: 金额 | M15: 销量 | N15: 平均单位成本 | O15: 金额
A16: 1 | H16: =D16-G16 -> 0 | I16: =IF(D16=0,0,H16/D16) -> 0 | P16: =L16-O16 -> 0 | Q16: =IF(L16=0,0,P16/L16) -> 0 | R16: =(C16-K16)/K16 -> #DIV/0! | S16: =(F16-N16)/N16 -> #DIV/0! | T16: =(D16-L16)/L16 -> #DIV/0! | U16: =(G16-O16)/O16 -> #DIV/0! | V16: =(H16-P16)/P16 -> #DIV/0! | W16: =I16-Q16 -> 0
A17: 2 | H17: =D17-G17 -> 0 | I17: =IF(D17=0,0,H17/D17) -> 0 | P17: =L17-O17 -> 0 | Q17: =IF(L17=0,0,P17/L17) -> 0 | R17: =(C17-K17)/K17 -> #DIV/0! | S17: =(F17-N17)/N17 -> #DIV/0! | T17: =(D17-L17)/L17 -> #DIV/0! | U17: =(G17-O17)/O17 -> #DIV/0! | V17: =(H17-P17)/P17 -> #DIV/0! | W17: =I17-Q17 -> 0
A18: 3 | H18: =D18-G18 -> 0 | I18: =IF(D18=0,0,H18/D18) -> 0 | P18: =L18-O18 -> 0 | Q18: =IF(L18=0,0,P18/L18) -> 0 | R18: =(C18-K18)/K18 -> #DIV/0! | S18: =(F18-N18)/N18 -> #DIV/0! | T18: =(D18-L18)/L18 -> #DIV/0! | U18: =(G18-O18)/O18 -> #DIV/0! | V18: =(H18-P18)/P18 -> #DIV/0! | W18: =I18-Q18 -> 0
A19: 4 | H19: =D19-G19 -> 0 | I19: =IF(D19=0,0,H19/D19) -> 0 | P19: =L19-O19 -> 0 | Q19: =IF(L19=0,0,P19/L19) -> 0 | R19: =(C19-K19)/K19 -> #DIV/0! | S19: =(F19-N19)/N19 -> #DIV/0! | T19: =(D19-L19)/L19 -> #DIV/0! | U19: =(G19-O19)/O19 -> #DIV/0! | V19: =(H19-P19)/P19 -> #DIV/0! | W19: =I19-Q19 -> 0
A20: 5 | H20: =D20-G20 -> 0 | I20: =IF(D20=0,0,H20/D20) -> 0 | P20: =L20-O20 -> 0 | Q20: =IF(L20=0,0,P20/L20) -> 0 | R20: =(C20-K20)/K20 -> #DIV/0! | S20: =(F20-N20)/N20 -> #DIV/0! | T20: =(D20-L20)/L20 -> #DIV/0! | U20: =(G20-O20)/O20 -> #DIV/0! | V20: =(H20-P20)/P20 -> #DIV/0! | W20: =I20-Q20 -> 0
A21: 6 | H21: =D21-G21 -> 0 | I21: =IF(D21=0,0,H21/D21) -> 0 | P21: =L21-O21 -> 0 | Q21: =IF(L21=0,0,P21/L21) -> 0 | R21: =(C21-K21)/K21 -> #DIV/0! | S21: =(F21-N21)/N21 -> #DIV/0! | T21: =(D21-L21)/L21 -> #DIV/0! | U21: =(G21-O21)/O21 -> #DIV/0! | V21: =(H21-P21)/P21 -> #DIV/0! | W21: =I21-Q21 -> 0
A22: 7 | H22: =D22-G22 -> 0 | I22: =IF(D22=0,0,H22/D22) -> 0 | P22: =L22-O22 -> 0 | Q22: =IF(L22=0,0,P22/L22) -> 0 | R22: =(C22-K22)/K22 -> #DIV/0! | S22: =(F22-N22)/N22 -> #DIV/0! | T22: =(D22-L22)/L22 -> #DIV/0! | U22: =(G22-O22)/O22 -> #DIV/0! | V22: =(H22-P22)/P22 -> #DIV/0! | W22: =I22-Q22 -> 0
A23: 8 | H23: =D23-G23 -> 0 | I23: =IF(D23=0,0,H23/D23) -> 0 | P23: =L23-O23 -> 0 | Q23: =IF(L23=0,0,P23/L23) -> 0 | R23: =(C23-K23)/K23 -> #DIV/0! | S23: =(F23-N23)/N23 -> #DIV/0! | T23: =(D23-L23)/L23 -> #DIV/0! | U23: =(G23-O23)/O23 -> #DIV/0! | V23: =(H23-P23)/P23 -> #DIV/0! | W23: =I23-Q23 -> 0
A24: 9 | H24: =D24-G24 -> 0 | I24: =IF(D24=0,0,H24/D24) -> 0 | P24: =L24-O24 -> 0 | Q24: =IF(L24=0,0,P24/L24) -> 0 | R24: =(C24-K24)/K24 -> #DIV/0! | S24: =(F24-N24)/N24 -> #DIV/0! | T24: =(D24-L24)/L24 -> #DIV/0! | U24: =(G24-O24)/O24 -> #DIV/0! | V24: =(H24-P24)/P24 -> #DIV/0! | W24: =I24-Q24 -> 0
A25: 10 | H25: =D25-G25 -> 0 | I25: =IF(D25=0,0,H25/D25) -> 0 | P25: =L25-O25 -> 0 | Q25: =IF(L25=0,0,P25/L25) -> 0 | R25: =(C25-K25)/K25 -> #DIV/0! | S25: =(F25-N25)/N25 -> #DIV/0! | T25: =(D25-L25)/L25 -> #DIV/0! | U25: =(G25-O25)/O25 -> #DIV/0! | V25: =(H25-P25)/P25 -> #DIV/0! | W25: =I25-Q25 -> 0
A26: 11 | H26: =D26-G26 -> 0 | I26: =IF(D26=0,0,H26/D26) -> 0 | P26: =L26-O26 -> 0 | Q26: =IF(L26=0,0,P26/L26) -> 0 | R26: =(C26-K26)/K26 -> #DIV/0! | S26: =(F26-N26)/N26 -> #DIV/0! | T26: =(D26-L26)/L26 -> #DIV/0! | U26: =(G26-O26)/O26 -> #DIV/0! | V26: =(H26-P26)/P26 -> #DIV/0! | W26: =I26-Q26 -> 0
A27: 12 | H27: =D27-G27 -> 0 | I27: =IF(D27=0,0,H27/D27) -> 0 | P27: =L27-O27 -> 0 | Q27: =IF(L27=0,0,P27/L27) -> 0 | R27: =(C27-K27)/K27 -> #DIV/0! | S27: =(F27-N27)/N27 -> #DIV/0! | T27: =(D27-L27)/L27 -> #DIV/0! | U27: =(G27-O27)/O27 -> #DIV/0! | V27: =(H27-P27)/P27 -> #DIV/0! | W27: =I27-Q27 -> 0
A28: 合计 | B28: =SUM(B16:B27) -> 0 | C28: =IF(B28<>0,D28/B28,0) -> 0 | D28: =SUM(D16:D27) -> 0 | E28: =SUM(E16:E27) -> 0 | F28: =IF(E28<>0,G28/E28,0) -> 0 | G28: =SUM(G16:G27) -> 0 | H28: =SUM(H16:H27) -> 0 | I28: =IF(D28=0,0,H28/D28) -> 0 | J28: =SUM(J16:J27) -> 0 | K28: =IF(J28<>0,L28/J28,0) -> 0 | L28: =SUM(L16:L27) -> 0 | M28: =SUM(M16:M27) -> 0 | N28: =IF(M28<>0,O28/M28,0) -> 0 | O28: =SUM(O16:O27) -> 0 | P28: =SUM(P16:P27) -> 0 | Q28: =IF(L28=0,0,P28/L28) -> 0 | R28: =(C28-K28)/K28 -> #DIV/0! | S28: =(F28-N28)/N28 -> #DIV/0! | T28: =(D28-L28)/L28 -> #DIV/0! | U28: =(G28-O28)/O28 -> #DIV/0! | V28: =(H28-P28)/P28 -> #DIV/0! | W28: =I28-Q28 -> 0
A29: 同行业A企业 | H29: =D29-G29 -> 0 | I29: =IF(D29=0,0,H29/D29) -> 0 | P29: =L29-O29 -> 0 | Q29: =IF(L29=0,0,P29/L29) -> 0 | R29: =(C29-K29)/K29 -> #DIV/0! | S29: =(F29-N29)/N29 -> #DIV/0! | T29: =(D29-L29)/L29 -> #DIV/0! | U29: =(G29-O29)/O29 -> #DIV/0! | V29: =(H29-P29)/P29 -> #DIV/0! | W29: =I29-Q29 -> 0
A30: 同行业B企业 | H30: =D30-G30 -> 0 | I30: =IF(D30=0,0,H30/D30) -> 0 | P30: =L30-O30 -> 0 | Q30: =IF(L30=0,0,P30/L30) -> 0 | R30: =(C30-K30)/K30 -> #DIV/0! | S30: =(F30-N30)/N30 -> #DIV/0! | T30: =(D30-L30)/L30 -> #DIV/0! | U30: =(G30-O30)/O30 -> #DIV/0! | V30: =(H30-P30)/P30 -> #DIV/0! | W30: =I30-Q30 -> 0
A31: 行业平均水平 | H31: =D31-G31 -> 0 | I31: =IF(D31=0,0,H31/D31) -> 0 | P31: =L31-O31 -> 0 | Q31: =IF(L31=0,0,P31/L31) -> 0 | R31: =(C31-K31)/K31 -> #DIV/0! | S31: =(F31-N31)/N31 -> #DIV/0! | T31: =(D31-L31)/L31 -> #DIV/0! | U31: =(G31-O31)/O31 -> #DIV/0! | V31: =(H31-P31)/P31 -> #DIV/0! | W31: =I31-Q31 -> 0
A32: 产品B……（略）：
A35: 三、审计说明
A38: 四、审计结论

Sheet 重要客户结构分析D4-9
A1: 致同会计师事务所
A2: 重要客户结构分析表
A3: =底稿目录!A2 -> 被审计单位名称： | C3: =底稿目录!A4 -> 编制人： | E3: =底稿目录!A5 -> 编制日期： | F3: 索引号： | G3: =底稿目录!F6 -> D4-9
A4: =底稿目录!A3 -> 会计期间：202X年度 | C4: =底稿目录!A6 -> 复核人： | E4: =底稿目录!A7 -> 复核日期： | F4: 页次：
A5: 一、审计目标
A6: 利润表中记录的营业收入已发生，且与被审计单位有关。
A7: 二、审计过程
A8: 1.……
A11: 本期：
A12: 序号 | B12: 客户名称 | C12: 销售金额 | D12: 销售金额占比 | E12: 销售数量 | F12: 销售数量占比 | G12: 上期排名
A13: 1 | D13: =IF(C13=0,0,C13/$C$24) -> 0 | F13: =IF(E13=0,0,E13/$E$24) -> 0
A14: 2 | D14: =IF(C14=0,0,C14/$C$24) -> 0 | F14: =IF(E14=0,0,E14/$E$24) -> 0
A15: 3 | D15: =IF(C15=0,0,C15/$C$24) -> 0 | F15: =IF(E15=0,0,E15/$E$24) -> 0
A16: 4 | D16: =IF(C16=0,0,C16/$C$24) -> 0 | F16: =IF(E16=0,0,E16/$E$24) -> 0
A17: 5 | D17: =IF(C17=0,0,C17/$C$24) -> 0 | F17: =IF(E17=0,0,E17/$E$24) -> 0
A18: 6 | D18: =IF(C18=0,0,C18/$C$24) -> 0 | F18: =IF(E18=0,0,E18/$E$24) -> 0
A19: 7 | D19: =IF(C19=0,0,C19/$C$24) -> 0 | F19: =IF(E19=0,0,E19/$E$24) -> 0
A20: 8 | D20: =IF(C20=0,0,C20/$C$24) -> 0 | F20: =IF(E20=0,0,E20/$E$24) -> 0
A21: 9 | D21: =IF(C21=0,0,C21/$C$24) -> 0 | F21: =IF(E21=0,0,E21/$E$24) -> 0
A22: 10 | D22: =IF(C22=0,0,C22/$C$24) -> 0 | F22: =IF(E22=0,0,E22/$E$24) -> 0
A23: 合计 | C23: =SUM(C13:C22) -> 0 | D23: =IF(C23=0,0,C23/$C$24) -> 0 | E23: =SUM(E13:E22) -> 0 | F23: =IF(E23=0,0,E23/$E$24) -> 0
A24: 本期销售总额 | C24: ='毛利率分析表D4-7'!D26 -> 0 | E24: ='毛利率分析表D4-7'!B26 -> 0
A25: 上期：
A26: 序号 | B26: 客户名称 | C26: 销售金额 | D26: 销售金额占比 | E26: 销售数量 | F26: 销售数量占比 | G26: 上期排名
A27: 1 | D27: =IF(C27=0,0,C27/$C$38) -> 0 | F27: =IF(E27=0,0,E27/$E$38) -> 0
A28: 2 | D28: =IF(C28=0,0,C28/$C$38) -> 0 | F28: =IF(E28=0,0,E28/$E$38) -> 0
A29: 3 | D29: =IF(C29=0,0,C29/$C$38) -> 0 | F29: =IF(E29=0,0,E29/$E$38) -> 0
A30: 4 | D30: =IF(C30=0,0,C30/$C$38) -> 0 | F30: =IF(E30=0,0,E30/$E$38) -> 0
A31: 5 | D31: =IF(C31=0,0,C31/$C$38) -> 0 | F31: =IF(E31=0,0,E31/$E$38) -> 0
A32: 6 | D32: =IF(C32=0,0,C32/$C$38) -> 0 | F32: =IF(E32=0,0,E32/$E$38) -> 0
A33: 7 | D33: =IF(C33=0,0,C33/$C$38) -> 0 | F33: =IF(E33=0,0,E33/$E$38) -> 0
A34: 8 | D34: =IF(C34=0,0,C34/$C$38) -> 0 | F34: =IF(E34=0,0,E34/$E$38) -> 0
A35: 9 | D35: =IF(C35=0,0,C35/$C$38) -> 0 | F35: =IF(E35=0,0,E35/$E$38) -> 0
A36: 10 | D36: =IF(C36=0,0,C36/$C$38) -> 0 | F36: =IF(E36=0,0,E36/$E$38) -> 0
A37: 合计 | C37: =SUM(C27:C36) -> 0 | D37: =IF(C37=0,0,C37/$C$38) -> 0 | E37: =SUM(E27:E36) -> 0 | F37: =IF(E37=0,0,E37/$E$38) -> 0
A38: 本期销售总额 | C38: ='毛利率分析表D4-7'!L26 -> 0 | E38: ='毛利率分析表D4-7'!J26 -> 0
A39: 三、审计说明
A40: 本年前十名客户的销售额较去年增加%，大于本年营业收入比去年营业收入增加的比率%
A41: 主要是因为…………
A42: 本年前十名客户的销售额较去年减少%，小于本年营业收入比去年营业收入减少的比率%
...

Sheet 重要客户销售价格分析D4-10
A1: 致同会计师事务所
A2: 重要客户销售价格分析
A3: 被审计单位名称： | F3: 编制人： | I3: 编制日期： | M3: 索引号： | N3: =底稿目录!F7 -> D4-10
A4: 会计期间：2024年度 | F4: 复核人： | I4: 复核日期： | M4: 页次：
A5: 一、审计目标：
A6: 利润表中记录的营业收入已发生，且与被审计单位有关，已记录于恰当的账户。
A7: 二、审计过程
A8: 1.……
A11: 序号 | B11: 客户名称 | C11: 产品种类 | D11: 销售情况 | H11: 销售单价分析
D12: 销售金额 | E12: 占比 | F12: 销售数量 | G12: 占比 | H12: 销售单价 | I12: 年度均价 （或销售指导价格） | J12: 与均价差异 | K12: 差异原因 | L12: 市场价格 | M12: 与均价差异 | N12: 差异原因
A13: 1 | B13: 大额客户一 | C13: 产品1 | E13: =IF(D13=0,0,D13/$D$34) -> 0 | G13: =IF(F13=0,0,F13/$F$34) -> 0 | H13: 0 | J13: =IF(AND(I13=0,H13=0),0,IF(AND(I13=0,H13>0),1,(H13-I13)/I13)) -> 0 | M13: =IF(AND(L13=0,H13=0),0,IF(AND(L13=0,H13>0),1,(H13-L13)/L13)) -> 0
C14: 产品2 | E14: =IF(D14=0,0,D14/$D$34) -> 0 | G14: =IF(F14=0,0,F14/$F$34) -> 0 | H14: 0 | J14: =IF(AND(I14=0,H14=0),0,IF(AND(I14=0,H14>0),1,(H14-I14)/I14)) -> 0 | M14: =IF(AND(L14=0,H14=0),0,IF(AND(L14=0,H14>0),1,(H14-L14)/L14)) -> 0
C15: 产品3 | E15: =IF(D15=0,0,D15/$D$34) -> 0 | G15: =IF(F15=0,0,F15/$F$34) -> 0 | H15: 0 | J15: =IF(AND(I15=0,H15=0),0,IF(AND(I15=0,H15>0),1,(H15-I15)/I15)) -> 0 | M15: =IF(AND(L15=0,H15=0),0,IF(AND(L15=0,H15>0),1,(H15-L15)/L15)) -> 0
A16: 2 | B16: 大额客户二 | C16: 产品1 | E16: =IF(D16=0,0,D16/$D$34) -> 0 | G16: =IF(F16=0,0,F16/$F$34) -> 0 | H16: 0 | J16: =IF(AND(I16=0,H16=0),0,IF(AND(I16=0,H16>0),1,(H16-I16)/I16)) -> 0 | M16: =IF(AND(L16=0,H16=0),0,IF(AND(L16=0,H16>0),1,(H16-L16)/L16)) -> 0
C17: 产品2 | E17: =IF(D17=0,0,D17/$D$34) -> 0 | G17: =IF(F17=0,0,F17/$F$34) -> 0 | H17: 0 | J17: =IF(AND(I17=0,H17=0),0,IF(AND(I17=0,H17>0),1,(H17-I17)/I17)) -> 0 | M17: =IF(AND(L17=0,H17=0),0,IF(AND(L17=0,H17>0),1,(H17-L17)/L17)) -> 0
C18: 产品3 | E18: =IF(D18=0,0,D18/$D$34) -> 0 | G18: =IF(F18=0,0,F18/$F$34) -> 0 | H18: 0 | J18: =IF(AND(I18=0,H18=0),0,IF(AND(I18=0,H18>0),1,(H18-I18)/I18)) -> 0 | M18: =IF(AND(L18=0,H18=0),0,IF(AND(L18=0,H18>0),1,(H18-L18)/L18)) -> 0
A19: 3 | B19: 大额客户三 | C19: 产品1 | E19: =IF(D19=0,0,D19/$D$34) -> 0 | G19: =IF(F19=0,0,F19/$F$34) -> 0 | H19: 0 | J19: =IF(AND(I19=0,H19=0),0,IF(AND(I19=0,H19>0),1,(H19-I19)/I19)) -> 0 | M19: =IF(AND(L19=0,H19=0),0,IF(AND(L19=0,H19>0),1,(H19-L19)/L19)) -> 0
C20: 产品2 | E20: =IF(D20=0,0,D20/$D$34) -> 0 | G20: =IF(F20=0,0,F20/$F$34) -> 0 | H20: 0 | J20: =IF(AND(I20=0,H20=0),0,IF(AND(I20=0,H20>0),1,(H20-I20)/I20)) -> 0 | M20: =IF(AND(L20=0,H20=0),0,IF(AND(L20=0,H20>0),1,(H20-L20)/L20)) -> 0
C21: 产品3 | E21: =IF(D21=0,0,D21/$D$34) -> 0 | G21: =IF(F21=0,0,F21/$F$34) -> 0 | H21: 0 | J21: =IF(AND(I21=0,H21=0),0,IF(AND(I21=0,H21>0),1,(H21-I21)/I21)) -> 0 | M21: =IF(AND(L21=0,H21=0),0,IF(AND(L21=0,H21>0),1,(H21-L21)/L21)) -> 0
A22: 4 | B22: 大额客户四 | C22: 产品1 | E22: =IF(D22=0,0,D22/$D$34) -> 0 | G22: =IF(F22=0,0,F22/$F$34) -> 0 | H22: 0 | J22: =IF(AND(I22=0,H22=0),0,IF(AND(I22=0,H22>0),1,(H22-I22)/I22)) -> 0 | M22: =IF(AND(L22=0,H22=0),0,IF(AND(L22=0,H22>0),1,(H22-L22)/L22)) -> 0
C23: 产品2 | E23: =IF(D23=0,0,D23/$D$34) -> 0 | G23: =IF(F23=0,0,F23/$F$34) -> 0 | H23: 0 | J23: =IF(AND(I23=0,H23=0),0,IF(AND(I23=0,H23>0),1,(H23-I23)/I23)) -> 0 | M23: =IF(AND(L23=0,H23=0),0,IF(AND(L23=0,H23>0),1,(H23-L23)/L23)) -> 0
C24: 产品3 | E24: =IF(D24=0,0,D24/$D$34) -> 0 | G24: =IF(F24=0,0,F24/$F$34) -> 0 | H24: 0 | J24: =IF(AND(I24=0,H24=0),0,IF(AND(I24=0,H24>0),1,(H24-I24)/I24)) -> 0 | M24: =IF(AND(L24=0,H24=0),0,IF(AND(L24=0,H24>0),1,(H24-L24)/L24)) -> 0
A25: 5 | B25: 大额客户五 | C25: 产品1 | E25: =IF(D25=0,0,D25/$D$34) -> 0 | G25: =IF(F25=0,0,F25/$F$34) -> 0 | H25: 0 | J25: =IF(AND(I25=0,H25=0),0,IF(AND(I25=0,H25>0),1,(H25-I25)/I25)) -> 0 | M25: =IF(AND(L25=0,H25=0),0,IF(AND(L25=0,H25>0),1,(H25-L25)/L25)) -> 0
C26: 产品2 | E26: =IF(D26=0,0,D26/$D$34) -> 0 | G26: =IF(F26=0,0,F26/$F$34) -> 0 | H26: 0 | J26: =IF(AND(I26=0,H26=0),0,IF(AND(I26=0,H26>0),1,(H26-I26)/I26)) -> 0 | M26: =IF(AND(L26=0,H26=0),0,IF(AND(L26=0,H26>0),1,(H26-L26)/L26)) -> 0
C27: 产品3 | E27: =IF(D27=0,0,D27/$D$34) -> 0 | G27: =IF(F27=0,0,F27/$F$34) -> 0 | H27: 0 | J27: =IF(AND(I27=0,H27=0),0,IF(AND(I27=0,H27>0),1,(H27-I27)/I27)) -> 0 | M27: =IF(AND(L27=0,H27=0),0,IF(AND(L27=0,H27>0),1,(H27-L27)/L27)) -> 0
A28: 6 | B28: 异常客户X | C28: 产品1 | E28: =IF(D28=0,0,D28/$D$34) -> 0 | G28: =IF(F28=0,0,F28/$F$34) -> 0 | H28: 0 | J28: =IF(AND(I28=0,H28=0),0,IF(AND(I28=0,H28>0),1,(H28-I28)/I28)) -> 0 | M28: =IF(AND(L28=0,H28=0),0,IF(AND(L28=0,H28>0),1,(H28-L28)/L28)) -> 0
C29: 产品2 | E29: =IF(D29=0,0,D29/$D$34) -> 0 | G29: =IF(F29=0,0,F29/$F$34) -> 0 | H29: 0 | J29: =IF(AND(I29=0,H29=0),0,IF(AND(I29=0,H29>0),1,(H29-I29)/I29)) -> 0 | M29: =IF(AND(L29=0,H29=0),0,IF(AND(L29=0,H29>0),1,(H29-L29)/L29)) -> 0
C30: 产品3 | E30: =IF(D30=0,0,D30/$D$34) -> 0 | G30: =IF(F30=0,0,F30/$F$34) -> 0 | H30: 0 | J30: =IF(AND(I30=0,H30=0),0,IF(AND(I30=0,H30>0),1,(H30-I30)/I30)) -> 0 | M30: =IF(AND(L30=0,H30=0),0,IF(AND(L30=0,H30>0),1,(H30-L30)/L30)) -> 0
A31: 7 | B31: 异常客户Y | C31: 产品1 | E31: =IF(D31=0,0,D31/$D$34) -> 0 | G31: =IF(F31=0,0,F31/$F$34) -> 0 | H31: 0 | J31: =IF(AND(I31=0,H31=0),0,IF(AND(I31=0,H31>0),1,(H31-I31)/I31)) -> 0 | M31: =IF(AND(L31=0,H31=0),0,IF(AND(L31=0,H31>0),1,(H31-L31)/L31)) -> 0
C32: 产品2 | E32: =IF(D32=0,0,D32/$D$34) -> 0 | G32: =IF(F32=0,0,F32/$F$34) -> 0 | H32: 0 | J32: =IF(AND(I32=0,H32=0),0,IF(AND(I32=0,H32>0),1,(H32-I32)/I32)) -> 0 | M32: =IF(AND(L32=0,H32=0),0,IF(AND(L32=0,H32>0),1,(H32-L32)/L32)) -> 0
C33: 产品3 | E33: =IF(D33=0,0,D33/$D$34) -> 0 | G33: =IF(F33=0,0,F33/$F$34) -> 0 | H33: 0 | J33: =IF(AND(I33=0,H33=0),0,IF(AND(I33=0,H33>0),1,(H33-I33)/I33)) -> 0 | M33: =IF(AND(L33=0,H33=0),0,IF(AND(L33=0,H33>0),1,(H33-L33)/L33)) -> 0
A34: 本期销售总额 | D34: -- | F34: --
A35: 三、审计说明
A38: 四、审计结论
A40: 提示：根据《中国注册会计师审计准则问题解答第18号——识别和应对第三方配合实施财务舞弊》，项目组在分析主要客户销售产品价格时关注：
A41: 在第三方配合下，进行显失公允的交易。例如，以明显高于其他客户的价格向第三方销售商品。再如，与同一客户或同受一方控制的多个客户在各期发生多次交易，
A42: 在客户配合下，通过调节各次交易的商品销售价格，调节各期销售收入金额。

Sheet 产品销售价格分析D4-11
A1: 致同会计师事务所
A2: 产品销售价格分析
A3: =底稿目录!A2 -> 被审计单位名称： | F3: =底稿目录!A4 -> 编制人： | J3: =底稿目录!A5 -> 编制日期： | N3: 索引号： | O3: =底稿目录!F8 -> D4-11
A4: =底稿目录!A3 -> 会计期间：202X年度 | F4: =底稿目录!A6 -> 复核人： | J4: =底稿目录!A7 -> 复核日期： | N4: 页次：
A5: 一、审计目标
A6: 利润表中记录的营业收入已发生，且与被审计单位有关。
A7: 二、审计过程
A8: 1.……
A11: 序号 | B11: 客户名称 | C11: 品种/规格 | D11: 销售单价 | E11: 销售数量 | F11: 开票日期 | G11: 销售订单 （销售凭证） | H11: 订单日期 | I11: 商品销售价格表所列单价 | J11: 与定价政策差异 | K11: 同期市场价格 | L11: 与市价差异 | M11: 差异原因分析 | N11: 同期市场价格来源（索引号） | O11: 备注
A12: 1 | J12: 0 | L12: 0
A13: 2 | J13: 0 | L13: 0
A14: 3 | J14: 0 | L14: 0
A15: 4 | J15: 0 | L15: 0
A16: 5 | J16: 0 | L16: 0
A17: 6 | J17: 0 | L17: 0
A18: 7 | J18: 0 | L18: 0
A19: 8 | J19: 0 | L19: 0
A20: 9 | J20: 0 | L20: 0
A21: 10 | J21: 0 | L21: 0
A22: 三、审计说明
A25: 四、审计结论
