Workbook

Sheet 收入毛利分析D4-（整体毛利率因素分析法示例）
A1: 致同会计师事务所
A2: 收入毛利分析
A3: =[1]底稿目录!$A$2 -> 被审计单位： | H3: =[1]底稿目录!$A$4 -> 编制人： | M3: =[1]底稿目录!$A$5 -> 编制日期： | Q3: 索引号： | R3: D4-
A4: =[1]底稿目录!$A$3 -> 会计期间：202X年度 | H4: =[1]底稿目录!$A$6 -> 复核人： | M4: =[1]底稿目录!$A$7 -> 复核日期： | Q4: 页次：
A5: 一、审计目标：
A6: 1.利润表中记录的营业收入已发生，且与被审计单位有关，已记录于恰当的账户。2.所有应当记录的营业收入均已记录，所有应当包括在财务报表中的相关披露均已包括。3.与营业收入有关的金额及其他数据已恰当记录，相关披露已得到恰当计量和描述
A7: 二、审计过程
A8: 1.结合收入来源和销售模式，按年度和月度分析不同产品类别的销售结构和毛利的变化。
A9: 1.1分析被审计单位收入构成及变化情况是否符合行业和市场同期的变化情况。被审计单位产品或服务价格、销量及变动趋势与市场上相同或相近产品或服务的信息及其走势相比是否存在显著异常。
A10: 1.2除分析主要产品和服务之外，还需要考虑被审计单位是否有联产品和副产品产出；如有，应同时分析联产品和副产品的毛利变化情况，并结合营业成本的审计，判断联产品和副产品的成本分摊是否正确。
A11: 2.如异常与适当客户人员讨论重大差异。
A12: 3.考虑管理层解释的可信度，并在适当情况下进行证实。 | F12: 4.确定执行上述程序的结果是否表明需要补充必要的审计程序，如果是，执行适当的应对程序。
A13: (一）分析整体毛利率变动
A14: 1.将报告期收入成本按产品列示，可知2021-2022年产品总毛利率增长
A15: 产品名称 | B15: 产品类别 | C15: 2022年度 | K15: 2021年度
C16: 单位 | D16: 数量 | E16: 单价 | F16: 产品销售收入 | G16: 单位成本 | H16: 产品销售成本 | I16: 利润 | J16: 毛利率 | K16: 单位 | L16: 数量 | M16: 单价 | N16: 产品销售收入 | O16: 单位成本 | P16: 产品销售成本 | Q16: 利润 | R16: 毛利率
A17: 产品名称1 | B17: 产品类别A | C17: KG | D17: 17648669 | E17: =IFERROR(F17/D17,0) -> 20.500292 | F17: 3.6180287e+08 | G17: =IFERROR(H17/D17,0) -> 17.073908 | H17: 3.0133175e+08 | I17: =F17-H17 -> 60471125 | J17: =IF(F17=0,0,I17/F17) -> 0.16713832 | K17: KG | L17: 5481036.5 | M17: =IFERROR(N17/L17,0) -> 19.983046 | N17: 1.0952781e+08 | O17: =IFERROR(P17/L17,0) -> 17.112849 | P17: 93796150 | Q17: =N17-P17 -> 15731657 | R17: =IF(N17=0,0,Q17/N17) -> 0.14363162
A18: 产品名称2 | B18: 产品类别A | C18: KG | D18: 26447515 | E18: =IFERROR(F18/D18,0) -> 25.804504 | F18: 6.82465e+08 | G18: =IFERROR(H18/D18,0) -> 15.625036 | H18: 4.1324338e+08 | I18: =F18-H18 -> 2.6922162e+08 | J18: =IF(F18=0,0,I18/F18) -> 0.39448414 | K18: KG | L18: 22989950 | M18: =IFERROR(N18/L18,0) -> 29.632353 | N18: 6.812463e+08 | O18: =IFERROR(P18/L18,0) -> 16.618693 | P18: 3.8206292e+08 | Q18: =N18-P18 -> 2.9918338e+08 | R18: =IF(N18=0,0,Q18/N18) -> 0.43917065
A19: 产品名称3 | B19: 产品类别B | C19: KG | D19: 13901504 | E19: =IFERROR(F19/D19,0) -> 4.290132 | F19: 59639287 | G19: =IFERROR(H19/D19,0) -> 3.8155124 | H19: 53041361 | I19: =F19-H19 -> 6597925.6 | J19: =IF(F19=0,0,I19/F19) -> 0.11063053 | K19: KG | L19: 28685844 | M19: =IFERROR(N19/L19,0) -> 3.7716922 | N19: 1.0819417e+08 | O19: =IFERROR(P19/L19,0) -> 3.4433923 | P19: 98776612 | Q19: =N19-P19 -> 9417561.1 | R19: =IF(N19=0,0,Q19/N19) -> 0.087043145
A20: 产品名称4 | B20: 产品类别A | C20: KG | D20: 2893621.5 | E20: =IFERROR(F20/D20,0) -> 12.5315 | F20: 36261417 | G20: =IFERROR(H20/D20,0) -> 19.566288 | H20: 56617431 | I20: =F20-H20 -> -20356013 | J20: =IF(F20=0,0,I20/F20) -> -0.56136839 | K20: KG | L20: 2110131 | M20: =IFERROR(N20/L20,0) -> 10.957544 | N20: 23121853 | O20: =IFERROR(P20/L20,0) -> 11.84457 | P20: 24993593 | Q20: =N20-P20 -> -1871740.4 | R20: =IF(N20=0,0,Q20/N20) -> -0.080951142
A21: 产品名称5 | B21: 产品类别C | C21: KG | D21: 816.65 | E21: =IFERROR(F21/D21,0) -> 460.80022 | F21: 376312.5 | G21: =IFERROR(H21/D21,0) -> 753.05989 | H21: 614986.36 | I21: =F21-H21 -> -238673.86 | J21: =IF(F21=0,0,I21/F21) -> -0.63424377 | K21: KG | L21: 1784.25 | M21: =IFERROR(N21/L21,0) -> 522.70422 | N21: 932635 | O21: =IFERROR(P21/L21,0) -> 628.49036 | P21: 1121383.9 | Q21: =N21-P21 -> -188748.93 | R21: =IF(N21=0,0,Q21/N21) -> -0.20238242
A22: 产品名称6 | B22: 产品类别A | C22: KG | D22: 1951941 | E22: =IFERROR(F22/D22,0) -> 34.312495 | F22: 66975966 | G22: =IFERROR(H22/D22,0) -> 31.272513 | H22: 61042101 | I22: =F22-H22 -> 5933864.7 | J22: =IF(F22=0,0,I22/F22) -> 0.088596926 | K22: KG | L22: 1384317.5 | M22: =IFERROR(N22/L22,0) -> 57.988744 | N22: 80274834 | O22: =IFERROR(P22/L22,0) -> 29.591619 | P22: 40964196 | Q22: =N22-P22 -> 39310637 | R22: =IF(N22=0,0,Q22/N22) -> 0.48970064
A23: 产品名称7 | B23: 产品类别A | C23: KG | D23: 310909 | E23: =IFERROR(F23/D23,0) -> 28.865648 | F23: 8974589.9 | G23: =IFERROR(H23/D23,0) -> 16.289288 | H23: 5064486.2 | I23: =F23-H23 -> 3910103.7 | J23: =IF(F23=0,0,I23/F23) -> 0.43568606 | K23: KG | L23: 806841.5 | M23: =IFERROR(N23/L23,0) -> 59.419632 | N23: 47942225 | O23: =IFERROR(P23/L23,0) -> 16.945975 | P23: 13672716 | Q23: =N23-P23 -> 34269509 | R23: =IF(N23=0,0,Q23/N23) -> 0.71480848
A24: 产品名称8 | B24: 产品类别C | C24: 瓶 | D24: 422 | E24: =IFERROR(F24/D24,0) -> 44.241706 | F24: 18670 | G24: =IFERROR(H24/D24,0) -> 67.986991 | H24: 28690.51 | I24: =F24-H24 -> -10020.51 | J24: =IF(F24=0,0,I24/F24) -> -0.53671719 | K24: 瓶 | L24: 13773 | M24: =IFERROR(N24/L24,0) -> 34.945473 | N24: 481304 | O24: =IFERROR(P24/L24,0) -> 33.613876 | P24: 462963.91 | Q24: =N24-P24 -> 18340.09 | R24: =IF(N24=0,0,Q24/N24) -> 0.038105002
A25: 产品名称9 | B25: 产品类别C | C25: / | D25: 1 | E25: =IFERROR(F25/D25,0) -> 152380.96 | F25: 152380.96 | G25: =IFERROR(H25/D25,0) -> 164610.14 | H25: 164610.14 | I25: =F25-H25 -> -12229.18 | J25: =IF(F25=0,0,I25/F25) -> -0.08025399 | K25: / | L25: 1 | M25: =IFERROR(N25/L25,0) -> 91743.12 | N25: 91743.12 | O25: =IFERROR(P25/L25,0) -> 164726.04 | P25: 164726.04 | Q25: =N25-P25 -> -72982.92 | R25: =IF(N25=0,0,Q25/N25) -> -0.79551382
A26: 产品名称10 | B26: 产品类别C | C26: / | D26: 642.5 | E26: =IFERROR(F26/D26,0) -> 176.19852 | F26: 113207.55 | G26: =IFERROR(H26/D26,0) -> 40.866724 | H26: 26256.87 | I26: =F26-H26 -> 86950.68 | J26: =IF(F26=0,0,I26/F26) -> 0.76806432 | K26: / | L26: 0 | M26: =IFERROR(N26/L26,0) -> 0 | N26: 30220 | O26: =IFERROR(P26/L26,0) -> 0 | Q26: =N26-P26 -> 30220 | R26: =IF(N26=0,0,Q26/N26) -> 1
A27: 合计 | D27: =SUM(D17:D26) -> 63156042 | F27: =SUM(F17:F26) -> 1.2167797e+09 | H27: =SUM(H17:H26) -> 8.9117505e+08 | I27: =SUM(I17:I26) -> 3.2560465e+08 | J27: =(F27-H27)/F27 -> 0.2675954 | L27: =SUM(L17:L26) -> 61473678 | N27: =SUM(N17:N26) -> 1.0518431e+09 | P27: =SUM(P17:P26) -> 6.5601527e+08 | Q27: =SUM(Q17:Q26) -> 3.9582783e+08 | R27: =(N27-P27)/N27 -> 0.37631832
E28: 账面数据 | F28: 1.2167797e+09 | H28: 8.9117505e+08 | N28: 1.0518431e+09 | P28: 6.5601527e+08
E29: 核对差异 | F29: =F27-F28 -> 0 | H29: =H27-H28 -> 1.9073486e-06 | N29: =N27-N28 -> 0 | P29: =P27-P28 -> 0
I30: 毛利率变动 | J30: =J27-R27 -> -0.10872292
A31: 2.各产品对整体毛利率的影响。 | E31: 换算标准 | F31: 10000 | N31: 10000
A32: 产品名称 | B32: 产品类别 | C32: 2022年度 | G32: 2021年度 | K32: 对整体毛利率影响
C33: 主营业务收入 | D33: 单位销售成本/元 | E33: 主营业务成本金额CD/元 | F33: 销售毛利/元 | G33: 主营业务收入金额RD/元 | H33: 单位销售成本/元 | I33: 主营业务成本金额CD/元 | J33: 销售毛利/元
A34: =A17 -> 产品名称1 | B34: =B17 -> 产品类别A | C34: =F17/($F$27/$F$31) -> 2973.446 | D34: =IFERROR(H17/D17,0) -> 17.073908 | E34: =H17/($F$27/$F$31) -> 2476.4692 | F34: =C34-E34 -> 496.97677 | G34: =N17/($N$27/$N$31) -> 1041.2941 | H34: =IFERROR(P17/L17,0) -> 17.112849 | I34: =P17/($N$27/$N$31) -> 891.73138 | J34: =G34-I34 -> 149.56277 | K34: =(F34-J34) /10000 -> 0.0347414
A35: =A18 -> 产品名称2 | B35: =B18 -> 产品类别A | C35: =F18/($F$27/$F$31) -> 5608.7803 | D35: =IFERROR(H18/D18,0) -> 15.625036 | E35: =H18/($F$27/$F$31) -> 3396.2054 | F35: =C35-E35 -> 2212.5749 | G35: =N18/($N$27/$N$31) -> 6476.6913 | H35: =IFERROR(P18/L18,0) -> 16.618693 | I35: =P18/($N$27/$N$31) -> 3632.3186 | J35: =G35-I35 -> 2844.3727 | K35: =(F35-J35) /10000 -> -0.063179783
A36: =A19 -> 产品名称3 | B36: =B19 -> 产品类别B | C36: =F19/($F$27/$F$31) -> 490.14038 | D36: =IFERROR(H19/D19,0) -> 3.8155124 | E36: =H19/($F$27/$F$31) -> 435.9159 | F36: =C36-E36 -> 54.224488 | G36: =N19/($N$27/$N$31) -> 1028.6151 | H36: =IFERROR(P19/L19,0) -> 3.4433923 | I36: =P19/($N$27/$N$31) -> 939.08124 | J36: =G36-I36 -> 89.533897 | K36: =(F36-J36) /10000 -> -0.0035309409
A37: =A20 -> 产品名称4 | B37: =B20 -> 产品类别A | C37: =F20/($F$27/$F$31) -> 298.01136 | D37: =IFERROR(H20/D20,0) -> 19.566288 | E37: =H20/($F$27/$F$31) -> 465.30551 | F37: =C37-E37 -> -167.29416 | G37: =N20/($N$27/$N$31) -> 219.82226 | H37: =IFERROR(P20/L20,0) -> 11.84457 | I37: =P20/($N$27/$N$31) -> 237.61713 | J37: =G37-I37 -> -17.794863 | K37: =(F37-J37) /10000 -> -0.014949929
A38: =A21 -> 产品名称5 | B38: =B21 -> 产品类别C | C38: =F21/($F$27/$F$31) -> 3.0926921 | D38: =IFERROR(H21/D21,0) -> 753.05989 | E38: =H21/($F$27/$F$31) -> 5.0542128 | F38: =C38-E38 -> -1.9615207 | G38: =N21/($N$27/$N$31) -> 8.8666741 | H38: =IFERROR(P21/L21,0) -> 628.49036 | I38: =P21/($N$27/$N$31) -> 10.661133 | J38: =G38-I38 -> -1.794459 | K38: =(F38-J38) /10000 -> -1.6706173e-05
A39: =A22 -> 产品名称6 | B39: =B22 -> 产品类别A | C39: =F22/($F$27/$F$31) -> 550.43625 | D39: =IFERROR(H22/D22,0) -> 31.272513 | E39: =H22/($F$27/$F$31) -> 501.66929 | F39: =C39-E39 -> 48.76696 | G39: =N22/($N$27/$N$31) -> 763.18259 | H39: =IFERROR(P22/L22,0) -> 29.591619 | I39: =P22/($N$27/$N$31) -> 389.45158 | J39: =G39-I39 -> 373.731 | K39: =(F39-J39) /10000 -> -0.032496404
A40: =A23 -> 产品名称7 | B40: =B23 -> 产品类别A | C40: =F23/($F$27/$F$31) -> 73.7569 | D40: =IFERROR(H23/D23,0) -> 16.289288 | E40: =H23/($F$27/$F$31) -> 41.622047 | F40: =C40-E40 -> 32.134853 | G40: =N23/($N$27/$N$31) -> 455.79255 | H40: =IFERROR(P23/L23,0) -> 16.945975 | I40: =P23/($N$27/$N$31) -> 129.98817 | J40: =G40-I40 -> 325.80438 | K40: =(F40-J40) /10000 -> -0.029366953
...

Sheet 合同履行检查表（示例）D4-
A1: 致同会计师事务所 | W1: 致同会计师事务所
A2: 合同履行检查表 | W2: 合同履行检查表
A3: =[1]底稿目录!$A$2 -> 被审计单位： | H3: =[1]底稿目录!$A$4 -> 编制人： | P3: =[1]底稿目录!$A$5 -> 编制日期： | U3: 索引号： | V3: D4- | W3: =[1]底稿目录!$A$2 -> 被审计单位： | AD3: =[1]底稿目录!$A$4 -> 编制人： | AI3: =[1]底稿目录!$A$5 -> 编制日期： | AP3: 索引号： | AQ3: D4-
A4: =[1]底稿目录!$A$3 -> 会计期间：202X年度 | H4: =[1]底稿目录!$A$6 -> 复核人： | P4: =[1]底稿目录!$A$7 -> 复核日期： | U4: 页次： | W4: =[1]底稿目录!$A$3 -> 会计期间：202X年度 | AD4: =[1]底稿目录!$A$6 -> 复核人： | AI4: =[1]底稿目录!$A$7 -> 复核日期： | AP4: 页次：
A5: 一、审计目标：
A6: 1.利润表中记录的营业收入已发生，且与被审计单位有关，已记录于恰当的账户。2.与营业收入有关的金额及其他数据已恰当记录，相关披露已得到恰当计量和描述
A7: 二、审计过程：
A8: 1.确定交易是否按合同条款履行（考虑直接与合同方函证合同条款）; | H8: 2.确定对原始合同的修改以及增加均有签字确认; | N8: 3.选取重要合同样本，测试收入确认时点及核算口径（总额、净额）是否正确;
A9: 4.关注销售合同签署人向最终产品签收人是否相符，签名是否一致； | H9: 5.关注销售内容披露情况与销售合同约定和实际情况是否一致。
A10: 项目基本信息 | F10: 财务系统账面收入信息 | P10: 项目收款及质保信息 | AA10: 出库信息 | AD10: 货运物流信息 | AH10: 收入确认政策及依据
A11: 产品分类 | B11: 项目名称 | C11: 关联关系 | D11: 合同客户（全称） | E11: 最终客户（全称） | F11: 合同签订日期 | G11: 合同号/索引 | H11: 合同金额 | I11: 补充协议金额 | J11: 收入确认时间 | K11: 账面收入金额 | L11: 账面成本金额 | M11: 毛利金额 | N11: 毛利率 | O11: 毛利率异常分析说明 | P11: 合同收款方式及进度约定 | Q11: 截至收入确认当月累计收款金额 | R11: 截至收入确认当月累计收款进度 | S11: 截至收入确认当年末累计收款金额 | T11: 截至收入确认当年末收款进度 | U11: 截至审计报告日累计收款金额 | V11: 截至审计报告日累计收款进度 | W11: 合同质保约定 | X11: 质保期限（月） | Y11: 质保金比例 | Z11: 质保到期日 | AA11: 出库单号 | AB11: 出库日期 | AC11: 其他 | AD11: 起运日期 | AE11: 到货签收日期 | AF11: 签收人 | AG11: 签收单位 | AH11: 收入确认政策（时点法/时段法） | AI11: 收入确认资料名称（验收单等） | AJ11: 验收日期 | AK11: 验收单签字人 | AL11: 验收单盖章信息(公章/合同章/部门章) | AM11: 验收单盖章单位 | AN11: 监理确认日期 | AO11: 监理签字人 | AP11: 监理单位盖章 | AQ11: 验收单索引
A27: 合计 | H27: =SUM(H12:H26) -> 0 | K27: =SUM(K12:K26) -> 0 | L27: =SUM(L12:L26) -> 0 | M27: =SUM(M12:M26) -> 0 | Q27: =SUM(Q12:Q26) -> 0 | S27: =SUM(S12:S26) -> 0 | U27: =SUM(U12:U26) -> 0
A28: 本期发生额
A29: 检查比例 | K29: =K27/K28 -> #DIV/0!
A31: 三、审计说明
A34: 四、审计结论

Sheet 工程施工收入检查表（示例）D4-
A1: 致同会计师事务所 | Y1: 致同会计师事务所 | AO1: 致同会计师事务所
A2: 工程施工收入检查表 | Y2: 工程施工收入检查表 | AO2: 工程施工收入检查表
A3: =[1]底稿目录!$A$2 -> 被审计单位： | J3: =[1]底稿目录!$A$4 -> 编制人： | P3: =[1]底稿目录!$A$5 -> 编制日期： | W3: 索引号： | X3: D4- | Y3: =[1]底稿目录!$A$2 -> 被审计单位： | AD3: =[1]底稿目录!$A$4 -> 编制人： | AH3: =[1]底稿目录!$A$5 -> 编制日期： | AM3: 索引号： | AN3: D4- | AO3: =[1]底稿目录!$A$2 -> 被审计单位： | AT3: =[1]底稿目录!$A$4 -> 编制人： | AX3: =[1]底稿目录!$A$5 -> 编制日期： | BC3: 索引号： | BD3: D4-
A4: =[1]底稿目录!$A$3 -> 会计期间：202X年度 | J4: =[1]底稿目录!$A$6 -> 复核人： | P4: =[1]底稿目录!$A$7 -> 复核日期： | W4: 页 次： | Y4: =[1]底稿目录!$A$3 -> 会计期间：202X年度 | AD4: =[1]底稿目录!$A$6 -> 复核人： | AH4: =[1]底稿目录!$A$7 -> 复核日期： | AM4: 页次： | AO4: =[1]底稿目录!$A$3 -> 会计期间：202X年度 | AT4: =[1]底稿目录!$A$6 -> 复核人： | AX4: =[1]底稿目录!$A$7 -> 复核日期： | BC4: 页次：
A5: 一、审计目标：
A6: 1.利润表中记录的营业收入已发生，且与被审计单位有关，已记录于恰当的账户。2.所有应当记录的营业收入均已记录，所有应当包括在财务报表中的相关披露均已包括。3.与营业收入有关的金额及其他数据已恰当记录，相关披露已得到恰当计量和描述
A7: 二、审计过程
A8: 1.获取工程施工项目台账，了解工程项目基本信息，并与企业明细账记录核对。
A9: 2.获取履约进度审核报告、竣工验收报告、监理报告等核实工程进度情况。
A10: 3.重新计算履约进度、收入、成本等，确认被审计单位计算是否正确。
A11: 序号 | B11: 项目基本信息 | N11: 企业记录 | Y11: 审计测算成本及收入 | AO11: 审计调整 | AR11: 审定数 | AU11: 核对 | AW11: 其他信息及资料 | BD11: 索引号
B12: 项目编码 | C12: 项目名称 | D12: 客户名称 | E12: 是否关联方 | F12: 合同金额（含税） | G12: 合同预计总收入（不含税） | H12: 实际开工日期 | I12: 实际完工日期 | J12: 合同预计总成本（不含税） | K12: 合同成本调整 | L12: 调整时间 | M12: 项目预计毛利率 | N12: 期初累计成本 | O12: 本期实际成本金额 | P12: 期末累计成本 | Q12: 履约进度 | R12: 累计结算金额 | S12: 当期结算金额 | T12: 累计收款 | U12: 当期收款 | V12: 期初累计确认收入 | W12: 期末累计确认收入 | X12: 当期确认收入 | Y12: 期初审计确认累计发生成本 | Z12: 本期审计确认成本 | AA12: 期末审计确认累计总成本 | AB12: 期初履约进度 | AC12: 期末履约进度 | AD12: 期初累计应确认收入 | AE12: 期末累计应确认收入 | AF12: 当期应确认收入金额 | AG12: 期末应收余额 | AH12: 期末合同资产余额 | AI12: 期末合同负债余额 | AJ12: 期末预计负债-预计合同损失 | AK12: 期末累计成本差异 | AL12: 当期成本差异 | AM12: 期末累计收入差异 | AN12: 当期收入差异 | AO12: 当期收入 | AP12: 当期营业成本 | AQ12: …… | AR12: 当期营业收入 | AS12: 当期营业成本 | AT12: …… | AU12: 账面期末累计成本与合同履约成本累计金额是否一致 | AV12: 合同履约进度是否与实际检查信息相符 | AW12: 经业主、监理确认工程进度情况 | AX12: 项目是否竣工验收 | AY12: 是否检查相关依据 | AZ12: 检查索引 | BA12: 累计开票金额 | BB12: 当期末票金额 | BC12: 是否函证
AR13: =AO13+X13 -> 0 | AS13: =AP13+Z13 -> 0
AB14: =Y14/J14 -> #DIV/0! | AC14: =AA14/J14 -> #DIV/0! | AD14: =AB14*G14 -> #DIV/0! | AE14: =AC14*G14 -> #DIV/0! | AF14: =AE14-AD14 -> #DIV/0! | AG14: =R14*1-T14 -> 0 | AH14: =IF(AE14-R14>0,AE14-R14,0) -> #DIV/0! | AI14: =IF(R14-AE14<0,0,R14-AE14) -> #DIV/0! | AJ14: =IF(G14-J14<0,(J14-G14)*(1-AC14),0) -> 0 | AK14: =AA14-P14 -> 0 | AL14: =Z14-O14 -> 0 | AM14: =AE14-W14 -> #DIV/0! | AN14: =AF14-X14 -> #DIV/0! | AR14: =AO14+X14 -> 0 | AS14: =AP14+Z14 -> 0
AB15: =Y15/J15 -> #DIV/0! | AC15: =AA15/J15 -> #DIV/0! | AD15: =AB15*G15 -> #DIV/0! | AE15: =AC15*G15 -> #DIV/0! | AF15: =AE15-AD15 -> #DIV/0! | AG15: =R15*1.1-T15 -> 0 | AH15: =IF(AE15-R15>0,AE15-R15,0) -> #DIV/0! | AI15: =IF(R15-AE15<0,0,R15-AE15) -> #DIV/0! | AJ15: =IF(G15-J15<0,(J15-G15)*(1-AC15),0) -> 0 | AK15: =AA15-P15 -> 0 | AL15: =Z15-O15 -> 0 | AM15: =AE15-W15 -> #DIV/0! | AN15: =AF15-X15 -> #DIV/0! | AR15: =AO15+X15 -> 0 | AS15: =AP15+Z15 -> 0
AB16: =Y16/J16 -> #DIV/0! | AC16: =AA16/J16 -> #DIV/0! | AD16: =AB16*G16 -> #DIV/0! | AE16: =AC16*G16 -> #DIV/0! | AF16: =AE16-AD16 -> #DIV/0! | AG16: =R16*1.1-T16 -> 0 | AH16: =IF(AE16-R16>0,AE16-R16,0) -> #DIV/0! | AI16: =IF(R16-AE16<0,0,R16-AE16) -> #DIV/0! | AJ16: =IF(G16-J16<0,(J16-G16)*(1-AC16),0) -> 0 | AK16: =AA16-P16 -> 0 | AL16: =Z16-O16 -> 0 | AM16: =AE16-W16 -> #DIV/0! | AN16: =AF16-X16 -> #DIV/0! | AR16: =AO16+X16 -> 0 | AS16: =AP16+Z16 -> 0
AB17: =Y17/J17 -> #DIV/0! | AC17: =AA17/J17 -> #DIV/0! | AD17: =AB17*G17 -> #DIV/0! | AE17: =AC17*G17 -> #DIV/0! | AF17: =AE17-AD17 -> #DIV/0! | AG17: =R17*1.1-T17 -> 0 | AH17: =IF(AE17-R17>0,AE17-R17,0) -> #DIV/0! | AI17: =IF(R17-AE17<0,0,R17-AE17) -> #DIV/0! | AJ17: =IF(G17-J17<0,(J17-G17)*(1-AC17),0) -> 0 | AK17: =AA17-P17 -> 0 | AL17: =Z17-O17 -> 0 | AM17: =AE17-W17 -> #DIV/0! | AN17: =AF17-X17 -> #DIV/0! | AR17: =AO17+X17 -> 0 | AS17: =AP17+Z17 -> 0
AB18: =Y18/J18 -> #DIV/0! | AC18: =AA18/J18 -> #DIV/0! | AD18: =AB18*G18 -> #DIV/0! | AE18: =AC18*G18 -> #DIV/0! | AF18: =AE18-AD18 -> #DIV/0! | AG18: =R18*1.1-T18 -> 0 | AH18: =IF(AE18-R18>0,AE18-R18,0) -> #DIV/0! | AI18: =IF(R18-AE18<0,0,R18-AE18) -> #DIV/0! | AJ18: =IF(G18-J18<0,(J18-G18)*(1-AC18),0) -> 0 | AK18: =AA18-P18 -> 0 | AL18: =Z18-O18 -> 0 | AM18: =AE18-W18 -> #DIV/0! | AN18: =AF18-X18 -> #DIV/0! | AR18: =AO18+X18 -> 0 | AS18: =AP18+Z18 -> 0
AB19: =Y19/J19 -> #DIV/0! | AC19: =AA19/J19 -> #DIV/0! | AD19: =AB19*G19 -> #DIV/0! | AE19: =AC19*G19 -> #DIV/0! | AF19: =AE19-AD19 -> #DIV/0! | AG19: =R19*1.1-T19 -> 0 | AH19: =IF(AE19-R19>0,AE19-R19,0) -> #DIV/0! | AI19: =IF(R19-AE19<0,0,R19-AE19) -> #DIV/0! | AJ19: =IF(G19-J19<0,(J19-G19)*(1-AC19),0) -> 0 | AK19: =AA19-P19 -> 0 | AL19: =Z19-O19 -> 0 | AM19: =AE19-W19 -> #DIV/0! | AN19: =AF19-X19 -> #DIV/0! | AR19: =AO19+X19 -> 0 | AS19: =AP19+Z19 -> 0
AB20: =Y20/J20 -> #DIV/0! | AC20: =AA20/J20 -> #DIV/0! | AD20: =AB20*G20 -> #DIV/0! | AE20: =AC20*G20 -> #DIV/0! | AF20: =AE20-AD20 -> #DIV/0! | AG20: =R20*1.1-T20 -> 0 | AH20: =IF(AE20-R20>0,AE20-R20,0) -> #DIV/0! | AI20: =IF(R20-AE20<0,0,R20-AE20) -> #DIV/0! | AJ20: =IF(G20-J20<0,(J20-G20)*(1-AC20),0) -> 0 | AK20: =AA20-P20 -> 0 | AL20: =Z20-O20 -> 0 | AM20: =AE20-W20 -> #DIV/0! | AN20: =AF20-X20 -> #DIV/0! | AR20: =AO20+X20 -> 0 | AS20: =AP20+Z20 -> 0
AB21: =Y21/J21 -> #DIV/0! | AC21: =AA21/J21 -> #DIV/0! | AD21: =AB21*G21 -> #DIV/0! | AE21: =AC21*G21 -> #DIV/0! | AF21: =AE21-AD21 -> #DIV/0! | AG21: =R21*1.1-T21 -> 0 | AH21: =IF(AE21-R21>0,AE21-R21,0) -> #DIV/0! | AI21: =IF(R21-AE21<0,0,R21-AE21) -> #DIV/0! | AJ21: =IF(G21-J21<0,(J21-G21)*(1-AC21),0) -> 0 | AK21: =AA21-P21 -> 0 | AL21: =Z21-O21 -> 0 | AM21: =AE21-W21 -> #DIV/0! | AN21: =AF21-X21 -> #DIV/0! | AR21: =AO21+X21 -> 0 | AS21: =AP21+Z21 -> 0
AB22: =Y22/J22 -> #DIV/0! | AC22: =AA22/J22 -> #DIV/0! | AD22: =AB22*G22 -> #DIV/0! | AE22: =AC22*G22 -> #DIV/0! | AF22: =AE22-AD22 -> #DIV/0! | AG22: =R22*1.1-T22 -> 0 | AH22: =IF(AE22-R22>0,AE22-R22,0) -> #DIV/0! | AI22: =IF(R22-AE22<0,0,R22-AE22) -> #DIV/0! | AJ22: =IF(G22-J22<0,(J22-G22)*(1-AC22),0) -> 0 | AK22: =AA22-P22 -> 0 | AL22: =Z22-O22 -> 0 | AM22: =AE22-W22 -> #DIV/0! | AN22: =AF22-X22 -> #DIV/0! | AR22: =AO22+X22 -> 0 | AS22: =AP22+Z22 -> 0
AB23: =Y23/J23 -> #DIV/0! | AC23: =AA23/J23 -> #DIV/0! | AD23: =AB23*G23 -> #DIV/0! | AE23: =AC23*G23 -> #DIV/0! | AF23: =AE23-AD23 -> #DIV/0! | AG23: =R23*1.1-T23 -> 0 | AH23: =IF(AE23-R23>0,AE23-R23,0) -> #DIV/0! | AI23: =IF(R23-AE23<0,0,R23-AE23) -> #DIV/0! | AJ23: =IF(G23-J23<0,(J23-G23)*(1-AC23),0) -> 0 | AK23: =AA23-P23 -> 0 | AL23: =Z23-O23 -> 0 | AM23: =AE23-W23 -> #DIV/0! | AN23: =AF23-X23 -> #DIV/0! | AR23: =AO23+X23 -> 0 | AS23: =AP23+Z23 -> 0
AB24: =Y24/J24 -> #DIV/0! | AC24: =AA24/J24 -> #DIV/0! | AD24: =AB24*G24 -> #DIV/0! | AE24: =AC24*G24 -> #DIV/0! | AF24: =AE24-AD24 -> #DIV/0! | AG24: =R24*1.1-T24 -> 0 | AH24: =IF(AE24-R24>0,AE24-R24,0) -> #DIV/0! | AI24: =IF(R24-AE24<0,0,R24-AE24) -> #DIV/0! | AJ24: =IF(G24-J24<0,(J24-G24)*(1-AC24),0) -> 0 | AK24: =AA24-P24 -> 0 | AL24: =Z24-O24 -> 0 | AM24: =AE24-W24 -> #DIV/0! | AN24: =AF24-X24 -> #DIV/0! | AR24: =AO24+X24 -> 0 | AS24: =AP24+Z24 -> 0
AB25: =Y25/J25 -> #DIV/0! | AC25: =AA25/J25 -> #DIV/0! | AD25: =AB25*G25 -> #DIV/0! | AE25: =AC25*G25 -> #DIV/0! | AF25: =AE25-AD25 -> #DIV/0! | AG25: =R25*1.1-T25 -> 0 | AH25: =IF(AE25-R25>0,AE25-R25,0) -> #DIV/0! | AI25: =IF(R25-AE25<0,0,R25-AE25) -> #DIV/0! | AJ25: =IF(G25-J25<0,(J25-G25)*(1-AC25),0) -> 0 | AK25: =AA25-P25 -> 0 | AL25: =Z25-O25 -> 0 | AM25: =AE25-W25 -> #DIV/0! | AN25: =AF25-X25 -> #DIV/0! | AR25: =AO25+X25 -> 0 | AS25: =AP25+Z25 -> 0
A26: 合计 | F26: =SUM(F13:F25) -> 0 | N26: =SUM(N13:N25) -> 0 | O26: =SUM(O13:O25) -> 0 | P26: =SUM(P13:P25) -> 0 | R26: =SUM(R13:R25) -> 0 | S26: =SUM(S13:S25) -> 0 | T26: =SUM(T13:T25) -> 0 | U26: =SUM(U13:U25) -> 0 | V26: =SUM(V13:V25) -> 0 | W26: =SUM(W13:W25) -> 0 | X26: =SUM(X13:X25) -> 0 | Y26: =SUM(Y13:Y25) -> 0 | ... AA26: =SUM(AA13:AA25) -> 0 | AD26: =SUM(AD13:AD25) -> #DIV/0! | AE26: =SUM(AE13:AE25) -> #DIV/0! | AF26: =SUM(AF13:AF25) -> #DIV/0! | AG26: =SUM(AG13:AG25) -> 0 | AH26: =SUM(AH13:AH25) -> #DIV/0! | AI26: =SUM(AI13:AI25) -> #DIV/0! | AJ26: =SUM(AJ13:AJ25) -> 0 | AK26: =SUM(AK13:AK25) -> 0 | ... AS26: =SUM(AS13:AS25) -> 0 | BA26: =SUM(BA13:BA25) -> 0 | BB26: =SUM(BB13:BB25) -> 0
A27: 三、审计说明
A31: 四、审计结论
A33: 【项目组应根据实际情况进行增减】

Sheet 贸易收入检查（示例）D4-
A1: 致同会计师事务所 | AB1: 致同会计师事务所 | AT1: 致同会计师事务所
A2: 贸易收入检查 | AB2: 贸易收入检查 | AT2: 贸易收入检查
A3: =[1]底稿目录!$A$2 -> 被审计单位： | I3: =[1]底稿目录!$A$4 -> 编制人： | R3: =[1]底稿目录!$A$5 -> 编制日期： | Z3: 索引号： | AA3: D4- | AB3: =[2]底稿目录!$A$2 -> 被审计单位： | AF3: =[2]底稿目录!$A$4 -> 编制人： | AK3: =[2]底稿目录!$A$5 -> 编制日期： | AT3: =[2]底稿目录!$A$2 -> 被审计单位： | BA3: =[2]底稿目录!$A$4 -> 编制人： | BG3: =[2]底稿目录!$A$5 -> 编制日期： | BL3: 索引号： | BM3: D4-
A4: =[1]底稿目录!$A$3 -> 会计期间：202X年度 | I4: =[1]底稿目录!$A$6 -> 复核人： | R4: =[1]底稿目录!$A$7 -> 复核日期： | Z4: 页次： | AB4: =[2]底稿目录!$A$3 -> 会计期间： | AF4: =[2]底稿目录!$A$6 -> 复核人： | AK4: =[2]底稿目录!$A$7 -> 复核日期： | AT4: =[2]底稿目录!$A$3 -> 会计期间： | BA4: =[2]底稿目录!$A$6 -> 复核人： | BG4: =[2]底稿目录!$A$7 -> 复核日期： | BL4: 页次：
A5: 一、审计目标：
A6: 1.利润表中记录的营业收入已发生，且与被审计单位有关，已记录于恰当的账户。2.所有应当记录的营业收入均已记录，所有应当包括在财务报表中的相关披露均已包括。3.与营业收入有关的金额及其他数据已恰当记录，相关披露已得到恰当计量和描述
A7: 二、审计过程：
A8: 1.询问管理层开展贸易收入的背景以及相关业务流程。
A9: 2.获取销售和采购清单、明细账等资料，核对采购和销售情况。
A10: 3.分析毛利率是否合理，关注企业的销售价格与资金占用时间的长短是否存在关系。
A11: 4.检查货物流转、资金流转情况，确定企业会计处理是否恰当，判断交易性质。
A12: 序号 | B12: 收入记账凭证 | E12: 采购记账凭证 | H12: 毛利率 | I12: 销售合同（含税） | P12: 客户性质 | Q12: 控制权转移方式 | R12: 出库单 | U12: 发出库房名称 | V12: 运输单据 | AB12: 货权转移（验收）证明/收货确认单/放货通知单 | AH12: 收款凭证 | AM12: 采购合同（含税） | AT12: 供应商性质 | AU12: 控制权转移方式 | AV12: 入库单 | AY12: 收货库房名称 | AZ12: 货权转移（验收）证明/收货确认单/放货通知单 | BF12: 付款凭证 | BK12: 上、下游是否是关联方 | BL12: 是否指定采购或销售 | BM12: 是否成本加成
B13: 日期 | C13: 编号 | D13: 收入确认金额 | E13: 日期 | F13: 编号 | G13: 成本结转金额 | I13: 日期 | J13: 合同号 | K13: 客户名称 | L13: 品种规格 | M13: 数量 | N13: 单价 | O13: 金额 | R13: 日期 | S13: 品种规格 | T13: 数量 | V13: 日期 | W13: 发货地 | X13: 收货地 | Y13: 运输单位名称 | Z13: 品种规格 | AA13: 数量 | AB13: 日期 | AC13: 对方单位名称 | AD13: 品种规格 | AE13: 数量 | AF13: 单价 | AG13: 金额 | AH13: 日期 | AI13: 记账凭证号 | AJ13: 金额 | AK13: 结算形式 | AL13: 付款方 | AM13: 日期 | AN13: 合同号 | AO13: 供应商名称 | AP13: 品种规格 | AQ13: 数量 | AR13: 单价 | AS13: 金额 | AV13: 日期 | AW13: 品种规格 | AX13: 数量 | AZ13: 日期 | BA13: 对方单位名称 | BB13: 品种规格 | BC13: 数量 | BD13: 单价 | BE13: 金额 | BF13: 日期 | BG13: 记账凭证号 | BH13: 金额 | BI13: 结算形式 | BJ13: 收款方
H14: =(D14-G14)/D14 -> #DIV/0!
H15: =(D15-G15)/D15 -> #DIV/0!
H16: =(D16-G16)/D16 -> #DIV/0!
H17: =(D17-G17)/D17 -> #DIV/0!
H18: =(D18-G18)/D18 -> #DIV/0!
H19: =(D19-G19)/D19 -> #DIV/0!
H20: =(D20-G20)/D20 -> #DIV/0!
H21: =(D21-G21)/D21 -> #DIV/0!
H22: =(D22-G22)/D22 -> #DIV/0!
H23: =(D23-G23)/D23 -> #DIV/0!
H24: =(D24-G24)/D24 -> #DIV/0!
H25: =(D25-G25)/D25 -> #DIV/0!
... H28: =(D28-G28)/D28 -> #DIV/0!
A29: 合计 | D29: =SUM(D14:D28) -> 0 | G29: =SUM(G14:G28) -> 0 | H29: =(D29-G29)/D29 -> #DIV/0! | O29: =SUM(O14:O28) -> 0 | AG29: =SUM(AG14:AG28) -> 0 | AJ29: =SUM(AJ14:AJ28) -> 0 | AS29: =SUM(AS14:AS28) -> 0 | BE29: =SUM(BE14:BE28) -> 0 | BH29: =SUM(BH14:BH28) -> 0
A30: 三、审计说明
A34: 四、审计结论
A36: 提示：对于贸易收入相关审计关注要点请参见《审计提示第29号（7）——融资性贸易、“空转”“走单”业务的舞弊风险识别与审计应对》 | P36: 终端使用客户 | Q36: 货未移动，通过货权转移单转移货权 | AK36: 银行
P37: 贸易商 | Q37: 货由生产商仓库或供应商发给客户 | AK37: 票据
P38: 生产商 | Q38: 货由公司发给客户
Q39: 货由供应商直接发给本单位
Q40: 货由生产商发给本单位

Sheet BOT收入测算（示例）D4-
A1: 致同会计师事务所
A2: BOT业务收入测算
A3: =[1]底稿目录!$A$2 -> 被审计单位： | D3: =[1]底稿目录!$A$4 -> 编制人： | G3: =[1]底稿目录!$A$5 -> 编制日期： | K3: 索引号： | L3: D4-
A4: =[1]底稿目录!$A$3 -> 会计期间：202X年度 | D4: =[1]底稿目录!$A$6 -> 复核人： | G4: =[1]底稿目录!$A$7 -> 复核日期： | K4: 页 次：
A6: 服务 | B6: 年 | C6: 预计成本 | D6: 预计毛利率 | E6: 单独售价 | F6: （1）根据成本加成等方法确定单独售价；
A7: 建造服务 | B7: 1 | C7: 50 | D7: 0.05 | E7: =C7*(1+D7) -> 52.5 | F7: （2）单独售价合计应低于合同总额，差额部分是融资的利息收入；
B8: 2 | C8: 50 | D8: 0.05 | E8: =C8*(1+D8) -> 52.5 | F8: （3）根据收入确认进度确定合同资产与应收款项余额；
A9: 运营服务 | B9: ‘3-10 | C9: 1 | D9: 0.2 | E9: =C9*(1+D9) -> 1.2 | F9: （4）使用插值法计算利率，使得总收入（含利息收入）等于合同总价。
A10: 大修服务 | B10: 8 | C10: 10 | D10: 0.1 | E10: =C10*(1+D10) -> 11 | F10: （5）注意质保金应列报为合同资产。
C11: =C7+C8+C9*8+C10 -> 118 | E11: =E7+E8+E9*8+E10 -> 125.6
A13: 项目 | B13: 1 | C13: 2 | D13: 3 | E13: 4 | F13: 5 | G13: 6 | H13: 7 | I13: 8 | J13: 9 | K13: 10 | L13: 合计
A14: 成本 | B14: 50 | C14: 50 | D14: 1 | E14: 1 | F14: 1 | G14: 1 | H14: 1 | I14: 11 | J14: 1 | K14: 1 | L14: =SUM(B14:K14) -> 118
A15: 收款 | D15: 20 | E15: 20 | F15: 20 | G15: 20 | H15: 20 | I15: 20 | J15: 20 | K15: 20 | L15: =SUM(B15:K15) -> 160
A16: 建造收入 | B16: =E7 -> 52.5 | C16: =E8 -> 52.5 | L16: =SUM(B16:K16) -> 105
A17: 运营收入 | D17: 1.2 | E17: 1.2 | F17: 1.2 | G17: 1.2 | H17: 1.2 | I17: 1.2 | J17: 1.2 | K17: 1.2 | L17: =SUM(B17:K17) -> 9.6
A18: 大修收入 | I18: =E10 -> 11 | L18: =SUM(B18:K18) -> 11
A19: 合同资产 | B19: =B16 -> 52.5
A20: 应收款项 | C20: =B19*(1+$B$21)+C16 -> 108.2441 | D20: =C20*(1+$B$21)-(D15-D17-D18) -> 96.132758 | E20: =D20*(1+$B$21)-(E15-E17-E18) -> 83.273029 | F20: =E20*(1+$B$21)-(F15-F17-F18) -> 69.618667 | G20: =F20*(1+$B$21)-(G15-G17-G18) -> 55.120569 | H20: =G20*(1+$B$21)-(H15-H17-H18) -> 39.726599 | I20: =H20*(1+$B$21)-(I15-I17-I18) -> 34.3814 | J20: =I20*(1+$B$21)-(J15-J17-J18) -> 17.705908 | K20: =J20*(1+$B$21)-(K15-K17-K18) -> -1.7865457e-06
A21: 利息收入 | B21: 0.061792367 | C21: =(B19+B20)*$B$21 -> 3.2440993 | D21: =(C19+C20)*$B$21 -> 6.6886592 | E21: =(D19+D20)*$B$21 -> 5.9402707 | F21: =(E19+E20)*$B$21 -> 5.1456376 | G21: =(F19+F20)*$B$21 -> 4.3019022 | H21: =(G19+G20)*$B$21 -> 3.4060305 | I21: =(H19+H20)*$B$21 -> 2.4548006 | J21: =(I19+I20)*$B$21 -> 2.1245081 | K21: =(J19+J20)*$B$21 -> 1.09409 | L21: =SUM(C21:K21) -> 34.399998
A22: 收入合计 | B22: =B16+B17+B18 -> 52.5 | C22: =C16+C17+C18+C21 -> 55.744099 | D22: =D16+D17+D18+D21 -> 7.8886592 | E22: =E16+E17+E18+E21 -> 7.1402707 | F22: =F16+F17+F18+F21 -> 6.3456376 | G22: =G16+G17+G18+G21 -> 5.5019022 | H22: =H16+H17+H18+H21 -> 4.6060305 | I22: =I16+I17+I18+I21 -> 14.654801 | J22: =J16+J17+J18+J21 -> 3.3245081 | K22: =K16+K17+K18+K21 -> 2.29409 | L22: =SUM(B22:K22) -> 160
A23: 现金缺口 | B23: =-B14 -> -50 | C23: =B23-C14+C15-C24 -> -103.35 | D23: =C23-D14+D15-D24 -> -91.27445 | E23: =D23-E14+E15-E24 -> -78.389838 | F23: =E23-F14+F15-F24 -> -64.641957 | G23: =F23-G14+G15-G24 -> -49.972968 | H23: =G23-H14+H15-H24 -> -34.321157 | I23: =H23-I14+I15-I24 -> -27.620675 | J23: =I23-J14+J15-J24 -> -10.47126 | K23: =J23-K14+K15-K24 -> 7.8271655
A24: 借款费用 | B24: 0.067 | C24: =-B23*$B$24 -> 3.35 | D24: =-C23*$B$24 -> 6.92445 | E24: =-D23*$B$24 -> 6.1153882 | F24: =-E23*$B$24 -> 5.2521192 | G24: =-F23*$B$24 -> 4.3310111 | H24: =-G23*$B$24 -> 3.3481889 | I24: =-H23*$B$24 -> 2.2995175 | J24: =-I23*$B$24 -> 1.8505852 | K24: =-J23*$B$24 -> 0.70157443 | L24: =SUM(C24:K24) -> 34.172835
A25: 现金流 | B25: =-B14+B15 -> -50 | C25: =-C14+C15-C24 -> -53.35 | D25: =-D14+D15-D24 -> 12.07555 | E25: =-E14+E15-E24 -> 12.884612 | F25: =-F14+F15-F24 -> 13.747881 | G25: =-G14+G15-G24 -> 14.668989 | H25: =-H14+H15-H24 -> 15.651811 | I25: =-I14+I15-I24 -> 6.7004825 | J25: =-J14+J15-J24 -> 17.149415 | K25: =-K14+K15-K24 -> 18.298426 | L25: =SUM(B25:K25) -> 7.8271655
A26: 净资产 | B26: =B19+B20+B23 -> 2.5 | C26: =C19+C20+C23 -> 4.8940993 | D26: =D19+D20+D23 -> 4.8583084 | E26: =E19+E20+E23 -> 4.883191 | F26: =F19+F20+F23 -> 4.9767095 | G26: =G19+G20+G23 -> 5.1476006 | H26: =H19+H20+H23 -> 5.4054422 | I26: =I19+I20+I23 -> 6.7607252 | ... K26: =K19+K20+K23 -> 7.8271637 | L26: =K26 -> 7.8271637
A28: 利润表：
A29: 项目 | B29: 1 | C29: 2 | D29: 3 | E29: 4 | F29: 5 | G29: 6 | H29: 7 | I29: 8 | J29: 9 | K29: 10 | L29: 合计
A30: 营业收入 | B30: =B16+B17+B18 -> 52.5 | C30: =C16+C17+C18 -> 52.5 | D30: =D16+D17+D18 -> 1.2 | E30: =E16+E17+E18 -> 1.2 | F30: =F16+F17+F18 -> 1.2 | G30: =G16+G17+G18 -> 1.2 | H30: =H16+H17+H18 -> 1.2 | I30: =I16+I17+I18 -> 12.2 | ... K30: =K16+K17+K18 -> 1.2 | L30: =SUM(B30:K30) -> 125.6
A31: 营业成本 | B31: =B14 -> 50 | C31: =C14 -> 50 | D31: =D14 -> 1 | E31: =E14 -> 1 | F31: =F14 -> 1 | G31: =G14 -> 1 | H31: =H14 -> 1 | I31: =I14 -> 11 | ... K31: =K14 -> 1 | L31: =SUM(B31:K31) -> 118
A32: 利息收入 | C32: =C21 -> 3.2440993 | D32: =D21 -> 6.6886592 | E32: =E21 -> 5.9402707 | F32: =F21 -> 5.1456376 | G32: =G21 -> 4.3019022 | H32: =H21 -> 3.4060305 | I32: =I21 -> 2.4548006 | J32: =J21 -> 2.1245081 | K32: =K21 -> 1.09409 | L32: =SUM(B32:K32) -> 34.399998
A33: 借款费用 | C33: =C24 -> 3.35 | D33: =D24 -> 6.92445 | E33: =E24 -> 6.1153882 | F33: =F24 -> 5.2521192 | G33: =G24 -> 4.3310111 | H33: =H24 -> 3.3481889 | I33: =I24 -> 2.2995175 | J33: =J24 -> 1.8505852 | K33: =K24 -> 0.70157443 | L33: =SUM(B33:K33) -> 34.172835
A34: 净利润 | B34: =B30-B31+B32-B33 -> 2.5 | C34: =C30-C31+C32-C33 -> 2.3940993 | D34: =D30-D31+D32-D33 -> -0.035790845 | E34: =E30-E31+E32-E33 -> 0.024882582 | F34: =F30-F31+F32-F33 -> 0.09351846 | G34: =G30-G31+G32-G33 -> 0.1708911 | H34: =H30-H31+H32-H33 -> 0.25784157 | I34: =I30-I31+I32-I33 -> 1.3552831 | ... K34: =K30-K31+K32-K33 -> 0.59251556 | L34: =SUM(B34:K34) -> 7.8271637
