Workbook

Sheet 五步法分析（Ⅰ）D4-
A1: 致同会计师事务所
A2: 五步法分析（一）识别与客户订立的合同
A3: =[4]底稿目录!$A$2 -> 被审计单位： | D3: =[4]底稿目录!$A$4 -> 编制人： | F3: =[4]底稿目录!$A$5 -> 编制日期： | H3: 索引号： | I3: D4-
A4: =[4]底稿目录!$A$3 -> 会计期间：202X年度 | D4: =[4]底稿目录!$A$6 -> 复核人： | F4: =[4]底稿目录!$A$7 -> 复核日期： | H4: 页次：
A5: 一、审计目标：
A6: 评价合同是否成立，合同合并的处理是否正确（若适用），合同变更的会计处理是否正确（若涉及）。
A7: 二、审计过程：
A8: 1.合同成立的条件
A9: 合同成立的条件（需同时满足） | C9: 说明 | E9: 注意事项 | G9: 审计证据及合同分析 | I9: 索引
A10: （1）合同各方已批准该合同并承诺将履行各自义务 | E10: 交易是否经过了合同各方的内部审批流程，是否合法有效
A11: （2）该合同明确了合同各方与所转让商品或提供劳务相关的权利和义务 | C11: 合同约定的权利和义务是否具有法律约束力 | E11: 各方的权利是否与一般商业惯例一致
A12: （3）该合同有明确的与所转让商品或提供劳务相关的支付条款 | E12: 支付条款是否与一般商业惯例及合同各方实务惯例一致
A13: （4）该合同具有商业实质 | C13: 即履行该合同将改变企业未来现金流量的风险、时间分布或金额 | E13: 没有商业实质的非货币性资产交换，不确认收入 | J13: 关于商业实质，应按照《企业会计准则第7 号——非货币性资产交换》的有关规定进行判断。
A14: （5）企业因向客户转让商品或提供劳务而有权取得的对价很可能收回 | C14: 考虑客户支付对价金额的财务能力和支付对价的意图 | E14: 信用风险不影响收入金额的计量 | J14: 在后续期间，客户的信用风险显著升高，企业需要评估其在未来向客户转让剩余商品而有权取得的对价是否很可能收回，如果不能满足很可能收回的条件，则该合同自此开始不再满足合同成立的相关条件，应当停止确认收入（但是，不应调整此前已经确认的收入）。
A15: 结 论
A16: 注：在合同开始日（通常是指合同生效日）进行评估。有迹象表明相关事实和情况发生重大变化的（如客户的信用风险显著升高），重新进行评估。
A18: 2.合同不成立（不能同时满足合同成立的5项条件） | E18: 是否适用 | F18: 是
A19: 项目 | D19: 说明 | F19: 分析 | G19: 审计证据 | I19: 索引
A20: （1.1）是否不再负有向客户转让商品的剩余义务？ | D20: 例如，合同已完成或取消 | F20: 是 | G20: 撤销协议
A21: （1.2）己向客户收取的对价无需退回？ | D21: 包括全部或部分对价 | F21: 否 | G21: 撤销协议、往来询证函
A22: （2）合同已终止且客户支付的对价无需退回？ | D22: 当主体停止向客户转让已承诺的商品或服务时，合同即被终止 | F22: 否 | G22: 终止协议、往来询证函
A23: 结 论 | C23: =IF(OR(F22="是",AND(F20="是",F21="是")),"将已收取的对价确认为收入","应当将已收取的对价作为负债进行会计处理（该负债代表了企业在未来向客户转让商品或者支付退款的义务）") -> 应当将已收取的对价作为负债进行会计处理（该负债代表了企业在未来向客户转让商品或者支付退款的义务） | J23: 企业向客户收取无需退回的对价的，应当在已经将该部分对价所对应的商品的控制权转移给客户，并且已经停止向客户转让额外的商品，也不再负有此类义务时；或者，相关合同已经终止时，将该部分对价确认为收入。
A25: 3.合同的合并 | E25: 是否适用 | F25: 否
A26: 条件 | D26: 说明 | F26: 注意事项 | G26: 合同分析 | I26: 索引
A27: 与同一客户（或该客户的关联方）同时订立或在相近时间内先后订立的两份或多份合同 | D27: 这些安排是同时或者在考虑了彼此影响的情况下订立的 | F27: 在对合同的一部分进行会计处理时，会优先采用更为具体的准则
A28: 满足条件之一时 | B28: （1）该两份或多份合同基于同一商业目的而订立并构成一揽子交易 | D28: 这些安排整体才能达成一项完整的商业结果
B29: （2）该两份或多份合同中的一份合同的对价金额取决于其他合同的定价或履行情况 | D29: 一项安排的发生或定价取决于其他至少一项安排的发生或定价
B30: （3）该两份或多份合同中所承诺的商品或服务（或每份合同中所承诺的部分商品或服务）构成单项履约义务 | D30: 履约义务，是指合同中企业向客户转让可明确区分商品的承诺 | F30: 本身能够明确区分及在基于相关合同进行考虑时可明确区分
A31: 结 论
A33: 4.合同变更（经合同各方批准对原合同范围或价格作出的变更）
A34: 项目 | C34: 说明 | F34: 分析 | G34: 审计证据 | I34: 索引
A35: （1.1）合同变更增加了可明确区分的商品及合同价款？ | C35: 可明确区分：客户能够从该商品本身或从该商品与其他易于获得资源一起使用中受益；与合同中其他承诺可单独区分 | F35: 是 | G35: 补充协议/合同变更单
A36: （1.2）新增合同价款反映了新增商品单独售价？ | C36: 应当考虑为反映该特定合同的具体情况而对新增商品价格所做的适当调整 | F36: 否 | G36: 补充协议/合同变更单
A37: （2）在合同变更日已转让的商品或已提供的服务与未转让的商品或未提供的服务之间可明确区分？ | C37: 未转让的商品既包括原合同中尚未转让的商品，也包括合同变更新增的商品 | F37: 是
A38: 结 论 | C38: =IF(AND(F35="是",F36="是"),"将该合同变更部分作为一份单独的合同进行会计处理，合同变更不影响原合同的会计处理",IF(F37="是","视为原合同终止，同时，将原合同未履约部分与合同变更部分合并为新合同进行会计处理","将该合同变更部分作为原合同的组成部分，在合同变更日重新计算履约进度，并调整当期收入和相应成本等")) -> 视为原合同终止，同时，将原合同未履约部分与合同变更部分合并为新合同进行会计处理
A39: 注：合同各方巳批准合同范围变更，但尚未确定相应价格变动的，企业应当按照收入准则有关可变对价的规定对合同变更所导致的交易价格变动进行估计。
A41: 三、审计说明：
A44: 四、审计结论：
A46: 提示：当企业与客户之间的合同同时满足合同成立的五项条件时，企业应当在客户取得相关商品控制权时确认收入。

Sheet 五步法分析（Ⅱ）D4-
A1: 致同会计师事务所
A2: 五步法分析（二）识别合同中的单项履约义务
A3: =[4]底稿目录!$A$2 -> 被审计单位： | D3: =[4]底稿目录!$A$4 -> 编制人： | F3: =[4]底稿目录!$A$5 -> 编制日期： | H3: 索引号： | I3: D4-
A4: =[4]底稿目录!$A$3 -> 会计期间：202X年度 | D4: =[4]底稿目录!$A$6 -> 复核人： | F4: =[4]底稿目录!$A$7 -> 复核日期： | H4: 页次：
A5: 一、审计目标：
A6: 合同中的单项履约义务是否正确识别。
A7: 二、审计过程：
A8: 1.可明确区分的商品或服务
A9: 条件（需同时满足） | B9: 说明 | E9: 注意事项 | G9: 审计证据及合同分析 | I9: 索引
A10: （1）客户能够从该商品或服务本身或从该商品或服务与其他易于获得资源一起使用中受益 | B10: 当客户能够使用、消耗或以高于残值的价格出售商品，或者以能够产生经济利益的其他方式持有商品时，表明客户能够从该商品本身获益。 主体经常单独出售某项商品或服务这一事实可能表明客户能够从单独使用该商品或服务、或将其与易于获得的其他资源一起使用中获益 | E10: 易于获得的资源是指（由主体或另一主体）单独出售的商品或服务、或是客户已从主体取得的（包括主体根据该合同已向客户转让的商品或服务）或来自其他交易或事项的资源。 | J10: 在评估某项商品是否能够明确区分时，应当基于该商品自身的特征，而与客户可能使用该商品的方式无关。因此，企业无需考虑合同中可能存在的阻止客户从其他来源取得相关资源的限制性条款。
A11: （2）企业向客户转让该商品或服务的承诺与合同中其他承诺可单独区分 | B11: 即，在基于相关合同进行考虑时该商品或服务可明确区分（distinct）。 在基于合同进行考虑时商品或服务可明确区分表明其具备“单独风险”的特征 | E11: 旨在基于合同考虑时，确定该承诺的性质是单独转让每一项商品或服务、还是转让以已承诺商品或服务作为投入要素而形成的一个或多个组合项目。 | G11: 表明不可单独区分的情形如下所示
A12: 表明不可单独区分的情形
A13: ①企业需提供重大的服务以将该商品或服务与合同中承诺的其他商品或服务整合成合同约定的组合产出转让给客户 | B13: 主体以这些商品或服务作为投入要素，生产或交付客户所要求的一项或多项组合产出。一项或多项组合产出可包括不止一个阶段、要素或单元。 | E13: 主体转让商品或服务的承诺将产生一个组合项目，而该组合项目大于（或在实质上不同于）已承诺的单个商品或服务加总后的结果。 主体应当评价在履行合同过程中两个项目之间是否存在转化关系（transformative relationship），而不是考虑某个项目从其本身性质来看是否依赖另一项目（即，两个项目之间是否存在功能关系）
A14: ②该商品或服务将对合同中承诺的其他商品或服务予以重大修改或定制 | B14: 对其他商品或服务作出重大修改或定制，或因其他商品或服务而作出重大修改或定制。
A15: ③该商品或服务与合同中承诺的其他商品或服务具有高度关联性 | B15: 每一项商品或服务均在很大程度上受合同中其他一项或多项商品或服务的影响，从而导致客户无法在不对合同承诺的其他商品或服务造成重大影响的情况下选择购买其中某一项商品或服务。
A16: 结 论
A17: 注：在合同开始日进行评估。如果在合同订立时，客户根据隐含的承诺（如企业已公开宣布的政策、特定声明或以往的习惯做法等）能够
A18: 对企业将向其转让某项商品形成合理的预期，则在识别单项履约义务时，应当考虑此类隐含的承诺（如免费保养/维修服务、免费升级服务等）。
A20: 2.运输服务是否构成单项履约义务 | E20: 是否适用 | F20: 是
A21: 情形 | D21: 说明 | F21: 分析 | G21: 审计证据 | I21: 索引 | J21: 参考《收入准则应用案例——运输服务》
A22: 销售产品属于在某一时点履行的履约义务，且控制权在出库时转移给客户 | F22: 否 | J22: 控制权转移给客户之后发生的运输活动则可能表明企业向客户提供了一项运输服务，企业应当考虑该项服务是否构成单项履约义务。
A23: 销售产品属于在某一时点履行的履约义务，且控制权在送达客户指定地点时转移给客户 | F23: =IF(F22="是","否","是") -> 是 | J23: 通常情况下，控制权转移给客户之前发生的运输活动不构成单项履约义务，而只是企业为了履行合同而从事的活动，相关成本应当作为合同履约成本
A24: 结 论 | C24: =IF(AND(F22="是",F23="否"),"如果该运输服务构成单项履约义务，且公司是运输服务的主要责任人。公司应当按照分摊至该运输服务的交易价格确认收入","运输活动是在产品的控制权转移给客户之前发生的，不构成单项履约义务，而是公司为履行合同发生的必要活动，相关成本应作为合同履约成本") -> 运输活动是在产品的控制权转移给客户之前发生的，不构成单项履约义务，而是公司为履行合同发生的必要活动，相关成本应作为合同履约成本
A25: 注：根据收入准则规定确认为资产的合同履约成本，初始确认时摊销期限不超过一年或一个正常营业周期的，在资产负债表中计入“存货”项目；
A26: 初始确认时摊销期限在一年或一个正常营业周期以上的，在资产负债表中计入“其他非流动资产”项目。
A28: 3.一系列实质相同且转让模式相同的商品或服务 | E28: 是否适用 | F28: 否
A29: 条件（需同时满足） | B29: 说明 | D29: 注意事项 | G29: 审计证据及合同分析 | I29: 索引
A30: （1）每项承诺实质上是相同的 | B30: 如果承诺的性质是提供特定数量的服务，评估时应当考虑每项服务是否可明确区分且实质上相同。 如果企业承诺的性质是准备好或在一段时间内提供单一服务，评估时应当考虑每个时间增量而非潜在的活动是否可明确区分且实质上相同。 | D30: 例如，企业与客户签订2年的合同，每月向客户提供工资核算服务，共计24次，由于企业提供服务的次数是确定的，在判断每月的服务是否实质相同时，应当考虑每次提供的具体服务是否相同。 例如，企业向客户提供2年的酒店管理服务，具体包括保洁、维修、安保等，但没有具体的服务次数或时间的要求，尽管企业每天提供的具体服务不一定相同，但是企业每天对于客户的承诺都是相同的，即按照约定的酒店管理标准，随时准备根据需要为其提供相关服务。
A31: （2）每项承诺转让模式相同 | B31: 例如重复性服务合同（保洁合同、交易处理或供电合同） | D31: 是指每一项可明确区分商品均满足收入准则第十一条规定的、在某一时段内履行履约义务的条件，且采用相同方法确定其履约进度
A32: （3）每项承诺均满足在某一时段内履行履约义务的条件 | D32: 适用于连续提供（而非同时提供） 的商品或服务
A33: （4）采用相同方法确定每项承诺的履约进度
A34: 结 论
A35: 注：企业向客户转让一系列实质相同且转让模式相同的、可明确区分商品的承诺，应当作为单项履约义务。
A37: 三、审计说明：
A39: 四、审计结论：
A41: 提示：
A42: 履约义务，是指合同中企业向客户转让可明确区分商品的承诺。履约义务既包括合同中明确的承诺，也包括由于企业已公开宣布的政策、
A43: 特定声明或以往的习惯做法等导致合同订立时客户合理预期企业将履行的承诺。
A44: 企业为履行合同而应开展的初始活动，通常不构成履约义务，除非该活动向客户转让了承诺的商品。

Sheet 五步法分析（Ⅲ）D4-
A1: 致同会计师事务所
A2: 五步法分析（三）确定交易价格
A3: =[4]底稿目录!$A$2 -> 被审计单位： | D3: =[4]底稿目录!$A$4 -> 编制人： | F3: =[4]底稿目录!$A$5 -> 编制日期： | H3: 索引号： | I3: D4-
A4: =[4]底稿目录!$A$3 -> 会计期间：202X年度 | D4: =[4]底稿目录!$A$6 -> 复核人： | F4: =[4]底稿目录!$A$7 -> 复核日期： | H4: 页次：
A5: 一、审计目标：
A6: 确定交易价格——企业因向客户转让商品而预期有权收取的对价金额，是否正确。
A7: 二、审计过程：
A8: 1.1 可变对价
A9: 项目 | B9: 说明 | E9: 注意事项 | G9: 审计证据及合同分析 | I9: 索引
A10: （1）合同所承诺的对价包括可变金额 | B10: 对价金额可能因折扣、回扣、退款、抵免、价格折让、激励措施、业绩奖金、罚款、索赔或其他类似项目而改变 | E10: 企业有权收取的对价金额，将根据一项或多项或有事项的发生有所不同的情况，也属于可变对价的情形，如产品销售附带退货权
A11: （2）根据企业已公开宣布的政策、特定声明或者以往的习惯做法等，客户能够合理预期企业将会接受低于合同约定的对价金额 | B11: 即企业会以折扣、返利等形式提供价格折让
A12: （3）其他相关事实和情况表明，企业在与客户签订合同时即打算向客户提供价格折让 | B12: 例如，企业与一新客户签订合同，虽然企业没有对该客户销售给予折扣的历史经验，但是，根据企业拓展客户关系的战略安排，企业愿意接受低于合同约定的价格
A13: 可变对价最佳估计数的确定
A14: （1）期望值（一系列可能发生的对价金额的概率加权金额的总和） | B14: 如果企业拥有大量具有类似特征的合同，企业据此估计合同可能产生多个结果时，按照期望值估计可变对价金额通常是恰当的。 | E14: 并非一项“自由选择”，具体取决于主体预计哪一种方法能更好地预测其有权获得的对价金额。 通常情况下，企业在估计可变对价金额时使用的信息，应当与其在对相关商品进行投标或定价时所使用的信息一致。
A15: （2）最可能发生金额（一系列可能发生的对价金额中最可能发生的单一金额，即合同最可能产生的单一结果） | B15: 当合同仅有两个可能结果(例如，企业能够达到或不能达到某业绩奖金目标)时，按照最可能发生金额估计可变对价金额可能是恰当的。
A16: 可变对价估计的限制
A17: 包含可变对价的交易价格，应当不超过在相关不确定性消除时累计已确认收入极可能不会发生重大转回的金额 | B17: 应当同时考虑收入转回的可能性及转回金额的比重。 应当评估可能发生的收入转回金额相对于合同总对价（包括固定对价和可变对价）而言的比重 | E17: “极可能”是一个比较高的门槛，其发生的概率应远高于“很可能（即，可能性超过50%）”，但不要求达到“基本确定（即，可能性超过95%）” | G17: 详见下述1.2 | J17: 将可变对价计入交易价格的限制条件不适用于企业向客户授予知识产权许可并约定按客户实际销售或使用情况收取特许权使用费的情况。
A18: 结 论
A21: 1.2 导致收入转回的可能性增强或转回金额比重增加的因素
A22: 情形 | D22: 说明 | F22: 分析 | G22: 审计证据 | I22: 索引
A23: （1）对价金额极易受到企业影响范围之外的因素影响 | D23: 例如市场波动性、第三方的判断或行动、天气状况、已承诺商品存在较高的陈旧过时风险等 | F23: 否
A24: （2）对价金额的不确定性预计在较长时期内无法消除 | F24: 否
A25: （3）企业对类似合同的经验（或其他证据）有限，或者相关经验（或其他证据）的预测价值有限 | F25: 否
A26: （4）企业在以往实务中对于类似情况下的类似合同，或曾提供了多种不同程度的价格折扣，或曾给予不同的付款条件 | F26: 否
A27: （5）合同有多种可能的对价金额，且这些对价金额分布非常广泛 | F27: 否
A28: 结 论 | C28: =IF(AND(F23="否",F24="否",F25="否",F26="否",F27="否"),"累计己确认的收入金额极可能不会发生重大转回","不满足累计己确认的收入金额极可能不会发生重大转回的要求") -> 累计己确认的收入金额极可能不会发生重大转回
A29: 注：每一资产负债表日，企业应当重新估计可变对价金额（包括重新评估对可变对价的估计是否受到限制），以如实反映报告期末存在的情况
A30: 以及报告期内发生的情况变化。
A32: 2.1 重大融资成分
A33: 项目 | B33: 说明 | E33: 注意事项 | G33: 审计证据及合同分析 | I33: 索引
A34: 各方以在合同中明确（或者以隐含的方式）约定的付款时间为客户或企业就转让商品的交易提供了重大融资利益 | B34: 在确定交易价格时，应当对己承诺的对价金额作出调整，以剔除货币时间价值的影响。 | E34: 应当按照假定客户在取得商品控制权时即以现金支付的应付金额（即，现销价格）确定交易价格
A35: （1）已承诺的对价金额与已承诺商品的现销价格之间的差额 | B35: 如果企业（或其他企业）在销售相同商品时，不同的付款时间会导致销售价格有所差别，则通常表明各方知晓合同中包含了融资成分
A36: （2）企业将承诺的商品转让给客户与客户支付相关款项之间的预计时间间隔和相应的市场现行利率的共同影响 | B36: 尽管向客户转让商品与客户支付相关款项之间的时间间隔并非决定性因素，但是，该时间间隔与现行利率两者的共同影响可能提供了是否存在重大融资利益的明显迹象 | E36: 如果在合同开始日，企业预计客户取得商品控制权与客户支付价款间隔不超过一年的，可以不考虑合同中存在的重大融资成分 | J36: 企业应当对类似情形下的类似合同一致地应用一简化处理方法
A37: 表明不包含重大融资成分的因素（任一）
A38: （1）客户就商品支付了预付款，且可以自行决定这些商品的转让时间 | B38: 例如，企业向客户出售其发行的储值卡，客户可随时到该企业持卡购物；再如，企业向客户授予奖励积分，客户可随时到该企业兑换这些积分等
A39: （2）客户承诺支付的对价中有相当大的部分是可变的，该对价金额或付款时间取决于某一未来事项是否发生，且该事项实质上不受客户或企业控制 | B39: 例如，按照实际销售量收取的特许权使用费 | E39: 此类付款条款的主要目的可能是就商品或服务的价值向各方提供保证，而非为客户提供重大融资。
A40: （3）合同承诺的对价金额与现销价格之间的差额是由于向客户或企业提供融资利益以外的其他原因所导致的，且这一差额与产生该差额的原因是相称的 | B40: 例如，合同约定的支付条款是为了向企业或客户提供保护，以防止另一方未能依照合同充分履行其部分或全部义务 | E40: 此类付款条款的主要目的可能是就主体将依照合同圆满完成其履约义务向客户提供保证，而非向客户或主体提供融资。
A41: 结 论
A43: 2.2 重大融资成分的折现率 | E43: 是否适用 | F43: 是
A44: 情形 | D44: 说明 | F44: 折现率 | G44: 现销价格 | H44: 合同名义金额 | I44: 时间差（年）
...

Sheet 五步法分析（Ⅳ）D4-
A1: 致同会计师事务所
A2: 五步法分析（四）将交易价格分摊至各单项履约义务
A3: =[4]底稿目录!$A$2 -> 被审计单位： | D3: =[4]底稿目录!$A$4 -> 编制人： | F3: =[4]底稿目录!$A$5 -> 编制日期： | H3: 索引号： | I3: D4-
A4: =[4]底稿目录!$A$3 -> 会计期间：202X年度 | D4: =[4]底稿目录!$A$6 -> 复核人： | F4: =[4]底稿目录!$A$7 -> 复核日期： | H4: 页次：
A5: 一、审计目标：
A6: 确定交易价格分摊是否正确。
A7: 二、审计过程：
A8: 当合同中包含两项或多项履约义务时，需要将交易价格分摊至各单项履约义务。
A9: 1.1 单独售价
A10: 项目 | B10: 说明 | E10: 注意事项 | G10: 审计证据及合同分析 | I10: 索引
A11: 单独销售商品的价格 | B11: 企业在类似环境下向类似客户单独销售某商品的价格，应作为确定该商品单独售价的最佳证据 | E11: 合同或价目表上的标价可能是商品的单独售价，但不能默认其一定是该商品的单独售价 | J11: 例如，企业为其销售的产品制定了标准价格，但是，在实务中经常以低于该标准价格的折扣价格对外销售，此时，企业在估计该产品的单独售价时，应当考虑这一因素。
A12: 单独售价无法直接观察时（应当最大限度地采用可观察的输入值，并对类似的情况采用一致的估计方法）
A13: 市场调整法 | B13: 根据某商品或类似商品的市场售价，考虑本企业的成本和毛利等进行适当调整后的金额，确定其单独售价的方法
A14: 成本加成法 | B14: 根据某商品的预计成本加上其合理毛利后的金额，确定其单独售价的方法 | E14: 预计成本应当与企业在定价时通常会考虑的成本因素一致，既包括直接成本，也包括间接成本
A15: 余值法 | B15: 根据合同交易价格减去合同中其他商品可观察单独售价后的余额，确定某商品单独售价的方法 | E15: 在商品近期售价波动幅度巨大，或者因未定价且未曾单独销售而使售价无法可靠确定时，可采用余值法估计其单独售价 | J15: 其中，售价波动幅度巨大，是指企业在相同或相近的时间向不同客户出售同一种商品时的价格差异很大，因而导致企业无法从以往的交易或其他可观察的证据中识别出具有代表性的单独售价；未定价且未曾单独销售，是指企业尚未对该商品进行定价，且该商品过往未曾单独出售过，即销售价格尚未确定。
A16: 结 论（选择适用的方法）
A18: 1.2 市场调整法
A19: 履约义务 | D19: 类似商品 | E19: 类似商品市场售价 | F19: 价格调整 | G19: 价格调整说明 | H19: 单独售价 | I19: 索引
A20: 产品A | E20: 55.555556 | F20: -0.1 | G20: 低价策略 | H20: =E20*(1+F20) -> 50
A21: 产品B | H21: =E21*(1+F21) -> 0
A22: 服务 | H22: =E22*(1+F22) -> 0
A23: 产品C | H23: =E23*(1+F23) -> 0
H24: =E24*(1+F24) -> 0
A25: 合计 | E25: =SUM(E20:E24) -> 55.555556 | H25: =SUM(H20:H24) -> 50
A26: 注：企业可以对其销售商品的市场进行评估，进而估计客户在该市场上购买本企业的商品所愿意支付的价格，也可以参考其竞争对于销售类似商品
A27: 的价格，并在此基础上进行必要调整以反映本企业的成本及毛利。
A28: 1.3 成本加成法
A29: 履约义务 | E29: 预计成本 | F29: 预期毛利率 | G29: 类似商品毛利率 | H29: 单独售价 | I29: 索引
A30: 产品A | H30: =E30*(1+F30) -> 0
A31: 产品B | E31: 20 | F31: 0.25 | G31: 0.3 | H31: =E31*(1+F31) -> 25
A32: 服务 | H32: =E32*(1+F32) -> 0
A33: 产品C | H33: =E33*(1+F33) -> 0
H34: =E34*(1+F34) -> 0
A35: 合计 | E35: =SUM(E30:E34) -> 20 | H35: =SUM(H30:H34) -> 25
A36: 注：应当考虑的因素包括类似商品单独售价的毛利水平、行业内的历史毛利水平、行业平均售价、市场情况以及企业的利润目标等
A37: 1.4 余值法
A38: 履约义务 | E38: 合同总对价 | F38: 其他商品单独售价 | G38: 余值 | H38: 单独售价 | I38: 索引
A39: 产品A | F39: =H20 -> 50 | H39: =F39 -> 50
A40: 产品B | F40: =H31 -> 25 | H40: =F40 -> 25
A41: 服务 | F41: 75 | H41: =F41 -> 75
...

Sheet 五步法分析（Ⅴ）D4-
A1: 致同会计师事务所
A2: 五步法分析（五）在履行履约义务时确认收入
A3: =[4]底稿目录!$A$2 -> 被审计单位： | D3: =[4]底稿目录!$A$4 -> 编制人： | F3: =[4]底稿目录!$A$5 -> 编制日期： | H3: 索引号： | I3: D4-
A4: =[4]底稿目录!$A$3 -> 会计期间：202X年度 | D4: =[4]底稿目录!$A$6 -> 复核人： | F4: =[4]底稿目录!$A$7 -> 复核日期： | H4: 页次：
A5: 一、审计目标：
A6: 确定在履行了合同中的履约义务，即在客户取得相关商品控制权时确认收入。
A7: 二、审计过程：
A8: 确定各单项履约义务是在某一时段内履行，还是在某一时点履行；然后，确定时在履行了各单项履约义务时分别确认收入。
A9: 1.1 在某一时段内履行履约义务【XX业务】
A10: 条件（满足任一） | C10: 说明 | F10: 分析 | G10: 审计证据 | I10: 索引
A11: （1）客户在企业履约的同时即取得并消耗企业履约所带来的经济利益； | C11: 常规或经常性服务，如保洁服务、运输、健身俱乐部； 他人在向客户履行剩余的履约义务时无需在实质上重新执行迄今为止已完成的工作 | F11: 否 | J11: 对于难以通过直观判断获知结论的情形，企业在进行判断时，可以假定在企业履约的过程中更换为其他企业继续履行剩余履约义务，当该继续履行合同的企业实质上无需重新执行企业累计至今已经完成的工作时，表明客户在企业履约的同时即取得并消耗了企业履约所带来的经济利益。 参考《收入准则应用案例——药品实验服务的收入确认》
A12: （2）客户能够控制企业履约过程中在建的商品； | C12: 应当应用准则中关于控制的要求（包括控制转移的迹象等）。 此种情况下，客户能够主导所有在产品的使用，并从中获得几乎全部的经济利益 | F12: 是 | G12: 客户能够合理利用开发过程中形成的在产品（例如建造服务、设计图、程序、文档等），并从中获得几乎全部的经济利益——主导使用并获得几乎全部经济利益的历史记录 | J12: 取得相关商品控制权，是指能够主导该商品的使用并从中获得几乎全部的经济利益。 参考《收入准则应用案例——定制软件开发服务的收入确认》
A13: （3）企业履约过程中所产出的商品具有不可替代用途，且该企业在整个合同期间内有权就累计至今已完成的履约部分收取款项。 | C13: 具有不可替代用途，是指因合同限制或实际可行性限制，企业不能轻易地将商品用于其他用途。 有权就累计至今已完成的履约部分收取款项，是指在由于客户或其他方原因终止合同的情况下，企业有权就累计至今已完成的履约部分收取能够补偿其已发生成本和合理利润的款项，并且该权利具有法律约束力。 | F13: 否 | J13: 仅按照合同里程碑支付的进度款，即使不必返还，也并不满足该条件。 企业有权收取的款项为保证金或仅是补偿企业已经发生的成本或可能损失的利润的不满足这一条件。 在进行判断时，既要考虑合同条款的约定，还应当充分考虑适用的法律法规、补充或者凌驾于合同条款之上的以往司法实践以及类似案例的结果等。例如，在以往的类似合同中，企业虽然拥有此类权利，却在考虑了各种因素之后没有行使该权利，这是否会导致企业主张该权利的要求在当前的法律环境下不被支持等。 参考《收入准则应用案例——定制软件开发服务的收入确认》
A14: 同行业可比公司的判断
A15: 结 论 | C15: =IF(OR(F11="是",F12="是",F13="是"),"属于在某一时段内履行履约义务","属于在某一时点履行履约义务") -> 属于在某一时段内履行履约义务
A16: 注意：准则并未对诸如期限较短（如短于一年）的合同等提供允许直接默认在某一时点确认收入的简便方法。
A17: 1.2 确定履约进度 | E17: 是否适用 | F17: 是
A18: 方法 | D18: 说明 | F18: 同行业可比公司采用的方法 | I18: 索引
A19: 产出法：以已转让的商品或服务的价值相对于剩余商品或服务对于客户的价值的直接计量结果为基础 | D19: •测量迄今为止已完成的履约情况 •评估已实现的结果 •已达到的里程碑 •流逝的时间 •已生产或已交付的单位 | J19: 如果所选择的产出无法计量某些控制权已转移给客户的商品或服务，则产出法不能提供对主体履约情况的如实反映。例如，如果在报告期末受客户控制的主体履约形成的在产品或产成品未包括在产出的计量中，则基于已生产单位或已交付单位的产出法无法如实反映主体对履约义务的履行。
A20: 投入法：以企业履行履约义务所作的工作或投入相对于履行履约义务的预计总投入为基础 | D20: •消耗的资源 •花费的工时数 •发生的成本 •流逝的时间 •使用的机器运转时数 | J20: 如果主体的工作或投入在履约期间内平均消耗，则主体按直线法确认收入可能是恰当的。
A21: 被审计单位采用的方法 | J21: 当履约进度不能合理确定时，企业已经发生的成本预计能够得到补偿的，应当按照已经发生的成本金额确认收入，直到履约进度能够合理确定为止。
A23: 1.2.1 确定履约进度（产出法） | E23: 是否适用 | F23: 是
A24: 组成部分 | D24: 履约进度 | E24: 使用产出法分摊的收入 | F24: 实际成本 | G24: 毛利率 | H24: 按履约进度计算的成本 | I24: 索引 | J24: 应当考虑商品的性质，采用产出法或投入法确定恰当的履约进度，并且在确定履约进度时，应当扣除那些控制权尚未转移给客户的商品和服务。
A25: 地基 | D25: 0.42 | E25: 2100000 | F25: 2000000 | G25: =(E25-F25)/E25 -> 0.047619048 | H25: 1680000
A26: 墙体 | D26: 0.24 | E26: 1200000 | F26: 1000000 | G26: =(E26-F26)/E26 -> 0.16666667 | H26: 960000
A27: 门窗 | D27: 0.16 | E27: 800000 | F27: 500000 | G27: =(E27-F27)/E27 -> 0.375 | H27: 640000
A28: 屋顶 | D28: 0.18 | E28: 900000 | F28: 500000 | G28: =(E28-F28)/E28 -> 0.44444444 | H28: 720000
A30: 合计 | D30: =SUM(D25:D29) -> 1 | E30: =SUM(E25:E29) -> 5000000 | F30: =SUM(F25:F29) -> 4000000 | G30: =(E30-F30)/E30 -> 0.2 | H30: =SUM(H25:H29) -> 4000000
A31: 产出法下的履约成本 | D31: 地基部分的建设工作已经完成，该部分实际发生的成本是与履约义务中已经履行的部分（即建设地基）相关的支出，即该支出与企业过去的履约活动相关，根据《企业会计准则第14号——收入》（2017年修订）第二十七条的相关规定，应将其在发生时计入当期损益。 因此，截至202X年12月31日，地基部分实际发生的成本200万元应当计入当期损益。 | J31: 参考《上市公司执行企业会计准则案例解析》（2020）案例6-06 釆用产出法确定履约进度时，应当如何确认履约成本
A32: 注：如果在达到合同约定的里程碑时才确认收入，且在各个里程碑之间产生了重大的未向客户转移的合同履约成本，这与该合同下公司的履约义务
A33: 满足在某一时段内确认收入的条件，即公司将其在履约过程中形成的产出的控制权持续转移给客户的结论是相悖的。
A34: 1.2.2 确定履约进度（投入法） | E34: 是否适用 | F34: 否
A35: 期间 | B35: 期初累计实际发生成本 | D35: 本期合同履约成本 | E35: 期末累计实际发生成本 | F35: 索引[实际发生合同成本检查] | G35: 期末预计完成合同尚需发生成本 | H35: 索引[定额成本/投标报价/目标成本/同类工程平均毛利率] | I35: 履约进度 | J35: 应当考虑商品的性质，采用产出法或投入法确定恰当的履约进度，并且在确定履约进度时，应当扣除那些控制权尚未转移给客户的商品和服务。
A36: 2018年度 | B36: 0 | D36: 154 | E36: =B36+D36 -> 154 | G36: 396 | I36: =E36/(E36+G36) -> 0.28
A37: 2019年度 | B37: =E36 -> 154 | D37: 146 | E37: =B37+D37 -> 300 | G37: 300 | I37: =E37/(E37+G37) -> 0.5
A38: 2020年度 | B38: =E37 -> 300 | D38: 188 | E38: =B38+D38 -> 488 | G38: 122 | I38: =E38/(E38+G38) -> 0.8
A39: 2021年度 | B39: =E38 -> 488 | D39: 122 | E39: =B39+D39 -> 610 | G39: 0 | I39: =E39/(E39+G39) -> 1
A41: 注：在采用投入法确定履约进度时，应当扣除那些虽然已经发生、但是未导致向客户转移商品的投入。 | J41: 参考《收入准则应用案例——亏损合同案例》
A42: 投入法的调整（如适用） | B42: 期末累计实际发生成本 | D42: 尚未安装、使用或耗用的商品或材料成本 | E42: 调整后的履约进度 | F42: 合同总金额 | G42: 应确认总收入 | H42: 应确认总成本 | I42: 合同预计损失（主营业务成本） | J42: 在运用以成本为基础的投入法时，在下列情况下可能需要对履约进度的计量作出调整： （1）已发生的成本并未反映企业履行履约义务的进度。例如，因企业生产效率低下等原因而导致的非正常消耗，包括非正常消耗的直接材料、直接人工及制造费用等，不应包括在累计实际发生的成本中。 （2）已发生的成本与企业履行履约义务的进度不成比例，通常仅以其已发生的成本为限确认收入。
B43: =E38 -> 488 | D43: 100 | E43: =(B43-D43)/(E38+G38-D43) -> 0.76078431 | F43: 580 | G43: =(F43-D43)*E43+D43 -> 465.17647 | H43: =((E38+G38)-D43)*E43+D43 -> 488 | I43: =((E38+G38)-F43)*(1-E43) -> 7.1764706
...

Sheet 主要责任人与代理人D4-
A1: 致同会计师事务所
A2: 主要责任人与代理人判断
A3: =[4]底稿目录!$A$2 -> 被审计单位： | D3: =[4]底稿目录!$A$4 -> 编制人： | F3: =[4]底稿目录!$A$5 -> 编制日期： | H3: 索引号： | I3: D4-
A4: =[4]底稿目录!$A$3 -> 会计期间：202X年度 | D4: =[4]底稿目录!$A$6 -> 复核人： | F4: =[4]底稿目录!$A$7 -> 复核日期： | H4: 页次：
A5: 一、审计目标：
A6: 确定企业从事交易时的身份是主要责任人还是代理人。 | J6: 企业应根据其在向客户转让商品前是否拥有对该商品的控制权，来判断其从事交易时的身份是主要责任人还是代理人。
A7: 二、审计过程：
A8: 判断企业在向客户转让商品或服务前是否能够控制该商品或服务。
A9: 1.识别向客户所承诺的“特定商品或服务”
A10: 例如，旅行社销售的机票向客户提供了乘坐航班的权利，团购网站销售的餐券向客户提供了在指定餐厅用餐的权利。 例如设计和制造专门设备（不可相互明确区分的一揽子商品或服务）。 | J10: 识别合同中主体的承诺（即履约义务）是确定主体作为主要责任人还是代理人的基础。 特定商品或服务是指拟向客户提供的可明确区分的商品或服务（或可明确区分的一揽子商品或服务）。
A11: 注：代理人的履约义务是安排另一方向客户提供商品或服务；代理人本身并未承诺向最终客户提供商品或服务。
A13: 2.在向客户转让前是否拥有特定商品或服务的控制权
A14: 2.1 向客户转让商品或服务前能够控制的情形
A15: 转让前能够控制的情形 | C15: 说明 | F15: 分析 | G15: 审计证据 | I15: 索引
A16: （1）企业自第三方取得商品或其他资产控制权后，再转让给客户； | C16: 企业应当考虑该权利是仅在转让给客户时才产生，还是在转让给客户之前就已经存在，且企业一直能够主导其使用，如果该权利在转让给客户之前不存在，则企业实质上并不能在该权利转让给客户之前控制该权利。 | J16: 这里的商品或其他资产也包括企业向客户转让的未来享有由其他方提供服务的权利。
A17: （2）企业能够主导第三方代表本企业向客户提供服务； | C17: 当企业承诺向客户提供服务，并委托第三方（例如分包商、其他服务提供商等）代表企业向客户提供服务时，如果企业能够主导该第三方代表本企业向客户提供服务，则表明企业在相关服务提供给客户之前能够控制该相关服务。 | J17: 主体本身不提供商品或服务这一事实并非决定性因素。 注意，《企业会计准则解释第2号》中关于BOT业务的规定并未废止，“项目公司未提供实际建造服务，将基础设施建造发包给其他方的，不应确认建造服务收入”。
A18: （3）企业自第三方取得商品控制权后，通过提供重大的服务将该商品与其他商品整合成某组合产出转让给客户。 | C18: 企业承诺提供的特定商品就是合同约定的组合产出。企业只有获得为生产该特定商品所需要的投入（包括从第三方取得的商品）的控制权，才能够将这些投入加工整合为合同约定的组合产出。
A19: 同行业可比公司的判断
A20: 结 论
A21: 注：如果主体在特定商品的法定所有权转移给客户之前只是暂时性地取得该商品的法定所有权，则主体不一定控制该商品。 | J21: （IFRS 15.B35/CAS 14.AG七（三）1）
A23: 2.2 应当综合考虑的相关事实和情况
A24: 相关事实和情况 | C24: 说明 | F24: 分析 | G24: 审计证据 | I24: 索引
A25: （1）企业承担向客户转让商品的主要责任； | C25: 应当从客户的角度进行评估，即客户认为哪一方承担了主要责任。例如，客户认为谁对商品的质量或性能负责、谁负责提供售后服务、谁负责解决客户投诉等。 | J25: 该主要责任包括就特定商品的可接受性（例如，确保商品的规格满足客户的要求）承担责任等。
A26: （2）企业在转让商品之前或之后承担了该商品的存货风险； | C26: 当企业在与客户订立合同之前已经购买或者承诺将自行购买特定商品时，这可能表明企业在将该特定商品转让给客户之前，承担了该特定商品的存货风险，企业有能力主导特定商品的使用并从中取得几乎全部的经济利益。 | J26: 在附有销售退回条款的销售中，企业将商品销售给客户之后，客户有权要求向该企业退货，这可能表明企业在转让商品之后仍然承担了该商品的存货风险。
A27: （3）企业有权自主决定所交易商品的价格； | C27: 然而，在某些情况下，代理人可能在一定程度上也拥有定价权（例如，在主要责任人规定的某一价格范围内决定价格），以便其在代表主要责任人向客户提供商品时，能够吸引更多的客户，从而赚取更多的收入。 | J27: 企业有权决定与客户交易的特定商品的价格，可能表明企业有能力主导该商品的使用并从中获得几乎全部的经济利益。
A28: （4）其他相关事实和情况。 | C28: 考虑交易的经济实质。 | J28: 实务中，企业在判断其在向客户转让特定商品之前是否已经拥有对该商品的控制权时，不应仅局限于合同的法律形式，而应当综合考虑所有相关事实和情况进行判断。
A29: 同行业可比公司的判断 | J29: 上述相关事实和情况仅为支持对控制权的评估，不能取代控制权的评估，也不能凌驾于控制权评估之上，更不是单独或额外的评估；并且这些事实和情况并元权重之分，其中某一项或几项也不能被孤立地用于支持某一结论。企业应当根据相关商品的性质、合同条款的约定以及其他具体情况，综合进行判断。不同的合同可能需要采用上述不同的事实和情况提供支持证据。
A30: 结 论
A31: 注：企业应当从客户的角度进行评估，而不应当仅考虑企业自身的看法。
A33: 三、审计说明：
A36: 四、审计结论：
A39: 提示：
A40: 企业应当根据其在向客户转让商品前是否拥有对该商品的控制权，来判断其从事交易时的身份是主要责任人还是代理人。
A41: 企业在向客户转让商品前能够控制该商品的，该企业为主要责任人，应当按照已收或应收对价总额确认收入；否则，该企业为代理人，
A42: 应当按照预期有权收取的佣金或手续费的金额确认收入，该金额应当按照已收或应收对价总额扣除应支付给其他相关方的价款后的净额，
A43: 或者按照既定的佣金金额或比例等确定。

Sheet 知识产权许可D4-
A1: 致同会计师事务所
A2: 授予知识产权许可
A3: =[4]底稿目录!$A$2 -> 被审计单位： | D3: =[4]底稿目录!$A$4 -> 编制人： | F3: =[4]底稿目录!$A$5 -> 编制日期： | H3: 索引号： | I3: D4-
A4: =[4]底稿目录!$A$3 -> 会计期间：202X年度 | D4: =[4]底稿目录!$A$6 -> 复核人： | F4: =[4]底稿目录!$A$7 -> 复核日期： | H4: 页次：
A5: 一、审计目标： | J5: 授予知识产权许可，是指企业授予客户对企业拥有的知识产权享有相应权利。常见的知识产权包括软件和技术、影视和音乐等的版权、特许经营权以及专利权、商标权和其他版权等。
A6: 确定授予知识产权许可属于在某一时段履行的履约义务，还是在某一时点履行的履约义务。
A7: 二、审计过程：
A8: 确定授予知识产权许可是否构成单项履约义务，确定授予知识产权许可属于在某一时段履行的履约义务还是在某一时点履行的履约义务。
A9: 1.知识产权许可与所售商品不可明确区分的情形
A10: 情形（任一） | C10: 说明 | F10: 分析 | G10: 审计证据 | I10: 索引
A11: （1）该知识产权许可构成有形商品的组成部分并且对于该商品的正常使用不可或缺； | C11: 例如，企业向客户销售设备和相关软件，该软件内嵌于设备之中，该设备必须安装了该软件之后才能正常使用
A12: （2）客户只有将该知识产权许可和相关服务一起使用才能够从中获益。 | C12: 例如，客户取得授权许可，但是只有通过企业提供的在线服务才能访问相关内容
A13: 结 论 | J13: 授予客户的知识产权许可不构成单项履约义务的，企业应当将该知识产权许可和所售商品一起作为单项履约义务进行会计处理。
A14: 注：企业应当评估授予客户的知识产权许可是否可与所售商品明确区分，即该知识产权许可是否构成单项履约义务，并进行相应的会计处理。
A16: 2.是否属于在某一时段履行的履约义务
A17: 须同时满足的条件 | C17: 说明 | F17: 分析 | G17: 审计证据 | I17: 索引
A18: （1）合同要求或客户能够合理预期企业将从事对该项知识产权有重大影响的活动； | C18: 当该项知识产权具有重大的独立功能，且该项知识产权绝大部分的经济利益来源于该项功能时，客户从该项知识产权中获得的利益可能不受企业从事的相关活动的重大影响，除非这些活动显著改变了该项知识产权的形式或者功能。 | F18: =IF(OR(F19="是",F20="是"),"是","否") -> 否 | J18: 具有重大独立功能的知识产权主要包括软件、生物合成物或药物配方以及已完成的媒体内容（例如电影、电视节目以及音乐录音）版权等。
A19: ①这些活动预期将显著改变该项知识产权的形式（如知识产权的设计、内容）或者功能（如执行某任务的能力） | C19: 改变了知识产权的设计或内容、执行某项功能或任务的能力等。 应当根据主体的活动是否对知识产权向客户提供利益的能力产生影响来评估此类活动是否会显著改变客户享有相关权利的知识产权。 | J19: 企业从事的活动存在此情况之一的，将会对该项知识产权有重大影响。
A20: ②客户从该项知识产权中获益的能力在很大程度上来源于或者取决于这些活动，即，这些活动会改变该项知识产权的价值 | C20: 例如企业授权客户使用其品牌，客户从该品牌获得的利益价值取决于企业为维护或提升其品牌价值而持续从事的活动。 | J20: 企业从事的活动存在此情况之一的，将会对该项知识产权有重大影响。
A21: （2）该活动对客户将产生有利或不利影响； | C21: 如果企业从事的后续活动并不影响授予客户的知识产权许可，那么企业的后续活动只是在改变其自己拥有的资产。虽然这些活动可能影响企业提供未来知识产权许可的能力，但将不会影响客户已控制或使用的内容。 | J21: 企业从事的这些后续活动将直接导致相关知识产权许可对客户产生影响，且这种影响既包括有利影响，也包括不利影响。
A22: （3）该活动不会导致向客户转让某项商品。 | C22: 企业向客户授予知识产权许可，并承诺从事与该许可相关的某些后续活动时，如果这些活动本身构成了单项履约义务，那么企业在评估授予知识产权许可是否属于在某一时段履行的履约义务时应当不予考虑。 | J22: 不应考虑下列因素：一是该许可在时间、地域、排他性以及相关知识产权消耗和使用方面的限制，这是因为这些限制界定了已承诺的许可的属性，并不能界定企业是在某一时点还是在某一时段内履行其履约义务。二是企业就其拥有的知识产权的有效性以及防止未经授权使用该知识产权许可所提供的保证，这是因为保护知识产权的承诺并不构成履约义务，该保护行为是为了保护企业知识产权资产的价值，并且就所转让的知识产权许可符合合同约定的具体要求而向客户提供保证。
A23: 同行业可比公司的判断
A24: 结 论 | C24: =IF(AND(F18="是",F21="是",F22="是"),"授予知识产权许可属于在某一时段履行的履约义务","属于在某一时点履行的履约义务,在客户能够使用某项知识产权许可并开始从中获利之前，企业不能对此类知识产权许可确认收入。") -> 属于在某一时点履行的履约义务,在客户能够使用某项知识产权许可并开始从中获利之前，企业不能对此类知识产权许可确认收入。 | J24: 满足条件时，属于获取主体知识产权的权利 （a right to access），其存在于整个使用许可有效期内。
A26: 3.基于销售或使用情况的特许权使用费（估计可变对价的一个例外规定）
A27: 适用情形（任一） | C27: 说明 | F27: 分析 | G27: 审计证据 | I27: 索引
A28: （1）特许权使用费仅与知识产权许可相关；
A29: （2）特许权使用费可能与合同中的知识产权许可和其他商品都相关，但是，与知识产权许可相关的部分占有主导地位。 | C29: 当企业能够合理预期，客户认为知识产权许可的价值远高于合同中与之相关的其他商品时，该知识产权许可可能是占有主导地位的。
A30: 结 论 | C30: =IF(OR(F28="是",F29="是"),"应当在客户后续销售或使用行为实际发生与企业履行相关履约义务二者孰晚的时点确认收入。","不适用例外规定，应当按照估计可变对价的一般原则进行处理。") -> 不适用例外规定，应当按照估计可变对价的一般原则进行处理。 | J30: 对于不适用该例外规定的特许权使用费，应当按照估计可变对价的一般原则进行处理。
A31: 注：使用上述例外规定时，应当对特许权使用费整体采用该规定，而不应当将特许权使用费进行分拆，即部分采用该例外规定进行处理，
A32: 而其他部分按照估计可变对价的一般原则进行处理。
A34: 三、审计说明：
A36: 四、审计结论：
A38: 提示：
A39: 授予知识产权许可，是指企业授予客户对企业拥有的知识产权享有相应权利。常见的知识产权包括软件和技术、影视和音乐等的版权、特许经营权以及专利权、商标权和其他版权等。
A40: 授予客户的知识产权许可构成单项履约义务的，企业应当根据该履约义务的性质，进一步确定其是在某一时段内履行还是在某一时点履行。
