Workbook

Sheet 底稿目录
A1: 底稿开列时，可先在以下单元格填写有关内容，以便其他底稿引用有关数据：
A2: 被审计单位：
A3: 截止日：202X年12月31日 | D3: 序号 | E3: 内容 | F3: 索引号 | G3: 备注
A4: 编制人： | E4: 固定资产审计程序表 | F4: H1A
A5: 编制日期： | D5: 1 | E5: 审定表 | F5: H1-1
A6: 复核人： | D6: =D5+1 -> 2 | E6: 附注披露信息（上市公司） | G6: 无需打印
A7: 复核日期： | D7: =D6+1 -> 3 | E7: 附注披露信息（国有企业） | G7: 无需打印
A8: 固定资产类别设置（以下内容请根据实际情况修改）： | D8: =D7+1 -> 4 | E8: 明细表 | F8: H1-2
A9: 房屋及建筑物 | D9: =D8+1 -> 5 | E9: 调整分录汇总 | F9: H1-3
A10: 机器设备 | D10: =D9+1 -> 6 | E10: 闲置检查表 | F10: H1-4
A11: 运输设备 | D11: =D10+1 -> 7 | E11: 会计政策估计检查表 | F11: H1-5
A12: 办公设备 | D12: =D11+1 -> 8 | E12: 分析表 | F12: H1-6
A13: 其他设备 | D13: =D12+1 -> 9 | E13: 增加检查表 | F13: H1-7
A14: …… | D14: =D13+1 -> 10 | E14: 减少检查表 | F14: H1-8
D15: =D14+1 -> 11 | E15: 监盘计划 | F15: H1-9
A16: 关于工作底稿与审计程序索引号对应的说明 | D16: =D15+1 -> 12 | E16: 盘点检查表 | F16: H1-10
A17: 1.编制的审计工作底稿应与审计程序对应。审计项目组应根据被审计单位实际情况和风险评估情况在实质性程序表中裁剪、修改或增加审计程序，根据实际执行的审计程序完成相应审计工作底稿，编制的工作底稿中应按自然顺序依次编制索引号，并通过唯一的索引号将与实质性程序表中的程序对应关联（即将工作底稿的索引号填入实质性程序表中的底稿索引号列）。 | D17: =D16+1 -> 13 | E17: 监盘小结 | F17: H1-11
D18: =D17+1 -> 14 | E18: 折旧测算表（不含减值）-直线法 | F18: H1-12
D19: =D18+1 -> 15 | E19: 折旧测算表（含减值） | F19: H1-12
D20: =D19+1 -> 16 | E20: 折旧测算表（多次减值） | F20: H1-12
A21: 2.获取的支持性证据应与审计底稿或程序对应。审计项目组在完成底稿时获取的支持性证据应根据底稿索引号编制下一级按自然顺序排序的索引号（如D1-2-1、D1-2-2、……），并在底稿中说明引用的支持性证据、关联索引号。 | D21: =D20+1 -> 17 | E21: 折旧分配分析表 | F21: H1-13
D22: =D21+1 -> 18 | E22: 减值测算表 | F22: H1-14
D23: =D22+1 -> 19 | E23: 可收回金额测试表 | F23: H1-15
A24: 3.工作底稿索引号的编码规则：实质性程序索引号按循环从“D”到“N”,循环内账户以顺序号排列，模板中底稿索引号按账户顺序+自然数顺序（即模板中索引号按二级自然顺序排列，如D1-1、D1-2、D1-3、……D1-N）。 | D24: =D23+1 -> 20 | E24: 房屋建筑物权属检查表 | F24: H1-16
D25: =D24+1 -> 21 | E25: 运输设备权属检查表 | F25: H1-17
D26: =D25+1 -> 22 | E26: 关联交易检查表 | F26: H1-18
D27: =D26+1 -> 23 | E27: 经营租出固定资产检查表 | F27: H1-19
D28: =D27+1 -> 24 | E28: 融资租出固定资产检查表 | F28: H1-20

Sheet 固定资产审计程序表H1A
A1: 致同会计师事务所
A2: 固定资产实质性程序表
A3: =底稿目录!A2 -> 被审计单位： | C3: =底稿目录!A4 -> 编制人： | E3: =底稿目录!A5 -> 编制日期： | I3: 索引号： | J3: H1A
A4: =底稿目录!A3 -> 截止日：202X年12月31日 | C4: =底稿目录!A6 -> 复核人： | E4: =底稿目录!A7 -> 复核日期： | I4: 页 次：
A5: 一、本账户涉及的科目
A6: 固定资产、累计折旧、减值准备
A7: 二、审计目标与认定的对应关系
A8: 审计目标 | G8: 财务报表的认定
A9: A. 资产负债表中记录的固定资产是存在的，且已记录于恰当的账户 | G9: 存在
A10: B. 所有应记录的固定资产均已记录，所有应当包括在财务报表中的相关披露均已包括 | G10: 完整性
A11: C. 记录的固定资产由被审计单位拥有或控制； | G11: 权利和义务
A12: D. 固定资产以恰当的金额包括在财务报表中，与之相关的计价或分摊调整已恰当记录，相关披露已得到恰当计量和描述 | G12: 准确性、计价和分摊
A13: E. 固定资产已被恰当地汇总或分解且表述清楚，相关披露在按照企业会计准则的编制基础下是相关的、可理解的 | G13: 列报
A14: 三、计划实施的实质性程序
A15: 序号 | B15: 审计程序 | C15: 程序分类 | D15: 财务报表的认定 | I15: 底稿索引号
D16: 存在 | E16: 完整性 | F16: 权利和 义务 | G16: 准确性、计价和分摊 | H16: 列报 | K16: 根据被审计单位实际情况和风险评估情况裁剪、修改或增加审计程序
A17: 1 | B17: 获取或编制固定资产的明细表，完成以下工作，并编制审定表 （1）复核加计是否正确，并与总账数和明细账合计数核对是否相符，期初余额与上期审定期末余额是否相符； （2）结合固定资产减值准备科目和报表数核对是否相符 （3）询问闲置资产或未入账资产处置情况（如有）。 | C17: 常规★ | D17: √ | E17: √ | G17: √ | I17: H1-1 /H1-2 /H1-4
A18: 2 | B18: 取得固定资产维修和保养的明细（如有），考虑执行以下程序：详细检查单个重大的固定资产，并复核相关支持性的文件，确定计入费用的项目是否合理。 | C18: 备选 | D18: √ | E18: √ | G18: √
A19: 3 | B19: 在使用手工编制、自定义信息报告、系统生成的非固定格式报告等由被审计单位生成的信息时，测试有关信息准确性和完整性，并考虑针对编制和维护由被审计单位生成的信息的相关控制实施控制测试，以评价该信息是否能够为实现审计目的提供基础。 | C19: 常规★ | E19: √ | G19: √ | I19: T1 / | K19: 可参见《审计手册》4.2.6，由被审计单位生成的信息可能是由系统生成的、或手工编制的、或二者兼而有之的方式生成的。例如，由被审计单位生成的信息可能包括： • 不涉及自定义的、由系统生成的报告（如，固定格式报告）； • 可能通过人工自定义的、由系统生成的报告，例如，（计算机）查询信息或特别定制的报告； • 手工编制的信息，例如，汇总信息的电子表格或用以支持分配、计算以及调节的电子表格； • 其他系统生成或手工编制的信息，例如，由被审计单位编制的客户发票； • 通过影印、拍摄、扫描或其他方式转换成电子形式的文件记录。
A20: 4 | B20: 对期初余额的审计，取得上期固定资产明细表、长期租赁资产（经营租出、融资租出）的明细表复核加计是否正确，与总账、明细账合计数是否相符； 重新测算期初累计折旧余额准确性；对单项金额重大资产，进行实地查看资产或检查支持性文件，其他必要追加的审计程序。（适用于首次承接） | C20: 备选 | D20: √ | E20: √ | F20: √ | G20: √ | K20: 由被审计单位生成的信息不包括： • 总分类账或明细分类账、试算平衡表、或经审计的财务报表； • 第三方（除了服务机构）的报表或报告，例如，原始银行对账单，或函证的回函； • 外部数据（例如，第三方发布的数据，如，定价来源）。
A21: 5 | B21: 关注会计政策、会计估计合理性、一贯性，关注其是否利用会计政策和会计估计及其变更操纵利润。必要时与同行业其他公司会计政策、会计估计进行对比，主要会计政策和估计包括： （1）固定资产的初始计量； （2）固定资产折旧/减值的政策和方法； （3）固定资产的后续支出（包括支出费用化和资本化）及终止确认。 | C21: 常规★ | D21: √ | E21: √ | G21: √ | I21: H1-5
A22: 6 | B22: 执行分析性程序，考虑识别需要执行额外程序的领域： （1）分析本期和上期固定资产净值占资产总额比例、当期计提折旧额、累计折旧及减值准备余额分别占固定资产原值比例是否异常； （2）分析固定资产原值与本期产品产量的比率（固定资产的规模及其变化是否与产能匹配）、并与以前年度对比； （3）分析租赁资产占相应资产的比例及本期与以前年度租赁收入情况（判断被审计单位对资产租赁收益的依赖程度及盈利能力的稳定性）； （4）分析维修费用与固定资产原值的比例等，并与以前年度对比。 | C22: 常规★ | D22: √ | E22: √ | G22: √ | I22: H1-6
A23: 7 | B23: 了解被审计单位的主要生产设备的名称、位置、建设及投产情况，与所生产产品种类的对应关系。将主要生产设备的产能与当期产量对比，判断是否存在异常迹象。 | C23: IPO/上市/新三板/重组/舞弊应对 | D23: √ | E23: √ | G23: √
A24: 8 | B24: 实地观察固定资产投入及运行情况、厂区员工人数以及车间生产情况，分析资产规模与产能的匹配性，开工情况与产量的匹配性；结合产能、产量、销量数据计算产能利用率（开工率），与同行业企业进行对比，分析变化原因及合理性。 | C24: IPO/上市/新三板/重组/舞弊应对 | D24: √ | E24: √ | G24: √
A25: 9 | B25: 检查本期新增的固定资产： （1）对于外购的固定资产，检查购置合同、发票、保险单、发运凭证等文件，检查其金额及会计处理是否正确；如果购买固定资产的价款超过正常信用条件延期支付，检查实质上是否具有融资性质，固定资产的成本是否以购买价款的现值为基础确定； （2）对于在建工程转入的固定资产，结合固定资产盘点程序，检查竣工决算、验收和移交报告是否正确，与在建工程相关的记录是否核对相符，借款费用资本化金额是否恰当；对已经在用或已经达到预定可使用状态但尚未办理竣工决算的固定资产，检查其是否已经暂估入账，并按规定计提折旧；检查资本性支出与收益性支出的划分是否恰当；竣工决算完成后，是否及时调整； （3）对于更新改造增加的固定资产，检查增加的固定资产原值是否真实，是否符合资本化条件，增计金额是否超过了该项固定资产的可收回金额；重新确定的剩余折旧年限是否恰当； （4）对于盘盈的固定资产，检查固定资产计价及确认的损益是否符合会计准则及相关规定； （5）关注固定资产是否存在弃置费用，如果存在弃置费用，检查弃置费用的估计方法和弃置费用现值的计算是否合理，会计处理是否正确。 | C25: 常规★ | D25: √ | E25: √ | F25: √ | G25: √ | I25: H1-7
A26: 10 | B26: 检查本期固定资产的处置： （1）结合固定资产清理科目，抽查固定资产账面转销额是否正确； （2）检查出售、盘亏、转让、报废或毁损的固定资产是否经授权批准、检查相关合同等，相关收益或损失已正确计算，并进行正确的会计处理； （3）检查因修理、更新改造而停止使用的固定资产的会计处理是否正确； | C26: 常规★ | D26: √ | E26: √ | G26: √ | I26: H1-8
A27: 11 | B27: 其他方式增加或减少的固定资产，考虑执行以下程序： （1）对于非货币性资产交换、债务重组、投资、投资者投入等交易方式取得或减少的有关长期资产，检查相关合同/协议，关注计价是否正确、移交手续是否办理以及会计处理是否正确。 （2）对于因清产核资、资产评估调增或调减有关长期资产价值的，检查有关清产核资报告、资产评估报告、国有资产管理等部门的确认文件、验资报告等，检查会计处理是否正确。 | C27: 备选 | D27: √ | E27: √ | F27: √ | G27: √ | I27: H1-7 /H1-8
A28: 12 | B28: 监盘固定资产： （1）取得公司固定资产清单，盘点范围考虑包括本期新增、容易侵占、重要、数量巨大、已损坏项目、存放在第三方及其他异常等。关注是否存在已报废但仍未核销的固定资产 （2）获取被审计单位对于固定资产的盘点计划，制定和实施监盘计划（如有）及盘点控制文件的复印件（如：盘点清单，标签控制清单）； （3）取得固定资产存放地点清单，初步确定监盘方式、时间、监盘计划； （4）观察被审计单位制定的盘点程序的执行情况 （5）检查固定资产的状态（在用、闲置、毁损或陈旧等）； （6）执行抽盘，注册会计师从固定资产盘点记录追查至固定资产实物，以及从固定资产实物中选取项目追查至固定资产清单，将抽盘结果与账面核对； （7）评价固定资产盘点结果，完成监盘小结。 | C28: 常规★ | D28: √ | F28: √ | G28: √ | I28: H1-9 /H1-10 /H1-11
A29: 13 | B29: 存放其他地方的资产（如有），考虑实地观察或函证由其他人保管或保管在盘点地之外的资产。 | C29: 备选 | D29: √ | F29: √ | G29: √
A30: 14 | B30: 检查累计折旧，考虑执行以下程序： （1）获取或编制累计折旧分类汇总表，复核加计正确，并与总账数和明细账合计数核对。 （2）重新计算折旧，当存在减值时，是否按照扣除减值损失之后的使用权资产账面价值进行后续折旧。 （3）获取暂时闲置、已提足折旧仍继续使用和前期已计提减值准备的固定资产的相关证明文件，并观察其实际状况，检查是否已按规定计提折旧； （4）检查折旧分配到成本、费用的情况，关注分配是否合理，与上期分配方法是否一致。 | C30: 常规★ | G30: √ | I30: H1-12 /H1-13
A31: 15 | B31: 结合固定资产清单和盘点程序，了解固定资产的状态。针对存在减值迹象的固定资产，考虑执行下列程序： 获取被审计单位在资产负债表日就固定资产是否可能发生减值迹象的判断的说明，判断其合理性。对于已计提减值准备的固定资产，检查减值测试相关参数是否合理，减值准备计提是否正确。对于管理层聘请评估专家出具的评估报告，复核评估报告。 | C31: 常规★ | G31: √ | I31: H1-14 /H1-15
A32: 16 | B32: 检查固定资产的所有权或控制权 （1）检查房屋及建筑物、运输设备等固定资产，并同时查看资产权属证明原件，结合银行借款等项目的检查，了解是否存在重大的抵押、担保情况，并取得复印件作为工作底稿； （2）对于正在办理权属证明的大额资产，了解权属证明办理情况，确认是否存在权属纠纷或实质性障碍。 | C32: 常规★ | F32: √ | I32: H1-16 /H1-17
A33: 17 | B33: 检查关联交易情况，检查关联交易的真实性、合理性及合规性；检查关联交易会计处理是否正确，考虑是否存在未识别的关联方，检查关联交易和余额披露是否正确。 | C33: 常规★ | D33: √ | E33: √ | F33: √ | G33: √ | H33: √ | I33: H1-18
A34: 18 | B34: 针对长期资产租赁（经营租出固定资产），考虑执行下列程序： （1）获取或编制资产租赁明细表，获取租赁合同/协议，核对重要条款，检查租赁分类是否正确。 （2）根据租赁合同/协议等文件，检查初始直接费用、或有租金确认是否合理，会计处理是否正确，重新计算租金收入并与利润表其他业务收入进行核对。 | C34: 备选 | D34: √ | E34: √ | F34: √ | G34: √ | I34: H1-19
A35: 19 | B35: 针对长期资产租赁（融资租出固定资产），考虑执行下列程序： （1）获取或编制资产租赁明细表，获取租赁合同/协议，核对重要条款，检查租赁分类是否正确，与固定资产增减变动明细表核对一致； （2）检查长期应收款、未确认融资收益的计算是否正确，实际利率、初始直接费用及或有租金的确认是否合理； （3）未担保余值发生变动的，分析变动原因，检查会计处理是否正确。 （4）本期租赁期届满的，分析处理方式（收回、优惠续租和出售），检查会计处理是否正确。 | C35: 备选 | D35: √ | E35: √ | F35: √ | G35: √ | I35: H1-20
A36: 20 | B36: 存在弃置义务的固定资产结合预计负债底稿检查会计处理是否正确。 | C36: 备选 | E36: √
A37: 21 | B37: 根据评估的舞弊风险等因素增加的审计程序。 | C37: IPO/上市/新三板/重组/舞弊应对
A38: 22 | B38: 检查固定资产、抵押和担保情况等是否已按企业会计准则或其他适用的规定在财务报表中做出恰当列报和披露 | C38: 常规★ | H38: √ | I38: A 1-1/A1-15 /A1-16

Sheet 审定表H1-1
A1: 致同会计师事务所
A2: 固定资产、累计折旧、减值准备审定表
A3: =底稿目录!A2 -> 被审计单位： | D3: =底稿目录!A4 -> 编制人： | G3: =底稿目录!A5 -> 编制日期： | H3: 索引号： | I3: H1-1
A4: =底稿目录!A3 -> 截止日：202X年12月31日 | D4: =底稿目录!A6 -> 复核人： | G4: =底稿目录!A7 -> 复核日期： | H4: 页 次：
A5: 项目 | B5: 期初数 | E5: 期末数 | H5: 本期审定数与上期 审定数的比较
B6: 未审数 | C6: 账项调整 | D6: 审定数 | E6: 未审数 | F6: 账项调整 | G6: 审定数 | H6: 变动额 | I6: 变动率
A7: 一、固定资产原值
A8: =底稿目录!A9 -> 房屋及建筑物 | B8: ='明细表H1-2'!D35 -> 0 | C8: ='明细表H1-2'!J35 -> 0 | D8: =B8+C8 -> 0 | E8: ='明细表H1-2'!I35 -> 0 | F8: ='明细表H1-2'!J35+'明细表H1-2'!K35-'明细表H1-2'!L35 -> 0 | G8: =E8+F8 -> 0 | H8: =G8-D8 -> 0 | I8: =IF(AND(D8=0,H8=0),0,IF(AND(D8=0,H8>0),1,H8/D8)) -> 0
A9: =底稿目录!A10 -> 机器设备 | B9: ='明细表H1-2'!D36 -> 0 | C9: ='明细表H1-2'!J36 -> 0 | D9: =B9+C9 -> 0 | E9: ='明细表H1-2'!I36 -> 0 | F9: ='明细表H1-2'!J36+'明细表H1-2'!K36-'明细表H1-2'!L36 -> 0 | G9: =E9+F9 -> 0 | H9: =G9-D9 -> 0 | I9: =IF(AND(D9=0,H9=0),0,IF(AND(D9=0,H9>0),1,H9/D9)) -> 0
A10: =底稿目录!A11 -> 运输设备 | B10: ='明细表H1-2'!D37 -> 0 | C10: ='明细表H1-2'!J37 -> 0 | D10: =B10+C10 -> 0 | E10: ='明细表H1-2'!I37 -> 0 | F10: ='明细表H1-2'!J37+'明细表H1-2'!K37-'明细表H1-2'!L37 -> 0 | G10: =E10+F10 -> 0 | H10: =G10-D10 -> 0 | I10: =IF(AND(D10=0,H10=0),0,IF(AND(D10=0,H10>0),1,H10/D10)) -> 0
A11: =底稿目录!A12 -> 办公设备 | B11: ='明细表H1-2'!D38 -> 0 | C11: ='明细表H1-2'!J38 -> 0 | D11: =B11+C11 -> 0 | E11: ='明细表H1-2'!I38 -> 0 | F11: ='明细表H1-2'!J38+'明细表H1-2'!K38-'明细表H1-2'!L38 -> 0 | G11: =E11+F11 -> 0 | H11: =G11-D11 -> 0 | I11: =IF(AND(D11=0,H11=0),0,IF(AND(D11=0,H11>0),1,H11/D11)) -> 0
A12: =底稿目录!A13 -> 其他设备 | B12: ='明细表H1-2'!D39 -> 0 | C12: ='明细表H1-2'!J39 -> 0 | D12: =B12+C12 -> 0 | E12: ='明细表H1-2'!I39 -> 0 | F12: ='明细表H1-2'!J39+'明细表H1-2'!K39-'明细表H1-2'!L39 -> 0 | G12: =E12+F12 -> 0 | H12: =G12-D12 -> 0 | I12: =IF(AND(D12=0,H12=0),0,IF(AND(D12=0,H12>0),1,H12/D12)) -> 0
A13: 合计 | B13: =SUM(B8:B12) -> 0 | C13: =SUM(C8:C12) -> 0 | D13: =SUM(D8:D12) -> 0 | E13: =SUM(E8:E12) -> 0 | F13: =SUM(F8:F12) -> 0 | G13: =SUM(G8:G12) -> 0 | H13: =G13-D13 -> 0 | I13: =IF(AND(D13=0,H13=0),0,IF(AND(D13=0,H13>0),1,H13/D13)) -> 0
A14: 二、累计折旧
A15: =底稿目录!A9 -> 房屋及建筑物 | B15: ='明细表H1-2'!Q35 -> 0 | C15: ='明细表H1-2'!W35 -> 0 | D15: =B15+C15 -> 0 | E15: ='明细表H1-2'!V35 -> 0 | F15: ='明细表H1-2'!W35+'明细表H1-2'!X35-'明细表H1-2'!Z35+'明细表H1-2'!Y35-'明细表H1-2'!AA35 -> 0 | G15: =E15+F15 -> 0 | H15: =G15-D15 -> 0 | I15: =IF(AND(D15=0,H15=0),0,IF(AND(D15=0,H15>0),1,H15/D15)) -> 0
A16: =底稿目录!A10 -> 机器设备 | B16: ='明细表H1-2'!Q36 -> 0 | C16: ='明细表H1-2'!W36 -> 0 | D16: =B16+C16 -> 0 | E16: ='明细表H1-2'!V36 -> 0 | F16: ='明细表H1-2'!W36+'明细表H1-2'!X36-'明细表H1-2'!Z36+'明细表H1-2'!Y36-'明细表H1-2'!AA36 -> 0 | G16: =E16+F16 -> 0 | H16: =G16-D16 -> 0 | I16: =IF(AND(D16=0,H16=0),0,IF(AND(D16=0,H16>0),1,H16/D16)) -> 0
A17: =底稿目录!A11 -> 运输设备 | B17: ='明细表H1-2'!Q37 -> 0 | C17: ='明细表H1-2'!W37 -> 0 | D17: =B17+C17 -> 0 | E17: ='明细表H1-2'!V37 -> 0 | F17: ='明细表H1-2'!W37+'明细表H1-2'!X37-'明细表H1-2'!Z37+'明细表H1-2'!Y37-'明细表H1-2'!AA37 -> 0 | G17: =E17+F17 -> 0 | H17: =G17-D17 -> 0 | I17: =IF(AND(D17=0,H17=0),0,IF(AND(D17=0,H17>0),1,H17/D17)) -> 0
A18: =底稿目录!A12 -> 办公设备 | B18: ='明细表H1-2'!Q38 -> 0 | C18: ='明细表H1-2'!W38 -> 0 | D18: =B18+C18 -> 0 | E18: ='明细表H1-2'!V38 -> 0 | F18: ='明细表H1-2'!W38+'明细表H1-2'!X38-'明细表H1-2'!Z38+'明细表H1-2'!Y38-'明细表H1-2'!AA38 -> 0 | G18: =E18+F18 -> 0 | H18: =G18-D18 -> 0 | I18: =IF(AND(D18=0,H18=0),0,IF(AND(D18=0,H18>0),1,H18/D18)) -> 0
A19: =底稿目录!A13 -> 其他设备 | B19: ='明细表H1-2'!Q39 -> 0 | C19: ='明细表H1-2'!W39 -> 0 | D19: =B19+C19 -> 0 | E19: ='明细表H1-2'!V39 -> 0 | F19: ='明细表H1-2'!W39+'明细表H1-2'!X39-'明细表H1-2'!Z39+'明细表H1-2'!Y39-'明细表H1-2'!AA39 -> 0 | G19: =E19+F19 -> 0 | H19: =G19-D19 -> 0 | I19: =IF(AND(D19=0,H19=0),0,IF(AND(D19=0,H19>0),1,H19/D19)) -> 0
A20: 合计 | B20: =SUM(B15:B19) -> 0 | C20: =SUM(C15:C19) -> 0 | D20: =SUM(D15:D19) -> 0 | E20: =SUM(E15:E19) -> 0 | F20: =SUM(F15:F19) -> 0 | G20: =SUM(G15:G19) -> 0 | H20: =G20-D20 -> 0 | I20: =IF(AND(D20=0,H20=0),0,IF(AND(D20=0,H20>0),1,H20/D20)) -> 0
A21: 三、减值准备
A22: =底稿目录!A9 -> 房屋及建筑物 | B22: ='明细表H1-2'!AF35 -> 0 | C22: ='明细表H1-2'!AL35 -> 0 | D22: =B22+C22 -> 0 | E22: ='明细表H1-2'!AK35 -> 0 | F22: ='明细表H1-2'!AL35+'明细表H1-2'!AM35-'明细表H1-2'!AO35+'明细表H1-2'!AN35-'明细表H1-2'!AP35 -> 0 | G22: =E22+F22 -> 0 | H22: =G22-D22 -> 0 | I22: =IF(AND(D22=0,H22=0),0,IF(AND(D22=0,H22>0),1,H22/D22)) -> 0
A23: =底稿目录!A10 -> 机器设备 | B23: ='明细表H1-2'!AF36 -> 0 | C23: ='明细表H1-2'!AL36 -> 0 | D23: =B23+C23 -> 0 | E23: ='明细表H1-2'!AK36 -> 0 | F23: ='明细表H1-2'!AL36+'明细表H1-2'!AM36-'明细表H1-2'!AO36+'明细表H1-2'!AN36-'明细表H1-2'!AP36 -> 0 | G23: =E23+F23 -> 0 | H23: =G23-D23 -> 0 | I23: =IF(AND(D23=0,H23=0),0,IF(AND(D23=0,H23>0),1,H23/D23)) -> 0
A24: =底稿目录!A11 -> 运输设备 | B24: ='明细表H1-2'!AF37 -> 0 | C24: ='明细表H1-2'!AL37 -> 0 | D24: =B24+C24 -> 0 | E24: ='明细表H1-2'!AK37 -> 0 | F24: ='明细表H1-2'!AL37+'明细表H1-2'!AM37-'明细表H1-2'!AO37+'明细表H1-2'!AN37-'明细表H1-2'!AP37 -> 0 | G24: =E24+F24 -> 0 | H24: =G24-D24 -> 0 | I24: =IF(AND(D24=0,H24=0),0,IF(AND(D24=0,H24>0),1,H24/D24)) -> 0
A25: =底稿目录!A12 -> 办公设备 | B25: ='明细表H1-2'!AF38 -> 0 | C25: ='明细表H1-2'!AL38 -> 0 | D25: =B25+C25 -> 0 | E25: ='明细表H1-2'!AK38 -> 0 | F25: ='明细表H1-2'!AL38+'明细表H1-2'!AM38-'明细表H1-2'!AO38+'明细表H1-2'!AN38-'明细表H1-2'!AP38 -> 0 | G25: =E25+F25 -> 0 | H25: =G25-D25 -> 0 | I25: =IF(AND(D25=0,H25=0),0,IF(AND(D25=0,H25>0),1,H25/D25)) -> 0
A26: =底稿目录!A13 -> 其他设备 | B26: ='明细表H1-2'!AF39 -> 0 | C26: ='明细表H1-2'!AL39 -> 0 | D26: =B26+C26 -> 0 | E26: ='明细表H1-2'!AK39 -> 0 | F26: ='明细表H1-2'!AL39+'明细表H1-2'!AM39-'明细表H1-2'!AO39+'明细表H1-2'!AN39-'明细表H1-2'!AP39 -> 0 | G26: =E26+F26 -> 0 | H26: =G26-D26 -> 0 | I26: =IF(AND(D26=0,H26=0),0,IF(AND(D26=0,H26>0),1,H26/D26)) -> 0
A27: 合计 | B27: =SUM(B22:B26) -> 0 | C27: =SUM(C22:C26) -> 0 | D27: =SUM(D22:D26) -> 0 | E27: =SUM(E22:E26) -> 0 | F27: =SUM(F22:F26) -> 0 | G27: =SUM(G22:G26) -> 0 | H27: =G27-D27 -> 0 | I27: =IF(AND(D27=0,H27=0),0,IF(AND(D27=0,H27>0),1,H27/D27)) -> 0
A28: 四、净值
A29: =底稿目录!A9 -> 房屋及建筑物 | B29: =B8-B15-B22 -> 0 | C29: =C8-C15-C22 -> 0 | D29: =D8-D15-D22 -> 0 | E29: =E8-E15-E22 -> 0 | F29: =F8-F15-F22 -> 0 | G29: =E29+F29 -> 0 | H29: =G29-D29 -> 0 | I29: =IF(AND(D29=0,H29=0),0,IF(AND(D29=0,H29>0),1,H29/D29)) -> 0
A30: =底稿目录!A10 -> 机器设备 | B30: =B9-B16-B23 -> 0 | C30: =C9-C16-C23 -> 0 | D30: =D9-D16-D23 -> 0 | E30: =E9-E16-E23 -> 0 | F30: =F9-F16-F23 -> 0 | G30: =E30+F30 -> 0 | H30: =G30-D30 -> 0 | I30: =IF(AND(D30=0,H30=0),0,IF(AND(D30=0,H30>0),1,H30/D30)) -> 0
A31: =底稿目录!A11 -> 运输设备 | B31: =B10-B17-B24 -> 0 | C31: =C10-C17-C24 -> 0 | D31: =D10-D17-D24 -> 0 | E31: =E10-E17-E24 -> 0 | F31: =F10-F17-F24 -> 0 | G31: =E31+F31 -> 0 | H31: =G31-D31 -> 0 | I31: =IF(AND(D31=0,H31=0),0,IF(AND(D31=0,H31>0),1,H31/D31)) -> 0
A32: =底稿目录!A12 -> 办公设备 | B32: =B11-B18-B25 -> 0 | C32: =C11-C18-C25 -> 0 | D32: =D11-D18-D25 -> 0 | E32: =E11-E18-E25 -> 0 | F32: =F11-F18-F25 -> 0 | G32: =E32+F32 -> 0 | H32: =G32-D32 -> 0 | I32: =IF(AND(D32=0,H32=0),0,IF(AND(D32=0,H32>0),1,H32/D32)) -> 0
A33: =底稿目录!A13 -> 其他设备 | B33: =B12-B19-B26 -> 0 | C33: =C12-C19-C26 -> 0 | D33: =D12-D19-D26 -> 0 | E33: =E12-E19-E26 -> 0 | F33: =F12-F19-F26 -> 0 | G33: =E33+F33 -> 0 | H33: =G33-D33 -> 0 | I33: =IF(AND(D33=0,H33=0),0,IF(AND(D33=0,H33>0),1,H33/D33)) -> 0
A34: 合计 | B34: =SUM(B29:B33) -> 0 | C34: =SUM(C29:C33) -> 0 | D34: =SUM(D29:D33) -> 0 | E34: =SUM(E29:E33) -> 0 | F34: =SUM(F29:F33) -> 0 | G34: =SUM(G29:G33) -> 0 | H34: =G34-D34 -> 0 | I34: =IF(AND(D34=0,H34=0),0,IF(AND(D34=0,H34>0),1,H34/D34)) -> 0
A35: 1、审计说明：
A36: （1）固定资产期末净值较期初净值增加（负数为减少）：
A37: 主要原因（比例超过30%的）：
A39: （2）本期由在建工程转入：
A41: （3）抵押、担保情况说明：
A43: （4）出售、置换情况说明：
...

Sheet 附注披露信息（上市公司）
A1: 致同会计师事务所
A2: 附注披露信息（上市公司）
A3: =底稿目录!A2 -> 被审计单位： | C3: =底稿目录!A4 -> 编制人： | F3: =底稿目录!A6 -> 复核人： | G3: 索引号： | H3: 返回目录
A4: =底稿目录!A3 -> 截止日：202X年12月31日 | C4: =底稿目录!A5 -> 编制日期： | F4: =底稿目录!A7 -> 复核日期： | G4: 页 次：
A6: 15、固定资产
A7: 项 目 | B7: 期末余额 | C7: 上年年末余额
A8: 固定资产
A9: 固定资产清理
A10: 合 计 | B10: X.XX | C10: X.XX
A11: （1）固定资产
A12: ①固定资产情况
A13: 项 目 | B13: 房屋及建筑物 | C13: 机器设备 | D13: 运输设备 | E13: …… | F13: 合 计
A14: 一、账面原值：
A15: 1.期初余额
A16: 2.本期增加金额
A17: （1）购置
A18: （2）在建工程转入
A19: （3）企业合并增加
A20: ……
A21: 3.本期减少金额
A22: （1）处置或报废
A23: （2）其他减少
A24: ……
A25: 4.期末余额
... A59: ②暂时闲置的固定资产情况
A60: 项 目 | B60: 账面原值 | C60: 累计折旧 | D60: 减值准备 | E60: 账面价值 | F60: 备注
A61: 房屋及建筑物
A62: 机器设备
A63: 电子设备
A64: 运输设备
A65: 可无限量添加行
A66: 合 计 | B66: X.XX | C66: X.XX | D66: X.XX | E66: X.XX
A68: ③通过经营租赁租出的固定资产
A69: 项 目 | B69: 账面价值
A70: 房屋及建筑物
A71: 机器设备
A72: 电子设备
A73: 运输设备
A74: 可无限量添加行
A75: 合 计 | B75: X.XX
...

Sheet 附注披露信息（国有企业）
A1: 致同会计师事务所
A2: 附注披露信息（国有企业）
A3: =底稿目录!A2 -> 被审计单位： | B3: =底稿目录!A4 -> 编制人： | D3: =底稿目录!A6 -> 复核人： | F3: 索引号： | G3: 返回目录
A4: =底稿目录!A3 -> 截止日：202X年12月31日 | B4: =底稿目录!A5 -> 编制日期： | D4: =底稿目录!A7 -> 复核日期： | F4: 页 次：
A6: 15、固定资产
A7: 项 目 | B7: 期末账面价值 | C7: 期初账面价值
A8: 固定资产
A9: 固定资产清理
A10: 合 计 | B10: X.XX | C10: X.XX
A11: （1）固定资产情况
A12: ① 固定资产情况
A13: 项 目 | B13: 期初余额 | C13: 本期增加 | D13: 本期减少 | E13: 期末余额
A14: 一、账面原值合计 | B14: XX | C14: XX | D14: XX | E14: XX
A15: 其中：土地资产
A16: 房屋、建筑物
A17: 机器设备
A18: 运输工具
A19: 电子设备
A20: 办公设备
A21: 酒店业家具
A22: 其他 | B22: XX | C22: XX | D22: XX | E22: XX
A23: 二、累计折旧合计 | B23: XX | C23: XX | D23: XX | E23: XX
A24: 其中：土地资产 | B24: — | C24: — | D24: — | E24: —
A25: 房屋、建筑物
A26: 机器设备
A27: 运输工具
A28: 电子设备
A29: 办公设备
A30: 酒店业家具
A31: 其他 | B31: XX | C31: XX | D31: XX | E31: XX
A32: 三、固定资产账面净值合计 | B32: XX | C32: XX | D32: XX | E32: XX
A33: 其中：土地资产 | C33: -- | D33: --
A34: 房屋、建筑物 | C34: -- | D34: --
A35: 机器设备 | C35: -- | D35: --
A36: 运输工具 | C36: -- | D36: --
A37: 电子设备 | C37: -- | D37: --
A38: 办公设备 | C38: -- | D38: --
A39: 酒店业家具 | C39: -- | D39: --
A40: 其他 | B40: XX | C40: -- | D40: -- | E40: XX
A41: 四、固定资产减值准备合计 | B41: XX | C41: XX | D41: XX | E41: XX
...

Sheet 明细表H1-2
D1: 致同会计师事务所 | Q1: 致同会计师事务所 | AF1: 致同会计师事务所
D2: 固定资产、累计折旧及减值准备明细表 | Q2: 固定资产、累计折旧及减值准备明细表 | AF2: 固定资产、累计折旧及减值准备明细表
A3: =底稿目录!A2 -> 被审计单位： | H3: =底稿目录!A4 -> 编制人： | L3: =底稿目录!A5 -> 编制日期： | O3: 索引号： | P3: H1-2 | Q3: =底稿目录!A2 -> 被审计单位： | V3: =底稿目录!A4 -> 编制人： | Z3: =底稿目录!A5 -> 编制日期： | AD3: 索引号： | AE3: H1-2 | AF3: =底稿目录!A2 -> 被审计单位： | AN3: =底稿目录!A4 -> 编制人： | AT3: =底稿目录!A5 -> 编制日期： | BA3: 索引号： | BB3: H1-2
A4: =底稿目录!A3 -> 截止日：202X年12月31日 | H4: =底稿目录!A6 -> 复核人： | L4: =底稿目录!A7 -> 复核日期： | O4: 页 次： | Q4: =底稿目录!A3 -> 截止日：202X年12月31日 | V4: =底稿目录!A6 -> 复核人： | Z4: =底稿目录!A7 -> 复核日期： | AD4: 页 次： | AF4: =底稿目录!A3 -> 截止日：202X年12月31日 | AN4: =底稿目录!A6 -> 复核人： | AT4: =底稿目录!A7 -> 复核日期： | BA4: 页 次：
A5: 一、审计目标:
A6: 1.资产负债表中记录的固定资产是存在的，且已记录于恰当的账户；2.所有应记录的固定资产均已记录，所有应当包括在财务报表中的相关披露均已包括；
A7: 3.固定资产以恰当的金额包括在财务报表中，与之相关的计价或分摊调整已恰当记录，相关披露已得到恰当计量和描述
A8: 二、审计过程：
A9: 固定资产类别 | B9: 固定资产编号 | C9: 固定资产名称 | D9: 固定资产原值 | Q9: 累计折旧 | AF9: 减值准备 | AU9: 期初净值 | AW9: 期末净值 | AY9: 是否提足折旧 | AZ9: 是否闲置 | BA9: 是否有权属证明 | BB9: 是否抵押受限
D10: 未审数 | J10: 期初调整 | K10: 账项调整 | M10: 审定数 | Q10: 未审数 | W10: 期初调整 | X10: 账项调整 | AB10: 审定数 | AF10: 未审数 | AL10: 期初调整 | AM10: 账项调整 | AQ10: 审定数
D11: 期初数 | E11: 本期增加 | G11: 本期减少 | I11: 期末数 | K11: 本期增加 | L11: 本期减少 | M11: 期初数 | N11: 本期增加 | O11: 本期减少 | P11: 期末数 | Q11: 期初数 | R11: 本期增加 | T11: 本期减少 | V11: 期末数 | X11: 本期增加 | Z11: 本期减少 | AB11: 期初数 | AC11: 本期增加 | AD11: 本期减少 | AE11: 期末数 | AF11: 期初数 | AG11: 本期增加 | AI11: 本期减少 | AK11: 期末数 | AM11: 本期增加 | AO11: 本期减少 | AQ11: 期初数 | AR11: 本期增加 | AS11: 本期减少 | AT11: 期末数 | AU11: 未审净值 | AV11: 审定净值 | AW11: 未审净值 | AX11: 审定净值
E12: 金额 | F12: 增加方式 | G12: 金额 | H12: 减少方式 | R12: 本期计提 | S12: 其他增加 | T12: 处置 | U12: 其他减少 | X12: 本期计提 | Y12: 其他增加 | Z12: 处置 | AA12: 其他减少 | AG12: 本期计提 | AH12: 其他增加 | AI12: 处置 | AJ12: 其他减少 | AM12: 本期计提 | AN12: 其他增加 | AO12: 处置 | AP12: 其他减少
I13: =SUM(D13:E13)-G13 -> 0 | M13: =D13+J13 -> 0 | N13: =E13+K13 -> 0 | O13: =G13+L13 -> 0 | P13: =M13+N13-O13 -> 0 | V13: =SUM(Q13:S13)-SUM(T13:U13) -> 0 | AB13: =Q13+W13 -> 0 | AC13: =R13+X13+S13+Y13 -> 0 | AD13: =T13+Z13+U13+AA13 -> 0 | AE13: =AB13+AC13-AD13 -> 0 | AK13: =SUM(AF13:AH13)-SUM(AI13:AJ13) -> 0 | AQ13: =AF13+AL13 -> 0 | AR13: =AG13+AM13+AH13+AN13 -> 0 | AS13: =AI13+AO13+AJ13+AP13 -> 0 | AT13: =AQ13+AR13-AS13 -> 0 | AU13: =D13-Q13-AF13 -> 0 | AV13: =M13-AB13-AQ13 -> 0 | AW13: =I13-V13-AK13 -> 0 | AX13: =P13-AE13-AT13 -> 0
I14: =SUM(D14:E14)-G14 -> 0 | M14: =D14+J14 -> 0 | N14: =E14+K14 -> 0 | O14: =G14+L14 -> 0 | P14: =M14+N14-O14 -> 0 | V14: =SUM(Q14:S14)-SUM(T14:U14) -> 0 | AB14: =Q14+W14 -> 0 | AC14: =R14+X14+S14+Y14 -> 0 | AD14: =T14+Z14+U14+AA14 -> 0 | AE14: =AB14+AC14-AD14 -> 0 | AK14: =SUM(AF14:AH14)-SUM(AI14:AJ14) -> 0 | AQ14: =AF14+AL14 -> 0 | AR14: =AG14+AM14+AH14+AN14 -> 0 | AS14: =AI14+AO14+AJ14+AP14 -> 0 | AT14: =AQ14+AR14-AS14 -> 0 | AU14: =D14-Q14-AF14 -> 0 | AV14: =M14-AB14-AQ14 -> 0 | AW14: =I14-V14-AK14 -> 0 | AX14: =P14-AE14-AT14 -> 0
I15: =SUM(D15:E15)-G15 -> 0 | M15: =D15+J15 -> 0 | N15: =E15+K15 -> 0 | O15: =G15+L15 -> 0 | P15: =M15+N15-O15 -> 0 | V15: =SUM(Q15:S15)-SUM(T15:U15) -> 0 | AB15: =Q15+W15 -> 0 | AC15: =R15+X15+S15+Y15 -> 0 | AD15: =T15+Z15+U15+AA15 -> 0 | AE15: =AB15+AC15-AD15 -> 0 | AK15: =SUM(AF15:AH15)-SUM(AI15:AJ15) -> 0 | AQ15: =AF15+AL15 -> 0 | AR15: =AG15+AM15+AH15+AN15 -> 0 | AS15: =AI15+AO15+AJ15+AP15 -> 0 | AT15: =AQ15+AR15-AS15 -> 0 | AU15: =D15-Q15-AF15 -> 0 | AV15: =M15-AB15-AQ15 -> 0 | AW15: =I15-V15-AK15 -> 0 | AX15: =P15-AE15-AT15 -> 0
I16: =SUM(D16:E16)-G16 -> 0 | M16: =D16+J16 -> 0 | N16: =E16+K16 -> 0 | O16: =G16+L16 -> 0 | P16: =M16+N16-O16 -> 0 | V16: =SUM(Q16:S16)-SUM(T16:U16) -> 0 | AB16: =Q16+W16 -> 0 | AC16: =R16+X16+S16+Y16 -> 0 | AD16: =T16+Z16+U16+AA16 -> 0 | AE16: =AB16+AC16-AD16 -> 0 | AK16: =SUM(AF16:AH16)-SUM(AI16:AJ16) -> 0 | AQ16: =AF16+AL16 -> 0 | AR16: =AG16+AM16+AH16+AN16 -> 0 | AS16: =AI16+AO16+AJ16+AP16 -> 0 | AT16: =AQ16+AR16-AS16 -> 0 | AU16: =D16-Q16-AF16 -> 0 | AV16: =M16-AB16-AQ16 -> 0 | AW16: =I16-V16-AK16 -> 0 | AX16: =P16-AE16-AT16 -> 0
I17: =SUM(D17:E17)-G17 -> 0 | M17: =D17+J17 -> 0 | N17: =E17+K17 -> 0 | O17: =G17+L17 -> 0 | P17: =M17+N17-O17 -> 0 | V17: =SUM(Q17:S17)-SUM(T17:U17) -> 0 | AB17: =Q17+W17 -> 0 | AC17: =R17+X17+S17+Y17 -> 0 | AD17: =T17+Z17+U17+AA17 -> 0 | AE17: =AB17+AC17-AD17 -> 0 | AK17: =SUM(AF17:AH17)-SUM(AI17:AJ17) -> 0 | AQ17: =AF17+AL17 -> 0 | AR17: =AG17+AM17+AH17+AN17 -> 0 | AS17: =AI17+AO17+AJ17+AP17 -> 0 | AT17: =AQ17+AR17-AS17 -> 0 | AU17: =D17-Q17-AF17 -> 0 | AV17: =M17-AB17-AQ17 -> 0 | AW17: =I17-V17-AK17 -> 0 | AX17: =P17-AE17-AT17 -> 0
I18: =SUM(D18:E18)-G18 -> 0 | M18: =D18+J18 -> 0 | N18: =E18+K18 -> 0 | O18: =G18+L18 -> 0 | P18: =M18+N18-O18 -> 0 | V18: =SUM(Q18:S18)-SUM(T18:U18) -> 0 | AB18: =Q18+W18 -> 0 | AC18: =R18+X18+S18+Y18 -> 0 | AD18: =T18+Z18+U18+AA18 -> 0 | AE18: =AB18+AC18-AD18 -> 0 | AK18: =SUM(AF18:AH18)-SUM(AI18:AJ18) -> 0 | AQ18: =AF18+AL18 -> 0 | AR18: =AG18+AM18+AH18+AN18 -> 0 | AS18: =AI18+AO18+AJ18+AP18 -> 0 | AT18: =AQ18+AR18-AS18 -> 0 | AU18: =D18-Q18-AF18 -> 0 | AV18: =M18-AB18-AQ18 -> 0 | AW18: =I18-V18-AK18 -> 0 | AX18: =P18-AE18-AT18 -> 0
I19: =SUM(D19:E19)-G19 -> 0 | M19: =D19+J19 -> 0 | N19: =E19+K19 -> 0 | O19: =G19+L19 -> 0 | P19: =M19+N19-O19 -> 0 | V19: =SUM(Q19:S19)-SUM(T19:U19) -> 0 | AB19: =Q19+W19 -> 0 | AC19: =R19+X19+S19+Y19 -> 0 | AD19: =T19+Z19+U19+AA19 -> 0 | AE19: =AB19+AC19-AD19 -> 0 | AK19: =SUM(AF19:AH19)-SUM(AI19:AJ19) -> 0 | AQ19: =AF19+AL19 -> 0 | AR19: =AG19+AM19+AH19+AN19 -> 0 | AS19: =AI19+AO19+AJ19+AP19 -> 0 | AT19: =AQ19+AR19-AS19 -> 0 | AU19: =D19-Q19-AF19 -> 0 | AV19: =M19-AB19-AQ19 -> 0 | AW19: =I19-V19-AK19 -> 0 | AX19: =P19-AE19-AT19 -> 0
I20: =SUM(D20:E20)-G20 -> 0 | M20: =D20+J20 -> 0 | N20: =E20+K20 -> 0 | O20: =G20+L20 -> 0 | P20: =M20+N20-O20 -> 0 | V20: =SUM(Q20:S20)-SUM(T20:U20) -> 0 | AB20: =Q20+W20 -> 0 | AC20: =R20+X20+S20+Y20 -> 0 | AD20: =T20+Z20+U20+AA20 -> 0 | AE20: =AB20+AC20-AD20 -> 0 | AK20: =SUM(AF20:AH20)-SUM(AI20:AJ20) -> 0 | AQ20: =AF20+AL20 -> 0 | AR20: =AG20+AM20+AH20+AN20 -> 0 | AS20: =AI20+AO20+AJ20+AP20 -> 0 | AT20: =AQ20+AR20-AS20 -> 0 | AU20: =D20-Q20-AF20 -> 0 | AV20: =M20-AB20-AQ20 -> 0 | AW20: =I20-V20-AK20 -> 0 | AX20: =P20-AE20-AT20 -> 0
I21: =SUM(D21:E21)-G21 -> 0 | M21: =D21+J21 -> 0 | N21: =E21+K21 -> 0 | O21: =G21+L21 -> 0 | P21: =M21+N21-O21 -> 0 | V21: =SUM(Q21:S21)-SUM(T21:U21) -> 0 | AB21: =Q21+W21 -> 0 | AC21: =R21+X21+S21+Y21 -> 0 | AD21: =T21+Z21+U21+AA21 -> 0 | AE21: =AB21+AC21-AD21 -> 0 | AK21: =SUM(AF21:AH21)-SUM(AI21:AJ21) -> 0 | AQ21: =AF21+AL21 -> 0 | AR21: =AG21+AM21+AH21+AN21 -> 0 | AS21: =AI21+AO21+AJ21+AP21 -> 0 | AT21: =AQ21+AR21-AS21 -> 0 | AU21: =D21-Q21-AF21 -> 0 | AV21: =M21-AB21-AQ21 -> 0 | AW21: =I21-V21-AK21 -> 0 | AX21: =P21-AE21-AT21 -> 0
I22: =SUM(D22:E22)-G22 -> 0 | M22: =D22+J22 -> 0 | N22: =E22+K22 -> 0 | O22: =G22+L22 -> 0 | P22: =M22+N22-O22 -> 0 | V22: =SUM(Q22:S22)-SUM(T22:U22) -> 0 | AB22: =Q22+W22 -> 0 | AC22: =R22+X22+S22+Y22 -> 0 | AD22: =T22+Z22+U22+AA22 -> 0 | AE22: =AB22+AC22-AD22 -> 0 | AK22: =SUM(AF22:AH22)-SUM(AI22:AJ22) -> 0 | AQ22: =AF22+AL22 -> 0 | AR22: =AG22+AM22+AH22+AN22 -> 0 | AS22: =AI22+AO22+AJ22+AP22 -> 0 | AT22: =AQ22+AR22-AS22 -> 0 | AU22: =D22-Q22-AF22 -> 0 | AV22: =M22-AB22-AQ22 -> 0 | AW22: =I22-V22-AK22 -> 0 | AX22: =P22-AE22-AT22 -> 0
I23: =SUM(D23:E23)-G23 -> 0 | M23: =D23+J23 -> 0 | N23: =E23+K23 -> 0 | O23: =G23+L23 -> 0 | P23: =M23+N23-O23 -> 0 | V23: =SUM(Q23:S23)-SUM(T23:U23) -> 0 | AB23: =Q23+W23 -> 0 | AC23: =R23+X23+S23+Y23 -> 0 | AD23: =T23+Z23+U23+AA23 -> 0 | AE23: =AB23+AC23-AD23 -> 0 | AK23: =SUM(AF23:AH23)-SUM(AI23:AJ23) -> 0 | AQ23: =AF23+AL23 -> 0 | AR23: =AG23+AM23+AH23+AN23 -> 0 | AS23: =AI23+AO23+AJ23+AP23 -> 0 | AT23: =AQ23+AR23-AS23 -> 0 | AU23: =D23-Q23-AF23 -> 0 | AV23: =M23-AB23-AQ23 -> 0 | AW23: =I23-V23-AK23 -> 0 | AX23: =P23-AE23-AT23 -> 0
I24: =SUM(D24:E24)-G24 -> 0 | M24: =D24+J24 -> 0 | N24: =E24+K24 -> 0 | O24: =G24+L24 -> 0 | P24: =M24+N24-O24 -> 0 | V24: =SUM(Q24:S24)-SUM(T24:U24) -> 0 | AB24: =Q24+W24 -> 0 | AC24: =R24+X24+S24+Y24 -> 0 | AD24: =T24+Z24+U24+AA24 -> 0 | AE24: =AB24+AC24-AD24 -> 0 | AK24: =SUM(AF24:AH24)-SUM(AI24:AJ24) -> 0 | AQ24: =AF24+AL24 -> 0 | AR24: =AG24+AM24+AH24+AN24 -> 0 | AS24: =AI24+AO24+AJ24+AP24 -> 0 | AT24: =AQ24+AR24-AS24 -> 0 | AU24: =D24-Q24-AF24 -> 0 | AV24: =M24-AB24-AQ24 -> 0 | AW24: =I24-V24-AK24 -> 0 | AX24: =P24-AE24-AT24 -> 0
... I32: =SUM(D32:E32)-G32 -> 0 | M32: =D32+J32 -> 0 | N32: =E32+K32 -> 0 | O32: =G32+L32 -> 0 | P32: =M32+N32-O32 -> 0 | V32: =SUM(Q32:S32)-SUM(T32:U32) -> 0 | AB32: =Q32+W32 -> 0 | AC32: =R32+X32+S32+Y32 -> 0 | AD32: =T32+Z32+U32+AA32 -> 0 | AE32: =AB32+AC32-AD32 -> 0 | AK32: =SUM(AF32:AH32)-SUM(AI32:AJ32) -> 0 | AQ32: =AF32+AL32 -> 0 | AR32: =AG32+AM32+AH32+AN32 -> 0 | AS32: =AI32+AO32+AJ32+AP32 -> 0 | AT32: =AQ32+AR32-AS32 -> 0 | AU32: =D32-Q32-AF32 -> 0 | AV32: =M32-AB32-AQ32 -> 0 | AW32: =I32-V32-AK32 -> 0 | AX32: =P32-AE32-AT32 -> 0
A33: 合计 | D33: =SUM(D13:D32) -> 0 | E33: =SUM(E13:E32) -> 0 | G33: =SUM(G13:G32) -> 0 | I33: =SUM(I13:I32) -> 0 | J33: =SUM(J13:J32) -> 0 | K33: =SUM(K13:K32) -> 0 | L33: =SUM(L13:L32) -> 0 | M33: =SUM(M13:M32) -> 0 | N33: =SUM(N13:N32) -> 0 | O33: =SUM(O13:O32) -> 0 | P33: =SUM(P13:P32) -> 0 | ... AX33: =SUM(AX13:AX32) -> 0
A34: 其中：
A35: =底稿目录!A9 -> 房屋及建筑物 | D35: =SUMPRODUCT(($A$13:$A$32=$A35)*(D$13:D$32)) -> 0 | E35: =SUMPRODUCT(($A$13:$A$32=$A35)*(E$13:E$32)) -> 0 | G35: =SUMPRODUCT(($A$13:$A$32=$A35)*(G$13:G$32)) -> 0 | I35: =SUMPRODUCT(($A$13:$A$32=$A35)*(I$13:I$32)) -> 0 | J35: =SUMPRODUCT(($A$13:$A$32=$A35)*(J$13:J$32)) -> 0 | K35: =SUMPRODUCT(($A$13:$A$32=$A35)*(K$13:K$32)) -> 0 | L35: =SUMPRODUCT(($A$13:$A$32=$A35)*(L$13:L$32)) -> 0 | M35: =SUMPRODUCT(($A$13:$A$32=$A35)*(M$13:M$32)) -> 0 | N35: =SUMPRODUCT(($A$13:$A$32=$A35)*(N$13:N$32)) -> 0 | O35: =SUMPRODUCT(($A$13:$A$32=$A35)*(O$13:O$32)) -> 0 | P35: =SUMPRODUCT(($A$13:$A$32=$A35)*(P$13:P$32)) -> 0 | ... AX35: =SUMPRODUCT(($A$13:$A$32=$A35)*(AX$13:AX$32)) -> 0
A36: =底稿目录!A10 -> 机器设备 | D36: =SUMPRODUCT(($A$13:$A$32=$A36)*(D$13:D$32)) -> 0 | E36: =SUMPRODUCT(($A$13:$A$32=$A36)*(E$13:E$32)) -> 0 | G36: =SUMPRODUCT(($A$13:$A$32=$A36)*(G$13:G$32)) -> 0 | I36: =SUMPRODUCT(($A$13:$A$32=$A36)*(I$13:I$32)) -> 0 | J36: =SUMPRODUCT(($A$13:$A$32=$A36)*(J$13:J$32)) -> 0 | K36: =SUMPRODUCT(($A$13:$A$32=$A36)*(K$13:K$32)) -> 0 | L36: =SUMPRODUCT(($A$13:$A$32=$A36)*(L$13:L$32)) -> 0 | M36: =SUMPRODUCT(($A$13:$A$32=$A36)*(M$13:M$32)) -> 0 | N36: =SUMPRODUCT(($A$13:$A$32=$A36)*(N$13:N$32)) -> 0 | O36: =SUMPRODUCT(($A$13:$A$32=$A36)*(O$13:O$32)) -> 0 | P36: =SUMPRODUCT(($A$13:$A$32=$A36)*(P$13:P$32)) -> 0 | ... AX36: =SUMPRODUCT(($A$13:$A$32=$A36)*(AX$13:AX$32)) -> 0
A37: =底稿目录!A11 -> 运输设备 | D37: =SUMPRODUCT(($A$13:$A$32=$A37)*(D$13:D$32)) -> 0 | E37: =SUMPRODUCT(($A$13:$A$32=$A37)*(E$13:E$32)) -> 0 | G37: =SUMPRODUCT(($A$13:$A$32=$A37)*(G$13:G$32)) -> 0 | I37: =SUMPRODUCT(($A$13:$A$32=$A37)*(I$13:I$32)) -> 0 | J37: =SUMPRODUCT(($A$13:$A$32=$A37)*(J$13:J$32)) -> 0 | K37: =SUMPRODUCT(($A$13:$A$32=$A37)*(K$13:K$32)) -> 0 | L37: =SUMPRODUCT(($A$13:$A$32=$A37)*(L$13:L$32)) -> 0 | M37: =SUMPRODUCT(($A$13:$A$32=$A37)*(M$13:M$32)) -> 0 | N37: =SUMPRODUCT(($A$13:$A$32=$A37)*(N$13:N$32)) -> 0 | O37: =SUMPRODUCT(($A$13:$A$32=$A37)*(O$13:O$32)) -> 0 | P37: =SUMPRODUCT(($A$13:$A$32=$A37)*(P$13:P$32)) -> 0 | ... AX37: =SUMPRODUCT(($A$13:$A$32=$A37)*(AX$13:AX$32)) -> 0
A38: =底稿目录!A12 -> 办公设备 | D38: =SUMPRODUCT(($A$13:$A$32=$A38)*(D$13:D$32)) -> 0 | E38: =SUMPRODUCT(($A$13:$A$32=$A38)*(E$13:E$32)) -> 0 | G38: =SUMPRODUCT(($A$13:$A$32=$A38)*(G$13:G$32)) -> 0 | I38: =SUMPRODUCT(($A$13:$A$32=$A38)*(I$13:I$32)) -> 0 | J38: =SUMPRODUCT(($A$13:$A$32=$A38)*(J$13:J$32)) -> 0 | K38: =SUMPRODUCT(($A$13:$A$32=$A38)*(K$13:K$32)) -> 0 | L38: =SUMPRODUCT(($A$13:$A$32=$A38)*(L$13:L$32)) -> 0 | M38: =SUMPRODUCT(($A$13:$A$32=$A38)*(M$13:M$32)) -> 0 | N38: =SUMPRODUCT(($A$13:$A$32=$A38)*(N$13:N$32)) -> 0 | O38: =SUMPRODUCT(($A$13:$A$32=$A38)*(O$13:O$32)) -> 0 | P38: =SUMPRODUCT(($A$13:$A$32=$A38)*(P$13:P$32)) -> 0 | ... AX38: =SUMPRODUCT(($A$13:$A$32=$A38)*(AX$13:AX$32)) -> 0
A39: =底稿目录!A13 -> 其他设备 | D39: =SUMPRODUCT(($A$13:$A$32=$A39)*(D$13:D$32)) -> 0 | E39: =SUMPRODUCT(($A$13:$A$32=$A39)*(E$13:E$32)) -> 0 | G39: =SUMPRODUCT(($A$13:$A$32=$A39)*(G$13:G$32)) -> 0 | I39: =SUMPRODUCT(($A$13:$A$32=$A39)*(I$13:I$32)) -> 0 | J39: =SUMPRODUCT(($A$13:$A$32=$A39)*(J$13:J$32)) -> 0 | K39: =SUMPRODUCT(($A$13:$A$32=$A39)*(K$13:K$32)) -> 0 | L39: =SUMPRODUCT(($A$13:$A$32=$A39)*(L$13:L$32)) -> 0 | M39: =SUMPRODUCT(($A$13:$A$32=$A39)*(M$13:M$32)) -> 0 | N39: =SUMPRODUCT(($A$13:$A$32=$A39)*(N$13:N$32)) -> 0 | O39: =SUMPRODUCT(($A$13:$A$32=$A39)*(O$13:O$32)) -> 0 | P39: =SUMPRODUCT(($A$13:$A$32=$A39)*(P$13:P$32)) -> 0 | ... AX39: =SUMPRODUCT(($A$13:$A$32=$A39)*(AX$13:AX$32)) -> 0
A40: 三、审计说明：
A43: 四、审计结论
A46: 提示：
A47: 1.本科目核算企业持有的固定资产原价。建造承包商的临时设施，以及企业购置计算机硬件所附带的、未单独计价的软件，也通过本科目核算。
A48: 2.审计说明可以概述：（1）程序的测试情况、结果；（2）拟调整事项及其调整分录、未调整事项及其影响，审计范围受到限制情况及其影响。
A49: 3.审计结论可参考：A、未见异常。 B、除上述重大不符事项应当作为调整事项予以调整外，其余未见异常。 C、由于存在以下重大未调整事项（或审计范围受到限制无法获取充分、适当证据），不可确认。

Sheet 调整分录汇总H1-3
A1: 致同会计师事务所
A2: 固定资产调整分录汇总表
A3: =底稿目录!A2 -> 被审计单位： | D3: =底稿目录!A4 -> 编制人： | G3: =底稿目录!A5 -> 编制日期： | I3: 索引号： | J3: H1-3
A4: =底稿目录!A3 -> 截止日：202X年12月31日 | D4: =底稿目录!A6 -> 复核人： | G4: =底稿目录!A7 -> 复核日期： | I4: 页 次：
A5: 调整事项说明 | B5: 类别（报表调整/账项调整/其他） | C5: 报表项目 | D5: 科目名称 | E5: 附注项目 | F5: …… | G5: 借方调整金额 | H5: 贷方调整金额 | I5: 索引 | J5: 备注
A24: 提示：本底稿适用于调整分录较多、较复杂的项目，且仅列示与本报表项目相关的审计调整。项目组可根据项目实际情况选择是否使用该底稿。

Sheet 闲置检查表H1-4
A1: 致同会计师事务所
A2: 闲置固定资产检查表
A3: =底稿目录!A2 -> 被审计单位： | E3: =底稿目录!A4 -> 编制人： | G3: =底稿目录!A5 -> 编制日期： | I3: 索引号： | J3: H1-4
A4: =底稿目录!A3 -> 截止日：202X年12月31日 | E4: =底稿目录!A6 -> 复核人： | G4: =底稿目录!A7 -> 复核日期： | I4: 页 次：
A5: 一、审计目标：
A6: 1.资产负债表中记录的固定资产是存在的，且已记录于恰当的账户；
A7: 2.固定资产以恰当的金额包括在财务报表中，与之相关的计价或分摊调整已恰当记录，相关披露已得到恰当计量和描述。
A8: 二、审计过程：
A9: 1.获取暂时闲置固定资产的相关证明文件，并观察其实际状况，是否已按规定计提折旧，相关的会计处理是否正确。
A10: 2.考虑暂时闲置固定资产是否存在减值迹象，……
A11: ①未使用固定资产：
A12: 序号 | B12: 固定资产类别 | C12: 固定资产名称 | D12: 固定资产原值 | E12: 累计折旧 | F12: 减值准备 | G12: 固定资产净值 | H12: 起止时间 | I12: 状况 | J12: 备注
A13: 1 | G13: =D13-E13-F13 -> 0
A14: 2 | G14: =D14-E14-F14 -> 0
A15: 3 | G15: =D15-E15-F15 -> 0
A16: … | G16: =D16-E16-F16 -> 0
A17: 合计 | D17: =SUM(D13:D16) -> 0 | E17: =SUM(E13:E16) -> 0 | F17: =SUM(F13:F16) -> 0 | G17: =SUM(G13:G16) -> 0
A18: ②不需用固定资产：
A19: 序号 | B19: 固定资产类别 | C19: 固定资产名称 | D19: 固定资产原值 | E19: 累计折旧 | F19: 减值准备 | G19: 固定资产净值 | H19: 起止时间 | I19: 状况 | J19: 备注
A20: 1 | G20: =D20-E20-F20 -> 0
A21: 2 | G21: =D21-E21-F21 -> 0
A22: 3 | G22: =D22-E22-F22 -> 0
A23: … | G23: =D23-E23-F23 -> 0
A24: 合计 | D24: =SUM(D20:D23) -> 0 | E24: =SUM(E20:E23) -> 0 | F24: =SUM(F20:F23) -> 0 | G24: =SUM(G20:G23) -> 0
A25: 三、审计说明：
A27: 四、审计结论：
A31: 提示：在停工停产期间应继续计提固定资产折旧和无形资产摊销，并根据用途计入相关资产的成本或当期损益。例如，企业因需求不足而停产或因事故而停工检修等，相关生产设备应当继续计提折旧，并计入营业成本。

Sheet 会计政策估计检查表H1-5
A1: 致同会计师事务所
A2: 固定资产相关会计政策/估计检查表
A3: =底稿目录!A2 -> 被审计单位： | E3: =底稿目录!A4 -> 编制人： | H3: =底稿目录!A5 -> 编制日期： | J3: 索引号： | K3: H1-5
A4: =底稿目录!A3 -> 截止日：202X年12月31日 | E4: =底稿目录!A6 -> 复核人： | H4: =底稿目录!A7 -> 复核日期： | J4: 页 次：
A5: 一、审计目标：
A6: 1.资产负债表中记录的固定资产是存在的，且已记录于恰当的账户；2.所有应记录的固定资产均已记录，所有应当包括在财务报表中的相关披露均已包括；
A7: 3.固定资产以恰当的金额包括在财务报表中，与之相关的计价或分摊调整已恰当记录，相关披露已得到恰当计量和描述
A8: 二、审计过程：
A9: 被审计单位的固定资产折旧政策：
A10: 序号 | B10: 类别 | C10: 折旧年限 | D10: 折旧方法 | E10: 残值率 | F10: 是否符合实际经营情况和会计准则的要求 | G10: 是否与相关资产所包含的经济利益预期实现方式相一致 | H10: 与同行业公司相比，会计政策是否合理 | I10: 是否存在会计政策/会计估计变更 | J10: 会计政策/会计估计变更是否合理 | K10: 备注
A11: 1 | B11: 房屋及建筑物
A12: 2 | B12: 机器设备
A13: 3 | B13: 运输设备
A14: 4 | B14: 办公设备
A15: 5 | B15: 其他设备
A16: 同行业其他公司的固定资产折旧政策
A17: 序号 | B17: 类别 | C17: 同行业公司1 | F17: 同行业公司2 | I17: 同行业公司3
C18: 折旧年限 | D18: 折旧方法 | E18: 残值率 | F18: 折旧年限 | G18: 折旧方法 | H18: 残值率 | I18: 折旧年限 | J18: 折旧方法 | K18: 残值率
A19: 1 | B19: 房屋及建筑物
A20: 2 | B20: 机器设备
A21: 3 | B21: 运输设备
A22: 4 | B22: 办公设备
A23: 5 | B23: 其他设备
B24: 如本期存在会计估计变更，原会计估计如下：
A25: 序号 | B25: 类别 | C25: 使用寿命 | D25: 摊销方法 | E25: 残值率
A26: 1 | B26: 房屋及建筑物
A27: 2 | B27: 机器设备
A28: 3 | B28: 运输设备
A29: 4 | B29: 办公设备
A30: 5 | B30: 其他设备
A31: 三、审计说明：
A34: 四、审计结论：

Sheet 分析表H1-6
A1: 致同会计师事务所
A2: 固定资产分析表
A3: =底稿目录!A2 -> 被审计单位： | C3: =底稿目录!A4 -> 编制人： | D3: =底稿目录!A5 -> 编制日期： | E3: 索引号： | F3: H1-6
A4: =底稿目录!A3 -> 截止日：202X年12月31日 | C4: =底稿目录!A6 -> 复核人： | D4: =底稿目录!A7 -> 复核日期： | E4: 页 次：
A5: 一、审计目标：
A6: 1.资产负债表中记录的固定资产是存在的，且已记录于恰当的账户；
A7: 2.所有应记录的固定资产均已记录，所有应当包括在财务报表中的相关披露均已包括；
A8: 3.固定资产以恰当的金额包括在财务报表中，与之相关的计价或分摊调整已恰当记录，相关披露已得到恰当计量和描述 。
A9: 二、审计过程：
A10: 序号 | B10: 比例 | C10: 2025年 | D10: 2024年 | E10: 变动 | F10: 变动原因及合理性解释
A11: 1 | B11: 固定资产净值÷资产总额 | E11: =C11-D11 -> 0
A12: 2 | B12: 本期计提折旧额÷固定资产原值 | E12: =C12-D12 -> 0
A13: 3 | B13: 累计计提折旧额÷固定资产原值 | E13: =C13-D13 -> 0
A14: 4 | B14: 固定资产减值准备余额÷固定资产原值 | E14: =C14-D14 -> 0
A15: 5 | B15: 固定资产原值÷本期产品产量 | E15: =C15-D15 -> 0
A16: 6 | B16: 租赁资产原值÷固定资产原值 | E16: =C16-D16 -> 0
A17: 7 | B17: 出租租金收入÷固定资产原值 | E17: =C17-D17 -> 0
A18: 8 | B18: 维修费用÷固定资产原值 | E18: =C18-D18 -> 0
A19: 9 | B19: …… | E19: =C19-D19 -> 0
A20: 三、审计说明：
A24: 四、审计结论：
A27: 提示：
A28: 1、分析固定资产的构成及其增减变动情况、增减变动原因，与在建工程、现金流量表、生产能力等相关信息交叉复核，检查固定资产相关金额的合理性和准确性；
A29: 2、分析本期末固定资产减值准备数额占期末固定资产原价的比率，并与期初数比较。

Sheet 增加检查表H1-7
A1: 致同会计师事务所
A2: 固定资产增加检查表
A3: =底稿目录!A2 -> 被审计单位： | F3: =底稿目录!A4 -> 编制人： | N3: =底稿目录!A5 -> 编制日期： | V3: 索引号： | W3: H1-7
A4: =底稿目录!A3 -> 截止日：202X年12月31日 | F4: =底稿目录!A6 -> 复核人： | N4: =底稿目录!A7 -> 复核日期： | V4: 页 次：
A5: 一、审计目标：
A6: 1.资产负债表中记录的固定资产是存在的，且已记录于恰当的账户；2.所有应记录的固定资产均已记录，所有应当包括在财务报表中的相关披露均已包括；
A7: 3.记录的固定资产由被审计单位拥有或控制；4.固定资产以恰当的金额包括在财务报表中，与之相关的计价或分摊调整已恰当记录，相关披露已得到恰当计量和描述。
A8: 二、样本选取标准与规模：
A9: 测试总体： | C9: 如固定资产借方发生额所有凭证共XX笔金额XX | I9: 特定样本： | J9: XX金额以上（大额）、关联方/关联交易形成的款项、XX异常款项全部测试，共XX笔；
A10: 抽样总体： | C10: 测试总体扣除特定样本以外的样本，共XX笔、金额XX | I10: 确定的抽样样本量： | K10: 抽取XX笔 | L10: （如果使用了样本计算器计算样本量，样本量计算过程见<XX>底稿）
A11: 抽样方法： | C11: 随机选样/系统选样/货币单元抽样/随意选样（非统计抽样适用） | I11: 抽样过程： | J11: 使用IDEA（XX抽样工具）选择XX数量、金额XX的样本进行测试，抽样工具中的样本选择过程和结果见<XX>底稿
A12: 三、测试过程：
A13: 测试内容说明：1.原始凭证是否齐全； 2.记账凭证与原始凭证是否相符；3.账务处理是否正确；4.是否记录于恰当的会计期间；5.……
A14: 序号 | B14: 固定资产类别 | C14: 固定资产编号 | D14: 固定资产名称 | E14: 增加日期 | F14: 增加方式 | G14: 入账凭证号 | H14: 对方科目 | I14: 增加情况 | M14: 验收单 | O14: 合同/协议/订单 | R14: 采购发票 | U14: …… | V14: 索引号 | W14: 是否异常 | X14: 检查的关键证据和要素根据被审计单位具体情况修改
I15: 原值 | J15: 累计折旧 | K15: 减值准备 | L15: 净值 | M15: 单据编号 | N15: 验收日期 | O15: 日期/编号 | P15: 对手方名称 | Q15: 金额 | R15: 日期/编号 | S15: 对手方名称 | T15: 金额
A16: 1 | L16: =I16-J16-K16 -> 0
A17: 2 | L17: =I17-J17-K17 -> 0
A18: 3 | L18: =I18-J18-K18 -> 0
A19: 4 | L19: =I19-J19-K19 -> 0
A20: 5 | L20: =I20-J20-K20 -> 0
A21: 6 | L21: =I21-J21-K21 -> 0
A22: 7 | L22: =I22-J22-K22 -> 0
A23: 8 | L23: =I23-J23-K23 -> 0
A24: 9 | L24: =I24-J24-K24 -> 0
A25: 10 | L25: =I25-J25-K25 -> 0
A26: 11 | L26: =I26-J26-K26 -> 0
A27: 12 | L27: =I27-J27-K27 -> 0
... A30: 15 | L30: =I30-J30-K30 -> 0
A31: …… | L31: =I31-J31-K31 -> 0
A32: 合计 | I32: =SUM(I16:I31) -> 0 | J32: =SUM(J16:J31) -> 0 | K32: =SUM(K16:K31) -> 0 | L32: =SUM(L16:L31) -> 0 | Q32: =SUM(Q16:Q31) -> 0 | T32: =SUM(T16:T31) -> 0
A33: 本期新增固定资产合计 | I33: ='明细表H1-2'!N33 -> 0
A34: 检查比例 | I34: =IF(I32=0,0,I32/$I$33) -> 0
A35: 四、审计说明：
A36: 1.如果检查比例较低应扩大检查样本量或说明原因
A37: 2.……
A39: 五、审计结论：
A42: 提示：
A43: 1、本表用于汇总本年度增加固定资产的测试情况。
A44: 2、对于外购固定资产，检查购货合同、发票、保险单、发运凭证等文件，抽查测试其计价是否正确，会计处理是否正确；如果购买固定资产的价款超过正常信用条件延期支付，
A45: 检查实质上是否具有融资性质，固定资产的成本是否以购买价款的现值为基础确定。
...

Sheet 减少检查表H1-8
A1: 致同会计师事务所
A2: 固定资产减少检查表
A3: =底稿目录!A2 -> 被审计单位： | F3: =底稿目录!A4 -> 编制人： | O3: =底稿目录!A5 -> 编制日期： | Y3: 索引号： | Z3: H1-8
A4: =底稿目录!A3 -> 截止日：202X年12月31日 | F4: =底稿目录!A6 -> 复核人： | O4: =底稿目录!A7 -> 复核日期： | Y4: 页 次：
A5: 一、审计目标：
A6: 1.资产负债表中记录的固定资产是存在的，且已记录于恰当的账户；2.所有应记录的固定资产均已记录，所有应当包括在财务报表中的相关披露均已包括；
A7: 3.固定资产以恰当的金额包括在财务报表中，与之相关的计价或分摊调整已恰当记录，相关披露已得到恰当计量和描述。
A8: 二、测试： | C8: 测试原因：大额（）关联方（）大额交易频繁（）异常（）其他（）
A9: 测试内容说明：1.原始凭证是否齐全； 2.记账凭证与原始凭证是否相符；3.账务处理是否正确；4.是否记录于恰当的会计期间；5.……
A10: 序号 | B10: 固定资产类别 | C10: 固定资产编号 | D10: 固定资产名称 | E10: 减少方式 | F10: 减少日期 | G10: 凭证号 | H10: 对方科目 | I10: 减少情况 | P10: 审批单 | R10: 合同/协议/订单 | U10: 发票 | X10: …… | Y10: 索引号 | Z10: 是否异常
I11: 转入清理的固定资产 | M11: 清理净收入 | O11: 清理净损益 | P11: 日期/编号 | Q11: 是否经过恰当审批 | R11: 日期/编号 | S11: 对手方名称 | T11: 金额 | U11: 日期/编号 | V11: 对手方名称 | W11: 金额 | AA11: 检查的关键证据和要素根据被审计单位具体情况修改
I12: 原值 | J12: 累计折旧 | K12: 减值准备 | L12: 净值 | M12: 清理费用 | N12: 清理收入
A13: 1 | L13: =I13-J13-K13 -> 0 | O13: =N13-M13-L13 -> 0
A14: 2 | L14: =I14-J14-K14 -> 0 | O14: =N14-M14-L14 -> 0
A15: 3 | L15: =I15-J15-K15 -> 0 | O15: =N15-M15-L15 -> 0
A16: 4 | L16: =I16-J16-K16 -> 0 | O16: =N16-M16-L16 -> 0
A17: 5 | L17: =I17-J17-K17 -> 0 | O17: =N17-M17-L17 -> 0
A18: 6 | L18: =I18-J18-K18 -> 0 | O18: =N18-M18-L18 -> 0
A19: 7 | L19: =I19-J19-K19 -> 0 | O19: =N19-M19-L19 -> 0
A20: 8 | L20: =I20-J20-K20 -> 0 | O20: =N20-M20-L20 -> 0
A21: 9 | L21: =I21-J21-K21 -> 0 | O21: =N21-M21-L21 -> 0
A22: 10 | L22: =I22-J22-K22 -> 0 | O22: =N22-M22-L22 -> 0
A23: 11 | L23: =I23-J23-K23 -> 0 | O23: =N23-M23-L23 -> 0
A24: 12 | L24: =I24-J24-K24 -> 0 | O24: =N24-M24-L24 -> 0
... A26: 14 | L26: =I26-J26-K26 -> 0 | O26: =N26-M26-L26 -> 0
A27: …… | L27: =I27-J27-K27 -> 0 | O27: =N27-M27-L27 -> 0
A28: 合计 | I28: =SUM(I13:I27) -> 0 | J28: =SUM(J13:J27) -> 0 | K28: =SUM(K13:K27) -> 0 | L28: =SUM(L13:L27) -> 0 | M28: =SUM(M13:M27) -> 0 | N28: =SUM(N13:N27) -> 0 | O28: =SUM(O13:O27) -> 0
A29: 本期减少固定资产合计 | I29: ='明细表H1-2'!O33 -> 0
A30: 检查比例 | I30: =IF(I28=0,0,I28/$I$29) -> 0
A31: 三、审计说明：
A32: 1.如果检查比例较低应扩大检查样本量或说明原因
A33: 2.……
A36: 四、审计结论：
A40: 提示：
A41: 1、本表用于汇总本年度减少固定资产的测试情况。
A42: 2、检查当年减少的固定资产的销账情况，减少的固定资产产生的损益是否及时记入营业外收支科目，账务处理是否与减少固定资产的授权批准文件一致。

Sheet 监盘计划H1-9
A1: 致同会计师事务所
A2: 固定资产监盘计划
A3: =底稿目录!A2 -> 被审计单位： | D3: =底稿目录!A4 -> 编制人： | F3: =底稿目录!A5 -> 编制日期： | H3: 索引号： | I3: H1-9
A4: =底稿目录!A3 -> 截止日：202X年12月31日 | D4: =底稿目录!A6 -> 复核人： | F4: =底稿目录!A7 -> 复核日期： | H4: 页 次：
A5: 一、确定的固定资产存在性认定可能存在重大错报的风险程度：
A7: 二、了解被审计单位固定资产期末状况与管理规定：
A8: （一）固定资产的期末状况：
A9: 1．期末资产状况：截至期末，闲置的资产包括……………，对应的金额 …………
A10: 2．资产存放地点：
B11: 类 别 | C11: 仓库（或场所） | D11: 地点 | E11: 说明
A15: （二）企业定期盘点内部控制制度与执行情况：
A16: 1．制度名称：（提示：按企业内部控制制度名称填写） 索引号：（ ）
A17: （1）规定盘点的时间与次数：
A18: （2）负责盘点的部门： | F18: 负责人：
A19: （提示：如制度规定与实际执行不一致的，应按制度规定与实际负责的部门分别填写）
A20: 2．企业实际盘点情况：
A21: （1）盘点计划安排：
A22: （2）盘点会议情况：
A23: （3）预计安排的盘点人员数量： | F23: 负责人：
A24: （4）对企业盘点计划的评价：
A25: （三）查阅以前年度工作底稿记录：
A26: 1．上一年度监盘时间： | F26: 实施监盘的人员：
A27: 2．抽盘的固定资产范围： | F27: 抽盘比例：
A28: 3．实施监盘中发现的问题与存在的不足：
A29: （提示：上年度如是本所实施监盘的，应当查阅上一年度工作底稿；如不是本所实施审计的，应当在与前任会计师实施沟通程序中安排本项沟通内容。）
A30: 三、评估审计人员的专业胜任能力：
A32: 提示：针对特殊类型的存货，应当评估审计人员是否具备专业胜任能力
A33: 四、盘点计划安排：
A34: （一）预计监盘时间：
A35: （二）预计安排监盘人员数量： | F35: 监盘程序负责人：
A36: （三）预计监盘的固定资产范围：
A37: 1.类别范围
A38: 类别 | B38: 期末余额 | C38: 减值准备 | D38: 账面净值 | E38: 计量单位 | F38: 数量 | G38: 计划监盘数量 | H38: 计划监盘金额 | I38: 监盘比例
A42: 合计： | B42: =SUM(B39:B41) -> 0 | C42: =SUM(C39:C41) -> 0 | D42: =SUM(D39:D41) -> 0 | E42: =SUM(E39:E41) -> 0 | F42: =SUM(F39:F41) -> 0 | G42: =SUM(G39:G41) -> 0 | H42: =SUM(H39:H41) -> 0 | I42: =SUM(I39:I41) -> 0
A43: 2．地点范围：
A44: （四）拟实施的盘点方法：
A45: （五）就监盘计划与管理层沟通事项
A46: 1．时间： | E46: 2.管理层人员：
A47: 3．审计小组参与人员：
A48: （六）针对被审计单位具体情况，需要向管理层提出的监盘的特殊要求：
...

Sheet 盘点检查表H1-10
A1: 致同会计师事务所
A2: 固定资产盘点检查表
A3: =底稿目录!A2 -> 被审计单位： | E3: =底稿目录!A4 -> 编制人： | I3: =底稿目录!A5 -> 编制日期： | L3: 索引号： | M3: H1-10
A4: =底稿目录!A3 -> 截止日：202X年12月31日 | E4: =底稿目录!A6 -> 复核人： | I4: =底稿目录!A7 -> 复核日期： | L4: 页 次：
A5: 一、审计目标：
A6: 1.资产负债表中记录的固定资产是存在的，且已记录于恰当的账户；2.记录的固定资产由被审计单位拥有或控制；
A7: 3.固定资产以恰当的金额包括在财务报表中，与之相关的计价或分摊调整已恰当记录，相关披露已得到恰当计量和描述 。
A8: 二、样本选取标准与规模：
A9: 测试总体： | B9: 如期末固定资产数量XX、金额XX | G9: 特定样本： | H9: XX金额以上（大额）、关联方/关联交易形成的款项、XX异常款项全部测试，共XX笔；
A10: 抽样总体： | B10: 测试总体扣除特定样本以外的样本，数量XX、金额XX | G10: 确定的抽样样本量： | H10: 抽取XX笔 | I10: （如果使用了样本计算器计算样本量，样本量计算过程见<XX>底稿）
A11: 抽样方法： | B11: 随机选样/系统选样/货币单元抽样/随意选样（非统计抽样适用） | G11: 抽样过程： | H11: 使用IDEA（XX抽样工具）选择XX数量、金额XX的样本进行测试，抽样工具中的样本选择过程和结果见<XX>底稿
A12: 三、审计过程：
A13: 抽盘地点：______________ | C13: 盘点人员： | D13: 被审计单位仓库盘点人和财务监盘人签字 | I13: 监盘人员： | J13: （审计人员签字） | L13: 盘点时间：__________________
A14: （一）从固定资产盘点记录中选取项目追查至固定资产实物
A15: 固定资产名称/类别 | B15: 资产编号 | C15: 规格 | D15: 单位 | E15: 单价 | F15: 盘点前财务账面记录 | H15: 企业盘点记录数量 | I15: 抽盘数量 | J15: 抽盘与账面差异（+盈-亏） | K15: 抽盘与企业盘点差异 | L15: 企业盘点与账面差异 | M15: 品质状况（正常/闲置/毁损等）
F16: 数量 | G16: 金额
J17: =I17-F17 -> 0 | K17: =I17-H17 -> 0 | L17: =H17-F17 -> 0
J18: =I18-F18 -> 0 | K18: =I18-H18 -> 0 | L18: =H18-F18 -> 0
J19: =I19-F19 -> 0 | K19: =I19-H19 -> 0 | L19: =H19-F19 -> 0
J20: =I20-F20 -> 0 | K20: =I20-H20 -> 0 | L20: =H20-F20 -> 0
J21: =I21-F21 -> 0 | K21: =I21-H21 -> 0 | L21: =H21-F21 -> 0
J22: =I22-F22 -> 0 | K22: =I22-H22 -> 0 | L22: =H22-F22 -> 0
J23: =I23-F23 -> 0 | K23: =I23-H23 -> 0 | L23: =H23-F23 -> 0
J24: =I24-F24 -> 0 | K24: =I24-H24 -> 0 | L24: =H24-F24 -> 0
J25: =I25-F25 -> 0 | K25: =I25-H25 -> 0 | L25: =H25-F25 -> 0
J26: =I26-F26 -> 0 | K26: =I26-H26 -> 0 | L26: =H26-F26 -> 0
A27: 合计 | F27: =SUM(F17:F26) -> 0 | G27: =SUM(G17:G26) -> 0 | H27: =SUM(H17:H26) -> 0 | I27: =SUM(I17:I26) -> 0 | J27: =SUM(J17:J26) -> 0 | K27: =SUM(K17:K26) -> 0 | L27: =SUM(L17:L26) -> 0
A28: 期末固定资产原值合计：
A29: 抽取样本占期末原值合计的比例：（%） | G29: =G27/G28 -> #DIV/0!
A31: （二）从固定资产实物中选取项目追查至固定资产盘点记录
A32: 固定资产名称/类别 | B32: 资产编号 | C32: 规格 | D32: 单位 | E32: 单价 | F32: 盘点前财务账面记录 | H32: 企业盘点记录数量 | I32: 抽盘数量 | J32: 抽盘与账面差异（+盈-亏） | K32: 抽盘与企业盘点差异 | L32: 企业盘点与账面差异 | M32: 品质状况（正常/闲着/毁损等）
F33: 数量 | G33: 金额
J34: =I34-F34 -> 0 | K34: =I34-H34 -> 0 | L34: =H34-F34 -> 0
J35: =I35-F35 -> 0 | K35: =I35-H35 -> 0 | L35: =H35-F35 -> 0
J36: =I36-F36 -> 0 | K36: =I36-H36 -> 0 | L36: =H36-F36 -> 0
J37: =I37-F37 -> 0 | K37: =I37-H37 -> 0 | L37: =H37-F37 -> 0
J38: =I38-F38 -> 0 | K38: =I38-H38 -> 0 | L38: =H38-F38 -> 0
J39: =I39-F39 -> 0 | K39: =I39-H39 -> 0 | L39: =H39-F39 -> 0
J40: =I40-F40 -> 0 | K40: =I40-H40 -> 0 | L40: =H40-F40 -> 0
J41: =I41-F41 -> 0 | K41: =I41-H41 -> 0 | L41: =H41-F41 -> 0
...

Sheet 监盘小结H1-11
A1: 致同会计师事务所
A2: 固定资产监盘小结
A3: =底稿目录!A2 -> 被审计单位： | D3: =底稿目录!A4 -> 编制人： | F3: =底稿目录!A5 -> 编制日期： | H3: 索引号： | I3: H1-11
A4: =底稿目录!A3 -> 截止日：202X年12月31日 | D4: =底稿目录!A6 -> 复核人： | F4: =底稿目录!A7 -> 复核日期： | H4: 页 次：
A5: 一、资产负债表日：
A7: 二、主要资产存放情况（房屋建筑物及主要机器设备）：
A8: 提示：房屋建筑物地点请核对房产证记载的地点，有多处房产的，请逐一说明
A9: 序号 | B9: 资产类别 | C9: 资产名称 | D9: 存放地点
A10: 1
A11: 2
A12: 3
A13: 三、了解资产管理情况
A14: 序号 | B14: 项目
A15: 1 | B15: 资产管理部门：
A16: 2 | B16: 管理人员：
A17: 3 | B17: 资产是否具有管理标识：
A18: 4 | B18: 资产是否具有定期保养制度：
A19: 5 | B19: 大修理周期时间：
A20: 6 | B20: 资产明细账（卡）是否完整：
A21: 7 | B21: 资产明细账（卡）的各项记录是否完整：
A22: 三、参与盘点人员：
A23: 1． 被审计单位的人员：
A24: 序号 | B24: 盘点人员所属部门 | C24: 人员数量 | D24: 人员名称 | E24: 所负责的部分
A25: 1
A26: 2
A27: 3
A28: 2． 审计人员：
A29: 序号 | B29: 人员名称 | C29: 负责的部分
A30: 1
A31: 2
A32: 3
A33: 四、实际盘点前的检查程序：
A34: 1．资产现场观察说明：
A35: 2．盘点前检查程序：
A36: （1）资产明细账（卡） 是否获取： | G36: 索引：
A37: （2）固定资产管理制度 是否获取： | G37: 索引：
A38: （3）固定资产维修制度是否获取： | G38: 索引：
A39: （4）获取或编制资产位置简图： | G39: 索引：
A40: 五、实际盘点时间：
A41: 实际监盘（盘点）日： | E41: 开始时间： | H41: 结束时间：
...

Sheet 折旧测算表（不含减值）-直线法H1-12
A1: 致同会计师事务所
A2: 固定资产折旧测算表
A3: =底稿目录!A2 -> 被审计单位： | G3: =底稿目录!A4 -> 编制人： | M3: =底稿目录!A5 -> 编制日期： | R3: 索引号： | S3: H1-12
A4: =底稿目录!A3 -> 截止日：202X年12月31日 | G4: =底稿目录!A6 -> 复核人： | M4: =底稿目录!A7 -> 复核日期： | R4: 页 次：
A5: 一、审计目标：固定资产以恰当的金额包括在财务报表中，与之相关的计价或分摊调整已恰当记录，相关披露已得到恰当计量和描述。
A6: 二、审计过程：
A7: 折旧期初： | C7: 折旧期末： | E7: 各列顺序请根据需要进行调整，行数请根据需要增加。非公式列输入数据时请使用“选择性粘贴-数值”。
A8: 固定资产类别 | B8: 固定资产编号 | C8: 固定资产名称 | D8: 管理部门 | E8: 原值 （期末） | F8: 累计折旧（期末） | G8: 开始使用日期 | H8: 使用年限 | I8: 残值率 | J8: 账面月折旧额 | K8: 使用月限 | L8: 测算到期日 | M8: 已提折旧月份 | N8: 本期折旧月份 | O8: 测算月折旧 | P8: 当期折旧费用 | Q8: 月折旧额差异 | R8: 累计折旧费用 | S8: 累计折旧额差异
A9: ='明细表H1-2'!A13 -> 0 | B9: ='明细表H1-2'!B13 -> 0 | C9: ='明细表H1-2'!C13 -> 0 | E9: ='明细表H1-2'!P13 -> 0 | F9: ='明细表H1-2'!AE13 -> 0 | K9: =IF(H9=0,0,IF(RIGHT(H9,1)<>"年",H9*12,IF(LEN(H9)=3,VALUE(LEFT(H9,2))*12,IF(LEN(H9)=2,VALUE(LEFT(H9,1))*12,"??")))) -> 0 | L9: =DATE((YEAR(G9)+H9),MONTH(G9),DAY(G9)) -> 0 | M9: =MIN((YEAR(L9)-YEAR(G9))*12+(MONTH(L9)-MONTH(G9)),(YEAR($D$7)-YEAR(G9))*12+MONTH($D$7)-MONTH(G9),H9*12) -> 0 | N9: =IF(YEAR(L9)=YEAR($D$7),12-(MONTH($D$7)-MONTH(L9)),(IF(L9<$B$7,0,IF($D$7>L9,MIN(MONTH($D$7),DATEDIF(DATE(YEAR(G9),MONTH(G9),"1"),$D$7,"M")-DATEDIF(DATE(YEAR(G9),MONTH(G9),"1"),DATEDIF(YEAR(L9),MONTH(L9),"1"),"M")),MIN(DATEDIF(DATE(YEAR(G9),MONTH(G9),"1"),$D$7,"m"),MONTH($D$7)))))) -> 12 | O9: =IF(K9=0,0,ROUND(((1-I9)/K9)*E9,4)) -> 0 | P9: =ROUND(O9*N9,2) -> 0 | Q9: =ROUND(J9-O9,2) -> 0 | R9: =ROUND(O9*M9,2) -> 0 | S9: =ROUND(F9-R9,2) -> 0
A10: ='明细表H1-2'!A14 -> 0 | B10: ='明细表H1-2'!B14 -> 0 | C10: ='明细表H1-2'!C14 -> 0 | E10: ='明细表H1-2'!P14 -> 0 | F10: ='明细表H1-2'!AE14 -> 0 | K10: =IF(H10=0,0,IF(RIGHT(H10,1)<>"年",H10*12,IF(LEN(H10)=3,VALUE(LEFT(H10,2))*12,IF(LEN(H10)=2,VALUE(LEFT(H10,1))*12,"??")))) -> 0 | L10: =DATE((YEAR(G10)+H10),MONTH(G10),DAY(G10)) -> 0 | M10: =MIN((YEAR(L10)-YEAR(G10))*12+(MONTH(L10)-MONTH(G10)),(YEAR($D$7)-YEAR(G10))*12+MONTH($D$7)-MONTH(G10),H10*12) -> 0 | N10: =IF(YEAR(L10)=YEAR($D$7),12-(MONTH($D$7)-MONTH(L10)),(IF(L10<$B$7,0,IF($D$7>L10,MIN(MONTH($D$7),DATEDIF(DATE(YEAR(G10),MONTH(G10),"1"),$D$7,"M")-DATEDIF(DATE(YEAR(G10),MONTH(G10),"1"),DATEDIF(YEAR(L10),MONTH(L10),"1"),"M")),MIN(DATEDIF(DATE(YEAR(G10),MONTH(G10),"1"),$D$7,"m"),MONTH($D$7)))))) -> 12 | O10: =IF(K10=0,0,ROUND(((1-I10)/K10)*E10,4)) -> 0 | P10: =ROUND(O10*N10,2) -> 0 | Q10: =ROUND(J10-O10,2) -> 0 | R10: =ROUND(O10*M10,2) -> 0 | S10: =ROUND(F10-R10,2) -> 0
A11: ='明细表H1-2'!A15 -> 0 | B11: ='明细表H1-2'!B15 -> 0 | C11: ='明细表H1-2'!C15 -> 0 | E11: ='明细表H1-2'!P15 -> 0 | F11: ='明细表H1-2'!AE15 -> 0 | K11: =IF(H11=0,0,IF(RIGHT(H11,1)<>"年",H11*12,IF(LEN(H11)=3,VALUE(LEFT(H11,2))*12,IF(LEN(H11)=2,VALUE(LEFT(H11,1))*12,"??")))) -> 0 | L11: =DATE((YEAR(G11)+H11),MONTH(G11),DAY(G11)) -> 0 | M11: =MIN((YEAR(L11)-YEAR(G11))*12+(MONTH(L11)-MONTH(G11)),(YEAR($D$7)-YEAR(G11))*12+MONTH($D$7)-MONTH(G11),H11*12) -> 0 | N11: =IF(YEAR(L11)=YEAR($D$7),12-(MONTH($D$7)-MONTH(L11)),(IF(L11<$B$7,0,IF($D$7>L11,MIN(MONTH($D$7),DATEDIF(DATE(YEAR(G11),MONTH(G11),"1"),$D$7,"M")-DATEDIF(DATE(YEAR(G11),MONTH(G11),"1"),DATEDIF(YEAR(L11),MONTH(L11),"1"),"M")),MIN(DATEDIF(DATE(YEAR(G11),MONTH(G11),"1"),$D$7,"m"),MONTH($D$7)))))) -> 12 | O11: =IF(K11=0,0,ROUND(((1-I11)/K11)*E11,4)) -> 0 | P11: =ROUND(O11*N11,2) -> 0 | Q11: =ROUND(J11-O11,2) -> 0 | R11: =ROUND(O11*M11,2) -> 0 | S11: =ROUND(F11-R11,2) -> 0
A12: ='明细表H1-2'!A16 -> 0 | B12: ='明细表H1-2'!B16 -> 0 | C12: ='明细表H1-2'!C16 -> 0 | E12: ='明细表H1-2'!P16 -> 0 | F12: ='明细表H1-2'!AE16 -> 0 | K12: =IF(H12=0,0,IF(RIGHT(H12,1)<>"年",H12*12,IF(LEN(H12)=3,VALUE(LEFT(H12,2))*12,IF(LEN(H12)=2,VALUE(LEFT(H12,1))*12,"??")))) -> 0 | L12: =DATE((YEAR(G12)+H12),MONTH(G12),DAY(G12)) -> 0 | M12: =MIN((YEAR(L12)-YEAR(G12))*12+(MONTH(L12)-MONTH(G12)),(YEAR($D$7)-YEAR(G12))*12+MONTH($D$7)-MONTH(G12),H12*12) -> 0 | N12: =IF(YEAR(L12)=YEAR($D$7),12-(MONTH($D$7)-MONTH(L12)),(IF(L12<$B$7,0,IF($D$7>L12,MIN(MONTH($D$7),DATEDIF(DATE(YEAR(G12),MONTH(G12),"1"),$D$7,"M")-DATEDIF(DATE(YEAR(G12),MONTH(G12),"1"),DATEDIF(YEAR(L12),MONTH(L12),"1"),"M")),MIN(DATEDIF(DATE(YEAR(G12),MONTH(G12),"1"),$D$7,"m"),MONTH($D$7)))))) -> 12 | O12: =IF(K12=0,0,ROUND(((1-I12)/K12)*E12,4)) -> 0 | P12: =ROUND(O12*N12,2) -> 0 | Q12: =ROUND(J12-O12,2) -> 0 | R12: =ROUND(O12*M12,2) -> 0 | S12: =ROUND(F12-R12,2) -> 0
A13: ='明细表H1-2'!A17 -> 0 | B13: ='明细表H1-2'!B17 -> 0 | C13: ='明细表H1-2'!C17 -> 0 | E13: ='明细表H1-2'!P17 -> 0 | F13: ='明细表H1-2'!AE17 -> 0 | K13: =IF(H13=0,0,IF(RIGHT(H13,1)<>"年",H13*12,IF(LEN(H13)=3,VALUE(LEFT(H13,2))*12,IF(LEN(H13)=2,VALUE(LEFT(H13,1))*12,"??")))) -> 0 | L13: =DATE((YEAR(G13)+H13),MONTH(G13),DAY(G13)) -> 0 | M13: =MIN((YEAR(L13)-YEAR(G13))*12+(MONTH(L13)-MONTH(G13)),(YEAR($D$7)-YEAR(G13))*12+MONTH($D$7)-MONTH(G13),H13*12) -> 0 | N13: =IF(YEAR(L13)=YEAR($D$7),12-(MONTH($D$7)-MONTH(L13)),(IF(L13<$B$7,0,IF($D$7>L13,MIN(MONTH($D$7),DATEDIF(DATE(YEAR(G13),MONTH(G13),"1"),$D$7,"M")-DATEDIF(DATE(YEAR(G13),MONTH(G13),"1"),DATEDIF(YEAR(L13),MONTH(L13),"1"),"M")),MIN(DATEDIF(DATE(YEAR(G13),MONTH(G13),"1"),$D$7,"m"),MONTH($D$7)))))) -> 12 | O13: =IF(K13=0,0,ROUND(((1-I13)/K13)*E13,4)) -> 0 | P13: =ROUND(O13*N13,2) -> 0 | Q13: =ROUND(J13-O13,2) -> 0 | R13: =ROUND(O13*M13,2) -> 0 | S13: =ROUND(F13-R13,2) -> 0
A14: ='明细表H1-2'!A18 -> 0 | B14: ='明细表H1-2'!B18 -> 0 | C14: ='明细表H1-2'!C18 -> 0 | E14: ='明细表H1-2'!P18 -> 0 | F14: ='明细表H1-2'!AE18 -> 0 | K14: =IF(H14=0,0,IF(RIGHT(H14,1)<>"年",H14*12,IF(LEN(H14)=3,VALUE(LEFT(H14,2))*12,IF(LEN(H14)=2,VALUE(LEFT(H14,1))*12,"??")))) -> 0 | L14: =DATE((YEAR(G14)+H14),MONTH(G14),DAY(G14)) -> 0 | M14: =MIN((YEAR(L14)-YEAR(G14))*12+(MONTH(L14)-MONTH(G14)),(YEAR($D$7)-YEAR(G14))*12+MONTH($D$7)-MONTH(G14),H14*12) -> 0 | N14: =IF(YEAR(L14)=YEAR($D$7),12-(MONTH($D$7)-MONTH(L14)),(IF(L14<$B$7,0,IF($D$7>L14,MIN(MONTH($D$7),DATEDIF(DATE(YEAR(G14),MONTH(G14),"1"),$D$7,"M")-DATEDIF(DATE(YEAR(G14),MONTH(G14),"1"),DATEDIF(YEAR(L14),MONTH(L14),"1"),"M")),MIN(DATEDIF(DATE(YEAR(G14),MONTH(G14),"1"),$D$7,"m"),MONTH($D$7)))))) -> 12 | O14: =IF(K14=0,0,ROUND(((1-I14)/K14)*E14,4)) -> 0 | P14: =ROUND(O14*N14,2) -> 0 | Q14: =ROUND(J14-O14,2) -> 0 | R14: =ROUND(O14*M14,2) -> 0 | S14: =ROUND(F14-R14,2) -> 0
A15: ='明细表H1-2'!A19 -> 0 | B15: ='明细表H1-2'!B19 -> 0 | C15: ='明细表H1-2'!C19 -> 0 | E15: ='明细表H1-2'!P19 -> 0 | F15: ='明细表H1-2'!AE19 -> 0 | K15: =IF(H15=0,0,IF(RIGHT(H15,1)<>"年",H15*12,IF(LEN(H15)=3,VALUE(LEFT(H15,2))*12,IF(LEN(H15)=2,VALUE(LEFT(H15,1))*12,"??")))) -> 0 | L15: =DATE((YEAR(G15)+H15),MONTH(G15),DAY(G15)) -> 0 | M15: =MIN((YEAR(L15)-YEAR(G15))*12+(MONTH(L15)-MONTH(G15)),(YEAR($D$7)-YEAR(G15))*12+MONTH($D$7)-MONTH(G15),H15*12) -> 0 | N15: =IF(YEAR(L15)=YEAR($D$7),12-(MONTH($D$7)-MONTH(L15)),(IF(L15<$B$7,0,IF($D$7>L15,MIN(MONTH($D$7),DATEDIF(DATE(YEAR(G15),MONTH(G15),"1"),$D$7,"M")-DATEDIF(DATE(YEAR(G15),MONTH(G15),"1"),DATEDIF(YEAR(L15),MONTH(L15),"1"),"M")),MIN(DATEDIF(DATE(YEAR(G15),MONTH(G15),"1"),$D$7,"m"),MONTH($D$7)))))) -> 12 | O15: =IF(K15=0,0,ROUND(((1-I15)/K15)*E15,4)) -> 0 | P15: =ROUND(O15*N15,2) -> 0 | Q15: =ROUND(J15-O15,2) -> 0 | R15: =ROUND(O15*M15,2) -> 0 | S15: =ROUND(F15-R15,2) -> 0
A16: ='明细表H1-2'!A20 -> 0 | B16: ='明细表H1-2'!B20 -> 0 | C16: ='明细表H1-2'!C20 -> 0 | E16: ='明细表H1-2'!P20 -> 0 | F16: ='明细表H1-2'!AE20 -> 0 | K16: =IF(H16=0,0,IF(RIGHT(H16,1)<>"年",H16*12,IF(LEN(H16)=3,VALUE(LEFT(H16,2))*12,IF(LEN(H16)=2,VALUE(LEFT(H16,1))*12,"??")))) -> 0 | L16: =DATE((YEAR(G16)+H16),MONTH(G16),DAY(G16)) -> 0 | M16: =MIN((YEAR(L16)-YEAR(G16))*12+(MONTH(L16)-MONTH(G16)),(YEAR($D$7)-YEAR(G16))*12+MONTH($D$7)-MONTH(G16),H16*12) -> 0 | N16: =IF(YEAR(L16)=YEAR($D$7),12-(MONTH($D$7)-MONTH(L16)),(IF(L16<$B$7,0,IF($D$7>L16,MIN(MONTH($D$7),DATEDIF(DATE(YEAR(G16),MONTH(G16),"1"),$D$7,"M")-DATEDIF(DATE(YEAR(G16),MONTH(G16),"1"),DATEDIF(YEAR(L16),MONTH(L16),"1"),"M")),MIN(DATEDIF(DATE(YEAR(G16),MONTH(G16),"1"),$D$7,"m"),MONTH($D$7)))))) -> 12 | O16: =IF(K16=0,0,ROUND(((1-I16)/K16)*E16,4)) -> 0 | P16: =ROUND(O16*N16,2) -> 0 | Q16: =ROUND(J16-O16,2) -> 0 | R16: =ROUND(O16*M16,2) -> 0 | S16: =ROUND(F16-R16,2) -> 0
A17: ='明细表H1-2'!A21 -> 0 | B17: ='明细表H1-2'!B21 -> 0 | C17: ='明细表H1-2'!C21 -> 0 | E17: ='明细表H1-2'!P21 -> 0 | F17: ='明细表H1-2'!AE21 -> 0 | K17: =IF(H17=0,0,IF(RIGHT(H17,1)<>"年",H17*12,IF(LEN(H17)=3,VALUE(LEFT(H17,2))*12,IF(LEN(H17)=2,VALUE(LEFT(H17,1))*12,"??")))) -> 0 | L17: =DATE((YEAR(G17)+H17),MONTH(G17),DAY(G17)) -> 0 | M17: =MIN((YEAR(L17)-YEAR(G17))*12+(MONTH(L17)-MONTH(G17)),(YEAR($D$7)-YEAR(G17))*12+MONTH($D$7)-MONTH(G17),H17*12) -> 0 | N17: =IF(YEAR(L17)=YEAR($D$7),12-(MONTH($D$7)-MONTH(L17)),(IF(L17<$B$7,0,IF($D$7>L17,MIN(MONTH($D$7),DATEDIF(DATE(YEAR(G17),MONTH(G17),"1"),$D$7,"M")-DATEDIF(DATE(YEAR(G17),MONTH(G17),"1"),DATEDIF(YEAR(L17),MONTH(L17),"1"),"M")),MIN(DATEDIF(DATE(YEAR(G17),MONTH(G17),"1"),$D$7,"m"),MONTH($D$7)))))) -> 12 | O17: =IF(K17=0,0,ROUND(((1-I17)/K17)*E17,4)) -> 0 | P17: =ROUND(O17*N17,2) -> 0 | Q17: =ROUND(J17-O17,2) -> 0 | R17: =ROUND(O17*M17,2) -> 0 | S17: =ROUND(F17-R17,2) -> 0
A18: ='明细表H1-2'!A22 -> 0 | B18: ='明细表H1-2'!B22 -> 0 | C18: ='明细表H1-2'!C22 -> 0 | E18: ='明细表H1-2'!P22 -> 0 | F18: ='明细表H1-2'!AE22 -> 0 | K18: =IF(H18=0,0,IF(RIGHT(H18,1)<>"年",H18*12,IF(LEN(H18)=3,VALUE(LEFT(H18,2))*12,IF(LEN(H18)=2,VALUE(LEFT(H18,1))*12,"??")))) -> 0 | L18: =DATE((YEAR(G18)+H18),MONTH(G18),DAY(G18)) -> 0 | M18: =MIN((YEAR(L18)-YEAR(G18))*12+(MONTH(L18)-MONTH(G18)),(YEAR($D$7)-YEAR(G18))*12+MONTH($D$7)-MONTH(G18),H18*12) -> 0 | N18: =IF(YEAR(L18)=YEAR($D$7),12-(MONTH($D$7)-MONTH(L18)),(IF(L18<$B$7,0,IF($D$7>L18,MIN(MONTH($D$7),DATEDIF(DATE(YEAR(G18),MONTH(G18),"1"),$D$7,"M")-DATEDIF(DATE(YEAR(G18),MONTH(G18),"1"),DATEDIF(YEAR(L18),MONTH(L18),"1"),"M")),MIN(DATEDIF(DATE(YEAR(G18),MONTH(G18),"1"),$D$7,"m"),MONTH($D$7)))))) -> 12 | O18: =IF(K18=0,0,ROUND(((1-I18)/K18)*E18,4)) -> 0 | P18: =ROUND(O18*N18,2) -> 0 | Q18: =ROUND(J18-O18,2) -> 0 | R18: =ROUND(O18*M18,2) -> 0 | S18: =ROUND(F18-R18,2) -> 0
A19: ='明细表H1-2'!A23 -> 0 | B19: ='明细表H1-2'!B23 -> 0 | C19: ='明细表H1-2'!C23 -> 0 | E19: ='明细表H1-2'!P23 -> 0 | F19: ='明细表H1-2'!AE23 -> 0 | K19: =IF(H19=0,0,IF(RIGHT(H19,1)<>"年",H19*12,IF(LEN(H19)=3,VALUE(LEFT(H19,2))*12,IF(LEN(H19)=2,VALUE(LEFT(H19,1))*12,"??")))) -> 0 | L19: =DATE((YEAR(G19)+H19),MONTH(G19),DAY(G19)) -> 0 | M19: =MIN((YEAR(L19)-YEAR(G19))*12+(MONTH(L19)-MONTH(G19)),(YEAR($D$7)-YEAR(G19))*12+MONTH($D$7)-MONTH(G19),H19*12) -> 0 | N19: =IF(YEAR(L19)=YEAR($D$7),12-(MONTH($D$7)-MONTH(L19)),(IF(L19<$B$7,0,IF($D$7>L19,MIN(MONTH($D$7),DATEDIF(DATE(YEAR(G19),MONTH(G19),"1"),$D$7,"M")-DATEDIF(DATE(YEAR(G19),MONTH(G19),"1"),DATEDIF(YEAR(L19),MONTH(L19),"1"),"M")),MIN(DATEDIF(DATE(YEAR(G19),MONTH(G19),"1"),$D$7,"m"),MONTH($D$7)))))) -> 12 | O19: =IF(K19=0,0,ROUND(((1-I19)/K19)*E19,4)) -> 0 | P19: =ROUND(O19*N19,2) -> 0 | Q19: =ROUND(J19-O19,2) -> 0 | R19: =ROUND(O19*M19,2) -> 0 | S19: =ROUND(F19-R19,2) -> 0
A20: ='明细表H1-2'!A24 -> 0 | B20: ='明细表H1-2'!B24 -> 0 | C20: ='明细表H1-2'!C24 -> 0 | E20: ='明细表H1-2'!P24 -> 0 | F20: ='明细表H1-2'!AE24 -> 0 | K20: =IF(H20=0,0,IF(RIGHT(H20,1)<>"年",H20*12,IF(LEN(H20)=3,VALUE(LEFT(H20,2))*12,IF(LEN(H20)=2,VALUE(LEFT(H20,1))*12,"??")))) -> 0 | L20: =DATE((YEAR(G20)+H20),MONTH(G20),DAY(G20)) -> 0 | M20: =MIN((YEAR(L20)-YEAR(G20))*12+(MONTH(L20)-MONTH(G20)),(YEAR($D$7)-YEAR(G20))*12+MONTH($D$7)-MONTH(G20),H20*12) -> 0 | N20: =IF(YEAR(L20)=YEAR($D$7),12-(MONTH($D$7)-MONTH(L20)),(IF(L20<$B$7,0,IF($D$7>L20,MIN(MONTH($D$7),DATEDIF(DATE(YEAR(G20),MONTH(G20),"1"),$D$7,"M")-DATEDIF(DATE(YEAR(G20),MONTH(G20),"1"),DATEDIF(YEAR(L20),MONTH(L20),"1"),"M")),MIN(DATEDIF(DATE(YEAR(G20),MONTH(G20),"1"),$D$7,"m"),MONTH($D$7)))))) -> 12 | O20: =IF(K20=0,0,ROUND(((1-I20)/K20)*E20,4)) -> 0 | P20: =ROUND(O20*N20,2) -> 0 | Q20: =ROUND(J20-O20,2) -> 0 | R20: =ROUND(O20*M20,2) -> 0 | S20: =ROUND(F20-R20,2) -> 0
... A28: ='明细表H1-2'!A32 -> 0 | B28: ='明细表H1-2'!B32 -> 0 | C28: ='明细表H1-2'!C32 -> 0 | E28: ='明细表H1-2'!P32 -> 0 | F28: ='明细表H1-2'!AE32 -> 0 | K28: =IF(H28=0,0,IF(RIGHT(H28,1)<>"年",H28*12,IF(LEN(H28)=3,VALUE(LEFT(H28,2))*12,IF(LEN(H28)=2,VALUE(LEFT(H28,1))*12,"??")))) -> 0 | L28: =DATE((YEAR(G28)+H28),MONTH(G28),DAY(G28)) -> 0 | M28: =MIN((YEAR(L28)-YEAR(G28))*12+(MONTH(L28)-MONTH(G28)),(YEAR($D$7)-YEAR(G28))*12+MONTH($D$7)-MONTH(G28),H28*12) -> 0 | N28: =IF(YEAR(L28)=YEAR($D$7),12-(MONTH($D$7)-MONTH(L28)),(IF(L28<$B$7,0,IF($D$7>L28,MIN(MONTH($D$7),DATEDIF(DATE(YEAR(G28),MONTH(G28),"1"),$D$7,"M")-DATEDIF(DATE(YEAR(G28),MONTH(G28),"1"),DATEDIF(YEAR(L28),MONTH(L28),"1"),"M")),MIN(DATEDIF(DATE(YEAR(G28),MONTH(G28),"1"),$D$7,"m"),MONTH($D$7)))))) -> 12 | O28: =IF(K28=0,0,ROUND(((1-I28)/K28)*E28,4)) -> 0 | P28: =ROUND(O28*N28,2) -> 0 | Q28: =ROUND(J28-O28,2) -> 0 | R28: =ROUND(O28*M28,2) -> 0 | S28: =ROUND(F28-R28,2) -> 0
A29: ='明细表H1-2'!A33 -> 合计 | E29: =SUM(E9:E28) -> 0 | F29: =SUM(F9:F28) -> 0 | O29: =SUM(O9:O28) -> 0 | P29: =SUM(P9:P28) -> 0 | Q29: =SUM(Q9:Q28) -> 0 | R29: =SUM(R9:R28) -> 0 | S29: =SUM(S9:S28) -> 0
A30: ='明细表H1-2'!A34 -> 其中：
A31: ='明细表H1-2'!A35 -> 房屋及建筑物 | E31: =SUMPRODUCT(($A$9:$A$28=$A31)*(E$9:E$28)) -> 0 | F31: =SUMPRODUCT(($A$9:$A$28=$A31)*(F$9:F$28)) -> 0 | S31: =SUMPRODUCT(($A$9:$A$28=$A31)*(S$9:S$28)) -> 0
A32: ='明细表H1-2'!A36 -> 机器设备 | E32: =SUMPRODUCT(($A$9:$A$28=$A32)*(E$9:E$28)) -> 0 | F32: =SUMPRODUCT(($A$9:$A$28=$A32)*(F$9:F$28)) -> 0 | S32: =SUMPRODUCT(($A$9:$A$28=$A32)*(S$9:S$28)) -> 0
A33: ='明细表H1-2'!A37 -> 运输设备 | E33: =SUMPRODUCT(($A$9:$A$28=$A33)*(E$9:E$28)) -> 0 | F33: =SUMPRODUCT(($A$9:$A$28=$A33)*(F$9:F$28)) -> 0 | S33: =SUMPRODUCT(($A$9:$A$28=$A33)*(S$9:S$28)) -> 0
A34: ='明细表H1-2'!A38 -> 办公设备 | E34: =SUMPRODUCT(($A$9:$A$28=$A34)*(E$9:E$28)) -> 0 | F34: =SUMPRODUCT(($A$9:$A$28=$A34)*(F$9:F$28)) -> 0 | S34: =SUMPRODUCT(($A$9:$A$28=$A34)*(S$9:S$28)) -> 0
A35: ='明细表H1-2'!A39 -> 其他设备 | E35: =SUMPRODUCT(($A$9:$A$28=$A35)*(E$9:E$28)) -> 0 | F35: =SUMPRODUCT(($A$9:$A$28=$A35)*(F$9:F$28)) -> 0 | S35: =SUMPRODUCT(($A$9:$A$28=$A35)*(S$9:S$28)) -> 0
A36: 三、审计说明：
A37: 需单独考虑本期固定资产减少对累计折旧的影响
A39: 四、审计结论
A44: 提示：
A45: 《企业所得税法实施条例》
A46: 第五十九条 固定资产按照直线法计算的折旧，准予扣除。
A47: 企业应当自固定资产投入使用月份的次月起计算折旧；停止使用的固定资产，应当自停止使用月份的次月起停止计算折旧。
A48: 企业应当根据固定资产的性质和使用情况，合理确定固定资产的预计净残值。固定资产的预计净残值一经确定，不得变更。
A49: 第六十条 除国务院财政、税务主管部门另有规定外，固定资产计算折旧的最低年限如下：
A50: （一）房屋、建筑物，为20年；
A51: （二）飞机、火车、轮船、机器、机械和其他生产设备，为10年；
A52: （三）与生产经营活动有关的器具、工具、家具等，为5年；
...

Sheet 折旧测算表（含减值）H1-12
A1: 致同会计师事务所
A2: 固定资产折旧测算表
A3: =底稿目录!A2 -> 被审计单位： | G3: =底稿目录!A4 -> 编制人： | R3: =底稿目录!A5 -> 编制日期： | X3: 索引号： | Y3: H1-12
A4: =底稿目录!A3 -> 截止日：202X年12月31日 | G4: =底稿目录!A6 -> 复核人： | R4: =底稿目录!A7 -> 复核日期： | X4: 页 次：
A5: 一、审计目标：固定资产以恰当的金额包括在财务报表中，与之相关的计价或分摊调整已恰当记录，相关披露已得到恰当计量和描述。
A6: 二、审计过程：
A7: 折旧期初： | C7: 折旧期末： | E7: 计提减值准备日期： | G7: 各列顺序请根据需要进行调整，行数请根据需要增加。非公式列输入数据时请使用“选择性粘贴-数值”。
A8: 固定资产类别 | B8: 固定资产编号 | C8: 固定资产名称 | D8: 管理部门 | E8: 原值 （期末） | F8: 累计折旧（期末） | G8: 减值准备（期末） | H8: 开始使用日期 | I8: 使用年限 | J8: 残值率 | K8: 账面月折旧额 | L8: 使用月限 | M8: 测算到期日 | N8: 已提折旧月份 | O8: 截止计提减值准备日计提月份 | P8: 本期折旧月份 | Q8: 本期折旧月份（减值前） | R8: 本期折旧月份（减值后） | S8: 计提减值准备前月折旧 | T8: 计提减值准备前累计折旧 | U8: 计提减值准备后月折旧 | V8: 当期折旧费用 | W8: 月折旧额差异 | X8: 累计折旧费用 | Y8: 累计折旧额差异
A9: ='明细表H1-2'!A13 -> 0 | B9: ='明细表H1-2'!B13 -> 0 | C9: ='明细表H1-2'!C13 -> 0 | E9: ='明细表H1-2'!P13 -> 0 | F9: ='明细表H1-2'!AE13 -> 0 | G9: ='明细表H1-2'!AT13 -> 0 | L9: =IF(I9=0,0,IF(RIGHT(I9,1)<>"年",I9*12,IF(LEN(I9)=3,VALUE(LEFT(I9,2))*12,IF(LEN(I9)=2,VALUE(LEFT(I9,1))*12,"??")))) -> 0 | M9: =IF(DAY(H9)=1,IF(H9=0,0,DATE(YEAR(H9),MONTH(H9)+L9,DAY(H9))),IF(H9=0,0,DATE(YEAR(H9),MONTH(H9)+L9,DAY(H9)-1))) -> 0 | N9: =MIN(IF(AND(DAY(H9)=31,DAY($D$7)=30),IF(H9=0,0,IF(M9>$D$7,VALUE(DATEDIF(H9,MIN($D$7,M9),"m"))+1,VALUE(DATEDIF(H9,MIN($D$7,M9),"m")+2))),IF(H9=0,0,IF(M9>$D$7,DATEDIF(H9,MIN($D$7,M9),"m"),VALUE(DATEDIF(H9,MIN($D$7,M9),"m")+1)))),L9) -> 0 | O9: =IF(AND(DAY(H9)=31,DAY($F$7)=30),MIN(IF(H9=0,0,IF($F$7>H9,VALUE(DATEDIF(H9,$F$7,"m"))+1,0)),N9+1),MIN(IF(H9=0,0,IF($F$7>H9,DATEDIF(H9,$F$7,"m"),0)),N9)) -> 0 | P9: =IF(OR(H9=0,M9<$B$7),0,IF(AND(H9<$B$7,M9>$D$7),VALUE(DATEDIF($B$7,$D$7,"m")+1),IF(AND(H9<$B$7,M9<=$D$7),VALUE(DATEDIF($B$7,M9,"m")+1),IF(AND(H9>=$B$7,M9>$D$7),VALUE(DATEDIF(H9,$D$7,"m")),IF(AND(H9>=$B$7,M9<=$D$7),VALUE(DATEDIF(H9,M9,"m")+1),))))) -> 0 | Q9: =IF(AND(YEAR(H9)=YEAR($D$7),DAY(H9)=31,DAY($D$7)=30),IF(H9>$F$7,0,P9-R9+1),IF(H9>$F$7,0,P9-R9)) -> 0 | R9: =IF(AND(DAY($F$7)=31,DAY($D$7)=30),IF(H9=0,0,IF($F$7<$B$7,P9,VALUE(DATEDIF(MAX(H9,$F$7),MIN(M9,$D$7),"m")))+1),IF(H9=0,0,IF($F$7<$B$7,P9,DATEDIF(MAX(H9,$F$7),MIN(M9,$D$7),"m")))) -> 0 | S9: =IF(L9=0,0,ROUND(((1-J9)/L9)*E9,4)) -> 0 | T9: =ROUND(S9*O9,2) -> 0 | U9: =IF((E9*(1-J9)-T9-G9)>0,(E9*(1-J9)-T9-G9)/(L9-O9),0) -> 0 | V9: =ROUND(S9*Q9,2)+ROUND(U9*R9,2) -> 0 | W9: =ROUND(K9-U9,2) -> 0 | X9: =ROUND(S9*O9,2)+ROUND(U9*(N9-O9),2) -> 0 | Y9: =ROUND(F9-X9,2) -> 0
