Workbook

Sheet 底稿目录
A1: 底稿开列时，可先在以下单元格填写有关内容，以便其他底稿引用有关数据：
A2: 被审计单位：
A3: 截止日：202X年12月31日 | D3: 序号 | E3: 内容 | F3: 索引号 | G3: 备注
A4: 编制人： | E4: 在建工程实质性程序表 | F4: H2A
A5: 复核人： | D5: 1 | E5: 审定表 | F5: H2-1
A6: 编制日期： | D6: =D5+1 -> 2 | E6: 附注披露信息（上市公司） | G6: 无需打印
A7: 复核日期： | D7: =D6+1 -> 3 | E7: 附注披露信息（国有企业） | G7: 无需打印
D8: =D7+1 -> 4 | E8: 明细表 | F8: H2-2
A9: 关于工作底稿与审计程序索引号对应的说明 | D9: =D8+1 -> 5 | E9: 调整分录汇总 | F9: H2-3
A10: 1.编制的审计工作底稿应与审计程序对应。审计项目组应根据被审计单位实际情况和风险评估情况在实质性程序表中裁剪、修改或增加审计程序，根据实际执行的审计程序完成相应审计工作底稿，编制的工作底稿中应按自然顺序依次编制索引号，并通过唯一的索引号将与实质性程序表中的程序对应关联（即将工作底稿的索引号填入实质性程序表中的底稿索引号列）。 | D10: =D9+1 -> 6 | E10: 分析表 | F10: H2-4
D11: =D10+1 -> 7 | E11: 转固时点检查表 | F11: H2-5
D12: =D11+1 -> 8 | E12: 在建工程审核记录 | F12: H2-6
D13: =D12+1 -> 9 | E13: 工程造价比较表 | F13: H2-7
A14: 2.获取的支持性证据应与审计底稿或程序对应。审计项目组在完成底稿时获取的支持性证据应根据底稿索引号编制下一级按自然顺序排序的索引号（如D1-2-1、D1-2-2、……），并在底稿中说明引用的支持性证据、关联索引号。 | D14: =D13+1 -> 10 | E14: 增加检查表 | F14: H2-8
D15: =D14+1 -> 11 | E15: 减少检查表 | F15: H2-9
D16: =D15+1 -> 12 | E16: 利息资本化测算表（无专门借款） | F16: H2-10
A17: 3.工作底稿索引号的编码规则：实质性程序索引号按循环从“D”到“N”,循环内账户以顺序号排列，模板中底稿索引号按账户顺序+自然数顺序（即模板中索引号按二级自然顺序排列，如D1-1、D1-2、D1-3、……D1-N）。 | D17: =D16+1 -> 13 | E17: 利息资本化测算表（有专门借款） | F17: H2-11
D18: =D17+1 -> 14 | E18: 监盘计划 | F18: H2-12
D19: =D18+1 -> 15 | E19: 盘点检查表 | F19: H2-13
D20: =D19+1 -> 16 | E20: 监盘小结 | F20: H2-14
D21: =D20+1 -> 17 | E21: 减值测算表 | F21: H2-15
D22: =D21+1 -> 18 | E22: 可收回金额测试表 | F22: H2-16
D23: =D22+1 -> 19 | E23: 关联交易检查表 | F23: H2-17

Sheet 在建工程实质性程序表H2A
A1: 致同会计师事务所
A2: 在建工程及减值准备实质性程序表
A3: =底稿目录!A2 -> 被审计单位： | C3: =底稿目录!A4 -> 编制人： | F3: =底稿目录!A6 -> 编制日期： | H3: 索引号： | I3: H2A
A4: =底稿目录!A3 -> 截止日：202X年12月31日 | C4: =底稿目录!A5 -> 复核人： | F4: =底稿目录!A7 -> 复核日期： | H4: 页 次：
A5: 一、本账户涉及的科目
A6: 在建工程、减值准备
A7: 二、审计目标与认定的对应关系
A8: 审计目标 | G8: 财务报表的认定
A9: A. 资产负债表中记录的在建工程是存在的，且已记录于恰当的账户 | G9: 存在
A10: B. 所有应记录的在建工程均已记录，所有应当包括在财务报表中的相关披露均已包括 | G10: 完整性
A11: C. 记录的在建工程由被审计单位拥有或控制； | G11: 权利和义务
A12: D. 在建工程以恰当的金额包括在财务报表中，与之相关的计价或分摊调整已恰当记录，相关披露已得到恰当计量和描述 | G12: 准确性、计价和分摊
A13: E. 在建工程已被恰当地汇总或分解且表述清楚，相关披露在按照企业会计准则的编制基础下是相关的、可理解的 | G13: 列报
A14: 三、计划实施的实质性程序
A15: 序号 | B15: 审计程序 | C15: 程序分类 | D15: 财务报表的认定 | I15: 底稿索引号
D16: 存在 | E16: 完整性 | F16: 权利和 义务 | G16: 准确性、计价和分摊 | H16: 列报 | J16: 根据被审计单位实际情况和风险评估情况裁剪、修改或增加审计程序
A17: 1 | B17: 获取或编制在建工程的明细表，完成以下工作，并编制审定表： （1）复核加计是否正确，并与总账数和明细账合计数核对是否相符，期初余额与上期审定期末余额是否相符； （2）结合银行借款等项目的检查，了解在建工程是否存在抵押、担保情况； （3）根据工程结算单，核对各项目施工进度尾款与工程明细、复核工程奖励款是否与合同一致。（如有） （4）询问闲置资产或未入账资产处置情况（如有）。 | C17: 常规★ | D17: √ | E17: √ | G17: √ | I17: H2-1 /H2-2
A18: 2 | B18: 在使用手工编制、自定义信息报告、系统生成的非固定格式报告等由被审计单位生成的信息时，测试有关信息准确性和完整性，并考虑针对编制和维护由被审计单位生成的信息的相关控制实施控制测试，以评价该信息是否能够为实现审计目的提供基础。 | C18: 常规★ | E18: √ | G18: √ | I18: T1 / | J18: 可参见《审计手册》4.2.6，由被审计单位生成的信息可能是由系统生成的、或手工编制的、或二者兼而有之的方式生成的。例如，由被审计单位生成的信息可能包括： • 不涉及自定义的、由系统生成的报告（如，固定格式报告）； • 可能通过人工自定义的、由系统生成的报告，例如，（计算机）查询信息或特别定制的报告； • 手工编制的信息，例如，汇总信息的电子表格或用以支持分配、计算以及调节的电子表格； • 其他系统生成或手工编制的信息，例如，由被审计单位编制的客户发票； • 通过影印、拍摄、扫描或其他方式转换成电子形式的文件记录。
A19: 3 | B19: 对期初余额，取得上期在建工程明细表复核加计是否正确，与总账、明细账合计数是否相符；对单项金额重大资产，进行实地查看资产或检查支持性文件；检查期初在建工程在本期增减变动情况，其他必要追加的审计程序。（适用于首次承接） | C19: 备选 | D19: √ | E19: √ | F19: √ | G19: √ | J19: 由被审计单位生成的信息不包括： • 总分类账或明细分类账、试算平衡表、或经审计的财务报表； • 第三方（除了服务机构）的报表或报告，例如，原始银行对账单，或函证的回函； • 外部数据（例如，第三方发布的数据，如，定价来源）。
A20: 4 | B20: 关注会计政策、会计估计合理性、一贯性，关注其是否利用会计政策和会计估计及其变更操纵利润。 | C20: 常规★ | E20: √ | G20: √
A21: 5 | B21: 将本期在建工程相关数据与可比上期数据进行比较，包括在建工程占资产总额比例、在建工程余额、在建工程减值准备占在建工程原值比例、实际支出与预算的差异、利息资本化率，以识别需要执行额外程序的领域。 | C21: 常规★ | D21: √ | E21: √ | G21: √ | I21: H2-4
A22: 6 | B22: 执行分析性程序，以识别需要执行额外程序的领域： （1）关注固定资产、在建工程的规模及其变化是否与产能匹配，并与以前年度对比分析，是否存在同类产品产能利用率较低却增加在建工程投入； （2）分析在建工程转固前后时点产品产能、产量变动，关注是否存在前期产品产能、产量与后期无差异、或差异很小的情形，并关注此情形是否表明公司人为推迟转固时间。 | C22: IPO/上市/新三板/重组/舞弊应对 | D22: √ | E22: √ | G22: √
A23: 7 | B23: 了解在建工程转固定资产、生产性生物资产、油气资产等政策，分析转固政策是否符合会计准则及相关规定，分析转固政策是否合理。检查是否存在推迟在建工程转固时间或外购固定资产达到预定使用状态时间等延迟固定资产开始计提折旧时间的情况， | C23: 常规★ | D23: √ | E23: √ | G23: √ | I23: H2-5
A24: 9 | B24: 检查在建工程本期增加： （1）询问管理层当年在建工程的增加情况，并与获取或编制的在建工程明细表进行核对。 （2）查阅公司资本支出预算、公司相关会议决议等，检查本年度增加的在建工程是否全部得到记录。 （3）检查本年度增加的在建工程的原始凭证是否完整，如立项申请、工程借款合同、施工合同、发票、工程物资请购申请、付款单据、建设合同、运单、验收报告等是否完整，计价是否正确。 （4）检查借款费用资本化的计算是否正确，包括用于计算确定借款费用资本化金额的资本化率、实际支出数以及资本化的开始和停止时间等。 | C24: 常规★ | D24: √ | E24: √ | F24: √ | G24: √ | I24: H2-6 /H2-8 /H2-10 /H2-11
A25: 10 | B25: 检查在建工程本期减少： （1）检查已完工工程项目的竣工决算报告、验收交接单等相关凭证以及其他转出数的原始凭证，检查会计处理是否正确。 （2）对于已达到预定可使用状态但尚未办理竣工决算的在建工程，考虑是否按照估计价值转出有关固定资产成本，并计提折旧/折耗；待办理竣工决算后，是否再按实际成本调整原来的暂估价值，但不需调整原已计提的折旧/折耗。 （3）结合固定资产审计，考虑在建工程转销额是否正确，是否存在将已经达到预定可使用状态的固定资产挂列在建工程，少计折旧/折耗。 | C25: 常规★ | D25: √ | E25: √ | G25: √ | I25: H2-9
A26: 11 | B26: 检查其他方式的资产增减或减少： （1）对于非货币性资产交换、债务重组、企业合并、投资者投入等交易方式取得或减少的有关长期资产，检查相关合同/协议，关注计价是否正确、移交手续是否办理以及会计处理是否正确。 （2）对于因清产核资、资产评估调增或调减有关长期资产价值的，检查有关清产核资报告、资产评估报告、国有资产管理等部门的确认文件、验资报告等，检查会计处理是否正确。 | C26: 备选 | D26: √ | E26: √ | F26: √ | G26: √ | I26: H2-8 /H2-9
A27: 12 | B27: 在建工程实地检查（盘点）程序： （1）取得公司在建工程清单，选择本期新增、长期停滞、容易侵占、重要、数量巨大、已损坏项目、存放在第三方及其他异常等在建工程项目进行实地检查； （2）获取被审计单位对于在建工程的盘点计划，制定和实施监盘计划（如有）； （3）取得在建工程存放/施工地点清单，初步确定监盘方式、时间、监盘计划； （4）观察被审计单位制定的盘点程序的执行情况 （5）抽取项目实地检查在建工程的施工状态及形象进度（在建、停滞、闲置、毁损）； （6）评价在建工程盘点结果，完成监盘小结。 | C27: 常规★ | D27: √ | F27: √ | G27: √ | I27: H2-12 /H2-13 /H2-14
A28: 13 | B28: 存放其他地方的资产（如有），考虑实地观察或函证由其他人保管或保管在盘点地之外的资产。 | C28: 备选 | D28: √ | F28: √ | G28: √ | I28: H0
A29: 14 | B29: 结合在建工程清单和盘点程序，了解在建工程的状态。针对存在减值迹象的在建工程，考虑执行下列程序： 获取被审计单位在资产负债表日就在建工程是否可能发生减值迹象的判断的说明，判断其合理性。对于已计提减值准备的在建工程，检查减值测试相关参数是否合理，减值准备计提是否正确。对于管理层聘请评估专家出具的评估报告，复核评估报告。 | C29: 常规★ | G29: √ | I29: H2-15 /H2-16
A30: 15 | B30: 检查关联交易情况，检查关联交易的真实性、合理性及合规性；检查关联交易会计处理是否正确，考虑是否存在未识别的关联方，检查关联交易和余额披露是否正确。如果识别出关联交易存在重大错报风险，需执行相关审计程序。 | C30: 常规★ | D30: √ | E30: √ | F30: √ | G30: √ | H30: √ | I30: H2-17
A31: 8 | B31: 识别当期新增的单项重要资产，考虑执行下列程序： （1）分析单位工程造价，关注其是否合理、是否与同业公司存在重大差异并调查原因，必要时，利用专家的工作。 （2）重大或异常工程项目，应对其施工方或设备供应商实施实地走访程序（具体程序请参考存货循环供应商走访程序）。 | C31: IPO/上市/新三板/重组/舞弊应对 | D31: √ | E31: √ | F31: √ | G31: √ | I31: H2-7 /H2-
A32: 16 | B32: 根据评估的舞弊风险等因素增加的审计程序。 | C32: IPO/上市/新三板/重组/舞弊应对
A33: 17 | B33: 检查在建工程、抵押和担保情况、资本性支出承诺等是否已按企业会计准则或其他适用的规定在财务报表中做出恰当列报和披露 | C33: 常规★ | H33: √ | I33: A 1-1/A1-15 /A1-16
A34: 18 | B34: 如被审计单位是上市公司，将在建工程增减数与募集资金使用情况的披露进行核对。 | C34: IPO/上市公司 | H34: √ | I34: A 1-1/A1-15 /A1-16

Sheet 审定表H2-1
A1: 致同会计师事务所
A2: 在建工程及减值准备审定表
A3: =底稿目录!A2 -> 被审计单位： | D3: =底稿目录!A4 -> 编制人： | H3: =底稿目录!A6 -> 编制日期： | J3: 索引号： | K3: H2-1
A4: =底稿目录!A3 -> 截止日：202X年12月31日 | D4: =底稿目录!A5 -> 复核人： | H4: =底稿目录!A7 -> 复核日期： | J4: 页 次：
A5: 项目 | B5: 期初数 | E5: 期末数 | H5: 本期未审数与上期 未审数的比较 | J5: 本期审定数与上期 审定数的比较
B6: 未审数 | C6: 账项调整 | D6: 审定数 | E6: 未审数 | F6: 账项调整 | G6: 审定数 | H6: 变动额 | I6: 变动率 | J6: 变动额 | K6: 变动率
A7: 一、在建工程原值
A8: ='明细表H2-2'!A13 -> 0 | B8: ='明细表H2-2'!J13 -> 0 | C8: ='明细表H2-2'!S13 -> 0 | D8: =B8+C8 -> 0 | E8: ='明细表H2-2'!Q13 -> 0 | F8: ='明细表H2-2'!S13+'明细表H2-2'!U13-'明细表H2-2'!W13-'明细表H2-2'!X13 -> 0 | G8: =E8+F8 -> 0 | H8: =E8-B8 -> 0 | I8: =IF(AND(B8=0,H8=0),0,IF(AND(B8=0,H8>0),1,H8/B8)) -> 0 | J8: =G8-D8 -> 0 | K8: =IF(AND(D8=0,J8=0),0,IF(AND(D8=0,J8>0),1,J8/D8)) -> 0
A9: ='明细表H2-2'!A14 -> 0 | B9: ='明细表H2-2'!J14 -> 0 | C9: ='明细表H2-2'!S14 -> 0 | D9: =B9+C9 -> 0 | E9: ='明细表H2-2'!Q14 -> 0 | F9: ='明细表H2-2'!S14+'明细表H2-2'!U14-'明细表H2-2'!W14-'明细表H2-2'!X14 -> 0 | G9: =E9+F9 -> 0 | H9: =E9-B9 -> 0 | I9: =IF(AND(B9=0,H9=0),0,IF(AND(B9=0,H9>0),1,H9/B9)) -> 0 | J9: =G9-D9 -> 0 | K9: =IF(AND(D9=0,J9=0),0,IF(AND(D9=0,J9>0),1,J9/D9)) -> 0
A10: ='明细表H2-2'!A15 -> 0 | B10: ='明细表H2-2'!J15 -> 0 | C10: ='明细表H2-2'!S15 -> 0 | D10: =B10+C10 -> 0 | E10: ='明细表H2-2'!Q15 -> 0 | F10: ='明细表H2-2'!S15+'明细表H2-2'!U15-'明细表H2-2'!W15-'明细表H2-2'!X15 -> 0 | G10: =E10+F10 -> 0 | H10: =E10-B10 -> 0 | I10: =IF(AND(B10=0,H10=0),0,IF(AND(B10=0,H10>0),1,H10/B10)) -> 0 | J10: =G10-D10 -> 0 | K10: =IF(AND(D10=0,J10=0),0,IF(AND(D10=0,J10>0),1,J10/D10)) -> 0
A11: ='明细表H2-2'!A16 -> 0 | B11: ='明细表H2-2'!J16 -> 0 | C11: ='明细表H2-2'!S16 -> 0 | D11: =B11+C11 -> 0 | E11: ='明细表H2-2'!Q16 -> 0 | F11: ='明细表H2-2'!S16+'明细表H2-2'!U16-'明细表H2-2'!W16-'明细表H2-2'!X16 -> 0 | G11: =E11+F11 -> 0 | H11: =E11-B11 -> 0 | I11: =IF(AND(B11=0,H11=0),0,IF(AND(B11=0,H11>0),1,H11/B11)) -> 0 | J11: =G11-D11 -> 0 | K11: =IF(AND(D11=0,J11=0),0,IF(AND(D11=0,J11>0),1,J11/D11)) -> 0
A12: ='明细表H2-2'!A17 -> 0 | B12: ='明细表H2-2'!J17 -> 0 | C12: ='明细表H2-2'!S17 -> 0 | D12: =B12+C12 -> 0 | E12: ='明细表H2-2'!Q17 -> 0 | F12: ='明细表H2-2'!S17+'明细表H2-2'!U17-'明细表H2-2'!W17-'明细表H2-2'!X17 -> 0 | G12: =E12+F12 -> 0 | H12: =E12-B12 -> 0 | I12: =IF(AND(B12=0,H12=0),0,IF(AND(B12=0,H12>0),1,H12/B12)) -> 0 | J12: =G12-D12 -> 0 | K12: =IF(AND(D12=0,J12=0),0,IF(AND(D12=0,J12>0),1,J12/D12)) -> 0
A13: ='明细表H2-2'!A18 -> 0 | B13: ='明细表H2-2'!J18 -> 0 | C13: ='明细表H2-2'!S18 -> 0 | D13: =B13+C13 -> 0 | E13: ='明细表H2-2'!Q18 -> 0 | F13: ='明细表H2-2'!S18+'明细表H2-2'!U18-'明细表H2-2'!W18-'明细表H2-2'!X18 -> 0 | G13: =E13+F13 -> 0 | H13: =E13-B13 -> 0 | I13: =IF(AND(B13=0,H13=0),0,IF(AND(B13=0,H13>0),1,H13/B13)) -> 0 | J13: =G13-D13 -> 0 | K13: =IF(AND(D13=0,J13=0),0,IF(AND(D13=0,J13>0),1,J13/D13)) -> 0
A14: ='明细表H2-2'!A19 -> 0 | B14: ='明细表H2-2'!J19 -> 0 | C14: ='明细表H2-2'!S19 -> 0 | D14: =B14+C14 -> 0 | E14: ='明细表H2-2'!Q19 -> 0 | F14: ='明细表H2-2'!S19+'明细表H2-2'!U19-'明细表H2-2'!W19-'明细表H2-2'!X19 -> 0 | G14: =E14+F14 -> 0 | H14: =E14-B14 -> 0 | I14: =IF(AND(B14=0,H14=0),0,IF(AND(B14=0,H14>0),1,H14/B14)) -> 0 | J14: =G14-D14 -> 0 | K14: =IF(AND(D14=0,J14=0),0,IF(AND(D14=0,J14>0),1,J14/D14)) -> 0
A15: ='明细表H2-2'!A20 -> 0 | B15: ='明细表H2-2'!J20 -> 0 | C15: ='明细表H2-2'!S20 -> 0 | D15: =B15+C15 -> 0 | E15: ='明细表H2-2'!Q20 -> 0 | F15: ='明细表H2-2'!S20+'明细表H2-2'!U20-'明细表H2-2'!W20-'明细表H2-2'!X20 -> 0 | G15: =E15+F15 -> 0 | H15: =E15-B15 -> 0 | I15: =IF(AND(B15=0,H15=0),0,IF(AND(B15=0,H15>0),1,H15/B15)) -> 0 | J15: =G15-D15 -> 0 | K15: =IF(AND(D15=0,J15=0),0,IF(AND(D15=0,J15>0),1,J15/D15)) -> 0
A16: 合计 | B16: =SUM(B8:B15) -> 0 | C16: =SUM(C8:C15) -> 0 | D16: =SUM(D8:D15) -> 0 | E16: =SUM(E8:E15) -> 0 | F16: =SUM(F8:F15) -> 0 | G16: =SUM(G8:G15) -> 0 | H16: =E16-B16 -> 0 | I16: =IF(AND(B16=0,H16=0),0,IF(AND(B16=0,H16>0),1,H16/B16)) -> 0 | J16: =G16-D16 -> 0 | K16: =IF(AND(D16=0,J16=0),0,IF(AND(D16=0,J16>0),1,J16/D16)) -> 0
A17: 二、减值准备
A18: =A8 -> 0 | B18: ='明细表H2-2'!AI13 -> 0 | C18: ='明细表H2-2'!AM13 -> 0 | D18: =B18+C18 -> 0 | E18: ='明细表H2-2'!AL13 -> 0 | F18: ='明细表H2-2'!AM13+'明细表H2-2'!AN13-'明细表H2-2'!AO13 -> 0 | G18: =E18+F18 -> 0 | H18: =E18-B18 -> 0 | I18: =IF(AND(B18=0,H18=0),0,IF(AND(B18=0,H18>0),1,H18/B18)) -> 0 | J18: =G18-D18 -> 0 | K18: =IF(AND(D18=0,J18=0),0,IF(AND(D18=0,J18>0),1,J18/D18)) -> 0
A19: =A9 -> 0 | B19: ='明细表H2-2'!AI14 -> 0 | C19: ='明细表H2-2'!AM14 -> 0 | D19: =B19+C19 -> 0 | E19: ='明细表H2-2'!AL14 -> 0 | F19: ='明细表H2-2'!AM14+'明细表H2-2'!AN14-'明细表H2-2'!AO14 -> 0 | G19: =E19+F19 -> 0 | H19: =E19-B19 -> 0 | I19: =IF(AND(B19=0,H19=0),0,IF(AND(B19=0,H19>0),1,H19/B19)) -> 0 | J19: =G19-D19 -> 0 | K19: =IF(AND(D19=0,J19=0),0,IF(AND(D19=0,J19>0),1,J19/D19)) -> 0
A20: =A10 -> 0 | B20: ='明细表H2-2'!AI15 -> 0 | C20: ='明细表H2-2'!AM15 -> 0 | D20: =B20+C20 -> 0 | E20: ='明细表H2-2'!AL15 -> 0 | F20: ='明细表H2-2'!AM15+'明细表H2-2'!AN15-'明细表H2-2'!AO15 -> 0 | G20: =E20+F20 -> 0 | H20: =E20-B20 -> 0 | I20: =IF(AND(B20=0,H20=0),0,IF(AND(B20=0,H20>0),1,H20/B20)) -> 0 | J20: =G20-D20 -> 0 | K20: =IF(AND(D20=0,J20=0),0,IF(AND(D20=0,J20>0),1,J20/D20)) -> 0
A21: =A11 -> 0 | B21: ='明细表H2-2'!AI16 -> 0 | C21: ='明细表H2-2'!AM16 -> 0 | D21: =B21+C21 -> 0 | E21: ='明细表H2-2'!AL16 -> 0 | F21: ='明细表H2-2'!AM16+'明细表H2-2'!AN16-'明细表H2-2'!AO16 -> 0 | G21: =E21+F21 -> 0 | H21: =E21-B21 -> 0 | I21: =IF(AND(B21=0,H21=0),0,IF(AND(B21=0,H21>0),1,H21/B21)) -> 0 | J21: =G21-D21 -> 0 | K21: =IF(AND(D21=0,J21=0),0,IF(AND(D21=0,J21>0),1,J21/D21)) -> 0
A22: =A12 -> 0 | B22: ='明细表H2-2'!AI17 -> 0 | C22: ='明细表H2-2'!AM17 -> 0 | D22: =B22+C22 -> 0 | E22: ='明细表H2-2'!AL17 -> 0 | F22: ='明细表H2-2'!AM17+'明细表H2-2'!AN17-'明细表H2-2'!AO17 -> 0 | G22: =E22+F22 -> 0 | H22: =E22-B22 -> 0 | I22: =IF(AND(B22=0,H22=0),0,IF(AND(B22=0,H22>0),1,H22/B22)) -> 0 | J22: =G22-D22 -> 0 | K22: =IF(AND(D22=0,J22=0),0,IF(AND(D22=0,J22>0),1,J22/D22)) -> 0
A23: =A13 -> 0 | B23: ='明细表H2-2'!AI18 -> 0 | C23: ='明细表H2-2'!AM18 -> 0 | D23: =B23+C23 -> 0 | E23: ='明细表H2-2'!AL18 -> 0 | F23: ='明细表H2-2'!AM18+'明细表H2-2'!AN18-'明细表H2-2'!AO18 -> 0 | G23: =E23+F23 -> 0 | H23: =E23-B23 -> 0 | I23: =IF(AND(B23=0,H23=0),0,IF(AND(B23=0,H23>0),1,H23/B23)) -> 0 | J23: =G23-D23 -> 0 | K23: =IF(AND(D23=0,J23=0),0,IF(AND(D23=0,J23>0),1,J23/D23)) -> 0
A24: =A14 -> 0 | B24: ='明细表H2-2'!AI19 -> 0 | C24: ='明细表H2-2'!AM19 -> 0 | D24: =B24+C24 -> 0 | E24: ='明细表H2-2'!AL19 -> 0 | F24: ='明细表H2-2'!AM19+'明细表H2-2'!AN19-'明细表H2-2'!AO19 -> 0 | G24: =E24+F24 -> 0 | H24: =E24-B24 -> 0 | I24: =IF(AND(B24=0,H24=0),0,IF(AND(B24=0,H24>0),1,H24/B24)) -> 0 | J24: =G24-D24 -> 0 | K24: =IF(AND(D24=0,J24=0),0,IF(AND(D24=0,J24>0),1,J24/D24)) -> 0
A25: =A15 -> 0 | B25: ='明细表H2-2'!AI20 -> 0 | C25: ='明细表H2-2'!AM20 -> 0 | D25: =B25+C25 -> 0 | E25: ='明细表H2-2'!AL20 -> 0 | F25: ='明细表H2-2'!AM20+'明细表H2-2'!AN20-'明细表H2-2'!AO20 -> 0 | G25: =E25+F25 -> 0 | H25: =E25-B25 -> 0 | I25: =IF(AND(B25=0,H25=0),0,IF(AND(B25=0,H25>0),1,H25/B25)) -> 0 | J25: =G25-D25 -> 0 | K25: =IF(AND(D25=0,J25=0),0,IF(AND(D25=0,J25>0),1,J25/D25)) -> 0
A26: =A16 -> 合计 | B26: =SUM(B18:B25) -> 0 | C26: =SUM(C18:C25) -> 0 | D26: =SUM(D18:D25) -> 0 | E26: =SUM(E18:E25) -> 0 | F26: =SUM(F18:F25) -> 0 | G26: =SUM(G18:G25) -> 0 | H26: =E26-B26 -> 0 | I26: =IF(AND(B26=0,H26=0),0,IF(AND(B26=0,H26>0),1,H26/B26)) -> 0 | J26: =G26-D26 -> 0 | K26: =IF(AND(D26=0,J26=0),0,IF(AND(D26=0,J26>0),1,J26/D26)) -> 0
A27: 三、净值
A28: =A18 -> 0 | B28: =B8-B18 -> 0 | C28: =C8-C18 -> 0 | D28: =D8-D18 -> 0 | E28: =E8-E18 -> 0 | F28: =F8-F18 -> 0 | G28: =G8-G18 -> 0 | H28: =E28-B28 -> 0 | I28: =IF(AND(B28=0,H28=0),0,IF(AND(B28=0,H28>0),1,H28/B28)) -> 0 | J28: =G28-D28 -> 0 | K28: =IF(AND(D28=0,J28=0),0,IF(AND(D28=0,J28>0),1,J28/D28)) -> 0
A29: =A19 -> 0 | B29: =B9-B19 -> 0 | C29: =C9-C19 -> 0 | D29: =D9-D19 -> 0 | E29: =E9-E19 -> 0 | F29: =F9-F19 -> 0 | G29: =G9-G19 -> 0 | H29: =E29-B29 -> 0 | I29: =IF(AND(B29=0,H29=0),0,IF(AND(B29=0,H29>0),1,H29/B29)) -> 0 | J29: =G29-D29 -> 0 | K29: =IF(AND(D29=0,J29=0),0,IF(AND(D29=0,J29>0),1,J29/D29)) -> 0
A30: =A20 -> 0 | B30: =B10-B20 -> 0 | C30: =C10-C20 -> 0 | D30: =D10-D20 -> 0 | E30: =E10-E20 -> 0 | F30: =F10-F20 -> 0 | G30: =G10-G20 -> 0 | H30: =E30-B30 -> 0 | I30: =IF(AND(B30=0,H30=0),0,IF(AND(B30=0,H30>0),1,H30/B30)) -> 0 | J30: =G30-D30 -> 0 | K30: =IF(AND(D30=0,J30=0),0,IF(AND(D30=0,J30>0),1,J30/D30)) -> 0
A31: =A21 -> 0 | B31: =B11-B21 -> 0 | C31: =C11-C21 -> 0 | D31: =D11-D21 -> 0 | E31: =E11-E21 -> 0 | F31: =F11-F21 -> 0 | G31: =G11-G21 -> 0 | H31: =E31-B31 -> 0 | I31: =IF(AND(B31=0,H31=0),0,IF(AND(B31=0,H31>0),1,H31/B31)) -> 0 | J31: =G31-D31 -> 0 | K31: =IF(AND(D31=0,J31=0),0,IF(AND(D31=0,J31>0),1,J31/D31)) -> 0
A32: =A22 -> 0 | B32: =B12-B22 -> 0 | C32: =C12-C22 -> 0 | D32: =D12-D22 -> 0 | E32: =E12-E22 -> 0 | F32: =F12-F22 -> 0 | G32: =G12-G22 -> 0 | H32: =E32-B32 -> 0 | I32: =IF(AND(B32=0,H32=0),0,IF(AND(B32=0,H32>0),1,H32/B32)) -> 0 | J32: =G32-D32 -> 0 | K32: =IF(AND(D32=0,J32=0),0,IF(AND(D32=0,J32>0),1,J32/D32)) -> 0
A33: =A23 -> 0 | B33: =B13-B23 -> 0 | C33: =C13-C23 -> 0 | D33: =D13-D23 -> 0 | E33: =E13-E23 -> 0 | F33: =F13-F23 -> 0 | G33: =G13-G23 -> 0 | H33: =E33-B33 -> 0 | I33: =IF(AND(B33=0,H33=0),0,IF(AND(B33=0,H33>0),1,H33/B33)) -> 0 | J33: =G33-D33 -> 0 | K33: =IF(AND(D33=0,J33=0),0,IF(AND(D33=0,J33>0),1,J33/D33)) -> 0
A34: =A24 -> 0 | B34: =B14-B24 -> 0 | C34: =C14-C24 -> 0 | D34: =D14-D24 -> 0 | E34: =E14-E24 -> 0 | F34: =F14-F24 -> 0 | G34: =G14-G24 -> 0 | H34: =E34-B34 -> 0 | I34: =IF(AND(B34=0,H34=0),0,IF(AND(B34=0,H34>0),1,H34/B34)) -> 0 | J34: =G34-D34 -> 0 | K34: =IF(AND(D34=0,J34=0),0,IF(AND(D34=0,J34>0),1,J34/D34)) -> 0
A35: =A25 -> 0 | B35: =B15-B25 -> 0 | C35: =C15-C25 -> 0 | D35: =D15-D25 -> 0 | E35: =E15-E25 -> 0 | F35: =F15-F25 -> 0 | G35: =G15-G25 -> 0 | H35: =E35-B35 -> 0 | I35: =IF(AND(B35=0,H35=0),0,IF(AND(B35=0,H35>0),1,H35/B35)) -> 0 | J35: =G35-D35 -> 0 | K35: =IF(AND(D35=0,J35=0),0,IF(AND(D35=0,J35>0),1,J35/D35)) -> 0
A36: 合计 | B36: =SUM(B28:B35) -> 0 | C36: =SUM(C28:C35) -> 0 | D36: =SUM(D28:D35) -> 0 | E36: =SUM(E28:E35) -> 0 | F36: =SUM(F28:F35) -> 0 | G36: =SUM(G28:G35) -> 0 | H36: =E36-B36 -> 0 | I36: =IF(AND(B36=0,H36=0),0,IF(AND(B36=0,H36>0),1,H36/B36)) -> 0 | J36: =G36-D36 -> 0 | K36: =IF(AND(D36=0,J36=0),0,IF(AND(D36=0,J36>0),1,J36/D36)) -> 0
A37: 1、审计说明：
A38: （1）在建工程期末净值较期初净值增加（负数为减少）：
A39: 主要原因（比例超过30%的）：
A42: （2）本期转入固定资产：
...

Sheet 附注披露信息（上市公司）
A1: 致同会计师事务所
A2: 附注披露信息（上市公司）
A3: =底稿目录!A2 -> 被审计单位： | C3: =底稿目录!A4 -> 编制人： | F3: =底稿目录!A6 -> 编制日期： | H3: 索引号： | J3: 返回目录
A4: =底稿目录!A3 -> 截止日：202X年12月31日 | C4: =底稿目录!A5 -> 复核人： | F4: =底稿目录!A7 -> 复核日期： | H4: 页 次：
A6: 23、在建工程
A7: 项 目 | B7: 期末余额 | C7: 上年年末余额
A8: 在建工程
A9: 工程物资
A10: 合 计 | B10: X.XX | C10: X.XX
A11: （1）在建工程
A12: ①在建工程明细
A13: 项 目 | B13: 期末余额 | E13: 上年年末余额
B14: 账面余额 | C14: 减值准备 | D14: 账面净值 | E14: 账面余额 | F14: 减值准备 | G14: 账面净值
A19: 合 计 | B19: X.XX | C19: X.XX | D19: X.XX | E19: X.XX | F19: X.XX | G19: X.XX
A21: ②重要在建工程项目变动情况
A22: 工程名称 | B22: 期初余额 | C22: 本期增加 | D22: 转入固定资产 | E22: 其他减少 | F22: 利息资 | G22: 其中：本期利息资本化金额 | H22: 本期利 | I22: 期末余额
F23: 本化累 | H23: 息资本
F24: 计金额 | H24: 化率%
B25: A | C25: B | D25: C | E25: D | I25: E=A+B-C-D
A28: 合 计 | B28: X.XX | C28: X.XX | D28: X.XX | E28: X.XX | F28: X.XX | G28: X.XX | H28: -- | I28: X.XX
A30: 重要在建工程项目变动情况（续）：
A31: 工程名称 | B31: 预算数 | C31: 工程累计投入占预算比例% | D31: 工程进度 | E31: 资金来源
A35: 合 计 | B35: X.XX | C35: -- | D35: -- | E35: --
A36: （注：工程进度不一定是投入进度）
A37: 在建工程项目变动情况
A38: （资金来源应区分募股资金、金融机构贷款和自筹、其他来源等）
A39: ③在建工程减值准备情况
A40: 项 目 | B40: 期初余额 | C40: 本期计提 | D40: 本期减少 | E40: 期末余额
A44: 合 计
A46: 【长期资产本期进行减值测试的，应披露可收回金额的具体确定方法。可收回金额按公允价值减去处置费用后的净额确定的，应披露公允价值和处置费用的确定方式、关键参数及其确定依据。可收回金额按预计未来现金流量的现值确定的，应披露预测期的年限、预测期及稳定期的关键参数及其确定依据。前述信息与以前年度减值测试采用的信息或外部信息明显不一致的，或公司以前年度减值测试采用信息与当年实际情况明显不一致的，应披露差异原因。（15号文第十九条（十九）
A47: 注意：1、本年执行减值测试的，即使未计提减值，也要参照上述要求披露。2、估计可收回金额时通常不应使用重置成本法。】
A49: （2）工程物资
A50: 项 目 | B50: 期末余额 | C50: 上年年末余额
A51: 专用材料
A52: 专用设备
A53: 工器具
B54: X.XX | C54: X.XX
A55: 工程物资减值准备 | B55: (XX.XX) | C55: (XX.XX)
A56: 合 计 | B56: X.XX | C56: X.XX

Sheet 附注披露信息（国有企业）
A1: 致同会计师事务所
A2: 附注披露信息（国有企业）
A3: =底稿目录!A2 -> 被审计单位： | E3: =底稿目录!A4 -> 编制人： | H3: =底稿目录!A6 -> 编制日期： | L3: 索引号： | N3: 返回目录
A4: =底稿目录!A3 -> 截止日：202X年12月31日 | E4: =底稿目录!A5 -> 复核人： | H4: =底稿目录!A7 -> 复核日期： | L4: 页 次：
A6: 23、在建工程
A7: 项 目 | B7: 期末余额 | E7: 期初余额
B8: 账面余额 | C8: 减值准备 | D8: 账面价值 | E8: 账面余额 | F8: 减值准备 | G8: 账面价值
A9: 在建工程
A10: 工程物资
A11: 合 计
A13: （1）在建工程情况
A14: 项 目 | B14: 期末余额 | E14: 期初余额
B15: 账面余额 | C15: 减值准备 | D15: 账面价值 | E15: 账面余额 | F15: 减值准备 | G15: 账面价值
D20: -- | G20: --
A21: 合 计 | D21: X.XX | G21: X.XX
A23: （2）重要在建工程项目本期变动情况
A25: 项目名称 | B25: 预算数 | C25: 期初余额 | D25: 本期 | E25: 本期转入固 | F25: 本期其他 | G25: 期末 | H25: 工程累计投入占 | I25: 工程 | J25: 利息资本化 | K25: 其中：本期利息 | L25: 本期利息 | M25: 资金
D26: 增加 | E26: 定资产金额 | F26: 减少金额 | G26: 余额 | H26: 预算比例(%) | I26: 进度 | J26: 累计金额 | K26: 资本化金额 | L26: 资本化率(%) | M26: 来源
A27: 1
A28: 2
A29: 3
A30: 4
A31: 5
A32: …….
A38: 合 计 | H38: —— | I38: -- | L38: —— | M38: --
A40: （3）本期计提在建工程减值准备情况
A41: 项 目 | B41: 本期计提金额 | C41: 计提原因
A47: 合 计 | C47: --

Sheet 明细表H2-2
A1: 致同会计师事务所 | S1: 致同会计师事务所 | AI1: 致同会计师事务所
A2: 在建工程明细表 | S2: 在建工程明细表 | AI2: 在建工程明细表
A3: =底稿目录!A2 -> 被审计单位： | E3: =底稿目录!A4 -> 编制人： | K3: =底稿目录!A6 -> 编制日期： | Q3: 索引号： | R3: H2-2 | S3: =底稿目录!A2 -> 被审计单位： | Y3: =底稿目录!A4 -> 编制人： | AD3: =底稿目录!A6 -> 编制日期： | AG3: 索引号： | AH3: H2-2 | AI3: =底稿目录!A2 -> 被审计单位： | AM3: =底稿目录!A4 -> 编制人： | AQ3: =底稿目录!A6 -> 编制日期： | AW3: 索引号： | AX3: H2-2
A4: =底稿目录!A3 -> 截止日：202X年12月31日 | E4: =底稿目录!A5 -> 复核人： | K4: =底稿目录!A7 -> 复核日期： | Q4: 页 次： | S4: =底稿目录!A3 -> 截止日：202X年12月31日 | Y4: =底稿目录!A5 -> 复核人： | AD4: =底稿目录!A7 -> 复核日期： | AG4: 页 次： | AI4: =底稿目录!A3 -> 截止日：202X年12月31日 | AM4: =底稿目录!A5 -> 复核人： | AQ4: =底稿目录!A7 -> 复核日期： | AW4: 页 次：
A5: 一、审计目标:
A6: 1.资产负债表中记录的在建工程是存在的，且已记录于恰当的账户；2.所有应记录的在建工程均已记录，所有应当包括在财务报表中的相关披露均已包括；
A7: 3.在建工程以恰当的金额包括在财务报表中，与之相关的计价或分摊调整已恰当记录，相关披露已得到恰当计量和描述；
A8: 二、审计过程：
A9: 工程项目名称 | B9: 预算金额 | C9: 资金来源 | D9: 工程累计投入占预算比例% | E9: 预计完工时间 | F9: 工程进度 | G9: 完工日期 | H9: 批准文号 | I9: 利息资本化率 | J9: 原值 | AI9: 减值准备 | AT9: 期初净值 | AV9: 期末净值 | AX9: 是否抵押
J10: 未审数 | S10: 期初调整 | U10: 账项调整 | Z10: 审定数 | AI10: 未审数 | AM10: 期初调整 | AN10: 账项调整 | AP10: 审定数
J11: 期初数 | L11: 本期增加 | N11: 本期减少 | Q11: 期末数 | U11: 本期增加 | W11: 本期减少 | Z11: 期初数 | AB11: 本期增加 | AD11: 本期减少 | AG11: 期末数 | AI11: 期初数 | AJ11: 本期增加 | AK11: 本期减少 | AL11: 期末数 | AN11: 本期增加 | AO11: 本期减少 | AP11: 期初数 | AQ11: 本期增加 | AR11: 本期减少 | AS11: 期末数 | AT11: 未审净值 | AU11: 审定净值 | AV11: 未审净值 | AW11: 审定净值
J12: 余额 | K12: 其中：累计资本化金额 | L12: 增加 | M12: 其中：本期利息资本化金额 | N12: 本期转入固定资产 | O12: 其他减少 | P12: 其中：利息资本化金额减少金额 | Q12: 余额 | R12: 其中：累计资本化金额 | S12: 余额 | T12: 其中：累计资本化金额 | U12: 增加 | V12: 其中：本期利息资本化金额 | W12: 本期转入固定资产 | X12: 其他减少 | Y12: 其中：利息资本化金额减少金额 | Z12: 余额 | AA12: 其中：累计资本化金额 | AB12: 增加 | AC12: 其中：本期利息资本化金额 | AD12: 本期转入固定资产 | AE12: 其他减少 | AF12: 其中：利息资本化金额减少金额 | AG12: 余额 | AH12: 其中：累计资本化金额
D13: =IF(AH13=0,0,AH13/B13) -> 0 | Q13: =J13+L13-N13-O13 -> 0 | R13: =K13+M13-P13 -> 0 | Z13: =J13+S13 -> 0 | AA13: =K13+T13 -> 0 | AB13: =L13+U13 -> 0 | AC13: =M13+V13 -> 0 | AD13: =N13+W13 -> 0 | AE13: =O13+X13 -> 0 | AF13: =P13+Y13 -> 0 | AG13: =Z13+AB13-AD13-AE13 -> 0 | AH13: =AA13+AC13-AF13 -> 0 | AL13: =AI13+AJ13-AK13 -> 0 | AP13: =AI13+AM13 -> 0 | AQ13: =AJ13+AN13 -> 0 | AR13: =AK13+AO13 -> 0 | AS13: =AP13+AQ13-AR13 -> 0 | AT13: =J13-AI13 -> 0 | AU13: =Z13-AP13 -> 0 | AV13: =R13-AL13 -> 0 | AW13: =AH13-AS13 -> 0
D14: =IF(AH14=0,0,AH14/B14) -> 0 | Q14: =J14+L14-N14-O14 -> 0 | R14: =K14+M14-P14 -> 0 | Z14: =J14+S14 -> 0 | AA14: =K14+T14 -> 0 | AB14: =L14+U14 -> 0 | AC14: =M14+V14 -> 0 | AD14: =N14+W14 -> 0 | AE14: =O14+X14 -> 0 | AF14: =P14+Y14 -> 0 | AG14: =Z14+AB14-AD14-AE14 -> 0 | AH14: =AA14+AC14-AF14 -> 0 | AL14: =AI14+AJ14-AK14 -> 0 | AP14: =AI14+AM14 -> 0 | AQ14: =AJ14+AN14 -> 0 | AR14: =AK14+AO14 -> 0 | AS14: =AP14+AQ14-AR14 -> 0 | AT14: =J14-AI14 -> 0 | AU14: =Z14-AP14 -> 0 | AV14: =R14-AL14 -> 0 | AW14: =AH14-AS14 -> 0
D15: =IF(AH15=0,0,AH15/B15) -> 0 | Q15: =J15+L15-N15-O15 -> 0 | R15: =K15+M15-P15 -> 0 | Z15: =J15+S15 -> 0 | AA15: =K15+T15 -> 0 | AB15: =L15+U15 -> 0 | AC15: =M15+V15 -> 0 | AD15: =N15+W15 -> 0 | AE15: =O15+X15 -> 0 | AF15: =P15+Y15 -> 0 | AG15: =Z15+AB15-AD15-AE15 -> 0 | AH15: =AA15+AC15-AF15 -> 0 | AL15: =AI15+AJ15-AK15 -> 0 | AP15: =AI15+AM15 -> 0 | AQ15: =AJ15+AN15 -> 0 | AR15: =AK15+AO15 -> 0 | AS15: =AP15+AQ15-AR15 -> 0 | AT15: =J15-AI15 -> 0 | AU15: =Z15-AP15 -> 0 | AV15: =R15-AL15 -> 0 | AW15: =AH15-AS15 -> 0
D16: =IF(AH16=0,0,AH16/B16) -> 0 | Q16: =J16+L16-N16-O16 -> 0 | R16: =K16+M16-P16 -> 0 | Z16: =J16+S16 -> 0 | AA16: =K16+T16 -> 0 | AB16: =L16+U16 -> 0 | AC16: =M16+V16 -> 0 | AD16: =N16+W16 -> 0 | AE16: =O16+X16 -> 0 | AF16: =P16+Y16 -> 0 | AG16: =Z16+AB16-AD16-AE16 -> 0 | AH16: =AA16+AC16-AF16 -> 0 | AL16: =AI16+AJ16-AK16 -> 0 | AP16: =AI16+AM16 -> 0 | AQ16: =AJ16+AN16 -> 0 | AR16: =AK16+AO16 -> 0 | AS16: =AP16+AQ16-AR16 -> 0 | AT16: =J16-AI16 -> 0 | AU16: =Z16-AP16 -> 0 | AV16: =R16-AL16 -> 0 | AW16: =AH16-AS16 -> 0
D17: =IF(AH17=0,0,AH17/B17) -> 0 | Q17: =J17+L17-N17-O17 -> 0 | R17: =K17+M17-P17 -> 0 | Z17: =J17+S17 -> 0 | AA17: =K17+T17 -> 0 | AB17: =L17+U17 -> 0 | AC17: =M17+V17 -> 0 | AD17: =N17+W17 -> 0 | AE17: =O17+X17 -> 0 | AF17: =P17+Y17 -> 0 | AG17: =Z17+AB17-AD17-AE17 -> 0 | AH17: =AA17+AC17-AF17 -> 0 | AL17: =AI17+AJ17-AK17 -> 0 | AP17: =AI17+AM17 -> 0 | AQ17: =AJ17+AN17 -> 0 | AR17: =AK17+AO17 -> 0 | AS17: =AP17+AQ17-AR17 -> 0 | AT17: =J17-AI17 -> 0 | AU17: =Z17-AP17 -> 0 | AV17: =R17-AL17 -> 0 | AW17: =AH17-AS17 -> 0
D18: =IF(AH18=0,0,AH18/B18) -> 0 | Q18: =J18+L18-N18-O18 -> 0 | R18: =K18+M18-P18 -> 0 | Z18: =J18+S18 -> 0 | AA18: =K18+T18 -> 0 | AB18: =L18+U18 -> 0 | AC18: =M18+V18 -> 0 | AD18: =N18+W18 -> 0 | AE18: =O18+X18 -> 0 | AF18: =P18+Y18 -> 0 | AG18: =Z18+AB18-AD18-AE18 -> 0 | AH18: =AA18+AC18-AF18 -> 0 | AL18: =AI18+AJ18-AK18 -> 0 | AP18: =AI18+AM18 -> 0 | AQ18: =AJ18+AN18 -> 0 | AR18: =AK18+AO18 -> 0 | AS18: =AP18+AQ18-AR18 -> 0 | AT18: =J18-AI18 -> 0 | AU18: =Z18-AP18 -> 0 | AV18: =R18-AL18 -> 0 | AW18: =AH18-AS18 -> 0
D19: =IF(AH19=0,0,AH19/B19) -> 0 | Q19: =J19+L19-N19-O19 -> 0 | R19: =K19+M19-P19 -> 0 | Z19: =J19+S19 -> 0 | AA19: =K19+T19 -> 0 | AB19: =L19+U19 -> 0 | AC19: =M19+V19 -> 0 | AD19: =N19+W19 -> 0 | AE19: =O19+X19 -> 0 | AF19: =P19+Y19 -> 0 | AG19: =Z19+AB19-AD19-AE19 -> 0 | AH19: =AA19+AC19-AF19 -> 0 | AL19: =AI19+AJ19-AK19 -> 0 | AP19: =AI19+AM19 -> 0 | AQ19: =AJ19+AN19 -> 0 | AR19: =AK19+AO19 -> 0 | AS19: =AP19+AQ19-AR19 -> 0 | AT19: =J19-AI19 -> 0 | AU19: =Z19-AP19 -> 0 | AV19: =R19-AL19 -> 0 | AW19: =AH19-AS19 -> 0
D20: =IF(AH20=0,0,AH20/B20) -> 0 | Q20: =J20+L20-N20-O20 -> 0 | R20: =K20+M20-P20 -> 0 | Z20: =J20+S20 -> 0 | AA20: =K20+T20 -> 0 | AB20: =L20+U20 -> 0 | AC20: =M20+V20 -> 0 | AD20: =N20+W20 -> 0 | AE20: =O20+X20 -> 0 | AF20: =P20+Y20 -> 0 | AG20: =Z20+AB20-AD20-AE20 -> 0 | AH20: =AA20+AC20-AF20 -> 0 | AL20: =AI20+AJ20-AK20 -> 0 | AP20: =AI20+AM20 -> 0 | AQ20: =AJ20+AN20 -> 0 | AR20: =AK20+AO20 -> 0 | AS20: =AP20+AQ20-AR20 -> 0 | AT20: =J20-AI20 -> 0 | AU20: =Z20-AP20 -> 0 | AV20: =R20-AL20 -> 0 | AW20: =AH20-AS20 -> 0
A21: 合计 | J21: =SUM(J13:J20) -> 0 | K21: =SUM(K13:K20) -> 0 | L21: =SUM(L13:L20) -> 0 | M21: =SUM(M13:M20) -> 0 | N21: =SUM(N13:N20) -> 0 | O21: =SUM(O13:O20) -> 0 | P21: =SUM(P13:P20) -> 0 | Q21: =SUM(Q13:Q20) -> 0 | ... Z21: =SUM(Z13:Z20) -> 0 | AA21: =K21+T21 -> 0 | AB21: =SUM(AB13:AB20) -> 0 | AC21: =M21+V21 -> 0 | AD21: =SUM(AD13:AD20) -> 0 | AE21: =SUM(AE13:AE20) -> 0 | AF21: =SUM(AF13:AF20) -> 0 | AG21: =Z21+AB21-AD21-AE21 -> 0 | AH21: =AA21+AC21-AF21 -> 0 | AI21: =SUM(AI13:AI20) -> 0 | AJ21: =SUM(AJ13:AJ20) -> 0 | AK21: =SUM(AK13:AK20) -> 0 | AL21: =SUM(AL13:AL20) -> 0 | AM21: =SUM(AM13:AM20) -> 0 | AN21: =SUM(AN13:AN20) -> 0 | AO21: =SUM(AO13:AO20) -> 0 | AP21: =SUM(AP13:AP20) -> 0 | ... AW21: =SUM(AW13:AW20) -> 0
A22: 三、审计说明：
A25: 四、审计结论：
A29: 提示：
A30: 1.资金来源应区分募股资金、金融机构贷款和其他来源等。
A31: 2.用于确定借款费用资本化金额的资本化率应单独披露。
A32: 3.为购建或生产满足资本化条件的资产发生的应予资本化的借款费用，在“在建工程”、“制造费用”等科目核算。
A33: 4.符合资本化条件的资产，是指需要经过相当长时间的购建或者生产活动才能达到预定可使用或者可销售状态的固定资产、投资性房地产和存货等资产。
A34: 购入即可使用的资产，或者购入后需要安装但所需安装时间较短的资产，或者需要建造或生产但建造或生产时间较短的资产，均不属于符合资本化条件的资产，例如企业取得的采矿权等。
A35: 5.非房地产开发企业自行开发建造厂房等建筑物，土地使用权与建筑物应当分别进行会计处理，土地使用权的账面价值不与地上建筑物合并计算其成本，而仍作为无形资产进行会计处理。
A36: 在该情形下，土地使用权在取得时通常已达到预定使用状态，土地使用权不满足借款费用准则规定的“符合资本化条件的资产”定义。因此，根据借款费用准则，企业应当以建造支出
A37: （包括土地使用权在房屋建造期间计入在建工程的摊销金额）为基础，而不是以土地使用权支出为基础，确定应予资本化的借款费用金额。
A38: 6.企业应当将租赁负债视同为获取使用权资产而发生的专门借款。使用权资产作为一项权利资产，租赁期开始日即可供承租人使用，因而无论租赁资产本身是否达到企业计划用途，
... A41: 8.审计结论可参考：A、未见异常。 B、除上述重大不符事项应当作为调整事项予以调整外，其余未见异常。 C、由于存在以下重大未调整事项（或审计范围受到限制无法获取充分、适当证据），不可确认。

Sheet 调整分录汇总H2-3
A1: 致同会计师事务所
A2: 在建工程调整分录汇总表
A3: =底稿目录!A2 -> 被审计单位： | D3: =底稿目录!A4 -> 编制人： | G3: =底稿目录!A6 -> 编制日期： | I3: 索引号： | J3: H2-3
A4: =底稿目录!A3 -> 截止日：202X年12月31日 | D4: =底稿目录!A5 -> 复核人： | G4: =底稿目录!A7 -> 复核日期： | I4: 页 次：
A5: 调整事项说明 | B5: 类别（报表调整/账项调整/其他） | C5: 报表项目 | D5: 科目名称 | E5: 附注项目 | F5: …… | G5: 借方调整金额 | H5: 贷方调整金额 | I5: 索引 | J5: 备注
A24: 提示：本底稿适用于调整分录较多、较复杂的项目，且仅列示与本报表项目相关的审计调整。项目组可根据项目实际情况选择是否使用该底稿。

Sheet 分析表H2-4
A1: 致同会计师事务所
A2: 在建工程分析表
A3: =底稿目录!A2 -> 被审计单位： | C3: =底稿目录!A4 -> 编制人： | D3: =底稿目录!A6 -> 编制日期： | E3: 索引号： | F3: H2-4
A4: =底稿目录!A3 -> 截止日：202X年12月31日 | C4: =底稿目录!A5 -> 复核人： | D4: =底稿目录!A7 -> 复核日期： | E4: 页 次：
A5: 一、审计目标：
A6: 1.资产负债表中记录的在建工程是存在的，且已记录于恰当的账户；2.所有应记录的在建工程均已记录，所有应当包括在财务报表中的相关披露均已包括；
A7: 二、审计过程：
A8: 序号 | B8: 项目 | C8: 2025年 | D8: 2024年 | E8: 变动 | F8: 变动原因及合理性解释
A9: 1 | B9: 在建工程÷资产总额 | E9: =C9-D9 -> 0
A10: 2 | B10: 在建工程期末余额 | E10: =C10-D10 -> 0
A11: 3 | B11: 在建工程减值准备÷在建工程原值 | E11: =C11-D11 -> 0
A12: 4 | B12: 实际支出与预算的差异 | E12: =C12-D12 -> 0
A13: 5 | B13: 利息资本化率 | E13: =C13-D13 -> 0
A14: 6 | B14: 实际产出÷生产能力（产能利用率） | E14: =C14-D14 -> 0
A15: 7 | B15: …… | E15: =C15-D15 -> 0
A16: 三、审计说明：
A19: 四、审计结论：

Sheet 转固时点检查表H2-5
A1: 致同会计师事务所
A2: 转固时点检查表
A3: =底稿目录!A2 -> 被审计单位： | H3: =底稿目录!A4 -> 编制人： | K3: =底稿目录!A6 -> 编制日期： | M3: 索引号： | N3: H2-5
A4: =底稿目录!A3 -> 截止日：202X年12月31日 | H4: =底稿目录!A5 -> 复核人： | K4: =底稿目录!A7 -> 复核日期： | M4: 页 次：
A5: 一、审计目标：
A6: 1.资产负债表中记录的在建工程是存在的，且已记录于恰当的账户；2.所有应记录的在建工程均已记录，所有应当包括在财务报表中的相关披露均已包括；
A7: 3.在建工程以恰当的金额包括在财务报表中，与之相关的计价或分摊调整已恰当记录，相关披露已得到恰当计量和描述；
A8: 二、审计过程
A9: 1.期末重要在建工程完工及转固情况检查
A10: 工程项目名称/设备 | B10: 在建工程期末余额 | F10: 工程累计投入占预算比例% | G10: 计划完工/转固时间 | H10: 工程进度 | I10: 开工/到货时间 | J10: 达到预定可使用状态的评价标准 | K10: 工程/设备是否达到预定可使用状态或在用 | L10: 未转固原因 | M10: 是否存在异常 | N10: 期后转固情况
B11: 原值 | C11: 其中：累计利息资本化金额 | D11: 减值准备 | E11: 净值
A16: 2.本期重要已转固的在建工程转固时点检查
A17: 工程项目名称/设备 | B17: 固定资产期末余额 | F17: 转固时点 | G17: 竣工验收（决算）信息 | I17: 达到预定可使用状态的评价标准 | J17: 试生产日期 | K17: 正式投产日期 | L17: 是否存在异常
B18: 原值 | C18: 累计折旧 | D18: 减值准备 | E18: 净值 | G18: 竣工/验收日期 | H18: 决算金额
A25: 三、审计说明
A28: 四、审计结论

Sheet 在建工程审核记录H2-6
A1: 致同会计师事务所
A2: 在建工程－XX项目-XX子项目审核记录
A3: =底稿目录!A2 -> 被审计单位： | D3: =底稿目录!A4 -> 编制人： | H3: =底稿目录!A6 -> 编制日期： | J3: 索引号： | K3: H2-6
A4: =底稿目录!A3 -> 截止日：202X年12月31日 | D4: =底稿目录!A5 -> 复核人： | H4: =底稿目录!A7 -> 复核日期： | J4: 页 次：
A5: 1、项目综合描述：
A7: 2、资料及合同核对情况描述：
B8: A、详见资料核对表，索引（ ）
B9: B、详见合同核对表，索引（ ）
A10: 3、历年发生额情况描述：
B11: 年份 | C11: 期初数 | D11: 本期借方 | E11: 本期贷方 | F11: 期末数
B12: 开工年份 年
B13: …
B14: 本年
B15: 合计
A16: 5、本期发生额查验：详见索引（ ）
A17: 6、利息资本化审核：详见利息资本化复核底稿，索引（ ）
A18: 7、状态查验：
B19: （提示：结合实地观察，对照在建工程明细表，检查有无已达到预计可使用状态但尚未办理竣工决算手续仍列于
B20: 在建工程，如有，应作审计调整，并根据实际开始使用时间，相应计提累计折旧。观察时需注意有无长期停工的
B21: 半拉子工程或已安装的机器设备长期不用等异常情况。）
B22: （1）是否存在，有无实施现场察看，
B24: （2）目前状况描述（包括完工进度、是否达到预计可使用状态、是否暂停）
A26: 6、是否长期挂账：
B27: 重点关注一年未变动的在建工程
A29: 7、有无关联方交易：
B30: （提示：通过对在建工程增加、减少的查证，确定是否存在与关联方之间工程代开发、工程代管理、工程
B31: 承包等行为，如有，检查是否经适当授权，价格是否公允，向开发商、管理单位、承包商发函询证，形成查验记录，
B32: 并提请客户作必要披露。）
A34: 8、是否受限：
B35: （提示：可查询贷款卡信息，结合对工程项目建设资金来源如银行长期借款、发行债券等的检查，了解在建工程
B36: 是否存在已抵押、担保的情况，如有应作出记录，并提请客户作必要披露）
A38: 9、是否存在减值：详见索引（ ）

Sheet 工程造价比较表H2-7
A1: 致同会计师事务所
A2: 工程造价比较分析表
A3: =底稿目录!A2 -> 被审计单位： | D3: =底稿目录!A4 -> 编制人： | I3: =底稿目录!A6 -> 编制日期： | L3: 索引号： | M3: H2-7
A4: =底稿目录!A3 -> 截止日：202X年12月31日 | D4: =底稿目录!A5 -> 复核人： | I4: =底稿目录!A7 -> 复核日期： | L4: 页 次：
A5: 一、审计目标：1.资产负债表中记录的在建工程是存在的，且已记录于恰当的账户；
A6: 二、审计过程：
A7: 序号 | B7: 项目 | C7: 工程项目总造价 | D7: 建筑面积 | E7: 单方造价 | F7: 可比价1 | G7: 可比价2 | H7: 可比价3 | I7: 可比价来源索引 | J7: 本期增加额 | K7: 本期计入现金流量金额 | L7: 差异 | M7: 差异原因
A8: 1 | B8: 工程A | E8: =C8/D8 -> #DIV/0! | L8: =J8-K8 -> 0
A9: 2 | B9: 工程B | E9: =C9/D9 -> #DIV/0! | L9: =J9-K9 -> 0
A10: 3 | B10: 工程C | E10: =C10/D10 -> #DIV/0! | L10: =J10-K10 -> 0
A11: 4 | B11: …… | E11: =C11/D11 -> #DIV/0! | L11: =J11-K11 -> 0
A12: 三、审计说明：
A16: 四、审计结论：
A19: 提示：
A20: 1.通过募投项目可行性研究报告、工程预算文件等，获取工程项目总造价及建筑面积等信息；计算单方造价，并与可比价比较；
A21: 2.对比当期在建工程投入的现金支出与现金流量表中“购置固定资产、无形资产和其他长期资产支付的现金 ”项目金额是否存在重大差异；
A22: 3.如存在重大的非预期差异，与适当客户人员讨论；
A23: 4.确定执行上述程序的结果是否表明需要补充必要的审计程序，如果是，执行适当的应对程序。

Sheet 增加检查表H2-8
A1: 致同会计师事务所
A2: 在建工程增加检查表
A3: =底稿目录!A2 -> 被审计单位： | D3: =底稿目录!A4 -> 编制人： | H3: =底稿目录!A6 -> 编制日期： | V3: 索引号： | W3: H2-8
A4: =底稿目录!A3 -> 截止日：202X年12月31日 | D4: =底稿目录!A5 -> 复核人： | H4: =底稿目录!A7 -> 复核日期： | V4: 页 次：
A5: 一、审计目标：1.资产负债表中记录的在建工程是存在的，且已记录于恰当的账户；2.所有应记录的在建工程均已记录，所有应当包括在财务报表中的相关披露均已包括；3.记录的在建工程由被审计单位拥有或控制；4.在建工程以恰当的金额包括在财务报表中，与之相关的计价或分摊调整已恰当记录，相关披露已得到恰当计量和描述。
A6: 二、样本选取标准与规模：
A7: 测试总体： | B7: 如在建工程借方发生额所有凭证共XX笔金额XX | F7: 特定样本： | G7: XX金额以上（大额）、关联方/关联交易形成的款项、XX异常款项全部测试，共XX笔；
A8: 抽样总体： | B8: 测试总体扣除特定样本以外的样本，共XX笔、金额XX | F8: 确定的抽样样本量： | G8: 抽取XX笔 | H8: （如果使用了样本计算器计算样本量，样本量计算过程见<XX>底稿）
A9: 抽样方法： | B9: 随机选样/系统选样/货币单元抽样/随意选样（非统计抽样适用） | F9: 抽样过程： | G9: 使用IDEA（XX抽样工具）选择XX数量、金额XX的样本进行测试，抽样工具中的样本选择过程和结果见<XX>底稿
A10: 三、测试：
A11: 测试内容说明：1.原始凭证是否齐全； 2.记账凭证与原始凭证是否相符；3.账务处理是否正确；4.是否记录于恰当的会计期间；5.……
A12: 序号 | B12: 工程项目名称 | C12: 增加日期 | D12: 凭证编号 | E12: 增加方式 | F12: 对方科目 | G12: 增加情况 | I12: 合同/协议/订单 | L12: 监理报告 | N12: 领料单 | R12: 采购发票 | U12: …… | V12: 索引号 | W12: 是否异常
G13: 明细 | H13: 金额 | I13: 日期/编号 | J13: 对手方名称 | K13: 金额 | L13: 日期/编号 | M13: 完工情况 | N13: 日期/编号 | O13: 品名 | P13: 单位 | Q13: 数量 | R13: 日期/编号 | S13: 对手方名称 | T13: 金额 | X13: 检查的关键证据和要素根据被审计单位具体情况修改
A14: 1
A15: 2
A16: 3
A17: 4
A18: 5
A19: 6
A20: 7
A21: 8
A22: 9
A23: 10
A24: 11
A25: 12
... A28: 15
A29: ……
A30: 合计 | H30: =SUM(H14:H29) -> 0 | K30: =SUM(K14:K29) -> 0 | T30: =SUM(T14:T29) -> 0
A31: 本期增加在建工程合计 | H31: ='明细表H2-2'!AB21 -> 0
A32: 检查比例 | H32: =H30/H31 -> #DIV/0!
A33: 四、审计说明：
A34: 1.如果检查比例较低应扩大检查样本量或说明原因
A35: 2.……
A38: 五、审计结论：
A40: 提示
A41: 1.本表用于汇总本年度增加在建工程的测试情况。
A42: 2.取得有关工程项目的立项批文、预算总额及建设批准文件，施工承包合同、现场监理施工进度报告等业务资料；
A43: 3.抽查工程款是否按照合同、协议、工程进度或监理进度报告分期支付，其付款授权批准手续是否齐备，会计处理是否正确；
A44: 4.抽查工程物资的领用是否有审批手续，会计处理是否正确；
A45: 5.自行开发建造厂房等建筑物，相关的土地使用权与建筑物应分别进行处理，土地使用权应单独作为无形资产核算。
...

Sheet 减少检查表H2-9
A1: 致同会计师事务所
A2: 在建工程减少检查表
A3: =底稿目录!A2 -> 被审计单位： | E3: =底稿目录!A4 -> 编制人： | H3: =底稿目录!A6 -> 编制日期： | Q3: 索引号： | R3: H2-9
A4: =底稿目录!A3 -> 截止日：202X年12月31日 | E4: =底稿目录!A5 -> 复核人： | H4: =底稿目录!A7 -> 复核日期： | Q4: 页 次：
A5: 一、审计目标：1.资产负债表中记录的在建工程是存在的，且已记录于恰当的账户；2.所有应记录的在建工程均已记录，所有应当包括在财务报表中的相关披露均已包括；3.在建工程以恰当的金额包括在财务报表中，与之相关的计价或分摊调整已恰当记录，相关披露已得到恰当计量和描述
A6: 二、样本选取标准与规模：
A7: 测试总体： | B7: 如在建工程贷方发生额所有凭证共XX笔金额XX | F7: 特定样本： | G7: XX金额以上（大额）、关联方/关联交易形成的款项、XX异常款项全部测试，共XX笔； | H7: XX金额以上（大额）、关联方/关联交易形成的款项、XX异常款项全部测试，共XX笔；
A8: 抽样总体： | B8: 测试总体扣除特定样本以外的样本，共XX笔、金额XX | F8: 确定的抽样样本量： | G8: 抽取XX笔 | I8: （如果使用了样本计算器计算样本量，样本量计算过程见<XX>底稿）
A9: 抽样方法： | B9: 随机选样/系统选样/货币单元抽样/随意选样（非统计抽样适用） | F9: 抽样过程： | G9: 使用IDEA（XX抽样工具）选择XX数量、金额XX的样本进行测试，抽样工具中的样本选择过程和结果见<XX>底稿
A10: 三、测试：
A11: 测试内容说明：1.原始凭证是否齐全； 2.记账凭证与原始凭证是否相符；3.账务处理是否正确；4.是否记录于恰当的会计期间；5.……
A12: 序号 | B12: 工程项目名称 | C12: 减少日期 | D12: 凭证编号 | E12: 转入固定资产 | G12: 其他减少 | I12: 审批单 | K12: 验收单 | P12: …… | Q12: 索引号 | R12: 是否异常
E13: 金额 | F13: 其中：利息资本化金额 | G13: 金额 | H13: 其中：利息资本化金额 | I13: 日期/编号 | J13: 是否经过恰当审批 | K13: 验收日期 | L13: 金额 | M13: 工程部盖章 | N13: 施工方盖章 | O13: 监理方盖章 | S13: 检查的关键证据和要素根据被审计单位具体情况修改
A14: 1
A15: 2
A16: 3
A17: 4
A18: 5
A19: 6
A20: 7
A21: 8
A22: 9
A23: 10
A24: 合计 | E24: =SUM(E14:E23) -> 0 | F24: =SUM(F14:F23) -> 0 | G24: =SUM(G14:G23) -> 0 | H24: =SUM(H14:H23) -> 0
A25: 本期减少在建工程合计 | E25: ='明细表H2-2'!AD21 -> 0 | G25: ='明细表H2-2'!AF21 -> 0
A26: 减少比例 | E26: =E24/E25 -> #DIV/0! | G26: =G24/G25 -> #DIV/0!
A27: 四、审计说明：
A28: 1.如果检查比例较低应扩大检查样本量或说明原因
A29: 2.……
A32: 五、审计结论：
A35: 提示
A36: 1、本表用于汇总本年度减少在建工程的测试情况。
A37: 2、检查已完工程项目的竣工决算报告、验收交接单等相关凭证以及其他转出数的原始凭证，检查会计处理是否正确；
A38: 3、对已达到预定可使用状态但尚未办理竣工决算的在建工程，检查其是否按照估计价值转出有关固定资产成本,并计提折旧；
A39: 待办理竣工决算后，是否再按实际成本调整原来的暂估价值，但不需调整原已计提的折旧额。
A40: 4、关注是否存在将已经达到预定可使用状态的固定资产挂列在建工程，少计折旧的情况。
A41: 5、概述：（1）程序的测试情况、结果；
A42: （2）拟调整事项及其调整分录、未调整事项及其影响，审计范围受到限制情况及其影响。

Sheet 利息资本化测算表（无专门借款）H2-10
A1: 致同会计师事务所
A2: 在建工程利息资本化测算表（无专门借款）
A3: =底稿目录!A2 -> 被审计单位： | D3: =底稿目录!A4 -> 编制人： | H3: =底稿目录!A6 -> 编制日期： | K3: 索引号： | L3: H2-10
A4: =底稿目录!A3 -> 截止日：202X年12月31日 | D4: =底稿目录!A5 -> 复核人： | H4: =底稿目录!A7 -> 复核日期： | K4: 页 次：
A5: 一、审计目标：在建工程以恰当的金额包括在财务报表中，与之相关的计价或分摊调整已恰当记录，相关披露已得到恰当计量和描述。
A6: 二、审计过程：
A7: 1 | B7: 计算一般借款资本化加权平均年利率：
A8: 序号 | B8: 一般借款本金 | C8: 本期开始计息日 | D8: 本期结束计息日 | E8: 本期计息天数 | F8: 当期天数 | G8: 一般借款本金加权平均数 | H8: 一般借款当期实际发生的利息费用 | I8: 一般借款的资本化率＝一般借款加权平均利率(年利率)
B9: ① | E9: ② | F9: ③ | G9: ④＝①×②÷③ | H9: ⑤ | I9: ⑥=⑤÷④
A10: 1 | G10: =B10*E10/F10 -> #DIV/0! | I10: =IF(G10=0,0,H10/G10) -> #DIV/0!
A11: 2 | G11: =B11*E11/F11 -> #DIV/0! | I11: =IF(G11=0,0,H11/G11) -> #DIV/0!
A12: 3 | G12: =B12*E12/F12 -> #DIV/0! | I12: =IF(G12=0,0,H12/G12) -> #DIV/0!
A13: 4 | G13: =B13*E13/F13 -> #DIV/0! | I13: =IF(G13=0,0,H13/G13) -> #DIV/0!
A14: 5 | G14: =B14*E14/F14 -> #DIV/0! | I14: =IF(G14=0,0,H14/G14) -> #DIV/0!
A15: 6 | G15: =B15*E15/F15 -> #DIV/0! | I15: =IF(G15=0,0,H15/G15) -> #DIV/0!
A16: 合计 | B16: =SUM(B10:B15) -> 0 | E16: =SUM(E10:E15) -> 0 | F16: =SUM(F10:F15) -> 0 | G16: =SUM(G10:G15) -> #DIV/0! | H16: =SUM(H10:H15) -> 0
A17: 注：此表是计算企业全部一般借款的资本化率，如果一般借款是在本期发生增加和减少，需按当期使用天数占当期全部天数的比例作为权数将借款本金换算成一般借款年平均数。
A18: 如果一般借款在本期没有变化，则一般借款本金加权平均数等于一般借款本金。如果一般借款利率均一致,此利率即平均利率.
B19: 3、一般借款资本化加权平均月利率计算：
A20: 序号 | B20: 本月一般借款本金增加额① | C20: 一般借款本金累计余额②=①+期初本金累计余额 | D20: 一般借款在当月所使用的天数③ | E20: 当月天数④ | F20: 一般借款本金加权平均余额⑤=本期初本金累计余额+①×③÷④ | G20: 一般借款当月实际发生的利息费用⑥ | H20: 一般借款的资本化率＝一般借款加权平均利率(月利率)⑦=⑥÷⑤
A21: 期初 | B21: 111 | C21: 111 | D21: 2 | E21: 2 | F21: 2 | G21: 2 | H21: 0.02
A22: 1
A23: 2
A24: 3
A25: 4
A26: 5
A27: 6
A28: 7
A29: 8
A30: 9
A31: 10
A32: 11
A33: 12
A34: 合计 | B34: =SUM(B22:B33) -> 0 | G34: =SUM(G22:G33) -> 0
A35: 注：此表是计算企业全部一般借款的月资本化率，如果一般借款是在本月发生增加和减少，需按当月使用天数占当月全部天数的比例作为权数将借款本金换算成一般借款月平均数。
A36: 一般借款当期实际发生的利息费用可直接从公司账上取数
A37: 2 | B37: 测算一般借款利息资本化金额 | J37: 资本化率（月）：
A38: 项目 月份 | B38: 前期开发 | C38: 工程费用 | D38: 借款费用 | E38: 建安工程 | F38: 土地 | G38: 工程支出合计 | H38: 本年减少 | I38: 预付工程款 | J38: 加权平均支出 | K38: 资本化金额 | L38: 备注
B39: ① | C39: ② | D39: ③ | E39: ④ | F39: ⑤ | G39: ⑥＝①+②+…+⑤ | H39: ⑦ | I39: ⑧ | J39: ⑨＝T-1⑨+（⑥-③-⑦+⑧）/2 | K39: ⑩=⑨*资本化率（月）
A40: 年初余额 | G40: =SUM(B40:F40) -> 0 | J40: =G40+I40-D40 -> 0 | K40: =J40*$K$37 -> 0
...

Sheet 利息资本化测算表（有专门借款）H2-11
A1: 致同会计师事务所
A2: 在建工程利息资本化测算表（存在专门借款）
A3: =底稿目录!A2 -> 被审计单位： | F3: =底稿目录!A4 -> 编制人： | I3: =底稿目录!A6 -> 编制日期： | L3: 索引号： | M3: H2-11
A4: =底稿目录!A3 -> 截止日：202X年12月31日 | F4: =底稿目录!A5 -> 复核人： | I4: =底稿目录!A7 -> 复核日期： | L4: 页 次：
A5: 一、审计目标：在建工程以恰当的金额包括在财务报表中，与之相关的计价或分摊调整已恰当记录，相关披露已得到恰当计量和描述。
A6: 二、审计过程：
K7: 资本化率（月）：
A8: 项目 月份 | B8: 前期开发 | C8: 工程费用 | D8: 借款费用 | E8: 建安工程 | F8: 土地 | G8: 工程支出合计 | H8: 本年减少 | I8: 预付工程款 | J8: 专门借款 | K8: 加权平均支出 | L8: 资本化金额 | M8: 备注
B9: ① | C9: ② | D9: ③ | E9: ④ | F9: ⑤ | G9: ⑥＝①+②+…+⑤ | H9: ⑦ | I9: ⑧ | J9: SP | K9: ⑨＝T-1⑨+（⑥-③-⑦+⑧-SP）/2 | L9: ⑩=⑨*资本化率（月）
A10: 年初余额 | G10: =SUM(B10:F10) -> 0 | K10: =G10+I10-D10 -> 0 | L10: =K10*$L$7 -> 0
A11: 1月 | G11: =SUM(B11:F11) -> 0 | K11: =K10+(G11-H11-D11+I11-J11)/2 -> 0 | L11: =K11*$L$7 -> 0
A12: 2月 | G12: =SUM(B12:F12) -> 0 | K12: =K11+(G12-H12-D12+I12-J12)/2 -> 0 | L12: =K12*$L$7 -> 0
A13: 3月 | G13: =SUM(B13:F13) -> 0 | K13: =K12+(G13-H13-D13+I13-J13)/2 -> 0 | L13: =K13*$L$7 -> 0
A14: 4月 | G14: =SUM(B14:F14) -> 0 | K14: =K13+(G14-H14-D14+I14-J14)/2 -> 0 | L14: =K14*$L$7 -> 0
A15: 5月 | G15: =SUM(B15:F15) -> 0 | K15: =K14+(G15-H15-D15+I15-J15)/2 -> 0 | L15: =K15*$L$7 -> 0
A16: 6月 | G16: =SUM(B16:F16) -> 0 | K16: =K15+(G16-H16-D16+I16-J16)/2 -> 0 | L16: =K16*$L$7 -> 0
A17: 7月 | G17: =SUM(B17:F17) -> 0 | K17: =K16+(G17-H17-D17+I17-J17)/2 -> 0 | L17: =K17*$L$7 -> 0
A18: 8月 | G18: =SUM(B18:F18) -> 0 | K18: =K17+(G18-H18-D18+I18-J18)/2 -> 0 | L18: =K18*$L$7 -> 0
A19: 9月 | G19: =SUM(B19:F19) -> 0 | K19: =K18+(G19-H19-D19+I19-J19)/2 -> 0 | L19: =K19*$L$7 -> 0
A20: 10月 | G20: =SUM(B20:F20) -> 0 | K20: =K19+(G20-H20-D20+I20-J20)/2 -> 0 | L20: =K20*$L$7 -> 0
A21: 11月 | G21: =SUM(B21:F21) -> 0 | K21: =K20+(G21-H21-D21+I21-J21)/2 -> 0 | L21: =K21*$L$7 -> 0
A22: 12月 | G22: =SUM(B22:F22) -> 0 | K22: =K21+(G22-H22-D22+I22-J22)/2 -> 0 | L22: =K22*$L$7 -> 0
A23: 本年合计 | B23: =SUM(B11:B22) -> 0 | C23: =SUM(C11:C22) -> 0 | D23: =SUM(D11:D22) -> 0 | E23: =SUM(E11:E22) -> 0 | F23: =SUM(F11:F22) -> 0 | G23: =SUM(G11:G22) -> 0 | H23: =SUM(H11:H22) -> 0 | I23: =SUM(I11:I22) -> 0 | ... L23: =SUM(L11:L22) -> 0
A24: 本年转固 | G24: =SUM(B24:F24) -> 0 | K24: 专门借款利息净额
A25: 年末余额 | B25: =B10+B23-B24 -> 0 | C25: =C10+C23-C24 -> 0 | D25: =D10+D23-D24 -> 0 | E25: =E10+E23-E24 -> 0 | F25: =F10+F23-F24 -> 0 | G25: =G10+G23-G24 -> 0 | K25: 差异 | L25: =L23+L24-D23 -> 0 | M25: =L25/L23 -> #DIV/0!
A26: 测算说明： | H26: 测算结论：
B27: 根据工程支出及预付工程款余额，扣除专门借款未使用的部分， | H27: 审计调整：冲回多记入在建工程的资本化利息
B28: 计算每月加权平均支出数， | H28: Dr.财务费用－利息支出
B29: 再用每月加权平均支出累计余额乘月利率测算每月应资本化的利息。 | I29: Cr.在建工程－期间费用－贷款利息
A32: 提示：
A33: 1、关注：
A34: （1）利息资本化的开始和停止时间是否正确；
A35: （2）利息资本化率是否正确；
A36: （3）相关会计处理是否正确。
A38: 2、借款费用资本化
A39: A、取得借款合同，分别专门借款、一般借款（专门借款应当有明确的专门用途，即为购建或者生产某项符合资本化条件的资产而专门借入的款项，通常应有标明专门用途
A40: 的借款合同；一般借款是指除专门借款以外的其他借款）；
A41: B、按照实际占用资金的项目分摊利息费用：项目开工日期至竣工日期（建筑工程竣工验收备案表）发生的利息费用净额应资本化计入开发成本；
A42: C、利息资本化进行测算
A43: 专门借款：应当以专门借款当期实际发生的利息费用，减去将尚未动用的借款资金存入银行取得的利息收入或者进行暂时性投资取得的投资收益后的金额，确定为专门借款
...

Sheet 监盘计划H2-12
A1: 致同会计师事务所
A2: 在建工程监盘计划
A3: =底稿目录!A2 -> 被审计单位： | D3: =底稿目录!A4 -> 编制人： | F3: =底稿目录!A6 -> 编制日期： | H3: 索引号： | I3: H2-12
A4: =底稿目录!A3 -> 截止日：202X年12月31日 | D4: =底稿目录!A5 -> 复核人： | F4: =底稿目录!A7 -> 复核日期： | H4: 页 次：
A5: 被审计单位名称： | F5: 审计目标：
A6: 一、确定的在建工程存在性认定可能存在重大错报的风险程度：
A8: 二、了解被审计单位在建工程期末状况与管理规定：
A9: （一）在建工程的期末状况：
A10: 1．期末余额：
A11: 2．主要工程项目情况：
A12: 序号 | B12: 工程项目 | C12: 原值 | D12: 减值准备 | E12: 账面净值 | F12: 所处地点 | G12: 说明
A13: 1 | E13: =C13-D13 -> 0
A14: 2 | E14: =C14-D14 -> 0
A15: 3 | E15: =C15-D15 -> 0
A16: （二）企业定期盘点内部控制制度与执行情况：
A17: 1．制度名称：（提示：按企业内部控制制度名称填写） 索引号：（ ）
A18: （1）规定盘点的时间与次数：
A19: （2）负责盘点的部门： | F19: 负责人：
A20: （提示：如制度规定与实际执行不一致的，应按制度规定与实际负责的部门分别填写）
A21: 2．企业实际盘点情况：
A22: （1）盘点计划安排：
A23: （2）盘点会议情况：
A24: （3）预计安排的盘点人员数量： | F24: 负责人：
A25: （4）对企业盘点计划的评价：
A26: （三）查阅以前年度工作底稿记录：
A27: 1．上一年度监盘时间： | F27: 实施监盘的人员：
A28: 2．抽盘的在建工程范围： | F28: 抽盘比例：
A29: 3．实施监盘中发现的问题与存在的不足：
A30: （提示：上年度如是本所实施监盘的，应当查阅上一年度工作底稿；如不是本所实施审计的，应当在与前任会计师实施沟通程序中安排本项沟通内容。）
A31: 三、评估审计人员的专业胜任能力：
A33: 提示：针对特殊类型的存货，应当评估审计人员是否具备专业胜任能力
A34: 四、盘点计划安排：
A35: （一）预计监盘时间：
A36: （二）预计安排监盘人员数量： | F36: 监盘程序负责人：
A37: （三）预计监盘的在建工程范围：
A38: 1．类别范围：
A39: 类别 | B39: 期末余额 | C39: 减值准备 | D39: 账面净值 | E39: 计量单位 | F39: 数量 | G39: 计划监盘数量 | H39: 计划监盘金额 | I39: 监盘比例
A40: 啊啊 | B40: 1 | C40: 1 | D40: =B40-C40 -> 0 | E40: 啊 | F40: 1 | G40: 1 | H40: 1 | I40: 0.05
A43: 合计： | B43: =SUM(B40:B42) -> 1 | C43: =SUM(C40:C42) -> 1 | D43: =SUM(D40:D42) -> 0 | E43: =SUM(E40:E42) -> 0 | F43: =SUM(F40:F42) -> 1 | G43: =SUM(G40:G42) -> 1 | H43: =SUM(H40:H42) -> 1 | I43: =SUM(I40:I42) -> 0.05
A44: 2．地点范围：
...

Sheet 盘点检查表H2-13
A1: 致同会计师事务所
A2: 在建工程盘点检查表
A3: =底稿目录!A2 -> 被审计单位： | F3: =底稿目录!A4 -> 编制人： | K3: =底稿目录!A6 -> 编制日期： | N3: 索引号： | O3: H2-13
A4: =底稿目录!A3 -> 截止日：202X年12月31日 | F4: =底稿目录!A5 -> 复核人： | K4: =底稿目录!A7 -> 复核日期： | N4: 页 次：
A5: 一、审计目标：
A6: 1.资产负债表中记录的在建工程是存在的，且已记录于恰当的账户；2.在建工程以恰当的金额包括在财务报表中，与之相关的计价或分摊调整已恰当记录，相关披露已得到恰当计量和描述 。
A7: 二、样本选取标准与规模：
A8: 测试总体： | B8: 如期末在建工程项目数量XX、金额XX | G8: 特定样本： | H8: XX金额以上（大额）、关联方/关联交易形成的款项、XX异常款项全部测试，共XX笔；
A9: 抽样总体： | B9: 测试总体扣除特定样本以外的样本，数量XX、金额XX | G9: 确定的抽样样本量： | H9: 抽取XX笔 | I9: （如果使用了样本计算器计算样本量，样本量计算过程见<XX>底稿）
A10: 抽样方法： | B10: 随机选样/系统选样/货币单元抽样/随意选样（非统计抽样适用） | G10: 抽样过程： | H10: 使用IDEA（XX抽样工具）选择XX数量、金额XX的样本进行测试，抽样工具中的样本选择过程和结果见<XX>底稿
A11: 三、审计过程：
A12: 抽盘地点：______________ | C12: 盘点人员： | D12: 被审计单位仓库盘点人和财务监盘人签字 | I12: 监盘人员： | J12: （审计人员签字） | L12: 盘点时间：__________________
A13: 在建工程名称 | B13: 资产编号 | C13: 单价 | D13: 盘点前财务账面记录 | F13: 企业盘点记录数量 | G13: 抽盘数量 | H13: 抽盘与账面差异（+盈-亏） | I13: 抽盘与企业盘点差异 | J13: 企业盘点与账面差异 | K13: 进度状况描述 | L13: 是否达到可使用状态 | M13: 已停工时间 | N13: 停工原因 | O13: 备注
D14: 数量 | E14: 金额 | L14: （正常 | M14: （正常 | N14: （正常
H15: =G15-D15 -> 0 | I15: =G15-F15 -> 0 | J15: =F15-D15 -> 0
H16: =G16-D16 -> 0 | I16: =G16-F16 -> 0 | J16: =F16-D16 -> 0
H17: =G17-D17 -> 0 | I17: =G17-F17 -> 0 | J17: =F17-D17 -> 0
H18: =G18-D18 -> 0 | I18: =G18-F18 -> 0 | J18: =F18-D18 -> 0
H19: =G19-D19 -> 0 | I19: =G19-F19 -> 0 | J19: =F19-D19 -> 0
H20: =G20-D20 -> 0 | I20: =G20-F20 -> 0 | J20: =F20-D20 -> 0
A21: 合计 | D21: =SUM(D15:D20) -> 0 | E21: =SUM(E15:E20) -> 0 | F21: =SUM(F15:F20) -> 0 | G21: =SUM(G15:G20) -> 0 | H21: =SUM(H15:H20) -> 0 | I21: =SUM(I15:I20) -> 0 | J21: =SUM(J15:J20) -> 0
A22: 期末在建工程原值合计：
A23: 抽取样本占期末原值合计的比例：（%）
A25: 四、盘点情况说明：
A27: 五、审计结论：
A30: 提示：
A31: 1、本表可作为在建工程盘点汇总表或盘点明细表或固定资产抽盘表。
A32: 2、财务账面记录与资产管理管理部门账面记录应一致，若存在差异应调整一致。
A33: 3、财务账面记录与实际盘点记录的差异构成盘盈/盘亏，应根据具体原因分析处理。应说明企业的处理结果。
A34: 4、盘点时，应关注易移动的“存量资产”及可能发生减值的“存量资产”；
A35: 5、盘点时应关注资产的品质状况（影响减值准备的计提）。

Sheet 监盘小结H2-14
A1: 致同会计师事务所
A2: 在建工程监盘小结
A3: =底稿目录!A2 -> 被审计单位： | D3: =底稿目录!A4 -> 编制人： | F3: =底稿目录!A6 -> 编制日期： | H3: 索引号： | I3: H2-14
A4: =底稿目录!A3 -> 截止日：202X年12月31日 | D4: =底稿目录!A5 -> 复核人： | F4: =底稿目录!A7 -> 复核日期： | H4: 页 次：
A5: 一、资产负债表日：
A7: 二、实际现场察看前的检查程序：
A8: 1．工程管理部门: 管理人员：
A9: 2、在建工程管理制度设计是否合理: 是否有效执行： 索引：
A11: 三、参与察看人员及察看时间：
A12: 1． 被审计单位的人员：
A13: 序号 | B13: 盘点人员所属部门 | C13: 人员数量 | D13: 人员名称 | E13: 所负责的部分
A14: 1
A15: 2
A16: 3
A17: 2． 审计人员：
A18: 序号 | B18: 人员名称 | C18: 负责的部分
A19: 1
A20: 2
A21: 3
A22: 3 . 实际现场察看日： | D22: 开始时间： | G22: 结束时间：
A23: 四、实际现场察看情况说明
A24: （一）逐个工程项目形象进度等情况描述：
A25: 序号 | B25: 在建工程名称 | C25: 工程简图索引号 | D25: 工程地点 | E25: 工程项目形象进度等情况描述 | H25: 现场照片索引号
A26: 1 | B26: 项目1-xx
A27: 2 | B27: 项目2-xx
A28: 3 | B28: …
A29: 4
A30: 5
A31: （二）察看总体情况描述:
A32: 1、实际观察到的在建工程是否与会计账簿记载数量一致：
G33: 检查记录索引：
A34: 2、是否存在会计账簿未记载的工程：
A36: 3、获取的工程简图与现场是否一致：
A38: 4、现场察看的工程完工进度是否与账面记载一致，并与监理报告核对一致：
A40: 5、有无已达到预计可使用状态但尚未办理竣工决算手续仍列于在建工程的情况：
A42: 6、有无长期停工的工程：
A44: 五、现场察看中发现的异常情况说明：
A46: 六、工程现场察看结束工作说明：
A47: 1、工程现场察看结束后的工作记录：
A49: 2、对工程现场察看工作的评价：
...

Sheet 减值测算表H2-15
A1: 致同会计师事务所
A2: 在建工程减值测算表
A3: =底稿目录!A2 -> 被审计单位： | D3: =底稿目录!A4 -> 编制人： | G3: =底稿目录!A6 -> 编制日期： | K3: 索引号： | L3: H2-15
A4: =底稿目录!A3 -> 截止日：202X年12月31日 | D4: =底稿目录!A5 -> 复核人： | G4: =底稿目录!A7 -> 复核日期： | K4: 页 次：
A5: 一、审计目标: | B5: 在建工程以恰当的金额包括在财务报表中，与之相关的计价或分摊调整已恰当记录，相关披露已得到恰当计量和描述
A6: 二、审计过程：
A7: 工程项目名称 | B7: 是否存在减值迹象 | C7: 减值迹象描述 | D7: 账面价值 | E7: 可收回金额 | H7: 期末应计提的减值金额（当⑤＜②） | I7: 期末账面已计提的减值准备 | J7: 本期应补提 或冲回的减值准备 | K7: 工作底稿索引号 | L7: 备注
E8: 公允价值减处置费用的净额 | F8: 预计未来现金流量现值 | G8: 可收回金额（③、④较高者） | I8: 期末已计提 减值准备
C9: ① | D9: ② | E9: ③ | F9: ④ | G9: ⑤ | H9: ⑥＝⑤－② | I9: ⑦ | J9: ⑧=⑥-⑦
G10: =MAX(E10,F10) -> 0 | H10: =IF(D10>G10,D10-G10,0) -> 0 | J10: =H10-I10 -> 0
G11: =MAX(E11,F11) -> 0 | H11: =IF(D11>G11,D11-G11,0) -> 0 | J11: =H11-I11 -> 0
G12: =MAX(E12,F12) -> 0 | H12: =IF(D12>G12,D12-G12,0) -> 0 | J12: =H12-I12 -> 0
G13: =MAX(E13,F13) -> 0 | H13: =IF(D13>G13,D13-G13,0) -> 0 | J13: =H13-I13 -> 0
G14: =MAX(E14,F14) -> 0 | H14: =IF(D14>G14,D14-G14,0) -> 0 | J14: =H14-I14 -> 0
G15: =MAX(E15,F15) -> 0 | H15: =IF(D15>G15,D15-G15,0) -> 0 | J15: =H15-I15 -> 0
G16: =MAX(E16,F16) -> 0 | H16: =IF(D16>G16,D16-G16,0) -> 0 | J16: =H16-I16 -> 0
G17: =MAX(E17,F17) -> 0 | H17: =IF(D17>G17,D17-G17,0) -> 0 | J17: =H17-I17 -> 0
G18: =MAX(E18,F18) -> 0 | H18: =IF(D18>G18,D18-G18,0) -> 0 | J18: =H18-I18 -> 0
A19: 合计 | D19: =SUM(D10:D18) -> 0 | E19: =SUM(E10:E18) -> 0 | F19: =SUM(F10:F18) -> 0 | G19: =SUM(G10:G18) -> 0 | H19: =SUM(H10:H18) -> 0 | I19: =SUM(I10:I18) -> 0 | J19: =SUM(J10:J18) -> 0
A20: 三、审计说明：
A22: 四、审计结论：
A25: 提示：
A26: 1.获取或编制在建工程减值准备明细表，复核加计正确，并与总账数和明细账合计数核对相符；
A27: 2.检查在建工程减值准备计提和转销的批准程序，取得书面报告等证明文件；检查被审计单位计提在建工程减值准备的依据是否充分，会计处理是否正确；
A28: 3.检查在建工程转让时，相应的减值准备是否一并结转，会计处理是否正确；
A29: 4.重新测试被审计单位计提的减值准备是否合理；比较我们预期所估计减值准备和已记录的金额，调查所有重大差异。
A30: 5.上期确认的在建工程减值准备在本期的变动是否适当。
A31: 6.关注管理层对减值迹象的识别是否充分，建设项目是否存在无法如期完工投产的风险。（例如受政策、经济及技术等原因的影响。）
A32: 7.重点关注被审计单位是否建立、健全资产减值准备计提和各项损失核销的内部控制制度，对资产减值损失做出适当估计，并根据会计准则及相关规定合理计提减值准备。
A33: 8.重点关注被审计单位是否定期检查在建工程是否出现减值迹象，如出现减值迹象，是否根据实际情况对在建工程进行减值测试；重点分析被审计单位按照会计准则及相关规定，对其存在的不良资产充分计提资产减值准备。
A34: 9.结合在建工程项目的审计，检查相关会计资料，重点关注被审计单位是否存在以下情形：利用计提资产j减值准备人为调节各期利润，随意变更计提方法和计提比例，利用计提资产减值准备的机会“一次亏足”或随意调节利润的情形。

Sheet 可收回金额测试表H2-16
A1: 致同会计师事务所
A2: 在建工程减值准备测试表-可收回金额
A3: =底稿目录!A2 -> 被审计单位： | D3: =底稿目录!A4 -> 编制人： | J3: =底稿目录!A6 -> 编制日期： | M3: 索引号： | N3: H2-16
A4: =底稿目录!A3 -> 截止日：202X年12月31日 | D4: =底稿目录!A5 -> 复核人： | J4: =底稿目录!A7 -> 复核日期： | M4: 页 次：
A5: 一、审计目标: | B5: 在建工程以恰当的金额包括在财务报表中，与之相关的计价或分摊调整已恰当记录，相关披露已得到恰当计量和描述
A6: 二、审计过程：
A7: （一）资产的公允价值减去处置费用后的净额
A8: 工程项目名称 | B8: 公允价值 | H8: 处置费用（资产处置的直接归属费用） | N8: 公允价值-处置费用 | O8: 备注
B9: 销售协议价格 | C9: 说明 | D9: 资产活跃市场价格 | E9: 说明 | F9: 估计价格 | G9: 说明 | H9: 法律费用 | I9: 相关税费 | J9: 搬运费 | K9: 直接费用 | L9: 其他费用 | M9: 处置费用合计
M10: =SUM(H10:L10) -> 0 | N10: =IF(B10>0,B10,IF(D10>0,D10,F10))-M10 -> 0
M11: =SUM(H11:L11) -> 0 | N11: =IF(B11>0,B11,IF(D11>0,D11,F11))-M11 -> 0
M12: =SUM(H12:L12) -> 0 | N12: =IF(B12>0,B12,IF(D12>0,D12,F12))-M12 -> 0
A13: 合计 | B13: =SUM(B10:B12) -> 0 | D13: =SUM(D10:D12) -> 0 | F13: =SUM(F10:F12) -> 0 | H13: =SUM(H10:H12) -> 0 | I13: =SUM(I10:I12) -> 0 | J13: =SUM(J10:J12) -> 0 | K13: =SUM(K10:K12) -> 0 | L13: =SUM(L10:L12) -> 0 | M13: =SUM(M10:M12) -> 0 | N13: =SUM(N10:N12) -> 0
A14: 审计说明：
A15: （二）资产预计未来现金流量的现值
A16: 预计未来现金流量 | B16: 预算或者预测期 | G16: 以后年度 | I16: 行业的长期平均增长率 | J16: 市场长期平均增长率 | K16: 所在国家或地区的长期平均增长率 | L16: 增长率确定依据 | N16: 预计未来现金流量的现值 | O16: 备注
B17: 第一年 | C17: 第二年 | D17: 第三年 | E17: 第四年 | F17: 第五年 | G17: 基数 | H17: 增长率
A18: 预计未来现金净流量 | G18: =F18 -> 0
A19: 折现系数 | B19: =1/(1+$K$23)^1 -> #DIV/0! | C19: =1/(1+$K$23)^2 -> #DIV/0! | D19: =1/(1+$K$23)^3 -> #DIV/0! | E19: =1/(1+$K$23)^4 -> #DIV/0! | F19: =1/(1+$K$23)^5 -> #DIV/0! | G19: =(1+H18)/((J23-H18)*(1+K23)^5) -> #DIV/0! | H19: （企业管理层如能证明递增的增长率是合理的，可以以递增的增长率为基础。）
A20: 现值 | B20: =B18*B19 -> #DIV/0! | C20: =C18*C19 -> #DIV/0! | D20: =D18*D19 -> #DIV/0! | E20: =E18*E19 -> #DIV/0! | F20: =F18*F19 -> #DIV/0! | G20: =G18*G19 -> #DIV/0! | H20: （建立在预算或者预测基础上的预计现金流量最多涵盖5年，更长期间需证明合理性。） | N20: =SUM(B20:G20) -> #DIV/0!
A21: 折现率 | B21: 所得税率 | C21: 债务总额 D | D21: 资本总额 E | E21: 债务成本Kd | F21: 无风险报酬率Rf | G21: β系数 | H21: 市场平均收益率Rm | I21: 资本成本Ke | J21: WACC (税后) | K21: 折现率 (税前) | L21: 税后折税前调整说明 | N21: 可收回金额 | O21: 备注
B22: 适用税率 | L22: 税率调整 | M22: 调整说明
A23: 加权平均资金成本 | I23: =F23+G23*(H23-F23) -> 0 | J23: =((C23*E23*(1-B23)+D23*I23))/(C23+D23) -> #DIV/0! | K23: =J23/(1-(B23+L23)) -> #DIV/0! | N23: =MAX(N13,N20) -> #DIV/0!
A24: 审计说明：
A25: （三）可收回金额
B26: =N23 -> #DIV/0! | C26: 资产的公允价值减去处置费用后的净额与资产预计未来现金流量的现值两者之间较高者
A27: 三、审计说明：
A30: 四、审计结论
A32: 提示：
A33: 1、可收回金额应当根据资产的公允价值减去处置费用后的净额与资产预计未来现金流量的现值两者之间较高者确定。
A35: 2、资产的公允价值减去处置费用后的净额，应当根据公平交易中销售协议价格减去可直接归属于该资产处置费用的金额确定。不存在销售协议但存在资产活跃市场的，
A36: 应当按照该资产的市场价格减去处置费用后的金额确定。资产的市场价格通常应当根据资产的买方出价确定。在不存在销售协议和资产活跃市场的情况下，应当
A37: 以可获取的最佳信息为基础，估计资产的公允价值减去处置费用后的净额，该净额可以参考同行业类似资产的最近交易价格或者结果进行估计。企业按照上述规定
A38: 仍然无法可靠估计资产的公允价值减去处置费用后的净额的，应当以该资产预计未来现金流量的现值作为其可收回金额。
A39: 3、处置费用包括与资产处置有关的法律费用、相关税费、搬运费以及为使资产达到可销售状态所发生的直接费用等。
A41: 4、资产预计未来现金流量的现值，应当按照资产在持续使用过程中和最终处置时所产生的预计未来现金流量，选择恰当的折现率对其进行折现后的金额加以确定。
A42: 5、预计资产的未来现金流量，应当以经企业管理层批准的最近财务预算或者预测数据，以及该预算或者预测期之后年份稳定的或者递减的增长率为基础。
A43: 预计的资产未来现金流量应当包括下列各项：
... A63: 5.上期确认的在建工程减值准备在本期的变动是否适当。

Sheet 关联交易检查表H2-17
A1: 致同会计师事务所
A2: 关联交易检查表
A3: =底稿目录!A2 -> 被审计单位： | F3: =底稿目录!A4 -> 编制人： | H3: =底稿目录!A6 -> 编制日期： | M3: 索引号： | N3: H2-17
A4: =底稿目录!A3 -> 截止日：202X年12月31日 | F4: =底稿目录!A5 -> 复核人： | H4: =底稿目录!A7 -> 复核日期： | M4: 页 次：
A5: 一、审计目标:
A6: 1.资产负债表中记录的在建工程是存在的，且已记录于恰当的账户；2.所有应记录的在建工程均已记录，所有应当包括在财务报表中的相关披露均已包括；3.记录的在建工程由被审计单位拥有或控制。
A7: 4.在建工程以恰当的金额包括在财务报表中，与之相关的计价或分摊调整已恰当记录，相关披露已得到恰当计量和描述；5.在建工程已被恰当地汇总或分解且表述清楚，相关披露在按照企业会计准则的编制基础下是相关的、可理解的。
A8: 二、审计过程：
A9: （1）向合并范围外关联方采购在建工程
A10: 关联单位名称 | B10: 关联方关系 | C10: 资产类别 | D10: 购买在建工程名称 | E10: 购买价款 | F10: 在建工程入账价值 | G10: 占同类交易金额的比例％ | H10: 购入时间 | I10: 定价政策 | J10: 关联交易是否存在异常 | K10: 备注 | L10: 索引号
A18: （2）向合并范围外关联方出售在建工程
A19: 关联单位名称 | B19: 关联方关系 | C19: 资产类别 | D19: 出售在建工程名称 | E19: 出售时在建工程原值 | F19: 出售时减值准备 | G19: 出售时净值 | H19: 销售价格 （不含税） | I19: 占同类交易金额的比例％ | J19: 出售时间 | K19: 定价政策 | L19: 关联交易是否存在异常 | M19: 备注 | N19: 索引号
A27: 三、审计说明：
A32: 四、审计结论：
A37: 勿改、勿删
A38: 关联关系
A39: 实际控制人
A40: 控股股东
A41: 控股股东、实际控制人的附属企业
A42: 持有5%以上股份的法人或其他组织
A43: 联营企业
A44: 合营企业
A45: 董高监等关键管理人员
A46: 其他关联方
