Workbook

Sheet 底稿目录
A1: 底稿开列时，可先在以下单元格填写有关内容，以便其他底稿引用有关数据：
A2: 被审计单位：
A3: 截止日： | D3: 序号 | E3: 内容 | F3: 索引号 | G3: 备注
A4: 编制人： | D4: 1 | E4: 工程物资实质性程序表 | F4: H4A
A5: 复核人： | D5: =D4+1 -> 2 | E5: 审定表 | F5: H4-1
A6: 编制日期： | D6: =D5+1 -> 3 | E6: 附注披露信息（上市公司） | G6: 无需打印
A7: 复核日期： | D7: =D6+1 -> 4 | E7: 附注披露信息（国有企业） | G7: 无需打印
A8: 固定资产类别设置（以下内容请根据实际情况修改）： | D8: =D7+1 -> 5 | E8: 明细表 | F8: H4-2
A9: 专用材料 | D9: =D8+1 -> 6 | E9: 调整分录汇总 | F9: H4-3
A10: 专用设备 | D10: =D9+1 -> 7 | E10: 增加检查表 | F10: H4-4
A11: 工器具 | D11: =D10+1 -> 8 | E11: 减少检查表 | F11: H4-5
A12: 其他 | D12: =D11+1 -> 9 | E12: 盘点检查表 | F12: H4-6
A13: …… | D13: =D12+1 -> 10 | E13: 减值测算表 | F13: H4-7
D14: =D13+1 -> 11 | E14: 可收回金额测试表 | F14: H4-8
A15: 关于工作底稿与审计程序索引号对应的说明 | D15: =D14+1 -> 12 | E15: 关联交易检查表 | F15: H4-9
A16: 1.编制的审计工作底稿应与审计程序对应。审计项目组应根据被审计单位实际情况和风险评估情况在实质性程序表中裁剪、修改或增加审计程序，根据实际执行的审计程序完成相应审计工作底稿，编制的工作底稿中应按自然顺序依次编制索引号，并通过唯一的索引号将与实质性程序表中的程序对应关联（即将工作底稿的索引号填入实质性程序表中的底稿索引号列）。
A20: 2.获取的支持性证据应与审计底稿或程序对应。审计项目组在完成底稿时获取的支持性证据应根据底稿索引号编制下一级按自然顺序排序的索引号（如D1-2-1、D1-2-2、……），并在底稿中说明引用的支持性证据、关联索引号。
A23: 3.工作底稿索引号的编码规则：实质性程序索引号按循环从“D”到“N”,循环内账户以顺序号排列，模板中底稿索引号按账户顺序+自然数顺序（即模板中索引号按二级自然顺序排列，如D1-1、D1-2、D1-3、……D1-N）。

Sheet 工程物资实质性程序表H4A
A1: 致同会计师事务所
A2: 工程物资及减值准备实质性程序表
A3: =底稿目录!A2 -> 被审计单位： | C3: =底稿目录!A4 -> 编制人： | F3: =底稿目录!A6 -> 编制日期： | H3: 索引号： | I3: H4A
A4: =底稿目录!A3 -> 截止日： | C4: =底稿目录!A5 -> 复核人： | F4: =底稿目录!A7 -> 复核日期： | H4: 页 次：
A5: 一、本账户涉及的科目
A6: 工程物资、减值准备
A7: 二、审计目标与认定的对应关系
A8: 审计目标 | G8: 财务报表的认定
A9: A. 资产负债表中记录的工程物资是存在的，且已记录于恰当的账户 | G9: 存在
A10: B. 所有应记录的工程物资均已记录，所有应当包括在财务报表中的相关披露均已包括 | G10: 完整性
A11: C. 记录的工程物资产由被审计单位拥有或控制； | G11: 权利和义务
A12: D.工程物资以恰当的金额包括在财务报表中，与之相关的计价或分摊调整已恰当记录，相关披露已得到恰当计量和描述 | G12: 准确性、计价和分摊
A13: E. 工程物资已被恰当地汇总或分解且表述清楚，相关披露在按照企业会计准则的编制基础下是相关的、可理解的 | G13: 列报
A14: 三、计划实施的实质性程序
A15: 序号 | B15: 审计程序 | C15: 程序分类 | D15: 财务报表的认定 | I15: 底稿索引号
D16: 存在 | E16: 完整性 | F16: 权利和 义务 | G16: 准确性、计价和分摊 | H16: 列报 | J16: 根据被审计单位实际情况和风险评估情况裁剪、修改或增加审计程序
A17: 1 | B17: 获取或编制工程物资的明细表，完成以下工作，并编制审定表： （1）复核加计是否正确，并与总账数和明细账合计数核对是否相符，期初余额与上期审定期末余额是否相符； （2）分析工程物资与上期变动情况； | C17: 常规★ | D17: √ | E17: √ | G17: √ | I17: H4-1 /H4-2
A18: 2 | B18: 在使用手工编制、自定义信息报告、系统生成的非固定格式报告等由被审计单位生成的信息时，测试有关信息准确性和完整性，并考虑针对编制和维护由被审计单位生成的信息的相关控制实施控制测试，以评价该信息是否能够为实现审计目的提供基础。 | C18: 常规★ | E18: √ | G18: √ | I18: T1 / | J18: 可参见《审计手册》4.2.6，由被审计单位生成的信息可能是由系统生成的、或手工编制的、或二者兼而有之的方式生成的。例如，由被审计单位生成的信息可能包括： • 不涉及自定义的、由系统生成的报告（如，固定格式报告）； • 可能通过人工自定义的、由系统生成的报告，例如，（计算机）查询信息或特别定制的报告； • 手工编制的信息，例如，汇总信息的电子表格或用以支持分配、计算以及调节的电子表格； • 其他系统生成或手工编制的信息，例如，由被审计单位编制的客户发票； • 通过影印、拍摄、扫描或其他方式转换成电子形式的文件记录。
A19: 3 | B19: 对期初余额的审计，取得上期工程物资明细表复核加计是否正确，与总账、明细账合计数是否相符；检查期初工程物资在本期领用情况；对单项金额重大资产，进行实地查看资产或检查支持性文件，其他必要追加的审计程序。（适用于首次承接） | C19: 常规★ | D19: √ | E19: √ | F19: √ | G19: √ | J19: 由被审计单位生成的信息不包括： • 总分类账或明细分类账、试算平衡表、或经审计的财务报表； • 第三方（除了服务机构）的报表或报告，例如，原始银行对账单，或函证的回函； • 外部数据（例如，第三方发布的数据，如，定价来源）。
A20: 4 | B20: 关注会计政策、会计估计合理性、一贯性，关注其是否利用会计政策和会计估计及其变更操纵利润。 | C20: 常规★ | D20: √ | E20: √ | G20: √
A21: 5 | B21: 检查本期新增的工程物资：对于外购的工程物资，检查采购合同、发票、收货单等原始凭证，检查其是否经过授权批准，会计处理是否正确。 | C21: 常规★ | D21: √ | E21: √ | F21: √ | G21: √ | I21: H4-4
A22: 6 | B22: 检查本期减少的工程物资：结合在建工程审计，检查物资领用手续是否齐全、会计处理是否正确。 | C22: 常规★ | D22: √ | E22: √ | G22: √ | I22: H4-5
A23: 7 | B23: 其他方式增加或减少工程物资，考虑执行的程序： （1）对于非货币性资产交换、债务重组、企业合并、投资者投入等交易方式取得或减少的有关长期资产，检查相关合同/协议，关注计价是否正确、移交手续是否办理以及会计处理是否正确。 （2）对于因清产核资、资产评估调增有关长期资产价值的，检查有关清产核资报告、资产评估报告、国有资产管理等部门的确认文件、验资报告等，检查会计处理是否正确。 | C23: 备选 | D23: √ | E23: √ | F23: √ | G23: √ | I23: H4-4 /H4-5
A24: 8 | B24: 监盘工程物资： （1）了解工程物资形态、取得工程物资存放地点清单等，初步确定监盘方式、时间、监盘计划； （2）获取被审计单位对于工程物资的盘点计划，制定和实施监盘计划（如有）； （3）取得工程物资地点清单，初步确定监盘方式、时间、监盘计划； （4）观察被审计单位制定的盘点程序的执行情况 （5）抽取工程物资盘点，并检查工程物资的状态（在建、闲置、毁损等）； （6）评价工程物资盘点结果，完成监盘小结。 | C24: 常规★ | D24: √ | F24: √ | G24: √ | I24: H4-6
A25: 9 | B25: 存放其他地方的资产（如有），考虑实地观察或函证由其他人保管或保管在盘点地之外的工程物资。 | C25: 备选 | D25: √ | F25: √ | G25: √ | I25: H0
A26: 10 | B26: 结合工程物资清单和盘点程序，了解工程物资的状态。针对存在减值迹象的投资性房地产，考虑执行下列程序： （1）获取工程物资的减值明细表，考虑对该资产可能造成减值的事件或环境变化。 （2）获取被审计单位管理层在资产负债表日就工程物资是否存在可能发生减值迹象的判断说明及减值测试过程，关注计提减值准备的依据是否充分，减值测试过程是否合理，会计处理是否正确。 | C26: 常规★ | G26: √ | I26: H4-7 /H4-8
A27: 11 | B27: 检查关联交易情况，检查关联交易的真实性、合理性及合规性；检查关联交易会计处理是否正确，考虑是否存在未识别的关联方，检查关联交易和余额披露是否正确。 | C27: 常规★ | D27: √ | E27: √ | F27: √ | G27: √ | H27: √ | I27: H4-9
A28: 12 | B28: 根据评估的舞弊风险等因素增加的审计程序。 | C28: IPO/上市/新三板/重组/舞弊应对
A29: 13 | B29: 检查工程物资、抵押和担保情况等是否已按企业会计准则或其他适用的规定在财务报表中做出恰当列报和披露 | C29: 常规★ | H29: √ | I29: A 1-1/A1-15 /A1-16

Sheet 审定表H4-1
A1: 致同会计师事务所
A2: 工程物资及减值准备审定表
A3: =底稿目录!A2 -> 被审计单位： | D3: =底稿目录!A4 -> 编制人： | F3: =底稿目录!A6 -> 编制日期： | H3: 索引号： | I3: H4-1
A4: =底稿目录!A3 -> 截止日： | D4: =底稿目录!A5 -> 复核人： | F4: =底稿目录!A7 -> 复核日期： | H4: 页 次：
A5: 项目 | B5: 期初数 | E5: 期末数 | H5: 本期审定数与上期 审定数的比较
B6: 未审数 | C6: 账项调整 | D6: 审定数 | E6: 未审数 | F6: 账项调整 | G6: 审定数 | H6: 变动额 | I6: 变动率
A7: 一、工程物资原值
A8: =底稿目录!A9 -> 专用材料 | B8: ='明细表H4-2'!G30 -> 0 | C8: ='明细表H4-2'!R30 -> 0 | D8: =B8+C8 -> 0 | E8: ='明细表H4-2'!P30 -> 0 | F8: ='明细表H4-2'!R30+'明细表H4-2'!T30-'明细表H4-2'!V30 -> 0 | G8: =E8+F8 -> 0 | H8: =G8-D8 -> 0 | I8: =IF(AND(D8=0,H8=0),0,IF(AND(D8=0,H8>0),1,H8/D8)) -> 0
A9: =底稿目录!A10 -> 专用设备 | B9: ='明细表H4-2'!G31 -> 0 | C9: ='明细表H4-2'!R31 -> 0 | D9: =B9+C9 -> 0 | E9: ='明细表H4-2'!P31 -> 0 | F9: ='明细表H4-2'!R31+'明细表H4-2'!T31-'明细表H4-2'!V31 -> 0 | G9: =E9+F9 -> 0 | H9: =G9-D9 -> 0 | I9: =IF(AND(D9=0,H9=0),0,IF(AND(D9=0,H9>0),1,H9/D9)) -> 0
A10: =底稿目录!A11 -> 工器具 | B10: ='明细表H4-2'!G32 -> 0 | C10: ='明细表H4-2'!R32 -> 0 | D10: =B10+C10 -> 0 | E10: ='明细表H4-2'!P32 -> 0 | F10: ='明细表H4-2'!R32+'明细表H4-2'!T32-'明细表H4-2'!V32 -> 0 | G10: =E10+F10 -> 0 | H10: =G10-D10 -> 0 | I10: =IF(AND(D10=0,H10=0),0,IF(AND(D10=0,H10>0),1,H10/D10)) -> 0
A11: =底稿目录!A12 -> 其他 | B11: ='明细表H4-2'!G33 -> 0 | C11: ='明细表H4-2'!R33 -> 0 | D11: =B11+C11 -> 0 | E11: ='明细表H4-2'!P33 -> 0 | F11: ='明细表H4-2'!R33+'明细表H4-2'!T33-'明细表H4-2'!V33 -> 0 | G11: =E11+F11 -> 0 | H11: =G11-D11 -> 0 | I11: =IF(AND(D11=0,H11=0),0,IF(AND(D11=0,H11>0),1,H11/D11)) -> 0
A12: =底稿目录!A13 -> …… | B12: ='明细表H4-2'!G34 -> 0 | C12: ='明细表H4-2'!R34 -> 0 | D12: =B12+C12 -> 0 | E12: ='明细表H4-2'!P34 -> 0 | F12: ='明细表H4-2'!R34+'明细表H4-2'!T34-'明细表H4-2'!V34 -> 0 | G12: =E12+F12 -> 0 | H12: =G12-D12 -> 0 | I12: =IF(AND(D12=0,H12=0),0,IF(AND(D12=0,H12>0),1,H12/D12)) -> 0
A13: 合计 | B13: =SUM(B8:B12) -> 0 | C13: =SUM(C8:C12) -> 0 | D13: =SUM(D8:D12) -> 0 | E13: =SUM(E8:E12) -> 0 | F13: =SUM(F8:F12) -> 0 | G13: =SUM(G8:G12) -> 0 | H13: =SUM(H8:H12) -> 0 | I13: =IF(AND(D13=0,H13=0),0,IF(AND(D13=0,H13>0),1,H13/D13)) -> 0
A14: 二、减值准备
A15: =A8 -> 专用材料 | B15: ='明细表H4-2'!AI30 -> 0 | C15: ='明细表H4-2'!AM30 -> 0 | D15: =B15+C15 -> 0 | E15: ='明细表H4-2'!AL30 -> 0 | F15: ='明细表H4-2'!AM30+'明细表H4-2'!AN30-'明细表H4-2'!AO30 -> 0 | G15: =E15+F15 -> 0 | H15: =G15-D15 -> 0 | I15: =IF(AND(D15=0,H15=0),0,IF(AND(D15=0,H15>0),1,H15/D15)) -> 0
A16: =A9 -> 专用设备 | B16: ='明细表H4-2'!AI31 -> 0 | C16: ='明细表H4-2'!AM31 -> 0 | D16: =B16+C16 -> 0 | E16: ='明细表H4-2'!AL31 -> 0 | F16: ='明细表H4-2'!AM31+'明细表H4-2'!AN31-'明细表H4-2'!AO31 -> 0 | G16: =E16+F16 -> 0 | H16: =G16-D16 -> 0 | I16: =IF(AND(D16=0,H16=0),0,IF(AND(D16=0,H16>0),1,H16/D16)) -> 0
A17: =A10 -> 工器具 | B17: ='明细表H4-2'!AI32 -> 0 | C17: ='明细表H4-2'!AM32 -> 0 | D17: =B17+C17 -> 0 | E17: ='明细表H4-2'!AL32 -> 0 | F17: ='明细表H4-2'!AM32+'明细表H4-2'!AN32-'明细表H4-2'!AO32 -> 0 | G17: =E17+F17 -> 0 | H17: =G17-D17 -> 0 | I17: =IF(AND(D17=0,H17=0),0,IF(AND(D17=0,H17>0),1,H17/D17)) -> 0
A18: =A11 -> 其他 | B18: ='明细表H4-2'!AI33 -> 0 | C18: ='明细表H4-2'!AM33 -> 0 | D18: =B18+C18 -> 0 | E18: ='明细表H4-2'!AL33 -> 0 | F18: ='明细表H4-2'!AM33+'明细表H4-2'!AN33-'明细表H4-2'!AO33 -> 0 | G18: =E18+F18 -> 0 | H18: =G18-D18 -> 0 | I18: =IF(AND(D18=0,H18=0),0,IF(AND(D18=0,H18>0),1,H18/D18)) -> 0
A19: =A12 -> …… | B19: ='明细表H4-2'!AI34 -> 0 | C19: ='明细表H4-2'!AM34 -> 0 | D19: =B19+C19 -> 0 | E19: ='明细表H4-2'!AL34 -> 0 | F19: ='明细表H4-2'!AM34+'明细表H4-2'!AN34-'明细表H4-2'!AO34 -> 0 | G19: =E19+F19 -> 0 | H19: =G19-D19 -> 0 | I19: =IF(AND(D19=0,H19=0),0,IF(AND(D19=0,H19>0),1,H19/D19)) -> 0
A20: 合计 | B20: =SUM(B15:B19) -> 0 | C20: =SUM(C15:C19) -> 0 | D20: =SUM(D15:D19) -> 0 | E20: =SUM(E15:E19) -> 0 | F20: =SUM(F15:F19) -> 0 | G20: =SUM(G15:G19) -> 0 | H20: =SUM(H15:H19) -> 0 | I20: =IF(AND(D20=0,H20=0),0,IF(AND(D20=0,H20>0),1,H20/D20)) -> 0
A21: 三、净值
A22: =A8 -> 专用材料 | B22: =B8-B15 -> 0 | C22: =C8-C15 -> 0 | D22: =B22+C22 -> 0 | E22: =E8-E15 -> 0 | F22: =F8-F15 -> 0 | G22: =E22+F22 -> 0 | H22: =G22-D22 -> 0 | I22: =IF(AND(D22=0,H22=0),0,IF(AND(D22=0,H22>0),1,H22/D22)) -> 0
A23: =A9 -> 专用设备 | B23: =B9-B16 -> 0 | C23: =C9-C16 -> 0 | D23: =B23+C23 -> 0 | E23: =E9-E16 -> 0 | F23: =F9-F16 -> 0 | G23: =E23+F23 -> 0 | H23: =G23-D23 -> 0 | I23: =IF(AND(D23=0,H23=0),0,IF(AND(D23=0,H23>0),1,H23/D23)) -> 0
A24: =A10 -> 工器具 | B24: =B10-B17 -> 0 | C24: =C10-C17 -> 0 | D24: =B24+C24 -> 0 | E24: =E10-E17 -> 0 | F24: =F10-F17 -> 0 | G24: =E24+F24 -> 0 | H24: =G24-D24 -> 0 | I24: =IF(AND(D24=0,H24=0),0,IF(AND(D24=0,H24>0),1,H24/D24)) -> 0
A25: =A11 -> 其他 | B25: =B11-B18 -> 0 | C25: =C11-C18 -> 0 | D25: =B25+C25 -> 0 | E25: =E11-E18 -> 0 | F25: =F11-F18 -> 0 | G25: =E25+F25 -> 0 | H25: =G25-D25 -> 0 | I25: =IF(AND(D25=0,H25=0),0,IF(AND(D25=0,H25>0),1,H25/D25)) -> 0
A26: =A12 -> …… | B26: =B12-B19 -> 0 | C26: =C12-C19 -> 0 | D26: =B26+C26 -> 0 | E26: =E12-E19 -> 0 | F26: =F12-F19 -> 0 | G26: =E26+F26 -> 0 | H26: =G26-D26 -> 0 | I26: =IF(AND(D26=0,H26=0),0,IF(AND(D26=0,H26>0),1,H26/D26)) -> 0
A27: 合计 | B27: =SUM(B22:B26) -> 0 | C27: =SUM(C22:C26) -> 0 | D27: =SUM(D22:D26) -> 0 | E27: =SUM(E22:E26) -> 0 | F27: =SUM(F22:F26) -> 0 | G27: =SUM(G22:G26) -> 0 | H27: =SUM(H22:H26) -> 0 | I27: =IF(AND(D27=0,H27=0),0,IF(AND(D27=0,H27>0),1,H27/D27)) -> 0
A28: 1、审计说明：
A29: （1）工程物资期末净值较期初净值增加（负数为减少）：
A30: 主要原因（比例超过30%的）：
A33: （2）情况说明：
A35: （3）与经审计的财务报表核对
B36: 期末数 | C36: 期初数
A37: 在建工程审定数
A38: 工程物资审定数 | B38: =G27 -> 0 | C38: =D27 -> 0
A39: 在建工程与工程物资合计数 | B39: =B37+B38 -> 0 | C39: =C37+C38 -> 0
A40: 报表数
A41: 差异 | B41: =B39-B40 -> 0 | C41: =C39-C40 -> 0
A43: 2、审计结论：
A48: 提示：
...

Sheet 附注披露信息（上市公司）
A1: 致同会计师事务所
A2: 附注披露信息（上市公司）
A3: =底稿目录!A2 -> 被审计单位： | C3: =底稿目录!A4 -> 编制人： | D3: =底稿目录!A6 -> 编制日期： | E3: 索引号：
A4: =底稿目录!A3 -> 截止日： | C4: =底稿目录!A5 -> 复核人： | D4: =底稿目录!A7 -> 复核日期： | E4: 页 次：
F5: 返回目录
A6: 【在建工程与工程物资的合计数披露详见J2-1】
A7: （2）工程物资
A8: 项 目 | B8: 期末余额 | C8: 上年年末余额
A9: 专用材料
A10: 专用设备
A11: 工器具
B12: X.XX | C12: X.XX
A13: 工程物资减值准备 | B13: (XX.XX) | C13: (XX.XX)
A14: 合 计 | B14: X.XX | C14: X.XX

Sheet 附注披露信息（国有企业）
A1: 致同会计师事务所
A2: 附注披露信息（国有企业）
A3: =底稿目录!A2 -> 被审计单位： | B3: =底稿目录!A4 -> 编制人： | D3: =底稿目录!A6 -> 编制日期： | F3: 索引号：
A4: =底稿目录!A3 -> 截止日： | B4: =底稿目录!A5 -> 复核人： | D4: =底稿目录!A7 -> 复核日期： | F4: 页 次：
A6: 【在建工程与工程物资的合计数披露详见J2-1】 | H6: 返回目录
A7: 23、在建工程
A8: 项 目 | B8: 期末余额 | E8: 期初余额
B9: 账面余额 | C9: 减值准备 | D9: 账面价值 | E9: 账面余额 | F9: 减值准备 | G9: 账面价值
A10: 在建工程
A11: 工程物资
A12: 合 计

Sheet 明细表H4-2
A1: 致同会计师事务所 | AI1: 致同会计师事务所
A2: 工程物资明细表 | AI2: 工程物资明细表
A3: =底稿目录!A2 -> 被审计单位： | J3: =底稿目录!A4 -> 编制人： | V3: =底稿目录!A6 -> 编制日期： | AG3: 索引号： | AH3: H4-2 | AI3: =底稿目录!A2 -> 被审计单位： | AN3: =底稿目录!A4 -> 编制人： | AR3: =底稿目录!A6 -> 编制日期： | AV3: 索引号： | AW3: H4-2
A4: =底稿目录!A3 -> 截止日： | J4: =底稿目录!A5 -> 复核人： | V4: =底稿目录!A7 -> 复核日期： | AG4: 页 次： | AI4: =底稿目录!A3 -> 截止日： | AN4: =底稿目录!A5 -> 复核人： | AR4: =底稿目录!A7 -> 复核日期： | AV4: 页 次：
A5: 一、审计目标：
A6: 1. 资产负债表中记录的工程物资是存在的，且已记录于恰当的账户；2. 所有应记录的工程物资均已记录，所有应当包括在财务报表中的相关披露均已包括；4. 工程物资以恰当的金额包括在财务报表中，与之相关的计价或分摊调整已恰当记录，相关披露已得到恰当计量和描述；
A7: 二、审计过程：
A8: 序号 | B8: 工程物资类别 | C8: 工程物资名称 | D8: 计量单位 | E8: 原值 | AI8: 减值准备 | AT8: 期末净值 | AV8: 库龄 | AW8: 品质状况（正常、残次、毁损、滞销等）
E9: 未审数 | Q9: 期初调整 | S9: 账项调整 | W9: 审定数 | AI9: 未审数 | AM9: 期初调整 | AN9: 账项调整 | AP9: 审定数
E10: 期初数 | H10: 本期增加 | K10: 本期减少 | N10: 期末数 | Q10: 账项调整 | S10: 本期增加 | U10: 本期减少 | W10: 期初数 | Z10: 本期增加 | AC10: 本期减少 | AF10: 期末数 | AI10: 期初数 | AJ10: 本期增加 | AK10: 本期减少 | AL10: 期末数 | AN10: 本期增加 | AO10: 本期减少 | AP10: 期初数 | AQ10: 本期增加 | AR10: 本期减少 | AS10: 期末数 | AT10: 未审净值 | AU10: 审定净值
E11: 数量 | F11: 单价 | G11: 金额 | H11: 数量 | I11: 单价 | J11: 金额 | K11: 数量 | L11: 单价 | M11: 金额 | N11: 数量 | O11: 单价 | P11: 金额 | Q11: 数量 | R11: 金额 | S11: 数量 | T11: 金额 | U11: 数量 | V11: 金额 | W11: 数量 | X11: 单价 | Y11: 金额 | Z11: 数量 | AA11: 单价 | AB11: 金额 | AC11: 数量 | AD11: 单价 | AE11: 金额 | AF11: 数量 | AG11: 单价 | AH11: 金额
A12: 1 | F12: =G12/E12 -> #DIV/0! | I12: =J12/H12 -> #DIV/0! | L12: =M12/K12 -> #DIV/0! | N12: =E12+H12-K12 -> 0 | O12: =P12/N12 -> #DIV/0! | P12: =G12+J12-M12 -> 0 | W12: =E12+Q12 -> 0 | X12: =Y12/W12 -> #DIV/0! | Y12: =G12+R12 -> 0 | Z12: =H12+S12 -> 0 | AA12: =AB12/Z12 -> #DIV/0! | AB12: =J12+T12 -> 0 | AC12: =K12+U12 -> 0 | AD12: =AE12/AC12 -> #DIV/0! | AE12: =M12+V12 -> 0 | AF12: =W12+Z12-AC12 -> 0 | AG12: =AH12/AF12 -> #DIV/0! | AH12: =Y12+AB12-AE12 -> 0 | AL12: =AI12+AJ12-AK12 -> 0 | AP12: =AI12+AM12 -> 0 | AQ12: =AJ12+AN12 -> 0 | AR12: =AK12+AO12 -> 0 | AS12: =AP12+AQ12-AR12 -> 0 | AT12: =P12-AL12 -> 0 | AU12: =AH12-AS12 -> 0
A13: 2 | F13: =G13/E13 -> #DIV/0! | I13: =J13/H13 -> #DIV/0! | L13: =M13/K13 -> #DIV/0! | N13: =E13+H13-K13 -> 0 | O13: =P13/N13 -> #DIV/0! | P13: =G13+J13-M13 -> 0 | W13: =E13+Q13 -> 0 | X13: =Y13/W13 -> #DIV/0! | Y13: =G13+R13 -> 0 | Z13: =H13+S13 -> 0 | AA13: =AB13/Z13 -> #DIV/0! | AB13: =J13+T13 -> 0 | AC13: =K13+U13 -> 0 | AD13: =AE13/AC13 -> #DIV/0! | AE13: =M13+V13 -> 0 | AF13: =W13+Z13-AC13 -> 0 | AG13: =AH13/AF13 -> #DIV/0! | AH13: =Y13+AB13-AE13 -> 0 | AL13: =AI13+AJ13-AK13 -> 0 | AP13: =AI13+AM13 -> 0 | AQ13: =AJ13+AN13 -> 0 | AR13: =AK13+AO13 -> 0 | AS13: =AP13+AQ13-AR13 -> 0 | AT13: =P13-AL13 -> 0 | AU13: =AH13-AS13 -> 0
A14: 3 | F14: =G14/E14 -> #DIV/0! | I14: =J14/H14 -> #DIV/0! | L14: =M14/K14 -> #DIV/0! | N14: =E14+H14-K14 -> 0 | O14: =P14/N14 -> #DIV/0! | P14: =G14+J14-M14 -> 0 | W14: =E14+Q14 -> 0 | X14: =Y14/W14 -> #DIV/0! | Y14: =G14+R14 -> 0 | Z14: =H14+S14 -> 0 | AA14: =AB14/Z14 -> #DIV/0! | AB14: =J14+T14 -> 0 | AC14: =K14+U14 -> 0 | AD14: =AE14/AC14 -> #DIV/0! | AE14: =M14+V14 -> 0 | AF14: =W14+Z14-AC14 -> 0 | AG14: =AH14/AF14 -> #DIV/0! | AH14: =Y14+AB14-AE14 -> 0 | AL14: =AI14+AJ14-AK14 -> 0 | AP14: =AI14+AM14 -> 0 | AQ14: =AJ14+AN14 -> 0 | AR14: =AK14+AO14 -> 0 | AS14: =AP14+AQ14-AR14 -> 0 | AT14: =P14-AL14 -> 0 | AU14: =AH14-AS14 -> 0
A15: 4 | F15: =G15/E15 -> #DIV/0! | I15: =J15/H15 -> #DIV/0! | L15: =M15/K15 -> #DIV/0! | N15: =E15+H15-K15 -> 0 | O15: =P15/N15 -> #DIV/0! | P15: =G15+J15-M15 -> 0 | W15: =E15+Q15 -> 0 | X15: =Y15/W15 -> #DIV/0! | Y15: =G15+R15 -> 0 | Z15: =H15+S15 -> 0 | AA15: =AB15/Z15 -> #DIV/0! | AB15: =J15+T15 -> 0 | AC15: =K15+U15 -> 0 | AD15: =AE15/AC15 -> #DIV/0! | AE15: =M15+V15 -> 0 | AF15: =W15+Z15-AC15 -> 0 | AG15: =AH15/AF15 -> #DIV/0! | AH15: =Y15+AB15-AE15 -> 0 | AL15: =AI15+AJ15-AK15 -> 0 | AP15: =AI15+AM15 -> 0 | AQ15: =AJ15+AN15 -> 0 | AR15: =AK15+AO15 -> 0 | AS15: =AP15+AQ15-AR15 -> 0 | AT15: =P15-AL15 -> 0 | AU15: =AH15-AS15 -> 0
A16: 5 | F16: =G16/E16 -> #DIV/0! | I16: =J16/H16 -> #DIV/0! | L16: =M16/K16 -> #DIV/0! | N16: =E16+H16-K16 -> 0 | O16: =P16/N16 -> #DIV/0! | P16: =G16+J16-M16 -> 0 | W16: =E16+Q16 -> 0 | X16: =Y16/W16 -> #DIV/0! | Y16: =G16+R16 -> 0 | Z16: =H16+S16 -> 0 | AA16: =AB16/Z16 -> #DIV/0! | AB16: =J16+T16 -> 0 | AC16: =K16+U16 -> 0 | AD16: =AE16/AC16 -> #DIV/0! | AE16: =M16+V16 -> 0 | AF16: =W16+Z16-AC16 -> 0 | AG16: =AH16/AF16 -> #DIV/0! | AH16: =Y16+AB16-AE16 -> 0 | AL16: =AI16+AJ16-AK16 -> 0 | AP16: =AI16+AM16 -> 0 | AQ16: =AJ16+AN16 -> 0 | AR16: =AK16+AO16 -> 0 | AS16: =AP16+AQ16-AR16 -> 0 | AT16: =P16-AL16 -> 0 | AU16: =AH16-AS16 -> 0
A17: 6 | F17: =G17/E17 -> #DIV/0! | I17: =J17/H17 -> #DIV/0! | L17: =M17/K17 -> #DIV/0! | N17: =E17+H17-K17 -> 0 | O17: =P17/N17 -> #DIV/0! | P17: =G17+J17-M17 -> 0 | W17: =E17+Q17 -> 0 | X17: =Y17/W17 -> #DIV/0! | Y17: =G17+R17 -> 0 | Z17: =H17+S17 -> 0 | AA17: =AB17/Z17 -> #DIV/0! | AB17: =J17+T17 -> 0 | AC17: =K17+U17 -> 0 | AD17: =AE17/AC17 -> #DIV/0! | AE17: =M17+V17 -> 0 | AF17: =W17+Z17-AC17 -> 0 | AG17: =AH17/AF17 -> #DIV/0! | AH17: =Y17+AB17-AE17 -> 0 | AL17: =AI17+AJ17-AK17 -> 0 | AP17: =AI17+AM17 -> 0 | AQ17: =AJ17+AN17 -> 0 | AR17: =AK17+AO17 -> 0 | AS17: =AP17+AQ17-AR17 -> 0 | AT17: =P17-AL17 -> 0 | AU17: =AH17-AS17 -> 0
A18: 7 | F18: =G18/E18 -> #DIV/0! | I18: =J18/H18 -> #DIV/0! | L18: =M18/K18 -> #DIV/0! | N18: =E18+H18-K18 -> 0 | O18: =P18/N18 -> #DIV/0! | P18: =G18+J18-M18 -> 0 | W18: =E18+Q18 -> 0 | X18: =Y18/W18 -> #DIV/0! | Y18: =G18+R18 -> 0 | Z18: =H18+S18 -> 0 | AA18: =AB18/Z18 -> #DIV/0! | AB18: =J18+T18 -> 0 | AC18: =K18+U18 -> 0 | AD18: =AE18/AC18 -> #DIV/0! | AE18: =M18+V18 -> 0 | AF18: =W18+Z18-AC18 -> 0 | AG18: =AH18/AF18 -> #DIV/0! | AH18: =Y18+AB18-AE18 -> 0 | AL18: =AI18+AJ18-AK18 -> 0 | AP18: =AI18+AM18 -> 0 | AQ18: =AJ18+AN18 -> 0 | AR18: =AK18+AO18 -> 0 | AS18: =AP18+AQ18-AR18 -> 0 | AT18: =P18-AL18 -> 0 | AU18: =AH18-AS18 -> 0
A19: 8 | F19: =G19/E19 -> #DIV/0! | I19: =J19/H19 -> #DIV/0! | L19: =M19/K19 -> #DIV/0! | N19: =E19+H19-K19 -> 0 | O19: =P19/N19 -> #DIV/0! | P19: =G19+J19-M19 -> 0 | W19: =E19+Q19 -> 0 | X19: =Y19/W19 -> #DIV/0! | Y19: =G19+R19 -> 0 | Z19: =H19+S19 -> 0 | AA19: =AB19/Z19 -> #DIV/0! | AB19: =J19+T19 -> 0 | AC19: =K19+U19 -> 0 | AD19: =AE19/AC19 -> #DIV/0! | AE19: =M19+V19 -> 0 | AF19: =W19+Z19-AC19 -> 0 | AG19: =AH19/AF19 -> #DIV/0! | AH19: =Y19+AB19-AE19 -> 0 | AL19: =AI19+AJ19-AK19 -> 0 | AP19: =AI19+AM19 -> 0 | AQ19: =AJ19+AN19 -> 0 | AR19: =AK19+AO19 -> 0 | AS19: =AP19+AQ19-AR19 -> 0 | AT19: =P19-AL19 -> 0 | AU19: =AH19-AS19 -> 0
A20: 9 | F20: =G20/E20 -> #DIV/0! | I20: =J20/H20 -> #DIV/0! | L20: =M20/K20 -> #DIV/0! | N20: =E20+H20-K20 -> 0 | O20: =P20/N20 -> #DIV/0! | P20: =G20+J20-M20 -> 0 | W20: =E20+Q20 -> 0 | X20: =Y20/W20 -> #DIV/0! | Y20: =G20+R20 -> 0 | Z20: =H20+S20 -> 0 | AA20: =AB20/Z20 -> #DIV/0! | AB20: =J20+T20 -> 0 | AC20: =K20+U20 -> 0 | AD20: =AE20/AC20 -> #DIV/0! | AE20: =M20+V20 -> 0 | AF20: =W20+Z20-AC20 -> 0 | AG20: =AH20/AF20 -> #DIV/0! | AH20: =Y20+AB20-AE20 -> 0 | AL20: =AI20+AJ20-AK20 -> 0 | AP20: =AI20+AM20 -> 0 | AQ20: =AJ20+AN20 -> 0 | AR20: =AK20+AO20 -> 0 | AS20: =AP20+AQ20-AR20 -> 0 | AT20: =P20-AL20 -> 0 | AU20: =AH20-AS20 -> 0
A21: 10 | F21: =G21/E21 -> #DIV/0! | I21: =J21/H21 -> #DIV/0! | L21: =M21/K21 -> #DIV/0! | N21: =E21+H21-K21 -> 0 | O21: =P21/N21 -> #DIV/0! | P21: =G21+J21-M21 -> 0 | W21: =E21+Q21 -> 0 | X21: =Y21/W21 -> #DIV/0! | Y21: =G21+R21 -> 0 | Z21: =H21+S21 -> 0 | AA21: =AB21/Z21 -> #DIV/0! | AB21: =J21+T21 -> 0 | AC21: =K21+U21 -> 0 | AD21: =AE21/AC21 -> #DIV/0! | AE21: =M21+V21 -> 0 | AF21: =W21+Z21-AC21 -> 0 | AG21: =AH21/AF21 -> #DIV/0! | AH21: =Y21+AB21-AE21 -> 0 | AL21: =AI21+AJ21-AK21 -> 0 | AP21: =AI21+AM21 -> 0 | AQ21: =AJ21+AN21 -> 0 | AR21: =AK21+AO21 -> 0 | AS21: =AP21+AQ21-AR21 -> 0 | AT21: =P21-AL21 -> 0 | AU21: =AH21-AS21 -> 0
A22: 11 | F22: =G22/E22 -> #DIV/0! | I22: =J22/H22 -> #DIV/0! | L22: =M22/K22 -> #DIV/0! | N22: =E22+H22-K22 -> 0 | O22: =P22/N22 -> #DIV/0! | P22: =G22+J22-M22 -> 0 | W22: =E22+Q22 -> 0 | X22: =Y22/W22 -> #DIV/0! | Y22: =G22+R22 -> 0 | Z22: =H22+S22 -> 0 | AA22: =AB22/Z22 -> #DIV/0! | AB22: =J22+T22 -> 0 | AC22: =K22+U22 -> 0 | AD22: =AE22/AC22 -> #DIV/0! | AE22: =M22+V22 -> 0 | AF22: =W22+Z22-AC22 -> 0 | AG22: =AH22/AF22 -> #DIV/0! | AH22: =Y22+AB22-AE22 -> 0 | AL22: =AI22+AJ22-AK22 -> 0 | AP22: =AI22+AM22 -> 0 | AQ22: =AJ22+AN22 -> 0 | AR22: =AK22+AO22 -> 0 | AS22: =AP22+AQ22-AR22 -> 0 | AT22: =P22-AL22 -> 0 | AU22: =AH22-AS22 -> 0
A23: 12 | F23: =G23/E23 -> #DIV/0! | I23: =J23/H23 -> #DIV/0! | L23: =M23/K23 -> #DIV/0! | N23: =E23+H23-K23 -> 0 | O23: =P23/N23 -> #DIV/0! | P23: =G23+J23-M23 -> 0 | W23: =E23+Q23 -> 0 | X23: =Y23/W23 -> #DIV/0! | Y23: =G23+R23 -> 0 | Z23: =H23+S23 -> 0 | AA23: =AB23/Z23 -> #DIV/0! | AB23: =J23+T23 -> 0 | AC23: =K23+U23 -> 0 | AD23: =AE23/AC23 -> #DIV/0! | AE23: =M23+V23 -> 0 | AF23: =W23+Z23-AC23 -> 0 | AG23: =AH23/AF23 -> #DIV/0! | AH23: =Y23+AB23-AE23 -> 0 | AL23: =AI23+AJ23-AK23 -> 0 | AP23: =AI23+AM23 -> 0 | AQ23: =AJ23+AN23 -> 0 | AR23: =AK23+AO23 -> 0 | AS23: =AP23+AQ23-AR23 -> 0 | AT23: =P23-AL23 -> 0 | AU23: =AH23-AS23 -> 0
... A27: 16 | F27: =G27/E27 -> #DIV/0! | I27: =J27/H27 -> #DIV/0! | L27: =M27/K27 -> #DIV/0! | N27: =E27+H27-K27 -> 0 | O27: =P27/N27 -> #DIV/0! | P27: =G27+J27-M27 -> 0 | W27: =E27+Q27 -> 0 | X27: =Y27/W27 -> #DIV/0! | Y27: =G27+R27 -> 0 | Z27: =H27+S27 -> 0 | AA27: =AB27/Z27 -> #DIV/0! | AB27: =J27+T27 -> 0 | AC27: =K27+U27 -> 0 | AD27: =AE27/AC27 -> #DIV/0! | AE27: =M27+V27 -> 0 | AF27: =W27+Z27-AC27 -> 0 | AG27: =AH27/AF27 -> #DIV/0! | AH27: =Y27+AB27-AE27 -> 0 | AL27: =AI27+AJ27-AK27 -> 0 | AP27: =AI27+AM27 -> 0 | AQ27: =AJ27+AN27 -> 0 | AR27: =AK27+AO27 -> 0 | AS27: =AP27+AQ27-AR27 -> 0 | AT27: =P27-AL27 -> 0 | AU27: =AH27-AS27 -> 0
A28: 合计 | E28: =SUM(E12:E27) -> 0 | F28: =G28/E28 -> #DIV/0! | G28: =SUM(G12:G27) -> 0 | H28: =SUM(H12:H27) -> 0 | I28: =J28/H28 -> #DIV/0! | J28: =SUM(J12:J27) -> 0 | K28: =SUM(K12:K27) -> 0 | L28: =M28/K28 -> #DIV/0! | M28: =SUM(M12:M27) -> 0 | N28: =SUM(N12:N27) -> 0 | O28: =P28/N28 -> #DIV/0! | P28: =SUM(P12:P27) -> 0 | Q28: =SUM(Q12:Q27) -> 0 | R28: =SUM(R12:R27) -> 0 | S28: =SUM(S12:S27) -> 0 | T28: =SUM(T12:T27) -> 0 | U28: =SUM(U12:U27) -> 0 | V28: =SUM(V12:V27) -> 0 | W28: =SUM(W12:W27) -> 0 | X28: =Y28/W28 -> #DIV/0! | Y28: =SUM(Y12:Y27) -> 0 | Z28: =SUM(Z12:Z27) -> 0 | AA28: =AB28/Z28 -> #DIV/0! | AB28: =SUM(AB12:AB27) -> 0 | AC28: =SUM(AC12:AC27) -> 0 | AD28: =AE28/AC28 -> #DIV/0! | AE28: =SUM(AE12:AE27) -> 0 | AF28: =SUM(AF12:AF27) -> 0 | AG28: =AH28/AF28 -> #DIV/0! | AH28: =SUM(AH12:AH27) -> 0 | AI28: =SUM(AI12:AI27) -> 0 | AJ28: =SUM(AJ12:AJ27) -> 0 | AK28: =SUM(AK12:AK27) -> 0 | AL28: =SUM(AL12:AL27) -> 0 | AM28: =SUM(AM12:AM27) -> 0 | AN28: =SUM(AN12:AN27) -> 0 | AO28: =SUM(AO12:AO27) -> 0 | ... AU28: =SUM(AU12:AU27) -> 0
A29: 其中：
A30: =底稿目录!A9 -> 专用材料 | E30: =SUMPRODUCT(($B$12:$B$27=$A30)*(E$12:E$27)) -> 0 | G30: =SUMPRODUCT(($B$12:$B$27=$A30)*(G$12:G$27)) -> 0 | H30: =SUMPRODUCT(($B$12:$B$27=$A30)*(H$12:H$27)) -> 0 | J30: =SUMPRODUCT(($B$12:$B$27=$A30)*(J$12:J$27)) -> 0 | K30: =SUMPRODUCT(($B$12:$B$27=$A30)*(K$12:K$27)) -> 0 | M30: =SUMPRODUCT(($B$12:$B$27=$A30)*(M$12:M$27)) -> 0 | N30: =SUMPRODUCT(($B$12:$B$27=$A30)*(N$12:N$27)) -> 0 | P30: =SUMPRODUCT(($B$12:$B$27=$A30)*(P$12:P$27)) -> 0 | Q30: =SUMPRODUCT(($B$12:$B$27=$A30)*(Q$12:Q$27)) -> 0 | R30: =SUMPRODUCT(($B$12:$B$27=$A30)*(R$12:R$27)) -> 0 | S30: =SUMPRODUCT(($B$12:$B$27=$A30)*(S$12:S$27)) -> 0 | T30: =SUMPRODUCT(($B$12:$B$27=$A30)*(T$12:T$27)) -> 0 | U30: =SUMPRODUCT(($B$12:$B$27=$A30)*(U$12:U$27)) -> 0 | V30: =SUMPRODUCT(($B$12:$B$27=$A30)*(V$12:V$27)) -> 0 | W30: =SUMPRODUCT(($B$12:$B$27=$A30)*(W$12:W$27)) -> 0 | Y30: =SUMPRODUCT(($B$12:$B$27=$A30)*(Y$12:Y$27)) -> 0 | Z30: =SUMPRODUCT(($B$12:$B$27=$A30)*(Z$12:Z$27)) -> 0 | AB30: =SUMPRODUCT(($B$12:$B$27=$A30)*(AB$12:AB$27)) -> 0 | AC30: =SUMPRODUCT(($B$12:$B$27=$A30)*(AC$12:AC$27)) -> 0 | AE30: =SUMPRODUCT(($B$12:$B$27=$A30)*(AE$12:AE$27)) -> 0 | AF30: =SUMPRODUCT(($B$12:$B$27=$A30)*(AF$12:AF$27)) -> 0 | AH30: =SUMPRODUCT(($B$12:$B$27=$A30)*(AH$12:AH$27)) -> 0 | AI30: =SUMPRODUCT(($B$12:$B$27=$A30)*(AI$12:AI$27)) -> 0 | AJ30: =SUMPRODUCT(($B$12:$B$27=$A30)*(AJ$12:AJ$27)) -> 0 | AK30: =SUMPRODUCT(($B$12:$B$27=$A30)*(AK$12:AK$27)) -> 0 | AL30: =SUMPRODUCT(($B$12:$B$27=$A30)*(AL$12:AL$27)) -> 0 | AM30: =SUMPRODUCT(($B$12:$B$27=$A30)*(AM$12:AM$27)) -> 0 | AN30: =SUMPRODUCT(($B$12:$B$27=$A30)*(AN$12:AN$27)) -> 0 | AO30: =SUMPRODUCT(($B$12:$B$27=$A30)*(AO$12:AO$27)) -> 0 | ... AU30: =SUMPRODUCT(($B$12:$B$27=$A30)*(AU$12:AU$27)) -> 0
A31: =底稿目录!A10 -> 专用设备 | E31: =SUMPRODUCT(($B$12:$B$27=$A31)*(E$12:E$27)) -> 0 | G31: =SUMPRODUCT(($B$12:$B$27=$A31)*(G$12:G$27)) -> 0 | H31: =SUMPRODUCT(($B$12:$B$27=$A31)*(H$12:H$27)) -> 0 | J31: =SUMPRODUCT(($B$12:$B$27=$A31)*(J$12:J$27)) -> 0 | K31: =SUMPRODUCT(($B$12:$B$27=$A31)*(K$12:K$27)) -> 0 | M31: =SUMPRODUCT(($B$12:$B$27=$A31)*(M$12:M$27)) -> 0 | N31: =SUMPRODUCT(($B$12:$B$27=$A31)*(N$12:N$27)) -> 0 | P31: =SUMPRODUCT(($B$12:$B$27=$A31)*(P$12:P$27)) -> 0 | Q31: =SUMPRODUCT(($B$12:$B$27=$A31)*(Q$12:Q$27)) -> 0 | R31: =SUMPRODUCT(($B$12:$B$27=$A31)*(R$12:R$27)) -> 0 | S31: =SUMPRODUCT(($B$12:$B$27=$A31)*(S$12:S$27)) -> 0 | T31: =SUMPRODUCT(($B$12:$B$27=$A31)*(T$12:T$27)) -> 0 | U31: =SUMPRODUCT(($B$12:$B$27=$A31)*(U$12:U$27)) -> 0 | V31: =SUMPRODUCT(($B$12:$B$27=$A31)*(V$12:V$27)) -> 0 | W31: =SUMPRODUCT(($B$12:$B$27=$A31)*(W$12:W$27)) -> 0 | Y31: =SUMPRODUCT(($B$12:$B$27=$A31)*(Y$12:Y$27)) -> 0 | Z31: =SUMPRODUCT(($B$12:$B$27=$A31)*(Z$12:Z$27)) -> 0 | AB31: =SUMPRODUCT(($B$12:$B$27=$A31)*(AB$12:AB$27)) -> 0 | AC31: =SUMPRODUCT(($B$12:$B$27=$A31)*(AC$12:AC$27)) -> 0 | AE31: =SUMPRODUCT(($B$12:$B$27=$A31)*(AE$12:AE$27)) -> 0 | AF31: =SUMPRODUCT(($B$12:$B$27=$A31)*(AF$12:AF$27)) -> 0 | AH31: =SUMPRODUCT(($B$12:$B$27=$A31)*(AH$12:AH$27)) -> 0 | AI31: =SUMPRODUCT(($B$12:$B$27=$A31)*(AI$12:AI$27)) -> 0 | AJ31: =SUMPRODUCT(($B$12:$B$27=$A31)*(AJ$12:AJ$27)) -> 0 | AK31: =SUMPRODUCT(($B$12:$B$27=$A31)*(AK$12:AK$27)) -> 0 | AL31: =SUMPRODUCT(($B$12:$B$27=$A31)*(AL$12:AL$27)) -> 0 | AM31: =SUMPRODUCT(($B$12:$B$27=$A31)*(AM$12:AM$27)) -> 0 | AN31: =SUMPRODUCT(($B$12:$B$27=$A31)*(AN$12:AN$27)) -> 0 | AO31: =SUMPRODUCT(($B$12:$B$27=$A31)*(AO$12:AO$27)) -> 0 | ... AU31: =SUMPRODUCT(($B$12:$B$27=$A31)*(AU$12:AU$27)) -> 0
A32: =底稿目录!A11 -> 工器具 | E32: =SUMPRODUCT(($B$12:$B$27=$A32)*(E$12:E$27)) -> 0 | G32: =SUMPRODUCT(($B$12:$B$27=$A32)*(G$12:G$27)) -> 0 | H32: =SUMPRODUCT(($B$12:$B$27=$A32)*(H$12:H$27)) -> 0 | J32: =SUMPRODUCT(($B$12:$B$27=$A32)*(J$12:J$27)) -> 0 | K32: =SUMPRODUCT(($B$12:$B$27=$A32)*(K$12:K$27)) -> 0 | M32: =SUMPRODUCT(($B$12:$B$27=$A32)*(M$12:M$27)) -> 0 | N32: =SUMPRODUCT(($B$12:$B$27=$A32)*(N$12:N$27)) -> 0 | P32: =SUMPRODUCT(($B$12:$B$27=$A32)*(P$12:P$27)) -> 0 | Q32: =SUMPRODUCT(($B$12:$B$27=$A32)*(Q$12:Q$27)) -> 0 | R32: =SUMPRODUCT(($B$12:$B$27=$A32)*(R$12:R$27)) -> 0 | S32: =SUMPRODUCT(($B$12:$B$27=$A32)*(S$12:S$27)) -> 0 | T32: =SUMPRODUCT(($B$12:$B$27=$A32)*(T$12:T$27)) -> 0 | U32: =SUMPRODUCT(($B$12:$B$27=$A32)*(U$12:U$27)) -> 0 | V32: =SUMPRODUCT(($B$12:$B$27=$A32)*(V$12:V$27)) -> 0 | W32: =SUMPRODUCT(($B$12:$B$27=$A32)*(W$12:W$27)) -> 0 | Y32: =SUMPRODUCT(($B$12:$B$27=$A32)*(Y$12:Y$27)) -> 0 | Z32: =SUMPRODUCT(($B$12:$B$27=$A32)*(Z$12:Z$27)) -> 0 | AB32: =SUMPRODUCT(($B$12:$B$27=$A32)*(AB$12:AB$27)) -> 0 | AC32: =SUMPRODUCT(($B$12:$B$27=$A32)*(AC$12:AC$27)) -> 0 | AE32: =SUMPRODUCT(($B$12:$B$27=$A32)*(AE$12:AE$27)) -> 0 | AF32: =SUMPRODUCT(($B$12:$B$27=$A32)*(AF$12:AF$27)) -> 0 | AH32: =SUMPRODUCT(($B$12:$B$27=$A32)*(AH$12:AH$27)) -> 0 | AI32: =SUMPRODUCT(($B$12:$B$27=$A32)*(AI$12:AI$27)) -> 0 | AJ32: =SUMPRODUCT(($B$12:$B$27=$A32)*(AJ$12:AJ$27)) -> 0 | AK32: =SUMPRODUCT(($B$12:$B$27=$A32)*(AK$12:AK$27)) -> 0 | AL32: =SUMPRODUCT(($B$12:$B$27=$A32)*(AL$12:AL$27)) -> 0 | AM32: =SUMPRODUCT(($B$12:$B$27=$A32)*(AM$12:AM$27)) -> 0 | AN32: =SUMPRODUCT(($B$12:$B$27=$A32)*(AN$12:AN$27)) -> 0 | AO32: =SUMPRODUCT(($B$12:$B$27=$A32)*(AO$12:AO$27)) -> 0 | ... AU32: =SUMPRODUCT(($B$12:$B$27=$A32)*(AU$12:AU$27)) -> 0
A33: =底稿目录!A12 -> 其他 | E33: =SUMPRODUCT(($B$12:$B$27=$A33)*(E$12:E$27)) -> 0 | G33: =SUMPRODUCT(($B$12:$B$27=$A33)*(G$12:G$27)) -> 0 | H33: =SUMPRODUCT(($B$12:$B$27=$A33)*(H$12:H$27)) -> 0 | J33: =SUMPRODUCT(($B$12:$B$27=$A33)*(J$12:J$27)) -> 0 | K33: =SUMPRODUCT(($B$12:$B$27=$A33)*(K$12:K$27)) -> 0 | M33: =SUMPRODUCT(($B$12:$B$27=$A33)*(M$12:M$27)) -> 0 | N33: =SUMPRODUCT(($B$12:$B$27=$A33)*(N$12:N$27)) -> 0 | P33: =SUMPRODUCT(($B$12:$B$27=$A33)*(P$12:P$27)) -> 0 | Q33: =SUMPRODUCT(($B$12:$B$27=$A33)*(Q$12:Q$27)) -> 0 | R33: =SUMPRODUCT(($B$12:$B$27=$A33)*(R$12:R$27)) -> 0 | S33: =SUMPRODUCT(($B$12:$B$27=$A33)*(S$12:S$27)) -> 0 | T33: =SUMPRODUCT(($B$12:$B$27=$A33)*(T$12:T$27)) -> 0 | U33: =SUMPRODUCT(($B$12:$B$27=$A33)*(U$12:U$27)) -> 0 | V33: =SUMPRODUCT(($B$12:$B$27=$A33)*(V$12:V$27)) -> 0 | W33: =SUMPRODUCT(($B$12:$B$27=$A33)*(W$12:W$27)) -> 0 | Y33: =SUMPRODUCT(($B$12:$B$27=$A33)*(Y$12:Y$27)) -> 0 | Z33: =SUMPRODUCT(($B$12:$B$27=$A33)*(Z$12:Z$27)) -> 0 | AB33: =SUMPRODUCT(($B$12:$B$27=$A33)*(AB$12:AB$27)) -> 0 | AC33: =SUMPRODUCT(($B$12:$B$27=$A33)*(AC$12:AC$27)) -> 0 | AE33: =SUMPRODUCT(($B$12:$B$27=$A33)*(AE$12:AE$27)) -> 0 | AF33: =SUMPRODUCT(($B$12:$B$27=$A33)*(AF$12:AF$27)) -> 0 | AH33: =SUMPRODUCT(($B$12:$B$27=$A33)*(AH$12:AH$27)) -> 0 | AI33: =SUMPRODUCT(($B$12:$B$27=$A33)*(AI$12:AI$27)) -> 0 | AJ33: =SUMPRODUCT(($B$12:$B$27=$A33)*(AJ$12:AJ$27)) -> 0 | AK33: =SUMPRODUCT(($B$12:$B$27=$A33)*(AK$12:AK$27)) -> 0 | AL33: =SUMPRODUCT(($B$12:$B$27=$A33)*(AL$12:AL$27)) -> 0 | AM33: =SUMPRODUCT(($B$12:$B$27=$A33)*(AM$12:AM$27)) -> 0 | AN33: =SUMPRODUCT(($B$12:$B$27=$A33)*(AN$12:AN$27)) -> 0 | AO33: =SUMPRODUCT(($B$12:$B$27=$A33)*(AO$12:AO$27)) -> 0 | ... AU33: =SUMPRODUCT(($B$12:$B$27=$A33)*(AU$12:AU$27)) -> 0
A34: =底稿目录!A13 -> …… | E34: =SUMPRODUCT(($B$12:$B$27=$A34)*(E$12:E$27)) -> 0 | G34: =SUMPRODUCT(($B$12:$B$27=$A34)*(G$12:G$27)) -> 0 | H34: =SUMPRODUCT(($B$12:$B$27=$A34)*(H$12:H$27)) -> 0 | J34: =SUMPRODUCT(($B$12:$B$27=$A34)*(J$12:J$27)) -> 0 | K34: =SUMPRODUCT(($B$12:$B$27=$A34)*(K$12:K$27)) -> 0 | M34: =SUMPRODUCT(($B$12:$B$27=$A34)*(M$12:M$27)) -> 0 | N34: =SUMPRODUCT(($B$12:$B$27=$A34)*(N$12:N$27)) -> 0 | P34: =SUMPRODUCT(($B$12:$B$27=$A34)*(P$12:P$27)) -> 0 | Q34: =SUMPRODUCT(($B$12:$B$27=$A34)*(Q$12:Q$27)) -> 0 | R34: =SUMPRODUCT(($B$12:$B$27=$A34)*(R$12:R$27)) -> 0 | S34: =SUMPRODUCT(($B$12:$B$27=$A34)*(S$12:S$27)) -> 0 | T34: =SUMPRODUCT(($B$12:$B$27=$A34)*(T$12:T$27)) -> 0 | U34: =SUMPRODUCT(($B$12:$B$27=$A34)*(U$12:U$27)) -> 0 | V34: =SUMPRODUCT(($B$12:$B$27=$A34)*(V$12:V$27)) -> 0 | W34: =SUMPRODUCT(($B$12:$B$27=$A34)*(W$12:W$27)) -> 0 | Y34: =SUMPRODUCT(($B$12:$B$27=$A34)*(Y$12:Y$27)) -> 0 | Z34: =SUMPRODUCT(($B$12:$B$27=$A34)*(Z$12:Z$27)) -> 0 | AB34: =SUMPRODUCT(($B$12:$B$27=$A34)*(AB$12:AB$27)) -> 0 | AC34: =SUMPRODUCT(($B$12:$B$27=$A34)*(AC$12:AC$27)) -> 0 | AE34: =SUMPRODUCT(($B$12:$B$27=$A34)*(AE$12:AE$27)) -> 0 | AF34: =SUMPRODUCT(($B$12:$B$27=$A34)*(AF$12:AF$27)) -> 0 | AH34: =SUMPRODUCT(($B$12:$B$27=$A34)*(AH$12:AH$27)) -> 0 | AI34: =SUMPRODUCT(($B$12:$B$27=$A34)*(AI$12:AI$27)) -> 0 | AJ34: =SUMPRODUCT(($B$12:$B$27=$A34)*(AJ$12:AJ$27)) -> 0 | AK34: =SUMPRODUCT(($B$12:$B$27=$A34)*(AK$12:AK$27)) -> 0 | AL34: =SUMPRODUCT(($B$12:$B$27=$A34)*(AL$12:AL$27)) -> 0 | AM34: =SUMPRODUCT(($B$12:$B$27=$A34)*(AM$12:AM$27)) -> 0 | AN34: =SUMPRODUCT(($B$12:$B$27=$A34)*(AN$12:AN$27)) -> 0 | AO34: =SUMPRODUCT(($B$12:$B$27=$A34)*(AO$12:AO$27)) -> 0 | ... AU34: =SUMPRODUCT(($B$12:$B$27=$A34)*(AU$12:AU$27)) -> 0
A36: 三、审计说明
A38: 四、审计结论：
A42: 提示：
A43: 1.本科目核算企业为在建工程准备的各种物资的成本，包括工程用材料、尚未安装的设备以及为生产准备的工器具等。
A44: 2.本科目可按“专用材料”、“专用设备”、“工器具”等进行明细核算。
A45: 3.审计说明可以概述：（1）程序的测试情况、结果；（2）拟调整事项及其调整分录、未调整事项及其影响，审计范围受到限制情况及其影响。
A46: 4.审计结论可参考：A、未见异常。 B、除上述重大不符事项应当作为调整事项予以调整外，其余未见异常。 C、由于存在以下重大未调整事项（或审计范围受到限制无法获取充分、适当证据），不可确认。

Sheet 调整分录汇总H4-3
A1: 致同会计师事务所
A2: 工程物资调整分录汇总表
A3: =底稿目录!A2 -> 被审计单位： | D3: =底稿目录!A4 -> 编制人： | G3: =底稿目录!A6 -> 编制日期： | I3: 索引号： | J3: H4-3
A4: =底稿目录!A3 -> 截止日： | D4: =底稿目录!A5 -> 复核人： | G4: =底稿目录!A7 -> 复核日期： | I4: 页 次：
A5: 调整事项说明 | B5: 类别（报表调整/账项调整/其他） | C5: 报表项目 | D5: 科目名称 | E5: 附注项目 | F5: …… | G5: 借方调整金额 | H5: 贷方调整金额 | I5: 索引 | J5: 备注
A22: 提示：本底稿适用于调整分录较多、较复杂的项目，且仅列示与本报表项目相关的审计调整。项目组可根据项目实际情况选择是否使用该底稿。

Sheet 增加检查表H4-4
A1: 致同会计师事务所
A2: 工程物资增加检查表
A3: =底稿目录!A2 -> 被审计单位： | C3: =底稿目录!A4 -> 编制人： | G3: =底稿目录!A6 -> 编制日期： | Q3: 索引号： | R3: H4-4
A4: =底稿目录!A3 -> 截止日： | C4: =底稿目录!A5 -> 复核人： | G4: =底稿目录!A7 -> 复核日期： | Q4: 页 次：
A5: 一、审计目标：
A6: 1.资产负债表中记录的工程物资是存在的，且已记录于恰当的账户；2.所有应记录的工程物资均已记录，所有应当包括在财务报表中的相关披露均已包括；
A7: 3.记录的工程物资由被审计单位拥有或控制；4.工程物资以恰当的金额包括在财务报表中，与之相关的计价或分摊调整已恰当记录，相关披露已得到恰当计量和描述。
A8: 二、样本选取标准与规模：
A9: 测试总体： | B9: 如工程物资借方发生额所有凭证共XX笔金额XX | G9: 特定样本： | H9: XX金额以上（大额）、关联方/关联交易形成的款项、XX异常款项全部测试，共XX笔；
A10: 抽样总体： | B10: 测试总体扣除特定样本以外的样本，共XX笔、金额XX | G10: 确定的抽样样本量： | I10: 抽取XX笔 | J10: （如果使用了样本计算器计算样本量，样本量计算过程见<XX>底稿）
A11: 抽样方法： | B11: 随机选样/系统选样/货币单元抽样/随意选样（非统计抽样适用） | G11: 抽样过程： | H11: 使用IDEA（XX抽样工具）选择XX数量、金额XX的样本进行测试，抽样工具中的样本选择过程和结果见<XX>底稿
A12: 三、测试：
A13: 测试内容说明：1.原始凭证是否齐全； 2.记账凭证与原始凭证是否相符；3.账务处理是否正确；4.是否记录于恰当的会计期间；5.……
A14: 序号 | B14: 工程物资类别 | C14: 工程物资名称 | D14: 记账凭证 | J14: 支持性文件 | K14: 核对内容 | P14: 索引号 | Q14: 是否异常 | R14: 备注说明
D15: 日期 | E15: 凭证编号 | F15: 业务内容 | G15: 对方科目 | H15: 对方明细科目 | I15: 借方金额 | K15: 1 | L15: 2 | M15: 3 | N15: 4 | O15: 5
A16: 1
A17: 2
A18: 3
A19: 4
A20: 5
A21: 6
A22: 7
A23: 8
A24: 9
A25: 10
A26: 11
A27: 12
... A30: 15
A31: ……
A32: 合计 | I32: =SUM(I16:I31) -> 0
A33: 本期新增工程物资合计 | I33: ='明细表H4-2'!AB28 -> 0
A34: 检查比例 | I34: =I32/I33 -> #DIV/0!
A35: 四、审计说明：
A36: 1.如果检查比例较低应扩大检查样本量或说明原因
A37: 2.……
A38: 五、审计结论：

Sheet 减少检查表H4-5
A1: 致同会计师事务所
A2: 工程物资减少检查表
A3: =底稿目录!A2 -> 被审计单位： | G3: =底稿目录!A4 -> 编制人： | L3: =底稿目录!A6 -> 编制日期： | U3: 索引号： | V3: H4-5
A4: =底稿目录!A3 -> 截止日： | G4: =底稿目录!A5 -> 复核人： | L4: =底稿目录!A7 -> 复核日期： | U4: 页 次：
A5: 一、审计目标：
A6: 1.资产负债表中记录的工程物资是存在的，且已记录于恰当的账户；2.所有应记录的工程物资均已记录，所有应当包括在财务报表中的相关披露均已包括；
A7: 3.工程物资以恰当的金额包括在财务报表中，与之相关的计价或分摊调整已恰当记录，相关披露已得到恰当计量和描述。
A8: 二、样本选取标准与规模：
A9: 测试总体： | B9: 如工程物资借方发生额所有凭证共XX笔金额XX、贷方发生额所有凭证共XX笔金额XX | H9: 特定样本： | I9: XX金额以上（大额）、关联方/关联交易形成的款项、XX异常款项全部测试，共XX笔；
A10: 抽样总体： | B10: 测试总体扣除特定样本以外的样本，共XX笔、金额XX | H10: 确定的抽样样本量： | J10: 抽取XX笔 | K10: （如果使用了样本计算器计算样本量，样本量计算过程见<XX>底稿）
A11: 抽样方法： | B11: 随机选样/系统选样/货币单元抽样/随意选样（非统计抽样适用） | H11: 抽样过程： | I11: 使用IDEA（XX抽样工具）选择XX数量、金额XX的样本进行测试，抽样工具中的样本选择过程和结果见<XX>底稿
A12: 三、测试：
A13: 测试内容说明：1.原始凭证是否齐全； 2.记账凭证与原始凭证是否相符；3.账务处理是否正确；4.是否记录于恰当的会计期间；5.……
A14: 序号 | B14: 工程物资类别 | C14: 工程物资名称 | D14: 入账凭证号 | E14: 减少方式 | F14: 对方科目 | G14: 减少情况 | N14: 支持性文件 | O14: 核对内容 | T14: 索引号 | U14: 是否异常 | V14: 备注说明
G15: 数量 | H15: 原值 | I15: 减值准备 | J15: 净值 | K15: 清理费用 | L15: 清理收入 | M15: 清理净损益 | O15: 1 | P15: 2 | Q15: 3 | R15: 4 | S15: 5
A16: 1 | J16: =H16-I16 -> 0 | M16: =L16-K16-J16 -> 0
A17: 2 | J17: =H17-I17 -> 0 | M17: =L17-K17-J17 -> 0
A18: 3 | J18: =H18-I18 -> 0 | M18: =L18-K18-J18 -> 0
A19: 4 | J19: =H19-I19 -> 0 | M19: =L19-K19-J19 -> 0
A20: 5 | J20: =H20-I20 -> 0 | M20: =L20-K20-J20 -> 0
A21: 6 | J21: =H21-I21 -> 0 | M21: =L21-K21-J21 -> 0
A22: 7 | J22: =H22-I22 -> 0 | M22: =L22-K22-J22 -> 0
A23: 8 | J23: =H23-I23 -> 0 | M23: =L23-K23-J23 -> 0
A24: 9 | J24: =H24-I24 -> 0 | M24: =L24-K24-J24 -> 0
A25: 10 | J25: =H25-I25 -> 0 | M25: =L25-K25-J25 -> 0
A26: 11 | J26: =H26-I26 -> 0 | M26: =L26-K26-J26 -> 0
A27: 12 | J27: =H27-I27 -> 0 | M27: =L27-K27-J27 -> 0
... A30: 15 | J30: =H30-I30 -> 0 | M30: =L30-K30-J30 -> 0
A31: …… | J31: =H31-I31 -> 0 | M31: =L31-K31-J31 -> 0
A32: 合计 | H32: =SUM(H16:H31) -> 0 | I32: =SUM(I16:I31) -> 0 | J32: =SUM(J16:J31) -> 0 | K32: =SUM(K16:K31) -> 0 | L32: =SUM(L16:L31) -> 0 | M32: =SUM(M16:M31) -> 0
A33: 本期减少工程物资合计 | H33: ='明细表H4-2'!AE28 -> 0
A34: 检查比例 | H34: =H32/H33 -> #DIV/0!
A35: 四、审计说明：
A36: 1.如果检查比例较低应扩大检查样本量或说明原因
A37: 2.……
A38: 五、审计结论：

Sheet 盘点检查表H4-6
A1: 致同会计师事务所
A2: 工程物资盘点检查表
A3: =底稿目录!A2 -> 被审计单位： | D3: =底稿目录!A4 -> 编制人： | H3: =底稿目录!A6 -> 编制日期： | K3: 索引号： | L3: H4-6
A4: =底稿目录!A3 -> 截止日： | D4: =底稿目录!A5 -> 复核人： | H4: =底稿目录!A7 -> 复核日期： | K4: 页 次：
A5: 一、审计目标：
A6: 1.资产负债表中记录的工程物资是存在的，且已记录于恰当的账户；2.所有应记录的工程物资均已记录，所有应当包括在财务报表中的相关披露均已包括；
A7: 3.工程物资以恰当的金额包括在财务报表中，与之相关的计价或分摊调整已恰当记录，相关披露已得到恰当计量和描述 。
A8: 二、样本选取标准与规模：
A9: 测试总体： | B9: 如期末工程物资数量XX、金额XX | G9: 特定样本： | H9: XX金额以上（大额）、关联方/关联交易形成的款项、XX异常款项全部测试，共XX笔；
A10: 抽样总体： | B10: 测试总体扣除特定样本以外的样本，数量XX、金额XX | G10: 确定的抽样样本量： | H10: 抽取XX笔 | I10: （如果使用了样本计算器计算样本量，样本量计算过程见<XX>底稿）
A11: 抽样方法： | B11: 随机选样/系统选样/货币单元抽样/随意选样 | G11: 抽样过程： | H11: 使用IDEA（XX抽样工具）选择XX数量、金额XX的样本进行测试，抽样工具中的样本选择过程和结果见<XX>底稿
A12: 三、审计过程：
A13: 抽盘地点：______________ | C13: 盘点人员： | D13: 被审计单位仓库盘点人和财务监盘人签字 | G13: 监盘人员： | H13: （审计人员签字） | J13: 盘点时间：__________________
A14: 工程物资名称/类别 | B14: 资产编号 | C14: 规格型号 | D14: 单位 | E14: 盘点前财务账面记录 | G14: 企业盘点记录数量 | H14: 抽盘数量 | I14: 抽盘与账面差异（+盈-亏） | J14: 抽盘与企业盘点差异 | K14: 企业盘点与账面差异 | L14: 品质状况（正常/闲置/毁损等）
E15: 数量 | F15: 金额
I16: =H16-E16 -> 0 | J16: =H16-G16 -> 0 | K16: =G16-E16 -> 0
I17: =H17-E17 -> 0 | J17: =H17-G17 -> 0 | K17: =G17-E17 -> 0
I18: =H18-E18 -> 0 | J18: =H18-G18 -> 0 | K18: =G18-E18 -> 0
I19: =H19-E19 -> 0 | J19: =H19-G19 -> 0 | K19: =G19-E19 -> 0
I20: =H20-E20 -> 0 | J20: =H20-G20 -> 0 | K20: =G20-E20 -> 0
I21: =H21-E21 -> 0 | J21: =H21-G21 -> 0 | K21: =G21-E21 -> 0
I22: =H22-E22 -> 0 | J22: =H22-G22 -> 0 | K22: =G22-E22 -> 0
I23: =H23-E23 -> 0 | J23: =H23-G23 -> 0 | K23: =G23-E23 -> 0
I24: =H24-E24 -> 0 | J24: =H24-G24 -> 0 | K24: =G24-E24 -> 0
I25: =H25-E25 -> 0 | J25: =H25-G25 -> 0 | K25: =G25-E25 -> 0
I26: =H26-E26 -> 0 | J26: =H26-G26 -> 0 | K26: =G26-E26 -> 0
A27: 合计 | E27: =SUM(E16:E26) -> 0 | F27: =SUM(F16:F26) -> 0 | G27: =SUM(G16:G26) -> 0 | H27: =SUM(H16:H26) -> 0 | I27: =SUM(I16:I26) -> 0 | J27: =SUM(J16:J26) -> 0 | K27: =SUM(K16:K26) -> 0
A28: 期末工程物资总额：
A29: 抽取样本占期末余额比例：（%） | F29: =F27/F28 -> #DIV/0!
A30: 四、盘点情况说明：
A31: 监盘计划、监盘小结，参考固定资产
A32: 五、审计结论：
A36: 提示：
A37: 1、本表可作为工程物资盘点汇总表或盘点明细表或固定资产抽盘表。
A38: 2、财务账面记录与资产管理管理部门账面记录应一致，若存在差异应调整一致。
A39: 3、财务账面记录与实际盘点记录的差异构成盘盈/盘亏，应根据具体原因分析处理。应说明企业的处理结果。
A40: 4、盘点时，应关注易移动的“存量资产”及可能发生减值的“存量资产”；
A41: 5、盘点时应关注资产的品质状况（影响减值准备的计提）。

Sheet 减值测算表H4-7
A1: 致同会计师事务所
A2: 工程物资减值测算表
A3: =底稿目录!A2 -> 被审计单位： | E3: =底稿目录!A4 -> 编制人： | I3: =底稿目录!A6 -> 编制日期： | L3: 索引号： | M3: H4-7
A4: =底稿目录!A3 -> 截止日： | E4: =底稿目录!A5 -> 复核人： | I4: =底稿目录!A7 -> 复核日期： | L4: 页 次：
A5: 一、审计目标：工程物资以恰当的金额包括在财务报表中，与之相关的计价或分摊调整已恰当记录，相关披露已得到恰当计量和描述。
A6: 二、审计过程：
A7: 工程物资类别 | B7: 工程物资名称 | C7: 是否存在减值迹象 | D7: 减值迹象描述 | E7: 账面价值 | F7: 可收回金额 | I7: 期末应计提的减值金额（当⑤＜②） | J7: 期末账面已计提的减值准备 | K7: 本期应补提 或冲回的减值准备 | L7: 工作底稿索引号 | M7: 备注
F8: 公允价值减处置费用的净额 | G8: 预计未来现金流量现值 | H8: 可收回金额（③、④较高者） | J8: 期末已计提 减值准备
D9: ① | E9: ② | F9: ③ | G9: ④ | H9: ⑤ | I9: ⑥＝⑤－② | J9: ⑦ | K9: ⑧=⑥-⑦
H10: =MAX(F10,G10) -> 0 | I10: =IF(E10>H10,E10-H10,0) -> 0 | K10: =I10-J10 -> 0
H11: =MAX(F11,G11) -> 0 | I11: =IF(E11>H11,E11-H11,0) -> 0 | K11: =I11-J11 -> 0
H12: =MAX(F12,G12) -> 0 | I12: =IF(E12>H12,E12-H12,0) -> 0 | K12: =I12-J12 -> 0
H13: =MAX(F13,G13) -> 0 | I13: =IF(E13>H13,E13-H13,0) -> 0 | K13: =I13-J13 -> 0
H14: =MAX(F14,G14) -> 0 | I14: =IF(E14>H14,E14-H14,0) -> 0 | K14: =I14-J14 -> 0
H15: =MAX(F15,G15) -> 0 | I15: =IF(E15>H15,E15-H15,0) -> 0 | K15: =I15-J15 -> 0
A16: 合计 | E16: =SUM(E10:E15) -> 0 | F16: =SUM(F10:F15) -> 0 | G16: =SUM(G10:G15) -> 0 | H16: =SUM(H10:H15) -> 0 | I16: =SUM(I10:I15) -> 0 | J16: =SUM(J10:J15) -> 0 | K16: =SUM(K10:K15) -> 0
A17: 三、审计说明：
A20: 四、审计结论：
A26: 提示：
A27: 1.获取或编制工程物资减值准备明细表，复核加计正确，并与总账数和明细账合计数核对相符；
A28: 2.检查工程物资减值准备计提和转销的批准程序，取得书面报告等证明文件；检查被审计单位计提工程物资减值准备的依据是否充分，会计处理是否正确；
A29: 3.检查工程物资转让时，相应的减值准备是否一并结转，会计处理是否正确；
A30: 4.重新测试被审计单位计提的减值准备是否合理；比较我们预期所估计减值准备和已记录的金额，调查所有重大差异；
A31: 5.上期确认的固定资产减值准备在本期的变动是否适当。

Sheet 可收回金额测试表H4-8
A1: 致同会计师事务所
A2: 工程物资减值准备测试表-可收回金额
A3: =底稿目录!A2 -> 被审计单位： | D3: =底稿目录!A4 -> 编制人： | J3: =底稿目录!A6 -> 编制日期： | N3: 索引号： | O3: H4-8
A4: =底稿目录!A3 -> 截止日： | D4: =底稿目录!A5 -> 复核人： | J4: =底稿目录!A7 -> 复核日期： | N4: 页 次：
A5: 一、审计目标：工程物资以恰当的金额包括在财务报表中，与之相关的计价或分摊调整已恰当记录，相关披露已得到恰当计量和描述。
A6: 二、审计过程：
A7: （一）资产的公允价值减去处置费用后的净额
A8: 工程物资名称/类别 | B8: 公允价值 | H8: 处置费用（资产处置的直接归属费用） | N8: 公允价值-处置费用 | O8: 备注
B9: 销售协议价格 | C9: 说明 | D9: 资产活跃市场价格 | E9: 说明 | F9: 估计价格 | G9: 说明 | H9: 法律费用 | I9: 相关税费 | J9: 搬运费 | K9: 直接费用 | L9: 其他费用 | M9: 处置费用合计
M10: =SUM(H10:L10) -> 0 | N10: =IF(B10>0,B10,IF(D10>0,D10,F10))-M10 -> 0
M11: =SUM(H11:L11) -> 0 | N11: =IF(B11>0,B11,IF(D11>0,D11,F11))-M11 -> 0
M12: =SUM(H12:L12) -> 0 | N12: =IF(B12>0,B12,IF(D12>0,D12,F12))-M12 -> 0
A13: 合计 | B13: =SUM(B10:B12) -> 0 | D13: =SUM(D10:D12) -> 0 | F13: =SUM(F10:F12) -> 0 | H13: =SUM(H10:H12) -> 0 | I13: =SUM(I10:I12) -> 0 | J13: =SUM(J10:J12) -> 0 | K13: =SUM(K10:K12) -> 0 | L13: =SUM(L10:L12) -> 0 | M13: =SUM(M10:M12) -> 0 | N13: =SUM(N10:N12) -> 0
A14: 审计说明：
A15: （二）资产预计未来现金流量的现值
A16: 预计未来现金流量 | B16: 预算或者预测期 | G16: 以后年度 | I16: 行业的长期平均增长率 | J16: 市场长期平均增长率 | K16: 所在国家或地区的长期平均增长率 | L16: 增长率确定依据 | N16: 预计未来现金流量的现值 | O16: 备注
B17: 第一年 | C17: 第二年 | D17: 第三年 | E17: 第四年 | F17: 第五年 | G17: 基数 | H17: 增长率
A18: 预计未来现金净流量 | G18: =F18 -> 0
A19: 折现系数 | B19: =1/(1+$K$23)^1 -> #DIV/0! | C19: =1/(1+$K$23)^2 -> #DIV/0! | D19: =1/(1+$K$23)^3 -> #DIV/0! | E19: =1/(1+$K$23)^4 -> #DIV/0! | F19: =1/(1+$K$23)^5 -> #DIV/0! | G19: =(1+H18)/((K23-H18)*(1+K23)^5) -> #DIV/0! | H19: （企业管理层如能证明递增的增长率是合理的，可以以递增的增长率为基础。）
A20: 现值 | B20: =B18*B19 -> #DIV/0! | C20: =C18*C19 -> #DIV/0! | D20: =D18*D19 -> #DIV/0! | E20: =E18*E19 -> #DIV/0! | F20: =F18*F19 -> #DIV/0! | G20: =G18*G19 -> #DIV/0! | H20: （建立在预算或者预测基础上的预计现金流量最多涵盖5年。） | N20: =SUM(B20:G20) -> #DIV/0!
A21: 折现率 | B21: 所得税率 | C21: 债务总额 | D21: 资本总额 | E21: 债务成本Kd | F21: 无风险报酬率Rf | G21: β系数 | H21: 平均风险股票必要报酬率Rm | I21: 资本成本Ke | J21: 折现率(税后) | K21: 折现率(税前) | L21: 税后折税前调整说明 | N21: 可收回金额 | O21: 备注
B22: 适用税率 | L22: 税率调整 | M22: 调整说明
A23: 加权平均资金成本 | I23: =F23+G23*(H23-F23) -> 0 | J23: =((C23*E23*(1-B23)+D23*I23))/(C23+D23) -> #DIV/0! | K23: =J23/(1-(B23+L23)) -> #DIV/0! | N23: =MAX(N13,N20) -> #DIV/0!
A24: 三、审计说明：
A27: 四、审计结论：
A31: 提示：
A32: 1、可收回金额应当根据资产的公允价值减去处置费用后的净额与资产预计未来现金流量的现值两者之间较高者确定。
A33: 2、资产的公允价值减去处置费用后的净额，应当根据公平交易中销售协议价格减去可直接归属于该资产处置费用的金额确定。不存在销售协议但存在资产活跃市场的，
A34: 应当按照该资产的市场价格减去处置费用后的金额确定。资产的市场价格通常应当根据资产的买方出价确定。在不存在销售协议和资产活跃市场的情况下，应当
A35: 以可获取的最佳信息为基础，估计资产的公允价值减去处置费用后的净额，该净额可以参考同行业类似资产的最近交易价格或者结果进行估计。企业按照上述规定
A36: 仍然无法可靠估计资产的公允价值减去处置费用后的净额的，应当以该资产预计未来现金流量的现值作为其可收回金额。
A37: 3、处置费用包括与资产处置有关的法律费用、相关税费、搬运费以及为使资产达到可销售状态所发生的直接费用等。
A38: 4、资产预计未来现金流量的现值，应当按照资产在持续使用过程中和最终处置时所产生的预计未来现金流量，选择恰当的折现率对其进行折现后的金额加以确定。
A39: 5、预计资产的未来现金流量，应当以经企业管理层批准的最近财务预算或者预测数据，以及该预算或者预测期之后年份稳定的或者递减的增长率为基础。
A40: 预计的资产未来现金流量应当包括下列各项：
... A58: 5.上期确认的固定资产减值准备在本期的变动是否适当。

Sheet 关联交易检查表H4-9
A1: 致同会计师事务所
A2: 关联交易检查表
A3: =底稿目录!A2 -> 被审计单位： | F3: =底稿目录!A4 -> 编制人： | I3: =底稿目录!A6 -> 编制日期： | M3: 索引号： | N3: H4-9
A4: =底稿目录!A3 -> 截止日： | F4: =底稿目录!A5 -> 复核人： | I4: =底稿目录!A7 -> 复核日期： | M4: 页 次：
A5: 一、审计目标:
A6: 1.资产负债表中记录的工程物资是存在的，且已记录于恰当的账户；2.所有应记录的工程物资均已记录，所有应当包括在财务报表中的相关披露均已包括；3.记录的工程物资由被审计单位拥有或控制。
A7: 4.工程物资以恰当的金额包括在财务报表中，与之相关的计价或分摊调整已恰当记录，相关披露已得到恰当计量和描述；5.工程物资已被恰当地汇总或分解且表述清楚，相关披露在按照企业会计准则的编制基础下是相关的、可理解的。
A8: 二、审计过程：
A9: （1）向合并范围外关联方采购工程物资
A10: 关联单位名称 | B10: 关联方关系 | C10: 资产类别 | D10: 购买工程物资名称 | E10: 购买价款 | F10: 工程物资入账价值 | G10: 占同类交易金额的比例％ | H10: 购入时间 | I10: 定价政策 | J10: 关联交易是否存在异常 | K10: 备注 | L10: 索引号
A18: （2）向合并范围外关联方出售工程物资
A19: 关联单位名称 | B19: 关联方关系 | C19: 资产类别 | D19: 出售工程物资名称 | E19: 出售时工程物资原值 | F19: 出售时减值准备 | G19: 出售时净值 | H19: 销售价格 （不含税） | I19: 占同类交易金额的比例％ | J19: 出售时间 | K19: 定价政策 | L19: 关联交易是否存在异常 | M19: 备注 | N19: 索引号
A24: 三、审计说明：
A27: 四、审计结论：
A33: 勿删
A34: 关联关系
A35: 实际控制人
A36: 控股股东
A37: 控股股东、实际控制人的附属企业
A38: 持有5%以上股份的法人或其他组织
A39: 联营企业
A40: 合营企业
A41: 董高监等关键管理人员
A42: 其他关联方
