Workbook

Sheet 底稿目录
A1: 底稿开列时，可先在以下单元格填写有关内容，以便其他底稿引用有关数据：
A2: 被审计单位：
A3: 会计期间：202X年度 | D3: 序号 | E3: 内容 | F3: 索引号
A4: 编制人： | E4: 净敞口套期收益实质性程序表 | F4: G12A
A5: 编制日期： | D5: 1 | E5: 审定表 | F5: G12-1
A6: 复核人： | D6: 2 | E6: 附注披露信息（上市公司） | G6: 无需打印
A7: 复核日期： | D7: 3 | E7: 附注披露信息（国企） | G7: 无需打印
D8: 4 | E8: 明细表 | F8: G12-2
A9: 关于工作底稿与审计程序索引号对应的说明 | D9: 5 | E9: 调整分录汇总 | F9: G12-3
A10: 1.编制的审计工作底稿应与审计程序对应。审计项目组应根据被审计单位实际情况和风险评估情况在实质性程序表中裁剪、修改或增加审计程序，根据实际执行的审计程序完成相应审计工作底稿，编制的工作底稿中应按自然顺序依次编制索引号，并通过唯一的索引号将与实质性程序表中的程序对应关联（即将工作底稿的索引号填入实质性程序表中的底稿索引号列）。 | D10: 6 | E10: 公允价值测试表 | F10: G12-4
D11: 7 | E11: 风险净敞口检查表 | F11: G12-5
D12: 8 | E12: 凭证检查表 | F12: G12-6
A14: 2.获取的支持性证据应与审计底稿或程序对应。审计项目组在完成底稿时获取的支持性证据应根据底稿索引号编制下一级按自然顺序排序的索引号（如D1-2-1、D1-2-2、……），并在底稿中说明引用的支持性证据、关联索引号。
A17: 3.工作底稿索引号的编码规则：实质性程序索引号按循环从“D”到“N”,循环内账户以顺序号排列，模板中底稿索引号按账户顺序+自然数顺序（即模板中索引号按二级自然顺序排列，如D1-1、D1-2、D1-3、……D1-N）。

Sheet 净敞口套期收益审计程序表G12A
A1: 致同会计师事务所
A2: 净敞口套期收益实质性程序表
A3: =底稿目录!A2 -> 被审计单位： | C3: =底稿目录!A4 -> 编制人： | F3: =底稿目录!A5 -> 编制日期： | H3: 索引号： | I3: =底稿目录!F4 -> G12A
A4: =底稿目录!A3 -> 会计期间：202X年度 | C4: =底稿目录!A6 -> 复核人： | F4: =底稿目录!A7 -> 复核日期： | H4: 页 次：
A5: 一、本账户涉及的科目
A6: 净敞口套期收益
A7: 二、审计目标与认定的对应关系
A8: 审计目标 | G8: 财务报表的认定
A9: A. 利润表中记录的净敞口套期收益已发生，且与被审计单位有关，已记录于恰当的账户 | G9: 发生
A10: B. 所有应记录的净敞口套期收益均已记录，所有应当包括在财务报表中的相关披露均已包括 | G10: 完整性
A11: C. 与净敞口套期收益有关的金额及其他数据已恰当记录，相关披露已得到恰当计量和描述 | G11: 准确性
A12: D. 净敞口套期收益已记录于正确的会计期间 | G12: 截止
A13: E. 净敞口套期收益已被恰当地汇总或分解且表述清楚，相关披露在按照企业会计准则的编制基础下是相关的、可理解的 | G13: 列报
A14: 三、计划实施的实质性程序
A15: 序号 | B15: 审计程序 | C15: 程序分类 | D15: 财务报表的认定 | I15: 底稿索引号
D16: 发生 | E16: 完整性 | F16: 准确性 | G16: 截止 | H16: 列报 | J16: 根据被审计单位实际情况和风险评估情况裁剪、修改或增加审计程序
A17: 1 | B17: 获取或编制净敞口套期收益的明细表，完成以下工作，并编制审定表 （1）复核加计是否正确，与总账、明细账合计数核对是否相符； （2）将上期发生额与上期经审计的财务报表核对； （3）追查明细表至调节表; （4）与上年明细项目进行比较，确定与上年分类相同； （5）结合净敞口套期收益、交易性金融负债等科目的审计，复核其勾稽关系； （6）调查重大或者异常的调节项目，并与客户的适当人员讨论差异，考虑回复的可信度并确认相关解释，以及采取适当的措施。 | C17: 常规★ | D17: √ | E17: √ | F17: √ | I17: G12-1 /G12-2
A18: 2 | B18: 在使用手工编制、自定义信息报告、系统生成的非固定格式报告等由被审计单位生成的信息时，测试有关信息准确性和完整性，并考虑针对编制和维护由被审计单位生成的信息的相关控制实施控制测试，以评价该信息是否能够为实现审计目的提供基础。 | C18: 常规★ | E18: √ | F18: √ | I18: T1 /G0-2
A19: 3 | B19: 对上期数的审计，取得净敞口套期收益上期明细表复核加计是否正确，与总账、明细账合计数是否相符，确定会计政策及程序是否适当，确定计算的准确性；确定是否需要补充必要的程序，如果是，执行适当的应对程序。（适用于首次承接） | C19: 备选 | D19: √ | G19: √
A20: 4 | B20: 考虑获取增、减分析表，确定增加内容及减少方式、对损益的影响。 | C20: 常规★ | D20: √ | F20: √ | G20: √ | I20: G12-2
A21: 5 | B21: 若企业存在期货交易，获取仓库的商品期货头寸清单，执行下列审计程序： （1）确定计算的准确性，将总金额与总账、明细账合计数核对相符； （2）查核至仓库收据； （3）函证确认每个仓库商品期货的存在性（可参考货币资金循环中的函证要求），对于未回函的仓库，核对该商品期货与支持文件一致； （4）追查审计日的在途物资至企业的记录，与客户的适当人员讨论差异，考虑回函的可信度并确认相关解释，以及采取适当的措施； （5）确定是否需要补充必要的程序，如果是，执行适当的应对程序。 | C21: 备选 | D21: √ | F21: √ | G21: √ | I21: G12-2
A22: 6 | B22: 检查审计日所有尚未平仓商品的后续清算明细表。 | C22: 备选 | D22: √ | F22: √ | G22: √ | I22: G12-2
A23: 7 | B23: 确定对套利交易的会计处理是否得当。 | C23: 备选 | D23: √ | F23: √ | G23: √ | I23: G12-2 /G12-5
A24: 8 | B24: 获取审计日未结算证券头寸的明细信息，核实审计日后结算的交易，考虑对财务报表的影响。 | C24: 常规★ | D24: √ | F24: √ | G24: √ | I24: G12-2 /G12-5
A25: 9 | B25: 对于未平仓合同预提的佣金和费用，确定对未平仓合同预提的佣金和费用是否合理，将预提手续费与清算机构（券商或期货公司）的对账单进行核对，并追查至现金日记账的期后付款。 | C25: 备选 | D25: √ | F25: √ | G25: √ | I25: G12-2 /G12-5
A26: 10 | B26: 检查与净敞口套期收益有关的的记账凭证和相应的支持性证据以确定交易的真实性，是否按规定进行相应的会计处理和披露。 | C26: 常规★ | D26: √ | F26: √ | G26: √ | I26: G12-6
A27: 10 | B27: 根据评估的舞弊风险等因素增加的审计程序。 | C27: IPO/上市/新三板/重组/舞弊应对
A28: 11 | B28: 检查净敞口套期收益是否已按企业会计准则或其他适用的规定在财务报表中做出恰当列报和披露。 | C28: 常规★ | H28: √ | I28: A1-1/A1-15 /A1-16

Sheet 净敞口套期收益审计程序表G12A-修订前
A1: 致同会计师事务所
A2: 净敞口套期收益实质性程序表
A3: =底稿目录!A2 -> 被审计单位： | C3: =底稿目录!A4 -> 编制人： | F3: =底稿目录!A5 -> 编制日期： | H3: 索引号： | I3: =底稿目录!F4 -> G12A
A4: =底稿目录!A3 -> 会计期间：202X年度 | C4: =底稿目录!A6 -> 复核人： | F4: =底稿目录!A7 -> 复核日期： | H4: 页 次：
A5: 一、本账户涉及的科目
A6: 净敞口套期收益
A7: 二、重大错报风险需从实质性程序获取的保证程度
A8: 审计目标与认定对应关系 | C8: 财务报表的认定 | H8: 信赖/不信赖/不适用 | I8: 索引号
C9: 发生 | D9: 完整性 | E9: 准确性 | F9: 分类 | G9: 列报与披露
A10: A. 利润表中记录的净敞口套期收益已发生，且与被审计单位有关。 | C10: √
A11: B. 所有应当记录的净敞口套期收益均已记录。 | D11: √
A12: C. 与净敞口套期收益有关的金额及其他数据已恰当记录于正确的会计期间。 | E12: √
A13: D. 净敞口套期收益已记录于恰当的账户。 | F13: √
A14: E. 净敞口套期收益已按照企业会计准则的规定在财务报表中作出恰当的列报和披露。 | G14: √
A15: 三、计划实施的实质性程序
A16: 序号 | B16: 审计程序 | C16: 程序分类 | D16: 审计目标 | H16: 执行情况说明 （含底稿索引）
A17: （一） | B17: 编制审定表 | C17: 常规★ | D17: D | H17: I11 | J17: 整合为1 | K17: 获取或编制净敞口套期收益的明细表，完成以下工作，并编制审定表 （1）复核加计是否正确，与总账、明细账合计数核对是否相符； （2）将上期发生额与上期经审计的财务报表核对； （3）追查明细表至调节表; （4）与上年明细项目进行比较，确定与上年分类相同； （5）结合净敞口套期收益、交易性金融负债等科目的审计，复核其勾稽关系； （6）调查重大或者异常的调节项目，并与客户的适当人员讨论差异，考虑回复的可信度并确认相关解释，以及采取适当的措施。
A18: （二） | B18: 获取或编制明细并执行下列程序： | C18: 常规★ | D18: D | J18: 整合为1
A19: 1 | B19: 复核加计正确 。 | C19: 常规★ | D19: BD | J19: 整合为1
A20: 2 | B20: 将总金额与总账、明细账合计数核对相符。 | C20: 常规★ | D20: BD | J20: 整合为1
A21: 3 | B21: 将上期发生额与上期经审计的财务报表核对。 | C21: 常规 | D21: BD | J21: 整合为1
A22: 4 | B22: 追查明细表至调节表。 | C22: 常规 | D22: BD | J22: 整合为1
A23: 5 | B23: 与上年明细项目进行比较，确定与上年分类相同。 | C23: 常规 | D23: BD | J23: 整合为1
A24: 6 | B24: 结合交易性金融资产、交易性金融负债等科目的审计，复核其勾稽关系。 | C24: 常规★ | D24: BD | J24: 整合为1
A25: 7 | B25: 调查重大或者异常的调节项目。 | C25: 常规 | D25: BD | J25: 整合为1
A26: 8 | B26: 与客户的适当人员讨论差异。 | C26: 常规 | D26: BD | J26: 整合为1
A27: 9 | B27: 考虑回复的可信度并确认相关解释，以及采取适当的措施。 | C27: 常规 | D27: BD | J27: 整合为1
A28: （三） | B28: 在使用被审计单位生成的信息（IPE）时，应当评价该信息对实现审计目的是否足够可靠，包括根据具体情况在必要时实施下列程序： | C28: 常规★ | D28: B | H28: T1 | J28: 保留修改为2 | K28: 在使用手工编制、自定义信息报告、系统生成的非固定格式报告等由被审计单位生成的信息时，测试有关信息准确性和完整性，并考虑针对编制和维护由被审计单位生成的信息的相关控制实施控制测试，以评价该信息是否能够为实现审计目的提供基础。
A29: 1 | B29: 获取有关信息准确性和完整性的审计证据。 | J29: 保留修改为2
A30: 2 | B30: 评价信息对实现审计目的是否足够准确和详细。 | J30: 保留修改为2
A31: （四） | B31: 若系首次承接，获取前期期末各科目明细表，执行下列程序：（适用于首次审计时对期初余额的审计） | C31: 备选 | D31: B | H31: I11-2 | J31: 保留修改为3 | K31: 对上期数的审计，取得净敞口套期收益上期明细表复核加计是否正确，与总账、明细账合计数是否相符，确定会计政策及程序是否适当，确定计算的准确性；确定是否需要补充必要的程序，如果是，执行适当的应对程序。（适用于首次承接）
A32: 1 | B32: 确定计算的准确性。 | C32: 备选 | D32: B | J32: 保留修改为3
A33: 2 | B33: 与总账核对一致。 | C33: 备选 | D33: B | J33: 保留修改为3
A34: 3 | B34: 确定是否需要补充必要的程序，如果是，执行适当的应对程序。 | C34: 备选 | D34: B | J34: 保留修改为3
A35: （五） | B35: 根据实际情况，实施以下分析程序： | C35: 常规 | D35: A | H35: I11-2 | J35: 保留4
A36: 1 | B36: 获取或编制增、减分析表，确定增加内容及减少方式、对损益的影响； | C36: 常规 | D36: A | J36: 保留4
A37: （六） | B37: 若企业存在期货交易，获取仓库的商品期货头寸清单，执行下列审计程序： | C37: 备选 | D37: A | H37: I11-9 | J37: 删除
A38: 1 | B38: 确定计算的准确性。 | C38: 备选 | D38: A | J38: 删除
A39: 2 | B39: 将总金额与总账、明细账合计数核对相符。 | C39: 备选 | D39: A | J39: 删除
A40: 3 | B40: 查核至仓库收据。 | C40: 备选 | D40: A | J40: 删除
...

Sheet 审定表G12-1
A1: 致同会计师事务所
A2: 净敞口套期收益审定表
A3: =底稿目录!A2 -> 被审计单位： | D3: =底稿目录!A4 -> 编制人： | G3: =底稿目录!A5 -> 编制日期： | I3: 索引号： | J3: =底稿目录!F5 -> G12-1
A4: =底稿目录!A3 -> 会计期间：202X年度 | D4: =底稿目录!A6 -> 复核人： | G4: =底稿目录!A7 -> 复核日期： | I4: 页 次：
A5: 项目 | B5: 本期数 | E5: 上期数 | H5: 本期与上期审定数比较 | J5: 原因分析
B6: 未审数 | C6: 调整数 | D6: 审定数 | E6: 未审数 | F6: 调整数 | G6: 审定数 | H6: 变动额 | I6: 变动率
A7: 预期销售和预期采购的外汇净头寸 | D7: =B7+C7 -> 0 | G7: =E7+F7 -> 0 | H7: =D7-G7 -> 0 | I7: =IF(AND(G7=0,D7=0),"",IF(AND(G7=0,D7>0),1,H7/G7))
D8: =B8+C8 -> 0 | G8: =E8+F8 -> 0 | H8: =D8-G8 -> 0 | I8: =IF(AND(G8=0,D8=0),"",IF(AND(G8=0,D8>0),1,H8/G8))
D9: =B9+C9 -> 0 | G9: =E9+F9 -> 0 | H9: =D9-G9 -> 0 | I9: =IF(AND(G9=0,D9=0),"",IF(AND(G9=0,D9>0),1,H9/G9))
D10: =B10+C10 -> 0 | G10: =E10+F10 -> 0 | H10: =D10-G10 -> 0 | I10: =IF(AND(G10=0,D10=0),"",IF(AND(G10=0,D10>0),1,H10/G10))
D11: =B11+C11 -> 0 | G11: =E11+F11 -> 0 | H11: =D11-G11 -> 0 | I11: =IF(AND(G11=0,D11=0),"",IF(AND(G11=0,D11>0),1,H11/G11))
A12: 合计 | B12: =SUM(B7:B11) -> 0 | C12: =SUM(C7:C11) -> 0 | D12: =SUM(D7:D11) -> 0 | E12: =SUM(E7:E11) -> 0 | F12: =SUM(F7:F11) -> 0 | G12: =SUM(G7:G11) -> 0 | H12: =SUM(H7:H11) -> 0 | I12: =IF(AND(G12=0,D12=0),"",IF(AND(G12=0,D12>0),1,H12/G12))
A13: 试算平衡表数
A14: 差异数 | D14: =D12-D13 -> 0 | G14: =G12-G13 -> 0
A15: 1、审计说明
A16: （1）净敞口套期收益本期较上期增加（负数为减少）： | D16: =IF(AND(G12=0,D12=0),0,IF(AND(G12=0,D12>0),1,(D12-G12)/G12)) -> 0
A17: 主要原因（比例超过30%的）：
A19: （2）情况说明
A22: 2、审计结论

Sheet 附注披露信息（上市公司）
A1: 致同会计师事务所
A2: 附注披露信息（上市公司）
A3: =底稿目录!A2 -> 被审计单位： | B3: =底稿目录!A4 -> 编制人： | C3: =底稿目录!A5 -> 编制日期： | D3: 索引号： | E3: =底稿目录!F6 -> 0
A4: =底稿目录!A3 -> 会计期间：202X年度 | B4: =底稿目录!A6 -> 复核人： | C4: =底稿目录!A7 -> 复核日期： | D4: 页次：
A5: 附注披露信息
A6: 净敞口套期收益
A7: 项 目 | B7: 本期发生额 | C7: 上期发生额
A11: 合 计 | B11: =SUM(B8:B10) -> 0 | C11: =SUM(C8:C10) -> 0

Sheet 附注披露信息（国企）
A1: 致同会计师事务所
A2: 附注披露信息（国企）
A3: =底稿目录!A2 -> 被审计单位： | B3: =底稿目录!A4 -> 编制人： | C3: =底稿目录!A5 -> 编制日期： | D3: 索引号： | E3: =底稿目录!F7 -> 0
A4: =底稿目录!A3 -> 会计期间：202X年度 | B4: =底稿目录!A6 -> 复核人： | C4: =底稿目录!A7 -> 复核日期： | D4: 页次：
A5: 附注披露信息
A6: 净敞口套期收益
A7: 产生净敞口套期收益的来源 | B7: 本期发生额 | C7: 上期发生额
A8: 净敞口套期下被套期项目累计公允价值变动转入当期损益的金额
A9: 净敞口套期下现金流量套期储备转入当期损益的金额
A10: 合 计 | B10: =SUM(B8:B9) -> 0 | C10: =SUM(C8:C9) -> 0

Sheet 明细表G12-2
A1: 致同会计师事务所
A2: 净敞口套期收益明细表
A3: =底稿目录!A2 -> 被审计单位： | C3: =底稿目录!A4 -> 编制人： | E3: =底稿目录!A5 -> 编制日期： | I3: 索引号： | J3: =底稿目录!F8 -> G12-2
A4: =底稿目录!A3 -> 会计期间：202X年度 | C4: =底稿目录!A6 -> 复核人： | E4: =底稿目录!A7 -> 复核日期： | I4: 页 次：
A5: 一、审计目标: | B5: 所有应记录的净敞口套期收益均已记录，所有应当包括在财务报表中的相关披露均已包括
A6: 二、审计过程：
A7: 项目 | B7: 净头寸 | C7: 套期工具 | D7: 套期工具公允价值 | H7: 套期调整摊销（计入净敞口套期损益） | I7: 净敞口套期损益 | J7: 索引号
D8: 套期工具累计公允价值变动 | E8: 对应预期销售的部分（计入净敞口套期损益） | F8: 对应预期采购的部分（套期调整） | G8: 校验
A9: 预期销售和预期采购的外汇净头寸 | B9: 支付200万美元 | C9: 购入200万美元的外汇远期合同 | D9: -200000 | E9: 1000000 | F9: -1200000 | G9: =D9=SUM(E9:F9) -> TRUE | I9: =E9+H9 -> 1000000
A10: 预期销售和预期采购的外汇净头寸 | H10: -240000 | I10: =E10+H10 -> -240000
A14: 合计 | B14: =SUM(B9,B12,B13:B13) -> 0 | C14: =SUM(C9:C13) -> 0 | D14: =SUM(D9:D13) -> -200000 | E14: =SUM(E9:E13) -> 1000000 | F14: =SUM(F9:F13) -> -1200000 | G14: =SUM(G9:G13) -> 0 | I14: =SUM(I7:I13) -> 760000 | J14: =SUM(J9:J13) -> 0
A15: 三、审计说明： | E15: 四、审计结论：
A20: 编制说明：
A21: 1、本科目核算净敞口套期下被套期项目累计公允价值变动转入当期损益的金额或现金流量套期储备转入当期损益的金额。
A22: 2、对于净敞口公允价值套期，应当在被套期项目影响损益时，将被套期项目因被套期风险敞口形成的累计利得或损失转出，贷记或借记“被套期项目”等科目，借记或贷记本科目。
A23: 3、对于净敞口现金流量套期，应当在将相关现金流量套期储备转入当期损益时，借记或贷记“其他综合收益——套期储备”贷记或借记本科目；将相关现金流量套期储备转入资产或负债的，当资产和负债影响损益时，借记或贷记资产（或其备抵科目）、负债科目，贷记或借记本科目。
A24: 4、审计说明可以概述：1)程序的测试情况、结果;(2)拟调整事项及其调整分录、未调整事项及其影响，审计范围受到限制情况及其影响。
A25: 5、审计结论可参考：A、未见异常。 B、除上述重大不符事项应当作为调整事项予以调整外，其余未见异常。 C、由于存在以下重大未调整事项(或审计范围受到限制无法获取充分、适当证据)，不可确认。

Sheet 调整分录汇总G12-3
A1: 致同会计师事务所
A2: 净敞口套期收益调整分录汇总表
A3: =底稿目录!A2 -> 被审计单位： | D3: =底稿目录!A4 -> 编制人： | G3: =底稿目录!A5 -> 编制日期： | I3: 索引号： | J3: =底稿目录!F9 -> G12-3
A4: =底稿目录!A3 -> 会计期间：202X年度 | D4: =底稿目录!A6 -> 复核人： | G4: =底稿目录!A7 -> 复核日期： | I4: 页 次：1
A5: 调整事项说明 | B5: 类别（报表调整/账项调整/其他） | C5: 报表项目 | D5: 科目名称 | E5: 附注项目 | F5: …… | G5: 借方调整金额 | H5: 贷方调整金额 | I5: 索引 | J5: 备注

Sheet 公允价值测试表G12-4
A1: 致同会计师事务所
A2: 套期工具投资公允价值测试表
A3: =底稿目录!A2 -> 被审计单位： | E3: =底稿目录!A4 -> 编制人： | I3: =底稿目录!A5 -> 编制日期： | P3: 索引号： | Q3: =底稿目录!F10 -> G12-4
A4: =底稿目录!A3 -> 会计期间：202X年度 | E4: =底稿目录!A6 -> 复核人： | I4: =底稿目录!A7 -> 复核日期： | P4: 页 次：
A5: 一、审计目标 | B5: 确定被审计单位套期工具投资以公允价值计量。
A6: 二、审计过程
A7: 套期工具 | B7: 期末未审数 | F7: 期末审定数 | J7: 差异 | K7: 估值方法 | L7: 估值方法与上期是否一致 | M7: 第一层次 | N7: 第二层次 | O7: 第三层次 | R7: 估值文件索引号
B8: 数量（张/股） | C8: 单位公允价值 | D8: 公允价值 | E8: 公允价值层次 | F8: 数量（张/股） | G8: 单位公允价值 | H8: 公允价值 | I8: 公允价值层次 | M8: 公允价值来源机构 | N8: 输入值来源及调整考虑因素 | O8: 估值技术 | P8: 不可观察输入值 | Q8: 数值
D9: =B9*C9 -> 0 | E9: 第二层次 | H9: =F9*G9 -> 0 | I9: 第二层次 | J9: =H9-D9 -> 0 | N9: 以合同规定的未来现金流量按照市场上具有可比信用等级并在相同条件下提供几乎相同现金流量的利率进行折现后的现值确定
D10: =B10*C10 -> 0 | H10: =F10*G10 -> 0 | I10: 第三层次 | J10: =H10-D10 -> 0
H11: =F11*G11 -> 0 | J11: =H11-D11 -> 0
H12: =F12*G12 -> 0 | J12: =H12-D12 -> 0
H13: =F13*G13 -> 0 | J13: =H13-D13 -> 0
H14: =F14*G14 -> 0 | J14: =H14-D14 -> 0
H15: =F15*G15 -> 0 | J15: =H15-D15 -> 0
H16: =F16*G16 -> 0 | J16: =H16-D16 -> 0
H17: =F17*G17 -> 0 | J17: =H17-D17 -> 0
H18: =F18*G18 -> 0 | J18: =H18-D18 -> 0
A19: 合计 | D19: =SUM(D9:D18) -> 0 | H19: =SUM(H9:H18) -> 0 | J19: =SUM(J9:J18) -> 0
A20: 三、审计说明： | H20: 四、审计结论：
A23: 编制说明：
A24: 概述：（1）程序的测试情况、结果；
A25: （2）拟调整事项及其调整分录、未调整事项及其影响，审计范围受到限制情况及其影响。
A26: 参考结论：
A27: A、 | B27: 未见异常。
A28: B、 | B28: 除以下重大不符事项应当作为调整事项予以调整外，其余未见异常。
A29: C、 | B29: 由于存在以下重大未调整事项（或审计范围受到限制无法获取充分、适当证据），不可确认。

Sheet 风险净敞口检查表G12-5
A1: 致同会计师事务所
A2: 风险净敞口检查表
A3: =底稿目录!A2 -> 被审计单位： | D3: =底稿目录!A4 -> 编制人： | F3: =底稿目录!A5 -> 编制日期： | H3: 索引号： | I3: =底稿目录!F11 -> G12-5
A4: =底稿目录!A3 -> 会计期间：202X年度 | D4: =底稿目录!A6 -> 复核人： | F4: =底稿目录!A7 -> 复核日期： | H4: 页 次：
A5: 一、测试目标： | B5: 检查风险净敞口的支持性证据，
A6: 二、样本选取标准与规模：
B7: 运用风险净敞口套期的风险净敞口
A8: 三、测试：
A9: 项目 | B9: 头寸1 | D9: 头寸2 | F9: 净头寸 | G9: 支持性证据 | H9: 套期工具 | I9: 索引号
B10: 头寸 | C10: 金额 | D10: 头寸 | E10: 金额
A11: 预期销售和预期采购的外汇净头寸 | B11: 预期外币销售收入 | C11: 1 000万美元 | D11: 预期外币固定资产采购 | E11: 1 200万美元 | F11: 支付200万美元
A17: 四、审计说明：
A20: 五、审计结论：
A24: 编制说明：
A25: 1、概述：（1）程序的测试情况、结果；
A26: （2）拟调整事项及其调整分录、未调整事项及其影响，审计范围受到限制情况及其影响。
A27: 参考结论：
A28: A、
A29: B、
A30: C、
A32: 2、选取测试项目的方法：包括选取全部项目、选取特定项目和审计抽样。
A33: （1）
A44: （2）
A56: （3）
B76: 扩展系数
B77: 1.9
B78: 1.6
B79: 1.5

Sheet 凭证检查表G12-6
A1: 致同会计师事务所
A2: 净敞口套期收益凭证检查表
A3: =底稿目录!A2 -> 被审计单位： | D3: =底稿目录!A4 -> 编制人： | G3: =底稿目录!A5 -> 编制日期： | O3: 索引号： | P3: =底稿目录!F12 -> G12-6
A4: =底稿目录!A3 -> 会计期间：202X年度 | D4: =底稿目录!A6 -> 复核人： | G4: =底稿目录!A7 -> 复核日期： | O4: 页 次：
A5: 一、审计目标
A6: 1.利润表中记录的投资收益已发生，且与被审计单位有关，已记录于恰当的账户；2.所有应记录的投资收益均已记录，所有应当包括在财务报表中的相关披露均已包括；
A7: 3.与投资收益有关的金额及其他数据已恰当记录，相关披露已得到恰当计量和描述
A8: 二、样本选取方法与规模：
A9: 测试总体： | B9: 如本期发生额所有凭证共XX笔金额XX | E9: 特定样本： | F9: XX金额以上（大额）、关联方/关联交易形成的款项、XX异常款项全部测试，共XX笔；
A10: 抽样总体： | B10: 测试总体扣除特定样本以外的样本，共XX笔、金额XX | E10: 确定的抽样样本量： | F10: 抽取XX笔（如果使用了样本计算器计算样本量，样本量计算过程见<XX>底稿）
A11: 抽样方法： | B11: 随机选样/系统选样/货币单元抽样/随意选样（非统计抽样适用） | E11: 抽样过程： | F11: 使用IDEA（XX抽样工具）选择XX数量、金额XX的样本进行测试，抽样工具中的样本选择过程和结果见<XX>底稿
A12: 三、测试：
A13: 测试内容说明：1.原始凭证内容完整； 2.有授权批准；3.账务处理正确；4.初始成本计算准确；5.符合套期会计要求；6、公允价值符合准则要求。
A14: 记账凭证 | G14: 支持性文件 | H14: 核对内容 | N14: 索引号 | O14: 是否异常 | P14: 备注说明
A15: 日期 | B15: 凭证编号 | C15: 业务内容 | D15: 对方科目 | E15: 明细科目 | F15: 贷方金额 | H15: 1 | I15: 2 | J15: 3 | K15: 4 | L15: 5 | M15: 6
A24: 合计 | F24: =SUM(F16:F23) -> 0
A25: 本期发生额 | F25: ='审定表G12-1'!G12 -> 0
A26: 检查比例 | F26: =F24/F25 -> #DIV/0!
A27: 四、审计说明：
A31: 五、审计结论：
A35: 编制说明：
A36: 1、概述：（1）程序的测试情况、结果；
A37: （2）拟调整事项及其调整分录、未调整事项及其影响，审计范围受到限制情况及其影响。
A38: 参考结论：
A39: A、 | B39: 未见异常。
A40: B、 | B40: 除以下重大不符事项应当作为调整事项予以调整外，其余未见异常。
A41: C、 | B41: 由于存在以下重大未调整事项（或审计范围受到限制无法获取充分、适当证据），不可确认。
A43: 2、选取测试项目的方法：包括选取全部项目、选取特定项目和审计抽样。
A44: （1） | B44: 当存在下列情形之一时，注册会计师应当考虑选取全部项目进行测试：
B45: （一）总体由少量的大额项目构成；
B46: （二）存在特别风险且其他方法未提供充分、适当的审计证据；
B47: （三）由于信息系统自动执行的计算或其他程序具有重复性，对全部项目进行检查符合成本效益原则。
B49: 特别风险涉及的事项包括但不限于：
B50: （1）舞弊风险（如1141准则的示例）；（2）重大非常规交易（如企业购并、债务重组、非货币性资产交换、
B51: 重大或有事项、持续经营、违反法律法规等）；(3)重大关联交易；(4)重大判断事项（如重大会计估计、
B52: 会计政策及其变更）；(5)重大复杂交易；(6)仅通过实质性程序无法应对的重大错报风险（如日常交易采用
B53: 高度自动化处理）等等。
A55: （2） | B55: 选取的特定项目可能包括：
B56: （一）大额或关键项目；
B57: （二）超过某一金额的全部项目；
...
