Workbook

Sheet 底稿目录
A1: 底稿开列时，可先在以下单元格填写有关内容，以便其他底稿引用有关数据：
A2: 被审计单位：
A3: 会计期间：202X年度 | D3: 序号 | E3: 内容 | F3: 索引号
A4: 编制人： | E4: 公允价值变动收益实质性程序表 | F4: G13A
A5: 编制日期： | D5: 1 | E5: 审定表 | F5: G13-1
A6: 复核人： | D6: =D5+1 -> 2 | E6: 附注披露信息（上市公司） | G6: 无需打印
A7: 复核日期： | D7: =D6+1 -> 3 | E7: 附注披露信息（国企） | G7: 无需打印
D8: =D7+1 -> 4 | E8: 明细表 | F8: G13-2
A9: 关于工作底稿与审计程序索引号对应的说明 | D9: =D8+1 -> 5 | E9: 调整分录汇总 | F9: G13-3
A10: 1.编制的审计工作底稿应与审计程序对应。审计项目组应根据被审计单位实际情况和风险评估情况在实质性程序表中裁剪、修改或增加审计程序，根据实际执行的审计程序完成相应审计工作底稿，编制的工作底稿中应按自然顺序依次编制索引号，并通过唯一的索引号将与实质性程序表中的程序对应关联（即将工作底稿的索引号填入实质性程序表中的底稿索引号列）。
A14: 2.获取的支持性证据应与审计底稿或程序对应。审计项目组在完成底稿时获取的支持性证据应根据底稿索引号编制下一级按自然顺序排序的索引号（如D1-2-1、D1-2-2、……），并在底稿中说明引用的支持性证据、关联索引号。
A17: 3.工作底稿索引号的编码规则：实质性程序索引号按循环从“D”到“N”,循环内账户以顺序号排列，模板中底稿索引号按账户顺序+自然数顺序（即模板中索引号按二级自然顺序排列，如D1-1、D1-2、D1-3、……D1-N）。

Sheet 公允价值变动收益审计程序表G13A
A1: 致同会计师事务所
A2: 公允价值变动收益实质性程序表
A3: =底稿目录!A2 -> 被审计单位： | C3: =底稿目录!A4 -> 编制人： | F3: =底稿目录!A5 -> 编制日期： | H3: 索引号： | I3: =底稿目录!F4 -> G13A
A4: =底稿目录!A3 -> 会计期间：202X年度 | C4: =底稿目录!A6 -> 复核人： | F4: =底稿目录!A7 -> 复核日期： | H4: 页 次：
A5: 一、本账户涉及的科目
A6: 公允价值变动收益
A7: 二、审计目标与认定的对应关系
A8: 审计目标 | G8: 财务报表的认定
A9: A. 利润表中记录的公允价值变动收益已发生，且与被审计单位有关，已记录于恰当的账户 | G9: 存在
A10: B. 所有应记录的公允价值变动收益均已记录，所有应当包括在财务报表中的相关披露均已包括 | G10: 完整性
A11: C. 与公允价值变动收益有关的金额及其他数据已恰当记录，相关披露已得到恰当计量和描述 | G11: 准确性
A12: D. 公允价值变动收益已记录于正确的会计期间 | G12: 截止
A13: E. 公允价值变动收益已被恰当地汇总或分解且表述清楚，相关披露在按照企业会计准则的编制基础下是相关的、可理解的 | G13: 列报
A14: 三、计划实施的实质性程序
A15: 序号 | B15: 审计程序 | C15: 程序分类 | D15: 财务报表的认定 | I15: 底稿索引号
D16: 发生 | E16: 完整性 | F16: 准确性 | G16: 截止 | H16: 列报 | J16: 根据被审计单位实际情况和风险评估情况裁剪、修改或增加审计程序
A17: 1 | B17: 获取或编制公允价值变动损益的明细表，完成以下工作，并编制审定表 （1）复核加计是否正确，与总账、明细账合计数核对是否相符； （2）将上期发生额与上期经审计的财务报表核对； （3）追查明细表至调节表； （4）与上年明细项目进行比较，确定与上年分类相同； （5）结合交易性金融资产、交易性金融负债、衍生工具、投资性房地产等科目的审计，复核其勾稽关系； （6）调查重大或者异常的调节项目，并与客户的适当人员讨论差异，考虑回复的可信度并确认相关解释，以及采取适当的措施； （7）检查非记账本位币计量的公允价值变动损益的折算汇率及折算是否正确。 | C17: 常规★ | D17: √ | E17: √ | F17: √ | I17: G13-1 /G13-2
A18: 2 | B18: 在使用手工编制、自定义信息报告、系统生成的非固定格式报告等由被审计单位生成的信息时，测试有关信息准确性和完整性，并考虑针对编制和维护由被审计单位生成的信息的相关控制实施控制测试，以评价该信息是否能够为实现审计目的提供基础。 | C18: 常规★ | E18: √ | F18: √ | I18: T1
A19: 3 | B19: 对上期数的审计，取得上期明细表复核加计是否正确，与总账、明细账合计数是否相符，确定计算的准确性；确定是否需要补充必要的程序，如果是，执行适当的应对程序。（适用于首次承接） | C19: 备选 | G19: √
A20: 4 | B20: 获取或编制增、减分析表，分析增加内容及减少方式、对损益的影响，与相关科目核对一致； | C20: 常规★ | D20: √ | E20: √ | F20: √ | G20: √ | I20: G13-2
A21: 5 | B21: 检查关联方交易： （1）了解关联交易的商业理由、交易事项的目的、价格和条件，考虑对关联方交易性金融资产的合理性、合法性； （2）检查对关联方交易性金融资产的真实性相关的支持性文件、检查会计处理是否正确； （3）考虑向关联方或其他注册会计师函证重大的关联交易和余额（包括担保和其他重要信息）； （4）必要时，向与交易相关的人员和机构函证或与其讨论有关信息； （5）考虑是否存在未识别的关联方，关联交易和余额披露是否正确。 | C21: 常规★ | D21: √ | E21: √ | F21: √ | G21: √ | H21: √
A22: 6 | B22: 根据评估的舞弊风险等因素增加的审计程序。 | C22: IPO/上市/新三板/重组/舞弊应对
A23: 7 | B23: 检查公允价值变动收益是否已按企业会计准则或其他适用的规定在财务报表中做出恰当列报和披露。 | C23: 常规★ | H23: √ | I23: A1-1/A1-15 /A1-16

Sheet 公允价值变动收益审计程序表G13A-修订前
A1: 致同会计师事务所
A2: 公允价值变动收益实质性程序表
A3: =底稿目录!A2 -> 被审计单位： | C3: =底稿目录!A4 -> 编制人： | F3: =底稿目录!A5 -> 编制日期： | H3: 索引号： | I3: =底稿目录!F4 -> G13A
A4: =底稿目录!A3 -> 会计期间：202X年度 | C4: =底稿目录!A6 -> 复核人： | F4: =底稿目录!A7 -> 复核日期： | H4: 页 次：
A5: 一、本账户涉及的科目
A6: 公允价值变动收益
A7: 二、重大错报风险需从实质性程序获取的保证程度
A8: 审计目标与认定对应关系 | C8: 财务报表的认定 | H8: 信赖/不信赖/不适用 | I8: 索引号
C9: 发生 | D9: 完整性 | E9: 准确性 | F9: 分类 | G9: 列报与披露
A10: A. 利润表中记录的公允价值变动收益已发生，且与被审计单位有关。 | C10: √
A11: B. 所有应当记录的公允价值变动收益均已记录。 | D11: √
A12: C. 与公允价值变动收益有关的金额及其他数据已恰当记录于正确的会计期间。 | E12: √
A13: D. 公允价值变动收益已记录于恰当的账户。 | F13: √
A14: E. 公允价值变动收益已按照企业会计准则的规定在财务报表中作出恰当的列报和披露。 | G14: √
A15: 三、计划实施的实质性程序
A16: 序号 | B16: 审计程序 | C16: 程序分类 | D16: 审计目标 | H16: 执行情况说明 （含底稿索引）
A17: （一） | B17: 编制审定表 | C17: 常规★ | D17: D | H17: I9 | J17: 整合为1 | K17: 获取或编制公允价值变动损益的明细表，完成以下工作，并编制审定表 （1）复核加计是否正确，与总账、明细账合计数核对是否相符； （2）将上期发生额与上期经审计的财务报表核对； （3）追查明细表至调节表； （4）与上年明细项目进行比较，确定与上年分类相同； （5）结合公允价值变动损益、交易性金融负债、应收款项融资、衍生工具、投资性房地产等科目的审计，复核其勾稽关系； （6）调查重大或者异常的调节项目，并与客户的适当人员讨论差异，考虑回复的可信度并确认相关解释，以及采取适当的措施； （7）检查非记账本位币计量的公允价值变动损益的折算汇率及折算是否正确。
A18: （二） | B18: 获取或编制明细并执行下列程序： | C18: 常规★ | D18: D | J18: 整合为1
A19: 1 | B19: 复核加计正确 。 | C19: 常规★ | D19: BD | J19: 整合为1
A20: 2 | B20: 将总金额与总账、明细账合计数核对相符。 | C20: 常规★ | D20: BD | J20: 整合为1
A21: 3 | B21: 将上期发生额与上期经审计的财务报表核对。 | C21: 常规 | D21: BD | J21: 整合为1
A22: 4 | B22: 追查明细表至调节表。 | C22: 常规 | D22: BD | J22: 整合为1
A23: 5 | B23: 与上年明细项目进行比较，确定与上年分类相同。 | C23: 常规 | D23: BD | J23: 整合为1
A24: 6 | B24: 结合交易性金融资产、交易性金融负债、应收款项融资、衍生工具、投资性房地产等科目的审计，复核其勾稽关系。 | C24: 常规★ | D24: BD | J24: 整合为1
A25: 7 | B25: 调查重大或者异常的调节项目。 | C25: 常规 | D25: BD | J25: 整合为1
A26: 8 | B26: 与客户的适当人员讨论差异。 | C26: 常规 | D26: BD | J26: 整合为1
A27: 9 | B27: 考虑回复的可信度并确认相关解释，以及采取适当的措施。 | C27: 常规 | D27: BD | J27: 整合为1
A28: （三） | B28: 在使用被审计单位生成的信息（IPE）时，应当评价该信息对实现审计目的是否足够可靠，包括根据具体情况在必要时实施下列程序： | C28: 常规★ | D28: B | H28: T1 | J28: 保留修改为2 | K28: 在使用手工编制、自定义信息报告、系统生成的非固定格式报告等由被审计单位生成的信息时，测试有关信息准确性和完整性，并考虑针对编制和维护由被审计单位生成的信息的相关控制实施控制测试，以评价该信息是否能够为实现审计目的提供基础。
A29: 1 | B29: 获取有关信息准确性和完整性的审计证据。 | J29: 保留修改为2
A30: 2 | B30: 评价信息对实现审计目的是否足够准确和详细。 | J30: 保留修改为2
A31: （四） | B31: 若系首次承接，获取前期期末各科目明细表，执行下列程序：（适用于首次审计时对期初余额的审计） | C31: 备选 | D31: B | H31: I9-2 | J31: 保留为3
A32: 1 | B32: 确定计算的准确性。 | C32: 备选 | D32: B | J32: 保留为3
A33: 2 | B33: 与总账核对一致。 | C33: 备选 | D33: B | J33: 保留为3
A34: 3 | B34: 确定是否需要补充必要的程序，如果是，执行适当的应对程序。 | C34: 备选 | D34: B | J34: 保留为3
A35: （五） | B35: 根据实际情况，实施以下分析程序： | C35: 常规 | D35: A | H35: I9-2 | J35: 保留为4
A36: 1 | B36: 获取或编制增、减分析表，确定增加内容及减少方式、对损益的影响； | C36: 常规 | D36: A | J36: 保留为4
A37: （六） | B37: 考虑大额或异常的余额或交易是否表明存在未识别的关联方。（参考“D 收入循环”关联方及关联方交易相关审计程序） | C37: 常规 | D37: AD | H37: I9-2 | J37: 保留为5
A38: （七） | B38: 根据评估的舞弊风险等因素增加审计程序，例如： | C38: 备选 | D38: A | H38: I9-2 | J38: 保留为6
A39: 1 | B39: 针对识别的特别风险（包括舞弊风险）考虑以下方面：期末或接近期末时的大额记录；在期末或接近期末增加的交易数量；异常的过账分录；期末或接近期末时的大笔日记账分录；会计处理方法或其他方面存在重大调整的项目；与复杂交易有关的项目；涉及重大判断或估计、计量结果具有高度不确定性的项目；涉及重大关联交易的项目；其他特殊项目。 | C39: 备选 | D39: A | J39: 保留为6
A40: 2 | B40: 询问会计部门以外的负责发起执行投资交易的人员如下内容：存在舞弊或舞弊嫌疑；未披露的附加协议；企业的异常活动或指令。 | C40: 备选 | D40: A | J40: 保留为6
...

Sheet 审定表G13-1
A1: 致同会计师事务所
A2: 公允价值变动收益审定表
A3: =底稿目录!A2 -> 被审计单位： | D3: =底稿目录!A4 -> 编制人： | G3: =底稿目录!A5 -> 编制日期： | I3: 索引号： | J3: =底稿目录!F5 -> G13-1
A4: =底稿目录!A3 -> 会计期间：202X年度 | D4: =底稿目录!A6 -> 复核人： | G4: =底稿目录!A7 -> 复核日期： | I4: 页 次：
A5: 项目 | B5: 本期数 | E5: 上期数 | H5: 本期与上期审定数比较 | J5: 原因分析
B6: 未审数 | C6: 调整数 | D6: 审定数 | E6: 未审数 | F6: 调整数 | G6: 审定数 | H6: 变动额 | I6: 变动率
A7: 交易性金融资产 | B7: =B8+B9 -> 0 | C7: =C8+C9 -> 0 | D7: =B7+C7 -> 0 | G7: =E7+F7 -> 0 | H7: =D7-G7 -> 0 | I7: =IF(AND(G9=0,D7=0),"",IF(AND(G9=0,D7>0),1,H7/G9))
A8: 其中：指定为以公允价值计量且其变动计入当期损益的金融资产 | B8: ='明细表G13-2'!B12 -> 0 | C8: ='明细表G13-2'!C12 -> 0 | D8: =B8+C8 -> 0 | G8: =E8+F8 -> 0 | H8: =D8-G8 -> 0 | I8: =IF(AND(G8=0,D8=0),"",IF(AND(G8=0,D8>0),1,H8/G8))
A9: 衍生金融资产 | B9: ='明细表G13-2'!B13 -> 0 | C9: ='明细表G13-2'!C13 -> 0 | D9: =B9+C9 -> 0 | G9: =E9+F9 -> 0 | H9: =D9-G9 -> 0 | I9: =IF(AND(G9=0,D9=0),"",IF(AND(G9=0,D9>0),1,H9/G9))
A10: 交易性金融负债 | B10: =B11+B12 -> 0 | C10: =C11+C12 -> 0 | D10: =B10+C10 -> 0 | G10: =E10+F10 -> 0 | H10: =D10-G10 -> 0 | I10: =IF(AND(G10=0,D10=0),"",IF(AND(G10=0,D10>0),1,H10/G10))
A11: 其中：指定为以公允价值计量且其变动计入当期损益的金融负债 | B11: ='明细表G13-2'!B15 -> 0 | C11: ='明细表G13-2'!C15 -> 0 | D11: =B11+C11 -> 0 | G11: =E11+F11 -> 0 | H11: =D11-G11 -> 0 | I11: =IF(AND(G11=0,D11=0),"",IF(AND(G11=0,D11>0),1,H11/G11))
A12: 衍生金融负债 | B12: ='明细表G13-2'!B16 -> 0 | C12: ='明细表G13-2'!C16 -> 0 | D12: =B12+C12 -> 0 | G12: =E12+F12 -> 0 | H12: =D12-G12 -> 0 | I12: =IF(AND(G12=0,D12=0),"",IF(AND(G12=0,D12>0),1,H12/G12))
A13: 其他非流动金融资产 | B13: =B14 -> 0 | C13: =C14 -> 0 | D13: =B13+C13 -> 0 | G13: =E13+F13 -> 0 | H13: =D13-G13 -> 0 | I13: =IF(AND(G13=0,D13=0),"",IF(AND(G13=0,D13>0),1,H13/G13))
A14: 其中：指定为以公允价值计量且其变动计入当期损益的金融资产 | B14: ='明细表G13-2'!B18 -> 0 | C14: ='明细表G13-2'!C18 -> 0 | D14: =B14+C14 -> 0 | G14: =E14+F14 -> 0 | H14: =D14-G14 -> 0 | I14: =IF(AND(G14=0,D14=0),"",IF(AND(G14=0,D14>0),1,H14/G14))
A15: 以公允价值计量的投资性房地产 | B15: ='明细表G13-2'!B19 -> 0 | C15: ='明细表G13-2'!C19 -> 0 | D15: =B15+C15 -> 0 | G15: =E15+F15 -> 0 | H15: =D15-G15 -> 0 | I15: =IF(AND(G15=0,D15=0),"",IF(AND(G15=0,D15>0),1,H15/G15))
A16: 其他 | B16: ='明细表G13-2'!B20 -> 0 | C16: ='明细表G13-2'!C20 -> 0 | D16: =B16+C16 -> 0 | G16: =E16+F16 -> 0 | H16: =D16-G16 -> 0 | I16: =IF(AND(G16=0,D16=0),"",IF(AND(G16=0,D16>0),1,H16/G16))
A17: 合计 | B17: =SUM(B7,B10,B13,B15:B16) -> 0 | C17: =SUM(C7,C10,C13,C15:C16) -> 0 | D17: =SUM(D7,D10,D13,D15:D16) -> 0 | E17: =SUM(E7,E10,E13,E15:E16) -> 0 | F17: =SUM(F7,F10,F13,F15:F16) -> 0 | G17: =SUM(G9,G10,G13,G15:G16) -> 0 | H17: =SUM(H7,H10,H13,H15:H16) -> 0 | I17: =SUM(I7,I10,I13,I15:I16) -> 0
A18: 试算平衡表数
A19: 差异数 | D19: =D17-D18 -> 0 | G19: =G17-G18 -> 0
A20: 1、审计说明
A21: （1）公允价值变动收益本期较上期增加（负数为减少）： | D21: =IF(AND(G17=0,D17=0),0,IF(AND(G17=0,D17>0),1,(D17-G17)/G17)) -> 0
A22: 主要原因（比例超过30%的）：
A24: （2）情况说明
A25: 2、审计结论
A28: 编制说明【非打印内容】
A29: 本科目核算企业交易性金融资产、交易性金融负债，以及采用公允价值模式计量的投资性房地产、衍生工具、套期保值业务等公允价值变动形成的应计入当期损益的利得或损失。
A30: 指定为以公允价值计量且其变动计入当期损益的金融资产或金融负债公允价值变动形成的应计入当期损益的利得或损失，也在本科目核算。
A31: 企业开展套期保值业务的，有效套期关系中套期工具或被套期项目的公允价值变动，也可以单独设置“6102 套期损益”科目核算。

Sheet 附注披露信息（上市公司）
A1: 致同会计师事务所
A2: 附注披露信息（上市公司）
A3: =底稿目录!A2 -> 被审计单位： | B3: =底稿目录!A4 -> 编制人： | C3: =底稿目录!A5 -> 编制日期： | D3: 索引号： | E3: =底稿目录!F6 -> 0
A4: =底稿目录!A3 -> 会计期间：202X年度 | B4: =底稿目录!A6 -> 复核人： | C4: =底稿目录!A7 -> 复核日期： | D4: 页次：
A5: 附注披露信息
A6: 公允价值变动收益（注：以下不存在的项目可以删除）
A7: 产生公允价值变动收益的来源 | B7: 本期发生额 | C7: 上期发生额
A8: 交易性金融资产 | B8: =B9+B10 -> 0 | C8: =C9+C10 -> 0
A9: 其中：指定为以公允价值计量且其变动计入当期损益的金融资产 | B9: ='审定表G13-1'!D8 -> 0 | C9: ='审定表G13-1'!G8 -> 0
A10: 衍生金融工具产生的公允价值变动收益 | B10: ='审定表G13-1'!D9+'审定表G13-1'!D12 -> 0 | C10: ='审定表G13-1'!G9+'审定表G13-1'!G12 -> 0
A11: 交易性金融负债 | B11: =SUM(B12:B13) -> 0 | C11: =SUM(C12:C13) -> 0
A12: 其中：指定为以公允价值计量且其变动计入当期损益的金融负债 | B12: ='审定表G13-1'!D11 -> 0 | C12: ='审定表G13-1'!G11 -> 0
A13: 其他非流动金融资产 | B13: ='审定表G13-1'!D13 -> 0 | C13: ='审定表G13-1'!G13 -> 0
A14: 其中：指定为以公允价值计量且其变动计入当期损益的金融资产 | B14: ='审定表G13-1'!D14 -> 0 | C14: ='审定表G13-1'!G14 -> 0
A15: 按公允价值计量的投资性房地产 | B15: ='审定表G13-1'!D15 -> 0 | C15: ='审定表G13-1'!G15 -> 0
A16: 其他 | B16: ='审定表G13-1'!D16 -> 0 | C16: ='审定表G13-1'!G16 -> 0
A17: 合 计 | B17: =B8+B10+B11+B13+B15+B16 -> 0 | C17: =C8+C10+C11+C13+C15+C16 -> 0

Sheet 附注披露信息（国企）
A1: 致同会计师事务所
A2: 附注披露信息（国企）
A3: =底稿目录!A2 -> 被审计单位： | B3: =底稿目录!A4 -> 编制人： | C3: =底稿目录!A5 -> 编制日期： | D3: 索引号： | E3: =底稿目录!F7 -> 0
A4: =底稿目录!A3 -> 会计期间：202X年度 | B4: =底稿目录!A6 -> 复核人： | C4: =底稿目录!A7 -> 复核日期： | D4: 页次：
A5: 附注披露信息
A6: 公允价值变动收益（注：以下不存在的项目可以删除）
A7: 产生公允价值变动收益的来源 | B7: 本期发生额 | C7: 上期发生额
A8: 交易性金融资产 | B8: ='审定表G13-1'!D7-'审定表G13-1'!D9 -> 0 | C8: ='审定表G13-1'!G7-'审定表G13-1'!G9 -> 0
A9: 衍生金融资产 | B9: ='审定表G13-1'!D9 -> 0 | C9: ='审定表G13-1'!G9 -> 0
A10: 其他非流动金融资产 | B10: ='审定表G13-1'!D13 -> 0 | C10: ='审定表G13-1'!G13 -> 0
A11: 交易性金融负债 | B11: ='审定表G13-1'!D10-'审定表G13-1'!D12 -> 0 | C11: ='审定表G13-1'!G10-'审定表G13-1'!G12 -> 0
A12: 衍生金融负债 | B12: ='审定表G13-1'!D12 -> 0 | C12: ='审定表G13-1'!G12 -> 0
A13: 按公允价值计量的投资性房地产 | B13: ='审定表G13-1'!D15 -> 0 | C13: ='审定表G13-1'!G15 -> 0
A14: 其他 | B14: ='审定表G13-1'!D16 -> 0 | C14: ='审定表G13-1'!G16 -> 0
A15: 合 计 | B15: =SUM(B8:B14) -> 0 | C15: =SUM(C8:C14) -> 0

Sheet 明细表G13-2
A1: 致同会计师事务所
A2: 公允价值变动收益明细表
A3: =底稿目录!A2 -> 被审计单位： | D3: =底稿目录!A4 -> 编制人： | G3: =底稿目录!A5 -> 编制日期： | K3: 索引号： | L3: =底稿目录!F8 -> G13-2
A4: =底稿目录!A3 -> 会计期间：202X年度 | D4: =底稿目录!A6 -> 复核人： | G4: =底稿目录!A7 -> 复核日期： | K4: 页 次：
A5: 一、审计目标
A6: 1.利润表中记录的公允价值变动收益已发生，且与被审计单位有关，已记录于恰当的账户；2.所有应记录的公允价值变动收益均已记录，所有应当包括在财务报表中的相关披露均已包括；
A7: 3.与公允价值变动收益有关的金额及其他数据已恰当记录，相关披露已得到恰当计量和描述
A8: 二、审计过程：
A9: 项目 | B9: 本期数 | E9: 对应科目 | F9: 对应科目-公允价值变动 | K9: 核对 | L9: 索引号
B10: 未审数 | C10: 调整数 | D10: 审定数 | F10: 成本 | G10: 本期公允价值变动 | H10: 累计公允价值变动 | I10: 公允价值 | J10: 计入损益
A11: 交易性金融资产 | B11: =B12+B13 -> 0 | C11: =C12+C13 -> 0 | D11: =B11+C11 -> 0 | E11: 交易性金融资产 | I11: =F11+H11 -> 0 | J11: =G11 -> 0 | K11: =J11=D11 -> TRUE
A12: 其中：指定为以公允价值计量且其变动计入当期损益的金融资产 | D12: =B12+C12 -> 0 | E12: 交易性金融资产 | I12: =F12+H12 -> 0 | J12: =G12 -> 0 | K12: =J12=D12 -> TRUE
A13: 衍生金融资产 | D13: =B13+C13 -> 0 | E13: 交易性金融资产/衍生金融资产 | I13: =F13+H13 -> 0 | J13: =G13 -> 0 | K13: =J13=D13 -> TRUE
A14: 交易性金融负债 | B14: =B15+B16 -> 0 | C14: =C15+C16 -> 0 | D14: =B14+C14 -> 0 | E14: 交易性金融负债 | I14: =F14+H14 -> 0 | J14: =G14 -> 0 | K14: =J14=D14 -> TRUE
A15: 其中：指定为以公允价值计量且其变动计入当期损益的金融负债 | D15: =B15+C15 -> 0 | E15: 交易性金融负债 | I15: =F15+H15 -> 0 | J15: =G15 -> 0 | K15: =J15=D15 -> TRUE
A16: 衍生金融负债 | D16: =B16+C16 -> 0 | E16: 交易性金融负债/衍生金融负债 | I16: =F16+H16 -> 0 | J16: =G16 -> 0 | K16: =J16=D16 -> TRUE
A17: 其他非流动金融资产 | B17: =B18 -> 0 | C17: =C18 -> 0 | D17: =B17+C17 -> 0 | E17: 其他非流动金融资产 | I17: =F17+H17 -> 0 | J17: =G17 -> 0 | K17: =J17=D17 -> TRUE
A18: 其中：指定为以公允价值计量且其变动计入当期损益的金融资产 | D18: =B18+C18 -> 0 | E18: 其他非流动金融资产 | I18: =F18+H18 -> 0 | J18: =G18 -> 0 | K18: =J18=D18 -> TRUE
A19: 以公允价值计量的投资性房地产 | D19: =B19+C19 -> 0 | E19: 投资性房地产 | I19: =F19+H19 -> 0 | J19: =G19 -> 0 | K19: =J19=D19 -> TRUE
A20: 其他 | D20: =B20+C20 -> 0 | I20: =F20+H20 -> 0 | J20: =G20 -> 0 | K20: =J20=D20 -> TRUE
A21: 合计 | B21: =B11+B14+B17+B19+B20 -> 0 | C21: =C11+C14+C17+C19+C20 -> 0 | D21: =D11+D14+D17+D19+D20 -> 0 | I21: =SUM(I11:I20) -> 0 | J21: =SUM(J11:J20) -> 0 | K21: =J21=D21 -> TRUE
A22: 三、审计说明：
A26: 编制说明：
A27: 1.审计说明可以概述:(1)程序的测试情况、结果;(2)拟调整事项及其调整分录、未调整事项及其影响，审计范围受到限制情况及其影响。
A28: 2.审计结论可参考:A、未见异常。 B、除上述重大不符事项应当作为调整事项予以调整外，其余未见异常。由于存在以下重大未调整事项(或审计范围受到限制无法获取充分、适当证据)，不可确认。

Sheet 调整分录汇总G13-3
A1: 致同会计师事务所
A2: 公允价值变动收益调整分录汇总表
A3: =底稿目录!A2 -> 被审计单位： | D3: =底稿目录!A4 -> 编制人： | G3: =底稿目录!A5 -> 编制日期： | I3: 索引号： | J3: =底稿目录!F9 -> G13-3
A4: =底稿目录!A3 -> 会计期间：202X年度 | D4: =底稿目录!A6 -> 复核人： | G4: =底稿目录!A7 -> 复核日期： | I4: 页 次：1
A5: 调整事项说明 | B5: 类别（报表调整/账项调整/其他） | C5: 报表项目 | D5: 科目名称 | E5: 附注项目 | F5: …… | G5: 借方调整金额 | H5: 贷方调整金额 | I5: 索引 | J5: 备注
