Workbook

Sheet 底稿目录
A1: 底稿开列时，可先在以下单元格填写有关内容，以便其他底稿引用有关数据：
A2: 被审计单位：
A3: 截止日：202X年12月31日 | D3: 序号 | E3: 内容 | F3: 索引号
A4: 编制人： | E4: 应收利息实质性程序表 | F4: G2A
A5: 编制日期： | D5: 1 | E5: 审定表 | F5: G2-1 | G5: 无需打印
A6: 复核人： | D6: 2 | E6: 附注披露信息（上市公司） | G6: 无需打印
A7: 复核日期： | D7: 3 | E7: 附注披露信息（国企）
D8: 4 | E8: 明细表 | F8: G2-2
A9: 关于工作底稿与审计程序索引号对应的说明 | D9: 5 | E9: 坏账准备明细表 | F9: G2-3
A10: 1.编制的审计工作底稿应与审计程序对应。审计项目组应根据被审计单位实际情况和风险评估情况在实质性程序表中裁剪、修改或增加审计程序，根据实际执行的审计程序完成相应审计工作底稿，编制的工作底稿中应按自然顺序依次编制索引号，并通过唯一的索引号将与实质性程序表中的程序对应关联（即将工作底稿的索引号填入实质性程序表中的底稿索引号列）。 | D10: 6 | E10: 调整分录汇总 | F10: G2-4
D11: 7 | E11: 利息测算表 | F11: G2-5
D12: 8 | E12: 长期未收回款项检查表 | F12: G2-6
D13: 9 | E13: 应收利息坏账准备测算表 | F13: G2-7
A14: 2.获取的支持性证据应与审计底稿或程序对应。审计项目组在完成底稿时获取的支持性证据应根据底稿索引号编制下一级按自然顺序排序的索引号（如D1-2-1、D1-2-2、……），并在底稿中说明引用的支持性证据、关联索引号。 | D14: 10 | E14: 凭证检查表 | F14: G2-8
A17: 3.工作底稿索引号的编码规则：实质性程序索引号按循环从“D”到“N”,循环内账户以顺序号排列，模板中底稿索引号按账户顺序+自然数顺序（即模板中索引号按二级自然顺序排列，如D1-1、D1-2、D1-3、……D1-N）。

Sheet 应收利息实质性程序表G2A
A1: 致同会计师事务所
A2: 应收利息实质性程序表
A3: =底稿目录!A2 -> 被审计单位： | C3: =底稿目录!A4 -> 编制人： | F3: =底稿目录!A5 -> 编制日期： | H3: 索引号： | I3: =底稿目录!F4 -> G2A
A4: =底稿目录!A3 -> 截止日：202X年12月31日 | C4: =底稿目录!A6 -> 复核人： | F4: =底稿目录!A7 -> 复核日期： | H4: 页 次：
A5: 一、本账户涉及的科目
A6: 应收利息
A7: 二、审计目标与认定的对应关系
A8: 审计目标 | G8: 财务报表的认定
A9: A. 资产负债表中记录的应收利息是存在的，且已记录于恰当的账户 | G9: 存在
A10: B. 所有应记录的应收利息均已记录，所有应当包括在财务报表中的相关披露均已包括 | G10: 完整性
A11: C. 记录的应收利息由被审计单位拥有或控制 | G11: 权利和义务
A12: D. 应收利息以恰当的金额包括在财务报表中，与之相关的计价或分摊调整已恰当记录，相关披露已得到恰当计量和描述 | G12: 准确性、计价和分摊
A13: E. 应收利息已被恰当地汇总或分解且表述清楚，相关披露在按照企业会计准则的编制基础下是相关的、可理解的 | G13: 列报
A14: 三、计划实施的实质性程序
A15: 序号 | B15: 审计程序 | C15: 程序分类 | D15: 财务报表的认定 | I15: 底稿索引号
D16: 存在 | E16: 完整性 | F16: 权利和 义务 | G16: 准确性、计价和分摊 | H16: 列报
A17: 1 | B17: 获取或编制应收利息的明细表，完成以下工作，并编制审定表 （1）复核加计是否正确，与总账、明细账合计数核对是否相符；获取余额调节表与总账核对一致； （2）将期初余额与上期期末余额核对； （3）追查明细表至调节表; （4）与上年明细项目进行比较，确定与上年分类相同； （5）与利息净收入或财务费用等项目的变动进行核对，复核其勾稽关系。 （6）调查重大或者异常的调节项目，并与客户的适当人员讨论差异，考虑回复的可信度并确认相关解释，以及采取适当的措施； （7）检查非记账本位币计量的应收利息的折算汇率及折算是否正确。 | C17: 常规★ | D17: √ | E17: √ | G17: √ | I17: G2-1 /G2-2 /G2-3 /G2-8
A18: 2 | B18: 在使用手工编制、自定义信息报告、系统生成的非固定格式报告等由被审计单位生成的信息时，测试有关信息准确性和完整性，并考虑针对编制和维护由被审计单位生成的信息的相关控制实施控制测试，以评价该信息是否能够为实现审计目的提供基础。 | C18: 常规★ | E18: √ | G18: √ | I18: T1 /G0-2 /
A19: 3 | B19: 若系首次承接，获取前期期末明细表，与总账核对一致，确定计算的准确性；将重大投资与其支持性文件核对一致；确定会计政策及程序是否适当；检查期初金额在本期收回情况；确定是否需要补充必要的程序，如果是，执行适当的应对程序。（适用于首次承接） | C19: 备选 | D19: √ | E19: √ | F19: √ | G19: √
A20: 4 | B20: 根据实际情况，实施以下分析程序： （1）获取增、减分析表，确定增加内容及减少方式、对损益的影响； （2）复核年度各项应收利息的总体合理性；对变化较大的项目或没有变动的项目进行复核，与被审计单位适当人员讨论原因，判断其存在的合理性，是否存在减值。 | C20: 常规★ | D20: √ | G20: √ | I20: G2-1 /G2-2 /G2-3
A21: 5 | B21: 关注会计政策、会计估计合理性、一贯性。关注其是否利用会计政策和会计估计及其变更操纵利润。 | C21: 常规★ | D21: √ | E21: √ | G21: √ | I21: G2-1 /G2-2
A22: 6 | B22: 对利息收益执行如下程序： （1）确定利息收入计算是否正确，会计处理是否正确； （2）检查应收利息计提依据是否充分，是否与相应的债权投资对应； （3）检查应收利息期后收款情况。 | C22: 常规★ | D22: √ | E22: √ | G22: √ | I22: G2-5 /G2-8
A23: 7 | B23: 针对坏账准备，执行下列核对程序： （1）对于坏账准备的账面金额、本期审计调整金额、审定金额分别与坏账准备账面、本期审计调整、审定金额勾稽一致； （2）确定应收利息是否已计提充足的坏账准备； （3）取得上述经账龄复核后的账龄明细表，并取得被审计单位的坏账准备计算表，复核加计正确，与总账数、明细账合计数核对相符； （4）重新计算应计提的坏账准备，与客户已记录的坏账准备进行比较，调整差异。特别关注大额坏账准备转回是否合理； （5）根据账龄分析表中，选取金额大于的账户，逾期超过（）天账户，以及其他认为必要的账户。针对所选取的账户，与授信部门经理或其他负责人员讨论其可收回性，并复核往来函件或其他相关信息，以支持被审计单位就此作出的声明； （6）实际发生坏账损失的，检查核销依据是否符合有关规定，会计处理是否正确。已经确认并转销的坏账重新收回的，检查其会计处理是否正确。 | C23: 常规★ | E23: √ | G23: √ | I23: G2-3 /G2-7
A24: 8 | B24: 必要时，向相关机构发函，并确定是否存在变现限制，同时记录函证过程： （1）以积极方式进行函证，设计询证函、发函前核实被函证单位信息； （2）注册会计师独立收发询证函； （3）编制函证结果汇总表，检查发函、回函物流信息和轨迹、比对回函印章和签字等以核实回函的真实性，检查回函是否相符，对不符事项查明原因确定是否存在错报； （4）如果未收到回函，应当考虑与被询证者联系，要求对方作出回应或再次寄发询证函，无法收到的回函实施替代程序； （5）如果管理层不允许寄发询证函的，询问管理层不允许寄发的原因，并就其原因的正当、合理性收集证据；考虑实施替代审计程序以获取相关、可靠的审计证据； （6）如果管理层不允许寄发询证函的原因不合理、或者认为回函不可靠，评价对评估的重大错报风险以及其他审计程序的性质、时间安排和范围的影响，并确定其对审计工作和审计意见的影响。 | C24: 备选 | D24: √ | E24: √ | F24: √ | G24: √ | I24: G0
A25: 9 | B25: 针对报告期内账龄较长的应收利息，判断是否有长期挂账而推迟正常经营管理所需开支或无需支付（如不合理的往来款挂账）的情况，并检查其原始凭证，确认会计处理是否正确，必要时进行函证。针对报告期内账龄较长的应收利息，实施上条程序后未发现不合理的情况，应当进而分析账龄较长的原因，是否双方有纠纷或对方单位缺乏付款能力等，考虑坏账准备的计提是否充分。 | C25: 常规★ | D25: √ | G25: √ | I25: G2-6
A26: 10 | B26: 检查关联方款项： （1）了解关联交易的商业理由、交易事项的目的、价格和条件，考虑对关联方应付票据的合理性、合法性； （2）检查对关联方应付票据的真实性相关的支持性文件、检查会计处理是否正确； （3）考虑向关联方或其他注册会计师函证重大的关联采购交易和余额（包括担保和其他重要信息）； （4）必要时，向与交易相关的人员和机构（如银行、律师）函证或与其讨论有关信息； （5）考虑是否存在未识别的关联方，关联交易和余额披露是否正确。 | C26: 常规★ | D26: √ | E26: √ | F26: √ | G26: √ | H26: √ | I26: G2-8
A27: 11 | B27: 根据评估的舞弊风险等因素增加的审计程序。 | C27: 舞弊应对/IPO/上市/新三板/重组
A28: 12 | B28: 检查应收利息是否已按企业会计准则或其他适用的规定在财务报表中做出恰当列报和披露。 | C28: 常规★ | H28: √ | I28: A1-1/A1-15 /A1-16

Sheet 审定表G2-1
A1: 致同会计师事务所
A2: 应收利息审定表
A3: =底稿目录!A2 -> 被审计单位： | D3: =底稿目录!A4 -> 编制人： | G3: =底稿目录!A5 -> 编制日期： | I3: 索引号： | J3: =底稿目录!F5 -> G2-1
A4: =底稿目录!A3 -> 截止日：202X年12月31日 | D4: =底稿目录!A6 -> 复核人： | G4: =底稿目录!A7 -> 复核日期： | I4: 页 次：1
A5: 项目 | B5: 期初数 | E5: 期末数 | H5: 本期与上期审定数比较 | J5: 原因分析
B6: 未审数 | C6: 账项调整 | D6: 审定数 | E6: 未审数 | F6: 账项调整 | G6: 审定数 | H6: 变动额 | I6: 变动率
A7: 一、应收利息原值
A8: 单项计提坏账准备 | D8: =B8+C8 -> 0 | E8: ='应收利息坏账准备测算G2-7'!I16 -> 0 | F8: ='应收利息坏账准备测算G2-7'!F16 -> 0 | G8: =E8+F8 -> 0 | H8: =G8-D8 -> 0 | I8: =IF(AND(D8=0,G8=0),"",IF(AND(D8=0,G8>0),1,H8/D8))
A9: 按组合计提坏账准备 | B9: =SUM(B10:B12) -> 0 | C9: =SUM(C10:C12) -> 0 | D9: =SUM(D10:D12) -> 0 | E9: =SUM(E10:E12) -> 0 | F9: =SUM(F10:F12) -> 0 | G9: =SUM(G10:G12) -> 0 | H9: =G9-D9 -> 0 | I9: =IF(AND(D9=0,G9=0),"",IF(AND(D9=0,G9>0),1,H9/D9))
D10: =B10+C10 -> 0 | G10: =E10+F10 -> 0 | H10: =G10-D10 -> 0 | I10: =IF(AND(D10=0,G10=0),"",IF(AND(D10=0,G10>0),1,H10/D10))
D11: =B11+C11 -> 0 | G11: =E11+F11 -> 0 | H11: =G11-D11 -> 0 | I11: =IF(AND(D11=0,G11=0),"",IF(AND(D11=0,G11>0),1,H11/D11))
D12: =B12+C12 -> 0 | G12: =E12+F12 -> 0 | H12: =G12-D12 -> 0 | I12: =IF(AND(D12=0,G12=0),"",IF(AND(D12=0,G12>0),1,H12/D12))
A13: 小计 | B13: =SUM(B8,B9) -> 0 | C13: =SUM(C8,C9) -> 0 | D13: =SUM(D8,D9) -> 0 | E13: =SUM(E8,E9) -> 0 | F13: =SUM(F8,F9) -> 0 | G13: =SUM(G8,G9) -> 0 | H13: =G13-D13 -> 0 | I13: =IF(AND(D13=0,G13=0),"",IF(AND(D13=0,G13>0),1,H13/D13))
A14: 二、应收利息坏账准备
A15: =A8 -> 单项计提坏账准备 | D15: =B15+C15 -> 0 | G15: =E15+F15 -> 0 | H15: =G15-D15 -> 0 | I15: =IF(AND(D15=0,G15=0),"",IF(AND(D15=0,G15>0),1,H15/D15))
A16: =A9 -> 按组合计提坏账准备 | B16: =SUM(B17:B19) -> 0 | C16: =SUM(C17:C19) -> 0 | D16: =SUM(D17:D19) -> 0 | E16: =SUM(E17:E19) -> 0 | F16: =SUM(F17:F19) -> 0 | G16: =SUM(G17:G19) -> 0 | H16: =G16-D16 -> 0 | I16: =IF(AND(D16=0,G16=0),"",IF(AND(D16=0,G16>0),1,H16/D16))
A17: =A10 -> 0 | D17: =B17+C17 -> 0 | G17: =E17+F17 -> 0 | H17: =G17-D17 -> 0 | I17: =IF(AND(D17=0,G17=0),"",IF(AND(D17=0,G17>0),1,H17/D17))
A18: =A11 -> 0 | D18: =B18+C18 -> 0 | G18: =E18+F18 -> 0 | H18: =G18-D18 -> 0 | I18: =IF(AND(D18=0,G18=0),"",IF(AND(D18=0,G18>0),1,H18/D18))
A19: =A12 -> 0 | D19: =B19+C19 -> 0 | G19: =E19+F19 -> 0 | H19: =G19-D19 -> 0 | I19: =IF(AND(D19=0,G19=0),"",IF(AND(D19=0,G19>0),1,H19/D19))
A20: 小计 | B20: =SUM(B15,B16) -> 0 | C20: =SUM(C15,C16) -> 0 | D20: =SUM(D15,D16) -> 0 | E20: =SUM(E15,E16) -> 0 | F20: =SUM(F15,F16) -> 0 | G20: =SUM(G15,G16) -> 0 | H20: =G20-D20 -> 0 | I20: =IF(AND(D20=0,G20=0),"",IF(AND(D20=0,G20>0),1,H20/D20))
A21: 三、应收利息净值
A22: =A8 -> 单项计提坏账准备 | B22: =B8-B15 -> 0 | C22: =C8-C15 -> 0 | D22: =D8-D15 -> 0 | E22: =E8-E15 -> 0 | F22: =F8-F15 -> 0 | G22: =G8-G15 -> 0 | H22: =G22-D22 -> 0 | I22: =IF(AND(D22=0,G22=0),"",IF(AND(D22=0,G22>0),1,H22/D22))
A23: =A9 -> 按组合计提坏账准备 | B23: =SUM(B24:B26) -> 0 | C23: =SUM(C24:C26) -> 0 | D23: =SUM(D24:D26) -> 0 | E23: =SUM(E24:E26) -> 0 | F23: =SUM(F24:F26) -> 0 | G23: =SUM(G24:G26) -> 0 | H23: =G23-D23 -> 0 | I23: =IF(AND(D23=0,G23=0),"",IF(AND(D23=0,G23>0),1,H23/D23))
A24: =A10 -> 0 | B24: =B10-B17 -> 0 | C24: =C10-C17 -> 0 | D24: =D10-D17 -> 0 | E24: =E10-E17 -> 0 | F24: =F10-F17 -> 0 | G24: =G10-G17 -> 0 | H24: =G24-D24 -> 0 | I24: =IF(AND(D24=0,G24=0),"",IF(AND(D24=0,G24>0),1,H24/D24))
A25: =A11 -> 0 | B25: =B11-B18 -> 0 | C25: =C11-C18 -> 0 | D25: =D11-D18 -> 0 | E25: =E11-E18 -> 0 | F25: =F11-F18 -> 0 | G25: =G11-G18 -> 0 | H25: =G25-D25 -> 0 | I25: =IF(AND(D25=0,G25=0),"",IF(AND(D25=0,G25>0),1,H25/D25))
A26: =A12 -> 0 | B26: =B12-B19 -> 0 | C26: =C12-C19 -> 0 | D26: =D12-D19 -> 0 | E26: =E12-E19 -> 0 | F26: =F12-F19 -> 0 | G26: =G12-G19 -> 0 | H26: =G26-D26 -> 0 | I26: =IF(AND(D26=0,G26=0),"",IF(AND(D26=0,G26>0),1,H26/D26))
A27: 合计 | B27: =SUM(B22,B23) -> 0 | C27: =SUM(C22,C23) -> 0 | D27: =SUM(D22,D23) -> 0 | E27: =SUM(E22,E23) -> 0 | F27: =SUM(F22,F23) -> 0 | G27: =SUM(G22,G23) -> 0 | H27: =G27-D27 -> 0 | I27: =IF(AND(D27=0,G27=0),"",IF(AND(D27=0,G27>0),1,H27/D27))
A28: 1、审计说明
A29: （1）应收利息本期较上期增加（负数为减少）： | D29: =IF(AND(D27=0,G27=0),0,IF(AND(D27=0,G27>0),1,(G27-D27)/D27)) -> 0
A30: 主要原因（比例超过30%的）：
A32: （2）金额较大的1年以上应收未收的应收利息金额，分别欠款单位说明未收回的原因和对预期信用损失所作的判断。
A36: 2、审计结论
A40: 编制说明：
A41: “应收利息”仅反映相关金融工具已到期可收取但于资产负债表日尚未收到的利息【即逾期部分】。基于实际利率法计提的金融工具的利息应包含在相应金融工具的账面余额中。

Sheet 附注披露信息（上市公司）
A1: 致同会计师事务所
A2: 附注披露信息（上市公司）
A3: =底稿目录!A2 -> 被审计单位： | B3: =底稿目录!A4 -> 编制人： | C3: =底稿目录!A5 -> 编制日期： | D3: 索引号： | E3: =底稿目录!F6 -> 0
A4: =底稿目录!A3 -> 截止日：202X年12月31日 | B4: =底稿目录!A6 -> 复核人： | C4: =底稿目录!A7 -> 复核日期： | D4: 页 次：
A5: 附注披露信息
A6: 【其他应收款、应收股利与应收利息的合计数披露详见M1-1】
A7: ① 应收利息分类
A8: 项 目 | B8: 期末余额 | C8: 上年年末余额
A9: 定期存款 | B9: =SUMIF('明细表G2-2'!$A$10:$A$15,'附注披露信息（上市公司）'!A9,'明细表G2-2'!$J$10:$J$15) -> 0 | C9: =SUMIF('明细表G2-2'!$A$10:$A$15,'附注披露信息（上市公司）'!A9,'明细表G2-2'!$E$10:$E$15) -> 0
A10: 委托贷款 | B10: =SUMIF('明细表G2-2'!$A$10:$A$15,'附注披露信息（上市公司）'!A10,'明细表G2-2'!$J$10:$J$15) -> 0 | C10: =SUMIF('明细表G2-2'!$A$10:$A$15,'附注披露信息（上市公司）'!A10,'明细表G2-2'!$E$10:$E$15) -> 0
A11: 债券投资 | B11: =SUMIF('明细表G2-2'!$A$10:$A$15,'附注披露信息（上市公司）'!A11,'明细表G2-2'!$J$10:$J$15) -> 0 | C11: =SUMIF('明细表G2-2'!$A$10:$A$15,'附注披露信息（上市公司）'!A11,'明细表G2-2'!$E$10:$E$15) -> 0
A12: 其他 | B12: =SUMIF('明细表G2-2'!$A$10:$A$15,'附注披露信息（上市公司）'!A12,'明细表G2-2'!$J$10:$J$15) -> 0 | C12: =SUMIF('明细表G2-2'!$A$10:$A$15,'附注披露信息（上市公司）'!A12,'明细表G2-2'!$E$10:$E$15) -> 0
A13: 小 计 | B13: =SUM(B9:B12) -> 0 | C13: =SUM(C9:C12) -> 0
A14: 减：坏账准备 | B14: ='审定表G2-1'!G20 -> 0 | C14: ='审定表G2-1'!D20 -> 0
A15: 合 计 | B15: =B13-B14 -> 0 | C15: =C13-C14 -> 0
A16: 【提示：仅反映相关金融工具已到期可收取但于资产负债表日尚未收到的利息。基于实际利率法计提的金融工具的利息应包含在金融工具的账面余额中。】
A17: ② 重要逾期利息
A18: 借款单位 | B18: 期末余额 | C18: 逾期时间（月） | D18: 逾期原因 | E18: 是否发生减值及其判断依据
A22: 合 计 | B22: =SUM(B19:B21) -> 0
A23: （对于重要的逾期应收利息，应按借款单位披露应收利息的期末余额、逾期时间和逾期原因、是否发生减值的判断。）
A24: 其他说明：
A25: ③ 坏账准备计提情况
A26: 说明：期末处于第一阶段、第二阶段和第三阶段的应收利息的坏账准备计提情况，披露格式可参考其他应收款的披露格式。
A27: 说明：坏账准备本期计提、转回、转销、核销情况，披露格式可参考其他应收款的披露格式。
A28: 说明：本期发生损失准备的应收利息账面余额显著变动的情况。
A29: 【也可以在其他应收款项下合并披露应收利息的坏账准备计提情况，并索引至其他应收款的注释。】

Sheet 附注披露信息（国企）
A1: 致同会计师事务所
A2: 附注披露信息（国企）
A3: =底稿目录!A2 -> 被审计单位： | B3: =底稿目录!A4 -> 编制人： | C3: =底稿目录!A5 -> 编制日期： | D3: 索引号： | E3: =底稿目录!F7 -> 0
A4: =底稿目录!A3 -> 截止日：202X年12月31日 | B4: =底稿目录!A6 -> 复核人： | C4: =底稿目录!A7 -> 复核日期： | D4: 页 次：
A5: 附注披露信息
A6: 【其他应收款、应收股利与应收利息的合计数披露详见M1-1】
A7: ① 应收利息分类
A8: 项 目 | B8: 期末余额 | C8: 期初余额
A9: 定期存款 | B9: =SUMIF('明细表G2-2'!$A$10:$A$15,A9,'明细表G2-2'!$J$10:$J$15) -> 0 | C9: =SUMIF('明细表G2-2'!$A$10:$A$15,A9,'明细表G2-2'!$E$10:$E$15) -> 0
A10: 委托贷款 | B10: =SUMIF('明细表G2-2'!$A$10:$A$15,A10,'明细表G2-2'!$J$10:$J$15) -> 0 | C10: =SUMIF('明细表G2-2'!$A$10:$A$15,A10,'明细表G2-2'!$E$10:$E$15) -> 0
A11: 债券投资 | B11: =SUMIF('明细表G2-2'!$A$10:$A$15,A11,'明细表G2-2'!$J$10:$J$15) -> 0 | C11: =SUMIF('明细表G2-2'!$A$10:$A$15,A11,'明细表G2-2'!$E$10:$E$15) -> 0
A12: 其他 | B12: =SUMIF('明细表G2-2'!$A$10:$A$15,A12,'明细表G2-2'!$J$10:$J$15) -> 0 | C12: =SUMIF('明细表G2-2'!$A$10:$A$15,A12,'明细表G2-2'!$E$10:$E$15) -> 0
A13: 小 计 | B13: =SUM(B9:B12) -> 0 | C13: =SUM(C9:C12) -> 0
A14: 减：坏账准备 | B14: ='审定表G2-1'!G20 -> 0 | C14: ='审定表G2-1'!D20 -> 0
A15: 合 计 | B15: =B13-B14 -> 0 | C15: =C13-C14 -> 0
A16: ② 重要逾期利息
A17: 借款单位 | B17: 期末余额 | C17: 逾期时间（月） | D17: 逾期原因 | E17: 是否发生减值及其判断依据
A21: 合 计 | B21: =SUM(B18:B20) -> 0
A22: ③ 坏账准备计提情况
A23: 坏账准备 | B23: 第一阶段 | C23: 第二阶段 | D23: 第三阶段 | E23: 合计
B24: 未来12个月预期信用损失 | C24: 整个存续期预期信用损失（未发生信用减值） | D24: 整个存续期预期信用损失（已发生信用减值）
A25: 期初余额 | E25: =SUM(B25:D25) -> 0
A26: 期初余额在本期 | E26: =SUM(B26:D26) -> 0
A27: —转入第二阶段 | E27: =SUM(B27:D27) -> 0
A28: —转入第三阶段 | E28: =SUM(B28:D28) -> 0
A29: —转回第二阶段 | E29: =SUM(B29:D29) -> 0
A30: —转回第一阶段 | E30: =SUM(B30:D30) -> 0
A31: 本期计提 | E31: =SUM(B31:D31) -> 0
A32: 本期转回 | E32: =SUM(B32:D32) -> 0
A33: 本期转销 | E33: =SUM(B33:D33) -> 0
A34: 本期核销 | E34: =SUM(B34:D34) -> 0
A35: 其他变动 | E35: =SUM(B35:D35) -> 0
A36: 期末余额 | B36: =SUM(B26:B30)+B31-B32-B33-B34+B35 -> 0 | C36: =SUM(C26:C30)+C31-C32-C33-C34+C35 -> 0 | D36: =SUM(D26:D30)+D31-D32-D33-D34+D35 -> 0 | E36: =SUM(E26:E30)+E31-E32-E33-E34+E35 -> 0

Sheet 明细表G2-2
A1: 致同会计师事务所
A2: 应收利息明细表
A3: =底稿目录!A2 -> 被审计单位： | E3: =底稿目录!A4 -> 编制人： | I3: =底稿目录!A5 -> 编制日期： | L3: 索引号： | M3: =底稿目录!F8 -> G2-2
A4: =底稿目录!A3 -> 截止日：202X年12月31日 | E4: =底稿目录!A6 -> 复核人： | I4: =底稿目录!A7 -> 复核日期： | L4: 页 次： 1
A5: 一、审计目标
A6: 1.资产负债表中记录的应收利息是存在的，且已经记录在恰当的账户中；2.所有应记录的应收利息均已记录，所有应当包括在财务报表中的相关披露均已包括
A7: 3.应收利息以恰当的金额包括在财务报表中，与之相关的计价或分摊调整已恰当记录，相关披露已得到恰当计量和描述
A8: 二、审计过程：
A9: 投资种类 | B9: 投资项目 | C9: 期初余额 | D9: 期初调整数 | E9: 期初余额审定数 | F9: 借方发生 | G9: 贷方发生 | H9: 期末余额 | I9: 账项调整 | J9: 应收利息余额审定数 | K9: 应收取的日期（结息日） | L9: 预计收取日期 | M9: 发函或期后收款情况
E10: =C10+D10 -> 0 | H10: =C10+F10-G10 -> 0 | J10: =H10+I10 -> 0
E11: =C11+D11 -> 0 | H11: =C11+F11-G11 -> 0 | J11: =H11+I11 -> 0
E12: =C12+D12 -> 0 | H12: =C12+F12-G12 -> 0 | J12: =H12+I12 -> 0
E13: =C13+D13 -> 0 | H13: =C13+F13-G13 -> 0 | J13: =H13+I13 -> 0
E14: =C14+D14 -> 0 | H14: =C14+F14-G14 -> 0 | J14: =H14+I14 -> 0
E15: =C15+D15 -> 0 | H15: =C15+F15-G15 -> 0 | J15: =H15+I15 -> 0
A16: 合计 | C16: =SUM(C10:C15) -> 0 | D16: =SUM(D10:D15) -> 0 | E16: =SUM(E10:E15) -> 0 | F16: =SUM(F10:F15) -> 0 | G16: =SUM(G10:G15) -> 0 | H16: =SUM(H10:H15) -> 0 | I16: =SUM(I10:I15) -> 0 | J16: =SUM(J10:J15) -> 0 | K16: =SUM(K10:K15) -> 0
A17: 注：“应收利息”仅反映相关金融工具已到期可收取但于资产负债表日尚未收到的利息。基于实际利率法计提的金融工具的利息应包含在相应金融工具的账面余额中。
A18: 三、审计说明：
A21: 四、审计结论：
A24: 编制说明：
A25: 1.审计说明可以概述:(1)程序的测试情况、结果;(2)拟调整事项及其调整分录、未调整事项及其影响，审计范围受到限制情况及其影响。
A26: 2.审计结论可参考:A、未见异常。 B、除上述重大不符事项应当作为调整事项予以调整外，其余未见异常。由于存在以下重大未调整事项(或审计范围受到限制无法获取充分、适当证据)，不可确认。

Sheet 坏账准备明细表G2-3
A1: 致同会计师事务所
A2: 应收利息坏账准备明细表
A3: =底稿目录!A2 -> 被审计单位： | E3: =底稿目录!A4 -> 编制人： | I3: =底稿目录!A5 -> 编制日期： | L3: 索引号： | M3: =底稿目录!F9 -> G2-3
A4: =底稿目录!A3 -> 截止日：202X年12月31日 | E4: =底稿目录!A6 -> 复核人： | I4: =底稿目录!A7 -> 复核日期： | L4: 页 次： 1
A5: 一、审计目标:
A6: 1.资产负债表中记录的应收利息是存在的；2.所有应当记录的应收利息均已记录；
A7: 3. 应收利息以恰当的金额包括在财务报表中，与之相关的计价调整已恰当记录
A8: 二、审计过程：
A9: 项目 | B9: 期初数 | E9: 本期增加 | G9: 本期减少 | J9: 期末数 | M9: 单独计提减值、转回或转销原因
B10: 期初未审数 | C10: 期初账项调整 | D10: 期初审定数 | E10: 计提 | F10: 其他增加 | G10: 转回 | H10: 转销 | I10: 其他减少 | J10: 期末未审数 | K10: 期末账项调整 | L10: 期末审定数额
A11: 按单项评估计提 | B11: =SUM(B12:B15) -> 0 | C11: =SUM(C12:C15) -> 0 | D11: =SUM(D12:D15) -> 0 | E11: =SUM(E12:E15) -> 0 | F11: =SUM(F12:F15) -> 0 | G11: =SUM(G12:G15) -> 0 | H11: =SUM(H12:H15) -> 0 | I11: =SUM(I12:I15) -> 0 | J11: =B11+SUM(E11:F11)-SUM(G11:I11) -> 0 | K11: =SUM(K12:K15) -> 0 | L11: =J11+K11 -> 0
A12: 其中： | D12: =B12+C12 -> 0 | J12: =B12+SUM(E12:F12)-SUM(G12:I12) -> 0 | L12: =J12+K12 -> 0
D13: =B13+C13 -> 0 | J13: =B13+SUM(E13:F13)-SUM(G13:I13) -> 0 | L13: =J13+K13 -> 0
D14: =B14+C14 -> 0 | J14: =B14+SUM(E14:F14)-SUM(G14:I14) -> 0 | L14: =J14+K14 -> 0
D15: =B15+C15 -> 0 | J15: =B15+SUM(E15:F15)-SUM(G15:I15) -> 0 | L15: =J15+K15 -> 0
A16: 信用风险组合计提 | B16: =SUM(B17:B20) -> 0 | C16: =SUM(C17:C20) -> 0 | E16: =SUM(E17:E20) -> 0 | F16: =SUM(F17:F20) -> 0 | G16: =SUM(G17:G20) -> 0 | H16: =SUM(H17:H20) -> 0 | I16: =SUM(I17:I20) -> 0 | J16: =B16+SUM(E16:F16)-SUM(G16:I16) -> 0 | K16: =SUM(K17:K20) -> 0 | L16: =J16+K16 -> 0
A17: 其中： | D17: =B17+C17 -> 0 | J17: =B17+SUM(E17:F17)-SUM(G17:I17) -> 0 | L17: =J17+K17 -> 0
D18: =B18+C18 -> 0 | J18: =B18+SUM(E18:F18)-SUM(G18:I18) -> 0 | L18: =J18+K18 -> 0
D19: =B19+C19 -> 0 | J19: =B19+SUM(E19:F19)-SUM(G19:I19) -> 0 | L19: =J19+K19 -> 0
D20: =B20+C20 -> 0 | J20: =B20+SUM(E20:F20)-SUM(G20:I20) -> 0 | L20: =J20+K20 -> 0
L21: =J21+K21 -> 0
A22: 合计 | B22: =B11+B16 -> 0 | C22: =C11+C16 -> 0 | D22: =D11+D16 -> 0 | E22: =E11+E16 -> 0 | F22: =F11+F16 -> 0 | G22: =G11+G16 -> 0 | H22: =H11+H16 -> 0 | I22: =I11+I16 -> 0 | ... L22: =L11+L16 -> 0 | M22: =SUM(M11:M21) -> 0
A23: 三、审计说明：
A27: 四、审计结论：

Sheet 调整分录汇总G2-4
A1: 致同会计师事务所
A2: 应收利息调整分录汇总表
A3: =底稿目录!A2 -> 被审计单位： | D3: =底稿目录!A4 -> 编制人： | G3: =底稿目录!A5 -> 编制日期： | I3: 索引号： | J3: =底稿目录!F10 -> G2-4
A4: =底稿目录!A3 -> 截止日：202X年12月31日 | D4: =底稿目录!A6 -> 复核人： | G4: =底稿目录!A7 -> 复核日期： | I4: 页 次：1
A5: 调整事项说明 | B5: 类别（报表调整/账项调整/其他） | C5: 报表项目 | D5: 科目名称 | E5: 附注项目 | F5: …… | G5: 借方调整金额 | H5: 贷方调整金额 | I5: 索引 | J5: 备注
A22: 【注：本底稿适用于调整分录较多、较复杂的项目，且仅列示与本报表项目相关的审计调整。项目组可根据项目实际情况选择是否使用该底稿。】

Sheet 利息测算表G2-5
A1: 致同会计师事务所
A2: 应收利息测算表
A3: =底稿目录!A2 -> 被审计单位： | E3: =底稿目录!A4 -> 编制人： | H3: =底稿目录!A5 -> 编制日期： | J3: 索引号： | K3: =底稿目录!F11 -> G2-5
A4: =底稿目录!A3 -> 截止日：202X年12月31日 | E4: =底稿目录!A6 -> 复核人： | H4: =底稿目录!A7 -> 复核日期： | J4: 页 次：
A5: 一、审计目标： | B5: 确认应收利息计算是否正确。
A6: 二、审计过程：
A7: 投资项目 | B7: 票面金额 | C7: 票面年利率 | D7: 计息开始日期 | E7: 计息结束日期 | F7: 计息天数 | G7: 应计利息 | H7: 其中：已到期可收取 ⑤ | I7: 已计利息 | J7: 差异 | K7: 差异原因
B8: ① | C8: ② | F8: ③ | G8: ④=①*②*③/365 | I8: ⑥ | J8: ⑦=⑥-⑤
F9: =E9-D9 -> 0 | G9: =ROUND(B9*C9/360*F9,2) -> 0 | J9: =I9-H9 -> 0
F10: =E10-D10 -> 0 | G10: =ROUND(B10*C10/360*F10,2) -> 0 | J10: =I10-H10 -> 0
F11: =E11-D11 -> 0 | G11: =ROUND(B11*C11/360*F11,2) -> 0 | J11: =I11-H11 -> 0
F12: =E12-D12 -> 0 | G12: =ROUND(B12*C12/360*F12,2) -> 0 | J12: =I12-H12 -> 0
A13: 小计 | B13: =SUM(B9:B12) -> 0 | G13: =SUM(G9:G12) -> 0 | H13: =SUM(H9:H12) -> 0 | I13: =SUM(I9:I12) -> 0 | J13: =SUM(J9:J12) -> 0
A14: 注：“应收利息”仅反映相关金融工具已到期可收取但于资产负债表日尚未收到的利息。基于实际利率法计提的金融工具的利息应包含在相应金融工具的账面余额中。
A15: 三、审计说明：
A18: 四、审计结论：

Sheet 长期未收回款项检查表G2-6
A1: 致同会计师事务所
A2: 应收利息长期未收回款项检查表
A3: =底稿目录!A2 -> 被审计单位： | D3: =底稿目录!A4 -> 编制人： | H3: =底稿目录!A5 -> 编制日期： | L3: 索引号： | M3: =底稿目录!F12 -> G2-6
A4: =底稿目录!A3 -> 截止日：202X年12月31日 | D4: =底稿目录!A6 -> 复核人： | H4: =底稿目录!A7 -> 复核日期： | L4: 页 次：
A5: 一、审计目标:
A6: 1.资产负债表中记录的应收利息、坏账准备是存在的，且已记录于恰当的账户；
A7: 2.应收利息、坏账准备以恰当的金额包括在财务报表中，与之相关的计价或分摊调整已恰当记录，相关披露已得到恰当计量和描述
A8: 二、审计过程：
A9: 债务人名称 | B9: 期初余额 | C9: 本期借方发生额 | D9: 本期贷方发生额 | E9: 期末余额 | F9: 账龄 | G9: 经济业务说明 | H9: 未收回或未结转的原因 | I9: 是否无法收回 | J9: 处理计划 | K9: 审定余额 | L9: 期后收款金额 | M9: 备注
E10: =B10+C10-D10 -> 0
A13: 合计 | B13: =SUM(B10:B12) -> 0 | C13: =SUM(C10:C12) -> 0 | D13: =SUM(D10:D12) -> 0 | E13: =SUM(E10:E12) -> 0 | F13: =SUM(F10:F12) -> 0 | K13: =SUM(K10:K12) -> 0 | L13: =SUM(L10:L12) -> 0
A14: 三、审计说明：
A16: 四、审计结论：
A19: 编制说明：
A20: 1、概述：（1）程序的测试情况、结果；
A21: （2）拟调整事项及其调整分录、未调整事项及其影响，审计范围受到限制情况及其影响。
A22: 参考结论：
A23: A、 | B23: 未见异常。
A24: B、 | B24: 除以下重大不符事项应当作为调整事项予以调整外，其余未见异常。
A25: C、 | B25: 由于存在以下重大未调整事项（或审计范围受到限制无法获取充分、适当证据），不可确认。

Sheet 应收利息坏账准备测算G2-7
A1: 致同会计师事务所
A2: 应收利息坏账准备测算表
A3: =底稿目录!A2 -> 被审计单位： | C3: =底稿目录!A4 -> 编制人： | E3: =底稿目录!A5 -> 编制日期： | G3: 索引号： | H3: =底稿目录!F13 -> G2-7
A4: =底稿目录!A3 -> 截止日：202X年12月31日 | C4: =底稿目录!A6 -> 复核人： | E4: =底稿目录!A7 -> 复核日期： | G4: 页 次：
A5: 一、审计目标 | B5: 确定应收利息坏账准备计提是否充分。
A6: 二、审计过程
A7: （一）单项计提坏账准备
A8: 投资项目 | B8: 审定账面余额 | C8: 预期信用损失率 | D8: 期末应计提坏账准备 | E8: 期末坏账准备账面余额 | F8: 差异 | G8: 坏账准备计提依据及文件 | H8: 索引号
B9: ① | C9: ② | D9: ③=①×② | E9: ④ | F9: ⑤=③-④
D10: =B10*C10 -> 0 | F10: =B10-E10 -> 0
D11: =B11*C11 -> 0 | F11: =B11-E11 -> 0
D12: =B12*C12 -> 0 | F12: =B12-E12 -> 0
D13: =B13*C13 -> 0 | F13: =B13-E13 -> 0
D14: =B14*C14 -> 0 | F14: =B14-E14 -> 0
D15: =B15*C15 -> 0 | F15: =B15-E15 -> 0
D16: =B16*C16 -> 0 | F16: =B16-E16 -> 0
D17: =B17*C17 -> 0 | F17: =B17-E17 -> 0
D18: =B18*C18 -> 0 | F18: =B18-E18 -> 0
D19: =B19*C19 -> 0 | F19: =B19-E19 -> 0
A20: 小计 | B20: =SUM(B10:B19) -> 0 | C20: =SUM(C10:C19) -> 0 | D20: =IF(B20=0,"",C20/B20) | E20: =SUM(E10:E19) -> 0 | F20: =SUM(F10:F19) -> 0 | G20: =SUM(G10:G19) -> 0
A21: 核对差异
A22: （二）单一账龄组合计提坏账准备 | C22: 是否适用：
A23: 账龄【账龄以记账凭证日期（确认收入日期）起计算，逾期则考虑信用期】 | B23: 未审数 | G23: 审计调整
B24: 账面余额 | C24: 校验 | D24: 预期信用损失率 | E24: 坏账准备 | F24: 账面价值 | G24: 账面余额调整
B25: ① | D25: ② | E25: ③=①×② | F25: ④=①-③ | G25: ⑤
A26: 1年以内/未逾期 | E26: =B26*D26 -> 0 | F26: =B26-E26 -> 0
A27: 1年-2年/逾期30天以内 | E27: =B27*D27 -> 0 | F27: =B27-E27 -> 0
A28: 2年-3年/逾期30-90天 | E28: =B28*D28 -> 0 | F28: =B28-E28 -> 0
A29: 3年-4年/逾期90天-1年 | E29: =B29*D29 -> 0 | F29: =B29-E29 -> 0
A30: 4年-5年/逾期1年-2年 | E30: =B30*D30 -> 0 | F30: =B30-E30 -> 0
A31: 5年以上/逾期2年以上 | E31: =B31*D31 -> 0 | F31: =B31-E31 -> 0
A32: 小计 | B32: =SUM(B26:B31) -> 0 | C32: =SUM(C26:C31) -> 0 | E32: =SUM(E26:E31) -> 0 | F32: =SUM(F26:F31) -> 0 | G32: =SUM(G26:G31) -> 0
A33: 核对差异 | B33: =B32-'坏账准备明细表G2-3'!J22 -> 0 | C33: =B32-C32 -> 0
A34: 总 计 | B34: =SUM(B20,B32) -> 0 | E34: =SUM(E20,E32) -> 0 | F34: =SUM(F20,F32) -> 0 | G34: =SUM(G20,G32) -> 0
A35: 核对差异 | B35: =IF(B32=0,0,B34-#REF!) -> 0
A37: （二）账龄组合计提坏账准备
A38: 账龄【账龄以记账凭证日期起计算，逾期则考虑信用期】 | B38: 审定账面余额 | C38: 预期信用损失率 | D38: 期末应计提坏账准备 | E38: 期末坏账准备账面余额 | F38: 差异 | G38: 坏账准备计提依据及文件 | H38: 索引号
B39: ① | C39: ② | D39: ③=①×② | E39: ④ | F39: ⑤=③-④
A40: 组合1：
A41: 1年以内/未逾期 | D41: =B41*C41 -> 0 | F41: =D41-E41 -> 0
...

Sheet 凭证检查表G2-8
A1: 致同会计师事务所
A2: 应收利息凭证检查表
A3: =底稿目录!A2 -> 被审计单位： | D3: =底稿目录!A4 -> 编制人： | G3: =底稿目录!A5 -> 编制日期： | O3: 索引号： | P3: =底稿目录!F14 -> G2-8
A4: =底稿目录!A3 -> 截止日：202X年12月31日 | D4: =底稿目录!A6 -> 复核人： | G4: =底稿目录!A7 -> 复核日期： | O4: 页 次：
A5: 一、审计目标：
A6: 1.资产负债表中记录的应收利息是存在的，且已经记录在恰当的账户中； | E6: 2、记录的应收利息由被审计单位拥有或控制；
A7: 3.应收利息以恰当的金额包括在财务报表中，与之相关的计价或分摊调整已恰当记录，相关披露已得到恰当计量和描述
A8: 二、样本选取方法与规模：
A9: 测试范围： | B9: 如借方发生额所有凭证共XX笔金额XX、贷方发生额所有凭证共XX笔金额XX | F9: 特定样本： | G9: XX金额以上（大额）、关联方/关联交易形成的款项、XX异常款项全部测试，共XX笔；
A10: 抽样总体： | B10: 测试总体扣除特定样本以外的样本，共XX笔、金额XX | F10: 确定的抽样样本量： | H10: 抽取XX笔（如果使用了样本计算器计算样本量，样本量计算过程见<XX>底稿）
A11: 抽样方法： | B11: 随机选样/系统选样/货币单元抽样/随意选样（非统计抽样适用） | F11: 抽样过程： | G11: 使用IDEA（XX抽样工具）选择XX数量占比XX%的样本进行测试，抽样工具中的样本选择过程和结果见XX底稿
A12: 三、测试：
A13: 测试内容说明：1.原始凭证是否齐全； 2.记账凭证与原始凭证是否相符；3.账务处理是否正确；4.是否记录于恰当的会计期间；5.……
A14: 1、本期发生额检查
A15: 记账凭证 | H15: 支持性文件 | I15: 核对内容 | N15: 索引号 | O15: 是否异常 | P15: 备注说明
A16: 日期 | B16: 凭证编号 | C16: 业务内容 | D16: 对方科目 | E16: 明细科目 | F16: 借方金额 | G16: 贷方金额 | I16: 1 | J16: 2 | K16: 3 | L16: 4 | M16: 5
A26: 合计 | F26: =SUM(F17:F25) -> 0 | G26: =SUM(G17:G25) -> 0
A27: 本期发生额 | F27: ='明细表G2-2'!F16 -> 0 | G27: ='明细表G2-2'!G16 -> 0
A28: 检查比例 | F28: =F26/F27 -> #DIV/0! | G28: =G26/G27 -> #DIV/0!
A29: 2.期后处置、新增检查表
A30: 记账凭证 | H30: 支持性文件 | I30: 核对内容 | N30: 索引号 | O30: 是否异常 | P30: 备注说明
A31: 日期 | B31: 凭证编号 | C31: 业务内容 | D31: 对方科目 | E31: 明细科目 | F31: 借方金额 | G31: 贷方金额 | I31: 1 | J31: 2 | K31: 3 | L31: 4 | M31: 5
A38: 合计 | F38: =SUM(F32:F37) -> 0 | G38: =SUM(G32:G37) -> 0
A39: 三、审计说明：
A42: 四、审计结论：
A46: 编制说明：
A47: 1、概述：（1）程序的测试情况、结果；
A48: （2）拟调整事项及其调整分录、未调整事项及其影响，审计范围受到限制情况及其影响。
A49: 参考结论：
A50: A、 | B50: 未见异常。
A51: B、 | B51: 除以下重大不符事项应当作为调整事项予以调整外，其余未见异常。
A52: C、 | B52: 由于存在以下重大未调整事项（或审计范围受到限制无法获取充分、适当证据），不可确认。
A54: 2、选取测试项目的方法：包括选取全部项目、选取特定项目和审计抽样。
A55: （1） | B55: 当存在下列情形之一时，注册会计师应当考虑选取全部项目进行测试：
B56: （一）总体由少量的大额项目构成；
B57: （二）存在特别风险且其他方法未提供充分、适当的审计证据；
B58: （三）由于信息系统自动执行的计算或其他程序具有重复性，对全部项目进行检查符合成本效益原则。
B60: 特别风险涉及的事项包括但不限于：
B61: （1）舞弊风险（如1141准则的示例）；（2）重大非常规交易（如企业购并、债务重组、非货币性资产交换、
B62: 重大或有事项、持续经营、违反法律法规等）；(3)重大关联交易；(4)重大判断事项（如重大会计估计、
...
