Workbook

Sheet 底稿目录
A1: 底稿开列时，可先在以下单元格填写有关内容，以便其他底稿引用有关数据：
A2: 被审计单位：
A3: 截止日：202X年12月31日 | D3: 序号 | E3: 内容 | F3: 索引号
A4: 编制人： | E4: 长期股权投资实质性程序表 | F4: G7A
A5: 编制日期： | D5: 1 | E5: 长期股权投资审定表 | F5: G7-1
A6: 复核人： | D6: 2 | E6: 附注披露信息（上市公司） | G6: 无需打印
A7: 复核日期： | D7: 3 | E7: 附注披露信息（国企） | G7: 无需打印
D8: 4 | E8: 明细表 | F8: G7-2
A9: 关于工作底稿与审计程序索引号对应的说明 | D9: 5 | E9: 调整分录汇总 | F9: G7-3
A10: 1.编制的审计工作底稿应与审计程序对应。审计项目组应根据被审计单位实际情况和风险评估情况在实质性程序表中裁剪、修改或增加审计程序，根据实际执行的审计程序完成相应审计工作底稿，编制的工作底稿中应按自然顺序依次编制索引号，并通过唯一的索引号将与实质性程序表中的程序对应关联（即将工作底稿的索引号填入实质性程序表中的底稿索引号列）。 | D10: 6 | E10: 被投资单位基本信息 | F10: G7-4
D11: 7 | E11: 被投资单位财务信息（合营、联营） | F11: G7-5
D12: 8 | E12: 被投资公司会计政策 | F12: G7-6
D13: 9 | E13: 长期股权投资初始判断 | F13: G7-7
A14: 2.获取的支持性证据应与审计底稿或程序对应。审计项目组在完成底稿时获取的支持性证据应根据底稿索引号编制下一级按自然顺序排序的索引号（如D1-2-1、D1-2-2、……），并在底稿中说明引用的支持性证据、关联索引号。 | D14: 10 | E14: 子公司初始计量测试（同控） | F14: G7-8
D15: 11 | E15: 子公司初始计量测试（非同控） | F15: G7-9
D16: 12 | E16: 子公司后续计量测试表 | F16: G7-10
A17: 3.工作底稿索引号的编码规则：实质性程序索引号按循环从“D”到“N”,循环内账户以顺序号排列，模板中底稿索引号按账户顺序+自然数顺序（即模板中索引号按二级自然顺序排列，如D1-1、D1-2、D1-3、……D1-N）。 | D17: 13 | E17: 处置子公司测试表（不包含一揽子交易） | F17: G7-11
D18: 14 | E18: 处置子公司测试表（一揽子交易） | F18: G7-12
D19: 15 | E19: 合营、联营企业投资成本测试表 | F19: G7-13
D20: 16 | E20: 权益法测算表 | F20: G7-14
D21: 17 | E21: 权益法未实现内部交易抵销测算表 | F21: G7-15
D22: 18 | E22: 未确认投资损失测试表 | F22: G7-16
D23: 19 | E23: 减值测试表 | F23: G7-17
D24: 20 | E24: 凭证检查表 | F24: G7-18

Sheet 长期股权投资实质性程序表G7A
A1: 致同会计师事务所
A2: 长期股权投资实质性程序表
A3: =底稿目录!A2 -> 被审计单位： | C3: =底稿目录!A4 -> 编制人： | F3: =底稿目录!A5 -> 编制日期： | H3: 索引号： | I3: =底稿目录!F4 -> G7A
A4: =底稿目录!A3 -> 截止日：202X年12月31日 | C4: =底稿目录!A6 -> 复核人： | F4: =底稿目录!A7 -> 复核日期： | H4: 页 次：
A5: 一、本账户涉及的科目
A6: 长期股权投资、长期股权投资减值准备
A7: 二、审计目标与认定的对应关系
A8: 审计目标 | G8: 财务报表的认定
A9: A. 资产负债表中记录的长期股权投资是存在的，且已记录于恰当的账户 | G9: 存在
A10: B. 所有应记录的长期股权投资均已记录，所有应当包括在财务报表中的相关披露均已包括 | G10: 完整性
A11: C. 记录的长期股权投资由被审计单位拥有或控制 | G11: 权利和义务
A12: D. 长期股权投资以恰当的金额包括在财务报表中，与之相关的计价或分摊调整已恰当记录，相关披露已得到恰当计量和描述 | G12: 准确性、计价和分摊
A13: E. 长期股权投资已被恰当地汇总或分解且表述清楚，相关披露在按照企业会计准则的编制基础下是相关的、可理解的 | G13: 列报
A14: 三、计划实施的实质性程序
A15: 序号 | B15: 审计程序 | C15: 程序分类 | D15: 财务报表的认定 | I15: 底稿索引号
D16: 存在 | E16: 完整性 | F16: 权利和 义务 | G16: 准确性、计价和分摊 | H16: 列报 | J16: 根据被审计单位实际情况和风险评估情况裁剪、修改或增加审计程序
A17: 1 | B17: 获取或编制长期股权投资的明细表，完成以下工作，并编制审定表 （1）复核加计是否正确，与总账、明细账合计数核对是否相符； （2）将期初余额与上期期末余额核对； （3）与上年明细项目进行比较，确定与上年分类相同； （4）检查非记账本位币计量的长期股权投资的折算汇率及折算是否正确。 | C17: 常规★ | D17: √ | E17: √ | G17: √ | I17: G7-1 /G7-2
A18: 2 | B18: 在使用手工编制、自定义信息报告、系统生成的非固定格式报告等由被审计单位生成的信息时，测试有关信息准确性和完整性，并考虑针对编制和维护由被审计单位生成的信息的相关控制实施控制测试，以评价该信息是否能够为实现审计目的提供基础。 | C18: 常规★ | E18: √ | G18: √ | I18: T1 /G0-2 /
A19: 3 | B19: 对期初余额的审计，获取前期期末对被投资单位股权投资的明细，以及相关支持文件并分析，判断公司对投资的分类及其影响程度的认定是否正确，关注计算的准确性，会计处理是否恰当；确定是否需要补充必要的程序。（适用于首次承接） | C19: 备选 | D19: √ | E19: √ | F19: √ | G19: √
A20: 4 | B20: 确认长期股权投资会计政策、会计处理是否合理并与前期一致；核对相关资产减值准备本期与以前年度计提方法是否一致，如有差异，查明政策调整的原因，并确定政策改变对本期损益的影响，提请被审计单位做适当披露。 | C20: 常规★ | D20: √ | E20: √ | G20: √ | I20: G7-6
A21: 5 | B21: 取得被投资单位的章程、营业执照、组织机构代码证等资料，根据有关合同和文件，确认长期股权投资的股权比例、表决权等，检查长期股权投资的分类和核算方法是否正确。 | C21: 常规★ | D21: √ | E21: √ | F21: √ | G21: √ | I21: G7-7 /G7-8 /G7-9 /G7-13 /G7-18
A22: 6 | B22: 对本期发生的长期股权投资的增减变动，检查至支持性文件，综合判断长期股权投资的购买日（或交易日）的认定是否正确，确定其会计处理是否正确，是否被记录在恰当的期间内。 | C22: 常规★ | D22: √ | F22: √ | G22: √ | I22: G7-10 /G7-14 /G7-15 /G7-16 /G7-18
A23: 7 | B23: 必要时对被投资单位进行函证确认主要条款（或查询工商存档文件），核实投资是否存在。 | C23: 备选 | D23: √ | E23: √ | F23: √ | G23: √ | I23: G0
A24: 8 | B24: 确定本期处置的重大股权投资，并执行下列程序： （1）检查与股权投资处置相关的合同、发票及其他文件； （2）重新计算相关的利得或损失； （3）确定会计处理是否恰当。 对于成本法和权益法相互转换的，检查会计处理是否正确。 | C24: 常规★ | D24: √ | E24: √ | F24: √ | G24: √ | I24: G7-11 /G7-12 /G7-18
A25: 9 | B25: 确定本期按权益法核算的长期股权投资进行正确的核算，考虑以下因素：（1）被投资单位的经营成果、财务状况和资本交易； （2）被投资单位为符合投资单位的会计政策而作出的任何必要的会计政策调整； （3）针对被投资单位账面价值、股利分配、收益影响、其他综合收益及其他权益变动的持续调整。 | C25: 常规★ | G25: √ | I25: G7-14 /G7-15 /G7-16
A26: 10 | B26: 对于按成本法核算的长期股权投资，检查股利分配的原始凭证及分配决议等资料，确定会计处理是否正确。 | C26: 常规★ | G26: √ | I26: G7-10
A27: 11 | B27: 针对存在减值迹象的长期股权投资，考虑执行下列程序： （1）获取长期股权投资的减值明细表，考虑对该投资可能造成减值的事件或环境变化； （2）获取被审计单位管理层在资产负债表日就长期股权投资是否存在可能发生减值迹象的判断说明及减值测试过程，关注计提减值准备的依据是否充分，减值测试过程是否合理，会计处理是否正确。 （3）考虑是否需要利用估值专家的工作，如需要完成利用专家工作底稿。 | C27: 常规★ | G27: √ | I27: G7-17
A28: 12 | B28: 了解长期股权投资是否存在所有权限制，承诺或留置。 | C28: 常规★ | F28: √ | I28: G7-2
A29: 13 | B29: 与被审计单位人员讨论确定是否存在被投资单位由于所在国家和地区及其他方面的影响，其向被审计单位转移资金的能力受到限制的情况，如存在，应详细记录受限情况，并提请被审计单位充分披露。 | C29: 常规★ | H29: √ | I29: G7-2
A30: 14 | B30: 检查关联方交易： （1）了解关联交易的商业理由、交易事项的目的、价格和条件，考虑对关联方交易性金融资产的合理性、合法性； （2）检查对关联方交易性金融资产的真实性相关的支持性文件、检查会计处理是否正确； （3）考虑向关联方或其他注册会计师函证重大的关联交易和余额（包括担保和其他重要信息）； （4）必要时，向与交易相关的人员和机构函证或与其讨论有关信息； （5）考虑是否存在未识别的关联方，关联交易和余额披露是否正确。 | C30: 常规★ | D30: √ | E30: √ | F30: √ | G30: √ | H30: √
A31: 15 | B31: 根据评估的舞弊风险等因素增加的审计程序。 | C31: IPO/上市/新三板/重组/舞弊应对
A32: 16 | B32: 检查长期股权投资是否已按照企业会计准则的规定在财务报表中作出恰当列报和披露。 | C32: 常规★ | H32: √ | I32: A1-1/A1-15 /A1-16

Sheet 长期股权投资审定表G7-1
A1: 致同会计师事务所
A2: 长期股权投资审定表
A3: =底稿目录!A2 -> 被审计单位： | D3: =底稿目录!A4 -> 编制人： | E3: =底稿目录!A5 -> 编制日期： | F3: 索引号： | G3: =底稿目录!F5 -> G7-1
A4: =底稿目录!A3 -> 截止日：202X年12月31日 | D4: =底稿目录!A6 -> 复核人： | E4: =底稿目录!A7 -> 复核日期： | F4: 页 次：
A5: 项目 | C5: 期初数 | D5: 本期增加 | E5: 本期减少 | F5: 期末数 | G5: 索引
A6: 一、原值
A7: 未审数 | C7: =SUM(C8:C11) -> 0 | D7: =SUM(D8:D11) -> 0 | E7: =SUM(E8:E11) -> 0 | F7: =SUM(F8:F11) -> 0
A8: 一、对子公司投资 | C8: ='明细表G7-2'!M26 -> 0 | D8: ='明细表G7-2'!O26 -> 0 | E8: ='明细表G7-2'!R26 -> 0 | F8: =C8+D8-E8 -> 0
A9: 二、对合营企业投资 | C9: ='明细表G7-2'!H38 -> 0 | D9: ='明细表G7-2'!J38+'明细表G7-2'!N38 -> 0 | E9: ='明细表G7-2'!Q38+'明细表G7-2'!R38 -> 0 | F9: =C9+D9-E9 -> 0
A10: 三、对联营企业投资 | C10: ='明细表G7-2'!H45 -> 0 | D10: ='明细表G7-2'!J45+'明细表G7-2'!N45 -> 0 | E10: ='明细表G7-2'!Q45+'明细表G7-2'!R45 -> 0 | F10: =C10+D10-E10 -> 0
F11: =C11+D11-E11 -> 0
A12: 账项调整 | C12: =SUM(C13:C16) -> 0 | D12: =SUM(D13:D16) -> 0 | E12: =SUM(E13:E16) -> 0 | F12: =SUM(F13:F16) -> 0
A13: =A8 -> 一、对子公司投资 | C13: ='明细表G7-2'!V26 -> 0 | D13: ='明细表G7-2'!X26 -> 0 | E13: ='明细表G7-2'!Y26 -> 0 | F13: =C13+D13-E13 -> 0
A14: =A9 -> 二、对合营企业投资 | C14: ='明细表G7-2'!V38 -> 0 | D14: ='明细表G7-2'!X38+'明细表G7-2'!Y38+'明细表G7-2'!Z38+'明细表G7-2'!AA38 -> 0 | E14: ='明细表G7-2'!AC38+'明细表G7-2'!AD38 -> 0 | F14: =C14+D14-E14 -> 0
A15: =A10 -> 三、对联营企业投资 | C15: ='明细表G7-2'!V45 -> 0 | D15: ='明细表G7-2'!X45+'明细表G7-2'!Y45+'明细表G7-2'!Z45+'明细表G7-2'!AA45 -> 0 | E15: ='明细表G7-2'!AC45+'明细表G7-2'!AD45 -> 0 | F15: =C15+D15-E15 -> 0
A16: =A11 -> 0 | F16: =C16+D16-E16 -> 0
A17: 重分类调整 | C17: =SUM(C18:C21) -> 0 | D17: =SUM(D18:D21) -> 0 | E17: =SUM(E18:E21) -> 0 | F17: =SUM(F18:F21) -> 0
A18: =A13 -> 一、对子公司投资 | C18: ='明细表G7-2'!W26 -> 0 | D18: ='明细表G7-2'!Z26 -> 0 | E18: ='明细表G7-2'!AA26 -> 0 | F18: =C18+D18-E18 -> 0
A19: =A14 -> 二、对合营企业投资 | C19: ='明细表G7-2'!W38 -> 0 | D19: ='明细表G7-2'!AF38+'明细表G7-2'!AG38+'明细表G7-2'!AH38+'明细表G7-2'!AI38 -> 0 | E19: ='明细表G7-2'!AK38+'明细表G7-2'!AL38 -> 0 | F19: =C19+D19-E19 -> 0
A20: =A15 -> 三、对联营企业投资 | C20: ='明细表G7-2'!W45 -> 0 | D20: ='明细表G7-2'!AF45+'明细表G7-2'!AG45+'明细表G7-2'!AH45+'明细表G7-2'!AI45 -> 0 | E20: ='明细表G7-2'!AK45+'明细表G7-2'!AL45 -> 0 | F20: =C20+D20-E20 -> 0
A21: =A16 -> 0 | F21: =C21+D21-E21 -> 0
A22: 审定数1 | C22: =SUM(C23:C26) -> 0 | D22: =SUM(D23:D26) -> 0 | E22: =SUM(E23:E26) -> 0 | F22: =SUM(F23:F26) -> 0
A23: =A18 -> 一、对子公司投资 | C23: =C8+C13+C18 -> 0 | D23: =D8+D13+D18 -> 0 | E23: =E8+E13+E18 -> 0 | F23: =C23+D23-E23 -> 0
A24: =A19 -> 二、对合营企业投资 | C24: =C9+C14+C19 -> 0 | D24: =D9+D14+D19 -> 0 | E24: =E9+E14+E19 -> 0 | F24: =C24+D24-E24 -> 0
A25: =A20 -> 三、对联营企业投资 | C25: =C10+C15+C20 -> 0 | D25: =D10+D15+D20 -> 0 | E25: =E10+E15+E20 -> 0 | F25: =C25+D25-E25 -> 0
A26: =A21 -> 0 | C26: =C11+C16+C21 -> 0 | D26: =D11+D16+D21 -> 0 | E26: =E11+E16+E21 -> 0 | F26: =C26+D26-E26 -> 0
A27: 二、减值准备
A28: 未审数 | C28: =SUM(C29:C32) -> 0 | D28: =SUM(D29:D32) -> 0 | E28: =SUM(E29:E32) -> 0 | F28: =SUM(F29:F32) -> 0
A29: =A8 -> 一、对子公司投资 | C29: ='明细表G7-2'!G63 -> 0 | D29: ='明细表G7-2'!H63 -> 0 | E29: ='明细表G7-2'!I63 -> 0 | F29: =C29+D29-E29 -> 0
A30: =A9 -> 二、对合营企业投资 | C30: ='明细表G7-2'!G71 -> 0 | D30: ='明细表G7-2'!H71 -> 0 | E30: ='明细表G7-2'!I71 -> 0 | F30: =C30+D30-E30 -> 0
A31: =A10 -> 三、对联营企业投资 | C31: ='明细表G7-2'!G78 -> 0 | D31: ='明细表G7-2'!H78 -> 0 | E31: ='明细表G7-2'!I78 -> 0 | F31: =C31+D31-E31 -> 0
A32: =A11 -> 0 | F32: =C32+D32-E32 -> 0
A33: 账项调整 | C33: =SUM(C34:C37) -> 0 | D33: =SUM(D34:D37) -> 0 | E33: =SUM(E34:E37) -> 0 | F33: =SUM(F34:F37) -> 0
A34: =A13 -> 一、对子公司投资 | C34: ='明细表G7-2'!L63 -> 0 | D34: ='明细表G7-2'!N63 -> 0 | E34: ='明细表G7-2'!O63 -> 0 | F34: =C34+D34-E34 -> 0
A35: =A14 -> 二、对合营企业投资 | C35: ='明细表G7-2'!L71 -> 0 | D35: ='明细表G7-2'!N71 -> 0 | E35: ='明细表G7-2'!O71 -> 0 | F35: =C35+D35-E35 -> 0
A36: =A15 -> 三、对联营企业投资 | C36: ='明细表G7-2'!L78 -> 0 | D36: ='明细表G7-2'!N78 -> 0 | E36: ='明细表G7-2'!O78 -> 0 | F36: =C36+D36-E36 -> 0
A37: =A16 -> 0 | F37: =C37+D37-E37 -> 0
A38: 重分类调整 | C38: =SUM(C39:C42) -> 0 | D38: =SUM(D39:D42) -> 0 | E38: =SUM(E39:E42) -> 0 | F38: =SUM(F39:F42) -> 0
A39: =A18 -> 一、对子公司投资 | C39: ='明细表G7-2'!M62 -> 0 | D39: ='明细表G7-2'!N63 -> 0 | E39: ='明细表G7-2'!O63 -> 0 | F39: =C39+D39-E39 -> 0
A40: =A19 -> 二、对合营企业投资 | C40: ='明细表G7-2'!M71 -> 0 | D40: ='明细表G7-2'!P71 -> 0 | E40: ='明细表G7-2'!Q71 -> 0 | F40: =C40+D40-E40 -> 0
...

Sheet 附注披露信息（上市公司）
A1: 致同会计师事务所
A2: 附注披露信息（上市公司）
A3: =底稿目录!A2 -> 被审计单位： | C3: =底稿目录!A4 -> 编制人： | F3: =底稿目录!A5 -> 编制日期： | K3: 索引号： | L3: =底稿目录!F6 -> 0
A4: =底稿目录!A3 -> 截止日：202X年12月31日 | C4: =底稿目录!A6 -> 复核人： | F4: =底稿目录!A7 -> 复核日期： | K4: 页次：
A5: 附注披露信息
A6: 长期股权投资
A8: 被投资单位 | B8: 期初余额（账面价值） | D8: 本期增减变动 | L8: 期末余额（账面价值） | M8: 减值准备期末余额
C9: 减值准备期初余额 | D9: 追加/新增投资 | E9: 减少投资 | F9: 权益法下 | G9: 其他综合 | H9: 其他权益变动 | I9: 宣告发放现金股利或利润 | J9: 计提减值准备 | K9: 其他
F10: 确认的 | G10: 收益调整
F11: 投资损益
A12: ①合营企业
A13: …
A15: 小 计
A16: ②联营企业
A17: …
A22: 小 计
A23: 合 计
A24: （长期资产本期进行减值测试的，应披露可收回金额的具体确定方法。可收回金额按公允价值减去处置费用后的净额确定的，应披露公允价值和处置费用的确定方式、关键参数及其确定依据。可收回金额按预计未来现金流量的现值确定的，应披露预测期的年限、预测期及稳定期的关键参数及其确定依据。前述信息与以前年度减值测试采用的信息或外部信息明显不一致的，或公司以前年度减值测试采用信息与当年实际情况明显不一致的，应披露差异原因。（15号文第十九条（十九）））
A26: 1、在子公司中的权益
A27: （1）企业集团的构成
A28: 子公司名称 | B28: 主要经营地 | C28: 注册地 | D28: 业务性质 | E28: 持股比例% | G28: 取得方式
E29: 直接 | F29: 间接
A30: ='被投资单位基本信息G7-4'!B12 -> 0 | B30: ='被投资单位基本信息G7-4'!F12 -> 0 | C30: ='被投资单位基本信息G7-4'!G12 -> 0 | D30: ='被投资单位基本信息G7-4'!H12 -> 0 | E30: ='被投资单位基本信息G7-4'!M12 -> 0 | F30: ='被投资单位基本信息G7-4'!N12 -> 0 | G30: ='被投资单位基本信息G7-4'!S12 -> 0
A31: ='被投资单位基本信息G7-4'!B13 -> 0 | B31: ='被投资单位基本信息G7-4'!F13 -> 0 | C31: ='被投资单位基本信息G7-4'!G13 -> 0 | D31: ='被投资单位基本信息G7-4'!H13 -> 0 | E31: ='被投资单位基本信息G7-4'!M13 -> 0 | F31: ='被投资单位基本信息G7-4'!N13 -> 0 | G31: ='被投资单位基本信息G7-4'!S13 -> 0
A32: ='被投资单位基本信息G7-4'!B14 -> 0 | B32: ='被投资单位基本信息G7-4'!F14 -> 0 | C32: ='被投资单位基本信息G7-4'!G14 -> 0 | D32: ='被投资单位基本信息G7-4'!H14 -> 0 | E32: ='被投资单位基本信息G7-4'!M14 -> 0 | F32: ='被投资单位基本信息G7-4'!N14 -> 0 | G32: ='被投资单位基本信息G7-4'!S14 -> 0
A33: ='被投资单位基本信息G7-4'!B15 -> 0 | B33: ='被投资单位基本信息G7-4'!F15 -> 0 | C33: ='被投资单位基本信息G7-4'!G15 -> 0 | D33: ='被投资单位基本信息G7-4'!H15 -> 0 | E33: ='被投资单位基本信息G7-4'!M15 -> 0 | F33: ='被投资单位基本信息G7-4'!N15 -> 0 | G33: ='被投资单位基本信息G7-4'!S15 -> 0
A34: ='被投资单位基本信息G7-4'!B16 -> 0 | B34: ='被投资单位基本信息G7-4'!F16 -> 0 | C34: ='被投资单位基本信息G7-4'!G16 -> 0 | D34: ='被投资单位基本信息G7-4'!H16 -> 0 | E34: ='被投资单位基本信息G7-4'!M16 -> 0 | F34: ='被投资单位基本信息G7-4'!N16 -> 0 | G34: ='被投资单位基本信息G7-4'!S16 -> 0
A35: ='被投资单位基本信息G7-4'!B17 -> 0 | B35: ='被投资单位基本信息G7-4'!F17 -> 0 | C35: ='被投资单位基本信息G7-4'!G17 -> 0 | D35: ='被投资单位基本信息G7-4'!H17 -> 0 | E35: ='被投资单位基本信息G7-4'!M17 -> 0 | F35: ='被投资单位基本信息G7-4'!N17 -> 0 | G35: ='被投资单位基本信息G7-4'!S17 -> 0
A36: ='被投资单位基本信息G7-4'!B18 -> 0 | B36: ='被投资单位基本信息G7-4'!F18 -> 0 | C36: ='被投资单位基本信息G7-4'!G18 -> 0 | D36: ='被投资单位基本信息G7-4'!H18 -> 0 | E36: ='被投资单位基本信息G7-4'!M18 -> 0 | F36: ='被投资单位基本信息G7-4'!N18 -> 0 | G36: ='被投资单位基本信息G7-4'!S18 -> 0
A37: ='被投资单位基本信息G7-4'!B19 -> 0 | B37: ='被投资单位基本信息G7-4'!F19 -> 0 | C37: ='被投资单位基本信息G7-4'!G19 -> 0 | D37: ='被投资单位基本信息G7-4'!H19 -> 0 | E37: ='被投资单位基本信息G7-4'!M19 -> 0 | F37: ='被投资单位基本信息G7-4'!N19 -> 0 | G37: ='被投资单位基本信息G7-4'!S19 -> 0
A38: ='被投资单位基本信息G7-4'!B20 -> 0 | B38: ='被投资单位基本信息G7-4'!F20 -> 0 | C38: ='被投资单位基本信息G7-4'!G20 -> 0 | D38: ='被投资单位基本信息G7-4'!H20 -> 0 | E38: ='被投资单位基本信息G7-4'!M20 -> 0 | F38: ='被投资单位基本信息G7-4'!N20 -> 0 | G38: ='被投资单位基本信息G7-4'!S20 -> 0
A39: ='被投资单位基本信息G7-4'!B21 -> …… | B39: ='被投资单位基本信息G7-4'!F21 -> 0 | C39: ='被投资单位基本信息G7-4'!G21 -> 0 | D39: ='被投资单位基本信息G7-4'!H21 -> 0 | E39: ='被投资单位基本信息G7-4'!M21 -> 0 | F39: ='被投资单位基本信息G7-4'!N21 -> 0 | G39: ='被投资单位基本信息G7-4'!S21 -> 0
A40: 说明：
A41: （1）子公司的持股比例不同于表决权比例的，应说明表决权比例及差异原因。
A42: （2）持有其他主体半数或以下表决权但仍控制该主体、以及公司持有其他主体半数以上表决权但不控制该主体的，公司应披露相关判断和依据。
A43: （3）披露确定公司是代理人还是委托人的判断和依据。
A44: （4）对于纳入合并范围的重要的结构化主体，应披露控制的相关判断和依据。
A45: 【例如资产证券化，公司应根据《信贷资产证券化试点管理办法》和《企业会计准则第23号-金融资产转移》，披露金融资产证券化业务的主要交易安排及其会计处理。涉及非金融资产的资产证券化业务，参照《信贷资产证券化试点管理办法》和《企业会计准则第23号-金融资产转移》的有关规定，披露资产证券化业务的主要交易安排及其会计处理。同时，应详细说明资产证券化业务的破产隔离条款。
A46: （本集团于本年度内将一笔金额为人民币[X]元（200Y年：人民币[X]元）的应收账款证券化转让给由XX银行设立的XX信托计划。作为转让的一部分，本集团就该笔应收账款的预期损失向信托计划提供信用担保。因此，本集团继续全额确认应收账款的账面金额并将因转让而收取的现金确认为抵押借款。在200X年12月31日，被转让的应收账款账面金额为人民币[X]元（200Y年：人民币[X]元），而相关负债的账面金额为人民币[X]元。）】
A47: （2）重要的非全资子公司
...

Sheet 附注披露信息（国企）
A1: 致同会计师事务所
A2: 附注披露信息（国企）
A3: =底稿目录!A2 -> 被审计单位： | D3: =底稿目录!A4 -> 编制人： | H3: =底稿目录!A5 -> 编制日期： | K3: 索引号： | L3: =底稿目录!F7 -> 0
A4: =底稿目录!A3 -> 截止日：202X年12月31日 | D4: =底稿目录!A6 -> 复核人： | H4: =底稿目录!A7 -> 复核日期： | K4: 页次：
A5: 附注披露信息
A6: 七、企业合并及合并财务报表
A7: （一）本期纳入合并报表范围的子公司基本情况
A8: （企业应当按下列格式披露纳入报表合并范围的全部子公司主要情况；大型企业集团合并报表范围可以披露到二级子公司，集团所属重要子公司不分级次全部披露）
A9: 序号 | B9: 企业名称 | C9: 级次 | D9: 企业类型 | E9: 注册地 | F9: 主要经营地 | G9: 业务性质 | H9: 实收资本 | I9: 认缴持股比例 （%） | J9: 实缴持股比例（%） | K9: 享有的表决权（%） | L9: 投资额 | M9: 取得方式
A10: 1 | B10: ='被投资单位基本信息G7-4'!B12 -> 0 | C10: ='被投资单位基本信息G7-4'!C12 -> 0 | D10: ='被投资单位基本信息G7-4'!D12 -> 0 | E10: ='被投资单位基本信息G7-4'!G12 -> 0 | F10: ='被投资单位基本信息G7-4'!F12 -> 0 | G10: ='被投资单位基本信息G7-4'!H12 -> 0 | H10: ='被投资单位基本信息G7-4'!I12 -> 0 | J10: ='被投资单位基本信息G7-4'!M12+'被投资单位基本信息G7-4'!N12 -> 0 | K10: ='被投资单位基本信息G7-4'!O12 -> 0 | L10: ='明细表G7-2'!AI16 -> 0 | M10: ='被投资单位基本信息G7-4'!S12 -> 0
A11: 2 | B11: ='被投资单位基本信息G7-4'!B13 -> 0 | C11: ='被投资单位基本信息G7-4'!C13 -> 0 | D11: ='被投资单位基本信息G7-4'!D13 -> 0 | E11: ='被投资单位基本信息G7-4'!G13 -> 0 | F11: ='被投资单位基本信息G7-4'!F13 -> 0 | G11: ='被投资单位基本信息G7-4'!H13 -> 0 | H11: ='被投资单位基本信息G7-4'!I13 -> 0 | J11: ='被投资单位基本信息G7-4'!M13+'被投资单位基本信息G7-4'!N13 -> 0 | K11: ='被投资单位基本信息G7-4'!O13 -> 0 | L11: ='明细表G7-2'!AI17 -> 0 | M11: ='被投资单位基本信息G7-4'!S13 -> 0
A12: 3 | B12: ='被投资单位基本信息G7-4'!B14 -> 0 | C12: ='被投资单位基本信息G7-4'!C14 -> 0 | D12: ='被投资单位基本信息G7-4'!D14 -> 0 | E12: ='被投资单位基本信息G7-4'!G14 -> 0 | F12: ='被投资单位基本信息G7-4'!F14 -> 0 | G12: ='被投资单位基本信息G7-4'!H14 -> 0 | H12: ='被投资单位基本信息G7-4'!I14 -> 0 | J12: ='被投资单位基本信息G7-4'!M14+'被投资单位基本信息G7-4'!N14 -> 0 | K12: ='被投资单位基本信息G7-4'!O14 -> 0 | L12: ='明细表G7-2'!AI18 -> 0 | M12: ='被投资单位基本信息G7-4'!S14 -> 0
A13: 4 | B13: ='被投资单位基本信息G7-4'!B15 -> 0 | C13: ='被投资单位基本信息G7-4'!C15 -> 0 | D13: ='被投资单位基本信息G7-4'!D15 -> 0 | E13: ='被投资单位基本信息G7-4'!G15 -> 0 | F13: ='被投资单位基本信息G7-4'!F15 -> 0 | G13: ='被投资单位基本信息G7-4'!H15 -> 0 | H13: ='被投资单位基本信息G7-4'!I15 -> 0 | J13: ='被投资单位基本信息G7-4'!M15+'被投资单位基本信息G7-4'!N15 -> 0 | K13: ='被投资单位基本信息G7-4'!O15 -> 0 | L13: ='明细表G7-2'!AI19 -> 0 | M13: ='被投资单位基本信息G7-4'!S15 -> 0
A14: 5 | B14: ='被投资单位基本信息G7-4'!B16 -> 0 | C14: ='被投资单位基本信息G7-4'!C16 -> 0 | D14: ='被投资单位基本信息G7-4'!D16 -> 0 | E14: ='被投资单位基本信息G7-4'!G16 -> 0 | F14: ='被投资单位基本信息G7-4'!F16 -> 0 | G14: ='被投资单位基本信息G7-4'!H16 -> 0 | H14: ='被投资单位基本信息G7-4'!I16 -> 0 | J14: ='被投资单位基本信息G7-4'!M16+'被投资单位基本信息G7-4'!N16 -> 0 | K14: ='被投资单位基本信息G7-4'!O16 -> 0 | L14: ='明细表G7-2'!AI20 -> 0 | M14: ='被投资单位基本信息G7-4'!S16 -> 0
A15: 6 | B15: ='被投资单位基本信息G7-4'!B17 -> 0 | C15: ='被投资单位基本信息G7-4'!C17 -> 0 | D15: ='被投资单位基本信息G7-4'!D17 -> 0 | E15: ='被投资单位基本信息G7-4'!G17 -> 0 | F15: ='被投资单位基本信息G7-4'!F17 -> 0 | G15: ='被投资单位基本信息G7-4'!H17 -> 0 | H15: ='被投资单位基本信息G7-4'!I17 -> 0 | J15: ='被投资单位基本信息G7-4'!M17+'被投资单位基本信息G7-4'!N17 -> 0 | K15: ='被投资单位基本信息G7-4'!O17 -> 0 | L15: ='明细表G7-2'!AI21 -> 0 | M15: ='被投资单位基本信息G7-4'!S17 -> 0
A16: 7 | B16: ='被投资单位基本信息G7-4'!B18 -> 0 | C16: ='被投资单位基本信息G7-4'!C18 -> 0 | D16: ='被投资单位基本信息G7-4'!D18 -> 0 | E16: ='被投资单位基本信息G7-4'!G18 -> 0 | F16: ='被投资单位基本信息G7-4'!F18 -> 0 | G16: ='被投资单位基本信息G7-4'!H18 -> 0 | H16: ='被投资单位基本信息G7-4'!I18 -> 0 | J16: ='被投资单位基本信息G7-4'!M18+'被投资单位基本信息G7-4'!N18 -> 0 | K16: ='被投资单位基本信息G7-4'!O18 -> 0 | L16: ='明细表G7-2'!AI22 -> 0 | M16: ='被投资单位基本信息G7-4'!S18 -> 0
A17: 8 | B17: ='被投资单位基本信息G7-4'!B19 -> 0 | C17: ='被投资单位基本信息G7-4'!C19 -> 0 | D17: ='被投资单位基本信息G7-4'!D19 -> 0 | E17: ='被投资单位基本信息G7-4'!G19 -> 0 | F17: ='被投资单位基本信息G7-4'!F19 -> 0 | G17: ='被投资单位基本信息G7-4'!H19 -> 0 | H17: ='被投资单位基本信息G7-4'!I19 -> 0 | J17: ='被投资单位基本信息G7-4'!M19+'被投资单位基本信息G7-4'!N19 -> 0 | K17: ='被投资单位基本信息G7-4'!O19 -> 0 | L17: ='明细表G7-2'!AI23 -> 0 | M17: ='被投资单位基本信息G7-4'!S19 -> 0
A18: 9 | B18: ='被投资单位基本信息G7-4'!B20 -> 0 | C18: ='被投资单位基本信息G7-4'!C20 -> 0 | D18: ='被投资单位基本信息G7-4'!D20 -> 0 | E18: ='被投资单位基本信息G7-4'!G20 -> 0 | F18: ='被投资单位基本信息G7-4'!F20 -> 0 | G18: ='被投资单位基本信息G7-4'!H20 -> 0 | H18: ='被投资单位基本信息G7-4'!I20 -> 0 | J18: ='被投资单位基本信息G7-4'!M20+'被投资单位基本信息G7-4'!N20 -> 0 | K18: ='被投资单位基本信息G7-4'!O20 -> 0 | L18: ='明细表G7-2'!AI24 -> 0 | M18: ='被投资单位基本信息G7-4'!S20 -> 0
A19: 10 | B19: ='被投资单位基本信息G7-4'!B21 -> …… | C19: ='被投资单位基本信息G7-4'!C21 -> 0 | D19: ='被投资单位基本信息G7-4'!D21 -> 0 | E19: ='被投资单位基本信息G7-4'!G21 -> 0 | F19: ='被投资单位基本信息G7-4'!F21 -> 0 | G19: ='被投资单位基本信息G7-4'!H21 -> 0 | H19: ='被投资单位基本信息G7-4'!I21 -> 0 | J19: ='被投资单位基本信息G7-4'!M21+'被投资单位基本信息G7-4'!N21 -> 0 | K19: ='被投资单位基本信息G7-4'!O21 -> 0 | L19: ='明细表G7-2'!AI25 -> 0 | M19: ='被投资单位基本信息G7-4'!S21 -> 0
A20: （注：企业类型：1.境内非金融子企业，2.境内金融子企业，3.境外子企业，4.事业单位，5.基建单位；
A21: 取得方式：1.投资设立，2.同一控制下的企业合并，3.非同一控制下的企业合并，4.其他）
A22: （注：子公司的持股比例不同于表决权比例的，应说明表决权比例及差异原因。）
A23: （注：级次为在整个中央企业集团内的法人级次）
A24: （二）母公司拥有被投资单位表决权不足半数但能对被投资单位形成控制的原因
A25: 序号 | B25: 企业名称 | C25: 认缴持股 比例（%） | D25: 享有的表决权 | E25: 注册资本 | F25: 投资额 | G25: 级次 | H25: 纳入合并范围原因
B26: =IF('被投资单位基本信息G7-4'!O12<=0.5,'被投资单位基本信息G7-4'!B12,0) -> 0 | C26: =IF('被投资单位基本信息G7-4'!O12<=0.5,'被投资单位基本信息G7-4'!M12+'被投资单位基本信息G7-4'!N12,0) -> 0 | D26: =IF('被投资单位基本信息G7-4'!O12<=0.5,'被投资单位基本信息G7-4'!O12,0) -> 0 | E26: =IF('被投资单位基本信息G7-4'!O12<=0.5,'被投资单位基本信息G7-4'!I12,0) -> 0 | F26: =IF('被投资单位基本信息G7-4'!O12<=0.5,'被投资单位基本信息G7-4'!J12,0) -> 0 | G26: =IF('被投资单位基本信息G7-4'!O12<=0.5,'被投资单位基本信息G7-4'!C12,0) -> 0 | H26: =IF('被投资单位基本信息G7-4'!O12<=0.5,'被投资单位基本信息G7-4'!Q12,0) -> 0
B27: =IF('被投资单位基本信息G7-4'!O13<=0.5,'被投资单位基本信息G7-4'!B13,0) -> 0 | C27: =IF('被投资单位基本信息G7-4'!O13<=0.5,'被投资单位基本信息G7-4'!M13+'被投资单位基本信息G7-4'!N13,0) -> 0 | D27: =IF('被投资单位基本信息G7-4'!O13<=0.5,'被投资单位基本信息G7-4'!O13,0) -> 0 | E27: =IF('被投资单位基本信息G7-4'!O13<=0.5,'被投资单位基本信息G7-4'!I13,0) -> 0 | F27: =IF('被投资单位基本信息G7-4'!O13<=0.5,'被投资单位基本信息G7-4'!J13,0) -> 0 | G27: =IF('被投资单位基本信息G7-4'!O13<=0.5,'被投资单位基本信息G7-4'!C13,0) -> 0 | H27: =IF('被投资单位基本信息G7-4'!O13<=0.5,'被投资单位基本信息G7-4'!Q13,0) -> 0
B28: =IF('被投资单位基本信息G7-4'!O14<=0.5,'被投资单位基本信息G7-4'!B14,0) -> 0 | C28: =IF('被投资单位基本信息G7-4'!O14<=0.5,'被投资单位基本信息G7-4'!M14+'被投资单位基本信息G7-4'!N14,0) -> 0 | D28: =IF('被投资单位基本信息G7-4'!O14<=0.5,'被投资单位基本信息G7-4'!O14,0) -> 0 | E28: =IF('被投资单位基本信息G7-4'!O14<=0.5,'被投资单位基本信息G7-4'!I14,0) -> 0 | F28: =IF('被投资单位基本信息G7-4'!O14<=0.5,'被投资单位基本信息G7-4'!J14,0) -> 0 | G28: =IF('被投资单位基本信息G7-4'!O14<=0.5,'被投资单位基本信息G7-4'!C14,0) -> 0 | H28: =IF('被投资单位基本信息G7-4'!O14<=0.5,'被投资单位基本信息G7-4'!Q14,0) -> 0
B29: =IF('被投资单位基本信息G7-4'!O15<=0.5,'被投资单位基本信息G7-4'!B15,0) -> 0 | C29: =IF('被投资单位基本信息G7-4'!O15<=0.5,'被投资单位基本信息G7-4'!M15+'被投资单位基本信息G7-4'!N15,0) -> 0 | D29: =IF('被投资单位基本信息G7-4'!O15<=0.5,'被投资单位基本信息G7-4'!O15,0) -> 0 | E29: =IF('被投资单位基本信息G7-4'!O15<=0.5,'被投资单位基本信息G7-4'!I15,0) -> 0 | F29: =IF('被投资单位基本信息G7-4'!O15<=0.5,'被投资单位基本信息G7-4'!J15,0) -> 0 | G29: =IF('被投资单位基本信息G7-4'!O15<=0.5,'被投资单位基本信息G7-4'!C15,0) -> 0 | H29: =IF('被投资单位基本信息G7-4'!O15<=0.5,'被投资单位基本信息G7-4'!Q15,0) -> 0
B30: =IF('被投资单位基本信息G7-4'!O16<=0.5,'被投资单位基本信息G7-4'!B16,0) -> 0 | C30: =IF('被投资单位基本信息G7-4'!O16<=0.5,'被投资单位基本信息G7-4'!M16+'被投资单位基本信息G7-4'!N16,0) -> 0 | D30: =IF('被投资单位基本信息G7-4'!O16<=0.5,'被投资单位基本信息G7-4'!O16,0) -> 0 | E30: =IF('被投资单位基本信息G7-4'!O16<=0.5,'被投资单位基本信息G7-4'!I16,0) -> 0 | F30: =IF('被投资单位基本信息G7-4'!O16<=0.5,'被投资单位基本信息G7-4'!J16,0) -> 0 | G30: =IF('被投资单位基本信息G7-4'!O16<=0.5,'被投资单位基本信息G7-4'!C16,0) -> 0 | H30: =IF('被投资单位基本信息G7-4'!O16<=0.5,'被投资单位基本信息G7-4'!Q16,0) -> 0
B31: =IF('被投资单位基本信息G7-4'!O17<=0.5,'被投资单位基本信息G7-4'!B17,0) -> 0 | C31: =IF('被投资单位基本信息G7-4'!O17<=0.5,'被投资单位基本信息G7-4'!M17+'被投资单位基本信息G7-4'!N17,0) -> 0 | D31: =IF('被投资单位基本信息G7-4'!O17<=0.5,'被投资单位基本信息G7-4'!O17,0) -> 0 | E31: =IF('被投资单位基本信息G7-4'!O17<=0.5,'被投资单位基本信息G7-4'!I17,0) -> 0 | F31: =IF('被投资单位基本信息G7-4'!O17<=0.5,'被投资单位基本信息G7-4'!J17,0) -> 0 | G31: =IF('被投资单位基本信息G7-4'!O17<=0.5,'被投资单位基本信息G7-4'!C17,0) -> 0 | H31: =IF('被投资单位基本信息G7-4'!O17<=0.5,'被投资单位基本信息G7-4'!Q17,0) -> 0
B32: =IF('被投资单位基本信息G7-4'!O18<=0.5,'被投资单位基本信息G7-4'!B18,0) -> 0 | C32: =IF('被投资单位基本信息G7-4'!O18<=0.5,'被投资单位基本信息G7-4'!M18+'被投资单位基本信息G7-4'!N18,0) -> 0 | D32: =IF('被投资单位基本信息G7-4'!O18<=0.5,'被投资单位基本信息G7-4'!O18,0) -> 0 | E32: =IF('被投资单位基本信息G7-4'!O18<=0.5,'被投资单位基本信息G7-4'!I18,0) -> 0 | F32: =IF('被投资单位基本信息G7-4'!O18<=0.5,'被投资单位基本信息G7-4'!J18,0) -> 0 | G32: =IF('被投资单位基本信息G7-4'!O18<=0.5,'被投资单位基本信息G7-4'!C18,0) -> 0 | H32: =IF('被投资单位基本信息G7-4'!O18<=0.5,'被投资单位基本信息G7-4'!Q18,0) -> 0
B33: =IF('被投资单位基本信息G7-4'!O19<=0.5,'被投资单位基本信息G7-4'!B19,0) -> 0 | C33: =IF('被投资单位基本信息G7-4'!O19<=0.5,'被投资单位基本信息G7-4'!M19+'被投资单位基本信息G7-4'!N19,0) -> 0 | D33: =IF('被投资单位基本信息G7-4'!O19<=0.5,'被投资单位基本信息G7-4'!O19,0) -> 0 | E33: =IF('被投资单位基本信息G7-4'!O19<=0.5,'被投资单位基本信息G7-4'!I19,0) -> 0 | F33: =IF('被投资单位基本信息G7-4'!O19<=0.5,'被投资单位基本信息G7-4'!J19,0) -> 0 | G33: =IF('被投资单位基本信息G7-4'!O19<=0.5,'被投资单位基本信息G7-4'!C19,0) -> 0 | H33: =IF('被投资单位基本信息G7-4'!O19<=0.5,'被投资单位基本信息G7-4'!Q19,0) -> 0
B34: =IF('被投资单位基本信息G7-4'!O20<=0.5,'被投资单位基本信息G7-4'!B20,0) -> 0 | C34: =IF('被投资单位基本信息G7-4'!O20<=0.5,'被投资单位基本信息G7-4'!M20+'被投资单位基本信息G7-4'!N20,0) -> 0 | D34: =IF('被投资单位基本信息G7-4'!O20<=0.5,'被投资单位基本信息G7-4'!O20,0) -> 0 | E34: =IF('被投资单位基本信息G7-4'!O20<=0.5,'被投资单位基本信息G7-4'!I20,0) -> 0 | F34: =IF('被投资单位基本信息G7-4'!O20<=0.5,'被投资单位基本信息G7-4'!J20,0) -> 0 | G34: =IF('被投资单位基本信息G7-4'!O20<=0.5,'被投资单位基本信息G7-4'!C20,0) -> 0 | H34: =IF('被投资单位基本信息G7-4'!O20<=0.5,'被投资单位基本信息G7-4'!Q20,0) -> 0
B35: =IF('被投资单位基本信息G7-4'!O21<=0.5,'被投资单位基本信息G7-4'!B21,0) -> …… | C35: =IF('被投资单位基本信息G7-4'!O21<=0.5,'被投资单位基本信息G7-4'!M21+'被投资单位基本信息G7-4'!N21,0) -> 0 | D35: =IF('被投资单位基本信息G7-4'!O21<=0.5,'被投资单位基本信息G7-4'!O21,0) -> 0 | E35: =IF('被投资单位基本信息G7-4'!O21<=0.5,'被投资单位基本信息G7-4'!I21,0) -> 0 | F35: =IF('被投资单位基本信息G7-4'!O21<=0.5,'被投资单位基本信息G7-4'!J21,0) -> 0 | G35: =IF('被投资单位基本信息G7-4'!O21<=0.5,'被投资单位基本信息G7-4'!C21,0) -> 0 | H35: =IF('被投资单位基本信息G7-4'!O21<=0.5,'被投资单位基本信息G7-4'!Q21,0) -> 0
A36: （三）母公司直接或通过其他子公司间接拥有被投资单位半数以上的表决权但未能对其形成控制的原因
A37: 序号 | B37: 企业名称 | C37: 认缴持股 比例（%） | D37: 享有的表决权 | E37: 注册资本 | F37: 投资额 | G37: 级次 | H37: 未纳入合并范围原因
B38: 合营企业
B39: =IF('被投资单位基本信息G7-4'!M23+'被投资单位基本信息G7-4'!N23>0.5,'被投资单位基本信息G7-4'!B23,0) -> 0 | C39: =IF('被投资单位基本信息G7-4'!M23+'被投资单位基本信息G7-4'!N23>0.5,'被投资单位基本信息G7-4'!M23+'被投资单位基本信息G7-4'!N23,0) -> 0 | D39: =IF('被投资单位基本信息G7-4'!M23+'被投资单位基本信息G7-4'!N23>0.5,'被投资单位基本信息G7-4'!O23,0) -> 0 | E39: =IF('被投资单位基本信息G7-4'!M23+'被投资单位基本信息G7-4'!N23>0.5,'被投资单位基本信息G7-4'!I23,0) -> 0 | F39: =IF('被投资单位基本信息G7-4'!M23+'被投资单位基本信息G7-4'!N23>0.5,'被投资单位基本信息G7-4'!J23,0) -> 0 | G39: =IF('被投资单位基本信息G7-4'!M23+'被投资单位基本信息G7-4'!N23>0.5,'被投资单位基本信息G7-4'!C23,0) -> 0 | H39: =IF('被投资单位基本信息G7-4'!M23+'被投资单位基本信息G7-4'!N23>0.5,'被投资单位基本信息G7-4'!R23,0) -> 0
B40: =IF('被投资单位基本信息G7-4'!M24+'被投资单位基本信息G7-4'!N24>0.5,'被投资单位基本信息G7-4'!B24,0) -> 0 | C40: =IF('被投资单位基本信息G7-4'!M24+'被投资单位基本信息G7-4'!N24>0.5,'被投资单位基本信息G7-4'!M24+'被投资单位基本信息G7-4'!N24,0) -> 0 | D40: =IF('被投资单位基本信息G7-4'!M24+'被投资单位基本信息G7-4'!N24>0.5,'被投资单位基本信息G7-4'!O24,0) -> 0 | E40: =IF('被投资单位基本信息G7-4'!M24+'被投资单位基本信息G7-4'!N24>0.5,'被投资单位基本信息G7-4'!I24,0) -> 0 | F40: =IF('被投资单位基本信息G7-4'!M24+'被投资单位基本信息G7-4'!N24>0.5,'被投资单位基本信息G7-4'!J24,0) -> 0 | G40: =IF('被投资单位基本信息G7-4'!M24+'被投资单位基本信息G7-4'!N24>0.5,'被投资单位基本信息G7-4'!C24,0) -> 0 | H40: =IF('被投资单位基本信息G7-4'!M24+'被投资单位基本信息G7-4'!N24>0.5,'被投资单位基本信息G7-4'!R24,0) -> 0
...

Sheet 明细表G7-2
A1: 致同会计师事务所 | V1: 致同会计师事务所 | AN1: 致同会计师事务所
A2: 长期股权投资明细表 | V2: 长期股权投资明细表 | AN2: 长期股权投资明细表
A3: =底稿目录!A2 -> 被审计单位： | C3: =底稿目录!A4 -> 编制人： | E3: =底稿目录!A5 -> 编制日期： | I3: 索引号： | J3: =底稿目录!F8 -> G7-2 | L3: =A3 -> 被审计单位： | P3: =C3 -> 编制人： | R3: =E3 -> 编制日期： | T3: =I3 -> 索引号： | U3: =J3 -> G7-2 | V3: =底稿目录!A2 -> 被审计单位： | AA3: =底稿目录!A4 -> 编制人： | AE3: =底稿目录!A5 -> 编制日期： | AL3: 索引号： | AM3: =底稿目录!F8 -> G7-2 | AN3: =底稿目录!A2 -> 被审计单位： | AS3: =底稿目录!A4 -> 编制人： | AX3: =底稿目录!A5 -> 编制日期： | BA3: 索引号： | BB3: =底稿目录!F8 -> G7-2
A4: =底稿目录!A3 -> 截止日：202X年12月31日 | C4: =底稿目录!A6 -> 复核人： | E4: =底稿目录!A7 -> 复核日期： | I4: 页 次： | L4: =A4 -> 截止日：202X年12月31日 | P4: =C4 -> 复核人： | R4: =E4 -> 复核日期： | T4: =I4 -> 页 次： | U4: =J4 -> 0 | V4: =底稿目录!A3 -> 截止日：202X年12月31日 | AA4: =底稿目录!A6 -> 复核人： | AE4: =底稿目录!A7 -> 复核日期： | AL4: 页次： | AN4: =底稿目录!A3 -> 截止日：202X年12月31日 | AS4: =底稿目录!A6 -> 复核人： | AX4: =底稿目录!A7 -> 复核日期： | BA4: 页次：
A5: 一、审计目标： | L5: =A5 -> 一、审计目标： | V5: =L5 -> 一、审计目标： | AN5: =V5 -> 一、审计目标：
A6: 1.资产负债表中记录的长期股权投资是存在的，且已经记录在恰当的账户中； | L6: 1.资产负债表中记录的长期股权投资是存在的，且已经记录在恰当的账户中； | V6: =L6 -> 1.资产负债表中记录的长期股权投资是存在的，且已经记录在恰当的账户中； | AN6: =V6 -> 1.资产负债表中记录的长期股权投资是存在的，且已经记录在恰当的账户中；
A7: 2.所有应记录的长期股权投资均已记录，所有应当包括在财务报表中的相关披露均已包括； | L7: 2.所有应记录的长期股权投资均已记录，所有应当包括在财务报表中的相关披露均已包括； | V7: =L7 -> 2.所有应记录的长期股权投资均已记录，所有应当包括在财务报表中的相关披露均已包括； | AN7: =V7 -> 2.所有应记录的长期股权投资均已记录，所有应当包括在财务报表中的相关披露均已包括；
A8: 3.长期股权投资以恰当的金额包括在财务报表中，与之相关的计价或分摊调整已恰当记录，相关披露已得到恰当计量和描述； | L8: 3.长期股权投资以恰当的金额包括在财务报表中，与之相关的计价或分摊调整已恰当记录，相关披露已得到恰当计量和描述； | V8: =L8 -> 3.长期股权投资以恰当的金额包括在财务报表中，与之相关的计价或分摊调整已恰当记录，相关披露已得到恰当计量和描述； | AN8: =V8 -> 3.长期股权投资以恰当的金额包括在财务报表中，与之相关的计价或分摊调整已恰当记录，相关披露已得到恰当计量和描述；
A9: 4.记录的长期股权投资由被审计单位拥有或控制 | L9: 4.记录的长期股权投资由被审计单位拥有或控制 | V9: =L9 -> 4.记录的长期股权投资由被审计单位拥有或控制 | AN9: =V9 -> 4.记录的长期股权投资由被审计单位拥有或控制
A10: 二、审计过程 | L10: =A10 -> 二、审计过程 | V10: =L10 -> 二、审计过程 | AN10: =V10 -> 二、审计过程
A11: 提示：与被审计单位人员讨论确定是否存在被投资单位由于所在国家和地区及其他方面的影响，其向被审计单位转移资金的能力受到限制的情况，如存在，应详细记录受限情况，并提请被审计单位充分披露 | L11: =A11 -> 提示：与被审计单位人员讨论确定是否存在被投资单位由于所在国家和地区及其他方面的影响，其向被审计单位转移资金的能力受到限制的情况，如存在，应详细记录受限情况，并提请被审计单位充分披露 | V11: =L11 -> 提示：与被审计单位人员讨论确定是否存在被投资单位由于所在国家和地区及其他方面的影响，其向被审计单位转移资金的能力受到限制的情况，如存在，应详细记录受限情况，并提请被审计单位充分披露 | AN11: =V11 -> 提示：与被审计单位人员讨论确定是否存在被投资单位由于所在国家和地区及其他方面的影响，其向被审计单位转移资金的能力受到限制的情况，如存在，应详细记录受限情况，并提请被审计单位充分披露
A12: （一）按成本法核算的长期股权投资 | L12: （一）按成本法核算的长期股权投资 | V12: （一）按成本法核算的长期股权投资
A13: 序号 | B13: 被投资单位名称 | F13: 初始投资成本 | H13: 投资比例 | I13: 投资时间 | J13: 投资方式 | K13: 本期现金红利 | L13: 未审数 | V13: 期初调整 | X13: 账项调整 | Z13: 重分类调整 | AB13: 审定数
L14: 期初余额 | N14: 本期增加 | Q14: 本期减少 | T14: 期末余额 | V14: 账项调整 | W14: 重分类调整 | X14: 本期增加 | Y14: 本期减少 | Z14: 本期增加 | AA14: 本期减少 | AB14: 期初余额 | AD14: 本期增加 | AF14: 本期减少 | AH14: 期末余额
L15: 投资比例 | M15: 金额 | N15: 投资比例 | O15: 金额 | P15: 索引号 | Q15: 投资比例 | R15: 金额 | S15: 索引号 | T15: 投资比例 | U15: 金额 | X15: 本期增加 | Y15: 本期减少 | Z15: 本期增加 | AA15: 本期减少 | AB15: 投资比例 | AC15: 金额 | AD15: 投资比例 | AE15: 金额 | AF15: 投资比例 | AG15: 金额 | AH15: 投资比例 | AI15: 金额
A16: 1 | T16: =L16+N16-Q16 -> 0 | U16: =M16+O16-R16 -> 0 | AB16: =L16 -> 0 | AC16: =M16+V16+W16 -> 0 | AD16: =N16 -> 0 | AE16: =O16+X16+Z16 -> 0 | AF16: =Q16 -> 0 | AG16: =R16+Y16+AA16 -> 0 | AH16: =AB16+AD16-AF16 -> 0 | AI16: =AC16+AE16-AG16 -> 0
A17: 2 | T17: =L17+N17-Q17 -> 0 | U17: =M17+O17-R17 -> 0 | AB17: =L17 -> 0 | AC17: =M17+V17+W17 -> 0 | AD17: =N17 -> 0 | AE17: =O17+X17+Z17 -> 0 | AF17: =Q17 -> 0 | AG17: =R17+Y17+AA17 -> 0 | AH17: =AB17+AD17-AF17 -> 0 | AI17: =AC17+AE17-AG17 -> 0
A18: 3 | T18: =L18+N18-Q18 -> 0 | U18: =M18+O18-R18 -> 0 | AB18: =L18 -> 0 | AC18: =M18+V18+W18 -> 0 | AD18: =N18 -> 0 | AE18: =O18+X18+Z18 -> 0 | AF18: =Q18 -> 0 | AG18: =R18+Y18+AA18 -> 0 | AH18: =AB18+AD18-AF18 -> 0 | AI18: =AC18+AE18-AG18 -> 0
A19: 4 | T19: =L19+N19-Q19 -> 0 | U19: =M19+O19-R19 -> 0 | AB19: =L19 -> 0 | AC19: =M19+V19+W19 -> 0 | AD19: =N19 -> 0 | AE19: =O19+X19+Z19 -> 0 | AF19: =Q19 -> 0 | AG19: =R19+Y19+AA19 -> 0 | AH19: =AB19+AD19-AF19 -> 0 | AI19: =AC19+AE19-AG19 -> 0
A20: 5 | T20: =L20+N20-Q20 -> 0 | U20: =M20+O20-R20 -> 0 | AB20: =L20 -> 0 | AC20: =M20+V20+W20 -> 0 | AD20: =N20 -> 0 | AE20: =O20+X20+Z20 -> 0 | AF20: =Q20 -> 0 | AG20: =R20+Y20+AA20 -> 0 | AH20: =AB20+AD20-AF20 -> 0 | AI20: =AC20+AE20-AG20 -> 0
A21: 6 | T21: =L21+N21-Q21 -> 0 | U21: =M21+O21-R21 -> 0 | AB21: =L21 -> 0 | AC21: =M21+V21+W21 -> 0 | AD21: =N21 -> 0 | AE21: =O21+X21+Z21 -> 0 | AF21: =Q21 -> 0 | AG21: =R21+Y21+AA21 -> 0 | AH21: =AB21+AD21-AF21 -> 0 | AI21: =AC21+AE21-AG21 -> 0
A22: 7 | T22: =L22+N22-Q22 -> 0 | U22: =M22+O22-R22 -> 0 | AB22: =L22 -> 0 | AC22: =M22+V22+W22 -> 0 | AD22: =N22 -> 0 | AE22: =O22+X22+Z22 -> 0 | AF22: =Q22 -> 0 | AG22: =R22+Y22+AA22 -> 0 | AH22: =AB22+AD22-AF22 -> 0 | AI22: =AC22+AE22-AG22 -> 0
A23: 8 | T23: =L23+N23-Q23 -> 0 | U23: =M23+O23-R23 -> 0 | AB23: =L23 -> 0 | AC23: =M23+V23+W23 -> 0 | AD23: =N23 -> 0 | AE23: =O23+X23+Z23 -> 0 | AF23: =Q23 -> 0 | AG23: =R23+Y23+AA23 -> 0 | AH23: =AB23+AD23-AF23 -> 0 | AI23: =AC23+AE23-AG23 -> 0
A24: 9 | T24: =L24+N24-Q24 -> 0 | U24: =M24+O24-R24 -> 0 | AB24: =L24 -> 0 | AC24: =M24+V24+W24 -> 0 | AD24: =N24 -> 0 | AE24: =O24+X24+Z24 -> 0 | AF24: =Q24 -> 0 | AG24: =R24+Y24+AA24 -> 0 | AH24: =AB24+AD24-AF24 -> 0 | AI24: =AC24+AE24-AG24 -> 0
A25: 10 | B25: …… | T25: =L25+N25-Q25 -> 0 | U25: =M25+O25-R25 -> 0 | AB25: =L25 -> 0 | AC25: =M25+V25+W25 -> 0 | AD25: =N25 -> 0 | AE25: =O25+X25+Z25 -> 0 | AF25: =Q25 -> 0 | AG25: =R25+Y25+AA25 -> 0 | AH25: =AB25+AD25-AF25 -> 0 | AI25: =AC25+AE25-AG25 -> 0
A26: 成本法小计 | G26: =SUM(G16:G25) -> 0 | H26: -- | I26: -- | J26: -- | K26: =SUM(K16:K25) -> 0 | L26: -- | M26: =SUM(M16:M25) -> 0 | N26: -- | O26: =SUM(O16:O25) -> 0 | P26: -- | Q26: -- | R26: =SUM(R16:R25) -> 0 | S26: -- | T26: -- | U26: =SUM(U16:U25) -> 0 | V26: =SUM(V16:V25) -> 0 | W26: =SUM(W16:W25) -> 0 | X26: =SUM(X16:X25) -> 0 | Y26: =SUM(Y16:Y25) -> 0 | Z26: =SUM(Z16:Z25) -> 0 | AA26: =SUM(AA16:AA25) -> 0 | AB26: -- | AC26: =SUM(AC16:AC25) -> 0 | AD26: -- | AE26: =SUM(AE16:AE25) -> 0 | AF26: -- | AG26: =SUM(AG16:AG25) -> 0 | AH26: -- | AI26: =SUM(AI16:AI25) -> 0
A27: （二）按权益法核算的长期股权投资 | V27: （二）按权益法核算的长期股权投资 | AN27: （二）按权益法核算的长期股权投资
A28: 序号 | B28: 被投资单位名称 | C28: 初始投资成本 | D28: 投资比例 | E28: 投资时间 | F28: 投资方式 | G28: 未审数 | V28: 期初调整 | X28: 账项调整 | AF28: 重分类调整 | AN28: 审定数
G29: 期初余额 | I29: 本期增加 | P29: 本期减少 | T29: 期末余额 | V29: 账项调整 | W29: 重分类调整 | X29: 本期增加 | AC29: 本期减少 | AF29: 本期增加 | AK29: 本期减少 | AN29: 期初余额 | AP29: 本期增加 | AW29: 本期减少 | BA29: 期末余额
G30: 投资比例 | H30: 金额 | I30: 投资比例 | J30: 投资成本增加 | K30: 权益增加 | O30: 其他 | P30: 投资比例 | Q30: 投资成本减少 | R30: 本期分回利润 | S30: 其他 | T30: 投资比例 | U30: 金额 | X30: 投资成本增加 | Y30: 权益增加 | AB30: 其他 | AC30: 投资成本减少 | AD30: 本期分回利润 | AE30: 其他 | AF30: 投资成本增加 | AG30: 权益增加 | AJ30: 其他 | AK30: 投资成本减少 | AL30: 本期分回利润 | AM30: 其他 | AN30: 投资比例 | AO30: 金额 | AP30: 投资比例 | AQ30: 投资成本增加 | AR30: 权益增加 | AV30: 其他 | AW30: 投资比例 | AX30: 投资成本减少 | AY30: 本期分回利润 | AZ30: 其他 | BA30: 投资比例 | BB30: 金额
K31: 损益调整 | L31: 其他综合收益 | M31: 其他权益变动 | N31: 权益增加小计 | Y31: 损益调整 | Z31: 其他综合收益 | AA31: 其他权益变动 | AG31: 损益调整 | AH31: 其他综合收益 | AI31: 其他权益变动 | AR31: 损益调整 | AS31: 其他综合收益 | AT31: 其他权益变动 | AU31: 权益增加小计
A32: 合营企业：
A33: 1 | N33: =SUM(K33:M33) -> 0 | T33: =G33+I33-P33 -> 0 | U33: =H33+J33+N33-Q33-R33+O33-S33 -> 0 | AN33: =G33 -> 0 | AO33: =H33+V33+W33 -> 0 | AP33: =I33 -> 0 | AQ33: =J33+X33+AF33 -> 0 | AR33: =K33+Y33+AG33 -> 0 | AS33: =L33+Z33+AH33 -> 0 | AT33: =M33+AA33+AI33 -> 0 | AU33: =SUM(AR33:AT33) -> 0 | AV33: =O33+AB33+AJ33 -> 0 | AW33: =P33 -> 0 | AX33: =Q33+AC33+AK33 -> 0 | AY33: =R33+AD33+AL33 -> 0 | AZ33: =S33+AE33+AM33 -> 0 | BA33: =AN33+AP33-AW33 -> 0 | BB33: =AO33+AQ33+AU33-AX33-AY33 -> 0
A34: 2 | N34: =SUM(K34:M34) -> 0 | T34: =G34+I34-P34 -> 0 | U34: =H34+J34+N34-Q34-R34+O34-S34 -> 0 | AN34: =G34 -> 0 | AO34: =H34+V34+W34 -> 0 | AP34: =I34 -> 0 | AQ34: =J34+X34+AF34 -> 0 | AR34: =K34+Y34+AG34 -> 0 | AS34: =L34+Z34+AH34 -> 0 | AT34: =M34+AA34+AI34 -> 0 | AU34: =SUM(AR34:AT34) -> 0 | AV34: =O34+AB34+AJ34 -> 0 | AW34: =P34 -> 0 | AX34: =Q34+AC34+AK34 -> 0 | AY34: =R34+AD34+AL34 -> 0 | AZ34: =S34+AE34+AM34 -> 0 | BA34: =AN34+AP34-AW34 -> 0 | BB34: =AO34+AQ34+AU34-AX34-AY34 -> 0
A35: 3 | N35: =SUM(K35:M35) -> 0 | T35: =G35+I35-P35 -> 0 | U35: =H35+J35+N35-Q35-R35+O35-S35 -> 0 | AN35: =G35 -> 0 | AO35: =H35+V35+W35 -> 0 | AP35: =I35 -> 0 | AQ35: =J35+X35+AF35 -> 0 | AR35: =K35+Y35+AG35 -> 0 | AS35: =L35+Z35+AH35 -> 0 | AT35: =M35+AA35+AI35 -> 0 | AU35: =SUM(AR35:AT35) -> 0 | AV35: =O35+AB35+AJ35 -> 0 | AW35: =P35 -> 0 | AX35: =Q35+AC35+AK35 -> 0 | AY35: =R35+AD35+AL35 -> 0 | AZ35: =S35+AE35+AM35 -> 0 | BA35: =AN35+AP35-AW35 -> 0 | BB35: =AO35+AQ35+AU35-AX35-AY35 -> 0
A36: 4 | N36: =SUM(K36:M36) -> 0 | T36: =G36+I36-P36 -> 0 | U36: =H36+J36+N36-Q36-R36+O36-S36 -> 0 | AN36: =G36 -> 0 | AO36: =H36+V36+W36 -> 0 | AP36: =I36 -> 0 | AQ36: =J36+X36+AF36 -> 0 | AR36: =K36+Y36+AG36 -> 0 | AS36: =L36+Z36+AH36 -> 0 | AT36: =M36+AA36+AI36 -> 0 | AU36: =SUM(AR36:AT36) -> 0 | AV36: =O36+AB36+AJ36 -> 0 | AW36: =P36 -> 0 | AX36: =Q36+AC36+AK36 -> 0 | AY36: =R36+AD36+AL36 -> 0 | AZ36: =S36+AE36+AM36 -> 0 | BA36: =AN36+AP36-AW36 -> 0 | BB36: =AO36+AQ36+AU36-AX36-AY36 -> 0
A37: 5 | B37: …… | N37: =SUM(K37:M37) -> 0 | T37: =G37+I37-P37 -> 0 | U37: =H37+J37+N37-Q37-R37+O37-S37 -> 0 | AN37: =G37 -> 0 | AO37: =H37+V37+W37 -> 0 | AP37: =I37 -> 0 | AQ37: =J37+X37+AF37 -> 0 | AR37: =K37+Y37+AG37 -> 0 | AS37: =L37+Z37+AH37 -> 0 | AT37: =M37+AA37+AI37 -> 0 | AU37: =SUM(AR37:AT37) -> 0 | AV37: =O37+AB37+AJ37 -> 0 | AW37: =P37 -> 0 | AX37: =Q37+AC37+AK37 -> 0 | AY37: =R37+AD37+AL37 -> 0 | AZ37: =S37+AE37+AM37 -> 0 | BA37: =AN37+AP37-AW37 -> 0 | BB37: =AO37+AQ37+AU37-AX37-AY37 -> 0
A38: 小计 | G38: -- | H38: =SUM(H33:H37) -> 0 | I38: -- | J38: =SUM(J33:J37) -> 0 | K38: =SUM(K33:K37) -> 0 | L38: =SUM(L33:L37) -> 0 | M38: =SUM(M33:M37) -> 0 | N38: =SUM(K38:M38) -> 0 | O38: =SUM(O33:O37) -> 0 | P38: =SUM(P33:P37) -> 0 | Q38: =SUM(Q33:Q37) -> 0 | R38: =SUM(R33:R37) -> 0 | T38: -- | U38: =SUM(U33:U37) -> 0 | V38: =SUM(V33:V37) -> 0 | W38: =SUM(W33:W37) -> 0 | X38: =SUM(X33:X37) -> 0 | Y38: =SUM(Y33:Y37) -> 0 | Z38: =SUM(Z33:Z37) -> 0 | AA38: =SUM(AA33:AA37) -> 0 | AB38: =SUM(AB33:AB37) -> 0 | ... AM38: =SUM(AM33:AM37) -> 0 | AN38: -- | AO38: =SUM(AO33:AO37) -> 0 | AP38: -- | AQ38: =SUM(AQ33:AQ37) -> 0 | AR38: =SUM(AR33:AR37) -> 0 | AS38: =SUM(AS33:AS37) -> 0 | AT38: =SUM(AT33:AT37) -> 0 | AU38: =SUM(AU33:AU37) -> 0 | AV38: =SUM(AV33:AV37) -> 0 | AW38: -- | AX38: =SUM(AX33:AX37) -> 0 | AY38: =SUM(AY33:AY37) -> 0 | AZ38: =SUM(AZ33:AZ37) -> 0 | BA38: -- | BB38: =SUM(BB33:BB37) -> 0
A39: 联营企业：
A40: 1 | N40: =SUM(K40:M40) -> 0 | T40: =G40+I40-P40 -> 0 | U40: =H40+J40+N40-Q40-R40+O40-S40 -> 0 | AN40: =G40 -> 0 | AO40: =H40+V40+W40 -> 0 | AP40: =I40 -> 0 | AQ40: =J40+X40+AF40 -> 0 | AR40: =K40+Y40+AG40 -> 0 | AS40: =L40+Z40+AH40 -> 0 | AT40: =M40+AA40+AI40 -> 0 | AU40: =SUM(AR40:AT40) -> 0 | AV40: =O40+AB40+AJ40 -> 0 | AW40: =P40 -> 0 | AX40: =Q40+AC40+AK40 -> 0 | AY40: =R40+AD40+AL40 -> 0 | AZ40: =S40+AE40+AM40 -> 0 | BA40: =AN40+AP40-AW40 -> 0 | BB40: =AO40+AQ40+AU40-AX40-AY40 -> 0
...

Sheet 调整分录汇总G7-3
A1: 致同会计师事务所
A2: 长期股权投资调整分录汇总表
A3: =底稿目录!A2 -> 被审计单位： | D3: =底稿目录!A4 -> 编制人： | G3: =底稿目录!A5 -> 编制日期： | I3: 索引号： | J3: =底稿目录!F9 -> G7-3
A4: =底稿目录!A3 -> 截止日：202X年12月31日 | D4: =底稿目录!A6 -> 复核人： | G4: =底稿目录!A7 -> 复核日期： | I4: 页 次：
A5: 调整事项说明 | B5: 类别（报表调整/账项调整/其他） | C5: 报表项目 | D5: 科目名称 | E5: 附注项目 | F5: …… | G5: 借方调整金额 | H5: 贷方调整金额 | I5: 索引 | J5: 备注

Sheet 被投资单位基本信息G7-4
A1: 致同会计师事务所
A2: 被投资单位基本信息
A3: =底稿目录!A2 -> 被审计单位： | F3: =底稿目录!A4 -> 编制人： | M3: =底稿目录!A5 -> 编制日期： | S3: 索引号： | T3: =底稿目录!F10 -> G7-4
A4: =底稿目录!A3 -> 截止日：202X年12月31日 | F4: =底稿目录!A6 -> 复核人： | M4: =底稿目录!A7 -> 复核日期： | S4: 页 次：
A5: 一、审计目标： | C5: 了解被审计单位投资公司的基本情况
A6: 二、审计过程 | C6: 1、取得被审计单位投资单位备查明细簿，了解投资单位的基本情况；
C7: 2、结合以前年度审计情况，了解被审计单位对各投资单位的核算方法。
C8: 3、结合“子公司初始计量测试”底稿，了解表决权比例不足半数但能对被投资单位形成控制的原因及直接或通过其他子公司间接拥有被投资单位半数以上的表决权但未能对其形成控制的原因
A9: 公司名称 | C9: 级次（国企适用） | D9: 企业类型（国企适用） | E9: 是否为本期新纳入合并范围的子公司（国企适用） | F9: 主要经营地 | G9: 注册地 | H9: 业务性质 | I9: 注册资本 | J9: 投资额 | K9: 期末净资产 | L9: 本期净利润 | M9: 持股比例/享有的份额% | O9: 表决权比例 | P9: 持股比例与表决权比例不一致的原因 | Q9: 表决权比例不足半数但能对被投资单位形成控制的原因 | R9: 直接或通过其他子公司间接拥有被投资单位半数以上的表决权但未能对其形成控制的原因 | S9: 取得方式 | T9: 会计处理方法
M10: 直接 | N10: 间接
A11: （一）子公司
B12: ='明细表G7-2'!B16 -> 0 | T12: 成本法
B13: ='明细表G7-2'!B17 -> 0
B14: ='明细表G7-2'!B18 -> 0
B15: ='明细表G7-2'!B19 -> 0
B16: ='明细表G7-2'!B20 -> 0
B17: ='明细表G7-2'!B21 -> 0
B18: ='明细表G7-2'!B22 -> 0
B19: ='明细表G7-2'!B23 -> 0
B20: ='明细表G7-2'!B24 -> 0
B21: ='明细表G7-2'!B25 -> ……
A22: （二）合营企业（共同控制）
B23: ='明细表G7-2'!B33 -> 0 | C23: -- | D23: -- | Q23: -- | T23: 权益法
B24: ='明细表G7-2'!B34 -> 0 | C24: -- | D24: -- | Q24: --
B25: ='明细表G7-2'!B35 -> 0 | C25: -- | D25: -- | Q25: --
B26: ='明细表G7-2'!B36 -> 0 | C26: -- | D26: -- | Q26: --
B27: ='明细表G7-2'!B37 -> …… | C27: -- | D27: -- | Q27: --
A28: （三）联营企业（重大影响）
B29: ='明细表G7-2'!B40 -> 0 | C29: -- | D29: -- | Q29: -- | T29: 权益法
B30: ='明细表G7-2'!B41 -> 0 | C30: -- | D30: -- | Q30: --
B31: ='明细表G7-2'!B42 -> 0 | C31: -- | D31: -- | Q31: --
B32: ='明细表G7-2'!B43 -> 0 | C32: -- | D32: -- | Q32: --
B33: ='明细表G7-2'!B44 -> …… | C33: -- | D33: -- | Q33: --
A34: （四）共同经营（共同控制）
C35: -- | D35: -- | O35: -- | P35: -- | T35: 各项单独确认
C36: -- | D36: -- | O36: -- | P36: --
C37: -- | D37: -- | O37: -- | P37: --
C38: -- | D38: -- | O38: -- | P38: --
A39: （注：企业类型：1.境内非金融子企业，2.境内金融子企业，3.境外子企业，4.事业单位，5.基建单位；
A40: 三、审计说明：
...

Sheet 被投资单位财务信息（合营、联营）G7-5
B1: 致同会计师事务所
B2: 被投资单位主要财务信息（合营、联营）
A3: =底稿目录!A2 -> 被审计单位： | D3: =底稿目录!A4 -> 编制人： | F3: =底稿目录!A5 -> 编制日期： | I3: 索引号： | J3: =底稿目录!F11 -> G7-5
A4: =底稿目录!A3 -> 截止日：202X年12月31日 | D4: =底稿目录!A6 -> 复核人： | F4: =底稿目录!A7 -> 复核日期： | I4: 页 次：
A5: 一、审计目标： | C5: 了解被审计单位合营、联营企业主要财务信息
A6: 二、审计过程 | C6: 取得被审计单位联营、合营企业已审计/审阅的财务报表；确定被投资单位联营、合营企业的主要财务信息
A7: 1.1重要合营、联营企业
B8: 项目 | C8: 合营企业1 | E8: 合营企业2 | G8: 联营企业1 | I8: 联营企业2
C9: 本期数 | D9: 上期数 | E9: 本期数 | F9: 上期数 | G9: 本期数 | H9: 上期数 | I9: 本期数 | J9: 上期数
B10: 流动资产
B11: 其中：现金和现金等价物
B12: 非流动资产
B13: 资产合计 | C13: =C10+C12 -> 0 | D13: =D10+D12 -> 0 | E13: =E10+E12 -> 0 | F13: =F10+F12 -> 0 | G13: =G10+G12 -> 0 | H13: =H10+H12 -> 0 | I13: =I10+I12 -> 0 | J13: =J10+J12 -> 0
B14: 流动负债
B15: 非流动负债
B16: 负债合计 | C16: =C14+C15 -> 0 | D16: =D14+D15 -> 0 | E16: =E14+E15 -> 0 | F16: =F14+F15 -> 0 | G16: =G14+G15 -> 0 | H16: =H14+H15 -> 0 | I16: =I14+I15 -> 0 | J16: =J14+J15 -> 0
B17: 净资产
B18: 其中：少数股东权益
B19: 归属于母公司的所有者权益
B20: 持股比例%
B21: 按持股比例计算的净资产份额 | C21: =C17*C20 -> 0 | D21: =D17*D20 -> 0 | E21: =E17*E20 -> 0 | F21: =F17*F20 -> 0 | G21: =G17*G20 -> 0 | H21: =H17*H20 -> 0 | I21: =I17*I20 -> 0 | J21: =J17*J20 -> 0
B22: 调整事项 | C22: =SUM(C23:C26) -> 0 | D22: =SUM(D23:D26) -> 0 | E22: =SUM(E23:E26) -> 0 | F22: =SUM(F23:F26) -> 0 | G22: =SUM(G23:G26) -> 0 | H22: =SUM(H23:H26) -> 0 | I22: =SUM(I23:I26) -> 0 | J22: =SUM(J23:J26) -> 0
B23: 其中：商誉
B24: 未实现内部交易损益
B25: 减值准备
B26: 其他
B27: 对合营/联营企业权益投资的账面价值 | C27: =C21-C22 -> 0 | D27: =D21-D22 -> 0 | E27: =E21-E22 -> 0 | F27: =F21-F22 -> 0 | G27: =G21-G22 -> 0 | H27: =H21-H22 -> 0 | I27: =I21-I22 -> 0 | J27: =J21-J22 -> 0
B28: 存在公开报价的权益投资的公允价值
B29: 营业收入
B30: 财务费用
B31: 所得税费用
B32: 净利润
B33: 终止经营的净利润
B34: 其他综合收益
B35: 综合收益总额 | C35: =C32+C34 -> 0 | D35: =D32+D34 -> 0 | E35: =E32+E34 -> 0 | F35: =F32+F34 -> 0 | G35: =G32+G34 -> 0 | H35: =H32+H34 -> 0 | I35: =I32+I34 -> 0 | J35: =J32+J34 -> 0
B36: 企业本期收到的来自合营/联营企业的股利
B37: 前期累积未确认的损失份额
B38: 本期未确认的损失份额（或本期实现净利润的分享额）
B39: 本期末累积未确认的损失份额 | C39: =C37+C38 -> 0 | D39: =D37+D38 -> 0 | E39: =E37+E38 -> 0 | F39: =F37+F38 -> 0 | G39: =G37+G38 -> 0 | H39: =H37+H38 -> 0 | I39: =I37+I38 -> 0 | J39: =J37+J38 -> 0
A40: 1.2其他合营企业
...

Sheet 被投资公司会计政策G7-6
A1: 致同会计师事务所
A2: 被投资单位会计政策
A3: =底稿目录!A2 -> 被审计单位： | C3: =底稿目录!A4 -> 编制人： | D3: =底稿目录!A5 -> 编制日期： | E3: 索引号： | F3: =底稿目录!F12 -> G7-6
A4: =底稿目录!A3 -> 截止日：202X年12月31日 | C4: =底稿目录!A6 -> 复核人： | D4: =底稿目录!A7 -> 复核日期： | E4: 页 次：
A5: 一、审计目标： | C5: 被投资公司会计政策与母公司主要会计政策比较，对主要会计政策差异在合并时进行调整
A6: 二、审计过程 | C6: 1、取得被投资单位会计政策，与被审计单位会计政策进行比对；
C7: 2、确定被投资单位是否需要为符合投资单位的会计政策而作出的任何必要的会计政策调整。
B8: 政策项目 | C8: AAA公司 | F8: 与本公司政策是否一致
B9: 会计年度 | C9: 1月1日-12月31日 | F9: 是
B10: 计量属性 | C10: 除公允价值套期工具外，按照历史价格计价 | F10: 是
B11: 记账本位币 | C11: 人民币 | F11: 是
B12: 外币折算 | C12: 交易发生日即期汇率折算 | F12: 是
B13: 现金及现金等价物 | C13: 随时可用于支付的流动性强、价值变动很小的投资
B14: 存货 | C14: 取得时实际成本入账、月末一次加权平均和移动加权平均法、成本与可变现净值孰低，永续盘存。 | F14: 是
B15: 长期股权投资 | F15: 是
B16: 固定资产 | C16: 使用周期超过一个会计年度的有形资产。 | F16: 是
B17: 累计折旧 | C17: 平均年限法 | F17: 是
B18: 在建工程 | C18: 达到预定可使用状态时转入固定资产，在建工程不计提折旧 | F18: 是
B19: 无形资产 | C19: 以成本减累计折旧于报表列示，直线法在预计可使用期限内摊销，土地使用权摊销按照土地证上年限摊销，无使用期限不固定的无形资产。 | F19: 是
B20: 职工薪酬 | C20: 除辞退福利外，其他计入当期负债及成本费用 | F20: 是
B21: 收入 | C21: 权责发生制 | F21: 是
B22: ……
A23: 三、审计说明
A24: 1 | B24: 主要会计政策基本相同。
B25: AAA公司为07年11月成立，其成立时被审计单位即持股30%。其主要资产为自行购建，且主要为自用，公允价值与其账面价值一致。
A29: 四、审计结论
B30: 经审计，未发现重大异常。

Sheet 长期股权投资初始判断G7-7
A1: 致同会计师事务所
A2: 长期股权投资初始判断
A3: =底稿目录!A2 -> 被审计单位： | D3: =底稿目录!A4 -> 编制人： | E3: =底稿目录!A5 -> 编制日期： | G3: 索引号： | H3: =底稿目录!F13 -> G7-7
A4: =底稿目录!A3 -> 截止日：202X年12月31日 | D4: =底稿目录!A6 -> 复核人： | E4: =底稿目录!A7 -> 复核日期： | G4: 页 次：
A5: 一、审计目标： | C5: 确定被审计单位对子公司长期股权投资初始计量是否恰当
A6: 二、审计过程：
A7: 1、是否控制的判断及结论
A8: 判断的事项 | D8: 公司1 | F8: 公司2
D9: 对应情形 | E9: 结论 | F9: 对应情形 | G9: 结论
A10: 被投资者的目标及设计
A11: 是否控制
A12: （1）权力
A13: （2）面临可变回报的风险
A14: （3）使用权力影响可变回报的能力
A15: 结 论
A16: 2、联营企业与合营企业的判断
A17: 合营判断（共同控制）： | D17: 说明 | E17: 联营判断（重大影响）： | H17: 说明 | I17: 审计证据
A18: （l）任何一个合营方均不能单独控制合营企业的相关活动 | E18: （1）在被投资单位的董事会或类似权力机构中派有代表
A19: （2）涉及合营企业的相关活动的决策需要各合营方一致同意 | E19: （2）参与被投资单位的政策制定过程,包括股利分配政策等的制定
A20: （3）各合营方可能通过合同或协议的形式任命其中的一个合营方对合营企业的日常活动进行管理,但其必须在各合营方已经一致同意的相关活动范围内行使管理权。 | E20: （3）与被投资单位之间发生重要交易
E21: （4）向被投资单位派出管理人员
A22: （4）其他 | E22: （5）向被投资单位提供关键技术资料
E23: （6）其他
A24: 3、确认合并（购买）日：
A25: 确认依据： | D25: 公司1 | E25: 公司2 | F25: 公司3
A26: （1）企业合并合同或协议已获股东大会等内部权力机构通过。
A27: （2）合并事项需要经过国家有关主管部门审批的，已获得相关部门的批准
A28: （3）参与合并各方已办理了必要的财产权交接手续。
A29: （4）购买方已支付了购买价款的大部分（一般应超过50％），并且有能力、有计划支付剩余款项。
A30: （5）购买方实际上已经控制了被购买方的财务和经营政策，享有相应的收益并承担相应的风险。
A31: 最终确定的合并（购买）日 | D31: 年 月 日 | E31: 年 月 日 | F31: 年 月 日
A32: 审计证据索引号
A33: 三、审计说明
A37: 四、审计结论
A40: 提示：
A41: 3、合并方式取得的长期股权投资初始投资成本：
A42: A、上述计算前提是合并前合并方与被合并方采用的会计政策应当一致。如企业合并前合并方与被合并方采用的会计政策不同的，应基于重要性原则，统一合并方与被合并方的会计政策。在按照合并方的会计政策对被合并方资产、负债的账面价值进行调整的基础上，计算确定形成长期股权投资的初始投资成本。
A43: B、在编制合并资产负债表时，对于被合并方在企业合并前实现的留存收益（盈余公积和未分配利润之和）中归属于合并方的部分，应按以下原则，自合并方的资本公积转入留存收益和未分配利润：
A44: ①确认企业合并形成的长期股权投资后，合并方账面资本公积（资本溢价或股本溢价）贷方余额大于被合并方在合并前实现的留存收益中归属于合并方的部分，在合并资产负债表中，应将被合并方在合并前实现的留存收益中归属于合并方的部分自“资本公积”转入“盈余公积”和“未分配利润”。在合并工作底稿中，借记“资本公积”项目，贷记“盈余公积”和“未分配利润”项目。 ②确认企业合并形成的长期股权投资后，合并方面资本公积（资本溢价或股本溢价）贷方余额小于被合并方在合并前实现的留存收益中归属于合并方的部分的，在合并资产负债表中，应以合并方资本公积(资本溢价或股本溢价)的贷方余额为限，将被合并方在企业合并前实现的留存收益中归属于合并方的部分自“资本公积”转入“盈余公积”和“未分配利润”。在合并工作底稿中，借记“资本公积”项目，贷记“盈余公积”和“未分配利润”项目。 因合并方的资本公积（资本溢价或股本溢价）余额不足，被合并方在合并前实现的留存收益中归属于合并方的部分在合并资产负债表中未予全额恢复的，合并方应当在会计报表附注中对这一情况进行说明。
A45: C、如果分步取得对子公司股权投资直至取得控制权的各项交易属于“一揽子交易”，应当将各项交易作为一项取得子公司控制权的交易。
...

Sheet 子公司初始计量测试（同控）G7-8
A1: 致同会计师事务所
A2: 子公司初始计量测试表
A3: =底稿目录!A2 -> 被审计单位： | D3: =底稿目录!A4 -> 编制人： | F3: =底稿目录!A5 -> 编制日期： | H3: 索引号： | I3: =底稿目录!F14 -> G7-8
A4: =底稿目录!A3 -> 截止日：202X年12月31日 | D4: =底稿目录!A6 -> 复核人： | F4: =底稿目录!A7 -> 复核日期： | H4: 页 次：
A5: 一、审计目标： | C5: 确定被审计单位对子公司长期股权投资初始计量是否恰当
A6: 二、审计过程：
A7: 1、合并方式取得的长期股权投资初始投资成本：
A8: 审核项目 | D8: 公司1 | E8: 索引 | F8: 公司2 | G8: 索引 | H8: 公司3 | I8: 索引
A9: 最终控制方
A10: 被合并方所有者权益账面价值（如果被合并方存在合并财务报表，则取合并报表数据）① | D10: 100
A11: 合并方合并后占被投资单位的出资比例② | D11: 0.32
A12: 长期股权投资初始投资成本：③=①*② | D12: =D10*D11 -> 32 | F12: =F10*F11 -> 0 | H12: =H10*H11 -> 0
A13: 购买方付出的资产，发生或承担的负债、发行的权益性证券的账面价值之和④ | D13: =SUM(D14:D18) -> 10 | F13: =SUM(F14:F18) -> 0 | H13: =SUM(H14:H18) -> 0
A14: 其中：现金 | D14: 2
A15: 非现金资产的账面价值 | D15: 2
A16: 发行或承担的债务的账面价值 | D16: 3
A17: 发行的权益性证券的面值
A18: 或有对价 | D18: 3
A19: 母公司报表中调整资本公积、留存收益⑤=③-④ | D19: =D12-D13 -> 22 | F19: =F12-F13 -> 0 | H19: =H12-H13 -> 0
A21: 2、通过多次交易分步实现的同一控制下企业合并（不构成一揽子交易）：
A22: 项目 | D22: P公司 | G22: Q公司
A23: 次别 | D23: 1 | E23: 2 | F23: 小计 | G23: 4 | H23: 5 | I23: 小计
A24: 交易日期 | D24: 1 | E24: 1 | F24: -- | I24: --
A25: 购买比例① | D25: 0.01 | E25: 0.02 | F25: =SUM(D25:E25) -> 0.03 | I25: =SUM(G25:H25) -> 0
A26: 支付对价② | D26: 1 | E26: 3 | F26: =SUM(D26:E26) -> 4 | I26: =SUM(G26:H26) -> 0
A27: 每笔交易发生时被投资方可辨认净资产的账面价值 | D27: 22 | E27: 44 | F27: -- | I27: --
A28: 因权益法核算确认的长期股权投资其他综合收益、损益调整和其他变动或其他投资确认的计入其他综合收益的公允价值调整③ | D28: 22 | E28: 4 | F28: =SUM(D28:E28) -> 26 | I28: =SUM(G28:H28) -> 0
A29: 公司名称 | C29: 合并日被投资方可辨认净资产的账面价值④ | D29: 合并日长期股权投资投资成本：⑤=④*① | E29: 母公司报表中调整资本公积、留存收益⑥=②+③-⑤ | F29: 索引/备注
A30: P公司 | C30: =E27 -> 44 | D30: =C30*F25 -> 1.32 | E30: =F26+F28-D30 -> 28.68
A31: Q公司 | C31: =H27 -> 0 | D31: =C31*I25 -> 0 | E31: =I26+I28-D31 -> 0
A33: 3、反向购买
A34: 交易内容 | C34: 会计上的购买方 | D34: 会计上的购买方的股东 | E34: 会计上的被购买方（上市公司） | F34: 会计上的被购买方的原股东（上市公司原股东） | G34: 判断构成反向购买的依据 | H34: 是否构成业务及其判断依据 | I34: 索引号
A38: 三、审计说明
A42: 四、审计结论
A45: 提示：
A46: 3、合并方式取得的长期股权投资初始投资成本：
A47: A、上述计算前提是合并前合并方与被合并方采用的会计政策应当一致。如企业合并前合并方与被合并方采用的会计政策不同的，应基于重要性原则，统一合并方与被合并方的会计政策。在按照合并方的会计政策对被合并方资产、负债的账面价值进行调整的基础上，计算确定形成长期股权投资的初始投资成本。
A48: B、在编制合并资产负债表时，对于被合并方在企业合并前实现的留存收益（盈余公积和未分配利润之和）中归属于合并方的部分，应按以下原则，自合并方的资本公积转入留存收益和未分配利润：
A49: ①确认企业合并形成的长期股权投资后，合并方账面资本公积（资本溢价或股本溢价）贷方余额大于被合并方在合并前实现的留存收益中归属于合并方的部分，在合并资产负债表中，应将被合并方在合并前实现的留存收益中归属于合并方的部分自“资本公积”转入“盈余公积”和“未分配利润”。在合并工作底稿中，借记“资本公积”项目，贷记“盈余公积”和“未分配利润”项目。 ②确认企业合并形成的长期股权投资后，合并方面资本公积（资本溢价或股本溢价）贷方余额小于被合并方在合并前实现的留存收益中归属于合并方的部分的，在合并资产负债表中，应以合并方资本公积(资本溢价或股本溢价)的贷方余额为限，将被合并方在企业合并前实现的留存收益中归属于合并方的部分自“资本公积”转入“盈余公积”和“未分配利润”。在合并工作底稿中，借记“资本公积”项目，贷记“盈余公积”和“未分配利润”项目。 因合并方的资本公积（资本溢价或股本溢价）余额不足，被合并方在合并前实现的留存收益中归属于合并方的部分在合并资产负债表中未予全额恢复的，合并方应当在会计报表附注中对这一情况进行说明。
A50: C、如果分步取得对子公司股权投资直至取得控制权的各项交易属于“一揽子交易”，应当将各项交易作为一项取得子公司控制权的交易。
...

Sheet 子公司初始计量测试（非同控）G7-9
A1: 致同会计师事务所
A2: 子公司初始计量测试表
A3: =底稿目录!A2 -> 被审计单位： | D3: =底稿目录!A4 -> 编制人： | F3: =底稿目录!A5 -> 编制日期： | H3: 索引号： | I3: =底稿目录!F15 -> G7-9
A4: =底稿目录!A3 -> 截止日：202X年12月31日 | D4: =底稿目录!A6 -> 复核人： | F4: =底稿目录!A7 -> 复核日期： | H4: 页 次：
A5: 一、审计目标： | C5: 确定被审计单位对子公司长期股权投资初始计量是否恰当
A6: 二、审计过程：
A7: 1、合并方式取得的长期股权投资初始投资成本：
A8: 审核项目 | D8: A公司 | E8: 索引 | F8: B公司 | G8: 索引 | H8: C公司 | I8: 索引
A9: 被合并方所有者权益账面价值
A10: 被购买方可辨认净资产的公允价值①
A11: 合并后占被投资单位的出资比例②
A12: 购买方付出的资产，发生或承担的负债、发行的权益性证券的公允价值之和③ | D12: =SUM(D13:D17) -> 0 | F12: =SUM(F13:F17) -> 0 | H12: =SUM(H13:H17) -> 0
A13: 其中：现金
A14: 非现金资产的公允价值
A15: 发行或承担的债务的公允价值
A16: 发行的权益性证券的公允价值
A17: 或有对价的公允价值
A18: 购买日之前持有的股权于购买日的公允价值④
A19: 购买方付出的资产，发生或承担的负债、发行的权益性证券的账面价值之和⑤
A20: 投资方初始投资成本：⑥=③+④ | D20: =D12+D18 -> 0 | F20: =F12+F18 -> 0 | H20: =H12+H18 -> 0
A21: 记入当期损益（营业外收入）⑦=③-⑤ | D21: =D12-D19 -> 0 | F21: =F12-F19 -> 0 | H21: =H12-H19 -> 0
A22: 合并报表中的商誉或损益（或吸收合并时计入母公司报表中的商誉或损益）⑧=⑥-①*② | D22: =D20-D10*D11 -> 0 | F22: =F20-F10*F11 -> 0 | H22: =H20-H10*H11 -> 0
A24: 2、通过多次交易分步实现的非同一控制下企业合并（不构成一揽子交易）
A25: 项目 | D25: M公司 | G25: N公司
A26: 次别 | D26: 1 | E26: 2 | F26: 小计 | G26: 1 | H26: 2 | I26: 小计
A27: 交易日期 | F27: -- | I27: --
A28: 购买比例① | F28: =SUM(D28:E28) -> 0 | I28: =SUM(G28:H28) -> 0
A29: 支付对价② | F29: =SUM(D29:E29) -> 0 | I29: =SUM(G29:H29) -> 0
A30: 每笔交易发生时被投资方可辨认净资产的公允价值③ | F30: -- | I30: --
A31: 每单交易应享有的被投资方可辨认净资产的公允价值的份额 ④=①*③ | D31: =D28*D30 -> 0 | E31: =E28*E30 -> 0 | F31: =SUM(D31:E31) -> 0 | G31: =G28*G30 -> 0 | H31: =H28*H30 -> 0 | I31: =SUM(G31:H31) -> 0
A32: 每单交易应确认的商誉或损益⑤=②-④ | D32: =D29-D31 -> 0 | E32: =E29-E31 -> 0 | F32: =SUM(D32:E32) -> 0 | G32: =G29-G31 -> 0 | H32: =H29-H31 -> 0 | I32: =SUM(G32:H32) -> 0
A33: 因权益法核算确认的长期股权投资其他综合收益、损益调整和其他变动或其他投资确认的计入其他综合收益的公允价值调整⑥ | F33: =SUM(D33:E33) -> 0 | I33: =SUM(G33:H33) -> 0
A34: 合并日母公司长期股权投资的确认金额⑦=②+⑥ | D34: -- | E34: -- | F34: =F29+F33 -> 0 | G34: -- | H34: -- | I34: =I29+I33 -> 0
A36: 3、反向购买
A37: 交易内容 | C37: 会计上的购买方 | D37: 会计上的购买方的股东 | E37: 会计上的被购买方（上市公司） | F37: 会计上的被购买方的原股东（上市公司原股东） | G37: 判断构成反向购买的依据 | H37: 是否构成业务及其判断依据 | I37: 索引号
A41: 三、审计说明
A44: 四、审计结论
A47: 提示：
A48: 3、合并方式取得的长期股权投资初始投资成本：
A49: A、购买方为企业合并发生的审计、法律服务、评估咨询等中介费用以及其他相关管理费用，应当于发生时计入当期损益；购买方作为合并对价发行的权益性证券或债务性证券的交易费用，应当计入权益性证券或债务性证券的初始确认金额。
...

Sheet 子公司后续计量测试表G7-10
A1: 致同会计师事务所
A2: 子公司后续计量测试表
A3: =底稿目录!A2 -> 被审计单位： | D3: =底稿目录!A4 -> 编制人： | F3: =底稿目录!A5 -> 编制日期： | H3: 索引号： | I3: =底稿目录!F16 -> G7-10
A4: =底稿目录!A3 -> 截止日：202X年12月31日 | D4: =底稿目录!A6 -> 复核人： | F4: =底稿目录!A7 -> 复核日期： | H4: 页 次：
A5: 一、审计目标： | C5: 确定子公司长期股权投资及其相关账户后续计量是否正确。
A6: 二、审计过程：
A7: 1、被投资单位分配股利测算
A8: 公司名称 | B8: 分配方案、股东/董事会决议 | C8: 持股比例 | D8: 宣告分派股利日 | E8: 主要股利分配政策 | F8: 宣告分派的股利金额 | G8: 被审计单位应分配股利 | H8: 实际入账股利 | I8: 差异
G9: =C9*F9 -> 0 | I9: =G9-H9 -> 0
G10: =C10*F10 -> 0 | I10: =G10-H10 -> 0
G11: =C11*F11 -> 0 | I11: =G11-H11 -> 0
G12: =C12*F12 -> 0 | I12: =G12-H12 -> 0
G13: =C13*F13 -> 0 | I13: =G13-H13 -> 0
A14: 2、购买少数股东股权的处理
A15: 项 目 | C15: 公司1 | D15: 公司2 | E15: 项 目 | G15: 公司1 | H15: 公司2
A16: 新增日长期股权投资账面价值 | E16: 子公司自购买日(或合并日)开始持续计算的可辨认净资产的公允价值③
A17: 原持股比例 | E17: 按新增持股比例计算应享有子公司自购买日(或合并日)开始持续计算的可辨认净资产的公允价值的份额 ④=③*① | G17: =G16*C18 -> 0 | H17: =H16*D18 -> 0
A18: 新增的持股比例① | E18: 调整合并报表中的资本公积/留存收益⑤=④-② | G18: =G17-C19 -> 0 | H18: =H17-D19 -> 0
A19: 购买成本② | C19: =SUM(C20:C24) -> 0 | D19: =SUM(D20:D24) -> 0 | E19: 其中：调整资本公积
A20: 其中：现金 | E20: 调整盈余公积
A21: 非现金资产的公允价值 | E21: 调整未分配利润
A22: 发行或承担的债务的账面价值 | E22: 索引号
A23: 发行的权益性证券的面值
A24: 或有对价
A25: 购买少数股权后长期股权投资账面价值 | C25: =C16+C19 -> 0 | D25: =D16+D19 -> 0
A27: 3、处置子公司权益但不丧失控制权
A28: 项 目 | C28: 公司1 | D28: 公司2 | E28: 项 目 | G28: 公司1 | H28: 公司2
A29: 处置日长期股权投资账面价值① | E29: 子公司自购买日(或合并日)开始持续计算的可辨认净资产的公允价值⑥
A30: 原持股比例② | E30: 按减少的持股比例计算应享有子公司自购买日(或合并日)开始持续计算的可辨认净资产的公允价值的份额⑦=⑥*③ | G30: =H29*C31 -> 0 | H30: =I29*D31 -> 0
A31: 减少的持股比例③ | E31: 调整合并报表中的资本公积/留存收益 ⑧=⑦-④ | G31: =G30-C32 -> 0 | H31: =H30-D32 -> 0
A32: 处置对价④ | C32: =SUM(C33:C37) -> 0 | D32: =SUM(D33:D37) -> 0 | E32: 其中：调整资本公积
A33: 其中：现金 | E33: 调整盈余公积
A34: 非现金资产的公允价值 | E34: 调整未分配利润
A35: 发行或承担的债务的账面价值 | E35: 索引号
A36: 发行的权益性证券的面值
A37: 或有对价
A38: 计入个别报表的投资收益 ⑤=④-③/②*① | C38: =IF(C30=0,0,C32-C31/C30*C29) -> 0 | D38: =IF(D30=0,0,D32-D31/D30*D29) -> 0
A39: 三、审计说明
A42: 四、审计结论
A45: 提示：
...

Sheet 处置子公司测试表（不包含一揽子交易）G7-11
A1: 致同会计师事务所
A2: 处置子公司测试表（不包含一揽子交易）
A3: =底稿目录!A2 -> 被审计单位： | E3: =底稿目录!A4 -> 编制人： | I3: =底稿目录!A5 -> 编制日期： | K3: 索引号： | L3: =底稿目录!F17 -> G7-11
A4: =底稿目录!A3 -> 截止日：202X年12月31日 | E4: =底稿目录!A6 -> 复核人： | I4: =底稿目录!A7 -> 复核日期： | K4: 页 次：
A5: 一、审计目标： | C5: 确定处置子公司的会计处理是否恰当。
A6: 二、审计过程：
A7: 1.本期处置的子公司基本情况
B8: 企业名称 | C8: 注册地 | D8: 业务性质 | E8: 持股比例% | F8: 表决权比例% | G8: 本期不再成为子公司的原因
B14: 子公司名称 | C14: 股权处置价款 | D14: 原股权比例% | E14: 股权处置比例% | F14: 剩余股权比例% | G14: 剩余股权构成 | H14: 股权处置方式 | I14: 丧失控制权的时点 | J14: 丧失控制权时点的确定依据 | K14: 取得的查验资料 | L14: 索引号
F15: =D15-E15 -> 0 | K15: 股权转让协议、产权交割单、…
F16: =D16-E16 -> 0
F17: =D17-E17 -> 0
F18: =D18-E18 -> 0
A19: 2.1 单体报表
B20: 子公司名称 | C20: 处置日长期股权投资账面价值 | D20: 应转出的长投 | E20: 丧失控制权之日剩余股权的账面价值 | F20: 丧失控制权之日剩余股权的公允价值 | G20: 按公允价值重新计量产生的利得/损失 | H20: 原子公司投资系联营/合营投资追加投资形成，与原联营/合营投资有关的可重分类至损益的OCI和其他净资产变动 | I20: 原子公司投资系金融资产投资追加投资形成，与原金融资产相关的按照公允价值计量的OCI | J20: 原子公司投资系联营/合营投资追加投资形成，与原联营/合营投资有关不可重分类至损益的OCI | K20: 处置子公司应确认的投资收益 | L20: 应转入权益
B21: =B15 -> 0 | D21: =IF(D15=0,0,C21*E15/D15) -> 0 | E21: =C21-D21 -> 0 | G21: =F21-E21 -> 0 | K21: =IF(D15=0,0,IF(G15="联营",G21+H21*E15/D15,IF(G15="合营",G21+H21*E15/D15,G21+I21))) -> 0 | L21: =IF(D15=0,0,IF(G15="联营",J21*E15/D15,IF(G15="合营",J21*E15/D15,J21))) -> 0
B22: =B16 -> 0 | D22: =C22*E16 -> 0 | E22: =C22-D22 -> 0 | G22: =F22-E22 -> 0 | K22: =IF(D16=0,0,IF(G16="联营",G22+H22*E16/D16,IF(G16="合营",G22+H22*E16/D16,G22+I22))) -> 0 | L22: =IF(D16=0,0,IF(G16="联营",J22*E16/D16,IF(G16="合营",J22*E16/D16,J22))) -> 0
B23: =B17 -> 0 | D23: =C23*E17 -> 0 | E23: =C23-D23 -> 0 | G23: =F23-E23 -> 0 | K23: =IF(D17=0,0,IF(G17="联营",G23+H23*E17/D17,IF(G17="合营",G23+H23*E17/D17,G23+I23))) -> 0 | L23: =IF(D17=0,0,IF(G17="联营",J23*E17/D17,IF(G17="合营",J23*E17/D17,J23))) -> 0
B24: =B18 -> 0 | D24: =C24*E18 -> 0 | E24: =C24-D24 -> 0 | G24: =F24-E24 -> 0 | K24: =IF(D18=0,0,IF(G18="联营",G24+H24*E18/D18,IF(G18="合营",G24+H24*E18/D18,G24+I24))) -> 0 | L24: =IF(D18=0,0,IF(G18="联营",J24*E18/D18,IF(G18="合营",J24*E18/D18,J24))) -> 0
A25: 2.2合并报表
B26: 子公司名称 | C26: 处置日合并财务报表层面子公司的净资产 | D26: 处置日合并财务报表层面享有该子公司净资产份额 | E26: 处置价款与处置投资对应的合并财务报表层面享有该子公司净资产份额的差额 | F26: 合并财务报表中与该子公司相关的商誉 | G26: 丧失控制权之日剩余股权的账面价值 | H26: 丧失控制权之日剩余股权的公允价值 | I26: 按公允价值重新计量产生的利得/损失 | J26: 丧失控制权之日剩余股权的公允价值的确定方法及主要假设 | K26: 与原子公司股权投资相关的其他综合收益转入投资损益的金额 | L26: 备注
B27: =B15 -> 0 | C27: 11 | D27: =IF(D15=0,0,C27*E15/D15) -> 0 | E27: =C15-D27 -> 0 | F27: 22 | G27: 4 | H27: =F21 -> 0 | I27: =H27-G27 -> -4 | J27: 5 | K27: =C15+H27-C27-F27 -> -33
B28: =B16 -> 0 | D28: =IF(D16=0,0,C28*E16/D16) -> 0 | E28: =C16-D28 -> 0 | G28: =E22 -> 0 | H28: =F22 -> 0 | I28: =H28-G28 -> 0 | K28: =C16+H28-C28-F28 -> 0
B29: =B17 -> 0 | D29: =IF(D17=0,0,C29*E17/D17) -> 0 | E29: =C17-D29 -> 0 | G29: =E23 -> 0 | H29: =F23 -> 0 | I29: =H29-G29 -> 0 | K29: =C17+H29-C29-F29 -> 0
B30: =B18 -> 0 | D30: =IF(D18=0,0,C30*E18/D18) -> 0 | E30: =C18-D30 -> 0 | G30: =E24 -> 0 | H30: =F24 -> 0 | I30: =H30-G30 -> 0 | K30: =C18+H30-C30-F30 -> 0
A32: 3、单次处置剩余股权为联营、合营时追溯调整为权益法
B33: 被投资单位名称 | C33: 持股比例 | D33: 被投资单位 | H33: 归属于母公司
D34: 原取得投资日至处置日净利润 | E34: 本期净利润 | F34: 其他综合收益 | G34: 其他所有者权益变动 | H34: 期初未分配利润 | I34: 盈余公积 | J34: 投资收益 | K34: 长期投资-其他综合收益 | L34: 长期投资-其他变动
C35: ① | D35: ② | E35: ③ | F35: ④ | G35: ⑤ | H35: ⑥=①*②*90% | I35: ⑦=①*②*10% | J35: ⑧=③×① | K35: ⑨=④×① | L35: ⑩=⑤×①
H36: =C36*D36*90% -> 0 | I36: =D36*C36*10% -> 0 | J36: =C36*E36 -> 0 | K36: =C36*F36 -> 0 | L36: =G36*C36 -> 0
H37: =C37*D37*90% -> 0 | I37: =D37*C37*10% -> 0 | J37: =C37*E37 -> 0 | K37: =C37*F37 -> 0 | L37: =G37*C37 -> 0
H38: =C38*D38*90% -> 0 | I38: =D38*C38*10% -> 0 | J38: =C38*E38 -> 0 | K38: =C38*F38 -> 0 | L38: =G38*C38 -> 0
H39: =C39*D39*90% -> 0 | I39: =D39*C39*10% -> 0 | J39: =C39*E39 -> 0 | K39: =C39*F39 -> 0 | L39: =G39*C39 -> 0
A40: 三、审计说明
A44: 四、审计结论

Sheet 处置子公司测试表（一揽子交易）G7-12
A1: 致同会计师事务所
A2: 处置子公司测试表（一揽子交易）
A3: =底稿目录!A2 -> 被审计单位： | E3: =底稿目录!A4 -> 编制人： | I3: =底稿目录!A5 -> 编制日期： | K3: 索引号： | L3: =底稿目录!F18 -> G7-12
A4: =底稿目录!A3 -> 截止日：202X年12月31日 | E4: =底稿目录!A6 -> 复核人： | I4: =底稿目录!A7 -> 复核日期： | K4: 页 次：
A5: 一、审计目标： | C5: 确定处置子公司的会计处理是否恰当。
A6: 二、审计过程：
A7: 1.本期处置的子公司基本情况
B8: 企业名称 | C8: 注册地 | D8: 业务性质 | E8: 持股比例% | F8: 表决权比例% | G8: 本期不再成为子公司的原因
A14: 2.多次交易分步处置股权至丧失控制权而减少的子公司
B15: 一揽子交易的判断事项 | E15: 公司1 | G15: 公司2 | I15: 公司3 | K15: 公司4
E16: 对应情形 | F16: 结论 | G16: 对应情形 | H16: 结论 | I16: 对应情形 | J16: 结论 | K16: 对应情形 | L16: 结论
B17: 这些交易是同时或者在考虑了彼此影响的情况下订立的
B18: 这些交易整体才能达成一项完整的商业结果
B19: 一项交易的发生取决于其他至少一项交易的发生
B20: 一项交易单独看是不经济的，但是和其他交易一并考虑时是经济的
B21: 结论
B22: 子公司名称 | C22: 股权处置价款 | D22: 原股权比例% | E22: 股权处置比例% | F22: 剩余股权比例% | G22: 剩余股权构成 | H22: 股权处置方式 | I22: 丧失控制权的时点 | J22: 丧失控制权时点的确定依据 | K22: 取得的查验资料 | L22: 索引号
F23: =D23-E23 -> 0 | K23: 股权转让协议、产权交割单、…
F24: =D24-E24 -> 0
F25: =D25-E25 -> 0
F26: =D26-E26 -> 0
A27: 2.1单体报表
B28: 子公司名称 | C28: 处置日长期股权投资账面价值 | D28: 应转出的长投 | E28: 丧失控制权之日剩余股权的账面价值 | F28: 丧失控制权之日剩余股权的公允价值 | G28: 按公允价值重新计量产生的利得/损失 | H28: 原子公司投资系联营/合营投资追加投资形成，与原联营/合营投资有关的可重分类至损益的OCI和其他净资产变动 | I28: 原子公司投资系金融资产投资追加投资形成，与原金融资产相关的按照公允价值计量的OCI | J28: 原子公司投资系联营/合营投资追加投资形成，与原联营/合营投资有关不可重分类至损益的OCI | K28: 处置子公司应确认的投资收益 | L28: 应转入权益
B29: =B23 -> 0 | D29: =IF(D23=0,0,C29*E23/D23) -> 0 | E29: =C29-D29 -> 0 | G29: =F29-E29 -> 0 | K29: =IF(D23=0,0,IF(G23="联营",G29+H29*E23/D23,IF(G23="合营",F29-E29+H29*E23/D23,G29+I29))) -> 0 | L29: =IF(D23=0,0,IF(G23="联营",J29*E23/D23,IF(G23="合营",J29*E23/D23,J29))) -> 0
B30: =B24 -> 0 | D30: =C30*E24 -> 0 | E30: =C30-D30 -> 0 | G30: =F30-E30 -> 0 | K30: =IF(D24=0,0,IF(G24="联营",G30+H30*E24/D24,IF(G24="合营",F30-E30+H30*E24/D24,G30+I30))) -> 0 | L30: =IF(D24=0,0,IF(G24="联营",J30*E24/D24,IF(G24="合营",J30*E24/D24,J30))) -> 0
B31: =B25 -> 0 | D31: =C31*E25 -> 0 | E31: =C31-D31 -> 0 | G31: =F31-E31 -> 0 | K31: =IF(D25=0,0,IF(G25="联营",G31+H31*E25/D25,IF(G25="合营",F31-E31+H31*E25/D25,G31+I31))) -> 0 | L31: =IF(D25=0,0,IF(G25="联营",J31*E25/D25,IF(G25="合营",J31*E25/D25,J31))) -> 0
B32: =B26 -> 0 | D32: =C32*E26 -> 0 | E32: =C32-D32 -> 0 | G32: =F32-E32 -> 0 | K32: =IF(D26=0,0,IF(G26="联营",G32+H32*E26/D26,IF(G26="合营",F32-E32+H32*E26/D26,G32+I32))) -> 0 | L32: =IF(D26=0,0,IF(G26="联营",J32*E26/D26,IF(G26="合营",J32*E26/D26,J32))) -> 0
A33: 2.2合并报表
B34: 子公司名称 | C34: 处置日合并财务报表层面子公司的净资产 | D34: 处置日合并财务报表层面享有该子公司净资产份额 | E34: 处置价款与处置投资对应的合并财务报表层面享有该子公司净资产份额的差额 | F34: 合并财务报表中与该子公司相关的商誉 | G34: 丧失控制权之日剩余股权的账面价值 | H34: 丧失控制权之日剩余股权的公允价值 | I34: 按公允价值重新计量产生的利得/损失 | J34: 丧失控制权之日剩余股权的公允价值的确定方法及主要假设 | K34: 与原子公司股权投资相关的其他综合收益转入投资损益的金额 | L34: 丧失控制权之前的各步交易处置价款与处置投资对应的合并财务报表层面享有该子公司净资产份额的差额
B35: =B23 -> 0 | D35: =IF(D23=0,0,C35*E23/D23) -> 0 | E35: =C23-D35 -> 0 | G35: =E29 -> 0 | H35: =F29 -> 0 | I35: =H35-G35 -> 0 | K35: =C23+H35-C35-F35 -> 0
B36: =B24 -> 0 | D36: =IF(D24=0,0,C36*E24/D24) -> 0 | E36: =C24-D36 -> 0 | G36: =E30 -> 0 | H36: =F30 -> 0 | I36: =H36-G36 -> 0 | K36: =C24+H36-C36-F36 -> 0
B37: =B25 -> 0 | D37: =IF(D25=0,0,C37*E25/D25) -> 0 | E37: =C25-D37 -> 0 | G37: =E31 -> 0 | H37: =F31 -> 0 | I37: =H37-G37 -> 0 | K37: =C25+H37-C37-F37 -> 0
B38: =B26 -> 0 | D38: =IF(D26=0,0,C38*E26/D26) -> 0 | E38: =C26-D38 -> 0 | G38: =E32 -> 0 | H38: =F32 -> 0 | I38: =H38-G38 -> 0 | K38: =C26+H38-C38-F38 -> 0
A39: 2.3剩余股权为联营、合营时追溯调整为权益法
B40: 被投资单位名称 | C40: 持股比例 | D40: 被投资单位 | H40: 归属于母公司
D41: 原取得投资日至处置日净利润 | E41: 本期净利润 | F41: 其他综合收益 | G41: 其他所有者权益变动 | H41: 期初未分配利润 | I41: 盈余公积 | J41: 投资收益 | K41: 长期投资-其他综合收益 | L41: 长期投资-其他变动
C42: ① | D42: ② | E42: ③ | F42: ④ | G42: ⑤ | H42: ⑥=①*②*90% | I42: ⑦=①*②*10% | J42: ⑧=③×① | K42: ⑨=④×① | L42: ⑩=⑤×①
H43: =C43*D43*90% -> 0 | I43: =D43*C43*10% -> 0 | J43: =C43*E43 -> 0 | K43: =C43*F43 -> 0 | L43: =G43*C43 -> 0
H44: =C44*D44*90% -> 0 | I44: =D44*C44*10% -> 0 | J44: =C44*E44 -> 0 | K44: =C44*F44 -> 0 | L44: =G44*C44 -> 0
H45: =C45*D45*90% -> 0 | I45: =D45*C45*10% -> 0 | J45: =C45*E45 -> 0 | K45: =C45*F45 -> 0 | L45: =G45*C45 -> 0
...

Sheet 合营、联营企业投资成本测试表G7-13
A1: 致同会计师事务所
A2: 合营、联营企业投资成本测试表
A3: =底稿目录!A2 -> 被审计单位： | F3: =底稿目录!A4 -> 编制人： | I3: =底稿目录!A5 -> 编制日期： | L3: 索引号： | M3: =底稿目录!F19 -> G7-13
A4: =底稿目录!A3 -> 截止日：202X年12月31日 | F4: =底稿目录!A6 -> 复核人： | I4: =底稿目录!A7 -> 复核日期： | L4: 页 次：
A5: 一、审计目标： | C5: 确定联营、合营企业的会计处理是否恰当。
A6: 二、审计过程 | C6: 1、检查与长期股权投资相关的原始文件或其他支持文件（股权投资协议及框架协议（如有）、交易双方对于交易事项的审批文件、相关政府机关的批准文件、权利交接手续（特别是董事会改选）、款项的收付凭据）。
C7: 2、综合判断长期股权投资是否满足共同控制/重大影响。
C8: 3、取得被审计单位管理层对被投资单位可辨认净资产公允价值的认定及依据的中介机构报告。检查被投资单位可辨认净资产公允价值的确认依据是否充分；
C9: 4、识别期后发生的长期股权投资的增加，检查至支持性文件，确定是否是被记录在恰当的期间内。
C10: 5、对于不纳入合并范围的被投资单位的预付投资款项或预收处置款项，确认重大条款和金额。
A11: （一）被投资单位基本情况
A12: 被投资单位A：
B13: 出资单位名称 | D13: 注册资本 | H13: 实收资本
D14: 期初注册资本 | E14: 本期增加 | F14: 本期减少 | G14: 期末注册资本 | H14: 期初实收资本 （股本） | I14: 本期增加 | J14: 本期减少 | K14: 期末实收资本 （股本）
B15: 1、本公司 | G15: =D15+E15-F15 -> 0 | K15: =H15+I15-J15 -> 0
B16: 2、 …股东 | G16: =D16+E16-F16 -> 0 | K16: =H16+I16-J16 -> 0
B17: 3、 …股东 | G17: =D17+E17-F17 -> 0 | K17: =H17+I17-J17 -> 0
B18: 合计 | D18: =SUM(D15:D17) -> 0 | E18: =SUM(E15:E17) -> 0 | F18: =SUM(F15:F17) -> 0 | G18: =SUM(G15:G17) -> 0 | H18: =SUM(H15:H17) -> 0 | I18: =SUM(I15:I17) -> 0 | J18: =SUM(J15:J17) -> 0 | K18: =SUM(K15:K17) -> 0
A19: （二）公司对其历次投资情况检查
B20: 1、一次投入投资成本确认：
B21: 被投资单位名称 | C21: 投资时间 | D21: 初始投资成本(支付对价) (A) | E21: 投资发生时被投资单位可辨认净资产公允价值 | G21: 新增投资与应享有的被投资单位可辨认净资产公允价值份额的差额（D）=A-B*C | H21: 确认本次投资的投资成本（E） | I21: 计入营业外收入金额（F）
E22: 金额 (B) | F22: 投资比例 （C)
G23: =D23-E23*F23 -> 0 | H23: =IF(G23>0,D23,D23-G23) -> 0 | I23: =IF(G23<0,-G23,0) -> 0
G24: =D24-E24 -> 0 | H24: =IF(G24>0,D24,D24-G24) -> 0 | I24: =IF(G24<0,-G24,0) -> 0
G25: =D25-E25 -> 0 | H25: =IF(G25>0,D25,D25-G25) -> 0 | I25: =IF(G25<0,-G25,0) -> 0
G26: =D26-E26 -> 0 | H26: =IF(G26>0,D26,D26-G26) -> 0 | I26: =IF(G26<0,-G26,0) -> 0
B27: 合计 | D27: =SUM(D23:D26) -> 0 | E27: =SUM(E23:E26) -> 0 | F27: =SUM(F23:F26) -> 0 | G27: =SUM(G23:G26) -> 0 | H27: =SUM(H23:H26) -> 0 | I27: =IF(G27<0,-G27,0) -> 0
B28: 2、原持有的对被投资单位不具有控制、共同控制或重大影响的金融资产，因追加投资导致持股比例上升,能够对被投资单位施加重大影响或是实施共同控制的,长期股权投资账面价值合计：
B29: 被投资单位名称 | C29: 原投资在追加投资日的公允价值(A) | D29: 原投资比例(B) | E29: 新增投资确认的投资成本（C） | F29: 追加的投资比例(D) | G29: 追加投资时被投资单位可辨认净资产公允价值(E) | H29: 新增投资与应享有的被投资单位可辨认净资产公允价值份额的差额（F）=(A)+(C)-(B+D)*E | I29: 确认本次投资的投资成本（G） | J29: 计入营业外收入金额（H） | K29: 原取得投资后至追加投资的交易日之间被投资单位公允价值的变动
K30: 原取得投资至追加投资当期期初已计入其他综合收益的累计公允价值变动（I） | L30: 追加投资当期期初至追加投资交易日之间的公允价值变动（J） | M30: 转入投资收益：公允价值变动合计（K=I+J）
H31: =C31+E31-(D31+F31)*G31 -> 0 | I31: =IF(H31>0,C31+E31,C31+E31-H31) -> 0 | J31: =IF(H31<0,-H31,0) -> 0 | M31: =K31+L31 -> 0
H32: =C32+E32-(D32+F32)*G32 -> 0 | I32: =IF(H32>0,C32+E32,C32+E32-H32) -> 0 | J32: =IF(H32<0,-H32,0) -> 0 | M32: =K32+L32 -> 0
H33: =C33+E33-(D33+F33)*G33 -> 0 | I33: =IF(H33>0,C33+E33,C33+E33-H33) -> 0 | J33: =IF(H33<0,-H33,0) -> 0 | M33: =K33+L33 -> 0
B34: 合计 | C34: -- | D34: -- | E34: -- | F34: -- | G34: -- | H34: -- | I34: -- | J34: =SUM(J31:J33) -> 0 | K34: -- | L34: -- | M34: =SUM(M31:M33) -> 0
B36: 3、主动增资：投资单位对联营企业的持股比例增加，但被投资单位仍然是投资单位的联营企业或合营企业时，长期股权投资账面价值合计：
B37: 被投资单位名称 | C37: 新增投资时的原账面价值（A） | D37: 其中：原投资的内含商誉（B） | E37: 原投资比例（C） | F37: 新增投资确认的投资成本（D） | G37: 新增投资比例（E） | H37: 新增投资时被投资单位单位可辨认净资产公允价值（F） | I37: 新增投资与应享有的被投资单位可辨认净资产公允价值份额的差额（G）=D-E*F | J37: 确认本次投资的投资成本（H） | K37: 计入营业外收入金额（I）
I38: =F38-G38*H38 -> 0 | J38: =IF((D38+I38)>0,F38,F38-I38-D38) -> 0 | K38: =IF(I38+D38<0,I38-D38,0) -> 0
