Workbook

Sheet 底稿目录
A1: 底稿开列时，可先在以下单元格填写有关内容，以便其他底稿引用有关数据：
A2: 被审计单位：
A3: 截止日：202X年12月31日 | D3: 序号 | E3: 内容 | F3: 索引号
A4: 编制人： | E4: 其他非流动金融资产实质性程序表 | F4: G9A
A5: 编制日期： | D5: 1 | E5: 审定表 | F5: G9-1
A6: 复核人： | D6: 2 | E6: 附注披露信息（上市公司） | G6: 无需打印
A7: 复核日期： | D7: 3 | E7: 附注披露信息（国企） | G7: 无需打印
D8: 4 | E8: 明细表 | F8: G9-2
A9: 关于工作底稿与审计程序索引号对应的说明 | D9: 5 | E9: 调整分录汇总 | F9: G9-3
A10: 1.编制的审计工作底稿应与审计程序对应。审计项目组应根据被审计单位实际情况和风险评估情况在实质性程序表中裁剪、修改或增加审计程序，根据实际执行的审计程序完成相应审计工作底稿，编制的工作底稿中应按自然顺序依次编制索引号，并通过唯一的索引号将与实质性程序表中的程序对应关联（即将工作底稿的索引号填入实质性程序表中的底稿索引号列）。 | D10: 6 | E10: 公允价值测试表 | F10: G9-4
D11: 7 | E11: 第三层次公允价值计量的调节表 | F11: G9-5
D12: 8 | E12: 函证结果汇总表 | F12: G0-1
D13: 9 | E13: 核实被函证单位信息 | F13: G0-2
A14: 2.获取的支持性证据应与审计底稿或程序对应。审计项目组在完成底稿时获取的支持性证据应根据底稿索引号编制下一级按自然顺序排序的索引号（如D1-2-1、D1-2-2、……），并在底稿中说明引用的支持性证据、关联索引号。 | D14: 10 | E14: 跟函函证过程控制 | F14: G0-3
D15: 11 | E15: 函证差异核对表（证券投资） | F15: G0-4
D16: 12 | E16: 函证差异核对表(非证券投资) | F16: G0-5
A17: 3.工作底稿索引号的编码规则：实质性程序索引号按循环从“D”到“N”,循环内账户以顺序号排列，模板中底稿索引号按账户顺序+自然数顺序（即模板中索引号按二级自然顺序排列，如D1-1、D1-2、D1-3、……D1-N）。 | D17: 13 | E17: 替代程序检查表 | F17: G0-6
D18: 14 | E18: 邮件传真回函可靠性验证 | F18: G0-7
D19: 15 | E19: 函证程序舞弊风险评价表 | F19: G0-8
D20: 16 | E20: 凭证检查表 | F20: G9-6
D21: 注： | E21: 业务模式分析详见G1-7
E22: 合同现金流量特征详见分析G1-8

Sheet 其他非流动金融资产实质性程序表G9A
A1: 致同会计师事务所
A2: 其他非流动金融资产实质性程序表
A3: =底稿目录!A2 -> 被审计单位： | C3: =底稿目录!A4 -> 编制人： | F3: =底稿目录!A5 -> 编制日期： | H3: 索引号： | I3: =底稿目录!F4 -> G9A
A4: =底稿目录!A3 -> 截止日：202X年12月31日 | C4: =底稿目录!A6 -> 复核人： | F4: =底稿目录!A7 -> 复核日期： | H4: 页 次：
A5: 一、本账户涉及的科目
A6: 其他非流动金融资产
A7: 二、审计目标与认定的对应关系
A8: 审计目标 | G8: 财务报表的认定
A9: A. 资产负债表中记录的其他非流动金融资产是存在的，且已记录于恰当的账户 | G9: 存在
A10: B. 所有应记录的其他非流动金融资产均已记录，所有应当包括在财务报表中的相关披露均已包括 | G10: 完整性
A11: C. 记录的其他非流动金融资产由被审计单位拥有或控制 | G11: 权利和义务
A12: D. 其他非流动金融资产以恰当的金额包括在财务报表中，与之相关的计价或分摊调整已恰当记录，相关披露已得到恰当计量和描述 | G12: 准确性、计价和分摊
A13: E. 其他非流动金融资产已被恰当地汇总或分解且表述清楚，相关披露在按照企业会计准则的编制基础下是相关的、可理解的 | G13: 列报
A14: 三、计划实施的实质性程序
A15: 序号 | B15: 审计程序 | C15: 程序分类 | D15: 财务报表的认定 | I15: 底稿索引号
D16: 存在 | E16: 完整性 | F16: 权利和 义务 | G16: 准确性、计价和分摊 | H16: 列报 | J16: 根据被审计单位实际情况和风险评估情况裁剪、修改或增加审计程序
A17: 1 | B17: 获取或编制其他非流动金融资产的明细表，完成以下工作，并编制审定表 （1）复核加计是否正确，与总账、明细账合计数核对是否相符，将期初余额与上期期末余额核对； （2）追查明细表至调节表/将重大头寸与相应证券记录清单/证券服务机构提供的所有投资账户的电子文件/对账单（在可能的情况下自行进入交易系统获得对账单））核对一致; （3）与上年明细项目进行比较，确定与上年分类相同； （4）与应收利息、投资收益、公允价值变动损益等项目的变动进行核对，复核其勾稽关系； （5）调查重大或者异常的调节项目，并与客户的适当人员讨论差异，考虑回复的可信度并确认相关解释，以及采取适当的措施； （6）检查非记账本位币计量的其他非流动金融资产的折算汇率及折算是否正确。 | C17: 常规★ | D17: √ | E17: √ | G17: √ | I17: G9-1 /G9-2
A18: 2 | B18: 在使用手工编制、自定义信息报告、系统生成的非固定格式报告等由被审计单位生成的信息时，测试有关信息准确性和完整性，并考虑针对编制和维护由被审计单位生成的信息的相关控制实施控制测试，以评价该信息是否能够为实现审计目的提供基础。 | C18: 常规★ | E18: √ | G18: √ | I18: T1 /G0-2
A19: 3 | B19: 对期初余额的审计，取得其他非流动金融资产期初余额明细表复核加计是否正确，与总账、明细账合计数是否相符，确定会计政策及程序是否适当，确定计算的准确性；检查期初投资在本期处置情况，确定证券投资是否在第一个季度亏损出售；将重大投资与其支持性文件核对一致；确定是否需要补充必要的程序，如果是，执行适当的应对程序。（适用于首次承接） | C19: 备选 | D19: √ | E19: √ | F19: √ | G19: √ | I19: G9-
A20: 4 | B20: 根据实际情况，实施以下分析程序： （1）获取增、减分析表，确定增加内容及减少方式、对损益的影响； （2）复核年度各项金融资产的总体合理性；对变化较大的项目或没有变动的项目进行复核，与被审计单位适当人员讨论原因，判断其存在的合理性，是否存在减值； （3）结合其他非流动金融资产循环中投资收益的审计，计算年度金融资产循环收益占利润总额的比例，分析公司对金融资产循环收益的依赖程度，判断其盈利能力和稳定性。 | C20: 常规★ | D20: √ | G20: √ | I20: G9-1 /G9-2
A21: 5 | B21: 确认其他非流动金融资产会计政策、会计处理是否合理并与前期一致，会计估计是否合理，实施以下程序： （1）关注被审计单位管理金融工具的业务模式，并结合合同现金流量特征，分析管理层对金融资产分类是否合理； （2）与管理层讨论其他非流动金融资产分类是否符合企业会计准则，是否根据确定的分类选用了正确的核算方法； （3）是否发现管理层在以前年度运用的重大判断和估计存在不合理的情形。如果存在，记录下管理层是否在当年进行了恰当的会计处理和披露，并选用了更为准确的判断和假设。 | C21: 常规★ | D21: √ | E21: √ | G21: √ | I21: G9-1 /G9-2
A22: 6 | B22: 对于本期新增的金融资产投资，执行以下程序： （1）获取本期增加的金融资产投资的合约、协议、中介机构报告等（若适用），查验金融资产的分类及计价是否正确；追查至相应的原始凭证及支持文件，检查其是否经过授权审批，确认是否符合合同协议条款的规定；必要时进行穿透核查，明确相关金融产品的资金投向，是否存在定向投资要求、投资对象是否与控股股东存在关联关系等； （2）对本期增加中的特定项目（如金额重大或性质特殊的）进行以下测试：检查非货币性资产交换、债务重组、企业合并、投资等发生取得金融资产的会计处理是否正确； | C22: 常规★ | D22: √ | F22: √ | G22: √ | I22: G9-2 /G9-5
A23: 7 | B23: 关注单独的重大金融资产转移或处置，考虑实施以下程序： （1）获取本期减少的金融资产投资的合约、协议、中介机构报告等（若适用），查验金融资产转移的处理及计价是否正确；追查至相应的原始凭证及支持文件，检查其是否经过授权审批，确认是否符合合同协议条款的规定； （2）对本期减少中的特定项目进行以下测试：检查非货币性资产交换、债务重组、企业合并、投资等发生金融资产转移的会计处理是否正确； （3）重新计算相关的利得或损失； （4）关注处置日期是否记录恰当，会计处理是否恰当。 | C23: 常规★ | D23: √ | E23: √ | F23: √ | G23: √ | I23: G9-2 /G9-5
A24: 8 | B24: 针对公允价值计量的投资，复核其他非流动金融资产计价方法，检查其是否按公允价值计量，前后期是否一致；复核公允价值取得依据是否充分；与被审计单位讨论以确定实际利率确定依据是否充分，非本期新增投资，复核实际利率是否与前期一致；复核计算持有期间的利息收入和投资收益；检查会计处理是否正确。若选择利用专家工作的审计程序，参考“S12利用专家的工作”相关程序执行。 | C24: 常规★ | G24: √ | I24: G9-4
A25: 9 | B25: 向相关机构发函，并确定是否存在变现限制，同时记录函证过程： （1）以积极方式进行函证，设计询证函、发函前核实被函证单位信息； （2）注册会计师独立收发询证函； （3）编制函证结果汇总表，检查发函、回函物流信息和轨迹、比对回函印章和签字等以核实回函的真实性，检查回函是否相符，对不符事项查明原因确定是否存在错报； （4）如果未收到回函，应当考虑与被询证者联系，要求对方作出回应或再次寄发询证函，无法收到的回函实施替代程序； （5）如果管理层不允许寄发询证函的，询问管理层不允许寄发的原因，并就其原因的正当、合理性收集证据；考虑实施替代审计程序以获取相关、可靠的审计证据； （6）如果管理层不允许寄发询证函的原因不合理、或者认为回函不可靠，评价对评估的重大错报风险以及其他审计程序的性质、时间安排和范围的影响，并确定其对审计工作和审计意见的影响。 | C25: 常规★ | D25: √ | E25: √ | F25: √ | G25: √ | I25: G0
A26: 10 | B26: 资产负债表日至审计工作日间，新增、售出、兑换、处置或偿付的大额出售或购买交易，确认是否被记录在恰当时期内；检查报表日后的证券处置是否出现亏损，如果确认亏损，确定这些亏损是否应该记录在报表期。 | C26: 常规★ | D26: √ | E26: √ | G26: √ | I26: G9-2
A27: 11 | B27: 询问各项投资是否存在任何限制、抵押或留置权。 检查有无变现存在重大限制的资产，如有，则查明情况，作出记录。 | C27: 常规★ | F27: √ | I27: G9-2
A28: 12 | B28: 检查关联方交易： （1）了解关联交易的商业理由、交易事项的目的、价格和条件，考虑对关联方交易性金融资产的合理性、合法性； （2）检查对关联方交易性金融资产的真实性相关的支持性文件、检查会计处理是否正确； （3）考虑向关联方或其他注册会计师函证重大的关联交易和余额（包括担保和其他重要信息）； （4）必要时，向与交易相关的人员和机构函证或与其讨论有关信息； （5）考虑是否存在未识别的关联方，关联交易和余额披露是否正确。 | C28: 常规★ | D28: √ | E28: √ | F28: √ | G28: √ | H28: √ | I28: G9-5
A29: 13 | B29: 根据评估的舞弊风险等因素增加的审计程序。 | C29: IPO/上市/新三板/重组/舞弊应对
A30: 14 | B30: 检查其他非流动金融资产是否已按企业会计准则或其他适用的规定在财务报表中做出恰当列报和披露。 | C30: 常规★ | H30: √ | I30: A1-1/A1-15 /A1-16

Sheet 审定表G9-1
A1: 致同会计师事务所
A2: 其他非流动金融资产审定表
A3: =底稿目录!A2 -> 被审计单位： | E3: =底稿目录!A4 -> 编制人： | H3: =底稿目录!A5 -> 编制日期： | K3: 索引号： | L3: =底稿目录!F5 -> G9-1
A4: =底稿目录!A3 -> 截止日：202X年12月31日 | E4: =底稿目录!A6 -> 复核人： | H4: =底稿目录!A7 -> 复核日期： | K4: 页 次：
A5: 项目 | B5: 期初数 | F5: 期末数 | J5: 本期与上期审定数比较 | L5: 原因分析
B6: 未审数 | C6: 账项调整 | D6: 重分类调整 | E6: 审定数 | F6: 未审数 | G6: 账项调整 | H6: 重分类调整 | I6: 审定数 | J6: 变动额 | K6: 变动率
A7: （一）投资成本
A8: 其他非流动金融资产 | B8: =SUM(B9:B12) -> 0 | C8: =SUM(C9:C12) -> 0 | D8: =SUM(D9:D12) -> 0 | E8: =SUM(E9:E12) -> 0 | F8: =SUM(F9:F12) -> 0 | G8: =SUM(G9:G12) -> 0 | H8: =SUM(H9:H12) -> 0 | I8: =SUM(I9:I12) -> 0 | J8: =SUM(J9:J12) -> 0 | K8: =IF(AND(E8=0,I8=0),"",IF(AND(E8=0,I8>0),1,J8/E8))
A9: 债务工具投资 | B9: =SUMIF('明细表G9-2'!A12:A16,"债务工具投资",'明细表G9-2'!C12:E16) -> 0 | C9: =SUMIF('明细表G9-2'!A12:A16,"债务工具投资",'明细表G9-2'!F12:F16) -> 0 | E9: =B9+C9+D9 -> 0 | F9: =SUMIF('明细表G9-2'!A12:A16,"债务工具投资",'明细表G9-2'!P12:P16) -> 0 | G9: =SUMIF('明细表G9-2'!A12:A16,"债务工具投资",'明细表G9-2'!S12:S16) -> 0 | I9: =F9+G9+H9 -> 0 | J9: =I9-E9 -> 0 | K9: =IF(AND(E9=0,I9=0),"",IF(AND(E9=0,I9>0),1,J9/E9))
A10: 权益工具投资 | B10: =SUMIF('明细表G9-2'!A12:A16,"权益工具投资",'明细表G9-2'!C12:C16) -> 0 | C10: =SUMIF('明细表G9-2'!A12:A16,"权益工具投资",'明细表G9-2'!F12:F16) -> 0 | E10: =B10+C10+D10 -> 0 | F10: =SUMIF('明细表G9-2'!A12:A16,"权益工具投资",'明细表G9-2'!P12:P16) -> 0 | G10: =SUMIF('明细表G9-2'!A12:A16,"权益工具投资",'明细表G9-2'!S12:S16) -> 0 | I10: =F10+G10+H10 -> 0 | J10: =I10-E10 -> 0 | K10: =IF(AND(E10=0,I10=0),"",IF(AND(E10=0,I10>0),1,J10/E10))
A11: 衍生金融资产 | B11: =SUMIF('明细表G9-2'!A12:A16,"衍生金融资产",'明细表G9-2'!C12:C16) -> 0 | C11: =SUMIF('明细表G9-2'!A12:A16,"衍生金融资产",'明细表G9-2'!F12:F16) -> 0 | E11: =B11+C11+D11 -> 0 | F11: =SUMIF('明细表G9-2'!A12:A16,"衍生金融资产",'明细表G9-2'!P12:P16) -> 0 | G11: =SUMIF('明细表G9-2'!A12:A16,"衍生金融资产",'明细表G9-2'!S12:S16) -> 0 | I11: =F11+G11+H11 -> 0 | J11: =I11-E11 -> 0 | K11: =IF(AND(E11=0,I11=0),"",IF(AND(E11=0,I11>0),1,J11/E11))
A12: 其他 | B12: =SUMIF('明细表G9-2'!A12:A16,"其他",'明细表G9-2'!C12:C16) -> 0 | C12: =SUMIF('明细表G9-2'!A12:A16,"其他",'明细表G9-2'!F12:F16) -> 0 | E12: =B12+C12+D12 -> 0 | F12: =SUMIF('明细表G9-2'!A12:A16,"其他",'明细表G9-2'!P12:P16) -> 0 | G12: =SUMIF('明细表G9-2'!A12:A16,"其他",'明细表G9-2'!S12:S16) -> 0 | I12: =F12+G12+H12 -> 0 | J12: =I12-E12 -> 0 | K12: =IF(AND(E12=0,I12=0),"",IF(AND(E12=0,I12>0),1,J12/E12))
A13: 划分为以公允价值计量且其变动计入当期损益的金融资产 | B13: =SUM(B14:B17) -> 0 | C13: =SUM(C14:C17) -> 0 | D13: =SUM(D14:D17) -> 0 | E13: =SUM(E14:E17) -> 0 | F13: =SUM(F14:F17) -> 0 | G13: =SUM(G14:G17) -> 0 | H13: =SUM(H14:H17) -> 0 | I13: =SUM(I14:I17) -> 0 | J13: =SUM(J14:J17) -> 0 | K13: =IF(AND(E13=0,I13=0),"",IF(AND(E13=0,I13>0),1,J13/E13))
A14: 债务工具投资 | B14: =SUMIF('明细表G9-2'!A19:A23,"债务工具投资",'明细表G9-2'!C19:C23) -> 0 | C14: =SUMIF('明细表G9-2'!A19:A23,"债务工具投资",'明细表G9-2'!F19:F23) -> 0 | E14: =B14+C14+D14 -> 0 | F14: =SUMIF('明细表G9-2'!A19:A23,"债务工具投资",'明细表G9-2'!P19:P23) -> 0 | G14: =SUMIF('明细表G9-2'!A19:A23,"债务工具投资",'明细表G9-2'!S19:S23) -> 0 | I14: =F14+G14+H14 -> 0 | J14: =I14-E14 -> 0 | K14: =IF(AND(E14=0,I14=0),"",IF(AND(E14=0,I14>0),1,J14/E14))
A15: 权益工具投资 | B15: =SUMIF('明细表G9-2'!A19:A23,"权益工具投资",'明细表G9-2'!C19:C23) -> 0 | C15: =SUMIF('明细表G9-2'!A19:A23,"权益工具投资",'明细表G9-2'!F19:F23) -> 0 | E15: =B15+C15+D15 -> 0 | F15: =SUMIF('明细表G9-2'!A19:A23,"权益工具投资",'明细表G9-2'!P19:P23) -> 0 | G15: =SUMIF('明细表G9-2'!A19:A23,"权益工具投资",'明细表G9-2'!S19:S23) -> 0 | I15: =F15+G15+H15 -> 0 | J15: =I15-E15 -> 0 | K15: =IF(AND(E15=0,I15=0),"",IF(AND(E15=0,I15>0),1,J15/E15))
A16: 衍生金融资产 | B16: =SUMIF('明细表G9-2'!A19:A23,"衍生金融资产",'明细表G9-2'!C19:C23) -> 0 | C16: =SUMIF('明细表G9-2'!A19:A23,"衍生金融资产",'明细表G9-2'!F19:F23) -> 0 | E16: =B16+C16+D16 -> 0 | F16: =SUMIF('明细表G9-2'!A19:A23,"衍生金融资产",'明细表G9-2'!P19:P23) -> 0 | G16: =SUMIF('明细表G9-2'!A19:A23,"衍生金融资产",'明细表G9-2'!S19:S23) -> 0 | I16: =F16+G16+H16 -> 0 | J16: =I16-E16 -> 0 | K16: =IF(AND(E16=0,I16=0),"",IF(AND(E16=0,I16>0),1,J16/E16))
A17: 其他 | B17: =SUMIF('明细表G9-2'!A19:A23,"其他",'明细表G9-2'!C19:C23) -> 0 | C17: =SUMIF('明细表G9-2'!A19:A23,"其他",'明细表G9-2'!F19:F23) -> 0 | E17: =B17+C17+D17 -> 0 | F17: =SUMIF('明细表G9-2'!A19:A23,"其他",'明细表G9-2'!P19:P23) -> 0 | G17: =SUMIF('明细表G9-2'!A19:A23,"其他",'明细表G9-2'!S19:S23) -> 0 | I17: =F17+G17+H17 -> 0 | J17: =I17-E17 -> 0 | K17: =IF(AND(E17=0,I17=0),"",IF(AND(E17=0,I17>0),1,J17/E17))
A18: 指定为以公允价值计量且其变动计入当期损益的金融资产 | B18: =SUM(B19:B20) -> 0 | C18: =SUM(C19:C20) -> 0 | D18: =SUM(D19:D20) -> 0 | E18: =SUM(E19:E20) -> 0 | F18: =SUM(F19:F20) -> 0 | G18: =SUM(G19:G20) -> 0 | H18: =SUM(H19:H20) -> 0 | I18: =SUM(I19:I20) -> 0 | J18: =SUM(J19:J20) -> 0 | K18: =IF(AND(E18=0,I18=0),"",IF(AND(E18=0,I18>0),1,J18/E18))
A19: 债务工具投资 | B19: =SUMIF('明细表G9-2'!A26:A28,"债务工具投资",'明细表G9-2'!C26:C28) -> 0 | C19: =SUMIF('明细表G9-2'!A26:A28,"债务工具投资",'明细表G9-2'!F26:F28) -> 0 | E19: =B19+C19+D19 -> 0 | F19: =SUMIF('明细表G9-2'!A26:A28,"债务工具投资",'明细表G9-2'!P26:P28) -> 0 | G19: =SUMIF('明细表G9-2'!A26:A28,"债务工具投资",'明细表G9-2'!S26:S28) -> 0 | I19: =F19+G19+H19 -> 0 | J19: =I19-E19 -> 0 | K19: =IF(AND(E19=0,I19=0),"",IF(AND(E19=0,I19>0),1,J19/E19))
A20: 其他 | B20: =SUMIF('明细表G9-2'!A26:A28,"其他",'明细表G9-2'!C26:C28) -> 0 | C20: =SUMIF('明细表G9-2'!A26:A28,"其他",'明细表G9-2'!F26:F28) -> 0 | E20: =B20+C20+D20 -> 0 | F20: =SUMIF('明细表G9-2'!A26:A28,"其他",'明细表G9-2'!P26:P28) -> 0 | G20: =SUMIF('明细表G9-2'!A26:A28,"其他",'明细表G9-2'!S26:S28) -> 0 | I20: =F20+G20+H20 -> 0 | J20: =I20-E20 -> 0 | K20: =IF(AND(E20=0,I20=0),"",IF(AND(E20=0,I20>0),1,J20/E20))
A21: 投资成本小计 | B21: =SUM(B8,B13,B18) -> 0 | C21: =SUM(C8,C13,C18) -> 0 | D21: =SUM(D8,D13,D18) -> 0 | E21: =SUM(E8,E13,E18) -> 0 | F21: =SUM(F8,F13,F18) -> 0 | G21: =SUM(G8,G13,G18) -> 0 | H21: =SUM(H8,H13,H18) -> 0 | I21: =SUM(I8,I13,I18) -> 0 | J21: =SUM(J8,J18) -> 0 | K21: =IF(AND(E21=0,I21=0),"",IF(AND(E21=0,I21>0),1,J21/E21))
A22: （二）累计公允价值变动
A23: 其他非流动金融资产 | B23: =SUM(B24:B27) -> 0 | C23: =SUM(C24:C27) -> 0 | D23: =SUM(D24:D27) -> 0 | E23: =SUM(E24:E27) -> 0 | F23: =SUM(F24:F27) -> 0 | G23: =SUM(G24:G27) -> 0 | H23: =SUM(H24:H27) -> 0 | I23: =SUM(I24:I27) -> 0 | J23: =SUM(J24:J27) -> 0 | K23: =IF(AND(E23=0,I23=0),"",IF(AND(E23=0,I23>0),1,J23/E23))
A24: 其中：债务工具投资 | B24: =SUMIF('明细表G9-2'!A12:A16,"债务工具投资",'明细表G9-2'!D12:D16) -> 0 | C24: =SUMIF('明细表G9-2'!A12:A16,"债务工具投资",'明细表G9-2'!G12:G16) -> 0 | E24: =B24+C24+D24 -> 0 | F24: =SUMIF('明细表G9-2'!A12:A16,"债务工具投资",'明细表G9-2'!Q12:Q16) -> 0 | G24: =SUMIF('明细表G9-2'!A12:A16,"债务工具投资",'明细表G9-2'!T12:T16) -> 0 | I24: =F24+G24+H24 -> 0 | J24: =I24-E24 -> 0 | K24: =IF(AND(E24=0,I24=0),"",IF(AND(E24=0,I24>0),1,J24/E24))
A25: 权益工具投资 | B25: =SUMIF('明细表G9-2'!A12:A16,"权益工具投资",'明细表G9-2'!D12:D16) -> 0 | C25: =SUMIF('明细表G9-2'!A12:A16,"权益工具投资",'明细表G9-2'!G12:G16) -> 0 | E25: =B25+C25+D25 -> 0 | F25: =SUMIF('明细表G9-2'!A12:A16,"权益工具投资",'明细表G9-2'!Q12:Q16) -> 0 | G25: =SUMIF('明细表G9-2'!A12:A16,"权益工具投资",'明细表G9-2'!T12:T16) -> 0 | I25: =F25+G25+H25 -> 0 | J25: =I25-E25 -> 0 | K25: =IF(AND(E25=0,I25=0),"",IF(AND(E25=0,I25>0),1,J25/E25))
A26: 衍生金融资产 | B26: =SUMIF('明细表G9-2'!A12:A16,"债衍生金融资产",'明细表G9-2'!D12:D16) -> 0 | C26: =SUMIF('明细表G9-2'!A12:A16,"债衍生金融资产",'明细表G9-2'!G12:G16) -> 0 | E26: =B26+C26+D26 -> 0 | F26: =SUMIF('明细表G9-2'!A12:A16,"衍生金融资产",'明细表G9-2'!Q12:Q16) -> 0 | G26: =SUMIF('明细表G9-2'!A12:A16,"衍生金融资产",'明细表G9-2'!T12:T16) -> 0 | I26: =F26+G26+H26 -> 0 | J26: =I26-E26 -> 0 | K26: =IF(AND(E26=0,I26=0),"",IF(AND(E26=0,I26>0),1,J26/E26))
A27: 其他 | B27: =SUMIF('明细表G9-2'!A12:A16,"其他",'明细表G9-2'!D12:D16) -> 0 | C27: =SUMIF('明细表G9-2'!A12:A16,"其他",'明细表G9-2'!G12:G16) -> 0 | E27: =B27+C27+D27 -> 0 | F27: =SUMIF('明细表G9-2'!A12:A16,"其他",'明细表G9-2'!Q12:Q16) -> 0 | G27: =SUMIF('明细表G9-2'!A12:A16,"其他",'明细表G9-2'!T12:T16) -> 0 | I27: =F27+G27+H27 -> 0 | J27: =I27-E27 -> 0 | K27: =IF(AND(E27=0,I27=0),"",IF(AND(E27=0,I27>0),1,J27/E27))
A28: 划分为以公允价值计量且其变动计入当期损益的金融资产 | B28: =SUM(B29:B32) -> 0 | C28: =SUM(C29:C32) -> 0 | D28: =SUM(D29:D32) -> 0 | E28: =SUM(E29:E32) -> 0 | F28: =SUM(F29:F32) -> 0 | G28: =SUM(G29:G32) -> 0 | H28: =SUM(H29:H32) -> 0 | I28: =SUM(I29:I32) -> 0 | J28: =SUM(J29:J32) -> 0 | K28: =IF(AND(E28=0,I28=0),"",IF(AND(E28=0,I28>0),1,J28/E28))
A29: 其中：债务工具投资 | B29: =SUMIF('明细表G9-2'!A19:A23,"债务工具投资",'明细表G9-2'!D19:D23) -> 0 | C29: =SUMIF('明细表G9-2'!A19:A23,"债务工具投资",'明细表G9-2'!G19:G23) -> 0 | E29: =B29+C29+D29 -> 0 | F29: =SUMIF('明细表G9-2'!A19:A23,"债务工具投资",'明细表G9-2'!Q19:Q23) -> 0 | G29: =SUMIF('明细表G9-2'!A19:A23,"债务工具投资",'明细表G9-2'!T19:T23) -> 0 | I29: =F29+G29+H29 -> 0 | J29: =I29-E29 -> 0 | K29: =IF(AND(E29=0,I29=0),"",IF(AND(E29=0,I29>0),1,J29/E29))
A30: 权益工具投资 | B30: =SUMIF('明细表G9-2'!A19:A23,"权益工具投资",'明细表G9-2'!D19:D23) -> 0 | C30: =SUMIF('明细表G9-2'!A19:A23,"权益工具投资",'明细表G9-2'!G19:G23) -> 0 | E30: =B30+C30+D30 -> 0 | F30: =SUMIF('明细表G9-2'!A19:A23,"权益工具投资",'明细表G9-2'!Q19:Q23) -> 0 | G30: =SUMIF('明细表G9-2'!A19:A23,"权益工具投资",'明细表G9-2'!T19:T23) -> 0 | I30: =F30+G30+H30 -> 0 | J30: =I30-E30 -> 0 | K30: =IF(AND(E30=0,I30=0),"",IF(AND(E30=0,I30>0),1,J30/E30))
A31: 衍生金融资产 | B31: =SUMIF('明细表G9-2'!A19:A23,"衍生金融资产",'明细表G9-2'!D19:D23) -> 0 | C31: =SUMIF('明细表G9-2'!A19:A23,"衍生金融资产",'明细表G9-2'!G19:G23) -> 0 | E31: =B31+C31+D31 -> 0 | F31: =SUMIF('明细表G9-2'!A19:A23,"衍生金融资产",'明细表G9-2'!Q19:Q23) -> 0 | G31: =SUMIF('明细表G9-2'!A19:A23,"衍生金融资产",'明细表G9-2'!T19:T23) -> 0 | I31: =F31+G31+H31 -> 0 | J31: =I31-E31 -> 0 | K31: =IF(AND(E31=0,I31=0),"",IF(AND(E31=0,I31>0),1,J31/E31))
A32: 其他 | B32: =SUMIF('明细表G9-2'!A19:A23,"其他",'明细表G9-2'!D19:D23) -> 0 | C32: =SUMIF('明细表G9-2'!A19:A23,"其他",'明细表G9-2'!G19:G23) -> 0 | E32: =B32+C32+D32 -> 0 | F32: =SUMIF('明细表G9-2'!A19:A23,"其他",'明细表G9-2'!Q19:Q23) -> 0 | G32: =SUMIF('明细表G9-2'!A19:A23,"其他",'明细表G9-2'!T19:T23) -> 0 | I32: =F32+G32+H32 -> 0 | J32: =I32-E32 -> 0 | K32: =IF(AND(E32=0,I32=0),"",IF(AND(E32=0,I32>0),1,J32/E32))
A33: 指定为以公允价值计量且其变动计入当期损益的金融资产 | B33: =SUM(B34:B35) -> 0 | C33: =SUM(C34:C35) -> 0 | D33: =SUM(D34:D35) -> 0 | E33: =SUM(E34:E35) -> 0 | F33: =SUM(F34:F35) -> 0 | G33: =SUM(G34:G35) -> 0 | H33: =SUM(H34:H35) -> 0 | I33: =SUM(I34:I35) -> 0 | J33: =SUM(J34:J35) -> 0 | K33: =IF(AND(E33=0,I33=0),"",IF(AND(E33=0,I33>0),1,J33/E33))
A34: 其中：债务工具投资 | B34: =SUMIF('明细表G9-2'!A26:A28,"债务工具投资",'明细表G9-2'!D26:D28) -> 0 | C34: =SUMIF('明细表G9-2'!A26:A28,"债务工具投资",'明细表G9-2'!G26:G28) -> 0 | E34: =B34+C34+D34 -> 0 | F34: =SUMIF('明细表G9-2'!A26:A28,"债务工具投资",'明细表G9-2'!Q26:Q28) -> 0 | G34: =SUMIF('明细表G9-2'!A26:A28,"债务工具投资",'明细表G9-2'!T26:T28) -> 0 | I34: =F34+G34+H34 -> 0 | J34: =I34-E34 -> 0 | K34: =IF(AND(E34=0,I34=0),"",IF(AND(E34=0,I34>0),1,J34/E34))
A35: 其他 | B35: =SUMIF('明细表G9-2'!A26:A28,"其他",'明细表G9-2'!C26:C28) -> 0 | C35: =SUMIF('明细表G9-2'!A26:A28,"其他",'明细表G9-2'!D26:D28) -> 0 | E35: =B35+C35+D35 -> 0 | F35: =SUMIF('明细表G9-2'!A26:A28,"其他",'明细表G9-2'!Q26:Q28) -> 0 | G35: =SUMIF('明细表G9-2'!A26:A28,"其他",'明细表G9-2'!T26:T28) -> 0 | I35: =F35+G35+H35 -> 0 | J35: =I35-E35 -> 0 | K35: =IF(AND(E35=0,I35=0),"",IF(AND(E35=0,I35>0),1,J35/E35))
A36: 公允价值变动小计 | B36: =SUM(B23,B28,B33) -> 0 | C36: =SUM(C23,C28,C33) -> 0 | D36: =SUM(D23,D28,D33) -> 0 | E36: =SUM(E23,E28,E33) -> 0 | F36: =SUM(F23,F28,F33) -> 0 | G36: =SUM(G23,G28,G33) -> 0 | H36: =SUM(H23,H28,H33) -> 0 | I36: =SUM(I23,I28,I33) -> 0 | J36: =SUM(J23,J33) -> 0 | K36: =IF(AND(E36=0,I36=0),"",IF(AND(E36=0,I36>0),1,J36/E36))
A37: （三）账面余额（公允价值）
A38: 其他非流动金融资产 | B38: =B8+B23 -> 0 | C38: =C8+C23 -> 0 | D38: =D8+D23 -> 0 | E38: =E8+E23 -> 0 | F38: =F8+F23 -> 0 | G38: =G8+G23 -> 0 | H38: =H8+H23 -> 0 | I38: =I8+I23 -> 0 | J38: =J8+J23 -> 0 | K38: =IF(AND(E38=0,I38=0),"",IF(AND(E38=0,I38>0),1,J38/E38))
A39: 其中：债务工具投资 | B39: =B9+B24 -> 0 | C39: =C9+C24 -> 0 | D39: =D9+D24 -> 0 | E39: =E9+E24 -> 0 | F39: =F9+F24 -> 0 | G39: =G9+G24 -> 0 | H39: =H9+H24 -> 0 | I39: =I9+I24 -> 0 | J39: =J9+J24 -> 0 | K39: =IF(AND(E39=0,I39=0),"",IF(AND(E39=0,I39>0),1,J39/E39))
A40: 权益工具投资 | B40: =B10+B25 -> 0 | C40: =C10+C25 -> 0 | D40: =D10+D25 -> 0 | E40: =E10+E25 -> 0 | F40: =F10+F25 -> 0 | G40: =G10+G25 -> 0 | H40: =H10+H25 -> 0 | I40: =I10+I25 -> 0 | J40: =J10+J25 -> 0 | K40: =IF(AND(E40=0,I40=0),"",IF(AND(E40=0,I40>0),1,J40/E40))
...

Sheet 附注披露信息（上市公司）
A1: 致同会计师事务所
A2: 附注披露信息（上市公司）
A3: =底稿目录!A2 -> 被审计单位： | B3: =底稿目录!A4 -> 编制人： | C3: =底稿目录!A5 -> 编制日期： | D3: 索引号： | E3: =底稿目录!F6 -> 0
A4: =底稿目录!A3 -> 截止日：202X年12月31日 | B4: =底稿目录!A6 -> 复核人： | C4: =底稿目录!A7 -> 复核日期： | D4: 页次：
A5: 附注披露信息
A6: 其他非流动金融资产
A7: 种 类 | B7: 期末余额 | C7: 上年年末余额
A8: 债务工具投资 | B8: ='审定表G9-1'!I39+'审定表G9-1'!I44 -> 0 | C8: ='审定表G9-1'!E39+'审定表G9-1'!E44 -> 0
A9: 权益工具投资 | B9: ='审定表G9-1'!I40+'审定表G9-1'!I45 -> 0 | C9: ='审定表G9-1'!E40+'审定表G9-1'!E45 -> 0
A10: 指定为以公允价值计量且其变动计入当期损益的金融资产 | B10: ='审定表G9-1'!I48 -> 0 | C10: ='审定表G9-1'!E48 -> 0
A11: 其他
A12: 合 计 | B12: =SUM(B8:B11) -> 0 | C12: =SUM(C8:C11) -> 0

Sheet 附注披露信息（国企）
A1: 致同会计师事务所
A2: 附注披露信息（国企）
A3: =底稿目录!A2 -> 被审计单位： | B3: =底稿目录!A4 -> 编制人： | C3: =底稿目录!A5 -> 编制日期： | D3: 索引号： | E3: =底稿目录!F7 -> 0
A4: =底稿目录!A3 -> 截止日：202X年12月31日 | B4: =底稿目录!A6 -> 复核人： | C4: =底稿目录!A7 -> 复核日期： | D4: 页次：
A5: 附注披露信息
A6: 其他非流动金融资产
A7: 项 目 | B7: 期末公允价值 | C7: 期初公允价值
A8: 债务工具投资 | B8: ='审定表G9-1'!I39+'审定表G9-1'!I44 -> 0 | C8: ='审定表G9-1'!E39+'审定表G9-1'!E44 -> 0
A9: 权益工具投资 | B9: ='审定表G9-1'!I40+'审定表G9-1'!I45 -> 0 | C9: ='审定表G9-1'!E40+'审定表G9-1'!E45 -> 0
A10: 指定为以公允价值计量且其变动计入当期损益的金融资产 | B10: ='审定表G9-1'!I48 -> 0 | C10: ='审定表G9-1'!E48 -> 0
A11: 其他
A12: 合 计 | B12: =SUM(B8:B11) -> 0 | C12: =SUM(C8:C11) -> 0

Sheet 明细表G9-2
A1: 致同会计师事务所 | M1: 致同会计师事务所
A2: 其他非流动金融资产明细表 | M2: 其他非流动金融资产明细表
A3: =底稿目录!A2 -> 被审计单位： | D3: =底稿目录!A4 -> 编制人： | I3: =底稿目录!A5 -> 编制日期： | K3: =AA3 -> 索引号： | L3: =AB3 -> G9-2 | M3: =底稿目录!A2 -> 被审计单位： | R3: =底稿目录!A4 -> 编制人： | V3: =底稿目录!A5 -> 编制日期： | AA3: 索引号： | AB3: =底稿目录!F8 -> G9-2
A4: =底稿目录!A3 -> 截止日：202X年12月31日 | D4: =底稿目录!A6 -> 复核人： | I4: =底稿目录!A7 -> 复核日期： | K4: =AA4 -> 页 次： | M4: =底稿目录!A3 -> 截止日：202X年12月31日 | R4: =底稿目录!A6 -> 复核人： | V4: =底稿目录!A7 -> 复核日期： | AA4: 页 次：
A5: 一、审计目标 | M5: 一、审计目标
A6: 1.资产负债表中记录的其他非流动金融资产是存在的，且已经记录在恰当的账户中；2.所有应记录的其他非流动金融资产均已记录，所有应当包括在财务报表中的相关披露均已包括； | M6: 1.资产负债表中记录的其他非流动金融资产是存在的，且已经记录在恰当的账户中；2.所有应记录的其他非流动金融资产均已记录，所有应当包括在财务报表中的相关披露均已包括；
A7: 3.其他非流动金融资产以恰当的金额包括在财务报表中，与之相关的计价或分摊调整已恰当记录，相关披露已得到恰当计量和描述 | M7: 3.其他非流动金融资产以恰当的金额包括在财务报表中，与之相关的计价或分摊调整已恰当记录，相关披露已得到恰当计量和描述
A8: 二、审计过程 | M8: 二、审计过程
A9: 类别 | B9: 投资项目【按明细项目列示，如证券名称或被投资单位名称】 | C9: 期初余额 | F9: 期初账项调整 | H9: 期初审定数 | K9: 期初重分类数 | L9: 期初报表数 | M9: 本期变动（借方发生填正数） | P9: 期末余额 | S9: 账项调整 | U9: 期末审定数 | X9: 期末重分类数 | Y9: 期末报表数 | Z9: 期末应收利息 | AA9: 变现是否存在限制 | AB9: 发函情况
C10: 成本 | D10: 累计公允价值变动 | E10: 公允价值 | F10: 成本 | G10: 公允价值变动 | H10: 成本 | I10: 累计公允价值变动 | J10: 公允价值 | M10: 成本 | N10: 本期公允价值变动 | O10: 计入投资收益的股息 | P10: 成本 | Q10: 累计公允价值变动 | R10: 公允价值 | S10: 成本 | T10: 公允价值变动 | U10: 成本 | V10: 累计公允价值变动 | W10: 公允价值
A11: 其他非流动金融资产
A12: 债务工具投资 | E12: =C12+D12 -> 0 | H12: =C12+F12 -> 0 | I12: =D12+G12 -> 0 | J12: =H12+I12 -> 0 | L12: =E12+K12 -> 0 | P12: =C12+M12 -> 0 | Q12: =D12+N12 -> 0 | R12: =P12+Q12 -> 0 | U12: =P12+S12 -> 0 | V12: =Q12+T12 -> 0 | W12: =U12+V12 -> 0 | Y12: =R12+X12 -> 0
E13: =C13+D13 -> 0 | H13: =C13+F13 -> 0 | I13: =D13+G13 -> 0 | J13: =H13+I13 -> 0 | L13: =E13+K13 -> 0 | P13: =C13+M13 -> 0 | Q13: =D13+N13 -> 0 | R13: =P13+Q13 -> 0 | U13: =P13+S13 -> 0 | V13: =Q13+T13 -> 0 | W13: =U13+V13 -> 0 | Y13: =R13+X13 -> 0
E14: =C14+D14 -> 0 | H14: =C14+F14 -> 0 | I14: =D14+G14 -> 0 | J14: =H14+I14 -> 0 | L14: =E14+K14 -> 0 | P14: =C14+M14 -> 0 | Q14: =D14+N14 -> 0 | R14: =P14+Q14 -> 0 | U14: =P14+S14 -> 0 | V14: =Q14+T14 -> 0 | W14: =U14+V14 -> 0 | Y14: =R14+X14 -> 0
E15: =C15+D15 -> 0 | H15: =C15+F15 -> 0 | I15: =D15+G15 -> 0 | J15: =H15+I15 -> 0 | L15: =E15+K15 -> 0 | P15: =C15+M15 -> 0 | Q15: =D15+N15 -> 0 | R15: =P15+Q15 -> 0 | U15: =P15+S15 -> 0 | V15: =Q15+T15 -> 0 | W15: =U15+V15 -> 0 | Y15: =R15+X15 -> 0
E16: =C16+D16 -> 0 | H16: =C16+F16 -> 0 | I16: =D16+G16 -> 0 | J16: =H16+I16 -> 0 | L16: =E16+K16 -> 0 | P16: =C16+M16 -> 0 | Q16: =D16+N16 -> 0 | R16: =P16+Q16 -> 0 | U16: =P16+S16 -> 0 | V16: =Q16+T16 -> 0 | W16: =U16+V16 -> 0 | Y16: =R16+X16 -> 0
A17: 小计 | C17: =SUM(C12:C16) -> 0 | D17: =SUM(D12:D16) -> 0 | E17: =SUM(E12:E16) -> 0 | F17: =SUM(F12:F16) -> 0 | G17: =SUM(G12:G16) -> 0 | H17: =SUM(H12:H16) -> 0 | I17: =SUM(I12:I16) -> 0 | J17: =SUM(J12:J16) -> 0 | ... Z17: =SUM(Z12:Z16) -> 0
A18: 划分为以公允价值计量且其变动计入当期损益的金融资产
A19: 债务工具投资 | E19: =C19+D19 -> 0 | H19: =C19+F19 -> 0 | I19: =D19+G19 -> 0 | J19: =H19+I19 -> 0 | L19: =E19+K19 -> 0 | P19: =C19+M19 -> 0 | Q19: =D19+N19 -> 0 | R19: =P19+Q19 -> 0 | U19: =P19+S19 -> 0 | V19: =Q19+T19 -> 0 | W19: =U19+V19 -> 0 | Y19: =R19+X19 -> 0
E20: =C20+D20 -> 0 | H20: =C20+F20 -> 0 | I20: =D20+G20 -> 0 | J20: =H20+I20 -> 0 | L20: =E20+K20 -> 0 | P20: =C20+M20 -> 0 | Q20: =D20+N20 -> 0 | R20: =P20+Q20 -> 0 | U20: =P20+S20 -> 0 | V20: =Q20+T20 -> 0 | W20: =U20+V20 -> 0 | Y20: =R20+X20 -> 0
E21: =C21+D21 -> 0 | H21: =C21+F21 -> 0 | I21: =D21+G21 -> 0 | J21: =H21+I21 -> 0 | L21: =E21+K21 -> 0 | P21: =C21+M21 -> 0 | Q21: =D21+N21 -> 0 | R21: =P21+Q21 -> 0 | U21: =P21+S21 -> 0 | V21: =Q21+T21 -> 0 | W21: =U21+V21 -> 0 | Y21: =R21+X21 -> 0
E22: =C22+D22 -> 0 | H22: =C22+F22 -> 0 | I22: =D22+G22 -> 0 | J22: =H22+I22 -> 0 | L22: =E22+K22 -> 0 | P22: =C22+M22 -> 0 | Q22: =D22+N22 -> 0 | R22: =P22+Q22 -> 0 | U22: =P22+S22 -> 0 | V22: =Q22+T22 -> 0 | W22: =U22+V22 -> 0 | Y22: =R22+X22 -> 0
E23: =C23+D23 -> 0 | H23: =C23+F23 -> 0 | I23: =D23+G23 -> 0 | J23: =H23+I23 -> 0 | L23: =E23+K23 -> 0 | P23: =C23+M23 -> 0 | Q23: =D23+N23 -> 0 | R23: =P23+Q23 -> 0 | U23: =P23+S23 -> 0 | V23: =Q23+T23 -> 0 | W23: =U23+V23 -> 0 | Y23: =R23+X23 -> 0
A24: 小计 | C24: =SUM(C19:C23) -> 0 | D24: =SUM(D19:D23) -> 0 | E24: =SUM(E19:E23) -> 0 | F24: =SUM(F19:F23) -> 0 | G24: =SUM(G19:G23) -> 0 | H24: =SUM(H19:H23) -> 0 | I24: =SUM(I19:I23) -> 0 | J24: =SUM(J19:J23) -> 0 | ... Z24: =SUM(Z19:Z23) -> 0
A25: 指定为以公允价值计量且其变动计入当期损益的金融资产
E26: =C26+D26 -> 0 | H26: =C26+F26 -> 0 | I26: =D26+G26 -> 0 | J26: =H26+I26 -> 0 | L26: =E26+K26 -> 0 | P26: =C26+M26 -> 0 | Q26: =D26+N26 -> 0 | R26: =P26+Q26 -> 0 | U26: =P26+S26 -> 0 | V26: =Q26+T26 -> 0 | W26: =U26+V26 -> 0 | Y26: =R26+X26 -> 0
E27: =C27+D27 -> 0 | H27: =C27+F27 -> 0 | I27: =D27+G27 -> 0 | J27: =H27+I27 -> 0 | L27: =E27+K27 -> 0 | P27: =C27+M27 -> 0 | Q27: =D27+N27 -> 0 | R27: =P27+Q27 -> 0 | U27: =P27+S27 -> 0 | V27: =Q27+T27 -> 0 | W27: =U27+V27 -> 0 | Y27: =R27+X27 -> 0
E28: =C28+D28 -> 0 | H28: =C28+F28 -> 0 | I28: =D28+G28 -> 0 | J28: =H28+I28 -> 0 | L28: =E28+K28 -> 0 | P28: =C28+M28 -> 0 | Q28: =D28+N28 -> 0 | R28: =P28+Q28 -> 0 | U28: =P28+S28 -> 0 | V28: =Q28+T28 -> 0 | W28: =U28+V28 -> 0 | Y28: =R28+X28 -> 0
A29: 小计 | C29: =SUM(C26:C28) -> 0 | D29: =SUM(D26:D28) -> 0 | E29: =SUM(E26:E28) -> 0 | F29: =SUM(F26:F28) -> 0 | G29: =SUM(G26:G28) -> 0 | H29: =SUM(H26:H28) -> 0 | I29: =SUM(I26:I28) -> 0 | J29: =SUM(J26:J28) -> 0 | ... Z29: =SUM(Z26:Z28) -> 0
A30: 合计 | C30: =SUM(C17,C24,C29) -> 0 | D30: =SUM(D17,D24,D29) -> 0 | E30: =SUM(E17,E24,E29) -> 0 | F30: =SUM(F17,F24,F29) -> 0 | G30: =SUM(G17,G24,G29) -> 0 | H30: =SUM(H17,H24,H29) -> 0 | I30: =SUM(I17,I24,I29) -> 0 | J30: =SUM(J17,J24,J29) -> 0 | ... Z30: =SUM(Z17,Z24,Z29) -> 0
A31: 三、审计说明：
A33: 四、审计结论：
A36: 编制说明【非打印内容】：
A37: 1．编制时应列入其他非流动金融资产的每一明细账户。2．外币其他非流动金融资产应列明原币金额及折合汇率（自行添加项目）。
A38: 2.本项目可能包括：
A39: （1）未能通过SPPI测试的、到期日不超过一年或预期持有不超过一年的债务工具投资（含嵌入衍生工具），例如非保本理财产品、保本浮动收益理财产品（结构性存款）等；
A40: （2）以其他业务模式持有的债务工具投资（含嵌入衍生工具）；
A41: （3）未指定为有效套期工具的衍生工具；
A42: （4）到期日不超过一年或预期持有不超过一年的权益工具投资（不包括指定为FVOCI的）；
A43: （5）到期日不超过一年或预期持有不超过一年的、直接指定为FVTPL的债务工具投资（含嵌入衍生工具）。
...

Sheet 调整分录汇总G9-3
A1: 致同会计师事务所
A2: 其他非流动金融资产调整分录汇总表
A3: =底稿目录!A2 -> 被审计单位： | D3: =底稿目录!A4 -> 编制人： | G3: =底稿目录!A5 -> 编制日期： | I3: 索引号： | J3: =底稿目录!F9 -> G9-3
A4: =底稿目录!A3 -> 截止日：202X年12月31日 | D4: =底稿目录!A6 -> 复核人： | G4: =底稿目录!A7 -> 复核日期： | I4: 页 次：1
A5: 调整事项说明 | B5: 类别（报表调整/账项调整/其他） | C5: 报表项目 | D5: 科目名称 | E5: 附注项目 | F5: …… | G5: 借方调整金额 | H5: 贷方调整金额 | I5: 索引 | J5: 备注
A24: 【注：本底稿适用于调整分录较多、较复杂的项目，且仅列示与本报表项目相关的审计调整。项目组可根据项目实际情况选择是否使用该底稿。】

Sheet 公允价值测试表G9-4
A1: 致同会计师事务所
A2: 公允价值测试表
A3: =底稿目录!A2 -> 被审计单位： | J3: =底稿目录!A4 -> 编制人： | N3: =底稿目录!A5 -> 编制日期： | Q3: 索引号： | R3: =底稿目录!F10 -> G9-4
A4: =底稿目录!A3 -> 截止日：202X年12月31日 | J4: =底稿目录!A6 -> 复核人： | N4: =底稿目录!A7 -> 复核日期： | Q4: 页 次：
A5: 一、审计目标 | B5: 确定被审计单位其他非流动金融资产以公允价值计量。
A6: 二、审计过程
A7: 投资项目 | B7: 期末未审数 | F7: 期末审定数 | J7: 差异 | K7: 估值方法 | L7: 估值方法与上期是否一致 | M7: 第一层次 | N7: 第二层次 | O7: 第三层次 | R7: 估值文件索引号
B8: 数量（张/股） | C8: 单位公允价值 | D8: 公允价值 | E8: 公允价值层次 | F8: 数量（张/股） | G8: 单位公允价值 | H8: 公允价值 | I8: 公允价值层次 | M8: 公允价值来源机构 | N8: 输入值来源及调整考虑因素 | O8: 估值技术 | P8: 不可观察输入值 | Q8: 数值
D9: =B9*C9 -> 0 | E9: 第二层次 | H9: =F9*G9 -> 0 | I9: 第二层次 | J9: =H9-D9 -> 0 | N9: 以合同规定的未来现金流量按照市场上具有可比信用等级并在相同条件下提供几乎相同现金流量的利率进行折现后的现值确定
D10: =B10*C10 -> 0 | H10: =F10*G10 -> 0 | I10: 第三层次 | J10: =H10-D10 -> 0 | O10: 收益法（折现现金流量法） | P10: 加权平均资本成本 长期收入增长率 长期税前营业利润率 非流通折价 | Q10: 16% 2% 10.3% 20%
A11: 0 | H11: =F11*G11 -> 0 | J11: =H11-D11 -> 0
A12: 0 | H12: =F12*G12 -> 0 | J12: =H12-D12 -> 0
A13: 0 | H13: =F13*G13 -> 0 | J13: =H13-D13 -> 0
A14: 0 | H14: =F14*G14 -> 0 | J14: =H14-D14 -> 0
A15: 0 | H15: =F15*G15 -> 0 | J15: =H15-D15 -> 0
A16: 0 | H16: =F16*G16 -> 0 | J16: =H16-D16 -> 0
A17: 0 | H17: =F17*G17 -> 0 | J17: =H17-D17 -> 0
A18: 0 | H18: =F18*G18 -> 0 | J18: =H18-D18 -> 0
A19: 合计 | D19: =SUM(D9:D18) -> 0 | H19: =SUM(H9:H18) -> 0 | J19: =SUM(J9:J18) -> 0
A20: 三、审计说明： | N20: 四、审计结论：
A21: 了解专家资质及利用估值专家的工作详见：B21、C25、S12、S13
A24: 编制说明：
A25: 1、公允价值的层次
A26: （1）第一层次——相同资产或负债在活跃市场中的报价（未经调整的）。只有在交易所或活跃指数/市场上进行交易的工具才能归入第一层次。
A27: 这一层次包括上市的权益证券和债权工具以及交易所交易的衍生产品如股指期货（基于Nasdaq、S&P500等指数）等。
A28: （2）第二层次——直接（即价格）或间接（即从价格推导出）地使用除第一层次中的资产或负债的市场报价之外的可观察输入值。
A29: 这一层次包括大部分场外交易的衍生工具和债券，交易性贷款和发行的结构型债务工具。
A30: （3）第三层次——资产或负债使用了任何非基于可观察市场数据的输入值（不可观察输入值）。
A31: 这一层次包括一项或多项重大输入为不可观察变量的股权和债券工具。所采用的估值模型通常为现金流折现模型。
A33: 2、概述：（1）程序的测试情况、结果；
A34: （2）拟调整事项及其调整分录、未调整事项及其影响，审计范围受到限制情况及其影响。
A35: 参考结论：
A36: A、 | E36: 未见异常。
A37: B、 | E37: 除以下重大不符事项应当作为调整事项予以调整外，其余未见异常。
A38: C、 | E38: 由于存在以下重大未调整事项（或审计范围受到限制无法获取充分、适当证据），不可确认。

Sheet 第三层次公允价值计量的调节表G9-5
A1: 致同会计师事务所
A2: 第三层次公允价值计量的调节表
A3: =底稿目录!A2 -> 被审计单位： | F3: =底稿目录!A4 -> 编制人： | H3: =底稿目录!A5 -> 编制日期： | L3: 索引号： | M3: =底稿目录!F11 -> G9-5
A4: =底稿目录!A3 -> 截止日：202X年12月31日 | F4: =底稿目录!A6 -> 复核人： | H4: =底稿目录!A7 -> 复核日期： | L4: 页次：
A5: 一、审计目标 | C5: 确定第三层次公允价值计量披露是否适当
A6: 二、审计过程 | C6: 1、取得第三层次公允价值计量金融资产明细清单，复核加计是否正确；
C7: 2、确定第三层次公允价值计量调节过程披露是否适当
A8: 投资项目【按明细项目列示，如证券名称或被投资单位名称】 | C8: 期初余额 | D8: 转入第三层次 | E8: 转出第三层次 | F8: 当期利得或损失总额 | H8: 购买、发行、出售和结算 | L8: 期末余额 | M8: 对于在报告期末持有的资产，计入损益的当期未实现利得或损失的变动
F9: 公允价值变动损益 | G9: 投资收益 | H9: 购入 | I9: 发行 | J9: 出售 | K9: 结算
L10: =C10+D10-E10+F10+H10+I10-J10-K10 -> 0
L11: =C11+D11-E11+F11+H11+I11-J11-K11 -> 0
L12: =C12+D12-E12+F12+H12+I12-J12-K12 -> 0
L13: =C13+D13-E13+F13+H13+I13-J13-K13 -> 0
L14: =C14+D14-E14+F14+H14+I14-J14-K14 -> 0
L15: =C15+D15-E15+F15+H15+I15-J15-K15 -> 0
L16: =C16+D16-E16+F16+H16+I16-J16-K16 -> 0
L17: =C17+D17-E17+F17+H17+I17-J17-K17 -> 0
L18: =C18+D18-E18+F18+H18+I18-J18-K18 -> 0
A19: 合 计 | C19: =SUM(C10:C18) -> 0 | D19: =SUM(D10:D18) -> 0 | E19: =SUM(E10:E18) -> 0 | F19: =SUM(F10:F18) -> 0 | G19: =SUM(G10:G18) -> 0 | H19: =SUM(H10:H18) -> 0 | I19: =SUM(I10:I18) -> 0 | J19: =SUM(J10:J18) -> 0 | ... L19: =SUM(L10:L18) -> 0
A20: 三、审计说明：
A22: 四、审计结论：

Sheet 凭证检查表G9-6
A1: 致同会计师事务所
A2: 其他非流动金融资产凭证检查表
A3: =底稿目录!A2 -> 被审计单位： | E3: =底稿目录!A4 -> 编制人： | H3: =底稿目录!A5 -> 编制日期： | P3: 索引号： | Q3: =底稿目录!F20 -> G9-6
A4: =底稿目录!A3 -> 截止日：202X年12月31日 | E4: =底稿目录!A6 -> 复核人： | H4: =底稿目录!A7 -> 复核日期： | P4: 页 次：
A5: 一、审计目标
A6: 1.资产负债表中记录的其他非流动金融资产是存在的，且已经记录在恰当的账户中；2.记录的其他非流动金融资产由被审计单位拥有或控制；
A7: 3.其他非流动金融资产以恰当的金额包括在财务报表中，与之相关的计价或分摊调整已恰当记录，相关披露已得到恰当计量和描述
A8: 二、样本选取方法与规模：
A9: 测试范围： | B9: 如借方发生额所有凭证共XX笔金额XX、贷方发生额所有凭证共XX笔金额XX | G9: 特定样本： | H9: XX金额以上（大额）、关联方/关联交易形成的款项、XX异常款项全部测试，共XX笔；
A10: 抽样总体： | B10: 测试总体扣除特定样本以外的样本，共XX笔、金额XX | G10: 确定的抽样样本量： | H10: 抽取XX笔（如果使用了样本计算器计算样本量，样本量计算过程见<XX>底稿）
A11: 抽样方法： | B11: 随机选样/系统选样/货币单元抽样/随意选样（非统计抽样适用） | G11: 抽样过程： | H11: 使用IDEA（XX抽样工具）选择XX数量占比XX%的样本进行测试，抽样工具中的样本选择过程和结果见XX底稿
A12: 三、测试：
A13: 测试内容说明：1.原始凭证内容完整；2.有授权批准；3.账务处理正确；4.初始成本计算正确；5.利息计算正确；6.公允价值符合准则要求。
A14: 1.本期发生额检查
A15: 记账凭证 | H15: 支持性文件 | I15: 核对内容 | O15: 索引号 | P15: 是否异常 | Q15: 备注说明
A16: 日期 | B16: 凭证编号 | C16: 业务内容 | D16: 对方科目 | E16: 对方明细科目 | F16: 借方金额 | G16: 贷方金额 | I16: 1 | J16: 2 | K16: 3 | L16: 4 | M16: 5 | N16: 6
A26: 合计 | F26: =SUM(F17:F25) -> 0 | G26: =SUM(G17:G25) -> 0 | K26: =SUM(K17:K25) -> 0
A27: 本期发生额
A28: 检查比例 | F28: =F26/F27 -> #DIV/0! | G28: =G26/G27 -> #DIV/0!
A29: 2.期后处置、新增检查表
C30: 记账凭证 | H30: 支持性文件 | I30: 核对内容 | O30: 索引号 | P30: 是否异常 | Q30: 备注说明
A31: 日期 | B31: 凭证编号 | C31: 业务内容 | D31: 对方科目 | E31: 对方明细科目 | F31: 借方金额 | G31: 贷方金额 | I31: 1 | J31: 2 | K31: 3 | L31: 4 | M31: 5 | N31: 6
A37: 合计 | F37: =SUM(F32:F36) -> 0 | G37: =SUM(G32:G36) -> 0
A38: 四、审计说明：
A40: 五、审计结论：
A44: 编制说明：
A45: 1、概述：（1）程序的测试情况、结果；
A46: （2）拟调整事项及其调整分录、未调整事项及其影响，审计范围受到限制情况及其影响。
A47: 参考结论：
A48: A、 | B48: 未见异常。
A49: B、 | B49: 除以下重大不符事项应当作为调整事项予以调整外，其余未见异常。
A50: C、 | B50: 由于存在以下重大未调整事项（或审计范围受到限制无法获取充分、适当证据），不可确认。
A52: 2、选取测试项目的方法：包括选取全部项目、选取特定项目和审计抽样。
A53: （1） | B53: 当存在下列情形之一时，注册会计师应当考虑选取全部项目进行测试：
B54: （一）总体由少量的大额项目构成；
B55: （二）存在特别风险且其他方法未提供充分、适当的审计证据；
B56: （三）由于信息系统自动执行的计算或其他程序具有重复性，对全部项目进行检查符合成本效益原则。
B58: 特别风险涉及的事项包括但不限于：
B59: （1）舞弊风险（如1141准则的示例）；（2）重大非常规交易（如企业购并、债务重组、非货币性资产交换、
B60: 重大或有事项、持续经营、违反法律法规等）；(3)重大关联交易；(4)重大判断事项（如重大会计估计、
...
