Workbook
Name bs: {#N/A,#N/A,FALSE,"BBPREP"}
Name bs: {#N/A,#N/A,FALSE,"BBPREP"}
Name bs_1: {#N/A,#N/A,FALSE,"BBPREP"}
Name bs_1: {#N/A,#N/A,FALSE,"BBPREP"}

Sheet 修订说明
A1: 原底稿表页 | B1: 修改后底稿表页 | C1: 修订内容
A3: 应付账款实质性程序表G4A | B3: 应付账款实质性程序表G4A | C3: 将155条程序、提示、过程梳理整合到21条程序中，将程序-认定-底稿对应，相关认定“打钩”加粗
A4: 应付账款实质性程序表G4A | B4: 应付账款实质性程序表G4A | C4: 增加供应链融资业务舞弊应对程序和底稿
A5: 审定表G4 | B5: 审定表G4 | C5: 删除（2）应付持本公司5%（含5%）以上表决权股份的股东单位款项情况说明、（3）与经审计的财务报表核对
A6: 期末应付账款明细表G4-2 | B6: 明细表G4-2 | C6: 修改审计目标、整合审计过程，调整审计说明格式
A7: 调整分录汇总G4-3 | B7: 调整分录汇总G4-2-3 | C7: 增加报表项目，删除审计说明、审计结论
B8: 实质性分析G4-4 | C8: 增加应付账款支付期、前五名分析
A9: 长期挂账应付账款检查表G4-2-2 | B9: 长期挂账检查表G4-5 | C9: 将处理金额、审定金额改为是否诉讼、支付计划、支持性证据
A10: 大额及关联方明细表G4-2-1 | B10: 关联方及交易检查表G4-6 | C10: 1、将期末应付账款前五名（审定数）分析移至分析性程序底稿 2、”B、持有5%以上股份股东欠款情况（审定数）“改为“B、关联方欠款情况（审定数）”，增加关联关系列同时增加下拉选项，增加期初、本期发生额列，增加定价政策列
A11: 应付账款核对表G4-4、查找未入账负债（自动化控制）G4-5、未入账负债测试记录（非自动化控制）G4-5 | B11: 未入账检查表G4-7 | C11: 将原三张底稿整合为一张，包含一项分析性检查、从4个方面实质性检查
B12: 应付账款检查表G4-8 | C12: 根据程序增加此底稿
B13: 供应商融资检查表G4-9 | C13: 根据程序增加此底稿

Sheet 底稿目录
A1: 底稿开列时，可先在以下单元格填写有关内容，以便其他底稿引用有关数据：
A2: 被审计单位： | D2: 序号 | E2: 内容 | F2: 索引号
A3: 截止日：202X年12月31日 | D3: 1 | E3: 应付账款实质性程序表 | F3: F4A
A4: 编制人： | D4: =D3+1 -> 2 | E4: 审定表 | F4: F4-1
A5: 编制日期： | D5: =D4+1 -> 3 | E5: 附注披露信息(上市公司) | G5: 无需打印
A6: 复核人： | D6: =D5+1 -> 4 | E6: 附注披露信息(国企) | G6: 无需打印
A7: 复核日期： | D7: =D6+1 -> 5 | E7: 应付账款明细表 | F7: F4-2
D8: =D7+1 -> 6 | E8: 调整分录汇总 | F8: F4-3
A9: 关于工作底稿与审计程序索引号对应的说明 | D9: =D8+1 -> 7 | E9: 实质性分析 | F9: F4-4
A10: 1.编制的审计工作底稿应与审计程序对应。审计项目组应根据被审计单位实际情况和风险评估情况在实质性程序表中裁剪、修改或增加审计程序，根据实际执行的审计程序完成相应审计工作底稿，编制的工作底稿中应按自然顺序依次编制索引号，并通过唯一的索引号将与实质性程序表中的程序对应关联（即将工作底稿的索引号填入实质性程序表中的底稿索引号列）。 | D10: =D9+1 -> 8 | E10: 函证结果汇总表 | F10: F0-1
D11: =D10+1 -> 9 | E11: 核实被函证单位信息 | F11: F0-2
D12: =D11+1 -> 10 | E12: 跟函函证过程控制 | F12: F0-3
D13: =D12+1 -> 11 | E13: 函证差异调节表 | F13: F0-4
A14: 2.获取的支持性证据应与审计底稿或程序对应。审计项目组在完成底稿时获取的支持性证据应根据底稿索引号编制下一级按自然顺序排序的索引号（如D1-2-1、D1-2-2、……），并在底稿中说明引用的支持性证据、关联索引号。 | D14: =D13+1 -> 12 | E14: 应付及采购替代程序检查表 | F14: F0-6
D15: =D14+1 -> 13 | E15: 邮件传真回函可靠性验证 | F15: F0-7
D16: =D15+1 -> 14 | E16: 函证程序舞弊风险评价表 | F16: F0-8
A17: 3.工作底稿索引号的编码规则：实质性程序索引号按循环从“D”到“N”,循环内账户以顺序号排列，模板中底稿索引号按账户顺序+自然数顺序（即模板中索引号按二级自然顺序排列，如D1-1、D1-2、D1-3、……D1-N）。 | D17: =D16+1 -> 15 | E17: 账龄1年以上的应付账款检查表 | F17: F4-5
D18: =D17+1 -> 16 | E18: 应付账款关联方及交易检查表 | F18: F4-6
D19: =D18+1 -> 17 | E19: 未入账应付账款情况检查表 | F19: F4-7
D20: =D19+1 -> 18 | E20: 应付账款检查表 | F20: F4-8
D21: =D20+1 -> 19 | E21: 供应商融资检查表 | F21: F4-9

Sheet 应付账款实质性程序表F4A
A1: 致同会计师事务所
A2: 应付账款实质性程序
A3: =底稿目录!A2 -> 被审计单位： | C3: =底稿目录!A4 -> 编制人： | E3: =底稿目录!A5 -> 编制日期： | H3: 索引号： | I3: =底稿目录!F3 -> F4A
A4: =底稿目录!A3 -> 截止日：202X年12月31日 | C4: =底稿目录!A6 -> 复核人： | E4: =底稿目录!A7 -> 复核日期： | H4: 页 次：
A5: 一、本账户涉及的科目
A6: 应付票据
A7: 二、审计目标与认定的对应关系
A8: 审计目标 | G8: 财务报表的认定
A9: A. 资产负债表中记录的应付账款是存在的，且已经记录在恰当的账户中 | G9: 存在
A10: B. 所有应记录的应付账款均已记录，所有应当包括在财务报表中的相关披露均已包括 | G10: 完整性
A11: C. 记录的应付账款由被审计单位拥有或控制 | G11: 权利和义务
A12: D. 应付账款以恰当的金额包括在财务报表中，与之相关的计价或分摊调整已恰当记录，相关披露已得到恰当计量和描述 | G12: 准确性、计价和分摊
A13: E. 应付账款已被恰当地汇总或分解且表述清楚，相关披露在按照企业会计准则的编制基础下是相关的、可理解的 | G13: 列报
A14: 三、计划实施的实质性程序
A15: 序号 | B15: 审计程序 | C15: 程序分类 | D15: 财务报表的认定 | I15: 底稿索引号
D16: 存在 | E16: 完整性 | F16: 权利和 义务 | G16: 准确性、计价和分摊 | H16: 列报 | K16: 根据被审计单位实际情况和风险评估情况裁剪、修改或增加审计程序
A17: 1 | B17: 获取或编制应付账款的明细表，完成以下工作，并编制审定表 （1）复核加计是否正确，与总账、明细账合计数核对是否相符，期初余额与上期审定期末余额是否相符； （2）获取管理层编制的应付账款账龄分析表，检查账龄划分是否正确； （3）结合预付账款等往来项目的明细余额，检查有无重复付款或将同一笔已付清的款项在预付账款和应付账款两个科目中同时挂账的情况、重大或异常调节项目，以及与购货无关的其他款项； （4）检查借方余额是否需要重分类、非记账本位币应付账款折算是否正确。 | C17: 常规★ | D17: √ | E17: √ | G17: √ | I17: F4-1 /F4-2
A18: 2 | B18: 获取并检查被审计单位与其供应商之间的对账单以及被审计单位编制的差异调节表，确定应付账款金额的准确性。 | C18: 常规★ | D18: √ | E18: √ | G18: √
A19: 3 | B19: 在使用手工编制、自定义信息报告、系统生成的非固定格式报告等由被审计单位生成的信息时，测试有关信息准确性和完整性，并考虑针对编制和维护由被审计单位生成的信息的相关控制实施控制测试，以评价该信息是否能够为实现审计目的提供基础。 | C19: 常规★ | E19: √ | G19: √ | I19: T1 /F0-1 / | K19: 可参见《审计手册》4.2.6，由被审计单位生成的信息可能是由系统生成的、或手工编制的、或二者兼而有之的方式生成的。例如，由被审计单位生成的信息可能包括： • 不涉及自定义的、由系统生成的报告（如，固定格式报告）； • 可能通过人工自定义的、由系统生成的报告，例如，（计算机）查询信息或特别定制的报告； • 手工编制的信息，例如，汇总信息的电子表格或用以支持分配、计算以及调节的电子表格； • 其他系统生成或手工编制的信息，例如，由被审计单位编制的客户发票； • 通过影印、拍摄、扫描或其他方式转换成电子形式的文件记录。
A20: 4 | B20: 对期初余额的审计，取得应付账款期初余额明细表复核加计是否正确，与总账、明细账合计数是否相符，检查上期应付账款在本期支付情况，函证期初余额以及其他必要追加的审计程序。（适用于首次承接） | C20: 备选 | D20: √ | E20: √ | F20: √ | G20: √ | K20: 由被审计单位生成的信息不包括： • 总分类账或明细分类账、试算平衡表、或经审计的财务报表； • 第三方（除了服务机构）的报表或报告，例如，原始银行对账单，或函证的回函； • 外部数据（例如，第三方发布的数据，如，定价来源）。
A21: 5 | B21: 关注会计政策、会计估计合理性、一贯性，关注其是否利用会计政策和会计估计及其变更操纵利润。 | C21: 常规★ | D21: √ | E21: √ | G21: √ | I21: F4-1 /F4-2 | K21: 应付账款中的由被审计单位生成的信息例如：采购合同台账、被函证方信息、单独提供的账龄明细表等
A22: 6 | B22: 分析应付账款余额及发生额： （1）分析平均应付账款支付期与上期以及同行业的变化，关注异常情况； （2）分析主要供应商应付账款应付账款余额的变化，关注异常情况； | C22: 常规★ | D22: √ | G22: √ | I22: F4-4
A23: 7 | B23: 实施函证程序： （1）以积极方式对应付账款进行函证，设计询证函、发函前核实被函证单位信息； （2）注册会计师独立收发询证函； （3）编制函证结果汇总表，检查发函、回函物流信息和轨迹、比对回函印章和签字等以核实回函的真实性，检查回函是否相符，对不符事项查明原因确定是否存在错报； （4）如果未收到回函，应当考虑与被询证者联系，要求对方作出回应或再次寄发询证函，无法收到的回函实施替代程序； （5）如果管理层不允许寄发询证函的，询问管理层不允许寄发的原因，并就其原因的正当、合理性收集证据；考虑实施替代审计程序以获取相关、可靠的审计证据； （6）如果管理层不允许寄发询证函的原因不合理、或者认为回函不可靠，评价对评估的重大错报风险以及其他审计程序的性质、时间安排和范围的影响，并确定其对审计工作和审计意见的影响。 | C23: 常规★ | D23: √ | E23: √ | F23: √ | G23: √ | I23: F0
A24: 8 | B24: 选择主要供应商、异常供应商，考虑对采购额、合同条款、是否存在关联方关系及是否存在补充协议实施函证程序。 | C24: IPO/上市/新三板/重组/舞弊应对 | D24: √ | E24: √ | F24: √ | G24: √ | I24: F0
A25: 9 | B25: 检查应付账款长期挂账的原因并作出记录，分析账龄较长的原因，是否双方有纠纷等，考虑负债计提是否充分，对确实无需支付的应付款的会计处理是否正确。 | C25: 常规★ | D25: √ | G25: √ | I25: F4-5
A26: 10 | B26: 检查应付关联方款项： （1）了解交易的商业理由、交易事项的目的、价格和条件，确定关联交易价格是否远高于或低于非关联方交易价格，考虑对关联方应付账款的合理性、合法性； （2）检查对关联方应付账款的真实性相关的支持性文件、检查会计处理是否正确； （3）考虑向关联方或其他注册会计师函证重大的关联采购交易和余额（包括担保和其他重要信息）； （4）必要时，向与交易相关的人员和机构（如银行、律师）函证或与其讨论有关信息； （5）考虑是否存在未识别的关联方，关联交易和余额披露是否正确。 | C26: 常规★ | D26: √ | E26: √ | F26: √ | G26: √ | H26: √ | I26: F4-6/F4-8/F0
A27: 11 | B27: 如果存在供应商折扣（返利），检查大额或异常供应商折扣计算的准确性、与采购合同核对折扣条件/折扣比例/折扣方式，会计处理是否正确、是否保持一惯性。 | C27: 备选 | G27: √
A28: 12 | B28: 查找未入账的负债： （1）分析大额供应商应付账款平均付款期，考虑期后付款金额大于期末余额的情况下，是否在平均付款天数内； （2）检查资产负债表日是否存在料到单未到的存货暂估入库； （3）检查截止审计现场结束日未处理的供应商发票，是否与期末负债有关； （4）检查资产负债表日后付款凭证，银行对账单及有关付款凭证； （5）检查资产负债表日后应付账款增加凭证，关注购货发票日期，入账期间是否合理； | C28: 常规★ | E28: √ | I28: F4-7
A29: 13 | B29: 结合存货监盘程序，检查被审计单位在资产负债日前后的存货人库资料(验收报告或人库单)，以及是否重大存货盘点调整，检查相关负债是否计人了正确的会计期间； | C29: 常规★ | E29: √ | G29: √
A30: 14 | B30: 检查与应付账款有关的的记账凭证和相应的支持性证据以确定交易的真实性，是否按规定进行相应的会计处理和披露。 | C30: 常规★ | D30: √ | F30: √ | G30: √ | I30: F4-8
A31: 15 | B31: 如果存在供应链融资业务，取得从供应链融资平台导出的融资业务明细表，与供应商融资台账核对一致，检查供应商采购业务是否真实，对于金融机构直接支付给供应商的款项账务处理和披露是否完整。 | C31: IPO/上市/新三板/重组/舞弊应对 | D31: √ | E31: √ | F31: √ | H31: √ | I31: F4-9
A32: 16 | B32: 分析应付账款明细账，按供应商、发票号排序，关注账龄划分是否正确、异常发票记录、同一供应商不同时点的连号发票、未纳入付款计划的应付账款。 | C32: IPO/上市/新三板/重组/舞弊应对 | D32: √ | E32: √ | G32: √
A33: 17 | B33: 主要供应商交易及变化情况： （1）比较分析主要供应商的采购数量、采购金额、信用期、支付方式的变动以及原因，关注新增和异常供应商交易的合理性及持续性； （2）检查向主要供应商采购金额是否与供应商规模是否匹配，采购的物资是否与供应商经营范围匹配； （2）分析主要和异常供应商的采购物资种类、采购金额、采购单价、与平均单价的差异等； | C33: IPO/上市/新三板/重组/舞弊应对 | D33: √ | E33: √ | I33: F2-68 /F2-62
A34: 18 | B34: 结合存货审计，考虑对重大、新增、异常等供应商进行背景调查、电话访谈、实地走访等。 | C34: IPO/上市/新三板/重组/舞弊应对 | D34: √ | E34: √ | F34: √ | G34: √ | I34: F2-69 /F2-70 /F2-71 /F2-72 /D4-32
A35: 19 | B35: 结合销售循环审计，分析客户、供应商名单以及应收、应付等往来明细，检查是否针对同一对方单位或存在关联关系的对方单位同时存在销售、采购的情况，是否有合理的商业理由，关注是否存在第三方配合舞弊的情形。 | C35: IPO/上市/新三板/重组/舞弊应对 | D35: √ | G35: √
A36: 20 | B36: 根据评估的舞弊风险等因素增加的审计程序。 | C36: IPO/上市/新三板/重组/舞弊应对
A37: 21 | B37: 关注是否存在重要采购承诺，采购承诺是否会产生损失。 | C37: 常规★ | F37: √ | G37: √ | H37: √
A38: 22 | B38: 检查应付账款是否已按企业会计准则或其他适用的规定在财务报表中做出恰当列报和披露。 | C38: 常规★ | H38: √ | I38: A1-1/A1-15 /A1-16

Sheet 审定表F4-1
A1: 致同会计师事务所
A2: 应付账款审定表
A3: =底稿目录!A2 -> 被审计单位： | E3: =底稿目录!A4 -> 编制人： | H3: =底稿目录!A5 -> 编制日期： | K3: 索引号： | L3: =底稿目录!F4 -> F4-1
A4: =底稿目录!A3 -> 截止日：202X年12月31日 | E4: =底稿目录!A6 -> 复核人： | H4: =底稿目录!A7 -> 复核日期： | K4: 页 次：
A5: 一、按照性质分类
A6: 项目 | B6: 期初数 | F6: 期末数 | J6: 本期审定数与上期 审定数的比较 | L6: 原因分析
B7: 未审数 | C7: 账项调整 | D7: 重分类调整 | E7: 审定数 | F7: 未审数 | G7: 账项调整 | H7: 重分类调整 | I7: 审定数 | J7: 变动额 | K7: 变动率
A8: 货款 | E8: =B8+C8+D8 -> 0 | F8: =SUMIF('明细表F4-2'!$D$11:$D$32,'审定表F4-1'!A8,'明细表F4-2'!$M$11:$M$32) -> 0 | G8: =SUMIF('明细表F4-2'!$D$11:$D$32,'审定表F4-1'!A8,'明细表F4-2'!$R$11:$R$32) -> 0 | H8: =SUMIF('明细表F4-2'!$D$11:$D$32,'审定表F4-1'!A8,'明细表F4-2'!$S$11:$S$32) -> 0 | I8: =F8+G8+H8 -> 0 | J8: =I8-E8 -> 0 | K8: =IF(AND(E8=0,J8=0),0,IF(AND(E8=0,J8>0),1,J8/E8)) -> 0
A9: 工程款 | E9: =B9+C9+D9 -> 0 | F9: =SUMIF('明细表F4-2'!$D$11:$D$32,'审定表F4-1'!A9,'明细表F4-2'!$M$11:$M$32) -> 0 | G9: =SUMIF('明细表F4-2'!$D$11:$D$32,'审定表F4-1'!A9,'明细表F4-2'!$R$11:$R$32) -> 0 | H9: =SUMIF('明细表F4-2'!$D$11:$D$32,'审定表F4-1'!A9,'明细表F4-2'!$S$11:$S$32) -> 0 | I9: =F9+G9+H9 -> 0 | J9: =I9-E9 -> 0 | K9: =IF(AND(E9=0,J9=0),0,IF(AND(E9=0,J9>0),1,J9/E9)) -> 0
A10: 设备款 | E10: =B10+C10+D10 -> 0 | F10: =SUMIF('明细表F4-2'!$D$11:$D$32,'审定表F4-1'!A10,'明细表F4-2'!$M$11:$M$32) -> 0 | G10: =SUMIF('明细表F4-2'!$D$11:$D$32,'审定表F4-1'!A10,'明细表F4-2'!$R$11:$R$32) -> 0 | H10: =SUMIF('明细表F4-2'!$D$11:$D$32,'审定表F4-1'!A10,'明细表F4-2'!$S$11:$S$32) -> 0 | I10: =F10+G10+H10 -> 0 | J10: =I10-E10 -> 0 | K10: =IF(AND(E10=0,J10=0),0,IF(AND(E10=0,J10>0),1,J10/E10)) -> 0
A11: 服务费 | E11: =B11+C11+D11 -> 0 | F11: =SUMIF('明细表F4-2'!$D$11:$D$32,'审定表F4-1'!A11,'明细表F4-2'!$M$11:$M$32) -> 0 | G11: =SUMIF('明细表F4-2'!$D$11:$D$32,'审定表F4-1'!A11,'明细表F4-2'!$R$11:$R$32) -> 0 | H11: =SUMIF('明细表F4-2'!$D$11:$D$32,'审定表F4-1'!A11,'明细表F4-2'!$S$11:$S$32) -> 0 | I11: =F11+G11+H11 -> 0 | J11: =I11-E11 -> 0 | K11: =IF(AND(E11=0,J11=0),0,IF(AND(E11=0,J11>0),1,J11/E11)) -> 0
A12: 其他 | E12: =B12+C12+D12 -> 0 | F12: =SUMIF('明细表F4-2'!$D$11:$D$32,'审定表F4-1'!A12,'明细表F4-2'!$M$11:$M$32) -> 0 | G12: =SUMIF('明细表F4-2'!$D$11:$D$32,'审定表F4-1'!A12,'明细表F4-2'!$R$11:$R$32) -> 0 | H12: =SUMIF('明细表F4-2'!$D$11:$D$32,'审定表F4-1'!A12,'明细表F4-2'!$S$11:$S$32) -> 0 | I12: =F12+G12+H12 -> 0 | J12: =I12-E12 -> 0 | K12: =IF(AND(E12=0,J12=0),0,IF(AND(E12=0,J12>0),1,J12/E12)) -> 0
A13: 合计 | B13: =SUM(B8:B12) -> 0 | C13: =SUM(C8:C12) -> 0 | D13: =SUM(D8:D12) -> 0 | E13: =SUM(E8:E12) -> 0 | F13: =SUM(F8:F12) -> 0 | G13: =SUM(G8:G12) -> 0 | H13: =SUM(H8:H12) -> 0 | I13: =SUM(I8:I12) -> 0 | J13: =SUM(J8:J12) -> 0 | K13: =IF(AND(E13=0,J13=0),0,IF(AND(E13=0,J13>0),1,J13/E13)) -> 0
A14: 二、按照账龄分类
A15: 项目 | B15: 期初数 | F15: 期末数 | J15: 本期审定数与上期 审定数的比较 | L15: 原因分析
B16: 未审数 | C16: 账项调整 | D16: 重分类调整 | E16: 审定数 | F16: 未审数 | G16: 账项调整 | H16: 重分类调整 | I16: 审定数 | J16: 变动额 | K16: 变动率
A17: 1年以内（含1年） | E17: =B17+C17+D17 -> 0 | F17: ='明细表F4-2'!N32 -> 0 | G17: =I17-F17-H17 -> 0 | I17: ='明细表F4-2'!U32 -> 0 | J17: =I17-E17 -> 0 | K17: =IF(AND(E17=0,J17=0),0,IF(AND(E17=0,J17>0),1,J17/E17)) -> 0
A18: 1至2年（含2年） | E18: =B18+C18+D18 -> 0 | F18: ='明细表F4-2'!O32 -> 0 | G18: =I18-F18-H18 -> 0 | I18: ='明细表F4-2'!V32 -> 0 | J18: =I18-E18 -> 0 | K18: =IF(AND(E18=0,J18=0),0,IF(AND(E18=0,J18>0),1,J18/E18)) -> 0
A19: 2至3年（含3年） | E19: =B19+C19+D19 -> 0 | F19: ='明细表F4-2'!P32 -> 0 | G19: =I19-F19-H19 -> 0 | I19: ='明细表F4-2'!W32 -> 0 | J19: =I19-E19 -> 0 | K19: =IF(AND(E19=0,J19=0),0,IF(AND(E19=0,J19>0),1,J19/E19)) -> 0
A20: 3年以上 | E20: =B20+C20+D20 -> 0 | F20: ='明细表F4-2'!Q32 -> 0 | G20: =I20-F20-H20 -> 0 | I20: ='明细表F4-2'!X32 -> 0 | J20: =I20-E20 -> 0 | K20: =IF(AND(E20=0,J20=0),0,IF(AND(E20=0,J20>0),1,J20/E20)) -> 0
E21: =B21+C21+D21 -> 0 | I21: =F21+G21+H21 -> 0 | J21: =I21-E21 -> 0 | K21: =IF(AND(E21=0,J21=0),0,IF(AND(E21=0,J21>0),1,J21/E21)) -> 0
A22: 合计 | B22: =SUM(B17:B21) -> 0 | C22: =SUM(C17:C21) -> 0 | D22: =SUM(D17:D21) -> 0 | E22: =SUM(E17:E21) -> 0 | F22: =SUM(F17:F21) -> 0 | G22: =SUM(G17:G21) -> 0 | H22: =SUM(H17:H21) -> 0 | I22: =SUM(I17:I21) -> 0 | J22: =SUM(J17:J21) -> 0 | K22: =IF(AND(E22=0,J22=0),0,IF(AND(E22=0,J22>0),1,J22/E22)) -> 0
A23: 试算平衡表数
A24: 差异数 | E24: =E22-E23 -> 0 | I24: =I22-I23 -> 0
A25: 三、审计说明：
A26: （1）应付账款期末余额较期初余额增加（负数为减少）： | D26: =IF(E18=0,0,(I18-E18)/E18) -> 0
A27: 主要原因（比例超过30%的）：
A28: （2）……
A30: 四、审计结论：

Sheet 附注披露信息(上市公司)
A1: 致同会计师事务所
A2: 应付账款附注披露信息（上市公司）
A3: =底稿目录!A2 -> 被审计单位： | B3: =底稿目录!A4 -> 编制人： | C3: =底稿目录!A5 -> 编制日期： | D3: 索引号：
A4: =底稿目录!A3 -> 截止日：202X年12月31日 | B4: =底稿目录!A6 -> 复核人： | C4: =底稿目录!A7 -> 复核日期： | D4: 页次：
A5: 应付账款附注披露信息：
A6: 项 目 | C6: 期末余额 | D6: 上年年末余额
A7: 货款 | C7: ='审定表F4-1'!I8 -> 0 | D7: ='审定表F4-1'!E8 -> 0
A8: 工程款 | C8: ='审定表F4-1'!I9 -> 0 | D8: ='审定表F4-1'!E9 -> 0
A9: 可无限量添加行
A10: 合 计 | C10: =SUM(C7:C9) -> 0 | D10: =SUM(D7:D9) -> 0
A11: 其中，账龄超过1年的重要应付账款
A12: 项目 | B12: 期末余额 | C12: 未偿还或未结转的原因
A13: ='长期挂账检查表F4-5'!B9 -> 0 | B13: ='长期挂账检查表F4-5'!K9 -> 0 | C13: ='长期挂账检查表F4-5'!F9 -> 0
A14: ='长期挂账检查表F4-5'!B13 -> 0 | B14: ='长期挂账检查表F4-5'!K13 -> 0 | C14: ='长期挂账检查表F4-5'!F13 -> 0
A15: ='长期挂账检查表F4-5'!B14 -> 0 | B15: ='长期挂账检查表F4-5'!K14 -> 0 | C15: ='长期挂账检查表F4-5'!F14 -> 0
A16: 合 计 | B16: =SUM(B13:B15) -> 0

Sheet 附注披露信息(国企)
A1: 致同会计师事务所
A2: 应付账款附注披露信息（国企）
A3: =底稿目录!A2 -> 被审计单位： | C3: =底稿目录!A4 -> 编制人： | D3: =底稿目录!A5 -> 编制日期： | E3: 索引号：
A4: =底稿目录!A3 -> 截止日：202X年12月31日 | C4: =底稿目录!A6 -> 复核人： | D4: =底稿目录!A7 -> 复核日期： | E4: 页 次：
A5: 应付账款附注披露信息：
A6: 账 龄 | C6: 期末余额 | D6: 期初余额
A7: 1年以内（含1年） | C7: ='审定表F4-1'!I17 -> 0 | D7: ='审定表F4-1'!E17 -> 0
A8: 1至2年（含2年） | C8: ='审定表F4-1'!I18 -> 0 | D8: ='审定表F4-1'!E18 -> 0
A9: 2至3年（含3年） | C9: ='审定表F4-1'!I19 -> 0 | D9: ='审定表F4-1'!E19 -> 0
A10: 3年以上 | C10: ='审定表F4-1'!I20 -> 0 | D10: ='审定表F4-1'!E20 -> 0
A11: 合 计 | C11: =SUM(C7:C10) -> 0 | D11: =SUM(D7:D10) -> 0
A12: 账龄超过1年的重要应付账款
A13: 债权单位名称 | C13: 期末余额 | D13: 未偿还原因
A14: ='长期挂账检查表F4-5'!B9 -> 0 | C14: ='长期挂账检查表F4-5'!K9 -> 0 | D14: ='长期挂账检查表F4-5'!F9 -> 0
A15: ='长期挂账检查表F4-5'!B13 -> 0 | C15: ='长期挂账检查表F4-5'!K13 -> 0 | D15: ='长期挂账检查表F4-5'!F13 -> 0
A16: ='长期挂账检查表F4-5'!B14 -> 0 | C16: ='长期挂账检查表F4-5'!K14 -> 0 | D16: ='长期挂账检查表F4-5'!F14 -> 0
A17: 合计 | C17: =SUM(C14:C16) -> 0

Sheet 明细表F4-2
A1: 致同会计师事务所
A2: 应付账款明细表
A3: =底稿目录!A2 -> 被审计单位： | M3: =底稿目录!A4 -> 编制人： | T3: =底稿目录!A5 -> 编制日期： | Z3: 索引号： | AA3: =底稿目录!F7 -> F4-2
A4: =底稿目录!A3 -> 截止日：202X年12月31日 | M4: =底稿目录!A6 -> 复核人： | T4: =底稿目录!A7 -> 复核日期： | Z4: 页 次：
A5: 一、审计目标:
A6: 1. 资产负债表中记录的应付账款是存在的，且已经记录在恰当的账户中； 2. 所有应记录的应付账款均已记录，所有应当包括在财务报表中的相关披露均已包括；
A7: 3. 应付账款以恰当的金额包括在财务报表中，与之相关的计价或分摊调整已恰当记录，相关披露已得到恰当计量和描述
A8: 二、审计过程：
A9: 债权人名称 | B9: 公司代码 | C9: 关联方类型 | D9: 款项性质 | E9: 期初未审余额 | F9: 期初账项调整 | G9: 期初重分类调整 | H9: 期初审定余额 | I9: 借方发生 | J9: 贷方发生 | K9: 期末余额 | L9: 被审计单位重分类调整 | M9: 期末未审余额 | N9: 未审账龄 | R9: 账项调整 | S9: 重分类调整 | T9: 审定数 | U9: 审定账龄 | Y9: 是否函证 | Z9: 期后付款 | AA9: 备注
C10: 关联方类型 | D10: 款项性质 | E10: 期初余额 | F10: 账项调整 | G10: 重分类调整 | H10: 期初审定 | I10: 借方发生 | J10: 贷方发生 | K10: 期末余额 | M10: 期末余额 | N10: 1年以下 | O10: 1～2年 | P10: ２～3年 | Q10: 3年以上 | U10: 1年以下 | V10: 1～2年 | W10: 2～3年 | X10: 3年以上
H11: =E11+F11+G11 -> 0 | K11: =E11+J11-I11 -> 0 | M11: =K11+L11 -> 0 | T11: =M11+R11+S11 -> 0
H12: =E12+F12+G12 -> 0 | K12: =E12+J12-I12 -> 0 | M12: =K12+L12 -> 0 | T12: =M12+R12+S12 -> 0
H13: =E13+F13+G13 -> 0 | K13: =E13+J13-I13 -> 0 | M13: =K13+L13 -> 0 | T13: =M13+R13+S13 -> 0
H14: =E14+F14+G14 -> 0 | K14: =E14+J14-I14 -> 0 | M14: =K14+L14 -> 0 | T14: =M14+R14+S14 -> 0
H15: =E15+F15+G15 -> 0 | K15: =E15+J15-I15 -> 0 | M15: =K15+L15 -> 0 | T15: =M15+R15+S15 -> 0
H16: =E16+F16+G16 -> 0 | K16: =E16+J16-I16 -> 0 | M16: =K16+L16 -> 0 | T16: =M16+R16+S16 -> 0
H17: =E17+F17+G17 -> 0 | K17: =E17+J17-I17 -> 0 | M17: =K17+L17 -> 0 | T17: =M17+R17+S17 -> 0
H18: =E18+F18+G18 -> 0 | K18: =E18+J18-I18 -> 0 | M18: =K18+L18 -> 0 | T18: =M18+R18+S18 -> 0
H19: =E19+F19+G19 -> 0 | K19: =E19+J19-I19 -> 0 | M19: =K19+L19 -> 0 | T19: =M19+R19+S19 -> 0
H20: =E20+F20+G20 -> 0 | K20: =E20+J20-I20 -> 0 | M20: =K20+L20 -> 0 | T20: =M20+R20+S20 -> 0
H21: =E21+F21+G21 -> 0 | K21: =E21+J21-I21 -> 0 | M21: =K21+L21 -> 0 | T21: =M21+R21+S21 -> 0
H22: =E22+F22+G22 -> 0 | K22: =E22+J22-I22 -> 0 | M22: =K22+L22 -> 0 | T22: =M22+R22+S22 -> 0
... H31: =E31+F31+G31 -> 0 | K31: =E31+J31-I31 -> 0 | M31: =K31+L31 -> 0 | T31: =M31+R31+S31 -> 0
A32: 合计 | E32: =SUM(E11:E31) -> 0 | F32: =SUM(F11:F31) -> 0 | G32: =SUM(G11:G31) -> 0 | H32: =E32+F32+G32 -> 0 | I32: =SUM(I11:I31) -> 0 | J32: =SUM(J11:J31) -> 0 | K32: =SUM(K11:K31) -> 0 | M32: =SUM(M11:M31) -> 0 | N32: =SUM(N11:N31) -> 0 | O32: =SUM(O11:O31) -> 0 | P32: =SUM(P11:P31) -> 0 | Q32: =SUM(Q11:Q31) -> 0 | R32: =SUM(R11:R31) -> 0 | S32: =SUM(S11:S31) -> 0 | T32: =SUM(T11:T31) -> 0 | ... X32: =SUM(X11:X31) -> 0 | Z32: =SUM(Z11:Z31) -> 0
M33: =IF((M32-N32-O32-P32-Q32)=0,"OK","账龄与审定不匹配") -> OK | T33: =IF((T32-U32-V32-W32-X32)=0,"OK","账龄与审定不匹配") -> OK
A34: 三、审计说明：
A35: 1.期初数与上期审定数一致,期末总账、明细账、报表相符。
A36: 2.与期初相比，期末余额变动较大的原因：
A37: 3.**应付账款发生额大，其主要原因列示如下：
A38: 4.超过1年的大额应付账款，其性质及发生原因如下：
A39: 5.**供应商期后付款超过资产负债表日余额的原因如下：
A40: 四、审计结论：
A43: 提示：
A44: 1.账龄超过1年的大额应付账款，应说明未偿还或未结转的原因，并在资产负债表日后事项中说明是否偿还。
A45: 2.账龄超过3年以上的应付账款应说明未偿还的原因。
A46: 4.审计说明可以概述：（1）程序的测试情况、结果；（2）拟调整事项及其调整分录、未调整事项及其影响，审计范围受到限制情况及其影响。
A47: 5.审计结论可参考：A、未见异常。 B、除上述重大不符事项应当作为调整事项予以调整外，其余未见异常。 C、由于存在以下重大未调整事项（或审计范围受到限制无法获取充分、适当证据），不可确认。

Sheet 调整分录汇总F4-3
A1: 致同会计师事务所
A2: 应付账款调整分录汇总表
A3: =底稿目录!A2 -> 被审计单位： | D3: =底稿目录!A4 -> 编制人： | F3: =底稿目录!A5 -> 编制日期： | I3: 索引号： | J3: =底稿目录!F8 -> F4-3
A4: =底稿目录!A3 -> 截止日：202X年12月31日 | D4: =底稿目录!A6 -> 复核人： | F4: =底稿目录!A7 -> 复核日期： | I4: 页 次：
A5: 调整事项说明 | B5: 类别（报表调整/账项调整/其他） | C5: 报表项目 | D5: 科目名称 | E5: 附注项目 | F5: …… | G5: 借方调整金额 | H5: 贷方调整金额 | I5: 索引 | J5: 备注
A22: 【注：本底稿适用于调整分录较多、较复杂的项目，且仅列示与本报表项目相关的审计调整。项目组可根据项目实际情况选择是否使用该底稿。】

Sheet 实质性分析F4-4
A1: 致同会计师事务所
A2: 应付账款实质性分析表
A3: =底稿目录!A2 -> 被审计单位： | B3: =底稿目录!A4 -> 编制人： | D3: =底稿目录!A5 -> 编制日期： | E3: 索引号： | F3: =底稿目录!F9 -> F4-4
A4: =底稿目录!A3 -> 截止日：202X年12月31日 | B4: =底稿目录!A6 -> 复核人： | D4: =底稿目录!A7 -> 复核日期： | E4: 页 次：
A5: 一、审计目标:
A6: 1.资产负债表中记录的应付账款是存在的，且已经记录在恰当的账户中；
A7: 2.所有应记录的应付账款均已记录，所有应当包括在财务报表中的相关披露均已包括；
A8: 3.应付账款以恰当的金额包括在财务报表中，与之相关的计价或分摊调整已恰当记录，相关披露已得到恰当计量和描述 。
A9: 二、审计过程：
A10: 1、应付账款周转率（支付期）分析
A11: 项目 | B11: 本期金额 | C11: 上期金额 | D11: 备注
A12: 期初应付账款 | B12: ='审定表F4-1'!E13 -> 0
A13: 期末应付账款 | B13: ='审定表F4-1'!I13 -> 0 | C13: ='审定表F4-1'!E13 -> 0
A14: 主营业务成本
A15: 存货期初余额
A16: 存货期末余额
A17: 应付账款周转率 | B17: =(B14+B16-B15)/((B12+B13)/2) -> #DIV/0! | C17: =(C14+C16-C15)/((C12+C13)/2) -> #DIV/0!
A18: 平均周转(支付）天数（天） | B18: =365/B17 -> #DIV/0! | C18: =365/C17 -> #DIV/0!
A19: 同行业应付账款平均周转率
A20: 与同行业应收账款周转率的差异 | B20: =B17-B19 -> #DIV/0! | C20: =C17-C19 -> #DIV/0!
A21: 审计说明：
A24: 2、期末应付账款前十名（审定数）分析
A25: 债权人名称 | B25: 期末余额 | C25: 上年年末余额 | D25: 变动金额 | E25: 变动比例 | F25: 发生原因（款项性质）
A26: 债权人1 | D26: =B26-C26 -> 0 | E26: =D26/C26 -> #DIV/0!
A27: 债权人2 | D27: =B27-C27 -> 0 | E27: =D27/C27 -> #DIV/0!
A28: 债权人3 | D28: =B28-C28 -> 0 | E28: =D28/C28 -> #DIV/0!
A29: 债权人4 | D29: =B29-C29 -> 0 | E29: =D29/C29 -> #DIV/0!
A30: 债权人5 | D30: =B30-C30 -> 0 | E30: =D30/C30 -> #DIV/0!
A31: 债权人6 | D31: =B31-C31 -> 0 | E31: =D31/C31 -> #DIV/0!
A32: 债权人7 | D32: =B32-C32 -> 0 | E32: =D32/C32 -> #DIV/0!
A33: 债权人8 | D33: =B33-C33 -> 0 | E33: =D33/C33 -> #DIV/0!
A34: 债权人9 | D34: =B34-C34 -> 0 | E34: =D34/C34 -> #DIV/0!
A35: 债权人10 | D35: =B35-C35 -> 0 | E35: =D35/C35 -> #DIV/0!
A36: 小计 | B36: =SUM(B26:B35) -> 0 | C36: =SUM(C26:C35) -> 0 | D36: =SUM(D26:D35) -> 0 | E36: =D36/C36 -> #DIV/0!
A37: 审计说明：
A40: 三、审计结论：

Sheet 长期挂账检查表F4-5
A1: 致同会计师事务所
A2: 账龄1年以上的应付账款检查表
A3: =底稿目录!A2 -> 被审计单位： | D3: =底稿目录!A4 -> 编制人： | G3: =底稿目录!A5 -> 编制日期： | J3: 索引号： | K3: =底稿目录!F17 -> F4-5
A4: =底稿目录!A3 -> 截止日：202X年12月31日 | D4: =底稿目录!A6 -> 复核人： | G4: =底稿目录!A7 -> 复核日期： | J4: 页 次：
A5: 一、审计目标：
A6: 资产负债表中记录的应付账款是存在的，且已经记录在恰当的账户中
A7: 二、审计过程：
A8: 债权人名称 | B8: 期末余额 | C8: 账龄 | D8: 经济业务说明 | E8: 未偿还或未结转的原因 | F8: 是否无法支付 | G8: 是否诉讼 | H8: 支付计划 | I8: 审定金额 | J8: 支持性证据 | K8: 备注
A15: 合计 | B15: =SUM(B9:B14) -> 0 | I15: =SUM(I9:I14) -> 0
A16: 三、审计说明：
A19: 四、审计结论：

Sheet 关联方及交易检查表F4-6
A1: 致同会计师事务所
A2: 应付账款关联方及交易检查表
A3: =底稿目录!A2 -> 被审计单位： | E3: =底稿目录!A4 -> 编制人： | I3: =底稿目录!A5 -> 编制日期： | K3: 索引号： | L3: =底稿目录!F18 -> F4-6
A4: =底稿目录!A3 -> 截止日：202X年12月31日 | E4: =底稿目录!A6 -> 复核人： | I4: =底稿目录!A7 -> 复核日期： | K4: 页 次：
A5: 关注对关联方应付账款的真实性、合理性、合法性、会计处理是否正确，考虑是否存在未识别的关联方，检查关联交易和余额披露是否正确。
A6: 关联方名称 | B6: 关联关系 | C6: 期初余额 | D6: 本期借方 | E6: 本期贷方 | F6: 期末余额 | G6: 账龄 | H6: 定价政策 | I6: 发生原因（款项性质） | J6: 期后付款金额 | K6: 索引号 | L6: 备注
F7: =C7+E7-D7 -> 0
F8: =C8+E8-D8 -> 0
F9: =C9+E9-D9 -> 0
F10: =C10+E10-D10 -> 0
F11: =C11+E11-D11 -> 0
A12: 合计 | C12: =SUM(C7:C11) -> 0 | D12: =SUM(D7:D11) -> 0 | E12: =SUM(E7:E11) -> 0 | F12: =SUM(F7:F11) -> 0 | J12: =SUM(J7:J11) -> 0
A13: 1、审计说明：
A15: 2、审计结论：
B17: 勿改、勿删
B18: 实际控制人
B19: 控股股东
B20: 控股股东、实际控制人的附属企业
B21: 持有5%以上股份的法人或其他组织
B22: 联营企业
B23: 合营企业
B24: 董高监等关键管理人员
B25: 其他关联方

Sheet 未入账检查表F4-7
A1: 致同会计师事务所
A2: 未入账应付账款情况检查表
A3: =底稿目录!A2 -> 被审计单位： | E3: =底稿目录!A4 -> 编制人： | G3: =底稿目录!A5 -> 编制日期： | J3: 索引号： | K3: =底稿目录!F19 -> F4-7
A4: =底稿目录!A3 -> 截止日：202X年12月31日 | E4: =底稿目录!A6 -> 复核人： | G4: =底稿目录!A7 -> 复核日期： | J4: 页 次：
A5: 一、审计目标：
A6: 所有应记录的应付账款均已记录，所有应当包括在财务报表中的相关披露均已包括
A7: 二、审计过程：
A8: 1.分析大额供应商应付账款平均付款期，考虑期后付款金额大于期末余额的情况下，是否在平均付款天数内；
A9: 2.检查资产负债表日是否存在料到单未到的存货暂估入库；
A10: 3.检查截止审计现场结束日未处理的供应商发票，是否与期末负债有关；
A11: 4.检查资产负债表日后付款凭证，银行对账单及有关付款凭证；
A12: 5.检查资产负债表日后应付账款增加凭证，关注购货发票日期，入账期间是否合理；
A13: （一）期后付款是否在平均付款天数内：
A14: 序号 | B14: 供应商名称 | C14: 期初余额 | D14: 本期借方 | E14: 本期贷方 | F14: 期末余额 | G14: 平均付款天数 | H14: 期后付款金额 | I14: 差异 | J14: 期后付款是否在平均付款天数内 | K14: 备注
F15: =C15+E15-D15 -> 0 | G15: =365/(E15/F15) -> #DIV/0! | I15: =H15-F15 -> 0
F16: =C16+E16-D16 -> 0 | G16: =365/(E16/F16) -> #DIV/0! | I16: =H16-F16 -> 0
F17: =C17+E17-D17 -> 0 | G17: =365/(E17/F17) -> #DIV/0! | I17: =H17-F17 -> 0
F18: =C18+E18-D18 -> 0 | G18: =365/(E18/F18) -> #DIV/0! | I18: =H18-F18 -> 0
F19: =C19+E19-D19 -> 0 | G19: =365/(E19/F19) -> #DIV/0! | I19: =H19-F19 -> 0
F20: =C20+E20-D20 -> 0 | G20: =365/(E20/F20) -> #DIV/0! | I20: =H20-F20 -> 0
F21: =C21+E21-D21 -> 0 | G21: =365/(E21/F21) -> #DIV/0! | I21: =H21-F21 -> 0
F22: =C22+E22-D22 -> 0 | G22: =365/(E22/F22) -> #DIV/0! | I22: =H22-F22 -> 0
F23: =C23+E23-D23 -> 0 | G23: =365/(E23/F23) -> #DIV/0! | I23: =H23-F23 -> 0
F24: =C24+E24-D24 -> 0 | G24: =365/(E24/F24) -> #DIV/0! | I24: =H24-F24 -> 0
A25: 合计 | C25: =SUM(C15:C24) -> 0 | D25: =SUM(D15:D24) -> 0 | E25: =SUM(E15:E24) -> 0 | F25: =SUM(F15:F24) -> 0 | G25: =365/(E25/F25) -> #DIV/0! | H25: =SUM(H15:H24) -> 0 | I25: =SUM(I15:I24) -> 0
A26: （二）资产负债表日是否存在料到单未到的经济业务——存货暂估入库：
A27: 序号 | B27: 入库单 | E27: 合同单价 | F27: 暂估金额 | G27: 记账凭证 | J27: 是否应调整 | K27: 备注
B28: 日期 | C28: 编号 | D28: 数量 | G28: 日期 | H28: 凭证号 | I28: 金额
F29: =D29*E29 -> 0
F30: =D30*E30 -> 0
F31: =D31*E31 -> 0
F32: =D32*E32 -> 0
F33: =D33*E33 -> 0
F34: =D34*E34 -> 0
F35: =D35*E35 -> 0
F36: =D36*E36 -> 0
F37: =D37*E37 -> 0
F38: =D38*E38 -> 0
F39: =D39*E39 -> 0
F40: =D40*E40 -> 0
...

Sheet 应付账款检查表F4-8
A1: 致同会计师事务所
A2: 应付账款检查表
A3: =底稿目录!A2 -> 被审计单位： | H3: =底稿目录!A4 -> 编制人： | L3: =底稿目录!A5 -> 编制日期： | P3: 索引号： | Q3: =底稿目录!F20 -> F4-8
A4: =底稿目录!A3 -> 截止日：202X年12月31日 | H4: =底稿目录!A6 -> 复核人： | L4: =底稿目录!A7 -> 复核日期： | P4: 页 次：
A5: 一、审计目标：
A6: 1.产负债表中记录的应付账款是存在的，且已经记录在恰当的账户中； 2.记录的应付账款由被审计单位拥有或控制；
A7: 3.应付账款以恰当的金额包括在财务报表中，与之相关的计价或分摊调整已恰当记录，相关披露已得到恰当计量和描述
A8: 二、样本选取标准与规模：
A9: 测试总体： | B9: 如应付账款借方发生额所有凭证共XX笔金额XX、贷方发生额所有凭证共XX笔金额XX | I9: 特定样本： | J9: XX金额以上（大额）、关联方/关联交易形成的款项、XX异常款项全部测试，共XX笔；
A10: 抽样总体： | B10: 测试总体扣除特定样本以外的样本，共XX笔、金额XX | I10: 确定的抽样样本量： | K10: 抽取XX笔 | L10: （如果使用了样本计算器计算样本量，样本量计算过程见<XX>底稿）
A11: 抽样方法： | B11: 随机选样/系统选样/货币单元抽样/随意选样（非统计抽样适用） | I11: 抽样过程： | J11: 使用IDEA（XX抽样工具）选择XX数量、金额XX的样本进行测试，抽样工具中的样本选择过程和结果见<XX>底稿
A12: 三、测试：
A13: 测试内容说明：1.原始凭证是否齐全； 2.记账凭证与原始凭证是否相符；3.账务处理是否正确；4.是否记录于恰当的会计期间；5.……
A14: 1.本期借方金额检查
A15: 记账凭证 | H15: 付款审批单 | J15: 银行回单 | M15: …… | N15: 索引号 | O15: 是否异常
A16: 供应商名称 | B16: 日期 | C16: 凭证编号 | D16: 业务内容 | E16: 对方科目 | F16: 明细科目 | G16: 借方金额 | H16: 日期/编号 | I16: 是否经过恰当审批 | J16: 日期 | K16: 收款方 | L16: 金额 | R16: 检查的关键证据和要素根据被审计单位具体情况修改
A38: 合计 | G38: =SUM(G17:G37) -> 0 | L38: =SUM(L17:L37) -> 0 | O38: =SUM(O17:O37) -> 0
A39: 2.本期贷方金额检查（可结合存货采购入库检查<F2-33>完成）
A40: 记账凭证 | H40: 入库单/验收单 | L40: 采购发票 | O40: …… | P40: 索引号 | Q40: 是否异常
A41: 供应商名称 | B41: 日期 | C41: 凭证编号 | D41: 业务内容 | E41: 对方科目 | F41: 明细科目 | G41: 贷方金额 | H41: 日期/编号 | I41: 品名 | J41: 单位 | K41: 数量 | L41: 日期/编号 | M41: 对手方名称 | N41: 金额 | R41: 检查的关键证据和要素根据被审计单位具体情况修改
A58: 合计 | G58: =SUM(G42:G57) -> 0 | N58: =SUM(N42:N57) -> 0
A59: 四、审计说明：
A60: 1.本期发生额检查比例： | D60: 方向 | E60: 账面金额 | F60: 检查金额 | G60: 检查比例 | H60: 如果检查比例较低应扩大检查样本量或说明原因
D61: 本期借方 | E61: ='明细表F4-2'!I32 -> 0 | F61: =G38 -> 0 | G61: =ROUND(F61/E61,4) -> #DIV/0!
D62: 本期贷方 | E62: ='明细表F4-2'!J32 -> 0 | F62: =G58 -> 0 | G62: =ROUND(F62/E62,2) -> #DIV/0!
A63: 2.……
A64: 五、审计结论：

Sheet 供应商融资检查表F4-9
A1: 致同会计师事务所
A2: 供应商融资检查表
A3: =底稿目录!A2 -> 被审计单位： | E3: =底稿目录!A4 -> 编制人： | I3: =底稿目录!A5 -> 编制日期： | M3: 索引号： | N3: =底稿目录!F21 -> F4-9
A4: =底稿目录!A3 -> 截止日：202X年12月31日 | E4: =底稿目录!A6 -> 复核人： | I4: =底稿目录!A7 -> 复核日期： | M4: 页 次：
A5: 一、审计目标：
A6: 1.所有应记录的应付账款均已记录，所有应当包括在财务报表中的相关披露均已包括
A7: 2.应付账款已被恰当地汇总或分解且表述清楚，供应商融资相关披露在按照企业会计准则的编制基础下是相关的、可理解的
A8: 二、审计过程：
A9: 1.从供应链融资平台导出的供应链融资明细表，将其中的供应商融资与企业供应商融资台账核对一致；
A10: 2.检查供应商融资金额与采购金额的差异，关注是否存在虚假采购合同的供应商融资，检查对金融机构直接支付给供应商款项的账务处理和披露是否正确、完整
A11: 供应商名称 | B11: 承诺付款方 | C11: 融资单号 | D11: 资金提供方（金融机构） | E11: 状态 | F11: 融资金额 | G11: 供应商签收日期 | H11: 放款日期 | I11: 转让日期 | J11: 承诺还款日期 | K11: 实际还款日期 | L11: 本期采购金额 | M11: 差异 | N11: 借款余额
A12: 供应商1
A13: 供应商1
A16: 小计 | F16: =SUM(F12:F15) -> 0 | M16: =F16-L16 -> 0 | O16: 如果供应商融资金额大于采购金额重点关注供应商资金流向，是否存在体外资金循环，必要时执行供应商资金穿透检查程序
A17: 供应商2
A18: 供应商2
A21: 小计 | F21: =SUM(F17:F20) -> 0 | M21: =F21-L21 -> 0
A22: 供应商3
A23: 供应商3
A26: 小计 | F26: =SUM(F22:F25) -> 0 | M26: =F26-L26 -> 0
A27: 合计 | F27: =F26+F21+F16 -> 0 | L27: =L26+L21+L16 -> 0 | M27: =M26+M21+M16 -> 0 | N27: =N26+N21+N16 -> 0
A28: 三、审计说明：
A31: 四、审计结论：

Sheet GT_Custom
A1: C1 | B1: Custom 1
A2: C2 | B2: Custom 2
A3: C3 | B3: Custom 3
A4: C4 | B4: Custom 4
A5: C5 | B5: Custom 5
A6: C6 | B6: Custom 6
A7: C7 | B7: Custom 7
A8: C8 | B8: Custom 8
