Workbook
Name AS2DocOpenMode: "AS2DocumentEdit"
Name a暗暗: [1]企业表一!$F$20
Name ffd: [1]企业表一!$E$20

Sheet 底稿目录
A1: 底稿开列时，可先在以下单元格填写有关内容，以便其他底稿引用有关数据：
A2: 被审计单位： | D2: 序号 | E2: 内容 | F2: 索引号
A3: 会计期间：202X年度 | D3: 1 | E3: 营业成本实质性程序表 | F3: F5A
A4: 编制人： | D4: =D3+1 -> 2 | E4: 营业务成本审定表 | F4: F5-1
A5: 编制日期： | D5: =D4+1 -> 3 | E5: 主营业务成本月度明细表 | F5: F5-2
A6: 复核人： | D6: =D5+1 -> 4 | E6: 其他业务成本明细表 | F6: F5-3
A7: 复核日期： | D7: =D6+1 -> 5 | E7: 调整分录汇总 | F7: F5-4
D8: =D7+1 -> 6 | E8: 主营业务成本与上年度比较分析表 | F8: F5-5
A9: 关于工作底稿与审计程序索引号对应的说明 | D9: =D8+1 -> 7 | E9: 销售数量与结转成本数量核对明细表 | F9: F5-6
A10: 1.编制的审计工作底稿应与审计程序对应。审计项目组应根据被审计单位实际情况和风险评估情况在实质性程序表中裁剪、修改或增加审计程序，根据实际执行的审计程序完成相应审计工作底稿，编制的工作底稿中应按自然顺序依次编制索引号，并通过唯一的索引号将与实质性程序表中的程序对应关联（即将工作底稿的索引号填入实质性程序表中的底稿索引号列）。 | D10: =D9+1 -> 8 | E10: 主营业务成本倒轧表 | F10: F5-7
D11: =D10+1 -> 9 | E11: 主营业务成本账户中重大调整事项核查表 | F11: F5-8
A14: 2.获取的支持性证据应与审计底稿或程序对应。审计项目组在完成底稿时获取的支持性证据应根据底稿索引号编制下一级按自然顺序排序的索引号（如D1-2-1、D1-2-2、……），并在底稿中说明引用的支持性证据、关联索引号。
A17: 3.工作底稿索引号的编码规则：实质性程序索引号按循环从“D”到“N”,循环内账户以顺序号排列，模板中底稿索引号按账户顺序+自然数顺序（即模板中索引号按二级自然顺序排列，如D1-1、D1-2、D1-3、……D1-N）。

Sheet 营业成本实质性程序表F5A
A1: 致同会计师事务所
A2: 营业成本实质性程序
A3: =底稿目录!A2 -> 被审计单位： | C3: =底稿目录!A4 -> 编制人： | E3: =底稿目录!A5 -> 编制日期： | H3: 索引号： | I3: =底稿目录!F3 -> F5A
A4: =底稿目录!A3 -> 会计期间：202X年度 | C4: =底稿目录!A6 -> 复核人： | E4: =底稿目录!A7 -> 复核日期： | H4: 页 次：
A5: 一、本账户涉及的科目
A6: 主营业务成本、其他业务成本
A7: 二、审计目标与认定的对应关系
A8: 审计目标 | G8: 财务报表的认定
A9: A. 利润表中记录的营业成本已发生，且与被审计单位有关，已记录于恰当的账户 | G9: 发生
A10: B. 所有应当记录的营业成本均已记录，所有应当包括在财务报表中的相关披露均已包括 | G10: 完整性
A11: C. 与营业成本有关的金额及其他数据已恰当记录，相关披露已得到恰当计量和描述 | G11: 准确性
A12: D. 营业成本已记录于正确的会计期间 | G12: 截止
A13: E. 营业成本已被恰当地汇总或分解且表述清楚，相关披露在按照企业会计准则的编制基础下是相关的、可理解的 | G13: 列报
A14: 三、计划实施的实质性程序
A15: 序号 | B15: 审计程序 | C15: 程序分类 | D15: 财务报表的认定 | I15: 底稿索引号
D16: 发生 | E16: 完整性 | F16: 准确性 | G16: 截止 | H16: 列报 | J16: 根据被审计单位实际情况和风险评估情况裁剪、修改或增加审计程序
A17: 1 | B17: 获取或编制主营业务成本、其他业务成本明细表，复核加计是否正确，并与总账数和明细账合计数核对是否相符，编制审定表，结合其他业务成本科目与营业成本报表数核对是否相符。 | C17: 常规★ | D17: √ | E17: √ | F17: √ | I17: F5-1/F5-2/F5-3
A18: 2 | B18: 在使用手工编制、自定义信息报告、系统生成的非固定格式报告等由被审计单位生成的信息时，测试有关信息准确性和完整性，并考虑针对编制和维护由被审计单位生成的信息的相关控制实施控制测试，以评价该信息是否能够为实现审计目的提供基础。 | C18: 常规★ | E18: √ | F18: √ | I18: T1/ | J18: 可参见《审计手册》4.2.6，由被审计单位生成的信息可能是由系统生成的、或手工编制的、或二者兼而有之的方式生成的。例如，由被审计单位生成的信息可能包括： • 不涉及自定义的、由系统生成的报告（如，固定格式报告）； • 可能通过人工自定义的、由系统生成的报告，例如，（计算机）查询信息或特别定制的报告； • 手工编制的信息，例如，汇总信息的电子表格或用以支持分配、计算以及调节的电子表格； • 其他系统生成或手工编制的信息，例如，由被审计单位编制的客户发票； • 通过影印、拍摄、扫描或其他方式转换成电子形式的文件记录。
A19: 3 | B19: 结合存货期初余额审计，确定营业成本前期期末的截止是否恰当。（适用于首次承接） | C19: 备选 | G19: √ | J19: 由被审计单位生成的信息不包括： • 总分类账或明细分类账、试算平衡表、或经审计的财务报表； • 第三方（除了服务机构）的报表或报告，例如，原始银行对账单，或函证的回函； • 外部数据（例如，第三方发布的数据，如，定价来源）。
A20: 4 | B20: 关注会计政策、会计估计合理性、一贯性，关注其是否利用会计政策和会计估计及其变更操纵利润。 （1）了解、分析主营业务成本结转政策及流程的合理性，是否符合实际经营情况和会计准则的要求，并与前期进行对比，分析其是否保持一贯性； （2）关注主营业务成本的内容和计算方法是否符合会计准则规定，前后期是否一致。 | C20: 常规★ | D20: √ | E20: √ | I20: F2-16
A21: 5 | B21: 分析主营业务成本： （1）将本期和上期主营业务成本按月度进行比较分析； （2）将本期和上期产品总成本的构成（如原材料，人工及制造费用）进行比较分析； （3）将本期和上期的主要产品单位成本进行比较分析； | C21: 常规★ | D21: √ | E21: √ | F21: √ | I21: F5-2 /F5-5
A22: 6 | B22: 检查月主营业务成本结转明细清单，比较计人主营业务成本的品种、规格、数量和计入主营业务收人的口径是否一致，是否符合配比原则。 | C22: 常规★ | D22: √ | E22: √ | I22: F5-6
A23: 7 | B23: 编制生产成本与主营业务成本倒轧表，并与相关科目交叉索引 | C23: 常规★ | D23: √ | E23: √ | F23: √ | I23: F5-7
A24: 8 | B24: 结合存货账户检查，针对主营业务成本中重大调整事项(如销售退回)、返利、非常规项目，检查相关原始凭证，评价真实性和合理性，检查其会计处理是否正确。 | C24: 常规★ | D24: √ | E24: √ | F24: √ | G24: √ | H24: √ | I24: F5-8
A25: 9 | B25: 结合营业收入、存货产成品出库检查，同时检查营业成本支持性文件，确定原始凭证是否齐全、记账凭证与原始凭证是否相符以及账务处理是否正确。 | C25: 常规★ | D25: √ | F25: √ | G25: √ | H25: √
A26: 10 | B26: 在采用计划成本、定额成本、标准成本或售价核算存货的条件下，结合存货标准成本差异和分摊的测试，检查产品成本差异或商品进销差价的计算、分配和会计处理是否正确。 | C26: 备选 | F26: √ | I26: F2-40
A27: 11 | B27: 根据评估的舞弊风险等因素增加的审计程序。 | C27: IPO/上市/新三板/重组/舞弊应对
A28: 12 | B28: 检查营业成本是否已按企业会计准则或其他适用的规定在财务报表中做出恰当列报和披露。 | C28: 常规★ | H28: √ | I28: A1-1/A1-15 /A1-16

Sheet 营业务成本审定表F5-1
A1: 致同会计师事务所
A2: 营业务成本审定表
A3: =底稿目录!A2 -> 被审计单位： | D3: =底稿目录!A4 -> 编制人： | G3: =底稿目录!A5 -> 编制日期： | I3: 索引号： | J3: =底稿目录!F4 -> F5-1
A4: =底稿目录!A3 -> 会计期间：202X年度 | D4: =底稿目录!A6 -> 复核人： | G4: =底稿目录!A7 -> 复核日期： | I4: 页 次：
A5: 项目 | B5: 本期数 | F5: 上期数 | J5: 索引
B6: 本期未审数 | C6: 账项调整 | D6: 重分类调整 | E6: 本期审定数 | F6: 上期未审数 | G6: 账项调整 | H6: 重分类调整 | I6: 上期审定数
A7: 主营业业成本：
A8: ='主营业务成本月度明细表F5-2'!A11 -> 品种1 | B8: ='主营业务成本月度明细表F5-2'!N11 -> 0 | C8: ='主营业务成本月度明细表F5-2'!O11 -> 0 | D8: ='主营业务成本月度明细表F5-2'!P11 -> 0 | E8: =B8+C8+D8 -> 0 | F8: ='主营业务成本月度明细表F5-2'!R11 -> 0 | G8: ='主营业务成本月度明细表F5-2'!S11 -> 0 | H8: ='主营业务成本月度明细表F5-2'!T11 -> 0 | I8: =F8+G8+H8 -> 0
A9: ='主营业务成本月度明细表F5-2'!A12 -> 品种2 | B9: ='主营业务成本月度明细表F5-2'!N12 -> 0 | C9: ='主营业务成本月度明细表F5-2'!O12 -> 0 | D9: ='主营业务成本月度明细表F5-2'!P12 -> 0 | E9: =B9+C9+D9 -> 0 | F9: ='主营业务成本月度明细表F5-2'!R12 -> 0 | G9: ='主营业务成本月度明细表F5-2'!S12 -> 0 | H9: ='主营业务成本月度明细表F5-2'!T12 -> 0 | I9: =F9+G9+H9 -> 0
A10: ='主营业务成本月度明细表F5-2'!A13 -> 品种3 | B10: ='主营业务成本月度明细表F5-2'!N13 -> 0 | C10: ='主营业务成本月度明细表F5-2'!O13 -> 0 | D10: ='主营业务成本月度明细表F5-2'!P13 -> 0 | E10: =B10+C10+D10 -> 0 | F10: ='主营业务成本月度明细表F5-2'!R13 -> 0 | G10: ='主营业务成本月度明细表F5-2'!S13 -> 0 | H10: ='主营业务成本月度明细表F5-2'!T13 -> 0 | I10: =F10+G10+H10 -> 0
A11: ='主营业务成本月度明细表F5-2'!A14 -> 品种4 | B11: ='主营业务成本月度明细表F5-2'!N14 -> 0 | C11: ='主营业务成本月度明细表F5-2'!O14 -> 0 | D11: ='主营业务成本月度明细表F5-2'!P14 -> 0 | E11: =B11+C11+D11 -> 0 | F11: ='主营业务成本月度明细表F5-2'!R14 -> 0 | G11: ='主营业务成本月度明细表F5-2'!S14 -> 0 | H11: ='主营业务成本月度明细表F5-2'!T14 -> 0 | I11: =F11+G11+H11 -> 0
A12: ='主营业务成本月度明细表F5-2'!A15 -> 品种5 | B12: ='主营业务成本月度明细表F5-2'!N15 -> 0 | C12: ='主营业务成本月度明细表F5-2'!O15 -> 0 | D12: ='主营业务成本月度明细表F5-2'!P15 -> 0 | E12: =B12+C12+D12 -> 0 | F12: ='主营业务成本月度明细表F5-2'!R15 -> 0 | G12: ='主营业务成本月度明细表F5-2'!S15 -> 0 | H12: ='主营业务成本月度明细表F5-2'!T15 -> 0 | I12: =F12+G12+H12 -> 0
A13: ='主营业务成本月度明细表F5-2'!A16 -> 品种6 | B13: ='主营业务成本月度明细表F5-2'!N16 -> 0 | C13: ='主营业务成本月度明细表F5-2'!O16 -> 0 | D13: ='主营业务成本月度明细表F5-2'!P16 -> 0 | E13: =B13+C13+D13 -> 0 | F13: ='主营业务成本月度明细表F5-2'!R16 -> 0 | G13: ='主营业务成本月度明细表F5-2'!S16 -> 0 | H13: ='主营业务成本月度明细表F5-2'!T16 -> 0 | I13: =F13+G13+H13 -> 0
A14: ='主营业务成本月度明细表F5-2'!A17 -> 品种7 | B14: ='主营业务成本月度明细表F5-2'!N17 -> 0 | C14: ='主营业务成本月度明细表F5-2'!O17 -> 0 | D14: ='主营业务成本月度明细表F5-2'!P17 -> 0 | E14: =B14+C14+D14 -> 0 | F14: ='主营业务成本月度明细表F5-2'!R17 -> 0 | G14: ='主营业务成本月度明细表F5-2'!S17 -> 0 | H14: ='主营业务成本月度明细表F5-2'!T17 -> 0 | I14: =F14+G14+H14 -> 0
A15: ='主营业务成本月度明细表F5-2'!A18 -> 品种8 | B15: ='主营业务成本月度明细表F5-2'!N18 -> 0 | C15: ='主营业务成本月度明细表F5-2'!O18 -> 0 | D15: ='主营业务成本月度明细表F5-2'!P18 -> 0 | E15: =B15+C15+D15 -> 0 | F15: ='主营业务成本月度明细表F5-2'!R18 -> 0 | G15: ='主营业务成本月度明细表F5-2'!S18 -> 0 | H15: ='主营业务成本月度明细表F5-2'!T18 -> 0 | I15: =F15+G15+H15 -> 0
A16: ='主营业务成本月度明细表F5-2'!A19 -> 0 | B16: ='主营业务成本月度明细表F5-2'!N19 -> 0 | C16: ='主营业务成本月度明细表F5-2'!O19 -> 0 | D16: ='主营业务成本月度明细表F5-2'!P19 -> 0 | E16: =B16+C16+D16 -> 0 | F16: ='主营业务成本月度明细表F5-2'!R19 -> 0 | G16: ='主营业务成本月度明细表F5-2'!S19 -> 0 | H16: ='主营业务成本月度明细表F5-2'!T19 -> 0 | I16: =F16+G16+H16 -> 0
A17: ='主营业务成本月度明细表F5-2'!A20 -> 0 | B17: ='主营业务成本月度明细表F5-2'!N20 -> 0 | C17: ='主营业务成本月度明细表F5-2'!O20 -> 0 | D17: ='主营业务成本月度明细表F5-2'!P20 -> 0 | E17: =B17+C17+D17 -> 0 | F17: ='主营业务成本月度明细表F5-2'!R20 -> 0 | G17: ='主营业务成本月度明细表F5-2'!S20 -> 0 | H17: ='主营业务成本月度明细表F5-2'!T20 -> 0 | I17: =F17+G17+H17 -> 0
A18: 小计 | B18: =SUM(B8:B17) -> 0 | C18: =SUM(C8:C17) -> 0 | D18: =SUM(D8:D17) -> 0 | E18: =SUM(E8:E17) -> 0 | F18: =SUM(F8:F17) -> 0 | G18: =SUM(G8:G17) -> 0 | H18: =SUM(H8:H17) -> 0 | I18: =SUM(I8:I17) -> 0
A19: 其他业务成本
E20: =B20+C20+D20 -> 0 | I20: =F20+G20+H20 -> 0
E21: =B21+C21+D21 -> 0 | I21: =F21+G21+H21 -> 0
E22: =B22+C22+D22 -> 0 | I22: =F22+G22+H22 -> 0
E23: =B23+C23+D23 -> 0 | I23: =F23+G23+H23 -> 0
E24: =B24+C24+D24 -> 0 | I24: =F24+G24+H24 -> 0
E25: =B25+C25+D25 -> 0 | I25: =F25+G25+H25 -> 0
A26: 小计 | B26: =SUM(B20:B25) -> 0 | C26: =SUM(C20:C25) -> 0 | D26: =SUM(D20:D25) -> 0 | E26: =SUM(E20:E25) -> 0 | F26: =SUM(F20:F25) -> 0 | G26: =SUM(G20:G25) -> 0 | H26: =SUM(H20:H25) -> 0 | I26: =SUM(I20:I25) -> 0
A27: 合计 | B27: =B26+B18 -> 0 | C27: =C26+C18 -> 0 | D27: =D26+D18 -> 0 | E27: =E26+E18 -> 0 | F27: =F26+F18 -> 0 | G27: =G26+G18 -> 0 | H27: =H26+H18 -> 0 | I27: =I26+I18 -> 0
A28: 试算平衡表数
A29: 差异数 | E29: =E27-E28 -> 0 | I29: =I27-I28 -> 0
A30: 1、审计说明
A31: （1）主营业务成本本期较上期增加（负数为减少）：
A32: 主要原因（比例超过30%的）：
A35: 2、审计结论
A39: 提示：
A40: 1.本科目核算企业确认的销售商品、提供劳务等主营业务的收入。
A41: 2.本科目可按主营业务的种类进行明细核算。

Sheet 主营业务成本月度明细表F5-2
A1: 致同会计师事务所
A2: 主营业务成本月度明细表
A3: =底稿目录!A2 -> 被审计单位： | H3: =底稿目录!A4 -> 编制人： | R3: =底稿目录!A5 -> 编制日期： | W3: 索引号： | X3: =底稿目录!F5 -> F5-2
A4: =底稿目录!A3 -> 会计期间：202X年度 | H4: =底稿目录!A6 -> 复核人： | R4: =底稿目录!A7 -> 复核日期： | W4: 页次：
A5: 一、审计目标：
A6: 1.利润表中记录的营业成本已发生，且与被审计单位有关，已记录于恰当的账户；2.所有应当记录的营业成本均已记录，所有应当包括在财务报表中的相关披露均已包括；
A7: 3. 与营业成本有关的金额及其他数据已恰当记录，相关披露已得到恰当计量和描述
A8: 二、审计过程
A9: 项目 月份 | B9: 主营业务成本分月小计 | N9: 本期未审数 | O9: 本期审计调整 | Q9: 本期审定数 | R9: 上期未审数 | S9: 上期审计调整 | U9: 上期审定数 | V9: 未审变动比例 | W9: 审定变动比例 | X9: 备注
B10: 1月 | C10: 2月 | D10: 3月 | E10: 4月 | F10: 5月 | G10: 6月 | H10: 7月 | I10: 8月 | J10: 9月 | K10: 10月 | L10: 11月 | M10: 12月 | O10: 账项调整 | P10: 重分类调整 | S10: 账项调整 | T10: 重分类调整
A11: 品种1 | N11: =SUM(B11:M11) -> 0 | Q11: =N11+O11+P11 -> 0 | U11: =R11+S11+T11 -> 0 | V11: =IF(AND(R11=0,N11-R11=0),0,IF(AND(R11=0,N11-R11>0),1,(N11-R11)/R11)) -> 0 | W11: =IF(AND(U11=0,Q11-U11=0),0,IF(AND(U11=0,Q11-U11>0),1,(Q11-U11)/U11)) -> 0
A12: 品种2 | N12: =SUM(B12:M12) -> 0 | Q12: =N12+O12+P12 -> 0 | U12: =R12+S12+T12 -> 0 | V12: =IF(AND(R12=0,N12-R12=0),0,IF(AND(R12=0,N12-R12>0),1,(N12-R12)/R12)) -> 0 | W12: =IF(AND(U12=0,Q12-U12=0),0,IF(AND(U12=0,Q12-U12>0),1,(Q12-U12)/U12)) -> 0
A13: 品种3 | N13: =SUM(B13:M13) -> 0 | Q13: =N13+O13+P13 -> 0 | U13: =R13+S13+T13 -> 0 | V13: =IF(AND(R13=0,N13-R13=0),0,IF(AND(R13=0,N13-R13>0),1,(N13-R13)/R13)) -> 0 | W13: =IF(AND(U13=0,Q13-U13=0),0,IF(AND(U13=0,Q13-U13>0),1,(Q13-U13)/U13)) -> 0
A14: 品种4 | N14: =SUM(B14:M14) -> 0 | Q14: =N14+O14+P14 -> 0 | U14: =R14+S14+T14 -> 0 | V14: =IF(AND(R14=0,N14-R14=0),0,IF(AND(R14=0,N14-R14>0),1,(N14-R14)/R14)) -> 0 | W14: =IF(AND(U14=0,Q14-U14=0),0,IF(AND(U14=0,Q14-U14>0),1,(Q14-U14)/U14)) -> 0
A15: 品种5 | N15: =SUM(B15:M15) -> 0 | Q15: =N15+O15+P15 -> 0 | U15: =R15+S15+T15 -> 0 | V15: =IF(AND(R15=0,N15-R15=0),0,IF(AND(R15=0,N15-R15>0),1,(N15-R15)/R15)) -> 0 | W15: =IF(AND(U15=0,Q15-U15=0),0,IF(AND(U15=0,Q15-U15>0),1,(Q15-U15)/U15)) -> 0
A16: 品种6 | N16: =SUM(B16:M16) -> 0 | Q16: =N16+O16+P16 -> 0 | U16: =R16+S16+T16 -> 0 | V16: =IF(AND(R16=0,N16-R16=0),0,IF(AND(R16=0,N16-R16>0),1,(N16-R16)/R16)) -> 0 | W16: =IF(AND(U16=0,Q16-U16=0),0,IF(AND(U16=0,Q16-U16>0),1,(Q16-U16)/U16)) -> 0
A17: 品种7 | N17: =SUM(B17:M17) -> 0 | Q17: =N17+O17+P17 -> 0 | U17: =R17+S17+T17 -> 0 | V17: =IF(AND(R17=0,N17-R17=0),0,IF(AND(R17=0,N17-R17>0),1,(N17-R17)/R17)) -> 0 | W17: =IF(AND(U17=0,Q17-U17=0),0,IF(AND(U17=0,Q17-U17>0),1,(Q17-U17)/U17)) -> 0
A18: 品种8 | N18: =SUM(B18:M18) -> 0 | Q18: =N18+O18+P18 -> 0 | U18: =R18+S18+T18 -> 0 | V18: =IF(AND(R18=0,N18-R18=0),0,IF(AND(R18=0,N18-R18>0),1,(N18-R18)/R18)) -> 0 | W18: =IF(AND(U18=0,Q18-U18=0),0,IF(AND(U18=0,Q18-U18>0),1,(Q18-U18)/U18)) -> 0
N19: =SUM(B19:M19) -> 0 | Q19: =N19+O19+P19 -> 0 | U19: =R19+S19+T19 -> 0 | V19: =IF(AND(R19=0,N19-R19=0),0,IF(AND(R19=0,N19-R19>0),1,(N19-R19)/R19)) -> 0 | W19: =IF(AND(U19=0,Q19-U19=0),0,IF(AND(U19=0,Q19-U19>0),1,(Q19-U19)/U19)) -> 0
N20: =SUM(B20:M20) -> 0 | Q20: =N20+O20+P20 -> 0 | U20: =R20+S20+T20 -> 0 | V20: =IF(AND(R20=0,N20-R20=0),0,IF(AND(R20=0,N20-R20>0),1,(N20-R20)/R20)) -> 0 | W20: =IF(AND(U20=0,Q20-U20=0),0,IF(AND(U20=0,Q20-U20>0),1,(Q20-U20)/U20)) -> 0
N21: =SUM(B21:M21) -> 0 | Q21: =N21+O21+P21 -> 0 | U21: =R21+S21+T21 -> 0 | V21: =IF(AND(R21=0,N21-R21=0),0,IF(AND(R21=0,N21-R21>0),1,(N21-R21)/R21)) -> 0 | W21: =IF(AND(U21=0,Q21-U21=0),0,IF(AND(U21=0,Q21-U21>0),1,(Q21-U21)/U21)) -> 0
N22: =SUM(B22:M22) -> 0 | Q22: =N22+O22+P22 -> 0 | U22: =R22+S22+T22 -> 0 | V22: =IF(AND(R22=0,N22-R22=0),0,IF(AND(R22=0,N22-R22>0),1,(N22-R22)/R22)) -> 0 | W22: =IF(AND(U22=0,Q22-U22=0),0,IF(AND(U22=0,Q22-U22>0),1,(Q22-U22)/U22)) -> 0
A23: 合计 | B23: =SUM(B11:B22) -> 0 | C23: =SUM(C11:C22) -> 0 | D23: =SUM(D11:D22) -> 0 | E23: =SUM(E11:E22) -> 0 | F23: =SUM(F11:F22) -> 0 | G23: =SUM(G11:G22) -> 0 | H23: =SUM(H11:H22) -> 0 | I23: =SUM(I11:I22) -> 0 | ... P23: =SUM(P11:P22) -> 0 | Q23: =N23+O23+P23 -> 0 | R23: =SUM(R11:R22) -> 0 | S23: =SUM(S11:S22) -> 0 | T23: =SUM(T11:T22) -> 0 | U23: =R23+S23+T23 -> 0 | V23: =IF(AND(R23=0,N23-R23=0),0,IF(AND(R23=0,N23-R23>0),1,(N23-R23)/R23)) -> 0 | W23: =IF(AND(U23=0,Q23-U23=0),0,IF(AND(U23=0,Q23-U23>0),1,(Q23-U23)/U23)) -> 0
A24: 比例 | B24: =IF(B23=0,0,B23/$N$23) -> 0 | C24: =IF(C23=0,0,C23/$N$23) -> 0 | D24: =IF(D23=0,0,D23/$N$23) -> 0 | E24: =IF(E23=0,0,E23/$N$23) -> 0 | F24: =IF(F23=0,0,F23/$N$23) -> 0 | G24: =IF(G23=0,0,G23/$N$23) -> 0 | H24: =IF(H23=0,0,H23/$N$23) -> 0 | I24: =IF(I23=0,0,I23/$N$23) -> 0 | ... N24: =IF(N23=0,0,N23/$N$23) -> 0
A25: 三、审计说明：
A28: 四、审计结论：

Sheet 其他业务成本明细表F5-3
A1: 致同会计师事务所
A2: 其他业务成本明细表
A3: =底稿目录!A2 -> 被审计单位： | E3: =底稿目录!A4 -> 编制人： | J3: =底稿目录!A5 -> 编制日期： | M3: 索引号： | N3: =底稿目录!F6 -> F5-3
A4: =底稿目录!A3 -> 会计期间：202X年度 | E4: =底稿目录!A6 -> 复核人： | J4: =底稿目录!A7 -> 复核日期： | M4: 页 次：
A5: 一、审计目标：
A6: 1.利润表中记录的营业成本已发生，且与被审计单位有关，已记录于恰当的账户；2.所有应当记录的营业成本均已记录，所有应当包括在财务报表中的相关披露均已包括；
A7: 3. 与营业成本有关的金额及其他数据已恰当记录，相关披露已得到恰当计量和描述
A8: 二、审计过程:
A9: 项目 | B9: 本期数 | G9: 上期数 | L9: 本期数比上期增加（减少） | N9: 备注
B10: 本期未审数 | C10: 账项调整 | D10: 重分类调整 | E10: 审定数 | F10: 结构比 | G10: 上期未审数 | H10: 账项调整 | I10: 重分类调整 | J10: 审定额 | K10: 结构比 | L10: 变动额 | M10: 变动率
A11: 出租固定资产 | E11: =B11+C11+D11 -> 0 | F11: =IF(E11=0,0,E11/E$22) -> 0 | J11: =G11+H11+I11 -> 0 | K11: =IF(J11=0,0,J11/$J$22) -> 0 | L11: =E11-J11 -> 0 | M11: =IF(AND(J11=0,L11=0),0,IF(AND(J11=0,L11>0),1,L11/J11)) -> 0
A12: 出租无形资产 | E12: =B12+C12+D12 -> 0 | F12: =IF(E12=0,0,E12/E$22) -> 0 | J12: =G12+H12+I12 -> 0 | K12: =IF(J12=0,0,J12/$J$22) -> 0 | L12: =E12-J12 -> 0 | M12: =IF(AND(J12=0,L12=0),0,IF(AND(J12=0,L12>0),1,L12/J12)) -> 0
A13: 出租包装物和商品 | E13: =B13+C13+D13 -> 0 | F13: =IF(E13=0,0,E13/E$22) -> 0 | J13: =G13+H13+I13 -> 0 | K13: =IF(J13=0,0,J13/$J$22) -> 0 | L13: =E13-J13 -> 0 | M13: =IF(AND(J13=0,L13=0),0,IF(AND(J13=0,L13>0),1,L13/J13)) -> 0
A14: 销售材料 | E14: =B14+C14+D14 -> 0 | F14: =IF(E14=0,0,E14/E$22) -> 0 | J14: =G14+H14+I14 -> 0 | K14: =IF(J14=0,0,J14/$J$22) -> 0 | L14: =E14-J14 -> 0 | M14: =IF(AND(J14=0,L14=0),0,IF(AND(J14=0,L14>0),1,L14/J14)) -> 0
A15: 用材料进行非货币性交换 | E15: =B15+C15+D15 -> 0 | F15: =IF(E15=0,0,E15/E$22) -> 0 | J15: =G15+H15+I15 -> 0 | K15: =IF(J15=0,0,J15/$J$22) -> 0 | L15: =E15-J15 -> 0 | M15: =IF(AND(J15=0,L15=0),0,IF(AND(J15=0,L15>0),1,L15/J15)) -> 0
A16: 用材料进行债务重组 | E16: =B16+C16+D16 -> 0 | F16: =IF(E16=0,0,E16/E$22) -> 0 | J16: =G16+H16+I16 -> 0 | K16: =IF(J16=0,0,J16/$J$22) -> 0 | L16: =E16-J16 -> 0 | M16: =IF(AND(J16=0,L16=0),0,IF(AND(J16=0,L16>0),1,L16/J16)) -> 0
A17: 与投资性房地产相关的支出（成本模式计量的投资性房地产计提的折旧，其他后续支出） | E17: =B17+C17+D17 -> 0 | F17: =IF(E17=0,0,E17/E$22) -> 0 | J17: =G17+H17+I17 -> 0 | K17: =IF(J17=0,0,J17/$J$22) -> 0 | L17: =E17-J17 -> 0 | M17: =IF(AND(J17=0,L17=0),0,IF(AND(J17=0,L17>0),1,L17/J17)) -> 0
A18: …… | E18: =B18+C18+D18 -> 0 | F18: =IF(E18=0,0,E18/E$22) -> 0 | J18: =G18+H18+I18 -> 0 | K18: =IF(J18=0,0,J18/$J$22) -> 0 | L18: =E18-J18 -> 0 | M18: =IF(AND(J18=0,L18=0),0,IF(AND(J18=0,L18>0),1,L18/J18)) -> 0
E19: =B19+C19+D19 -> 0 | F19: =IF(E19=0,0,E19/E$22) -> 0 | J19: =G19+H19+I19 -> 0 | K19: =IF(J19=0,0,J19/$J$22) -> 0 | L19: =E19-J19 -> 0 | M19: =IF(AND(J19=0,L19=0),0,IF(AND(J19=0,L19>0),1,L19/J19)) -> 0
E20: =B20+C20+D20 -> 0 | F20: =IF(E20=0,0,E20/E$22) -> 0 | J20: =G20+H20+I20 -> 0 | K20: =IF(J20=0,0,J20/$J$22) -> 0 | L20: =E20-J20 -> 0 | M20: =IF(AND(J20=0,L20=0),0,IF(AND(J20=0,L20>0),1,L20/J20)) -> 0
E21: =B21+C21+D21 -> 0 | F21: =IF(E21=0,0,E21/E$22) -> 0 | J21: =G21+H21+I21 -> 0 | K21: =IF(J21=0,0,J21/$J$22) -> 0 | L21: =E21-J21 -> 0 | M21: =IF(AND(J21=0,L21=0),0,IF(AND(J21=0,L21>0),1,L21/J21)) -> 0
A22: 合计 | B22: =SUM(B11:B21) -> 0 | C22: =SUM(C11:C21) -> 0 | D22: =SUM(D11:D21) -> 0 | E22: =SUM(E11:E21) -> 0 | F22: =IF(E22=0,0,E22/E$22) -> 0 | G22: =SUM(G11:G21) -> 0 | H22: =SUM(H11:H21) -> 0 | I22: =SUM(I11:I21) -> 0 | J22: =SUM(J11:J21) -> 0 | K22: =IF(J22=0,0,J22/$J$22) -> 0 | L22: =SUM(L11:L21) -> 0 | M22: =IF(AND(J22=0,L22=0),0,IF(AND(J22=0,L22>0),1,L22/J22)) -> 0
A23: 三、审计说明：
A24: 1.出租固定资产的折旧与用于出租的固定资产折旧测算核对一致，详见固定资产折旧测算表，索引<XX>
A25: 2.出租无形资产的摊销与用于出租的无形资产摊销测算核对一致，详见无形资产摊销测算表，索引<XX>
A26: 3.对大额销售材料进行检查，详见底稿<XX>
A27: 4.……
A28: 四、审计结论：
A33: 提示：
A34: 1.本科目核算企业确认的除主营业务活动以外的其他经营活动所发生的支出，包括销售材料的成本、出租固定资产的折旧额、出租无形资产的摊销额、出租包装物的成本或摊销额等。
A35: 2.除主营业务活动以外的其他经营活动发生的相关税费，在“营业税金及附加”科目核算。
A36: 3.采用成本模式计量投资性房地产的，其投资性房地产计提的折旧额或摊销额，也通过本科目核算。

Sheet 调整分录汇总F5-4
A1: 致同会计师事务所
A2: 主营业务成本调整分录汇总表
A3: =底稿目录!A2 -> 被审计单位： | D3: =底稿目录!A4 -> 编制人： | G3: =底稿目录!A5 -> 编制日期： | I3: 索引号： | J3: =底稿目录!F7 -> F5-4
A4: =底稿目录!A3 -> 会计期间：202X年度 | D4: =底稿目录!A6 -> 复核人： | G4: =底稿目录!A7 -> 复核日期： | I4: 页 次：
A5: 调整事项说明 | B5: 类别（报表调整/账项调整/其他） | C5: 报表项目 | D5: 科目名称 | E5: 附注项目 | F5: …… | G5: 借方调整金额 | H5: 贷方调整金额 | I5: 索引 | J5: 备注
A22: 【注：本底稿适用于调整分录较多、较复杂的项目，且仅列示与本报表项目相关的审计调整。项目组可根据项目实际情况选择是否使用该底稿。】

Sheet 与上年度比较分析表F5-5
A1: 致同会计师事务所
A2: 主营业务成本与上年度比较分析表
A3: =底稿目录!A2 -> 被审计单位： | E3: =底稿目录!A4 -> 编制人： | I3: =底稿目录!A5 -> 编制日期： | N3: 索引号： | O3: =底稿目录!F8 -> F5-5
A4: =底稿目录!A3 -> 会计期间：202X年度 | E4: =底稿目录!A6 -> 复核人： | I4: =底稿目录!A7 -> 复核日期： | N4: 页 次：
A5: 一、审计目标：
A6: 1.利润表中记录的营业成本已发生，且与被审计单位有关，已记录于恰当的账户；
A7: 2. 所有应当记录的营业成本均已记录，所有应当包括在财务报表中的相关披露均已包括；3.营业成本已记录于正确的会计期间
A8: 二、审计过程：
A9: 产品 | B9: 本期数 | E9: 上期数 | H9: 变动额 | K9: 变动率 | N9: 差异原因分析
B10: 数量 | C10: 平均单位成本 | D10: 总成本 | E10: 数量 | F10: 平均单位成本 | G10: 总成本 | H10: 数量 | I10: 平均单位成本 | J10: 总成本 | K10: 数量 | L10: 平均单位成本 | M10: 总成本 | N10: 变动原因 | O10: 索引号
D11: =B11*C11 -> 0 | G11: =E11*F11 -> 0 | H11: =B11-E11 -> 0 | I11: =C11-F11 -> 0 | J11: =D11-G11 -> 0 | K11: =H11/E11 -> #DIV/0! | L11: =I11/F11 -> #DIV/0! | M11: =J11/G11 -> #DIV/0!
D12: =B12*C12 -> 0 | G12: =E12*F12 -> 0 | H12: =B12-E12 -> 0 | I12: =C12-F12 -> 0 | J12: =D12-G12 -> 0 | K12: =H12/E12 -> #DIV/0! | L12: =I12/F12 -> #DIV/0! | M12: =J12/G12 -> #DIV/0!
D13: =B13*C13 -> 0 | G13: =E13*F13 -> 0 | H13: =B13-E13 -> 0 | I13: =C13-F13 -> 0 | J13: =D13-G13 -> 0 | K13: =H13/E13 -> #DIV/0! | L13: =I13/F13 -> #DIV/0! | M13: =J13/G13 -> #DIV/0!
D14: =B14*C14 -> 0 | G14: =E14*F14 -> 0 | H14: =B14-E14 -> 0 | I14: =C14-F14 -> 0 | J14: =D14-G14 -> 0 | K14: =H14/E14 -> #DIV/0! | L14: =I14/F14 -> #DIV/0! | M14: =J14/G14 -> #DIV/0!
D15: =B15*C15 -> 0 | G15: =E15*F15 -> 0 | H15: =B15-E15 -> 0 | I15: =C15-F15 -> 0 | J15: =D15-G15 -> 0 | K15: =H15/E15 -> #DIV/0! | L15: =I15/F15 -> #DIV/0! | M15: =J15/G15 -> #DIV/0!
D16: =B16*C16 -> 0 | G16: =E16*F16 -> 0 | H16: =B16-E16 -> 0 | I16: =C16-F16 -> 0 | J16: =D16-G16 -> 0 | K16: =H16/E16 -> #DIV/0! | L16: =I16/F16 -> #DIV/0! | M16: =J16/G16 -> #DIV/0!
A17: 合计 | D17: =SUM(D11:D16) -> 0 | G17: =SUM(G11:G16) -> 0 | J17: =D17-G17 -> 0 | M17: =J17/G17 -> #DIV/0!
A18: 三、审计说明：
A22: 四、审计结论：

Sheet 销售数量与结转成本数量核对明细表F5-6
A1: 致同会计师事务所
A2: 销售数量与结转成本数量核对明细表
A3: =底稿目录!A2 -> 被审计单位： | F3: =底稿目录!A4 -> 编制人： | J3: =底稿目录!A5 -> 编制日期： | M3: 索引号： | N3: =底稿目录!F9 -> F5-6
A4: =底稿目录!A3 -> 会计期间：202X年度 | F4: =底稿目录!A6 -> 复核人： | J4: =底稿目录!A7 -> 复核日期： | M4: 页 次：
A5: 一、审计目标：
A6: 1.利润表中记录的营业成本已发生，且与被审计单位有关，已记录于恰当的账户
A7: 2.所有应当记录的营业成本均已记录，所有应当包括在财务报表中的相关披露均已包括
A8: 二、审计过程：
A9: 1.本期销售数量表
A10: 项目 | B10: 1月 | C10: 2月 | D10: 3月 | E10: 4月 | F10: 5月 | G10: 6月 | H10: 7月 | I10: 8月 | J10: 9月 | K10: 10月 | L10: 11月 | M10: 12月 | N10: 总计
A11: 分厂1 | B11: =SUM(B12:B15) -> 0 | C11: =SUM(C12:C15) -> 0 | D11: =SUM(D12:D15) -> 0 | E11: =SUM(E12:E15) -> 0 | F11: =SUM(F12:F15) -> 0 | G11: =SUM(G12:G15) -> 0 | H11: =SUM(H12:H15) -> 0 | I11: =SUM(I12:I15) -> 0 | ... N11: =SUM(N12:N15) -> 0
A12: 产品1 | N12: =SUM(B12:M12) -> 0
A13: 产品2 | N13: =SUM(B13:M13) -> 0
A14: 产品3 | N14: =SUM(B14:M14) -> 0
A15: 产品4 | N15: =SUM(B15:M15) -> 0
A16: 分厂2 | B16: =SUM(B17:B20) -> 0 | C16: =SUM(C17:C20) -> 0 | D16: =SUM(D17:D20) -> 0 | E16: =SUM(E17:E20) -> 0 | F16: =SUM(F17:F20) -> 0 | G16: =SUM(G17:G20) -> 0 | H16: =SUM(H17:H20) -> 0 | I16: =SUM(I17:I20) -> 0 | ... N16: =SUM(N17:N20) -> 0
A17: 产品1 | N17: =SUM(B17:M17) -> 0
A18: 产品2 | N18: =SUM(B18:M18) -> 0
A19: 产品3 | N19: =SUM(B19:M19) -> 0
A20: 产品4 | N20: =SUM(B20:M20) -> 0
A21: 总计 | B21: =B11+B16 -> 0 | C21: =C11+C16 -> 0 | D21: =D11+D16 -> 0 | E21: =E11+E16 -> 0 | F21: =F11+F16 -> 0 | G21: =G11+G16 -> 0 | H21: =H11+H16 -> 0 | I21: =I11+I16 -> 0 | ... N21: =N11+N16 -> 0
A22: 2.本期结转销售成本数量表
A23: 项目 | B23: 1月 | C23: 2月 | D23: 3月 | E23: 4月 | F23: 5月 | G23: 6月 | H23: 7月 | I23: 8月 | J23: 9月 | K23: 10月 | L23: 11月 | M23: 12月 | N23: 总计
A24: 分厂1 | B24: =SUM(B25:B28) -> 0 | C24: =SUM(C25:C28) -> 0 | D24: =SUM(D25:D28) -> 0 | E24: =SUM(E25:E28) -> 0 | F24: =SUM(F25:F28) -> 0 | G24: =SUM(G25:G28) -> 0 | H24: =SUM(H25:H28) -> 0 | I24: =SUM(I25:I28) -> 0 | ... N24: =SUM(N25:N28) -> 0
A25: 产品1 | N25: =SUM(B25:M25) -> 0
A26: 产品2 | N26: =SUM(B26:M26) -> 0
A27: 产品3 | N27: =SUM(B27:M27) -> 0
A28: 产品4 | N28: =SUM(B28:M28) -> 0
A29: 分厂2 | B29: =SUM(B30:B33) -> 0 | C29: =SUM(C30:C33) -> 0 | D29: =SUM(D30:D33) -> 0 | E29: =SUM(E30:E33) -> 0 | F29: =SUM(F30:F33) -> 0 | G29: =SUM(G30:G33) -> 0 | H29: =SUM(H30:H33) -> 0 | I29: =SUM(I30:I33) -> 0 | ... N29: =SUM(N30:N33) -> 0
A30: 产品1 | N30: =SUM(B30:M30) -> 0
A31: 产品2 | N31: =SUM(B31:M31) -> 0
A32: 产品3 | N32: =SUM(B32:M32) -> 0
A33: 产品4 | N33: =SUM(B33:M33) -> 0
A34: 总计 | B34: =B24+B29 -> 0 | C34: =C24+C29 -> 0 | D34: =D24+D29 -> 0 | E34: =E24+E29 -> 0 | F34: =F24+F29 -> 0 | G34: =G24+G29 -> 0 | H34: =H24+H29 -> 0 | I34: =I24+I29 -> 0 | ... N34: =N24+N29 -> 0
A35: 3、差异
A36: 项目 | B36: 1月 | C36: 2月 | D36: 3月 | E36: 4月 | F36: 5月 | G36: 6月 | H36: 7月 | I36: 8月 | J36: 9月 | K36: 10月 | L36: 11月 | M36: 12月 | N36: 总计
A37: 分厂1 | B37: =B11-B24 -> 0 | C37: =C11-C24 -> 0 | D37: =D11-D24 -> 0 | E37: =E11-E24 -> 0 | F37: =F11-F24 -> 0 | G37: =G11-G24 -> 0 | H37: =H11-H24 -> 0 | I37: =I11-I24 -> 0 | ... N37: =N11-N24 -> 0
A38: 产品1 | B38: =B12-B25 -> 0 | C38: =C12-C25 -> 0 | D38: =D12-D25 -> 0 | E38: =E12-E25 -> 0 | F38: =F12-F25 -> 0 | G38: =G12-G25 -> 0 | H38: =H12-H25 -> 0 | I38: =I12-I25 -> 0 | ... N38: =N12-N25 -> 0
A39: 产品2 | B39: =B13-B26 -> 0 | C39: =C13-C26 -> 0 | D39: =D13-D26 -> 0 | E39: =E13-E26 -> 0 | F39: =F13-F26 -> 0 | G39: =G13-G26 -> 0 | H39: =H13-H26 -> 0 | I39: =I13-I26 -> 0 | ... N39: =N13-N26 -> 0
A40: 产品3 | B40: =B14-B27 -> 0 | C40: =C14-C27 -> 0 | D40: =D14-D27 -> 0 | E40: =E14-E27 -> 0 | F40: =F14-F27 -> 0 | G40: =G14-G27 -> 0 | H40: =H14-H27 -> 0 | I40: =I14-I27 -> 0 | ... N40: =N14-N27 -> 0
...

Sheet 成本倒轧表F5-7
A1: 致同会计师事务所
A2: 主营业务成本倒轧表
A3: =底稿目录!A2 -> 被审计单位： | C3: =底稿目录!A4 -> 编制人： | E3: =底稿目录!A5 -> 编制日期： | G3: 索引号： | H3: =底稿目录!F10 -> F5-7
A4: =底稿目录!A3 -> 会计期间：202X年度 | C4: =底稿目录!A6 -> 复核人： | E4: =底稿目录!A7 -> 复核日期： | G4: 页 次：
A5: 一、审计目标
A6: 1.利润表中记录的营业成本已发生，且与被审计单位有关，已记录于恰当的账户；
A7: 2.所有应当记录的营业成本均已记录，所有应当包括在财务报表中的相关披露均已包括；
A8: 3.与营业成本有关的金额及其他数据已恰当记录，相关披露已得到恰当计量和描述
A9: 二、审计过程
A10: 项目内容 | B10: 计算说明 | C10: 数据来源 | D10: 索引号 | E10: 未审数 | F10: 审计调整 | G10: 审定数 | H10: 上期数
A11: 期初原材料余额 | B11: ⑴ | C11: 总账“材料”账户期初余额 | G11: =E11+F11 -> 0
A12: 加：本期购入材料净额 | B12: ⑵ | C12: “材料”借方购入额扣退货折让金额 | G12: =E12+F12 -> 0
A13: 加：其他增加额 | B13: ⑶ | C13: “材料”借方其他发生额 | G13: =E13+F13 -> 0
A14: 减：期末原材料余额 | B14: ⑷ | C14: 总账“材料”账户年末余额 | G14: =E14+F14 -> 0
A15: 减：其他原材料发出额 | B15: ⑸ | C15: “材料”贷方其他发生额 | G15: =E15+F15 -> 0
A16: 直接材料成本 | B16: ⑹=⑴+⑵+⑶-⑷-⑸ | C16: 生产成本明细账 | E16: =E11+E12+E13-E14-E15 -> 0 | F16: =F11+F12+F13-F14-F15 -> 0 | G16: =G11+G12+G13-G14-G15 -> 0 | H16: =H11+H12+H13-H14-H15 -> 0
A17: 加：直接人工成本 | B17: ⑺ | C17: 生产成本明细账 | G17: =E17+F17 -> 0
A18: 加：制造费用 | B18: ⑻ | C18: 生产成本明细账 | G18: =E18+F18 -> 0
A19: 其中：材料费用 | C19: “材料”转入“制造费用”借方金额 | G19: =E19+F19 -> 0
A20: 专用工模具 | B20: ⑼ | C20: 生产成本明细账 | G20: =E20+F20 -> 0
A21: 产品生产成本 | B21: ⑽=⑹+⑺+⑻+⑼ | C21: “生产成本”借方发生额 | E21: =E16+E17+E18+E20 -> 0 | F21: =F16+F17+F18+F20 -> 0 | G21: =G16+G17+G18+G20 -> 0 | H21: =H16+H17+H18+H20 -> 0
A22: 加：在产品期初余额 | B22: ⑾ | C22: “生产成本”期初余额 | G22: =E22+F22 -> 0
A23: 减：在产品期末余额 | B23: ⑿ | C23: “生产成本”期末余额 | G23: =E23+F23 -> 0
A24: 产成品（库存商品）成本 | B24: ⒀=⑽+⑾-⑿ | C24: “生产成本”转入“产成品”借方金额 | E24: =E21+E22-E23 -> 0 | F24: =F21+F22-F23 -> 0 | G24: =G21+G22-G23 -> 0 | H24: =H21+H22-H23 -> 0
A25: 加：产成品期初余额 | B25: ⒁ | C25: “产成品”账户期初余额 | G25: =E25+F25 -> 0
A26: 加：其他增加额 | B26: ⒂ | G26: =E26+F26 -> 0
A27: 减：产成品期末余额 | B27: ⒃ | C27: “产成品”账户期末余额 | G27: =E27+F27 -> 0
A28: 减：自制自用产品成本 | B28: ⒄ | C28: “产成品”转入“生产成本”借方金额 | G28: =E28+F28 -> 0
A29: 减：内部领用产品成本 | B29: ⒅ | C29: 内部领用记录 | G29: =E29+F29 -> 0
A30: 减：其他产成品发出额 | B30: ⒆ | C30: 产成品折价、盘亏、废损会计记录 | G30: =E30+F30 -> 0
A31: 主营业务成本 | B31: ⒇=⒀+⒁+⒂-⒃-⒄-⒅-⒆ | E31: =E24+E25+E26-E27-E28-E29-E30 -> 0 | F31: =F24+F25+F26-F27-F28-F29-F30 -> 0 | G31: =G24+G56+G57-G58-G59-G60-G61 -> 0 | H31: =H24+H25+H26-H27-H28-H29-H30 -> 0
A32: 三、审计说明：
A35: 四、审计结论：

Sheet 重大调整核查表F5-8
A1: 致同会计师事务所
A2: 主营业务成本账户中重大调整事项核查表
A3: =底稿目录!A2 -> 被审计单位： | C3: =底稿目录!A4 -> 编制人： | E3: =底稿目录!A5 -> 编制日期： | G3: 索引号： | H3: =底稿目录!F11 -> F5-8
A4: =底稿目录!A3 -> 会计期间：202X年度 | C4: =底稿目录!A6 -> 复核人： | E4: =底稿目录!A7 -> 复核日期： | G4: 页次：
A5: 一、审计目标：
A6: 1.利润表中记录的营业成本已发生，且与被审计单位有关，已记录于恰当的账户；
A7: 2. 所有应当记录的营业成本均已记录，所有应当包括在财务报表中的相关披露均已包括；
A8: 3. 与营业成本有关的金额及其他数据已恰当记录，相关披露已得到恰当计量和描述；
A9: 4. 营业成本已记录于正确的会计期间；
A10: 5. 营业成本已被恰当地汇总或分解且表述清楚，相关披露在按照企业会计准则的编制基础下是相关的、可理解的；
A11: 二、审计过程：
A12: 日期 | B12: 凭证号 | C12: 重大调整事项内容 | D12: 调整金额 | F12: 调整理由 | H12: 理由是否充分
D13: 借方 | E13: 贷方
A30: 三、审计说明：
A33: 四、审计结论：
A37: 提示：
A38: 1.本表是销售成本审定表的附表，用于审查销售成本帐户中重大调整事项的理由是否充分。
A39: 2.检查现金返利、实物返利是否冲减或调整存货或购货当期的主营业务成本。

Sheet GT_Custom
A1: C1 | B1: Custom 1
A2: C2 | B2: Custom 2
A3: C3 | B3: Custom 3
A4: C4 | B4: Custom 4
A5: C5 | B5: Custom 5
A6: C6 | B6: Custom 6
A7: C7 | B7: Custom 7
A8: C8 | B8: Custom 8
