Workbook

Sheet 底稿目录
A1: 底稿开列时，可先在以下单元格填写有关内容，以便其他底稿引用有关数据：
A2: 被审计单位： | B2: 序号 | C2: 内容 | D2: 索引号 | E2: 备注
A3: 截止日： | C3: 长期应付职工薪酬实质性程序表 | D3: J2A
A4: 编制人： | B4: 1 | C4: 长期应付职工薪酬-设定受益计划净资产审定表 | D4: J2-1
A5: 编制日期： | B5: 2 | C5: 长期应付职工薪酬-设定受益计划净资产附注披露信息（上市公司） | E5: 无需打印
A6: 复核人： | B6: 3 | C6: 长期应付职工薪酬-设定受益计划净资产附注披露信息（国有企业） | E6: 无需打印
A7: 复核日期： | B7: 4 | C7: 长期应付职工薪酬-设定受益计划净资产明细表 | D7: J2-2
B8: 5 | C8: 调整分录汇总表 | D8: J2-3
A9: 关于工作底稿与审计程序索引号对应的说明 | B9: 6 | C9: 长期应付职工薪酬-设定受益计划净资产检查表 | D9: J2-4
A10: 1.编制的审计工作底稿应与审计程序对应。审计项目组应根据被审计单位实际情况和风险评估情况在实质性程序表中裁剪、修改或增加审计程序，根据实际执行的审计程序完成相应审计工作底稿，编制的工作底稿中应按自然顺序依次编制索引号，并通过唯一的索引号将与实质性程序表中的程序对应关联（即将工作底稿的索引号填入实质性程序表中的底稿索引号列）。
A14: 2.获取的支持性证据应与审计底稿或程序对应。审计项目组在完成底稿时获取的支持性证据应根据底稿索引号编制下一级按自然顺序排序的索引号（如D1-2-1、D1-2-2、……），并在底稿中说明引用的支持性证据、关联索引号。
A17: 3.工作底稿索引号的编码规则：实质性程序索引号按循环从“D”到“N”,循环内账户以顺序号排列，模板中底稿索引号按账户顺序+自然数顺序（即模板中索引号按二级自然顺序排列，如D1-1、D1-2、D1-3、……D1-N）。

Sheet 长期应付职工薪酬实质性程序表 J2A
A1: 致同会计师事务所
A2: 长期应付职工薪酬实质性程序
A3: =底稿目录!A2 -> 被审计单位： | C3: =底稿目录!A4 -> 编制人： | E3: =底稿目录!A5 -> 编制日期： | H3: 索引号： | I3: =底稿目录!D3 -> J2A
A4: =底稿目录!A3 -> 截止日： | C4: =底稿目录!A6 -> 复核人： | E4: =底稿目录!A7 -> 复核日期： | H4: 页 次：
A5: 一、本循环涉及的报表账户
A6: 长期应付职工薪酬
A7: 二、审计目标与认定的对应关系
A8: 审计目标 | G8: 财务报表的认定
A9: A. 资产负债表中记录的长期应付职工薪酬是存在的，且已经记录在恰当的账户中 | G9: 存在
A10: B. 所有应记录的长期应付职工薪酬均已记录，所有应当包括在财务报表中的相关披露均已包括 | G10: 完整性
A11: C. 记录的长期应付职工薪酬由被审计单位拥有或控制 | G11: 权利和义务
A12: D. 长期应付职工薪酬以恰当的金额包括在财务报表中，与之相关的计价或分摊调整已恰当记录，相关披露已得到恰当计量和描述 | G12: 计价和分摊
A13: E. 长期应付职工薪酬已被恰当地汇总或分解且表述清楚，相关披露在按照企业会计准则的编制基础下是相关的、可理解的 | G13: 列报与披露
A14: 三、计划实施的实质性程序
A15: 序号 | B15: 审计程序 | C15: 程序分类 | D15: 财务报表的认定 | I15: 底稿索引号
D16: 存在 | E16: 完整性 | F16: 权利和 义务 | G16: 准确性、计价和分摊 | H16: 列报 | J16: 根据被审计单位实际情况和风险评估情况裁剪、修改或增加审计程序
A17: 1 | B17: 获取或编制长期应付职工薪酬明细表，复核加计是否正确，并与报表数、总账数和明细账合计数核对是否相符。 | C17: 常规★ | D17: √ | E17: √ | G17: √ | I17: J2-1 /J2-2
A18: 2 | B18: 在使用手工编制、自定义信息报告、系统生成的非固定格式报告等由被审计单位生成的信息时，测试有关信息准确性和完整性，并考虑针对编制和维护由被审计单位生成的信息的相关控制实施控制测试，以评价该信息是否能够为实现审计目的提供基础。 | C18: 常规★ | E18: √ | G18: √ | I18: T1/
A19: 3 | B19: 对期初余额的审计，取得长期应付职工薪酬期初余额明细表复核加计是否正确，与总账、明细账合计数是否相符，检查上期长期应付职工薪酬在本期支付情况，检查重大长期薪酬计提支持性文件以及其他必要追加的审计程序。（适用于首次承接） | C19: 备选 | D19: √ | E19: √ | F19: √ | G19: √
A20: 4 | B20: 如果存在养老金等离职后福利设定受益计划； （1）取得相关协议，确定指定该计划为设定受益计划是恰当的； （2）复核设定受益计划义务现值、计划资产的公允价值及设定受益计划净负债（净资产）的增减变动情况； （3）复核计划资产的构成及其公允价值，复核设定受益计划预期缴存金额及资金来源及预计到期情况； （4）完成“利用专家工作”底稿，取得精算报告，复核设定受益义务现值精算估计所采用的重大假设、日期，确定假设是否合理、计算是否正确、会计处理是否恰当。 | C20: 备选 | D20: √ | E20: √ | F20: √ | G20: √ | I20: J2-4
A21: 5 | B21: 如果存在辞退福利，取得相关辞退文件、协议： （1）对于职工没有选择权的辞退计划，检查按辞退职工数量、辞退补偿标准计提辞退福利负债金额是否正确； （2）对于自愿接受裁减的建议，检查按接受裁减建议的预计职工数量、辞退补偿标准（该标准确定）等计提辞退福利负债金额是否正确； （3）检查实质性辞退工作在一年内完成,但付款时间超过一年的辞退福利，是否按折现后的金额计量，折现率的选择是否合理； （3）识别辞退福利中是否包含未予辞退的员工； 检查辞退福利相关的工资薪酬是否已经恰当计入相关费用、会计处理是否正确。 | C21: 备选 | D21: √ | E21: √ | F21: √ | G21: √
A22: 6 | B22: 如果存在长期带薪缺勤： (1)根据职工薪酬相关制度分析是否存在长期带薪缺勤、累计带薪缺勤与非累计带薪缺勤分类是否恰当； （2）检查计提长期带薪缺勤负债的会计处理是否正确，是否将计提金额计入当期损益或相关资产成本； (3)检查付款时间超过一年的长期带薪缺勤，是否按折现后的金额计量，折现率的选择是否合理。 | C22: 备选 | D22: √ | E22: √ | F22: √ | G22: √
A23: 7 | B23: 如果存在其他长期职工福利,取得相关文件、协议： (1)检查文件、协议，确定分类为长期应付职工薪酬是恰当的，确定协议中的条款是否已适当的反映在精算假设中； （2）考虑完成“利用专家工作”底稿，取得精算报告，复核精算估计所采用的重大假设、日期，确定假设是否合理、计算是否正确、会计处理是否恰当。 | C23: 备选 | D23: √ | E23: √ | F23: √ | G23: √
A24: 8 | B24: 对本期长期应付职工薪酬的减少，检查支持性文件，确定会计处理是否正确 | C24: 常规★ | D24: √ | E24: √ | F24: √
A25: 9 | B25: 针对识别的其他舞弊风险等因素增加的审计程序。 | C25: IPO/上市/新三板/重组/舞弊应对
A26: 10 | B26: 检查长期应付职工薪酬是否已按企业会计准则或其他适用的规定在财务报表中做出恰当列报和披露。 | C26: 常规★ | H26: √ | I26: A 1-1/A1-15 /A1-16

Sheet 长期应付职工薪酬实质性程序表 L2A
A1: 致同会计师事务所
A2: 长期应付职工薪酬实质性程序
A3: =[4]底稿目录!A2 -> 客户名称： | C3: =[4]底稿目录!A4 -> 编制人： | E3: =[4]底稿目录!A5 -> 编制日期： | K3: 索引号： | L3: L2A
A4: =[4]底稿目录!A3 -> 截止日：202X年12月31日 | C4: =[4]底稿目录!A6 -> 复核人： | E4: =[4]底稿目录!A7 -> 复核日期： | K4: 页 次：
A5: 一、本循环涉及的报表账户
A6: 长期应付职工薪酬
A7: 二、重大错报风险需从实质性程序获取的保证程度
A8: 根据风险评估和内控测试的结果按下列顺序作出判断： | D8: 财务报表的认定 | K8: 说明 | L8: 索引号
D9: 存在 | E9: 完整性 | F9: 权利和义务 | G9: 计价和分摊 | H9: 列报与披露
A10: A资产负债表中记录的应付职工薪酬是存在的。 | D10: √
A11: B所有应当记录的应付职工薪酬均已记录。 | E11: √
A12: C记录的应付职工薪酬是被审计单位应当履行的现时义务。 | F12: √
A13: D应付职工薪酬以恰当的金额包括在财务报表中，与之相关的计价调整已恰当记录。 | G13: √
A14: E应付职工薪酬已按照企业会计准则的规定在财务报表中作出恰当列报和披露。 | H14: √
A15: 三、计划实施的实质性程序
A16: 序号 | B16: 审计程序 | D16: 程序分类 | F16: 审计目标 | K16: 执行情况说明 （含底稿索引）
A17: 一 | B17: 检查应付职工薪酬的确认，与生产成本、制造费用、在建工程等相关账项进行核对： | D17: 常规★ | F17: ABD | K17: L2-2
A18: 1 | B18: 确定会计处理是否符合企业会计准则的规定。 | D18: 常规★ | E18: 长期应付职工薪酬 | M18: 删除，会计处理已在每项长期薪酬中体现
A19: 2 | B19: 分析计入成本、费用的工资薪金，关注构成是否异常变化、各月之间波动有无异常，如果异常降低，关注是否存在其他方（如关联方）代付工资的情况； | D19: IPO/上市公司 | E19: 长期应付职工薪酬 | M19: 删除，长期应付职工薪酬无需分析月波动
A20: 二 | B20: 取得辞退福利的明细表 | D20: 备选 | E20: 长期应付职工薪酬 | F20: ABD | K20: L2-2 | M20: 整合 | N20: 如果存在辞退福利，取得相关辞退文件、协议： （1）对于职工没有选择权的辞退计划，检查按辞退职工数量、辞退补偿标准计提辞退福利负债金额是否正确； （2）对于自愿接受裁减的建议，检查按接受裁减建议的预计职工数量、辞退补偿标准（该标准确定）等计提辞退福利负债金额是否正确； （3）检查实质性辞退工作在一年内完成,但付款时间超过一年的辞退福利，是否按折现后的金额计量，折现率的选择是否合理； （3）识别辞退福利中是否包含未予辞退的员工； 检查辞退福利相关的工资薪酬是否已经恰当计入相关费用、会计处理是否正确。
A21: 1 | B21: 确定计算的准确性。 | D21: 备选 | E21: 长期应付职工薪酬 | M21: 整合
A22: 2 | B22: 与总账核对一致。 | D22: 备选 | E22: 长期应付职工薪酬 | M22: 整合
A23: 3 | B23: 确定该福利是否满足确认为负债的标准。 | D23: 备选 | E23: 长期应付职工薪酬 | M23: 整合
A24: 4 | B24: 确定负债的计算是否合理。 | D24: 备选 | E24: 长期应付职工薪酬 | M24: 整合
A25: 5 | B25: 对于职工没有选择权的辞退计划，检查按辞退职工数量、辞退补偿标准计提辞退福利负债金额是否正确 | D25: 备选 | E25: 长期应付职工薪酬 | M25: 整合
A26: 6 | B26: 对于自愿接受裁减的建议，检查按接受裁减建议的预计职工数量、辞退补偿标准（该标准确定）等计提辞退福利负债金额是否正确 | D26: 备选 | E26: 长期应付职工薪酬 | M26: 整合
A27: 7 | B27: 检查实质性辞退工作在一年内完成,但付款时间超过一年的辞退福利，是否按折现后的金额计量，折现率的选择是否合理 | D27: 备选 | E27: 长期应付职工薪酬 | M27: 整合
A28: 8 | B28: 识别辞退福利中是否包含未予辞退的员工；检查其工资薪酬是否已经恰当计入相关费用。 | D28: 备选 | E28: 长期应付职工薪酬 | M28: 整合
A29: 9 | B29: 检查辞退福利支付凭证是否真实正确 | D29: 备选 | E29: 长期应付职工薪酬 | M29: 整合
A30: 三 | B30: 在使用被审计单位生成的信息（IPE）时，应当评价该信息对实现审计目的是否足够可靠，包括根据具体情况在必要时实施下列程序： | D30: 常规★ | F30: B | K30: T1 | M30: 整合 | N30: 在使用手工编制、自定义信息报告、系统生成的非固定格式报告等由被审计单位生成的信息时，测试有关信息准确性和完整性，并考虑针对编制和维护由被审计单位生成的信息的相关控制实施控制测试，以评价该信息是否能够为实现审计目的提供基础。
A31: 1 | B31: 获取有关信息准确性和完整性的审计证据。 | M31: 整合
A32: 2 | B32: 评价信息对实现审计目的是否足够准确和详细。 | M32: 整合
A33: 四 | B33: 对于带薪休假： | D33: 备选 | E33: 长期应付职工薪酬 | F33: ABD | K33: L2-3 | M33: 修改为长期带薪缺勤 | N33: 如果存在长期带薪缺勤： (1)检查计提长期带薪缺勤负债的会计处理是否正确，是否将计提金额计入当期损益或相关资产成本 (2)检查付款时间超过一年的长期带薪缺勤，是否按折现后的金额计量，折现率的选择是否合理 (3)检查长期带薪缺勤支付凭证是否真实正确
A34: 1 | B34: 确定所有员工均包含在列表中。 | D34: 备选 | E34: 长期应付职工薪酬 | M34: 修改为长期带薪缺勤
A35: 2 | B35: 确定企业确认带薪休假的方法是否正确。 | D35: 备选 | E35: 长期应付职工薪酬 | M35: 修改为长期带薪缺勤
A36: 3 | B36: 识别总体中的关键项目。 | D36: 备选 | E36: 长期应付职工薪酬 | M36: 修改为长期带薪缺勤
A37: 4 | B37: 使用样本计算器从剩余的总体中，设计样本以确定需测试项目的数量。 | D37: 备选 | E37: 长期应付职工薪酬 | M37: 修改为长期带薪缺勤
A38: 5 | B38: 采用适当选样方法选取%S的项目。 | D38: 备选 | E38: 长期应付职工薪酬 | M38: 修改为长期带薪缺勤
A39: 6 | B39: 将小时工资费用率与相关的记录核对。 | D39: 备选 | E39: 长期应付职工薪酬 | M39: 修改为长期带薪缺勤
A40: 7 | B40: 向适当的人员报告未解决的差异。 | D40: 备选 | E40: 长期应付职工薪酬 | M40: 修改为长期带薪缺勤
...

Sheet 审定表J2-1
A1: 致同会计师事务所
A2: 长期应付职工薪酬/设定受益计划净资产审定表
A3: =底稿目录!A2 -> 被审计单位： | C3: =底稿目录!A4 -> 编制人： | I3: =底稿目录!A5 -> 编制日期： | K3: 索引号： | L3: =底稿目录!D4 -> J2-1
A4: =底稿目录!A3 -> 截止日： | C4: =底稿目录!A6 -> 复核人： | I4: =底稿目录!A7 -> 复核日期： | K4: 页 次：
A5: 项目名称 | B5: 期初数 | E5: 期末数 | H5: 本期未审数与上期 审定数的比较 | J5: 本期审定数与上期 审定数的比较 | L5: 原因分析
B6: 未审数 | C6: 账项调整 | D6: 审定数 | E6: 未审数 | F6: 账项调整 | G6: 审定数 | H6: 变动额 | I6: 变动率 | J6: 变动额 | K6: 变动率
A7: 设定受益计划 | B7: =B8+B9 -> 0 | C7: =C8+C9 -> 0 | D7: =D8+D9 -> 0 | E7: =E8+E9 -> 0 | F7: =F8+F9 -> 0 | G7: =G8+G9 -> 0 | H7: =H8+H9 -> 0 | I7: =IF(AND(B7=0,E7=0),0,IF(AND(B7=0,E7>0),1,H7/B7)) -> 0 | J7: =J8+J9 -> 0 | K7: =IF(AND(D7=0,G7=0),0,IF(AND(D7=0,G7>0),1,J7/D7)) -> 0
A8: 其中：1、离职后福利 | B8: ='明细表J2-2'!C14 -> 0 | C8: ='明细表J2-2'!G14 -> 0 | D8: =B8+C8 -> 0 | E8: ='明细表J2-2'!F14 -> 0 | F8: ='明细表J2-2'!G14+'明细表J2-2'!H14-'明细表J2-2'!I14 -> 0 | G8: =E8+F8 -> 0 | H8: =E8-B8 -> 0 | I8: =IF(AND(B8=0,E8=0),0,IF(AND(B8=0,E8>0),1,H8/B8)) -> 0 | J8: =G8-D8 -> 0 | K8: =IF(AND(D8=0,G8=0),0,IF(AND(D8=0,G8>0),1,J8/D8)) -> 0
A9: 2、其他长期职工福利 | B9: ='明细表J2-2'!C15 -> 0 | C9: ='明细表J2-2'!G15 -> 0 | D9: =B9+C9 -> 0 | E9: ='明细表J2-2'!F15 -> 0 | F9: ='明细表J2-2'!G15+'明细表J2-2'!H15-'明细表J2-2'!I15 -> 0 | G9: =E9+F9 -> 0 | H9: =E9-B9 -> 0 | I9: =IF(AND(B9=0,E9=0),0,IF(AND(B9=0,E9>0),1,H9/B9)) -> 0 | J9: =G9-D9 -> 0 | K9: =IF(AND(D9=0,G9=0),0,IF(AND(D9=0,G9>0),1,J9/D9)) -> 0
A10: 辞退福利 | B10: ='明细表J2-2'!C16 -> 0 | C10: ='明细表J2-2'!G16 -> 0 | D10: =B10+C10 -> 0 | E10: ='明细表J2-2'!F16 -> 0 | F10: ='明细表J2-2'!G16+'明细表J2-2'!H16-'明细表J2-2'!I16 -> 0 | G10: =E10+F10 -> 0 | H10: =E10-B10 -> 0 | I10: =IF(AND(B10=0,E10=0),0,IF(AND(B10=0,E10>0),1,H10/B10)) -> 0 | J10: =G10-D10 -> 0 | K10: =IF(AND(D10=0,G10=0),0,IF(AND(D10=0,G10>0),1,J10/D10)) -> 0
A11: 减：一年内支付的辞退福利 | B11: ='明细表J2-2'!C17 -> 0 | C11: ='明细表J2-2'!G17 -> 0 | D11: =B11+C11 -> 0 | E11: ='明细表J2-2'!F17 -> 0 | F11: ='明细表J2-2'!G17+'明细表J2-2'!H17-'明细表J2-2'!I17 -> 0 | G11: =E11+F11 -> 0 | H11: =E11-B11 -> 0 | I11: =IF(AND(B11=0,E11=0),0,IF(AND(B11=0,E11>0),1,H11/B11)) -> 0 | J11: =G11-D11 -> 0 | K11: =IF(AND(D11=0,G11=0),0,IF(AND(D11=0,G11>0),1,J11/D11)) -> 0
A12: 合计 | B12: =B7+B10-B11 -> 0 | C12: =C7+C10-C11 -> 0 | D12: =D7+D10-D11 -> 0 | E12: =E7+E10-E11 -> 0 | F12: =F7+F10-F11 -> 0 | G12: =G7+G10-G11 -> 0 | H12: =H7+H10-H11 -> 0 | I12: =IF(AND(B12=0,E12=0),0,IF(AND(B12=0,E12>0),1,H12/B12)) -> 0 | J12: =J7+J10-J11 -> 0 | K12: =IF(AND(D12=0,G12=0),0,IF(AND(D12=0,G12>0),1,J12/D12)) -> 0
A13: 未折现的离职后福利预计到期分析：
A14: 项 目 | B14: 金额
A15: 一年以内 | B15: ='明细表J2-2'!M22 -> 0
A16: 一到两年 | B16: ='明细表J2-2'!M23 -> 0
A17: 二到五年 | B17: ='明细表J2-2'!M24 -> 0
A18: 五年以上 | B18: ='明细表J2-2'!M25 -> 0
A19: 合 计 | B19: =SUM(B15:B18) -> 0
A20: 其中：（1）设定受益计划情况
A21: 项 目 | B21: 设定受益计划义务现值 | F21: 计划资产的公允价值 | H21: 设定受益计划净负债
B22: 本期未审金额 | C22: 账项调整 | D22: 期末审定金额 | E22: 上期金额 | F22: 本期金额 | G22: 上期金额 | H22: 本期金额 | I22: 上期金额
A23: 一、期初余额 | B23: ='明细表J2-2'!C32 -> 0 | C23: ='明细表J2-2'!D32 -> 0 | D23: =B23+C23 -> 0 | E23: ='明细表J2-2'!F32 -> 0 | F23: =E52 -> 0 | G23: ='明细表J2-2'!H32 -> 0 | H23: =B23-F23 -> 0 | I23: ='明细表J2-2'!J32 -> 0
A24: 二、计入当期损益的设定受益成本 | B24: =B25+B26+B27+B28 -> 0 | C24: =C25+C26+C27+C28 -> 0 | D24: =D25+D26+D27+D28 -> 0 | E24: =E25+E26+E27+E28 -> 0 | F24: =F28 -> 0 | G24: =G28 -> 0 | H24: =H25+H26+H27+H28 -> 0 | I24: =I25+I26+I27+I28 -> 0
A25: 1．当期服务成本 | B25: ='明细表J2-2'!C34 -> 0 | C25: ='明细表J2-2'!D34 -> 0 | D25: =B25+C25 -> 0 | E25: ='明细表J2-2'!F34 -> 0 | F25: -- | G25: -- | H25: =B25 -> 0 | I25: ='明细表J2-2'!J34 -> 0
A26: 2．过去服务成本 | B26: ='明细表J2-2'!C35 -> 0 | C26: ='明细表J2-2'!D35 -> 0 | D26: =B26+C26 -> 0 | E26: ='明细表J2-2'!F35 -> 0 | F26: -- | G26: -- | H26: =B26 -> 0 | I26: ='明细表J2-2'!J35 -> 0
A27: 3．结算利得（损失以“-”表示） | B27: ='明细表J2-2'!C36 -> 0 | C27: ='明细表J2-2'!D36 -> 0 | D27: =B27+C27 -> 0 | E27: ='明细表J2-2'!F36 -> 0 | F27: -- | G27: -- | H27: =B27 -> 0 | I27: ='明细表J2-2'!J36 -> 0
A28: 4．利息净额 | B28: ='明细表J2-2'!C37 -> 0 | C28: ='明细表J2-2'!D37 -> 0 | D28: =B28+C28 -> 0 | E28: ='明细表J2-2'!F37 -> 0 | F28: ='明细表J2-2'!G37 -> 0 | G28: ='明细表J2-2'!H37 -> 0 | H28: =B28-F28 -> 0 | I28: ='明细表J2-2'!J37 -> 0
A29: 三、计入其他综合收益的设定受益成本 | B29: =B30 -> 0 | C29: =C30 -> 0 | D29: =D30 -> 0 | E29: =E30 -> 0 | F29: =F30 -> 0 | G29: =G30 -> 0 | H29: =H30 -> 0 | I29: =I30 -> 0
A30: 设定受益计划净负债（净资产）的重新计量 | B30: =SUM(B31:B33) -> 0 | C30: =SUM(C31:C33) -> 0 | D30: =B30+C30 -> 0 | E30: =SUM(E31:E33) -> 0 | F30: =SUM(F31:F33) -> 0 | G30: =SUM(G31:G33) -> 0 | H30: =SUM(H31:H33) -> 0 | I30: =SUM(I31:I33) -> 0
A31: 1．精算利得（损失以“-”表示） | B31: ='明细表J2-2'!C40 -> 0 | C31: ='明细表J2-2'!D40 -> 0 | D31: =B31+C31 -> 0 | E31: ='明细表J2-2'!F40 -> 0 | F31: -- | G31: -- | H31: =B31 -> 0 | I31: ='明细表J2-2'!J40 -> 0
A32: 2．计划资产的回报（计入利息净额的除外） | B32: ='明细表J2-2'!C41 -> 0 | C32: ='明细表J2-2'!D41 -> 0 | D32: =B32+C32 -> 0 | E32: ='明细表J2-2'!F41 -> 0 | F32: ='明细表J2-2'!G41 -> 0 | G32: ='明细表J2-2'!H41 -> 0 | H32: =B32-F32 -> 0 | I32: ='明细表J2-2'!J41 -> 0
A33: 3．资产上限影响的变动（计入利息净额的除外） | B33: ='明细表J2-2'!C42 -> 0 | C33: ='明细表J2-2'!D42 -> 0 | D33: =B33+C33 -> 0 | E33: ='明细表J2-2'!F42 -> 0 | F33: ='明细表J2-2'!G42 -> 0 | G33: ='明细表J2-2'!H42 -> 0 | H33: =B33-F33 -> 0 | I33: ='明细表J2-2'!J42 -> 0
A34: 四、其他变动 | B34: =SUM(B35:B37) -> 0 | C34: =SUM(C35:C37) -> 0 | D34: =SUM(D35:D37) -> 0 | E34: =SUM(E35:E37) -> 0 | F34: =SUM(F35:F37) -> 0 | G34: =SUM(G35:G37) -> 0 | H34: =SUM(H35:H37) -> 0 | I34: =SUM(I35:I37) -> 0
A35: 1．结算时消除的负债 | B35: ='明细表J2-2'!C44 -> 0 | C35: ='明细表J2-2'!D44 -> 0 | D35: =B35+C35 -> 0 | E35: ='明细表J2-2'!F44 -> 0 | F35: ='明细表J2-2'!G44 -> 0 | G35: ='明细表J2-2'!H44 -> 0 | H35: =B35-F35 -> 0 | I35: ='明细表J2-2'!J44 -> 0
A36: 2．已支付的福利 | B36: ='明细表J2-2'!C45 -> 0 | C36: ='明细表J2-2'!D45 -> 0 | D36: =B36+C36 -> 0 | E36: ='明细表J2-2'!F45 -> 0 | F36: ='明细表J2-2'!G45 -> 0 | G36: ='明细表J2-2'!H45 -> 0 | H36: =B36-F36 -> 0 | I36: ='明细表J2-2'!J45 -> 0
A37: …… | B37: ='明细表J2-2'!C46 -> 0 | C37: ='明细表J2-2'!D46 -> 0 | D37: =B37+C37 -> 0 | E37: ='明细表J2-2'!F46 -> 0 | F37: ='明细表J2-2'!G46 -> 0 | G37: ='明细表J2-2'!H46 -> 0 | H37: =B37-F37 -> 0 | I37: ='明细表J2-2'!J46 -> 0
A38: 五、期末余额 | B38: =B23+B24+B29-B34 -> 0 | C38: =C23+C24+C29-C34 -> 0 | D38: =D23+D24+D29-D34 -> 0 | E38: =E23+E24+E29-E34 -> 0 | F38: =F23+F24+F29-F34 -> 0 | G38: =G23+G24+G29-G34 -> 0 | H38: =H23+H24+H29-H34 -> 0 | I38: =I23+I24+I29-I34 -> 0
A39: （2）计划资产
A40: 项 目 | B40: 计划资产的公允价值
...

Sheet 附注披露信息（上市公司）
A1: 致同会计师事务所
A2: 长期应付职工薪酬//设定受益计划净资产附注披露信息（上市公司）
A3: =底稿目录!A2 -> 被审计单位： | B3: =底稿目录!A4 -> 编制人： | C3: =底稿目录!A5 -> 编制日期： | D3: 索引号：
A4: =底稿目录!A3 -> 截止日： | B4: =底稿目录!A6 -> 复核人： | C4: =底稿目录!A7 -> 复核日期： | D4: 页次：
A5: 长期应付职工薪酬（不适用的删除）
A6: 项 目 | B6: 期末数 | C6: 期初数
A7: 设定受益计划净负债 | B7: ='审定表J2-1'!G8 -> 0 | C7: ='审定表J2-1'!D8 -> 0
A8: 辞退福利 | B8: ='审定表J2-1'!G10 -> 0 | C8: ='审定表J2-1'!D10 -> 0
A9: 符合设定受益计划条件的其他长期职工福利的净负债（不适用删除） | B9: ='审定表J2-1'!G9 -> 0 | C9: ='审定表J2-1'!D9 -> 0
A10: 其他长期福利
A11: 小 计 | B11: =SUM(B7:B10) -> 0 | C11: =SUM(C7:C10) -> 0
A12: 减：一年内到期的长期应付职工薪酬 | B12: ='审定表J2-1'!G11 -> 0 | C12: ='审定表J2-1'!D11 -> 0
A13: 合 计 | B13: =B11-B12 -> 0 | C13: =C11-C12 -> 0
A14: 说明：1、辞退福利的性质、内容及计算依据详见附注五、35；
A15: 2、其他长期职工福利的性质及计算依据。
A16: （1）设定受益计划变动情况
A17: 设定受益计划义务现值：
A18: 项 目 | B18: 本期金额 | C18: 上期金额
A19: 一、期初余额 | B19: ='审定表J2-1'!D23 -> 0 | C19: ='审定表J2-1'!E23 -> 0
A20: 二、计入当期损益的设定受益成本 | B20: ='审定表J2-1'!D24 -> 0 | C20: ='审定表J2-1'!E24 -> 0
A21: 1．当期服务成本 | B21: ='审定表J2-1'!D25 -> 0 | C21: ='审定表J2-1'!E25 -> 0
A22: 2．过去服务成本 | B22: ='审定表J2-1'!D26 -> 0 | C22: ='审定表J2-1'!E26 -> 0
A23: 3．结算利得（损失以“-”表示） | B23: ='审定表J2-1'!D27 -> 0 | C23: ='审定表J2-1'!E27 -> 0
A24: 4．利息净额 | B24: ='审定表J2-1'!D28 -> 0 | C24: ='审定表J2-1'!E28 -> 0
A25: 三、计入其他综合收益的设定受益成本 | B25: ='审定表J2-1'!D29 -> 0 | C25: ='审定表J2-1'!E29 -> 0
A26: 1．精算利得（损失以“-”表示） | B26: ='审定表J2-1'!D30 -> 0 | C26: ='审定表J2-1'!E30 -> 0
A27: 2．计划资产的回报（计入利息净额的除外） | B27: ='审定表J2-1'!D31 -> 0 | C27: ='审定表J2-1'!E31 -> 0
A28: 3．资产上限影响的变动（计入利息净额的除外） | B28: ='审定表J2-1'!D32 -> 0 | C28: ='审定表J2-1'!E32 -> 0
A29: 四、其他变动 | B29: ='审定表J2-1'!D33 -> 0 | C29: ='审定表J2-1'!E33 -> 0
A30: 1．结算时消除的负债 | B30: ='审定表J2-1'!D34 -> 0 | C30: ='审定表J2-1'!E34 -> 0
... A32: …… | B32: ='审定表J2-1'!D36 -> 0 | C32: ='审定表J2-1'!E36 -> 0
A33: 五、期末余额 | B33: ='审定表J2-1'!D37 -> 0 | C33: ='审定表J2-1'!E38 -> 0
A34: 计划资产：
A35: 项 目 | B35: 本期金额 | C35: 上期金额
A36: 一、期初余额 | B36: ='审定表J2-1'!F23 -> 0 | C36: ='审定表J2-1'!G23 -> 0
A37: 二、计入当期损益的设定受益成本 | B37: =SUM(B38:B39) -> 0 | C37: =SUM(C38:C39) -> 0
A38: 1．利息净额 | B38: ='审定表J2-1'!F28 -> 0 | C38: ='审定表J2-1'!G28 -> 0
A40: 三、计入其他综合收益的设定受益成本 | B40: ='审定表J2-1'!F29 -> 0 | C40: ='审定表J2-1'!G29 -> 0
A41: 1．计划资产的回报（计入利息净额的除外） | B41: ='审定表J2-1'!F32 -> 0 | C41: ='审定表J2-1'!G32 -> 0
A42: 2．资产上限影响的变动（计入利息净额的除外） | B42: ='审定表J2-1'!F33 -> 0 | C42: ='审定表J2-1'!G33 -> 0
...

Sheet 附注披露信息（国有企业）
A1: 致同会计师事务所
A2: 长期应付职工薪酬//设定受益计划净资产附注披露信息（国有企业）
A3: =底稿目录!A2 -> 被审计单位： | B3: =底稿目录!A4 -> 编制人： | D3: =底稿目录!A5 -> 编制日期： | F3: 索引号：
A4: =底稿目录!A3 -> 截止日： | B4: =底稿目录!A6 -> 复核人： | D4: =底稿目录!A7 -> 复核日期： | F4: 页次：
A5: 长期应付职工薪酬（不适用的删除）
A6: 项 目 | B6: 期初数 | C6: 本期增加 | D6: 本期减少 | E6: 期末数
A7: 设定受益计划净负债 | B7: ='审定表J2-1'!D8 -> 0 | C7: ='明细表J2-2'!K14 -> 0 | D7: ='明细表J2-2'!L14 -> 0 | E7: =B7+C7-D7 -> 0
A8: 符合设定受益计划条件的其他长期职工福利的净负债（不适用删除） | B8: ='审定表J2-1'!D9 -> 0 | C8: ='明细表J2-2'!K15 -> 0 | D8: ='明细表J2-2'!L15 -> 0 | E8: =B8+C8-D8 -> 0
A9: 一年后支付的辞退福利 | B9: ='审定表J2-1'!D10-'审定表J2-1'!D11 -> 0 | C9: ='明细表J2-2'!K16-'明细表J2-2'!K17 -> 0 | D9: ='明细表J2-2'!L16-'明细表J2-2'!L17 -> 0 | E9: =B9+C9-D9 -> 0
A10: 合 计 | B10: =SUM(B7:B9) -> 0 | C10: =SUM(C7:C9) -> 0 | D10: =SUM(D7:D9) -> 0 | E10: =SUM(E7:E9) -> 0
A11: 说明：（1、辞退福利的性质、内容及计算依据详见附注八、35；2、其他长期职工福利的性质及计算依据）
A12: 设定受益计划情况：
A13: 项 目 | B13: 设定受益计划义务现值 | D13: 计划资产的公允价值 | F13: 设定受益计划净负债
B14: （不适用删除） | D14: （不适用删除） | F14: （净资产）
B15: 本期金额 | C15: 上期金额 | D15: 本期金额 | E15: 上期金额 | F15: 本期金额 | G15: 上期金额
A16: 一、期初余额 | B16: ='审定表J2-1'!D23 -> 0 | C16: ='审定表J2-1'!E23 -> 0 | D16: ='审定表J2-1'!F23 -> 0 | E16: ='审定表J2-1'!G23 -> 0 | F16: ='审定表J2-1'!H23 -> 0 | G16: ='审定表J2-1'!I23 -> 0
A17: 二、计入当期损益的设定受益成本 | B17: =SUM(B18:B21) -> 0 | C17: =SUM(C18:C21) -> 0 | D17: =D21 -> 0 | E17: =E21 -> 0 | F17: ='审定表J2-1'!H24 -> 0 | G17: ='审定表J2-1'!I24 -> 0
A18: 1．当期服务成本 | B18: ='审定表J2-1'!D25 -> 0 | C18: ='审定表J2-1'!E25 -> 0 | D18: -- | E18: -- | F18: ='审定表J2-1'!H25 -> 0 | G18: ='审定表J2-1'!I25 -> 0
A19: 2．过去服务成本 | B19: ='审定表J2-1'!D26 -> 0 | C19: ='审定表J2-1'!E26 -> 0 | D19: -- | E19: -- | F19: ='审定表J2-1'!H26 -> 0 | G19: ='审定表J2-1'!I26 -> 0
A20: 3．结算利得（损失以“-”表示） | B20: ='审定表J2-1'!D27 -> 0 | C20: ='审定表J2-1'!E27 -> 0 | D20: -- | E20: -- | F20: ='审定表J2-1'!H27 -> 0 | G20: ='审定表J2-1'!I27 -> 0
A21: 4．利息净额 | B21: ='审定表J2-1'!D28 -> 0 | C21: ='审定表J2-1'!E28 -> 0 | D21: ='审定表J2-1'!F28 -> 0 | E21: ='审定表J2-1'!G28 -> 0 | F21: ='审定表J2-1'!H28 -> 0 | G21: ='审定表J2-1'!I28 -> 0
A22: 三、计入其他综合收益的设定受益成本 | B22: =B23 -> 0 | C22: =C23 -> 0 | D22: =D23 -> 0 | E22: =E23 -> 0 | F22: ='审定表J2-1'!H29 -> 0 | G22: ='审定表J2-1'!I29 -> 0
A23: 设定受益计划净负债（净资产）的重新计量 | B23: =SUM(B24:B26) -> 0 | C23: =SUM(C24:C26) -> 0 | D23: =D25+D26 -> 0 | E23: =E25+E26 -> 0 | F23: ='审定表J2-1'!H30 -> 0 | G23: ='审定表J2-1'!I30 -> 0
A24: 1．精算利得（损失以“-”表示） | B24: ='审定表J2-1'!D31 -> 0 | C24: ='审定表J2-1'!E31 -> 0 | D24: -- | E24: -- | F24: ='审定表J2-1'!H31 -> 0 | G24: ='审定表J2-1'!I31 -> 0
A25: 2．计划资产的回报（计入利息净额的除外） | B25: ='审定表J2-1'!D32 -> 0 | C25: ='审定表J2-1'!E32 -> 0 | D25: ='审定表J2-1'!F32 -> 0 | E25: ='审定表J2-1'!G32 -> 0 | F25: ='审定表J2-1'!H32 -> 0 | G25: ='审定表J2-1'!I32 -> 0
A26: 3．资产上限影响的变动（计入利息净额的除外） | B26: ='审定表J2-1'!D33 -> 0 | C26: ='审定表J2-1'!E33 -> 0 | D26: ='审定表J2-1'!F33 -> 0 | E26: ='审定表J2-1'!G33 -> 0 | F26: ='审定表J2-1'!H33 -> 0 | G26: ='审定表J2-1'!I33 -> 0
A27: 四、其他变动 | B27: =SUM(B28:B30) -> 0 | C27: =SUM(C28:C30) -> 0 | D27: =SUM(D28:D30) -> 0 | E27: =SUM(E28:E30) -> 0 | F27: ='审定表J2-1'!H34 -> 0 | G27: ='审定表J2-1'!I34 -> 0
A28: 1．结算时消除的负债 | B28: ='审定表J2-1'!D35 -> 0 | C28: ='审定表J2-1'!E35 -> 0 | D28: ='审定表J2-1'!F35 -> 0 | E28: ='审定表J2-1'!G35 -> 0 | F28: ='审定表J2-1'!H35 -> 0 | G28: ='审定表J2-1'!I35 -> 0
A29: 2．已支付的福利 | B29: ='审定表J2-1'!D36 -> 0 | C29: ='审定表J2-1'!E36 -> 0 | D29: ='审定表J2-1'!F36 -> 0 | E29: ='审定表J2-1'!G36 -> 0 | F29: ='审定表J2-1'!H36 -> 0 | G29: ='审定表J2-1'!I36 -> 0
A30: …… | B30: ='审定表J2-1'!D37 -> 0 | C30: ='审定表J2-1'!E37 -> 0 | D30: ='审定表J2-1'!F37 -> 0 | E30: ='审定表J2-1'!G37 -> 0 | F30: ='审定表J2-1'!H37 -> 0 | G30: ='审定表J2-1'!I37 -> 0
A31: 五、期末余额 | B31: =B16+B17+B22+B27 -> 0 | C31: =C16+C17+C22+C27 -> 0 | D31: =D16+D17+D22+D27 -> 0 | E31: =E16+E17+E22+E27 -> 0 | F31: =F16+F17+F22+F27 -> 0 | G31: =G16+G17+G22+G27 -> 0
A32: 【提示：设定受益计划存在资产的，企业应当将设定受益计划义务现值减去设定受益计划资产公允价值所形成的赤字或盈余确认为一项设定受益计划净负债或净资产。】
A33: 说明：（1、设定受益计划形成的原因、特征及与之相关的风险；
A34: 2、如有对计划的修改或结算的，还应当披露修改或结算计划的有关情况；
A35: 3、影响设定受益计划未来缴存金额的有关筹资政策和计划、下一会计年度预期将缴存的金额，设定受益义务有关到期情况的信息，如设定受益义务的加权平均期间、对有关福利支付的到期日分析等）
A36: 未折现的离职后福利预计到期分析：
A37: 项 目 | B37: 金额
A38: 一年以内 | B38: ='审定表J2-1'!B15 -> 0
A39: 一到两年 | B39: ='审定表J2-1'!B16 -> 0
A40: 二到五年 | B40: ='审定表J2-1'!B17 -> 0
...

Sheet 明细表J2-2
A1: 致同会计师事务所
A2: 长期应付职工薪酬/设定受益计划净资产明细表
A3: =底稿目录!A2 -> 被审计单位： | E3: =底稿目录!A4 -> 编制人： | J3: =底稿目录!A5 -> 编制日期： | M3: 索引号： | N3: =底稿目录!D7 -> J2-2
A4: =底稿目录!A3 -> 截止日： | E4: =底稿目录!A6 -> 复核人： | J4: =底稿目录!A7 -> 复核日期： | M4: 页 次：
A5: 一、审计目标:
A6: 1.资产负债表中记录的长期应付职工薪酬是存在的，且已经记录在恰当的账户中
A7: 2.所有应记录的长期应付职工薪酬均已记录，所有应当包括在财务报表中的相关披露均已包括
A8: 3.记录的长期应付职工薪酬由被审计单位拥有或控制
A9: 4.长期应付职工薪酬以恰当的金额包括在财务报表中，与之相关的计价或分摊调整已恰当记录，相关披露已得到恰当计量和描述
A10: 二、审计过程：
A11: 序号 | B11: 项目名称 | C11: 未审数 | G11: 期初调整 | H11: 账项调整 | J11: 审定数 | N11: 备注
C12: 期初数 | D12: 本期增加 | E12: 本期减少 | F12: 期末数 | G12: 账项调整 | H12: 本期增加 | I12: 本期减少 | J12: 期初数 | K12: 本期增加 | L12: 本期减少 | M12: 期末数
A13: 一 | B13: 设定受益计划 | C13: =C14+C15 -> 0 | D13: =D14+D15 -> 0 | E13: =E14+E15 -> 0 | F13: =F14+F15 -> 0 | G13: =G14+G15 -> 0 | H13: =H14+H15 -> 0 | I13: =I14+I15 -> 0 | J13: =J14+J15 -> 0 | ... M13: =M14+M15 -> 0
B14: 其中：1、离职后福利 | F14: =C14+D14-E14 -> 0 | J14: =C14+G14 -> 0 | K14: =D14+H14 -> 0 | L14: =E14+I14 -> 0 | M14: =J14+K14-L14 -> 0
B15: 2、其他长期职工福利 | F15: =C15+D15-E15 -> 0 | J15: =C15+G15 -> 0 | K15: =D15+H15 -> 0 | L15: =E15+I15 -> 0 | M15: =J15+K15-L15 -> 0
A16: 二 | B16: 辞退福利 | F16: =C16+D16-E16 -> 0 | J16: =C16+G16 -> 0 | K16: =D16+H16 -> 0 | L16: =E16+I16 -> 0 | M16: =J16+K16-L16 -> 0
B17: 减：一年内支付的辞退福利 | F17: =C17+D17-E17 -> 0 | J17: =C17+G17 -> 0 | K17: =D17+H17 -> 0 | L17: =E17+I17 -> 0 | M17: =J17+K17-L17 -> 0
A18: 合计 | C18: =C13+C16-C17 -> 0 | D18: =D13+D16-D17 -> 0 | E18: =E13+E16-E17 -> 0 | F18: =F13+F16-F17 -> 0 | G18: =G13+G16-G17 -> 0 | H18: =H13+H16-H17 -> 0 | I18: =I13+I16-I17 -> 0 | J18: =J13+J16-J17 -> 0 | ... M18: =M13+M16-M17 -> 0
A19: 1、未折现的离职后福利预计到期分析
A20: 序号 | B20: 项目名称 | C20: 未审数 | G20: 期初调整 | H20: 账项调整 | J20: 审定数 | N20: 备注
C21: 期初数 | D21: 本期增加 | E21: 本期减少 | F21: 期末数 | G21: 账项调整 | H21: 本期增加 | I21: 本期减少 | J21: 期初数 | K21: 本期增加 | L21: 本期减少 | M21: 期末数
A22: 1 | B22: 一年以内 | F22: =C22+D22-E22 -> 0 | J22: =C22+G22 -> 0 | K22: =D22+H22 -> 0 | L22: =E22+I22 -> 0 | M22: =J22+K22-L22 -> 0
A23: 2 | B23: 一到两年 | F23: =C23+D23-E23 -> 0 | J23: =C23+G23 -> 0 | K23: =D23+H23 -> 0 | L23: =E23+I23 -> 0 | M23: =J23+K23-L23 -> 0
A24: 3 | B24: 二到五年 | F24: =C24+D24-E24 -> 0 | J24: =C24+G24 -> 0 | K24: =D24+H24 -> 0 | L24: =E24+I24 -> 0 | M24: =J24+K24-L24 -> 0
A25: 4 | B25: 五年以上 | F25: =C25+D25-E25 -> 0 | J25: =C25+G25 -> 0 | K25: =D25+H25 -> 0 | L25: =E25+I25 -> 0 | M25: =J25+K25-L25 -> 0
F26: =C26+D26-E26 -> 0 | J26: =C26+G26 -> 0 | K26: =D26+H26 -> 0 | L26: =E26+I26 -> 0 | M26: =J26+K26-L26 -> 0
A27: 合计 | C27: =SUM(C22:C26) -> 0 | D27: =SUM(D22:D26) -> 0 | E27: =SUM(E22:E26) -> 0 | F27: =SUM(F22:F26) -> 0 | G27: =SUM(G22:G26) -> 0 | H27: =SUM(H22:H26) -> 0 | I27: =SUM(I22:I26) -> 0 | J27: =C27+G27 -> 0 | K27: =D27+H27 -> 0 | L27: =E27+I27 -> 0 | M27: =J27+K27-L27 -> 0
A29: 2、设定受益计划情况
A30: 序号 | B30: 项目名称 | C30: 设定受益计划义务现值 | G30: 计划资产的公允价值 | I30: 设定受益计划净负债（净资产） | K30: 备注
C31: 本期未审金额 | D31: 账项调整 | E31: 期末审定金额 | F31: 上期金额 | G31: 本期金额 | H31: 上期金额 | I31: 本期金额 | J31: 上期金额
A32: 一、 | B32: 期初余额 | E32: =C32+D32 -> 0 | G32: =J61 -> 0 | I32: =C32-G32 -> 0
A33: 二、 | B33: 计入当期损益的设定受益成本 | C33: =C34+C35+C36+C37 -> 0 | D33: =D34+D35+D36+D37 -> 0 | E33: =E34+E35+E36+E37 -> 0 | F33: =F34+F35+F36+F37 -> 0 | G33: =G37 -> 0 | H33: =H37 -> 0 | I33: =I34+I35+I36+I37 -> 0 | J33: =J34+J35+J36+J37 -> 0
A34: 1 | B34: 当期服务成本 | E34: =C34+D34 -> 0 | G34: -- | H34: -- | I34: =C34 -> 0
A35: 2 | B35: 过去服务成本 | E35: =C35+D35 -> 0 | G35: -- | H35: -- | I35: =C35 -> 0
A36: 3 | B36: 结算利得（损失以“-”表示） | E36: =C36+D36 -> 0 | G36: -- | H36: -- | I36: =C36 -> 0
A37: 4 | B37: 利息净额 | E37: =C37+D37 -> 0 | I37: =C37-G37 -> 0
A38: 三、 | B38: 计入其他综合收益的设定受益成本 | C38: =C39 -> 0 | D38: =D39 -> 0 | E38: =E39 -> 0 | F38: =F39 -> 0 | G38: =G39 -> 0 | H38: =H39 -> 0 | I38: =I39 -> 0 | J38: =J39 -> 0
B39: 设定受益计划净负债（净资产）的重新计量 | C39: =SUM(C40:C42) -> 0 | D39: =SUM(D40:D42) -> 0 | E39: =SUM(E40:E42) -> 0 | F39: =SUM(F40:F42) -> 0 | G39: =SUM(G40:G42) -> 0 | H39: =SUM(H40:H42) -> 0 | I39: =SUM(I40:I42) -> 0 | J39: =SUM(J40:J42) -> 0
A40: 1 | B40: 精算利得（损失以“-”表示） | E40: =C40+D40 -> 0 | G40: -- | H40: -- | I40: =C40 -> 0
A41: 2 | B41: 计划资产的回报（计入利息净额的除外） | E41: =C41+D41 -> 0 | I41: =C41-G41 -> 0
...

Sheet 调整分录汇总表J2-3
A1: 致同会计师事务所
A2: 长期应付职工薪酬调整分录汇总表
A3: =底稿目录!A2 -> 被审计单位： | D3: =底稿目录!A4 -> 编制人： | G3: =底稿目录!A5 -> 编制日期： | I3: 索引号： | J3: =底稿目录!D8 -> J2-3
A4: =底稿目录!A3 -> 截止日： | D4: =底稿目录!A6 -> 复核人： | G4: =底稿目录!A7 -> 复核日期： | I4: 页 次：
A5: 调整事项说明 | B5: 类别（报表调整/账项调整/其他） | C5: 报表项目 | D5: 科目名称 | E5: 附注项目 | F5: …… | G5: 借方调整金额 | H5: 贷方调整金额 | I5: 索引 | J5: 备注
A22: 【注：本底稿适用于调整分录较多、较复杂的项目，且仅列示与本报表项目相关的审计调整。项目组可根据项目实际情况选择是否使用该底稿。】

Sheet 计提情况检查表J2-4
A1: 致同会计师事务所
A2: 长期应付职工薪酬/设定受益计划净资产检查表
A3: =底稿目录!A2 -> 被审计单位： | C3: =底稿目录!A4 -> 编制人： | D3: =底稿目录!A5 -> 编制日期： | E3: 索引号： | F3: =底稿目录!D9 -> J2-4
A4: =底稿目录!A3 -> 截止日： | C4: =底稿目录!A6 -> 复核人： | D4: =底稿目录!A7 -> 复核日期： | E4: 页 次：
A5: 一、审计目标:
A6: 1.资产负债表中记录的长期应付职工薪酬是存在的，且已经记录在恰当的账户中
A7: 2.所有应记录的长期应付职工薪酬均已记录，所有应当包括在财务报表中的相关披露均已包括
A8: 3.记录的长期应付职工薪酬由被审计单位拥有或控制
A9: 4.长期应付职工薪酬以恰当的金额包括在财务报表中，与之相关的计价或分摊调整已恰当记录，相关披露已得到恰当计量和描述
A10: 二、审计过程：
A11: （一）判断为设定受益计划的理由
A12: 序号 | B12: 判断项目 | D12: 对应的设定受益计划主要条款 | E12: 判断理由 | F12: 判断结论（是\否\N/A）
A13: 1 | B13: 计划福利公式不仅仅与提存金金额相关，且要求企业在资产不足以满足该公式的福利时提供进一步的提存金
A14: 2 | B14: 通过计划间接地或直接地对提存金的特定回报作出担保
A15: 3 | B15: 企业给予补偿的事项是职工在职时提供的服务而不是退休本身
A16: 4 | B16: 精算风险和投资风险由企业来承担
A17: （二）了解精算师资质及利用精算师的工作
A18: 序号 | B18: 项目 | C18: 索引号
A19: 1 | B19: 利用专家的工作 | C19: S12
A20: 2 | B20: 评估专家工作 | C20: S12A
A21: （三）精算假设完整性测试
A22: 序号 | B22: 涉及精算假设的设定受益计划主要条款 | C22: 该精算假设是否在精算师的精算报告中 | D22: 精算报告中的精算假设
A28: （四）计量准确性测试
A29: 1、设定受益计划义务现值测试
A30: 考虑因素：（1）设定受益计划义务；（2）折现率的选取
A31: 2、设定受益计划资产测试
A32: 考虑因素：（1）设定受益资产原值；（2）设定受益资产公允价值的变动；（3）设定受益资产上限
A33: 3、计入当期损益金额测试
A34: 考虑因素：（1）当期服务成本；（2）过去服务成本；（3）结算利得和损失
A35: 4、计入其他综合收益金额测试
A36: 考虑因素：（1）精算利得或损失；（2）计划资产回报；（3）资产上限影响的变动
A37: 5、其他测试
A38: 考虑因素：（1）本期结算时消除的负债；（2）已支付的福利
A39: 测试过程如下：
... A45: 四、审计结论：
